Workbook

Sheet 总体目标
A1: 1. 玩家成长、追求时间
A2: 对于平均玩家而言，我们在首个上线版本中将努力使其在5个月左右的时间内不停有需要追寻、提升自己的内容。
A3: 对于大R玩家，这5个月时间将被大幅缩短。但我们的联盟玩法会给予这部分玩家新的追求（如有可能我们还将通过联盟events来刺激这个追求），并且一部分通过任务才能达成的追求也会要求他继续保持活跃。
A4: 对于每日登陆但操作频率低的玩家，这5个月的时间将被拉长2-3倍。
A6: 2.兴奋点安排
A7: 目前确定的重要兴奋点为：
A8: 兴奋点 | B8: 参数 | C8: 时间点（天）
A9: 建造车辆 | B9: 1、2 | C9: 0.5
A10: 制造装备 | B10: 1 | C10: 0.8
A11: 加入联盟 | B11: 1 | C11: 1
A12: 修理队列解锁 | B12: 1 | C12: 1.5
A13: 建造车辆 | B13: 3、4、5、6 | C13: 2
A14: 车辆升级 | B14: 1 | C14: 3
A15: 制造弹药 | B15: 1 | C15: 4
A16: 解锁车队 | B16: 2 | C16: 7
A17: 装备升档 | B17: 2 | C17: 7
A18: 修理队列解锁 | B18: 2 | C18: 10
A19: 车辆升级 | B19: 2 | C19: 14
A20: 弹药升档 | B20: 2 | C20: 14
A21: 装备升档 | B21: 3 | C21: 21
A22: 解锁车队 | B22: 3 | C22: 30
A23: 修理队列解锁 | B23: 3 | C23: 40
A24: 弹药升档 | B24: 3 | C24: 45
A25: 装备升档 | B25: 4 | C25: 60
... A27: 解锁车队 | B27: 5 | C27: 150
A29: 3.玩家获得、消耗资源的方式
A30: 获得资源：
A31: 分类 | B31: 系统整体产出？ | C31: 前期占比 | D31: 中期占比 | E31: 后期占比
A32: 野外资源点 | B32: Y | C32: 0.05 | D32: 0.4 | E32: 0.4
A33: 建筑物生产 | B33: Y | C33: 0.25 | D33: 0.25 | E33: 0.2
A34: 任务 | B34: Y | C34: 0.6 | D34: 0.15 | E34: 0.1
A35: PVP掠夺 | B35: N | C35: 0.05 | D35: 0.15 | E35: 0.25
A36: 其他 | B36: N | C36: 0.05 | D36: 0.05 | E36: 0.05
A37: 总计 | C37: 1 | D37: 1 | E37: 1
A38: 消耗资源：
A39: 分类 | B39: 系统整体消耗？ | C39: 前期占比 | D39: 中期占比 | E39: 后期占比
A40: 城建（建筑物升级、科技发展） | B40: Y | C40: 0.55 | D40: 0.3 | E40: 0.25
A41: 车辆 | B41: Y | C41: 0.3 | D41: 0.35 | E41: 0.05
A42: 装备 | B42: Y | C42: 0.03 | D42: 0.05 | E42: 0.15
A43: 修理 | B43: Y | C43: 0.05 | D43: 0.05 | E43: 0.1
...

Sheet 重要规划与假设
A1: 与传统的此类游戏相比，我们主要希望针对两个目标做修改、优化：  1、宏观上建筑方面达到5个月左右的建造、升级时间。  2、微观上，用户的提升不过于缓慢，玩家后期可以在2-3天左右体验到自己的提升，并强化其在游戏中的登陆习惯。
A6: 这两个目标一个要求总时间长，一个要求间隔时间短。其解决办法就是让用户更多次的操作，而两次操作中间间隔缩短。
A9: 提高操作次数的方式有： 1、 使得大部分玩家升级完了40所有的建筑，而不是偏重某一种。玩家的偏向性主要体现在科技上,而并非在建筑物升级上。为达到这个目的可能的方式有： a. 通过数值的设置使得所有资源建筑升级完成后方可升级stronghold b. 通过建筑物的依赖关系使得玩家需要将大部分的建筑物有效的升级 c. 通过性价比等设置引导玩家将各种建筑作较为平均的升级 2、 更多的资源建筑物种类 3、 将资源上限建筑与资源生产速度建筑分开 4、 增加同一种资源建筑的数量。与此相匹配的是： a. 数量上限 b. 解锁的时间点 5、 增加资源建筑的级别数 其中2、3两种做法与我们前期的设计差异较大，1、4、5是冲突比较小的优化方式。本表中将针对第5点作大量的优化。
A19: 为清晰性与一致性，本表以建筑物等级为度量。
A21: 资源建筑物建造需要更多的时间、更少的资源，总建造时间在2000小时左右
A22: 功能建筑物建造需要更多的资源、更少的时间，总建造时间在1000小时左右
A24: 与gow、dhd一样，升级时间膨胀迅速，而出产速度提高相对慢
A26: 确保升级时间在界面上的显示由两级可以完成，如“1H40M”“ 1D19H”
A28: 建筑物升级带来的玩家经验、power提升待定。另外，通过本设计之后，我们将讨论出基础的资源定价，并以此为基础得到各建筑物的instant价格。
A30: 科技共可为资源生产带来20%幅度的增益。科技随基地等级而解锁等级，基地每升高3级科技解锁一个新等级，且科技的增益升高越来越快。
A32: 建造、升级资源建筑物将每级给予主线任务的奖励，前期以junk为主，后期以oil为主

Sheet FAQ
A1: Q:玩家会不会不想升级资源建筑物，而是穷兵黩武呢？
A3: A：这也是一种玩法，事实上，这种玩家具有很强的互动性，我们并不介意玩家以这种方式进行游戏。另外，这一类型的玩家最终的追求往往还是体现在一座高等级的城池上，因为军队可以被消灭，只有城市不能回退。
A5: Q：玩家中后期资源不足够其建造、升级使用，会让玩家卡住、产生挫折感吗？
A7: A：我们给了玩家多样化的获取资源的方式。大地图有资源点供玩家采集，若资源点出产太少，可以迁移到更高级的地区。 玩家如果不通过掠夺其他玩家、占领资源点获取额外的资源，而是一直依靠城中出产的资源，其发展时间将被拉长。但是其玩法不会被打断，总体上我们保证其接受到的都是正向的反馈。
A9: Q：资源建筑物会随着基地升级而解锁，这会使此规划失效吗？
A11: A：资源建筑物数量随着总部级别而逐步解锁，但并不影响资源建筑的规划。因为最终玩家需要将几个资源建筑物建造并升到顶级，这个过程并不可跳过。
A13: Q：资源建筑物与功能建筑物之间为什么需要平衡？
A15: A：我们来讨论极端情况 若资源建筑物配比极端提高： 基地升级后，玩家将不存在取舍，必将首先升级功能建筑，随后通过时间积累、资源获取达到满足资源建筑物需求的条件。 若功能建筑物配比极端提高： 玩家的行为是基地升级后，将资源建筑物全部升级，可以一直点击下去。中间没有任何断层，玩家也就没有出去找资源、进行PVP或PVE的动力。

Sheet table (no research)
C1: for each resource building | P1: for resource buildings total | V1: for all buildings total
A2: level | B2: gained/cost | D2: sum | E2: hours | F2: minutes | G2: sec for reference | H2: research enhancing reduced | I2: capacity full time | J2: level duration (sec) | K2: level time | L2: resource needed | M2: resource output/hour | N2: Capacity | O2: resource reward | P2: level duration (sec) | Q2: level time | R2: resource needed | S2: resource output/hour | T2: Capacity | U2: resource reward | V2: level duration (sec) | W2: level time | X2: resource needed | Y2: resource output/hour | Z2: Capacity | AA2: protection limit | AB2: resource reward | AC2: resource gained | AD2: resource output in this level | AE2: protection proportion | AF2: gained/cost （resource） | AG2: output/ needed (resources)
A3: 1 | B3: 10 | C3: 0 | D3: =SUM($C$3:C3) -> 0 | E3: =F3/60 -> 0.016666667 | F3: =EXP(D3) -> 1 | G3: =F3*60 -> 60 | H3: =G3*'Research Enhancing'!C2 -> 60.6 | I3: 50 | J3: 60 | K3: =IF(INT(J3/3600/24)=0,"",INT(J3/3600/24)&"D")&IF(INT(MOD(J3,3600*24)/3600)=0,"",INT(MOD(J3,3600*24)/3600)&"H")&IF(INT(MOD(J3,3600)/60)=0,"",INT(MOD(J3,3600)/60)&"M")&IF(MOD(J3,60)=0,"",INT(MOD(J3,60))&"S") -> 1M | L3: 1000 | M3: =ROUND(0*A3*A3+120*A3,0) -> 120 | N3: =I3*M3 -> 6000 | O3: =U3/3 -> 12983.1 | P3: =J3*13 -> 780 | Q3: =IF(INT(P3/3600/24)=0,"",INT(P3/3600/24)&"D")&IF(INT(MOD(P3,3600*24)/3600)=0,"",INT(MOD(P3,3600*24)/3600)&"H")&IF(INT(MOD(P3,3600)/60)=0,"",INT(MOD(P3,3600)/60)&"M")&IF(MOD(P3,60)=0,"",INT(MOD(P3,60))&"S") -> 13M | R3: =L3*13 -> 13000 | S3: =M3*13 -> 1560 | T3: =N3*13 -> 78000 | U3: =AB3*'reward percentage'!$B$3 -> 38949.3 | V3: =P3*1.5 -> 1170 | W3: =IF(INT(V3/3600/24)=0,"",INT(V3/3600/24)&"D")&IF(INT(MOD(V3,3600*24)/3600)=0,"",INT(MOD(V3,3600*24)/3600)&"H")&IF(INT(MOD(V3,3600)/60)=0,"",INT(MOD(V3,3600)/60)&"M")&IF(MOD(V3,60)=0,"",INT(MOD(V3,60))&"S") -> 19M30S | X3: =R3*3 -> 39000 | Y3: =S3 -> 1560 | Z3: =T3 -> 78000 | AA3: 156000 | AB3: =AC3-AD3 -> 389493 | AC3: =X3*B3 -> 390000 | AD3: =Y3*V3/3600 -> 507 | AE3: =AA3/Z3 -> 2 | AF3: 10 | AG3: =AD3/X3 -> 0.013
A4: 2 | B4: =EXP($S$40*($A$12-A4)) -> 7.7426368 | C4: 0.328 | D4: =SUM($C$3:C4) -> 0.328 | E4: =F4/60 -> 0.023136483 | F4: =EXP(D4) -> 1.388189 | G4: =F4*60 -> 83.291338 | H4: =G4*'Research Enhancing'!C3 -> 84.124252 | I4: 51 | J4: 80 | K4: =IF(INT(J4/3600/24)=0,"",INT(J4/3600/24)&"D")&IF(INT(MOD(J4,3600*24)/3600)=0,"",INT(MOD(J4,3600*24)/3600)&"H")&IF(INT(MOD(J4,3600)/60)=0,"",INT(MOD(J4,3600)/60)&"M")&IF(MOD(J4,60)=0,"",INT(MOD(J4,60))&"S") -> 1M20S | L4: =J4*1000/60 -> 1333.3333 | M4: =ROUND(0*A4*A4+120*A4,0) -> 240 | N4: =I4*M4 -> 12240 | O4: =U4/3 -> 13386.77 | P4: =J4*13 -> 1040 | Q4: =IF(INT(P4/3600/24)=0,"",INT(P4/3600/24)&"D")&IF(INT(MOD(P4,3600*24)/3600)=0,"",INT(MOD(P4,3600*24)/3600)&"H")&IF(INT(MOD(P4,3600)/60)=0,"",INT(MOD(P4,3600)/60)&"M")&IF(MOD(P4,60)=0,"",INT(MOD(P4,60))&"S") -> 17M20S | R4: =L4*13 -> 17333.333 | S4: =M4*13 -> 3120 | T4: =N4*13 -> 159120 | U4: =AB4*'reward percentage'!$B$3 -> 40160.311 | V4: =P4*1.5 -> 1560 | W4: =IF(INT(V4/3600/24)=0,"",INT(V4/3600/24)&"D")&IF(INT(MOD(V4,3600*24)/3600)=0,"",INT(MOD(V4,3600*24)/3600)&"H")&IF(INT(MOD(V4,3600)/60)=0,"",INT(MOD(V4,3600)/60)&"M")&IF(MOD(V4,60)=0,"",INT(MOD(V4,60))&"S") -> 26M | X4: =R4*3 -> 52000 | Y4: =S4 -> 3120 | Z4: =T4 -> 159120 | AA4: =AA3+29575 -> 185575 | AB4: =AC4-AD4 -> 401603.11 | AC4: =X4*B4 -> 402617.11 | AD4: =(Y4+Y3)/2*V4/3600 -> 1014 | AE4: =AA4/Z4 -> 1.1662582 | AF4: 7.7426368 | AG4: =AD4/X4 -> 0.0195
A5: 3 | B5: =EXP($S$40*($A$12-A5)) -> 5.9948425 | C5: 0.328 | D5: =SUM($C$3:C5) -> 0.656 | E5: =F5/60 -> 0.03211781 | F5: =EXP(D5) -> 1.9270686 | G5: =F5*60 -> 115.62412 | H5: =G5*'Research Enhancing'!C4 -> 116.78036 | I5: 52 | J5: 120 | K5: =IF(INT(J5/3600/24)=0,"",INT(J5/3600/24)&"D")&IF(INT(MOD(J5,3600*24)/3600)=0,"",INT(MOD(J5,3600*24)/3600)&"H")&IF(INT(MOD(J5,3600)/60)=0,"",INT(MOD(J5,3600)/60)&"M")&IF(MOD(J5,60)=0,"",INT(MOD(J5,60))&"S") -> 2M | L5: =J5*1000/60 -> 2000 | M5: =ROUND(0*A5*A5+120*A5,0) -> 360 | N5: =I5*M5 -> 18720 | O5: =U5/3 -> 15502.091 | P5: =J5*13 -> 1560 | Q5: =IF(INT(P5/3600/24)=0,"",INT(P5/3600/24)&"D")&IF(INT(MOD(P5,3600*24)/3600)=0,"",INT(MOD(P5,3600*24)/3600)&"H")&IF(INT(MOD(P5,3600)/60)=0,"",INT(MOD(P5,3600)/60)&"M")&IF(MOD(P5,60)=0,"",INT(MOD(P5,60))&"S") -> 26M | R5: =L5*13 -> 26000 | S5: =M5*13 -> 4680 | T5: =N5*13 -> 243360 | U5: =AB5*'reward percentage'!$B$3 -> 46506.272 | V5: =P5*1.5 -> 2340 | W5: =IF(INT(V5/3600/24)=0,"",INT(V5/3600/24)&"D")&IF(INT(MOD(V5,3600*24)/3600)=0,"",INT(MOD(V5,3600*24)/3600)&"H")&IF(INT(MOD(V5,3600)/60)=0,"",INT(MOD(V5,3600)/60)&"M")&IF(MOD(V5,60)=0,"",INT(MOD(V5,60))&"S") -> 39M | X5: =R5*3 -> 78000 | Y5: =S5 -> 4680 | Z5: =T5 -> 243360 | AA5: =AA4+29575 -> 215150 | AB5: =AC5-AD5 -> 465062.72 | AC5: =X5*B5 -> 467597.72 | AD5: =(Y5+Y4)/2*V5/3600 -> 2535 | AE5: =AA5/Z5 -> 0.8840812 | AF5: 5.9948425 | AG5: =AD5/X5 -> 0.0325
A6: 4 | B6: =EXP($S$40*($A$12-A6)) -> 4.6415888 | C6: 0.328 | D6: =SUM($C$3:C6) -> 0.984 | E6: =F6/60 -> 0.04458559 | F6: =EXP(D6) -> 2.6751354 | G6: =F6*60 -> 160.50812 | H6: =G6*'Research Enhancing'!C5 -> 163.71829 | I6: 53 | J6: 160 | K6: =IF(INT(J6/3600/24)=0,"",INT(J6/3600/24)&"D")&IF(INT(MOD(J6,3600*24)/3600)=0,"",INT(MOD(J6,3600*24)/3600)&"H")&IF(INT(MOD(J6,3600)/60)=0,"",INT(MOD(J6,3600)/60)&"M")&IF(MOD(J6,60)=0,"",INT(MOD(J6,60))&"S") -> 2M40S | L6: =J6*1000/60 -> 2666.6667 | M6: =ROUND(0*A6*A6+120*A6,0) -> 480 | N6: =I6*M6 -> 25440 | O6: =U6/3 -> 15933.108 | P6: =J6*13 -> 2080 | Q6: =IF(INT(P6/3600/24)=0,"",INT(P6/3600/24)&"D")&IF(INT(MOD(P6,3600*24)/3600)=0,"",INT(MOD(P6,3600*24)/3600)&"H")&IF(INT(MOD(P6,3600)/60)=0,"",INT(MOD(P6,3600)/60)&"M")&IF(MOD(P6,60)=0,"",INT(MOD(P6,60))&"S") -> 34M40S | R6: =L6*13 -> 34666.667 | S6: =M6*13 -> 6240 | T6: =N6*13 -> 330720 | U6: =AB6*'reward percentage'!$B$3 -> 47799.324 | V6: =P6*1.5 -> 3120 | W6: =IF(INT(V6/3600/24)=0,"",INT(V6/3600/24)&"D")&IF(INT(MOD(V6,3600*24)/3600)=0,"",INT(MOD(V6,3600*24)/3600)&"H")&IF(INT(MOD(V6,3600)/60)=0,"",INT(MOD(V6,3600)/60)&"M")&IF(MOD(V6,60)=0,"",INT(MOD(V6,60))&"S") -> 52M | X6: =R6*3 -> 104000 | Y6: =S6 -> 6240 | Z6: =T6 -> 330720 | AA6: =AA5+29575 -> 244725 | AB6: =AC6-AD6 -> 477993.24 | AC6: =X6*B6 -> 482725.24 | AD6: =(Y6+Y5)/2*V6/3600 -> 4732 | AE6: =AA6/Z6 -> 0.73997642 | AF6: 4.6415888 | AG6: =AD6/X6 -> 0.0455
A7: 5 | B7: =EXP($S$40*($A$12-A7)) -> 3.5938137 | C7: 0.328 | D7: =SUM($C$3:C7) -> 1.312 | E7: =F7/60 -> 0.061893225 | F7: =EXP(D7) -> 3.7135935 | G7: =F7*60 -> 222.81561 | H7: =G7*'Research Enhancing'!C6 -> 227.27192 | I7: 54 | J7: 240 | K7: =IF(INT(J7/3600/24)=0,"",INT(J7/3600/24)&"D")&IF(INT(MOD(J7,3600*24)/3600)=0,"",INT(MOD(J7,3600*24)/3600)&"H")&IF(INT(MOD(J7,3600)/60)=0,"",INT(MOD(J7,3600)/60)&"M")&IF(MOD(J7,60)=0,"",INT(MOD(J7,60))&"S") -> 4M | L7: =J7*1000/60 -> 4000 | M7: =ROUND(0*A7*A7+120*A7,0) -> 600 | N7: =I7*M7 -> 32400 | O7: =U7/3 -> 18383.631 | P7: =J7*13 -> 3120 | Q7: =IF(INT(P7/3600/24)=0,"",INT(P7/3600/24)&"D")&IF(INT(MOD(P7,3600*24)/3600)=0,"",INT(MOD(P7,3600*24)/3600)&"H")&IF(INT(MOD(P7,3600)/60)=0,"",INT(MOD(P7,3600)/60)&"M")&IF(MOD(P7,60)=0,"",INT(MOD(P7,60))&"S") -> 52M | R7: =L7*13 -> 52000 | S7: =M7*13 -> 7800 | T7: =N7*13 -> 421200 | U7: =AB7*'reward percentage'!$B$3 -> 55150.893 | V7: =P7*1.5 -> 4680 | W7: =IF(INT(V7/3600/24)=0,"",INT(V7/3600/24)&"D")&IF(INT(MOD(V7,3600*24)/3600)=0,"",INT(MOD(V7,3600*24)/3600)&"H")&IF(INT(MOD(V7,3600)/60)=0,"",INT(MOD(V7,3600)/60)&"M")&IF(MOD(V7,60)=0,"",INT(MOD(V7,60))&"S") -> 1H18M | X7: =R7*3 -> 156000 | Y7: =S7 -> 7800 | Z7: =T7 -> 421200 | AA7: =AA6+29575 -> 274300 | AB7: =AC7-AD7 -> 551508.93 | AC7: =X7*B7 -> 560634.93 | AD7: =(Y7+Y6)/2*V7/3600 -> 9126 | AE7: =AA7/Z7 -> 0.65123457 | AF7: 3.5938137 | AG7: =AD7/X7 -> 0.0585
A8: 6 | B8: =EXP($S$40*($A$12-A8)) -> 2.7825594 | C8: 0.328 | D8: =SUM($C$3:C8) -> 1.64 | E8: =F8/60 -> 0.085919492 | F8: =EXP(D8) -> 5.1551695 | G8: =F8*60 -> 309.31017 | H8: =G8*'Research Enhancing'!C7 -> 315.49637 | I8: 55 | J8: 300 | K8: =IF(INT(J8/3600/24)=0,"",INT(J8/3600/24)&"D")&IF(INT(MOD(J8,3600*24)/3600)=0,"",INT(MOD(J8,3600*24)/3600)&"H")&IF(INT(MOD(J8,3600)/60)=0,"",INT(MOD(J8,3600)/60)&"M")&IF(MOD(J8,60)=0,"",INT(MOD(J8,60))&"S") -> 5M | L8: =J8*1000/60 -> 5000 | M8: =ROUND(0*A8*A8+120*A8,0) -> 720 | N8: =I8*M8 -> 39600 | O8: =U8/3 -> 17621.886 | P8: =J8*13 -> 3900 | Q8: =IF(INT(P8/3600/24)=0,"",INT(P8/3600/24)&"D")&IF(INT(MOD(P8,3600*24)/3600)=0,"",INT(MOD(P8,3600*24)/3600)&"H")&IF(INT(MOD(P8,3600)/60)=0,"",INT(MOD(P8,3600)/60)&"M")&IF(MOD(P8,60)=0,"",INT(MOD(P8,60))&"S") -> 1H5M | R8: =L8*13 -> 65000 | S8: =M8*13 -> 9360 | T8: =N8*13 -> 514800 | U8: =AB8*'reward percentage'!$B$3 -> 52865.658 | V8: =P8*1.5 -> 5850 | W8: =IF(INT(V8/3600/24)=0,"",INT(V8/3600/24)&"D")&IF(INT(MOD(V8,3600*24)/3600)=0,"",INT(MOD(V8,3600*24)/3600)&"H")&IF(INT(MOD(V8,3600)/60)=0,"",INT(MOD(V8,3600)/60)&"M")&IF(MOD(V8,60)=0,"",INT(MOD(V8,60))&"S") -> 1H37M30S | X8: =R8*3 -> 195000 | Y8: =S8 -> 9360 | Z8: =T8 -> 514800 | AA8: =AA7+29575 -> 303875 | AB8: =AC8-AD8 -> 528656.58 | AC8: =X8*B8 -> 542599.08 | AD8: =(Y8+Y7)/2*V8/3600 -> 13942.5 | AE8: =AA8/Z8 -> 0.59027778 | AF8: 2.7825594 | AG8: =AD8/X8 -> 0.0715
A9: 7 | B9: =EXP($S$40*($A$12-A9)) -> 2.1544347 | C9: 0.328 | D9: =SUM($C$3:C9) -> 1.968 | E9: =F9/60 -> 0.11927249 | F9: =EXP(D9) -> 7.1563495 | G9: =F9*60 -> 429.38097 | H9: =G9*'Research Enhancing'!C8 -> 442.2624 | I9: 56 | J9: 450 | K9: =IF(INT(J9/3600/24)=0,"",INT(J9/3600/24)&"D")&IF(INT(MOD(J9,3600*24)/3600)=0,"",INT(MOD(J9,3600*24)/3600)&"H")&IF(INT(MOD(J9,3600)/60)=0,"",INT(MOD(J9,3600)/60)&"M")&IF(MOD(J9,60)=0,"",INT(MOD(J9,60))&"S") -> 7M30S | L9: =J9*1000/60 -> 7500 | M9: =ROUND(0*A9*A9+120*A9,0) -> 840 | N9: =I9*M9 -> 47040 | O9: =U9/3 -> 20181.863 | P9: =J9*13 -> 5850 | Q9: =IF(INT(P9/3600/24)=0,"",INT(P9/3600/24)&"D")&IF(INT(MOD(P9,3600*24)/3600)=0,"",INT(MOD(P9,3600*24)/3600)&"H")&IF(INT(MOD(P9,3600)/60)=0,"",INT(MOD(P9,3600)/60)&"M")&IF(MOD(P9,60)=0,"",INT(MOD(P9,60))&"S") -> 1H37M30S | R9: =L9*13 -> 97500 | S9: =M9*13 -> 10920 | T9: =N9*13 -> 611520 | U9: =AB9*'reward percentage'!$B$3 -> 60545.59 | V9: =P9*1.5 -> 8775 | W9: =IF(INT(V9/3600/24)=0,"",INT(V9/3600/24)&"D")&IF(INT(MOD(V9,3600*24)/3600)=0,"",INT(MOD(V9,3600*24)/3600)&"H")&IF(INT(MOD(V9,3600)/60)=0,"",INT(MOD(V9,3600)/60)&"M")&IF(MOD(V9,60)=0,"",INT(MOD(V9,60))&"S") -> 2H26M15S | X9: =R9*3 -> 292500 | Y9: =S9 -> 10920 | Z9: =T9 -> 611520 | AA9: =AA8+29575 -> 333450 | AB9: =AC9-AD9 -> 605455.9 | AC9: =X9*B9 -> 630172.15 | AD9: =(Y9+Y8)/2*V9/3600 -> 24716.25 | AE9: =AA9/Z9 -> 0.54528061 | AF9: 2.1544347 | AG9: =AD9/X9 -> 0.0845
A10: 8 | B10: =EXP($S$40*($A$12-A10)) -> 1.6681005 | C10: 0.328 | D10: =SUM($C$3:C10) -> 2.296 | E10: =F10/60 -> 0.16557276 | F10: =EXP(D10) -> 9.9343654 | G10: =F10*60 -> 596.06192 | H10: =G10*'Research Enhancing'!C9 -> 613.94378 | I10: 57 | J10: 620 | K10: =IF(INT(J10/3600/24)=0,"",INT(J10/3600/24)&"D")&IF(INT(MOD(J10,3600*24)/3600)=0,"",INT(MOD(J10,3600*24)/3600)&"H")&IF(INT(MOD(J10,3600)/60)=0,"",INT(MOD(J10,3600)/60)&"M")&IF(MOD(J10,60)=0,"",INT(MOD(J10,60))&"S") -> 10M20S | L10: =J10*1000/60 -> 10333.333 | M10: =ROUND(0*A10*A10+120*A10,0) -> 960 | N10: =I10*M10 -> 54720 | O10: =U10/3 -> 21098.401 | P10: =J10*13 -> 8060 | Q10: =IF(INT(P10/3600/24)=0,"",INT(P10/3600/24)&"D")&IF(INT(MOD(P10,3600*24)/3600)=0,"",INT(MOD(P10,3600*24)/3600)&"H")&IF(INT(MOD(P10,3600)/60)=0,"",INT(MOD(P10,3600)/60)&"M")&IF(MOD(P10,60)=0,"",INT(MOD(P10,60))&"S") -> 2H14M20S | R10: =L10*13 -> 134333.33 | S10: =M10*13 -> 12480 | T10: =N10*13 -> 711360 | U10: =AB10*'reward percentage'!$B$3 -> 63295.202 | V10: =P10*1.5 -> 12090 | W10: =IF(INT(V10/3600/24)=0,"",INT(V10/3600/24)&"D")&IF(INT(MOD(V10,3600*24)/3600)=0,"",INT(MOD(V10,3600*24)/3600)&"H")&IF(INT(MOD(V10,3600)/60)=0,"",INT(MOD(V10,3600)/60)&"M")&IF(MOD(V10,60)=0,"",INT(MOD(V10,60))&"S") -> 3H21M30S | X10: =R10*3 -> 403000 | Y10: =S10 -> 12480 | Z10: =T10 -> 711360 | AA10: =AA9+29575 -> 363025 | AB10: =AC10-AD10 -> 632952.02 | AC10: =X10*B10 -> 672244.52 | AD10: =(Y10+Y9)/2*V10/3600 -> 39292.5 | AE10: =AA10/Z10 -> 0.51032529 | AF10: 1.6681005 | AG10: =AD10/X10 -> 0.0975
A11: 9 | B11: =EXP($S$40*($A$12-A11)) -> 1.2915497 | C11: 0.328 | D11: =SUM($C$3:C11) -> 2.624 | E11: =F11/60 -> 0.22984628 | F11: =EXP(D11) -> 13.790777 | G11: =F11*60 -> 827.44659 | H11: =G11*'Research Enhancing'!C10 -> 852.26999 | I11: 58 | J11: 860 | K11: =IF(INT(J11/3600/24)=0,"",INT(J11/3600/24)&"D")&IF(INT(MOD(J11,3600*24)/3600)=0,"",INT(MOD(J11,3600*24)/3600)&"H")&IF(INT(MOD(J11,3600)/60)=0,"",INT(MOD(J11,3600)/60)&"M")&IF(MOD(J11,60)=0,"",INT(MOD(J11,60))&"S") -> 14M20S | L11: =J11*1000/60 -> 14333.333 | M11: =ROUND(0*A11*A11+120*A11,0) -> 1080 | N11: =I11*M11 -> 62640 | O11: =U11/3 -> 22006.892 | P11: =J11*13 -> 11180 | Q11: =IF(INT(P11/3600/24)=0,"",INT(P11/3600/24)&"D")&IF(INT(MOD(P11,3600*24)/3600)=0,"",INT(MOD(P11,3600*24)/3600)&"H")&IF(INT(MOD(P11,3600)/60)=0,"",INT(MOD(P11,3600)/60)&"M")&IF(MOD(P11,60)=0,"",INT(MOD(P11,60))&"S") -> 3H6M20S | R11: =L11*13 -> 186333.33 | S11: =M11*13 -> 14040 | T11: =N11*13 -> 814320 | U11: =AB11*'reward percentage'!$B$3 -> 66020.676 | V11: =P11*1.5 -> 16770 | W11: =IF(INT(V11/3600/24)=0,"",INT(V11/3600/24)&"D")&IF(INT(MOD(V11,3600*24)/3600)=0,"",INT(MOD(V11,3600*24)/3600)&"H")&IF(INT(MOD(V11,3600)/60)=0,"",INT(MOD(V11,3600)/60)&"M")&IF(MOD(V11,60)=0,"",INT(MOD(V11,60))&"S") -> 4H39M30S | X11: =R11*3 -> 559000 | Y11: =S11 -> 14040 | Z11: =T11 -> 814320 | AA11: =AA10+29575 -> 392600 | AB11: =AC11-AD11 -> 660206.76 | AC11: =X11*B11 -> 721976.26 | AD11: =(Y11+Y10)/2*V11/3600 -> 61769.5 | AE11: =AA11/Z11 -> 0.48212005 | AF11: 1.2915497 | AG11: =AD11/X11 -> 0.1105
A12: 10 | B12: 1 | C12: 0.328 | D12: =SUM($C$3:C12) -> 2.952 | E12: =F12/60 -> 0.31907006 | F12: =EXP(D12) -> 19.144204 | G12: =F12*60 -> 1148.6522 | H12: =G12*'Research Enhancing'!C11 -> 1194.5983 | I12: 59 | J12: 1200 | K12: =IF(INT(J12/3600/24)=0,"",INT(J12/3600/24)&"D")&IF(INT(MOD(J12,3600*24)/3600)=0,"",INT(MOD(J12,3600*24)/3600)&"H")&IF(INT(MOD(J12,3600)/60)=0,"",INT(MOD(J12,3600)/60)&"M")&IF(MOD(J12,60)=0,"",INT(MOD(J12,60))&"S") -> 20M | L12: =J12*1000/60 -> 20000 | M12: =ROUND(0*A12*A12+120*A12,0) -> 1200 | N12: =I12*M12 -> 70800 | O12: =U12/3 -> 22789 | P12: =J12*13 -> 15600 | Q12: =IF(INT(P12/3600/24)=0,"",INT(P12/3600/24)&"D")&IF(INT(MOD(P12,3600*24)/3600)=0,"",INT(MOD(P12,3600*24)/3600)&"H")&IF(INT(MOD(P12,3600)/60)=0,"",INT(MOD(P12,3600)/60)&"M")&IF(MOD(P12,60)=0,"",INT(MOD(P12,60))&"S") -> 4H20M | R12: =L12*13 -> 260000 | S12: =M12*13 -> 15600 | T12: =N12*13 -> 920400 | U12: =AB12*'reward percentage'!$B$3 -> 68367 | V12: =P12*1.5 -> 23400 | W12: =IF(INT(V12/3600/24)=0,"",INT(V12/3600/24)&"D")&IF(INT(MOD(V12,3600*24)/3600)=0,"",INT(MOD(V12,3600*24)/3600)&"H")&IF(INT(MOD(V12,3600)/60)=0,"",INT(MOD(V12,3600)/60)&"M")&IF(MOD(V12,60)=0,"",INT(MOD(V12,60))&"S") -> 6H30M | X12: =R12*3 -> 780000 | Y12: =S12 -> 15600 | Z12: =T12 -> 920400 | AA12: =AA11+29575 -> 422175 | AB12: =AC12-AD12 -> 683670 | AC12: =X12*B12 -> 780000 | AD12: =(Y12+Y11)/2*V12/3600 -> 96330 | AE12: =AA12/Z12 -> 0.45868644 | AF12: 1 | AG12: =AD12/X12 -> 0.1235
A13: 11 | B13: =EXP($S$38*(A13-10)) -> 0.92685116 | C13: 0.328 | D13: =SUM($C$3:C13) -> 3.28 | E13: =F13/60 -> 0.44292954 | F13: =EXP(D13) -> 26.575773 | G13: =F13*60 -> 1594.5464 | H13: =G13*'Research Enhancing'!C12 -> 1658.3282 | I13: 60 | J13: 1660 | K13: =IF(INT(J13/3600/24)=0,"",INT(J13/3600/24)&"D")&IF(INT(MOD(J13,3600*24)/3600)=0,"",INT(MOD(J13,3600*24)/3600)&"H")&IF(INT(MOD(J13,3600)/60)=0,"",INT(MOD(J13,3600)/60)&"M")&IF(MOD(J13,60)=0,"",INT(MOD(J13,60))&"S") -> 27M40S | L13: =J13*1000/60 -> 27666.667 | M13: =ROUND(0*A13*A13+120*A13,0) -> 1320 | N13: =I13*M13 -> 79200 | O13: =U13/3 -> 28426.297 | P13: =J13*13 -> 21580 | Q13: =IF(INT(P13/3600/24)=0,"",INT(P13/3600/24)&"D")&IF(INT(MOD(P13,3600*24)/3600)=0,"",INT(MOD(P13,3600*24)/3600)&"H")&IF(INT(MOD(P13,3600)/60)=0,"",INT(MOD(P13,3600)/60)&"M")&IF(MOD(P13,60)=0,"",INT(MOD(P13,60))&"S") -> 5H59M40S | R13: =L13*13 -> 359666.67 | S13: =M13*13 -> 17160 | T13: =N13*13 -> 1029600 | U13: =AB13*'reward percentage'!$B$3 -> 85278.89 | V13: =P13*1.5 -> 32370 | W13: =IF(INT(V13/3600/24)=0,"",INT(V13/3600/24)&"D")&IF(INT(MOD(V13,3600*24)/3600)=0,"",INT(MOD(V13,3600*24)/3600)&"H")&IF(INT(MOD(V13,3600)/60)=0,"",INT(MOD(V13,3600)/60)&"M")&IF(MOD(V13,60)=0,"",INT(MOD(V13,60))&"S") -> 8H59M30S | X13: =R13*3 -> 1079000 | Y13: =S13 -> 17160 | Z13: =T13 -> 1029600 | AA13: =AA12+29575 -> 451750 | AB13: =AC13-AD13 -> 852788.9 | AC13: =X13*B13 -> 1000072.4 | AD13: =(Y13+Y12)/2*V13/3600 -> 147283.5 | AE13: =AA13/Z13 -> 0.43876263 | AF13: 0.92685116 | AG13: =AD13/X13 -> 0.1365
A14: 12 | B14: =EXP($S$38*(A14-10)) -> 0.85905308 | C14: 0.328 | D14: =SUM($C$3:C14) -> 3.608 | E14: =F14/60 -> 0.61486991 | F14: =EXP(D14) -> 36.892195 | G14: =F14*60 -> 2213.5317 | H14: =G14*'Research Enhancing'!C13 -> 2302.0729 | I14: 61 | J14: 2300 | K14: =IF(INT(J14/3600/24)=0,"",INT(J14/3600/24)&"D")&IF(INT(MOD(J14,3600*24)/3600)=0,"",INT(MOD(J14,3600*24)/3600)&"H")&IF(INT(MOD(J14,3600)/60)=0,"",INT(MOD(J14,3600)/60)&"M")&IF(MOD(J14,60)=0,"",INT(MOD(J14,60))&"S") -> 38M20S | L14: =J14*1000/60 -> 38333.333 | M14: =ROUND(0*A14*A14+120*A14,0) -> 1440 | N14: =I14*M14 -> 87840 | O14: =U14/3 -> 35359.395 | P14: =J14*13 -> 29900 | Q14: =IF(INT(P14/3600/24)=0,"",INT(P14/3600/24)&"D")&IF(INT(MOD(P14,3600*24)/3600)=0,"",INT(MOD(P14,3600*24)/3600)&"H")&IF(INT(MOD(P14,3600)/60)=0,"",INT(MOD(P14,3600)/60)&"M")&IF(MOD(P14,60)=0,"",INT(MOD(P14,60))&"S") -> 8H18M20S | R14: =L14*13 -> 498333.33 | S14: =M14*13 -> 18720 | T14: =N14*13 -> 1141920 | U14: =AB14*'reward percentage'!$B$3 -> 106078.18 | V14: =P14*1.5 -> 44850 | W14: =IF(INT(V14/3600/24)=0,"",INT(V14/3600/24)&"D")&IF(INT(MOD(V14,3600*24)/3600)=0,"",INT(MOD(V14,3600*24)/3600)&"H")&IF(INT(MOD(V14,3600)/60)=0,"",INT(MOD(V14,3600)/60)&"M")&IF(MOD(V14,60)=0,"",INT(MOD(V14,60))&"S") -> 12H27M30S | X14: =R14*3 -> 1495000 | Y14: =S14 -> 18720 | Z14: =T14 -> 1141920 | AA14: =AA13+29575 -> 481325 | AB14: =AC14-AD14 -> 1060781.8 | AC14: =X14*B14 -> 1284284.3 | AD14: =(Y14+Y13)/2*V14/3600 -> 223502.5 | AE14: =AA14/Z14 -> 0.42150501 | AF14: 0.85905308 | AG14: =AD14/X14 -> 0.1495
A15: 13 | B15: =EXP($S$38*(A15-10)) -> 0.79621434 | C15: 0.328 | D15: =SUM($C$3:C15) -> 3.936 | E15: =F15/60 -> 0.85355563 | F15: =EXP(D15) -> 51.213338 | G15: =F15*60 -> 3072.8003 | H15: =G15*'Research Enhancing'!C14 -> 3226.4403 | I15: 62 | J15: 3240 | K15: =IF(INT(J15/3600/24)=0,"",INT(J15/3600/24)&"D")&IF(INT(MOD(J15,3600*24)/3600)=0,"",INT(MOD(J15,3600*24)/3600)&"H")&IF(INT(MOD(J15,3600)/60)=0,"",INT(MOD(J15,3600)/60)&"M")&IF(MOD(J15,60)=0,"",INT(MOD(J15,60))&"S") -> 54M | L15: =J15*1000/60 -> 54000 | M15: =ROUND(0*A15*A15+120*A15,0) -> 1560 | N15: =I15*M15 -> 96720 | O15: =U15/3 -> 44486.747 | P15: =J15*13 -> 42120 | Q15: =IF(INT(P15/3600/24)=0,"",INT(P15/3600/24)&"D")&IF(INT(MOD(P15,3600*24)/3600)=0,"",INT(MOD(P15,3600*24)/3600)&"H")&IF(INT(MOD(P15,3600)/60)=0,"",INT(MOD(P15,3600)/60)&"M")&IF(MOD(P15,60)=0,"",INT(MOD(P15,60))&"S") -> 11H42M | R15: =L15*13 -> 702000 | S15: =M15*13 -> 20280 | T15: =N15*13 -> 1257360 | U15: =AB15*'reward percentage'!$B$3 -> 133460.24 | V15: =P15*1.5 -> 63180 | W15: =IF(INT(V15/3600/24)=0,"",INT(V15/3600/24)&"D")&IF(INT(MOD(V15,3600*24)/3600)=0,"",INT(MOD(V15,3600*24)/3600)&"H")&IF(INT(MOD(V15,3600)/60)=0,"",INT(MOD(V15,3600)/60)&"M")&IF(MOD(V15,60)=0,"",INT(MOD(V15,60))&"S") -> 17H33M | X15: =R15*3 -> 2106000 | Y15: =S15 -> 20280 | Z15: =T15 -> 1257360 | AA15: =AA14+29575 -> 510900 | AB15: =AC15-AD15 -> 1334602.4 | AC15: =X15*B15 -> 1676827.4 | AD15: =(Y15+Y14)/2*V15/3600 -> 342225 | AE15: =AA15/Z15 -> 0.40632754 | AF15: 0.79621434 | AG15: =AD15/X15 -> 0.1625
A16: 14 | B16: =EXP($S$38*(A16-10)) -> 0.73797219 | C16: 0.328 | D16: =SUM($C$3:C16) -> 4.264 | E16: =F16/60 -> 1.1848965 | F16: =EXP(D16) -> 71.093791 | G16: =F16*60 -> 4265.6274 | H16: =G16*'Research Enhancing'!C15 -> 4478.9088 | I16: 63 | J16: 4500 | K16: =IF(INT(J16/3600/24)=0,"",INT(J16/3600/24)&"D")&IF(INT(MOD(J16,3600*24)/3600)=0,"",INT(MOD(J16,3600*24)/3600)&"H")&IF(INT(MOD(J16,3600)/60)=0,"",INT(MOD(J16,3600)/60)&"M")&IF(MOD(J16,60)=0,"",INT(MOD(J16,60))&"S") -> 1H15M | L16: =J16*1000/60 -> 75000 | M16: =ROUND(0*A16*A16+120*A16,0) -> 1680 | N16: =I16*M16 -> 105840 | O16: =U16/3 -> 54841.038 | P16: =J16*13 -> 58500 | Q16: =IF(INT(P16/3600/24)=0,"",INT(P16/3600/24)&"D")&IF(INT(MOD(P16,3600*24)/3600)=0,"",INT(MOD(P16,3600*24)/3600)&"H")&IF(INT(MOD(P16,3600)/60)=0,"",INT(MOD(P16,3600)/60)&"M")&IF(MOD(P16,60)=0,"",INT(MOD(P16,60))&"S") -> 16H15M | R16: =L16*13 -> 975000 | S16: =M16*13 -> 21840 | T16: =N16*13 -> 1375920 | U16: =AB16*'reward percentage'!$B$3 -> 164523.11 | V16: =P16*1.5 -> 87750 | W16: =IF(INT(V16/3600/24)=0,"",INT(V16/3600/24)&"D")&IF(INT(MOD(V16,3600*24)/3600)=0,"",INT(MOD(V16,3600*24)/3600)&"H")&IF(INT(MOD(V16,3600)/60)=0,"",INT(MOD(V16,3600)/60)&"M")&IF(MOD(V16,60)=0,"",INT(MOD(V16,60))&"S") -> 1D22M30S | X16: =R16*3 -> 2925000 | Y16: =S16 -> 21840 | Z16: =T16 -> 1375920 | AA16: =AA15+29575 -> 540475 | AB16: =AC16-AD16 -> 1645231.1 | AC16: =X16*B16 -> 2158568.6 | AD16: =(Y16+Y15)/2*V16/3600 -> 513337.5 | AE16: =AA16/Z16 -> 0.3928099 | AF16: 0.73797219 | AG16: =AD16/X16 -> 0.1755
A17: 15 | B17: =EXP($S$38*(A17-10)) -> 0.68399038 | C17: 0.328 | D17: =SUM($C$3:C17) -> 4.592 | E17: =F17/60 -> 1.6448603 | F17: =EXP(D17) -> 98.691616 | G17: =F17*60 -> 5921.497 | H17: =G17*'Research Enhancing'!C16 -> 6217.5718 | I17: 64 | J17: 6240 | K17: =IF(INT(J17/3600/24)=0,"",INT(J17/3600/24)&"D")&IF(INT(MOD(J17,3600*24)/3600)=0,"",INT(MOD(J17,3600*24)/3600)&"H")&IF(INT(MOD(J17,3600)/60)=0,"",INT(MOD(J17,3600)/60)&"M")&IF(MOD(J17,60)=0,"",INT(MOD(J17,60))&"S") -> 1H44M | L17: =J17*1000/60 -> 104000 | M17: =ROUND(0*A17*A17+120*A17,0) -> 1800 | N17: =I17*M17 -> 115200 | O17: =U17/3 -> 66990.299 | P17: =J17*13 -> 81120 | Q17: =IF(INT(P17/3600/24)=0,"",INT(P17/3600/24)&"D")&IF(INT(MOD(P17,3600*24)/3600)=0,"",INT(MOD(P17,3600*24)/3600)&"H")&IF(INT(MOD(P17,3600)/60)=0,"",INT(MOD(P17,3600)/60)&"M")&IF(MOD(P17,60)=0,"",INT(MOD(P17,60))&"S") -> 22H32M | R17: =L17*13 -> 1352000 | S17: =M17*13 -> 23400 | T17: =N17*13 -> 1497600 | U17: =AB17*'reward percentage'!$B$3 -> 200970.9 | V17: =P17*1.5 -> 121680 | W17: =IF(INT(V17/3600/24)=0,"",INT(V17/3600/24)&"D")&IF(INT(MOD(V17,3600*24)/3600)=0,"",INT(MOD(V17,3600*24)/3600)&"H")&IF(INT(MOD(V17,3600)/60)=0,"",INT(MOD(V17,3600)/60)&"M")&IF(MOD(V17,60)=0,"",INT(MOD(V17,60))&"S") -> 1D9H48M | X17: =R17*3 -> 4056000 | Y17: =S17 -> 23400 | Z17: =T17 -> 1497600 | AA17: =AA16+29575 -> 570050 | AB17: =AC17-AD17 -> 2009709 | AC17: =X17*B17 -> 2774265 | AD17: =(Y17+Y16)/2*V17/3600 -> 764556 | AE17: =AA17/Z17 -> 0.38064236 | AF17: 0.68399038 | AG17: =AD17/X17 -> 0.1885
A18: 16 | B18: =EXP($S$38*(A18-10)) -> 0.63395728 | C18: 0.328 | D18: =SUM($C$3:C18) -> 4.92 | E18: =F18/60 -> 2.2833769 | F18: =EXP(D18) -> 137.00261 | G18: =F18*60 -> 8220.1568 | H18: =G18*'Research Enhancing'!C17 -> 8795.5678 | I18: 65 | J18: 8820 | K18: =IF(INT(J18/3600/24)=0,"",INT(J18/3600/24)&"D")&IF(INT(MOD(J18,3600*24)/3600)=0,"",INT(MOD(J18,3600*24)/3600)&"H")&IF(INT(MOD(J18,3600)/60)=0,"",INT(MOD(J18,3600)/60)&"M")&IF(MOD(J18,60)=0,"",INT(MOD(J18,60))&"S") -> 2H27M | L18: =J18*1000/60 -> 147000 | M18: =ROUND(0*A18*A18+120*A18,0) -> 1920 | N18: =I18*M18 -> 124800 | O18: =U18/3 -> 82642.586 | P18: =J18*13 -> 114660 | Q18: =IF(INT(P18/3600/24)=0,"",INT(P18/3600/24)&"D")&IF(INT(MOD(P18,3600*24)/3600)=0,"",INT(MOD(P18,3600*24)/3600)&"H")&IF(INT(MOD(P18,3600)/60)=0,"",INT(MOD(P18,3600)/60)&"M")&IF(MOD(P18,60)=0,"",INT(MOD(P18,60))&"S") -> 1D7H51M | R18: =L18*13 -> 1911000 | S18: =M18*13 -> 24960 | T18: =N18*13 -> 1622400 | U18: =AB18*'reward percentage'!$B$3 -> 247927.76 | V18: =P18*1.5 -> 171990 | W18: =IF(INT(V18/3600/24)=0,"",INT(V18/3600/24)&"D")&IF(INT(MOD(V18,3600*24)/3600)=0,"",INT(MOD(V18,3600*24)/3600)&"H")&IF(INT(MOD(V18,3600)/60)=0,"",INT(MOD(V18,3600)/60)&"M")&IF(MOD(V18,60)=0,"",INT(MOD(V18,60))&"S") -> 1D23H46M30S | X18: =R18*3 -> 5733000 | Y18: =S18 -> 24960 | Z18: =T18 -> 1622400 | AA18: =AA17+29575 -> 599625 | AB18: =AC18-AD18 -> 2479277.6 | AC18: =X18*B18 -> 3634477.1 | AD18: =(Y18+Y17)/2*V18/3600 -> 1155199.5 | AE18: =AA18/Z18 -> 0.36959135 | AF18: 0.63395728 | AG18: =AD18/X18 -> 0.2015
A19: 17 | B19: =EXP($S$38*(A19-10)) -> 0.58758404 | C19: 0.328 | D19: =SUM($C$3:C19) -> 5.248 | E19: =F19/60 -> 3.1697586 | F19: =EXP(D19) -> 190.18552 | G19: =F19*60 -> 11411.131 | H19: =G19*'Research Enhancing'!C18 -> 12209.91 | I19: 66 | J19: 12240 | K19: =IF(INT(J19/3600/24)=0,"",INT(J19/3600/24)&"D")&IF(INT(MOD(J19,3600*24)/3600)=0,"",INT(MOD(J19,3600*24)/3600)&"H")&IF(INT(MOD(J19,3600)/60)=0,"",INT(MOD(J19,3600)/60)&"M")&IF(MOD(J19,60)=0,"",INT(MOD(J19,60))&"S") -> 3H24M | L19: =J19*1000/60 -> 204000 | M19: =ROUND(0*A19*A19+120*A19,0) -> 2040 | N19: =I19*M19 -> 134640 | O19: =U19/3 -> 98941.887 | P19: =J19*13 -> 159120 | Q19: =IF(INT(P19/3600/24)=0,"",INT(P19/3600/24)&"D")&IF(INT(MOD(P19,3600*24)/3600)=0,"",INT(MOD(P19,3600*24)/3600)&"H")&IF(INT(MOD(P19,3600)/60)=0,"",INT(MOD(P19,3600)/60)&"M")&IF(MOD(P19,60)=0,"",INT(MOD(P19,60))&"S") -> 1D20H12M | R19: =L19*13 -> 2652000 | S19: =M19*13 -> 26520 | T19: =N19*13 -> 1750320 | U19: =AB19*'reward percentage'!$B$3 -> 296825.66 | V19: =P19*1.5 -> 238680 | W19: =IF(INT(V19/3600/24)=0,"",INT(V19/3600/24)&"D")&IF(INT(MOD(V19,3600*24)/3600)=0,"",INT(MOD(V19,3600*24)/3600)&"H")&IF(INT(MOD(V19,3600)/60)=0,"",INT(MOD(V19,3600)/60)&"M")&IF(MOD(V19,60)=0,"",INT(MOD(V19,60))&"S") -> 2D18H18M | X19: =R19*3 -> 7956000 | Y19: =S19 -> 26520 | Z19: =T19 -> 1750320 | AA19: =AA18+29575 -> 629200 | AB19: =AC19-AD19 -> 2968256.6 | AC19: =X19*B19 -> 4674818.6 | AD19: =(Y19+Y18)/2*V19/3600 -> 1706562 | AE19: =AA19/Z19 -> 0.35947712 | AF19: 0.58758404 | AG19: =AD19/X19 -> 0.2145
A20: 18 | B20: =EXP($S$38*(A20-10)) -> 0.54460295 | C20: 0.328 | D20: =SUM($C$3:C20) -> 5.576 | E20: =F20/60 -> 4.400224 | F20: =EXP(D20) -> 264.01344 | G20: =F20*60 -> 15840.806 | H20: =G20*'Research Enhancing'!C19 -> 16949.663 | I20: 67 | J20: 15900 | K20: =IF(INT(J20/3600/24)=0,"",INT(J20/3600/24)&"D")&IF(INT(MOD(J20,3600*24)/3600)=0,"",INT(MOD(J20,3600*24)/3600)&"H")&IF(INT(MOD(J20,3600)/60)=0,"",INT(MOD(J20,3600)/60)&"M")&IF(MOD(J20,60)=0,"",INT(MOD(J20,60))&"S") -> 4H25M | L20: =J20*1000/60 -> 265000 | M20: =ROUND(0*A20*A20+120*A20,0) -> 2160 | N20: =I20*M20 -> 144720 | O20: =U20/3 -> 109241.97 | P20: =J20*13 -> 206700 | Q20: =IF(INT(P20/3600/24)=0,"",INT(P20/3600/24)&"D")&IF(INT(MOD(P20,3600*24)/3600)=0,"",INT(MOD(P20,3600*24)/3600)&"H")&IF(INT(MOD(P20,3600)/60)=0,"",INT(MOD(P20,3600)/60)&"M")&IF(MOD(P20,60)=0,"",INT(MOD(P20,60))&"S") -> 2D9H25M | R20: =L20*13 -> 3445000 | S20: =M20*13 -> 28080 | T20: =N20*13 -> 1881360 | U20: =AB20*'reward percentage'!$B$3 -> 327725.9 | V20: =P20*1.5 -> 310050 | W20: =IF(INT(V20/3600/24)=0,"",INT(V20/3600/24)&"D")&IF(INT(MOD(V20,3600*24)/3600)=0,"",INT(MOD(V20,3600*24)/3600)&"H")&IF(INT(MOD(V20,3600)/60)=0,"",INT(MOD(V20,3600)/60)&"M")&IF(MOD(V20,60)=0,"",INT(MOD(V20,60))&"S") -> 3D14H7M30S | X20: =R20*3 -> 10335000 | Y20: =S20 -> 28080 | Z20: =T20 -> 1881360 | AA20: =AA19+29575 -> 658775 | AB20: =AC20-AD20 -> 3277259 | AC20: =X20*B20 -> 5628471.5 | AD20: =(Y20+Y19)/2*V20/3600 -> 2351212.5 | AE20: =AA20/Z20 -> 0.35015893 | AF20: 0.54460295 | AG20: =AD20/X20 -> 0.2275
A21: 19 | B21: =EXP($S$38*(A21-10)) -> 0.50476588 | C21: 0.328 | D21: =SUM($C$3:C21) -> 5.904 | E21: =F21/60 -> 6.1083424 | F21: =EXP(D21) -> 366.50054 | G21: =F21*60 -> 21990.033 | H21: =G21*'Research Enhancing'!C20 -> 23969.135 | I21: 68 | J21: 24000 | K21: =IF(INT(J21/3600/24)=0,"",INT(J21/3600/24)&"D")&IF(INT(MOD(J21,3600*24)/3600)=0,"",INT(MOD(J21,3600*24)/3600)&"H")&IF(INT(MOD(J21,3600)/60)=0,"",INT(MOD(J21,3600)/60)&"M")&IF(MOD(J21,60)=0,"",INT(MOD(J21,60))&"S") -> 6H40M | L21: =J21*1000/60 -> 400000 | M21: =ROUND(0*A21*A21+120*A21,0) -> 2280 | N21: =I21*M21 -> 155040 | O21: =U21/3 -> 137418.26 | P21: =J21*13 -> 312000 | Q21: =IF(INT(P21/3600/24)=0,"",INT(P21/3600/24)&"D")&IF(INT(MOD(P21,3600*24)/3600)=0,"",INT(MOD(P21,3600*24)/3600)&"H")&IF(INT(MOD(P21,3600)/60)=0,"",INT(MOD(P21,3600)/60)&"M")&IF(MOD(P21,60)=0,"",INT(MOD(P21,60))&"S") -> 3D14H40M | R21: =L21*13 -> 5200000 | S21: =M21*13 -> 29640 | T21: =N21*13 -> 2015520 | U21: =AB21*'reward percentage'!$B$3 -> 412254.77 | V21: =P21*1.5 -> 468000 | W21: =IF(INT(V21/3600/24)=0,"",INT(V21/3600/24)&"D")&IF(INT(MOD(V21,3600*24)/3600)=0,"",INT(MOD(V21,3600*24)/3600)&"H")&IF(INT(MOD(V21,3600)/60)=0,"",INT(MOD(V21,3600)/60)&"M")&IF(MOD(V21,60)=0,"",INT(MOD(V21,60))&"S") -> 5D10H | X21: =R21*3 -> 15600000 | Y21: =S21 -> 29640 | Z21: =T21 -> 2015520 | AA21: =AA20+29575 -> 688350 | AB21: =AC21-AD21 -> 4122547.7 | AC21: =X21*B21 -> 7874347.7 | AD21: =(Y21+Y20)/2*V21/3600 -> 3751800 | AE21: =AA21/Z21 -> 0.34152477 | AF21: 0.50476588 | AG21: =AD21/X21 -> 0.2405
A22: 20 | B22: =EXP($S$38*(A22-10)) -> 0.46784284 | C22: 0.328 | D22: =SUM($C$3:C22) -> 6.232 | E22: =F22/60 -> 8.4795335 | F22: =EXP(D22) -> 508.77201 | G22: =F22*60 -> 30526.321 | H22: =G22*'Research Enhancing'!C21 -> 33273.689 | I22: 69 | J22: 33300 | K22: =IF(INT(J22/3600/24)=0,"",INT(J22/3600/24)&"D")&IF(INT(MOD(J22,3600*24)/3600)=0,"",INT(MOD(J22,3600*24)/3600)&"H")&IF(INT(MOD(J22,3600)/60)=0,"",INT(MOD(J22,3600)/60)&"M")&IF(MOD(J22,60)=0,"",INT(MOD(J22,60))&"S") -> 9H15M | L22: =J22*1000/60 -> 555000 | M22: =ROUND(0*A22*A22+120*A22,0) -> 2400 | N22: =I22*M22 -> 165600 | O22: =U22/3 -> 154648.36 | P22: =J22*13 -> 432900 | Q22: =IF(INT(P22/3600/24)=0,"",INT(P22/3600/24)&"D")&IF(INT(MOD(P22,3600*24)/3600)=0,"",INT(MOD(P22,3600*24)/3600)&"H")&IF(INT(MOD(P22,3600)/60)=0,"",INT(MOD(P22,3600)/60)&"M")&IF(MOD(P22,60)=0,"",INT(MOD(P22,60))&"S") -> 5D15M | R22: =L22*13 -> 7215000 | S22: =M22*13 -> 31200 | T22: =N22*13 -> 2152800 | U22: =AB22*'reward percentage'!$B$3 -> 463945.07 | V22: =P22*1.5 -> 649350 | W22: =IF(INT(V22/3600/24)=0,"",INT(V22/3600/24)&"D")&IF(INT(MOD(V22,3600*24)/3600)=0,"",INT(MOD(V22,3600*24)/3600)&"H")&IF(INT(MOD(V22,3600)/60)=0,"",INT(MOD(V22,3600)/60)&"M")&IF(MOD(V22,60)=0,"",INT(MOD(V22,60))&"S") -> 7D12H22M30S | X22: =R22*3 -> 21645000 | Y22: =S22 -> 31200 | Z22: =T22 -> 2152800 | AA22: =AA21+29575 -> 717925 | AB22: =AC22-AD22 -> 4639450.7 | AC22: =X22*B22 -> 10126458 | AD22: =(Y22+Y21)/2*V22/3600 -> 5487007.5 | AE22: =AA22/Z22 -> 0.3334843 | AF22: 0.46784284 | AG22: =AD22/X22 -> 0.2535
A23: 21 | B23: =EXP($S$38*(A23-10)) -> 0.43362068 | C23: 0.328 | D23: =SUM($C$3:C23) -> 6.56 | E23: =F23/60 -> 11.771195 | F23: =EXP(D23) -> 706.27169 | G23: =F23*60 -> 42376.302 | H23: =G23*'Research Enhancing'!C22 -> 46190.169 | I23: 70 | J23: 46200 | K23: =IF(INT(J23/3600/24)=0,"",INT(J23/3600/24)&"D")&IF(INT(MOD(J23,3600*24)/3600)=0,"",INT(MOD(J23,3600*24)/3600)&"H")&IF(INT(MOD(J23,3600)/60)=0,"",INT(MOD(J23,3600)/60)&"M")&IF(MOD(J23,60)=0,"",INT(MOD(J23,60))&"S") -> 12H50M | L23: =J23*1000/60 -> 770000 | M23: =ROUND(0*A23*A23+120*A23,0) -> 2520 | N23: =I23*M23 -> 176400 | O23: =U23/3 -> 167287.8 | P23: =J23*13 -> 600600 | Q23: =IF(INT(P23/3600/24)=0,"",INT(P23/3600/24)&"D")&IF(INT(MOD(P23,3600*24)/3600)=0,"",INT(MOD(P23,3600*24)/3600)&"H")&IF(INT(MOD(P23,3600)/60)=0,"",INT(MOD(P23,3600)/60)&"M")&IF(MOD(P23,60)=0,"",INT(MOD(P23,60))&"S") -> 6D22H50M | R23: =L23*13 -> 10010000 | S23: =M23*13 -> 32760 | T23: =N23*13 -> 2293200 | U23: =AB23*'reward percentage'!$B$3 -> 501863.4 | V23: =P23*1.5 -> 900900 | W23: =IF(INT(V23/3600/24)=0,"",INT(V23/3600/24)&"D")&IF(INT(MOD(V23,3600*24)/3600)=0,"",INT(MOD(V23,3600*24)/3600)&"H")&IF(INT(MOD(V23,3600)/60)=0,"",INT(MOD(V23,3600)/60)&"M")&IF(MOD(V23,60)=0,"",INT(MOD(V23,60))&"S") -> 10D10H15M | X23: =R23*3 -> 30030000 | Y23: =S23 -> 32760 | Z23: =T23 -> 2293200 | AA23: =AA22+29575 -> 747500 | AB23: =AC23-AD23 -> 5018634 | AC23: =X23*B23 -> 13021629 | AD23: =(Y23+Y22)/2*V23/3600 -> 8002995 | AE23: =AA23/Z23 -> 0.32596372 | AF23: 0.43362068 | AG23: =AD23/X23 -> 0.2665
A24: 22 | B24: =EXP($S$38*(A24-10)) -> 0.40190183 | C24: 0.328 | D24: =SUM($C$3:C24) -> 6.888 | E24: =F24/60 -> 16.340643 | F24: =EXP(D24) -> 980.43858 | G24: =F24*60 -> 58826.315 | H24: =G24*'Research Enhancing'!C23 -> 65885.472 | I24: 71 | J24: 66000 | K24: =IF(INT(J24/3600/24)=0,"",INT(J24/3600/24)&"D")&IF(INT(MOD(J24,3600*24)/3600)=0,"",INT(MOD(J24,3600*24)/3600)&"H")&IF(INT(MOD(J24,3600)/60)=0,"",INT(MOD(J24,3600)/60)&"M")&IF(MOD(J24,60)=0,"",INT(MOD(J24,60))&"S") -> 18H20M | L24: =J24*1000/60 -> 1100000 | M24: =ROUND(0*A24*A24+120*A24,0) -> 2640 | N24: =I24*M24 -> 187440 | O24: =U24/3 -> 175034.62 | P24: =J24*13 -> 858000 | Q24: =IF(INT(P24/3600/24)=0,"",INT(P24/3600/24)&"D")&IF(INT(MOD(P24,3600*24)/3600)=0,"",INT(MOD(P24,3600*24)/3600)&"H")&IF(INT(MOD(P24,3600)/60)=0,"",INT(MOD(P24,3600)/60)&"M")&IF(MOD(P24,60)=0,"",INT(MOD(P24,60))&"S") -> 9D22H20M | R24: =L24*13 -> 14300000 | S24: =M24*13 -> 34320 | T24: =N24*13 -> 2436720 | U24: =AB24*'reward percentage'!$B$3 -> 525103.85 | V24: =P24*1.5 -> 1287000 | W24: =IF(INT(V24/3600/24)=0,"",INT(V24/3600/24)&"D")&IF(INT(MOD(V24,3600*24)/3600)=0,"",INT(MOD(V24,3600*24)/3600)&"H")&IF(INT(MOD(V24,3600)/60)=0,"",INT(MOD(V24,3600)/60)&"M")&IF(MOD(V24,60)=0,"",INT(MOD(V24,60))&"S") -> 14D21H30M | X24: =R24*3 -> 42900000 | Y24: =S24 -> 34320 | Z24: =T24 -> 2436720 | AA24: =AA23+29575 -> 777075 | AB24: =AC24-AD24 -> 5251038.5 | AC24: =X24*B24 -> 17241588 | AD24: =(Y24+Y23)/2*V24/3600 -> 11990550 | AE24: =AA24/Z24 -> 0.31890205 | AF24: 0.40190183 | AG24: =AD24/X24 -> 0.2795
... A26: 24 | B26: =EXP($S$38*(A26-10)) -> 0.345255 | C26: 0.328 | D26: =SUM($C$3:C26) -> 7.544 | E26: =F26/60 -> 31.48954 | F26: =EXP(D26) -> 1889.3724 | G26: =F26*60 -> 113362.35 | H26: =G26*'Research Enhancing'!C25 -> 126965.83 | I26: 73 | J26: 129600 | K26: =IF(INT(J26/3600/24)=0,"",INT(J26/3600/24)&"D")&IF(INT(MOD(J26,3600*24)/3600)=0,"",INT(MOD(J26,3600*24)/3600)&"H")&IF(INT(MOD(J26,3600)/60)=0,"",INT(MOD(J26,3600)/60)&"M")&IF(MOD(J26,60)=0,"",INT(MOD(J26,60))&"S") -> 1D12H | L26: =J26*1000/60 -> 2160000 | M26: =ROUND(0*A26*A26+120*A26,0) -> 2880 | N26: =I26*M26 -> 210240 | O26: =U26/3 -> 111632.05 | P26: =J26*13 -> 1684800 | Q26: =IF(INT(P26/3600/24)=0,"",INT(P26/3600/24)&"D")&IF(INT(MOD(P26,3600*24)/3600)=0,"",INT(MOD(P26,3600*24)/3600)&"H")&IF(INT(MOD(P26,3600)/60)=0,"",INT(MOD(P26,3600)/60)&"M")&IF(MOD(P26,60)=0,"",INT(MOD(P26,60))&"S") -> 19D12H | R26: =L26*13 -> 28080000 | S26: =M26*13 -> 37440 | T26: =N26*13 -> 2733120 | U26: =AB26*'reward percentage'!$B$3 -> 334896.14 | V26: =P26*1.5 -> 2527200 | W26: =IF(INT(V26/3600/24)=0,"",INT(V26/3600/24)&"D")&IF(INT(MOD(V26,3600*24)/3600)=0,"",INT(MOD(V26,3600*24)/3600)&"H")&IF(INT(MOD(V26,3600)/60)=0,"",INT(MOD(V26,3600)/60)&"M")&IF(MOD(V26,60)=0,"",INT(MOD(V26,60))&"S") -> 29D6H | X26: =R26*3 -> 84240000 | Y26: =S26 -> 37440 | Z26: =T26 -> 2733120 | AA26: =AA25+29575 -> 836225 | AB26: =AC26-AD26 -> 3348961.4 | AC26: =X26*B26 -> 29084281 | AD26: =(Y26+Y25)/2*V26/3600 -> 25735320 | AE26: =AA26/Z26 -> 0.30595986 | AF26: 0.345255 | AG26: =AD26/X26 -> 0.3055
A27: 25 | B27: =EXP($S$38*(A27-10)) -> 0.32 | C27: 0.328 | D27: =SUM($C$3:C27) -> 7.872 | E27: =F27/60 -> 43.713433 | F27: =EXP(D27) -> 2622.806 | G27: =F27*60 -> 157368.36 | H27: =G27*'Research Enhancing'!C26 -> 180973.61 | I27: 74 | J27: 180000 | K27: =IF(INT(J27/3600/24)=0,"",INT(J27/3600/24)&"D")&IF(INT(MOD(J27,3600*24)/3600)=0,"",INT(MOD(J27,3600*24)/3600)&"H")&IF(INT(MOD(J27,3600)/60)=0,"",INT(MOD(J27,3600)/60)&"M")&IF(MOD(J27,60)=0,"",INT(MOD(J27,60))&"S") -> 2D2H | L27: =J27*1000/60 -> 3000000 | M27: =ROUND(0*A27*A27+120*A27,0) -> 3000 | N27: =I27*M27 -> 222000 | O27: =U27/3 -> 5850 | P27: =J27*13 -> 2340000 | Q27: =IF(INT(P27/3600/24)=0,"",INT(P27/3600/24)&"D")&IF(INT(MOD(P27,3600*24)/3600)=0,"",INT(MOD(P27,3600*24)/3600)&"H")&IF(INT(MOD(P27,3600)/60)=0,"",INT(MOD(P27,3600)/60)&"M")&IF(MOD(P27,60)=0,"",INT(MOD(P27,60))&"S") -> 27D2H | R27: =L27*13 -> 39000000 | S27: =M27*13 -> 39000 | T27: =N27*13 -> 2886000 | U27: =AB27*'reward percentage'!$B$3 -> 17550 | V27: =P27*1.5 -> 3510000 | W27: =IF(INT(V27/3600/24)=0,"",INT(V27/3600/24)&"D")&IF(INT(MOD(V27,3600*24)/3600)=0,"",INT(MOD(V27,3600*24)/3600)&"H")&IF(INT(MOD(V27,3600)/60)=0,"",INT(MOD(V27,3600)/60)&"M")&IF(MOD(V27,60)=0,"",INT(MOD(V27,60))&"S") -> 40D15H | X27: =R27*3 -> 117000000 | Y27: =S27 -> 39000 | Z27: =T27 -> 2886000 | AA27: 865800 | AB27: =AC27-AD27 -> 175500 | AC27: =X27*B27 -> 37440000 | AD27: =(Y27+Y26)/2*V27/3600 -> 37264500 | AE27: =AA27/Z27 -> 0.3 | AF27: 0.32 | AG27: =AD27/X27 -> 0.3185
A28: total | E28: =SUM(E3:E27) -> 156.27914 | F28: =SUM(F3:F27) -> 9376.7484 | G28: =SUM(G3:G27) -> 562604.9 | J28: =SUM(J3:J27) -> 628090 | K28: =IF(INT(J28/3600/24)=0,"",INT(J28/3600/24)&"D")&IF(INT(MOD(J28,3600*24)/3600)=0,"",INT(MOD(J28,3600*24)/3600)&"H")&IF(INT(MOD(J28,3600)/60)=0,"",INT(MOD(J28,3600)/60)&"M")&IF(MOD(J28,60)=0,"",INT(MOD(J28,60))&"S") -> 7D6H28M10S | L28: =SUM(L3:L27) -> 10468167 | O28: =SUM(O3:O27) -> 1608694.2 | P28: =SUM(P3:P27) -> 8165170 | Q28: =IF(INT(P28/3600/24)=0,"",INT(P28/3600/24)&"D")&IF(INT(MOD(P28,3600*24)/3600)=0,"",INT(MOD(P28,3600*24)/3600)&"H")&IF(INT(MOD(P28,3600)/60)=0,"",INT(MOD(P28,3600)/60)&"M")&IF(MOD(P28,60)=0,"",INT(MOD(P28,60))&"S") -> 94D12H6M10S | R28: =SUM(R3:R27) -> 1.3608617e+08 | U28: =SUM(U3:U27) -> 4826082.7 | V28: =SUM(V3:V27) -> 12247755 | W28: =IF(INT(V28/3600/24)=0,"",INT(V28/3600/24)&"D")&IF(INT(MOD(V28,3600*24)/3600)=0,"",INT(MOD(V28,3600*24)/3600)&"H")&IF(INT(MOD(V28,3600)/60)=0,"",INT(MOD(V28,3600)/60)&"M")&IF(MOD(V28,60)=0,"",INT(MOD(V28,60))&"S") -> 141D18H9M15S | X28: =R28*3 -> 4.082585e+08 | AB28: =SUM(AB3:AB27) -> 48260827 | AC28: =SUM(AC3:AC27) -> 1.6506209e+08 | AD28: =SUM(AD3:AD27) -> 1.1680127e+08
J31: =J28/3600/24 -> 7.2695602
K32: =EXP(0.3277) -> 1.3877726
Y33: =X27/Y27 -> 3000
S37: =LN(0.32) -> -1.1394343 | Y37: =LN(0.25) -> -1.3862944
S38: =S37/15 -> -0.075962286 | Y38: =Y37/15 -> -0.092419624
Q39: =LN(40)/29 -> 0.12720274 | W39: =LN(40)/29 -> 0.12720274
Q40: =EXP(Q39) -> 1.1356472 | S40: =LN(10)/9 -> 0.25584279 | W40: =EXP(W39) -> 1.1356472 | Y40: =LN(10)/9 -> 0.25584279

Sheet table (after research)
B1: for each resource building | H1: for resource buildings total | N1: for all buildings total
A2: level | B2: level duration (sec) | C2: level time | D2: resource needed | E2: resource output/hour | F2: Capacity | G2: resource reward | H2: level duration (sec) | I2: level time | J2: resource needed | K2: resource output/hour | L2: Capacity | M2: resource reward | N2: level duration (sec) | O2: level time | P2: resource needed | Q2: resource output/hour | R2: Capacity | S2: protection limit | T2: resource reward | U2: resource gained | V2: resource output in this level | W2: protection proportion | X2: gained/cost （resource） | Y2: output/ needed (resources)
A3: 1 | B3: ='table (no research)'!J3/'Research Enhancing'!C2 -> 59.405941 | C3: =IF(INT(B3/3600/24)=0,"",INT(B3/3600/24)&"D")&IF(INT(MOD(B3,3600*24)/3600)=0,"",INT(MOD(B3,3600*24)/3600)&"H")&IF(INT(MOD(B3,3600)/60)=0,"",INT(MOD(B3,3600)/60)&"M")&IF(MOD(B3,60)=0,"",INT(MOD(B3,60))&"S") -> 59S | D3: 1000 | E3: ='table (no research)'!M3*'Research Enhancing'!C2 -> 121.2 | F3: ='table (no research)'!N3*'Research Enhancing'!C2 -> 6060 | G3: ='table (no research)'!O3 -> 12983.1 | H3: =B3*13 -> 772.27723 | I3: =IF(INT(H3/3600/24)=0,"",INT(H3/3600/24)&"D")&IF(INT(MOD(H3,3600*24)/3600)=0,"",INT(MOD(H3,3600*24)/3600)&"H")&IF(INT(MOD(H3,3600)/60)=0,"",INT(MOD(H3,3600)/60)&"M")&IF(MOD(H3,60)=0,"",INT(MOD(H3,60))&"S") -> 12M52S | J3: =D3*13 -> 13000 | K3: =E3*13 -> 1575.6 | L3: =F3*13 -> 78780 | M3: ='table (no research)'!U3 -> 38949.3 | N3: =H3*1.5 -> 1158.4158 | O3: =IF(INT(N3/3600/24)=0,"",INT(N3/3600/24)&"D")&IF(INT(MOD(N3,3600*24)/3600)=0,"",INT(MOD(N3,3600*24)/3600)&"H")&IF(INT(MOD(N3,3600)/60)=0,"",INT(MOD(N3,3600)/60)&"M")&IF(MOD(N3,60)=0,"",INT(MOD(N3,60))&"S") -> 19M18S | P3: =J3*3 -> 39000 | Q3: =K3 -> 1575.6 | R3: =L3 -> 78780 | S3: ='table (no research)'!AA3*'Research Enhancing'!C2 -> 157560 | T3: ='table (no research)'!AB3 -> 389493 | U3: =T3+V3 -> 390000 | V3: =Q3*N3/3600 -> 507 | W3: =S3/R3 -> 2 | X3: =U3/P3 -> 10 | Y3: =V3/P3 -> 0.013
A4: 2 | B4: ='table (no research)'!J4/'Research Enhancing'!C3 -> 79.207921 | C4: =IF(INT(B4/3600/24)=0,"",INT(B4/3600/24)&"D")&IF(INT(MOD(B4,3600*24)/3600)=0,"",INT(MOD(B4,3600*24)/3600)&"H")&IF(INT(MOD(B4,3600)/60)=0,"",INT(MOD(B4,3600)/60)&"M")&IF(MOD(B4,60)=0,"",INT(MOD(B4,60))&"S") -> 1M19S | D4: =B4*1000/60 -> 1320.132 | E4: ='table (no research)'!M4*'Research Enhancing'!C3 -> 242.4 | F4: ='table (no research)'!N4*'Research Enhancing'!C3 -> 12362.4 | G4: ='table (no research)'!O4 -> 13386.77 | H4: =B4*13 -> 1029.703 | I4: =IF(INT(H4/3600/24)=0,"",INT(H4/3600/24)&"D")&IF(INT(MOD(H4,3600*24)/3600)=0,"",INT(MOD(H4,3600*24)/3600)&"H")&IF(INT(MOD(H4,3600)/60)=0,"",INT(MOD(H4,3600)/60)&"M")&IF(MOD(H4,60)=0,"",INT(MOD(H4,60))&"S") -> 17M9S | J4: =D4*13 -> 17161.716 | K4: =E4*13 -> 3151.2 | L4: =F4*13 -> 160711.2 | M4: ='table (no research)'!U4 -> 40160.311 | N4: =H4*1.5 -> 1544.5545 | O4: =IF(INT(N4/3600/24)=0,"",INT(N4/3600/24)&"D")&IF(INT(MOD(N4,3600*24)/3600)=0,"",INT(MOD(N4,3600*24)/3600)&"H")&IF(INT(MOD(N4,3600)/60)=0,"",INT(MOD(N4,3600)/60)&"M")&IF(MOD(N4,60)=0,"",INT(MOD(N4,60))&"S") -> 25M44S | P4: =J4*3 -> 51485.149 | Q4: =K4 -> 3151.2 | R4: =L4 -> 160711.2 | S4: ='table (no research)'!AA4*'Research Enhancing'!C3 -> 187430.75 | T4: ='table (no research)'!AB4 -> 401603.11 | U4: =T4+V4 -> 402617.11 | V4: =(Q4+Q3)/2*N4/3600 -> 1014 | W4: =S4/R4 -> 1.1662582 | X4: =U4/P4 -> 7.8200632 | Y4: =V4/P4 -> 0.019695
A5: 3 | B5: ='table (no research)'!J5/'Research Enhancing'!C4 -> 118.81188 | C5: =IF(INT(B5/3600/24)=0,"",INT(B5/3600/24)&"D")&IF(INT(MOD(B5,3600*24)/3600)=0,"",INT(MOD(B5,3600*24)/3600)&"H")&IF(INT(MOD(B5,3600)/60)=0,"",INT(MOD(B5,3600)/60)&"M")&IF(MOD(B5,60)=0,"",INT(MOD(B5,60))&"S") -> 1M58S | D5: =B5*1000/60 -> 1980.198 | E5: ='table (no research)'!M5*'Research Enhancing'!C4 -> 363.6 | F5: ='table (no research)'!N5*'Research Enhancing'!C4 -> 18907.2 | G5: ='table (no research)'!O5 -> 15502.091 | H5: =B5*13 -> 1544.5545 | I5: =IF(INT(H5/3600/24)=0,"",INT(H5/3600/24)&"D")&IF(INT(MOD(H5,3600*24)/3600)=0,"",INT(MOD(H5,3600*24)/3600)&"H")&IF(INT(MOD(H5,3600)/60)=0,"",INT(MOD(H5,3600)/60)&"M")&IF(MOD(H5,60)=0,"",INT(MOD(H5,60))&"S") -> 25M44S | J5: =D5*13 -> 25742.574 | K5: =E5*13 -> 4726.8 | L5: =F5*13 -> 245793.6 | M5: ='table (no research)'!U5 -> 46506.272 | N5: =H5*1.5 -> 2316.8317 | O5: =IF(INT(N5/3600/24)=0,"",INT(N5/3600/24)&"D")&IF(INT(MOD(N5,3600*24)/3600)=0,"",INT(MOD(N5,3600*24)/3600)&"H")&IF(INT(MOD(N5,3600)/60)=0,"",INT(MOD(N5,3600)/60)&"M")&IF(MOD(N5,60)=0,"",INT(MOD(N5,60))&"S") -> 38M36S | P5: =J5*3 -> 77227.723 | Q5: =K5 -> 4726.8 | R5: =L5 -> 245793.6 | S5: ='table (no research)'!AA5*'Research Enhancing'!C4 -> 217301.5 | T5: ='table (no research)'!AB5 -> 465062.72 | U5: =T5+V5 -> 467597.72 | V5: =(Q5+Q4)/2*N5/3600 -> 2535 | W5: =S5/R5 -> 0.8840812 | X5: =U5/P5 -> 6.0547909 | Y5: =V5/P5 -> 0.032825
A6: 4 | B6: ='table (no research)'!J6/'Research Enhancing'!C5 -> 156.86275 | C6: =IF(INT(B6/3600/24)=0,"",INT(B6/3600/24)&"D")&IF(INT(MOD(B6,3600*24)/3600)=0,"",INT(MOD(B6,3600*24)/3600)&"H")&IF(INT(MOD(B6,3600)/60)=0,"",INT(MOD(B6,3600)/60)&"M")&IF(MOD(B6,60)=0,"",INT(MOD(B6,60))&"S") -> 2M36S | D6: =B6*1000/60 -> 2614.3791 | E6: ='table (no research)'!M6*'Research Enhancing'!C5 -> 489.6 | F6: ='table (no research)'!N6*'Research Enhancing'!C5 -> 25948.8 | G6: ='table (no research)'!O6 -> 15933.108 | H6: =B6*13 -> 2039.2157 | I6: =IF(INT(H6/3600/24)=0,"",INT(H6/3600/24)&"D")&IF(INT(MOD(H6,3600*24)/3600)=0,"",INT(MOD(H6,3600*24)/3600)&"H")&IF(INT(MOD(H6,3600)/60)=0,"",INT(MOD(H6,3600)/60)&"M")&IF(MOD(H6,60)=0,"",INT(MOD(H6,60))&"S") -> 33M59S | J6: =D6*13 -> 33986.928 | K6: =E6*13 -> 6364.8 | L6: =F6*13 -> 337334.4 | M6: ='table (no research)'!U6 -> 47799.324 | N6: =H6*1.5 -> 3058.8235 | O6: =IF(INT(N6/3600/24)=0,"",INT(N6/3600/24)&"D")&IF(INT(MOD(N6,3600*24)/3600)=0,"",INT(MOD(N6,3600*24)/3600)&"H")&IF(INT(MOD(N6,3600)/60)=0,"",INT(MOD(N6,3600)/60)&"M")&IF(MOD(N6,60)=0,"",INT(MOD(N6,60))&"S") -> 50M58S | P6: =J6*3 -> 101960.78 | Q6: =K6 -> 6364.8 | R6: =L6 -> 337334.4 | S6: ='table (no research)'!AA6*'Research Enhancing'!C5 -> 249619.5 | T6: ='table (no research)'!AB6 -> 477993.24 | U6: =T6+V6 -> 482705.36 | V6: =(Q6+Q5)/2*N6/3600 -> 4712.1176 | W6: =S6/R6 -> 0.73997642 | X6: =U6/P6 -> 4.7342256 | Y6: =V6/P6 -> 0.046215
A7: 5 | B7: ='table (no research)'!J7/'Research Enhancing'!C6 -> 235.29412 | C7: =IF(INT(B7/3600/24)=0,"",INT(B7/3600/24)&"D")&IF(INT(MOD(B7,3600*24)/3600)=0,"",INT(MOD(B7,3600*24)/3600)&"H")&IF(INT(MOD(B7,3600)/60)=0,"",INT(MOD(B7,3600)/60)&"M")&IF(MOD(B7,60)=0,"",INT(MOD(B7,60))&"S") -> 3M55S | D7: =B7*1000/60 -> 3921.5686 | E7: ='table (no research)'!M7*'Research Enhancing'!C6 -> 612 | F7: ='table (no research)'!N7*'Research Enhancing'!C6 -> 33048 | G7: ='table (no research)'!O7 -> 18383.631 | H7: =B7*13 -> 3058.8235 | I7: =IF(INT(H7/3600/24)=0,"",INT(H7/3600/24)&"D")&IF(INT(MOD(H7,3600*24)/3600)=0,"",INT(MOD(H7,3600*24)/3600)&"H")&IF(INT(MOD(H7,3600)/60)=0,"",INT(MOD(H7,3600)/60)&"M")&IF(MOD(H7,60)=0,"",INT(MOD(H7,60))&"S") -> 50M58S | J7: =D7*13 -> 50980.392 | K7: =E7*13 -> 7956 | L7: =F7*13 -> 429624 | M7: ='table (no research)'!U7 -> 55150.893 | N7: =H7*1.5 -> 4588.2353 | O7: =IF(INT(N7/3600/24)=0,"",INT(N7/3600/24)&"D")&IF(INT(MOD(N7,3600*24)/3600)=0,"",INT(MOD(N7,3600*24)/3600)&"H")&IF(INT(MOD(N7,3600)/60)=0,"",INT(MOD(N7,3600)/60)&"M")&IF(MOD(N7,60)=0,"",INT(MOD(N7,60))&"S") -> 1H16M28S | P7: =J7*3 -> 152941.18 | Q7: =K7 -> 7956 | R7: =L7 -> 429624 | S7: ='table (no research)'!AA7*'Research Enhancing'!C6 -> 279786 | T7: ='table (no research)'!AB7 -> 551508.93 | U7: =T7+V7 -> 560634.93 | V7: =(Q7+Q6)/2*N7/3600 -> 9126 | W7: =S7/R7 -> 0.65123457 | X7: =U7/P7 -> 3.6656899 | Y7: =V7/P7 -> 0.05967
A8: 6 | B8: ='table (no research)'!J8/'Research Enhancing'!C7 -> 294.11765 | C8: =IF(INT(B8/3600/24)=0,"",INT(B8/3600/24)&"D")&IF(INT(MOD(B8,3600*24)/3600)=0,"",INT(MOD(B8,3600*24)/3600)&"H")&IF(INT(MOD(B8,3600)/60)=0,"",INT(MOD(B8,3600)/60)&"M")&IF(MOD(B8,60)=0,"",INT(MOD(B8,60))&"S") -> 4M54S | D8: =B8*1000/60 -> 4901.9608 | E8: ='table (no research)'!M8*'Research Enhancing'!C7 -> 734.4 | F8: ='table (no research)'!N8*'Research Enhancing'!C7 -> 40392 | G8: ='table (no research)'!O8 -> 17621.886 | H8: =B8*13 -> 3823.5294 | I8: =IF(INT(H8/3600/24)=0,"",INT(H8/3600/24)&"D")&IF(INT(MOD(H8,3600*24)/3600)=0,"",INT(MOD(H8,3600*24)/3600)&"H")&IF(INT(MOD(H8,3600)/60)=0,"",INT(MOD(H8,3600)/60)&"M")&IF(MOD(H8,60)=0,"",INT(MOD(H8,60))&"S") -> 1H3M43S | J8: =D8*13 -> 63725.49 | K8: =E8*13 -> 9547.2 | L8: =F8*13 -> 525096 | M8: ='table (no research)'!U8 -> 52865.658 | N8: =H8*1.5 -> 5735.2941 | O8: =IF(INT(N8/3600/24)=0,"",INT(N8/3600/24)&"D")&IF(INT(MOD(N8,3600*24)/3600)=0,"",INT(MOD(N8,3600*24)/3600)&"H")&IF(INT(MOD(N8,3600)/60)=0,"",INT(MOD(N8,3600)/60)&"M")&IF(MOD(N8,60)=0,"",INT(MOD(N8,60))&"S") -> 1H35M35S | P8: =J8*3 -> 191176.47 | Q8: =K8 -> 9547.2 | R8: =L8 -> 525096 | S8: ='table (no research)'!AA8*'Research Enhancing'!C7 -> 309952.5 | T8: ='table (no research)'!AB8 -> 528656.58 | U8: =T8+V8 -> 542599.08 | V8: =(Q8+Q7)/2*N8/3600 -> 13942.5 | W8: =S8/R8 -> 0.59027778 | X8: =U8/P8 -> 2.8382106 | Y8: =V8/P8 -> 0.07293
A9: 7 | B9: ='table (no research)'!J9/'Research Enhancing'!C8 -> 436.8932 | C9: =IF(INT(B9/3600/24)=0,"",INT(B9/3600/24)&"D")&IF(INT(MOD(B9,3600*24)/3600)=0,"",INT(MOD(B9,3600*24)/3600)&"H")&IF(INT(MOD(B9,3600)/60)=0,"",INT(MOD(B9,3600)/60)&"M")&IF(MOD(B9,60)=0,"",INT(MOD(B9,60))&"S") -> 7M16S | D9: =B9*1000/60 -> 7281.5534 | E9: ='table (no research)'!M9*'Research Enhancing'!C8 -> 865.2 | F9: ='table (no research)'!N9*'Research Enhancing'!C8 -> 48451.2 | G9: ='table (no research)'!O9 -> 20181.863 | H9: =B9*13 -> 5679.6117 | I9: =IF(INT(H9/3600/24)=0,"",INT(H9/3600/24)&"D")&IF(INT(MOD(H9,3600*24)/3600)=0,"",INT(MOD(H9,3600*24)/3600)&"H")&IF(INT(MOD(H9,3600)/60)=0,"",INT(MOD(H9,3600)/60)&"M")&IF(MOD(H9,60)=0,"",INT(MOD(H9,60))&"S") -> 1H34M39S | J9: =D9*13 -> 94660.194 | K9: =E9*13 -> 11247.6 | L9: =F9*13 -> 629865.6 | M9: ='table (no research)'!U9 -> 60545.59 | N9: =H9*1.5 -> 8519.4175 | O9: =IF(INT(N9/3600/24)=0,"",INT(N9/3600/24)&"D")&IF(INT(MOD(N9,3600*24)/3600)=0,"",INT(MOD(N9,3600*24)/3600)&"H")&IF(INT(MOD(N9,3600)/60)=0,"",INT(MOD(N9,3600)/60)&"M")&IF(MOD(N9,60)=0,"",INT(MOD(N9,60))&"S") -> 2H21M59S | P9: =J9*3 -> 283980.58 | Q9: =K9 -> 11247.6 | R9: =L9 -> 629865.6 | S9: ='table (no research)'!AA9*'Research Enhancing'!C8 -> 343453.5 | T9: ='table (no research)'!AB9 -> 605455.9 | U9: =T9+V9 -> 630061.39 | V9: =(Q9+Q8)/2*N9/3600 -> 24605.498 | W9: =S9/R9 -> 0.54528061 | X9: =U9/P9 -> 2.2186777 | Y9: =V9/P9 -> 0.086645
A10: 8 | B10: ='table (no research)'!J10/'Research Enhancing'!C9 -> 601.94175 | C10: =IF(INT(B10/3600/24)=0,"",INT(B10/3600/24)&"D")&IF(INT(MOD(B10,3600*24)/3600)=0,"",INT(MOD(B10,3600*24)/3600)&"H")&IF(INT(MOD(B10,3600)/60)=0,"",INT(MOD(B10,3600)/60)&"M")&IF(MOD(B10,60)=0,"",INT(MOD(B10,60))&"S") -> 10M1S | D10: =B10*1000/60 -> 10032.362 | E10: ='table (no research)'!M10*'Research Enhancing'!C9 -> 988.8 | F10: ='table (no research)'!N10*'Research Enhancing'!C9 -> 56361.6 | G10: ='table (no research)'!O10 -> 21098.401 | H10: =B10*13 -> 7825.2427 | I10: =IF(INT(H10/3600/24)=0,"",INT(H10/3600/24)&"D")&IF(INT(MOD(H10,3600*24)/3600)=0,"",INT(MOD(H10,3600*24)/3600)&"H")&IF(INT(MOD(H10,3600)/60)=0,"",INT(MOD(H10,3600)/60)&"M")&IF(MOD(H10,60)=0,"",INT(MOD(H10,60))&"S") -> 2H10M25S | J10: =D10*13 -> 130420.71 | K10: =E10*13 -> 12854.4 | L10: =F10*13 -> 732700.8 | M10: ='table (no research)'!U10 -> 63295.202 | N10: =H10*1.5 -> 11737.864 | O10: =IF(INT(N10/3600/24)=0,"",INT(N10/3600/24)&"D")&IF(INT(MOD(N10,3600*24)/3600)=0,"",INT(MOD(N10,3600*24)/3600)&"H")&IF(INT(MOD(N10,3600)/60)=0,"",INT(MOD(N10,3600)/60)&"M")&IF(MOD(N10,60)=0,"",INT(MOD(N10,60))&"S") -> 3H15M37S | P10: =J10*3 -> 391262.14 | Q10: =K10 -> 12854.4 | R10: =L10 -> 732700.8 | S10: ='table (no research)'!AA10*'Research Enhancing'!C9 -> 373915.75 | T10: ='table (no research)'!AB10 -> 632952.02 | U10: =T10+V10 -> 672244.52 | V10: =(Q10+Q9)/2*N10/3600 -> 39292.5 | W10: =S10/R10 -> 0.51032529 | X10: =U10/P10 -> 1.7181436 | Y10: =V10/P10 -> 0.100425
A11: 9 | B11: ='table (no research)'!J11/'Research Enhancing'!C10 -> 834.95146 | C11: =IF(INT(B11/3600/24)=0,"",INT(B11/3600/24)&"D")&IF(INT(MOD(B11,3600*24)/3600)=0,"",INT(MOD(B11,3600*24)/3600)&"H")&IF(INT(MOD(B11,3600)/60)=0,"",INT(MOD(B11,3600)/60)&"M")&IF(MOD(B11,60)=0,"",INT(MOD(B11,60))&"S") -> 13M54S | D11: =B11*1000/60 -> 13915.858 | E11: ='table (no research)'!M11*'Research Enhancing'!C10 -> 1112.4 | F11: ='table (no research)'!N11*'Research Enhancing'!C10 -> 64519.2 | G11: ='table (no research)'!O11 -> 22006.892 | H11: =B11*13 -> 10854.369 | I11: =IF(INT(H11/3600/24)=0,"",INT(H11/3600/24)&"D")&IF(INT(MOD(H11,3600*24)/3600)=0,"",INT(MOD(H11,3600*24)/3600)&"H")&IF(INT(MOD(H11,3600)/60)=0,"",INT(MOD(H11,3600)/60)&"M")&IF(MOD(H11,60)=0,"",INT(MOD(H11,60))&"S") -> 3H54S | J11: =D11*13 -> 180906.15 | K11: =E11*13 -> 14461.2 | L11: =F11*13 -> 838749.6 | M11: ='table (no research)'!U11 -> 66020.676 | N11: =H11*1.5 -> 16281.553 | O11: =IF(INT(N11/3600/24)=0,"",INT(N11/3600/24)&"D")&IF(INT(MOD(N11,3600*24)/3600)=0,"",INT(MOD(N11,3600*24)/3600)&"H")&IF(INT(MOD(N11,3600)/60)=0,"",INT(MOD(N11,3600)/60)&"M")&IF(MOD(N11,60)=0,"",INT(MOD(N11,60))&"S") -> 4H31M21S | P11: =J11*3 -> 542718.45 | Q11: =K11 -> 14461.2 | R11: =L11 -> 838749.6 | S11: ='table (no research)'!AA11*'Research Enhancing'!C10 -> 404378 | T11: ='table (no research)'!AB11 -> 660206.76 | U11: =T11+V11 -> 721976.26 | V11: =(Q11+Q10)/2*N11/3600 -> 61769.5 | W11: =S11/R11 -> 0.48212005 | X11: =U11/P11 -> 1.3302962 | Y11: =V11/P11 -> 0.113815
A12: 10 | B12: ='table (no research)'!J12/'Research Enhancing'!C11 -> 1153.8462 | C12: =IF(INT(B12/3600/24)=0,"",INT(B12/3600/24)&"D")&IF(INT(MOD(B12,3600*24)/3600)=0,"",INT(MOD(B12,3600*24)/3600)&"H")&IF(INT(MOD(B12,3600)/60)=0,"",INT(MOD(B12,3600)/60)&"M")&IF(MOD(B12,60)=0,"",INT(MOD(B12,60))&"S") -> 19M13S | D12: =B12*1000/60 -> 19230.769 | E12: ='table (no research)'!M12*'Research Enhancing'!C11 -> 1248 | F12: ='table (no research)'!N12*'Research Enhancing'!C11 -> 73632 | G12: ='table (no research)'!O12 -> 22789 | H12: =B12*13 -> 15000 | I12: =IF(INT(H12/3600/24)=0,"",INT(H12/3600/24)&"D")&IF(INT(MOD(H12,3600*24)/3600)=0,"",INT(MOD(H12,3600*24)/3600)&"H")&IF(INT(MOD(H12,3600)/60)=0,"",INT(MOD(H12,3600)/60)&"M")&IF(MOD(H12,60)=0,"",INT(MOD(H12,60))&"S") -> 4H10M | J12: =D12*13 -> 250000 | K12: =E12*13 -> 16224 | L12: =F12*13 -> 957216 | M12: ='table (no research)'!U12 -> 68367 | N12: =H12*1.5 -> 22500 | O12: =IF(INT(N12/3600/24)=0,"",INT(N12/3600/24)&"D")&IF(INT(MOD(N12,3600*24)/3600)=0,"",INT(MOD(N12,3600*24)/3600)&"H")&IF(INT(MOD(N12,3600)/60)=0,"",INT(MOD(N12,3600)/60)&"M")&IF(MOD(N12,60)=0,"",INT(MOD(N12,60))&"S") -> 6H15M | P12: =J12*3 -> 750000 | Q12: =K12 -> 16224 | R12: =L12 -> 957216 | S12: ='table (no research)'!AA12*'Research Enhancing'!C11 -> 439062 | T12: ='table (no research)'!AB12 -> 683670 | U12: =T12+V12 -> 779561.25 | V12: =(Q12+Q11)/2*N12/3600 -> 95891.25 | W12: =S12/R12 -> 0.45868644 | X12: =U12/P12 -> 1.039415 | Y12: =V12/P12 -> 0.127855
A13: 11 | B13: ='table (no research)'!J13/'Research Enhancing'!C12 -> 1596.1538 | C13: =IF(INT(B13/3600/24)=0,"",INT(B13/3600/24)&"D")&IF(INT(MOD(B13,3600*24)/3600)=0,"",INT(MOD(B13,3600*24)/3600)&"H")&IF(INT(MOD(B13,3600)/60)=0,"",INT(MOD(B13,3600)/60)&"M")&IF(MOD(B13,60)=0,"",INT(MOD(B13,60))&"S") -> 26M36S | D13: =B13*1000/60 -> 26602.564 | E13: ='table (no research)'!M13*'Research Enhancing'!C12 -> 1372.8 | F13: ='table (no research)'!N13*'Research Enhancing'!C12 -> 82368 | G13: ='table (no research)'!O13 -> 28426.297 | H13: =B13*13 -> 20750 | I13: =IF(INT(H13/3600/24)=0,"",INT(H13/3600/24)&"D")&IF(INT(MOD(H13,3600*24)/3600)=0,"",INT(MOD(H13,3600*24)/3600)&"H")&IF(INT(MOD(H13,3600)/60)=0,"",INT(MOD(H13,3600)/60)&"M")&IF(MOD(H13,60)=0,"",INT(MOD(H13,60))&"S") -> 5H45M50S | J13: =D13*13 -> 345833.33 | K13: =E13*13 -> 17846.4 | L13: =F13*13 -> 1070784 | M13: ='table (no research)'!U13 -> 85278.89 | N13: =H13*1.5 -> 31125 | O13: =IF(INT(N13/3600/24)=0,"",INT(N13/3600/24)&"D")&IF(INT(MOD(N13,3600*24)/3600)=0,"",INT(MOD(N13,3600*24)/3600)&"H")&IF(INT(MOD(N13,3600)/60)=0,"",INT(MOD(N13,3600)/60)&"M")&IF(MOD(N13,60)=0,"",INT(MOD(N13,60))&"S") -> 8H38M45S | P13: =J13*3 -> 1037500 | Q13: =K13 -> 17846.4 | R13: =L13 -> 1070784 | S13: ='table (no research)'!AA13*'Research Enhancing'!C12 -> 469820 | T13: ='table (no research)'!AB13 -> 852788.9 | U13: =T13+V13 -> 1000072.4 | V13: =(Q13+Q12)/2*N13/3600 -> 147283.5 | W13: =S13/R13 -> 0.43876263 | X13: =U13/P13 -> 0.96392521 | Y13: =V13/P13 -> 0.14196
A14: 12 | B14: ='table (no research)'!J14/'Research Enhancing'!C13 -> 2211.5385 | C14: =IF(INT(B14/3600/24)=0,"",INT(B14/3600/24)&"D")&IF(INT(MOD(B14,3600*24)/3600)=0,"",INT(MOD(B14,3600*24)/3600)&"H")&IF(INT(MOD(B14,3600)/60)=0,"",INT(MOD(B14,3600)/60)&"M")&IF(MOD(B14,60)=0,"",INT(MOD(B14,60))&"S") -> 36M51S | D14: =B14*1000/60 -> 36858.974 | E14: ='table (no research)'!M14*'Research Enhancing'!C13 -> 1497.6 | F14: ='table (no research)'!N14*'Research Enhancing'!C13 -> 91353.6 | G14: ='table (no research)'!O14 -> 35359.395 | H14: =B14*13 -> 28750 | I14: =IF(INT(H14/3600/24)=0,"",INT(H14/3600/24)&"D")&IF(INT(MOD(H14,3600*24)/3600)=0,"",INT(MOD(H14,3600*24)/3600)&"H")&IF(INT(MOD(H14,3600)/60)=0,"",INT(MOD(H14,3600)/60)&"M")&IF(MOD(H14,60)=0,"",INT(MOD(H14,60))&"S") -> 7H59M10S | J14: =D14*13 -> 479166.67 | K14: =E14*13 -> 19468.8 | L14: =F14*13 -> 1187596.8 | M14: ='table (no research)'!U14 -> 106078.18 | N14: =H14*1.5 -> 43125 | O14: =IF(INT(N14/3600/24)=0,"",INT(N14/3600/24)&"D")&IF(INT(MOD(N14,3600*24)/3600)=0,"",INT(MOD(N14,3600*24)/3600)&"H")&IF(INT(MOD(N14,3600)/60)=0,"",INT(MOD(N14,3600)/60)&"M")&IF(MOD(N14,60)=0,"",INT(MOD(N14,60))&"S") -> 11H58M45S | P14: =J14*3 -> 1437500 | Q14: =K14 -> 19468.8 | R14: =L14 -> 1187596.8 | S14: ='table (no research)'!AA14*'Research Enhancing'!C13 -> 500578 | T14: ='table (no research)'!AB14 -> 1060781.8 | U14: =T14+V14 -> 1284284.3 | V14: =(Q14+Q13)/2*N14/3600 -> 223502.5 | W14: =S14/R14 -> 0.42150501 | X14: =U14/P14 -> 0.8934152 | Y14: =V14/P14 -> 0.15548
