Workbook

Sheet Inscriptions
A1: This chart helps simulating a battle between 4 vehicles ( 2 factions, and 2 vehicles for each faction). Fill the stats of the 4 vehicles in Sheet A1/A2/B1/B2 (within the red cells). And see the 10 times of simulations in Sheet "Total Result". PS:After simulations, this chart would be modified. So to have a copy of this chart somewhere else is strongly recommended. If you don't want to copy it, please make sure you don't push the modified one to the git.

Sheet A1
A1: Fill stats in the red cells | E1: A1 is the front vehicle of Side A | M1: 0shotgun | N1: 0pickup
M2: 1machinegun | N2: 1buggy
M3: 2:50cal | N3: 2car
B4: Level | C4: HP Uplimit | D4: Attack | E4: Defense | F4: Crit Chance Level | G4: Crit Result Level | H4: Absorption Chance Level | I4: Absorption Result Level | J4: Precision Level | K4: Penetration Level | L4: Toughness | M4: Attack Type | N4: Armor Type
A5: Bare Vehicle | B5: 1 | C5: 240 | D5: 20
A6: Weapon | M6: 1
A7: Armor | N7: 1
A8: Engine
A9: Tyre
A10: Chasis
A11: Total | B11: =SUM(B5:B10) -> 1 | C11: =SUM(C5:C10) -> 240 | D11: =SUM(D5:D10) -> 20 | E11: =SUM(E5:E10) -> 0 | F11: =SUM(F5:F10) -> 0 | G11: =SUM(G5:G10) -> 0 | H11: =SUM(H5:H10) -> 0 | I11: =SUM(I5:I10) -> 0 | ... N11: =SUM(N5:N10) -> 1

Sheet A2
A1: Fill stats in the red cells | E1: A2 is the back vehicle of Side A | M1: 0shotgun | N1: 0pickup
M2: 1machinegun | N2: 1buggy
M3: 2:50cal | N3: 2car
B4: Level | C4: HP Uplimit | D4: Attack | E4: Defense | F4: Crit Chance Level | G4: Crit Result Level | H4: Absorption Chance Level | I4: Absorption Result Level | J4: Precision Level | K4: Penetration Level | L4: Toughness | M4: Attack Type | N4: Armor Type
A5: Bare Vehicle | B5: 1 | C5: 160 | D5: 30
A6: Weapon | M6: 1
A7: Armor | N7: 1
A8: Engine
A9: Tyre
A10: Chasis
A11: Total | B11: =SUM(B5:B10) -> 1 | C11: =SUM(C5:C10) -> 160 | D11: =SUM(D5:D10) -> 30 | E11: =SUM(E5:E10) -> 0 | F11: =SUM(F5:F10) -> 0 | G11: =SUM(G5:G10) -> 0 | H11: =SUM(H5:H10) -> 0 | I11: =SUM(I5:I10) -> 0 | ... N11: =SUM(N5:N10) -> 1

Sheet B1
A1: Fill stats in the red cells | E1: B1 is the front vehicle of Side B | M1: 0shotgun | N1: 0pickup
M2: 1machinegun | N2: 1buggy
M3: 2:50cal | N3: 2car
B4: Level | C4: HP Uplimit | D4: Attack | E4: Defense | F4: Crit Chance Level | G4: Crit Result Level | H4: Absorption Chance Level | I4: Absorption Result Level | J4: Precision Level | K4: Penetration Level | L4: Toughness | M4: Attack Type | N4: Armor Type
A5: Bare Vehicle | B5: 1 | C5: 240 | D5: 20
A6: Weapon | M6: 1
A7: Armor | N7: 1
A8: Engine
A9: Tyre
A10: Chasis
A11: Total | B11: =SUM(B5:B10) -> 1 | C11: =SUM(C5:C10) -> 240 | D11: =SUM(D5:D10) -> 20 | E11: =SUM(E5:E10) -> 0 | F11: =SUM(F5:F10) -> 0 | G11: =SUM(G5:G10) -> 0 | H11: =SUM(H5:H10) -> 0 | I11: =SUM(I5:I10) -> 0 | ... N11: =SUM(N5:N10) -> 1

Sheet B2
A1: Fill stats in the red cells | E1: B2 is the front vehicle of Side B | M1: 0shotgun | N1: 0pickup
M2: 1machinegun | N2: 1buggy
M3: 2:50cal | N3: 2car
B4: Level | C4: HP Uplimit | D4: Attack | E4: Defense | F4: Crit Chance Level | G4: Crit Result Level | H4: Absorption Chance Level | I4: Absorption Result Level | J4: Precision Level | K4: Penetration Level | L4: Toughness | M4: Attack Type | N4: Armor Type
A5: Bare Vehicle | B5: 1 | C5: 160 | D5: 30
A6: Weapon | M6: 1
A7: Armor | N7: 1
A8: Engine
A9: Tyre
A10: Chasis
A11: Total | B11: =SUM(B5:B10) -> 1 | C11: =SUM(C5:C10) -> 160 | D11: =SUM(D5:D10) -> 30 | E11: =SUM(E5:E10) -> 0 | F11: =SUM(F5:F10) -> 0 | G11: =SUM(G5:G10) -> 0 | H11: =SUM(H5:H10) -> 0 | I11: =SUM(I5:I10) -> 0 | ... N11: =SUM(N5:N10) -> 1

Sheet Total Result
A1: Vehicle Stats
B2: Level | C2: HP Uplimit | D2: Attack | E2: Defense | F2: Crit Chance Level | G2: Crit Result Level | H2: Absorption Chance Level | I2: Absorption Result Level | J2: Precision Level | K2: Penetration Level | L2: Toughness | M2: Attack Type | N2: Armor Type
A3: A2 | B3: ='A2'!B11 -> 1 | C3: ='A2'!C11 -> 160 | D3: ='A2'!D11 -> 30 | E3: ='A2'!E11 -> 0 | F3: ='A2'!F11 -> 0 | G3: ='A2'!G11 -> 0 | H3: ='A2'!H11 -> 0 | I3: ='A2'!I11 -> 0 | ... N3: ='A2'!N11 -> 1
A4: A1 | B4: ='A1'!B11 -> 1 | C4: ='A1'!C11 -> 240 | D4: ='A1'!D11 -> 20 | E4: ='A1'!E11 -> 0 | F4: ='A1'!F11 -> 0 | G4: ='A1'!G11 -> 0 | H4: ='A1'!H11 -> 0 | I4: ='A1'!I11 -> 0 | ... N4: ='A1'!N11 -> 1
A5: 楚河 汉界
A6: B1 | B6: ='B1'!B11 -> 1 | C6: ='B1'!C11 -> 240 | D6: ='B1'!D11 -> 20 | E6: ='B1'!E11 -> 0 | F6: ='B1'!F11 -> 0 | G6: ='B1'!G11 -> 0 | H6: ='B1'!H11 -> 0 | I6: ='B1'!I11 -> 0 | ... N6: ='B1'!N11 -> 1
A7: B2 | B7: ='B2'!B11 -> 1 | C7: ='B2'!C11 -> 160 | D7: ='B2'!D11 -> 30 | E7: ='B2'!E11 -> 0 | F7: ='B2'!F11 -> 0 | G7: ='B2'!G11 -> 0 | H7: ='B2'!H11 -> 0 | I7: ='B2'!I11 -> 0 | ... N7: ='B2'!N11 -> 1
M8: 0shotgun | N8: 0pickup
M9: 1machinegun | N9: 1buggy
M10: 2:50cal | N10: 2car
A11: A Win Times: | C11: =COUNTIF($N$15:$N$43,"A wins") -> 1 | E11: Round Draw Times | G11: =COUNTIF($N$15:$N$43,"Round Draw") -> 7 | I11: B win Times | K11: =COUNTIF($N$15:$N$43,"B wins") -> 2
A13: 10次战斗模拟
A15: =A12+1 -> 1 | B15: =战斗模拟1!$B$3 -> 0 | E15: =战斗模拟1!$E$3 -> 0 | F15: =战斗模拟1!$F$3 -> 楚河 | H15: =战斗模拟1!$H$3 -> 0 | K15: =战斗模拟1!$K$3 -> 0 | M15: 胜方： | N15: =IF(B15>0,"A wins",IF(K15>0,"B wins","Round Draw")) -> Round Draw
B16: =战斗模拟1!$B$4 -> A2 | E16: =战斗模拟1!$E$4 -> A1 | F16: =战斗模拟1!$F$4 -> 汉界 | H16: =战斗模拟1!$H$4 -> B1 | K16: =战斗模拟1!$K$4 -> B2
A18: =A15+1 -> 2 | B18: =战斗模拟2!$B$3 -> 0 | E18: =战斗模拟2!$E$3 -> 0 | F18: =战斗模拟1!$F$3 -> 楚河 | H18: =战斗模拟2!$H$3 -> 0 | K18: =战斗模拟2!$K$3 -> 0 | M18: 胜方： | N18: =IF(B18>0,"A wins",IF(K18>0,"B wins","Round Draw")) -> Round Draw
B19: =战斗模拟1!$B$4 -> A2 | E19: =战斗模拟1!$E$4 -> A1 | F19: =战斗模拟1!$F$4 -> 汉界 | H19: =战斗模拟1!$H$4 -> B1 | K19: =战斗模拟1!$K$4 -> B2
A21: =A18+1 -> 3 | B21: =战斗模拟3!$B$3 -> 0 | E21: =战斗模拟3!$E$3 -> 0 | F21: =战斗模拟1!$F$3 -> 楚河 | H21: =战斗模拟3!$H$3 -> 0 | K21: =战斗模拟3!$K$3 -> 0 | M21: 胜方： | N21: =IF(B21>0,"A wins",IF(K21>0,"B wins","Round Draw")) -> Round Draw
B22: =战斗模拟1!$B$4 -> A2 | E22: =战斗模拟1!$E$4 -> A1 | F22: =战斗模拟1!$F$4 -> 汉界 | H22: =战斗模拟1!$H$4 -> B1 | K22: =战斗模拟1!$K$4 -> B2
A24: =A21+1 -> 4 | B24: =战斗模拟4!$B$3 -> 0.15 | E24: =战斗模拟4!$E$3 -> 0 | F24: =战斗模拟1!$F$3 -> 楚河 | H24: =战斗模拟4!$H$3 -> 0 | K24: =战斗模拟4!$K$3 -> 0 | M24: 胜方： | N24: =IF(B24>0,"A wins",IF(K24>0,"B wins","Round Draw")) -> A wins
B25: =战斗模拟1!$B$4 -> A2 | E25: =战斗模拟1!$E$4 -> A1 | F25: =战斗模拟1!$F$4 -> 汉界 | H25: =战斗模拟1!$H$4 -> B1 | K25: =战斗模拟1!$K$4 -> B2
A27: =A24+1 -> 5 | B27: =战斗模拟5!$B$3 -> 0 | E27: =战斗模拟5!$E$3 -> 0 | F27: =战斗模拟1!$F$3 -> 楚河 | H27: =战斗模拟5!$H$3 -> 0 | K27: =战斗模拟5!$K$3 -> 0 | M27: 胜方： | N27: =IF(B27>0,"A wins",IF(K27>0,"B wins","Round Draw")) -> Round Draw
B28: =战斗模拟1!$B$4 -> A2 | E28: =战斗模拟1!$E$4 -> A1 | F28: =战斗模拟1!$F$4 -> 汉界 | H28: =战斗模拟1!$H$4 -> B1 | K28: =战斗模拟1!$K$4 -> B2
A30: =A27+1 -> 6 | B30: =战斗模拟6!$B$3 -> 0 | E30: =战斗模拟6!$E$3 -> 0 | F30: =战斗模拟1!$F$3 -> 楚河 | H30: =战斗模拟6!$H$3 -> 0 | K30: =战斗模拟6!$K$3 -> 0.0375 | M30: 胜方： | N30: =IF(B30>0,"A wins",IF(K30>0,"B wins","Round Draw")) -> B wins
B31: =战斗模拟1!$B$4 -> A2 | E31: =战斗模拟1!$E$4 -> A1 | F31: =战斗模拟1!$F$4 -> 汉界 | H31: =战斗模拟1!$H$4 -> B1 | K31: =战斗模拟1!$K$4 -> B2
A33: =A30+1 -> 7 | B33: =战斗模拟7!$B$3 -> 0 | E33: =战斗模拟7!$E$3 -> 0 | F33: =战斗模拟1!$F$3 -> 楚河 | H33: =战斗模拟7!$H$3 -> 0 | K33: =战斗模拟7!$K$3 -> 0.1875 | M33: 胜方： | N33: =IF(B33>0,"A wins",IF(K33>0,"B wins","Round Draw")) -> B wins
B34: =战斗模拟1!$B$4 -> A2 | E34: =战斗模拟1!$E$4 -> A1 | F34: =战斗模拟1!$F$4 -> 汉界 | H34: =战斗模拟1!$H$4 -> B1 | K34: =战斗模拟1!$K$4 -> B2
A36: =A33+1 -> 8 | B36: =战斗模拟8!$B$3 -> 0 | E36: =战斗模拟8!$E$3 -> 0 | F36: =战斗模拟1!$F$3 -> 楚河 | H36: =战斗模拟8!$H$3 -> 0 | K36: =战斗模拟8!$K$3 -> 0 | M36: 胜方： | N36: =IF(B36>0,"A wins",IF(K36>0,"B wins","Round Draw")) -> Round Draw
B37: =战斗模拟1!$B$4 -> A2 | E37: =战斗模拟1!$E$4 -> A1 | F37: =战斗模拟1!$F$4 -> 汉界 | H37: =战斗模拟1!$H$4 -> B1 | K37: =战斗模拟1!$K$4 -> B2
A39: =A36+1 -> 9 | B39: =战斗模拟9!$B$3 -> 0 | E39: =战斗模拟9!$E$3 -> 0 | F39: =战斗模拟1!$F$3 -> 楚河 | H39: =战斗模拟9!$H$3 -> 0 | K39: =战斗模拟9!$K$3 -> 0 | M39: 胜方： | N39: =IF(B39>0,"A wins",IF(K39>0,"B wins","Round Draw")) -> Round Draw
B40: =战斗模拟1!$B$4 -> A2 | E40: =战斗模拟1!$E$4 -> A1 | F40: =战斗模拟1!$F$4 -> 汉界 | H40: =战斗模拟1!$H$4 -> B1 | K40: =战斗模拟1!$K$4 -> B2
A42: =A39+1 -> 10 | B42: =战斗模拟10!$B$3 -> 0 | E42: =战斗模拟10!$E$3 -> 0 | F42: =战斗模拟1!$F$3 -> 楚河 | H42: =战斗模拟10!$H$3 -> 0 | K42: =战斗模拟10!$K$3 -> 0 | M42: 胜方： | N42: =IF(B42>0,"A wins",IF(K42>0,"B wins","Round Draw")) -> Round Draw
B43: =战斗模拟1!$B$4 -> A2 | E43: =战斗模拟1!$E$4 -> A1 | F43: =战斗模拟1!$F$4 -> 汉界 | H43: =战斗模拟1!$H$4 -> B1 | K43: =战斗模拟1!$K$4 -> B2

Sheet 常数
A1: 实际效果 | B1: 对应属性项 | C1: counter属性项 | D1: 常数a | E1: 常数b | F1: 基础值 | G1: 上限值 | H1: 下限值
A2: 暴击几率 | B2: 暴击几率等级 | C2: 无 | D2: 4 | E2: 76 | F2: 0.05 | G2: 0.7 | H2: 0.05
A3: 暴击伤害加成乘数 | B3: 暴击伤害等级 | C3: 韧性 | D3: 5 | E3: 95 | F3: 0.5 | G3: 2 | H3: 0.5
A4: 偏移几率 | B4: 偏移几率等级 | C4: 精准等级 | D4: 6.7 | E4: 126.7 | F4: 0.05 | G4: 0.7 | H4: 0.05
A5: 偏移减伤乘数 | B5: 偏移减伤等级 | C5: 无 | D5: 8.3 | E5: 158.3 | F5: 0.33 | G5: 0.67 | H5: 0.33
A6: 护甲乘数 | B6: 防御力 | C6: 护甲穿透 | D6: 1.5 | E6: 28.5 | F6: 0 | G6: 1 | H6: 0

Sheet 战斗模拟1
A1: 开始时4辆车的血量 | B1: 检测4辆车的状态，若已经死亡则不发射炮弹 | C1: 检测对方前排是否存活 | D1: 检测对方后排是否存活 | E1: 让其战斗30轮 | F1: 记录10轮的剩余血量结果
F2: 战斗结果
B3: =B1208 -> 0 | E3: =E1208 -> 0 | F3: 楚河 | H3: =H1208 -> 0 | K3: =K1208 -> 0
B4: A2 | E4: A1 | F4: 汉界 | H4: B1 | K4: B2
A7: A2初始血量： | B7: ='Total Result'!C3 -> 160 | D7: A1初始血量： | E7: ='Total Result'!C4 -> 240 | G7: B1初始血量 | H7: ='Total Result'!C6 -> 240 | J7: B2初始血量 | K7: ='Total Result'!C7 -> 160
A8: 百分比： | B8: 1 | D8: 百分比 | E8: 1 | G8: 百分比 | H8: 1 | J8: 百分比 | K8: 1
A10: 攻击轮数： | B10: 1
A12: A2是否存活？（上轮A2血量是否大于0？） | B12: =IF(B7>0,1,0) -> 1 | D12: A1是否存活？（上轮A1血量是否大于0？） | E12: =IF(E7>0,1,0) -> 1 | G12: B1是否存活？（上轮B1血量是否大于0？） | H12: =IF(H7>0,1,0) -> 1 | J12: B2是否存活？（上轮B2血量是否大于0？） | K12: =IF(K7>0,1,0) -> 1
A14: A2攻击 | D14: A1攻击 | G14: B1攻击 | J14: B2攻击
A15: 攻击方 | B15: A2 | D15: 攻击方 | E15: A1 | G15: 攻击方 | H15: B1 | J15: 攻击方 | K15: B2
A16: 对象 | B16: =IF($H7>0,"B1","B2") -> B1 | D16: 对象 | E16: =IF($H7>0,"B1","B2") -> B1 | G16: 对象 | H16: =IF($E7>0,"A1","A2") -> A1 | J16: 对象 | K16: =IF(E7>0,"A1","A2") -> A1
A17: 属性 | B17: 攻击方 | C17: 防御方 | D17: 属性 | E17: 攻击方 | F17: 防御方 | G17: 属性 | H17: 攻击方 | I17: 防御方 | J17: 属性 | K17: 攻击方 | L17: 防御方
A18: 级别 | B18: =VLOOKUP(B15,'Total Result'!$A$3:$N$7,2,FALSE) -> 1 | C18: =VLOOKUP(B16,'Total Result'!$A$3:$N$7,2,FALSE) -> 1 | D18: 级别 | E18: =VLOOKUP(E15,'Total Result'!$A$3:$N$7,2,FALSE) -> 1 | F18: =VLOOKUP(E16,'Total Result'!$A$3:$N$7,2,FALSE) -> 1 | G18: 级别 | H18: =VLOOKUP(H15,'Total Result'!$A$3:$N$7,2,FALSE) -> 1 | I18: =VLOOKUP(H16,'Total Result'!$A$3:$N$7,2,FALSE) -> 1 | J18: 级别 | K18: =VLOOKUP(K15,'Total Result'!$A$3:$N$7,2,FALSE) -> 1 | L18: =VLOOKUP(K16,'Total Result'!$A$3:$N$7,2,FALSE) -> 1
A19: 生命值上限 | B19: =VLOOKUP(B15,'Total Result'!$A$3:$N$7,3,FALSE) -> 160 | C19: =VLOOKUP(B16,'Total Result'!$A$3:$N$7,3,FALSE) -> 240 | D19: 生命值上限 | E19: =VLOOKUP(E15,'Total Result'!$A$3:$N$7,3,FALSE) -> 240 | F19: =VLOOKUP(E16,'Total Result'!$A$3:$N$7,3,FALSE) -> 240 | G19: 生命值上限 | H19: =VLOOKUP(H15,'Total Result'!$A$3:$N$7,3,FALSE) -> 240 | I19: =VLOOKUP(H16,'Total Result'!$A$3:$N$7,3,FALSE) -> 240 | J19: 生命值上限 | K19: =VLOOKUP(K15,'Total Result'!$A$3:$N$7,3,FALSE) -> 160 | L19: =VLOOKUP(K16,'Total Result'!$A$3:$N$7,3,FALSE) -> 240
A20: 攻击力 | B20: =VLOOKUP(B15,'Total Result'!$A$3:$N$7,4,FALSE) -> 30 | C20: =VLOOKUP(B16,'Total Result'!$A$3:$N$7,4,FALSE) -> 20 | D20: 攻击力 | E20: =VLOOKUP(E15,'Total Result'!$A$3:$N$7,4,FALSE) -> 20 | F20: =VLOOKUP(E16,'Total Result'!$A$3:$N$7,4,FALSE) -> 20 | G20: 攻击力 | H20: =VLOOKUP(H15,'Total Result'!$A$3:$N$7,4,FALSE) -> 20 | I20: =VLOOKUP(H16,'Total Result'!$A$3:$N$7,4,FALSE) -> 20 | J20: 攻击力 | K20: =VLOOKUP(K15,'Total Result'!$A$3:$N$7,4,FALSE) -> 30 | L20: =VLOOKUP(K16,'Total Result'!$A$3:$N$7,4,FALSE) -> 20
A21: 护甲 | B21: =VLOOKUP(B15,'Total Result'!$A$3:$N$7,5,FALSE) -> 0 | C21: =VLOOKUP(B16,'Total Result'!$A$3:$N$7,5,FALSE) -> 0 | D21: 护甲 | E21: =VLOOKUP(E15,'Total Result'!$A$3:$N$7,5,FALSE) -> 0 | F21: =VLOOKUP(E16,'Total Result'!$A$3:$N$7,5,FALSE) -> 0 | G21: 护甲 | H21: =VLOOKUP(H15,'Total Result'!$A$3:$N$7,5,FALSE) -> 0 | I21: =VLOOKUP(H16,'Total Result'!$A$3:$N$7,5,FALSE) -> 0 | J21: 护甲 | K21: =VLOOKUP(K15,'Total Result'!$A$3:$N$7,5,FALSE) -> 0 | L21: =VLOOKUP(K16,'Total Result'!$A$3:$N$7,5,FALSE) -> 0
A22: 暴击几率等级 | B22: =VLOOKUP(B15,'Total Result'!$A$3:$N$7,6,FALSE) -> 0 | C22: =VLOOKUP(B16,'Total Result'!$A$3:$N$7,6,FALSE) -> 0 | D22: 暴击几率等级 | E22: =VLOOKUP(E15,'Total Result'!$A$3:$N$7,6,FALSE) -> 0 | F22: =VLOOKUP(E16,'Total Result'!$A$3:$N$7,6,FALSE) -> 0 | G22: 暴击几率等级 | H22: =VLOOKUP(H15,'Total Result'!$A$3:$N$7,6,FALSE) -> 0 | I22: =VLOOKUP(H16,'Total Result'!$A$3:$N$7,6,FALSE) -> 0 | J22: 暴击几率等级 | K22: =VLOOKUP(K15,'Total Result'!$A$3:$N$7,6,FALSE) -> 0 | L22: =VLOOKUP(K16,'Total Result'!$A$3:$N$7,6,FALSE) -> 0
A23: 暴击伤害等级 | B23: =VLOOKUP(B15,'Total Result'!$A$3:$N$7,7,FALSE) -> 0 | C23: =VLOOKUP(B16,'Total Result'!$A$3:$N$7,7,FALSE) -> 0 | D23: 暴击伤害等级 | E23: =VLOOKUP(E15,'Total Result'!$A$3:$N$7,7,FALSE) -> 0 | F23: =VLOOKUP(E16,'Total Result'!$A$3:$N$7,7,FALSE) -> 0 | G23: 暴击伤害等级 | H23: =VLOOKUP(H15,'Total Result'!$A$3:$N$7,7,FALSE) -> 0 | I23: =VLOOKUP(H16,'Total Result'!$A$3:$N$7,7,FALSE) -> 0 | J23: 暴击伤害等级 | K23: =VLOOKUP(K15,'Total Result'!$A$3:$N$7,7,FALSE) -> 0 | L23: =VLOOKUP(K16,'Total Result'!$A$3:$N$7,7,FALSE) -> 0
A24: 偏移几率等级 | B24: =VLOOKUP(B15,'Total Result'!$A$3:$N$7,8,FALSE) -> 0 | C24: =VLOOKUP(B16,'Total Result'!$A$3:$N$7,8,FALSE) -> 0 | D24: 偏移几率等级 | E24: =VLOOKUP(E15,'Total Result'!$A$3:$N$7,8,FALSE) -> 0 | F24: =VLOOKUP(E16,'Total Result'!$A$3:$N$7,8,FALSE) -> 0 | G24: 偏移几率等级 | H24: =VLOOKUP(H15,'Total Result'!$A$3:$N$7,8,FALSE) -> 0 | I24: =VLOOKUP(H16,'Total Result'!$A$3:$N$7,8,FALSE) -> 0 | J24: 偏移几率等级 | K24: =VLOOKUP(K15,'Total Result'!$A$3:$N$7,8,FALSE) -> 0 | L24: =VLOOKUP(K16,'Total Result'!$A$3:$N$7,8,FALSE) -> 0
A25: 偏移减伤等级 | B25: =VLOOKUP(B15,'Total Result'!$A$3:$N$7,9,FALSE) -> 0 | C25: =VLOOKUP(B16,'Total Result'!$A$3:$N$7,9,FALSE) -> 0 | D25: 偏移减伤等级 | E25: =VLOOKUP(E15,'Total Result'!$A$3:$N$7,9,FALSE) -> 0 | F25: =VLOOKUP(E16,'Total Result'!$A$3:$N$7,9,FALSE) -> 0 | G25: 偏移减伤等级 | H25: =VLOOKUP(H15,'Total Result'!$A$3:$N$7,9,FALSE) -> 0 | I25: =VLOOKUP(H16,'Total Result'!$A$3:$N$7,9,FALSE) -> 0 | J25: 偏移减伤等级 | K25: =VLOOKUP(K15,'Total Result'!$A$3:$N$7,9,FALSE) -> 0 | L25: =VLOOKUP(K16,'Total Result'!$A$3:$N$7,9,FALSE) -> 0
A26: 精准等级 | B26: =VLOOKUP(B15,'Total Result'!$A$3:$N$7,10,FALSE) -> 0 | C26: =VLOOKUP(B16,'Total Result'!$A$3:$N$7,10,FALSE) -> 0 | D26: 精准等级 | E26: =VLOOKUP(E15,'Total Result'!$A$3:$N$7,10,FALSE) -> 0 | F26: =VLOOKUP(E16,'Total Result'!$A$3:$N$7,10,FALSE) -> 0 | G26: 精准等级 | H26: =VLOOKUP(H15,'Total Result'!$A$3:$N$7,10,FALSE) -> 0 | I26: =VLOOKUP(H16,'Total Result'!$A$3:$N$7,10,FALSE) -> 0 | J26: 精准等级 | K26: =VLOOKUP(K15,'Total Result'!$A$3:$N$7,10,FALSE) -> 0 | L26: =VLOOKUP(K16,'Total Result'!$A$3:$N$7,10,FALSE) -> 0
A27: 护甲穿透 | B27: =VLOOKUP(B15,'Total Result'!$A$3:$N$7,11,FALSE) -> 0 | C27: =VLOOKUP(B16,'Total Result'!$A$3:$N$7,11,FALSE) -> 0 | D27: 护甲穿透 | E27: =VLOOKUP(E15,'Total Result'!$A$3:$N$7,11,FALSE) -> 0 | F27: =VLOOKUP(E16,'Total Result'!$A$3:$N$7,11,FALSE) -> 0 | G27: 护甲穿透 | H27: =VLOOKUP(H15,'Total Result'!$A$3:$N$7,11,FALSE) -> 0 | I27: =VLOOKUP(H16,'Total Result'!$A$3:$N$7,11,FALSE) -> 0 | J27: 护甲穿透 | K27: =VLOOKUP(K15,'Total Result'!$A$3:$N$7,11,FALSE) -> 0 | L27: =VLOOKUP(K16,'Total Result'!$A$3:$N$7,11,FALSE) -> 0
A28: 韧性等级 | B28: =VLOOKUP(B15,'Total Result'!$A$3:$N$7,12,FALSE) -> 0 | C28: =VLOOKUP(B16,'Total Result'!$A$3:$N$7,12,FALSE) -> 0 | D28: 韧性等级 | E28: =VLOOKUP(E15,'Total Result'!$A$3:$N$7,12,FALSE) -> 0 | F28: =VLOOKUP(E16,'Total Result'!$A$3:$N$7,12,FALSE) -> 0 | G28: 韧性等级 | H28: =VLOOKUP(H15,'Total Result'!$A$3:$N$7,12,FALSE) -> 0 | I28: =VLOOKUP(H16,'Total Result'!$A$3:$N$7,12,FALSE) -> 0 | J28: 韧性等级 | K28: =VLOOKUP(K15,'Total Result'!$A$3:$N$7,12,FALSE) -> 0 | L28: =VLOOKUP(K16,'Total Result'!$A$3:$N$7,12,FALSE) -> 0
A29: 攻击类型 （等待整理） | B29: =VLOOKUP(B15,'Total Result'!$A$3:$N$7,13,FALSE) -> 1 | C29: =VLOOKUP(B16,'Total Result'!$A$3:$N$7,13,FALSE) -> 1 | D29: 攻击类型 （等待整理） | E29: =VLOOKUP(E15,'Total Result'!$A$3:$N$7,13,FALSE) -> 1 | F29: =VLOOKUP(E16,'Total Result'!$A$3:$N$7,13,FALSE) -> 1 | G29: 攻击类型 （等待整理） | H29: =VLOOKUP(H15,'Total Result'!$A$3:$N$7,13,FALSE) -> 1 | I29: =VLOOKUP(H16,'Total Result'!$A$3:$N$7,13,FALSE) -> 1 | J29: 攻击类型 （等待整理） | K29: =VLOOKUP(K15,'Total Result'!$A$3:$N$7,13,FALSE) -> 1 | L29: =VLOOKUP(K16,'Total Result'!$A$3:$N$7,13,FALSE) -> 1
A30: 护甲类型 （等待整理） | B30: =VLOOKUP(B15,'Total Result'!$A$3:$N$7,14,FALSE) -> 1 | C30: =VLOOKUP(B16,'Total Result'!$A$3:$N$7,14,FALSE) -> 1 | D30: 护甲类型 （等待整理） | E30: =VLOOKUP(E15,'Total Result'!$A$3:$N$7,14,FALSE) -> 1 | F30: =VLOOKUP(E16,'Total Result'!$A$3:$N$7,14,FALSE) -> 1 | G30: 护甲类型 （等待整理） | H30: =VLOOKUP(H15,'Total Result'!$A$3:$N$7,14,FALSE) -> 1 | I30: =VLOOKUP(H16,'Total Result'!$A$3:$N$7,14,FALSE) -> 1 | J30: 护甲类型 （等待整理） | K30: =VLOOKUP(K15,'Total Result'!$A$3:$N$7,14,FALSE) -> 1 | L30: =VLOOKUP(K16,'Total Result'!$A$3:$N$7,14,FALSE) -> 1
A32: 护甲减伤率 | B32: =(C21-B27)/(C21-B27+B18*1.5+28.5) -> 0 | D32: 护甲减伤率 | E32: =(F21-E27)/(F21-E27+E18*1.5+28.5) -> 0 | G32: 护甲减伤率 | H32: =(I21-H27)/(I21-H27+H18*1.5+28.5) -> 0 | J32: 护甲减伤率 | K32: =(L21-K27)/(L21-K27+K18*1.5+28.5) -> 0
A33: RPS差 | B33: =VLOOKUP(战斗模拟1!B15,'Total Result'!$A$2:$N$7,13,TRUE)-VLOOKUP(战斗模拟1!B16,'Total Result'!$A$2:$N$7,14,TRUE) -> 0 | D33: RPS差 | E33: =VLOOKUP(战斗模拟1!E15,'Total Result'!$A$2:$N$7,13,TRUE)-VLOOKUP(战斗模拟1!E16,'Total Result'!$A$2:$N$7,14,TRUE) -> 0 | G33: RPS差 | H33: =VLOOKUP(战斗模拟1!H15,'Total Result'!$A$2:$N$7,13,TRUE)-VLOOKUP(战斗模拟1!H16,'Total Result'!$A$2:$N$7,14,TRUE) -> 0 | J33: RPS差 | K33: =VLOOKUP(战斗模拟1!K15,'Total Result'!$A$2:$N$7,13,TRUE)-VLOOKUP(战斗模拟1!K16,'Total Result'!$A$2:$N$7,14,TRUE) -> 0
A34: RPS结果系数 | B34: =IF(MOD(B33,3)=0,100%,IF(MOD(B33,3)=1,90%,110%)) -> 1 | D34: RPS结果系数 | E34: =IF(MOD(E33,3)=0,100%,IF(MOD(E33,3)=1,90%,110%)) -> 1 | G34: RPS结果系数 | H34: =IF(MOD(H33,3)=0,100%,IF(MOD(H33,3)=1,90%,110%)) -> 1 | J34: RPS结果系数 | K34: =IF(MOD(K33,3)=0,100%,IF(MOD(K33,3)=1,90%,110%)) -> 1
A35: 普通击中伤害 | B35: =B20*(1-B32)*B34 -> 30 | D35: 普通击中伤害 | E35: =E20*(1-E32)*E34 -> 20 | G35: 普通击中伤害 | H35: =H20*(1-H32)*H34 -> 20 | J35: 普通击中伤害 | K35: =K20*(1-K32)*K34 -> 30
A36: 偏移几率 | B36: =IF((C24-B26)/(6.7*B18+126.7)+5%>70%,70%,(C24-B26)/(6.7*B18+126.7)+5%) -> 0.05 | D36: 偏移几率 | E36: =IF((F24-E26)/(6.7*E18+126.7)+5%>70%,70%,(F24-E26)/(6.7*E18+126.7)+5%) -> 0.05 | G36: 偏移几率 | H36: =IF((I24-H26)/(6.7*H18+126.7)+5%>70%,70%,(I24-H26)/(6.7*H18+126.7)+5%) -> 0.05 | J36: 偏移几率 | K36: =IF((L24-K26)/(6.7*K18+126.7)+5%>70%,70%,(L24-K26)/(6.7*K18+126.7)+5%) -> 0.05
A37: 是否发生偏移 | B37: =IF(RAND()<B36,1,0) -> 0 | D37: 是否发生偏移 | E37: =IF(RAND()<E36,1,0) -> 0 | G37: 是否发生偏移 | H37: =IF(RAND()<H36,1,0) -> 0 | J37: 是否发生偏移 | K37: =IF(RAND()<K36,1,0) -> 0
A38: 偏移减伤比率 | B38: =IF(C25/(8.3*B18+158.3)+33%>67%,67%,C25/(8.3*B18+158.3)+33%) -> 0.33 | D38: 偏移减伤比率 | E38: =IF(F25/(8.3*E18+158.3)+33%>67%,67%,F25/(8.3*E18+158.3)+33%) -> 0.33 | G38: 偏移减伤比率 | H38: =IF(I25/(8.3*H18+158.3)+33%>67%,67%,I25/(8.3*H18+158.3)+33%) -> 0.33 | J38: 偏移减伤比率 | K38: =IF(L25/(8.3*K18+158.3)+33%>67%,67%,L25/(8.3*K18+158.3)+33%) -> 0.33
A39: 暴击几率 | B39: =IF(B22/(4*C18+76)+5%>70%,70%,B22/(4*C18+76)+5%) -> 0.05 | D39: 暴击几率 | E39: =IF(E22/(4*F18+76)+5%>70%,70%,E22/(4*F18+76)+5%) -> 0.05 | G39: 暴击几率 | H39: =IF(H22/(4*I18+76)+5%>70%,70%,H22/(4*I18+76)+5%) -> 0.05 | J39: 暴击几率 | K39: =IF(K22/(4*L18+76)+5%>70%,70%,K22/(4*L18+76)+5%) -> 0.05
A40: 是否发生暴击 | B40: =IF(RAND()<B39,1,0) -> 0 | D40: 是否发生暴击 | E40: =IF(RAND()<E39,1,0) -> 0 | G40: 是否发生暴击 | H40: =IF(RAND()<H39,1,0) -> 0 | J40: 是否发生暴击 | K40: =IF(RAND()<K39,1,0) -> 0
A41: 暴击伤害率 | B41: =IF((B23-C28)/(5*C18+95)+50%>200%,200%,(B23-C28)/(5*C18+95)+50%) -> 0.5 | D41: 暴击伤害率 | E41: =IF((E23-F28)/(5*F18+95)+50%>200%,200%,(E23-F28)/(5*F18+95)+50%) -> 0.5 | G41: 暴击伤害率 | H41: =IF((H23-I28)/(5*I18+95)+50%>200%,200%,(H23-I28)/(5*I18+95)+50%) -> 0.5 | J41: 暴击伤害率 | K41: =IF((K23-L28)/(5*L18+95)+50%>200%,200%,(K23-L28)/(5*L18+95)+50%) -> 0.5
A42: 5%随机 | B42: =RAND()*0.1+0.95 -> 0.95313996 | D42: 5%随机 | E42: =RAND()*0.1+0.95 -> 1.021539 | G42: 5%随机 | H42: =RAND()*0.1+0.95 -> 0.97661999 | J42: 5%随机 | K42: =RAND()*0.1+0.95 -> 0.9563743
A43: 本次伤害 | B43: =ROUND(B35*(1+B40*B41)*(1-B37*B38)*B42*B12,0) -> 29 | D43: 本次伤害 | E43: =ROUND(E35*(1+E40*E41)*(1-E37*E38)*E42*E12,0) -> 20 | G43: 本次伤害 | H43: =ROUND(H35*(1+H40*H41)*(1-H37*H38)*H42*H12,0) -> 20 | J43: 本次伤害 | K43: =ROUND(K35*(1+K40*K41)*(1-K37*K38)*K42*K12,0) -> 29
A45: A方所受伤害 | B45: =H43+K43 -> 49 | D45: 是否伤害在A1？ | E45: =E12 -> 1 | G45: B方所受伤害 | H45: =B43+E43 -> 49 | J45: 是否伤害在B1？ | K45: =H12 -> 1
A46: A2输出 | B46: =B43 -> 29 | D46: A1输出 | E46: =E43 -> 20 | G46: B1输出 | H46: =H43 -> 20 | J46: B2输出 | K46: =K43 -> 29
A47: A2剩余血量 | B47: =MAX(B7-(1-E45)*B45,0) -> 160 | D47: A1剩余血量 | E47: =MAX(0,E7-E45*B45) -> 191 | G47: B1剩余血量 | H47: =MAX(0,H7-H45*K45) -> 191 | J47: B2剩余血量 | K47: =MAX(K7-(1-K45)*H45,0) -> 160
...

Sheet 战斗模拟2
A1: 开始时4辆车的血量 | B1: 检测4辆车的状态，若已经死亡则不发射炮弹 | C1: 检测对方前排是否存活 | D1: 检测对方后排是否存活 | E1: 让其战斗30轮 | F1: 记录10轮的剩余血量结果
F2: 战斗结果
B3: =B1208 -> 0 | E3: =E1208 -> 0 | F3: 楚河 | H3: =H1208 -> 0 | K3: =K1208 -> 0
B4: A2 | E4: A1 | F4: 汉界 | H4: B1 | K4: B2
A7: A2初始血量： | B7: ='Total Result'!C3 -> 160 | D7: A1初始血量： | E7: ='Total Result'!C4 -> 240 | G7: B1初始血量 | H7: ='Total Result'!C6 -> 240 | J7: B2初始血量 | K7: ='Total Result'!C7 -> 160
A8: 百分比： | B8: 1 | D8: 百分比 | E8: 1 | G8: 百分比 | H8: 1 | J8: 百分比 | K8: 1
A10: 攻击轮数： | B10: 1
A12: A2是否存活？（上轮A2血量是否大于0？） | B12: =IF(B7>0,1,0) -> 1 | D12: A1是否存活？（上轮A1血量是否大于0？） | E12: =IF(E7>0,1,0) -> 1 | G12: B1是否存活？（上轮B1血量是否大于0？） | H12: =IF(H7>0,1,0) -> 1 | J12: B2是否存活？（上轮B2血量是否大于0？） | K12: =IF(K7>0,1,0) -> 1
A14: A2攻击 | D14: A1攻击 | G14: B1攻击 | J14: B2攻击
A15: 攻击方 | B15: A2 | D15: 攻击方 | E15: A1 | G15: 攻击方 | H15: B1 | J15: 攻击方 | K15: B2
A16: 对象 | B16: =IF($H7>0,"B1","B2") -> B1 | D16: 对象 | E16: =IF($H7>0,"B1","B2") -> B1 | G16: 对象 | H16: =IF($E7>0,"A1","A2") -> A1 | J16: 对象 | K16: =IF(E7>0,"A1","A2") -> A1
A17: 属性 | B17: 攻击方 | C17: 防御方 | D17: 属性 | E17: 攻击方 | F17: 防御方 | G17: 属性 | H17: 攻击方 | I17: 防御方 | J17: 属性 | K17: 攻击方 | L17: 防御方
A18: 级别 | B18: =VLOOKUP(B15,'Total Result'!$A$3:$N$7,2,FALSE) -> 1 | C18: =VLOOKUP(B16,'Total Result'!$A$3:$N$7,2,FALSE) -> 1 | D18: 级别 | E18: =VLOOKUP(E15,'Total Result'!$A$3:$N$7,2,FALSE) -> 1 | F18: =VLOOKUP(E16,'Total Result'!$A$3:$N$7,2,FALSE) -> 1 | G18: 级别 | H18: =VLOOKUP(H15,'Total Result'!$A$3:$N$7,2,FALSE) -> 1 | I18: =VLOOKUP(H16,'Total Result'!$A$3:$N$7,2,FALSE) -> 1 | J18: 级别 | K18: =VLOOKUP(K15,'Total Result'!$A$3:$N$7,2,FALSE) -> 1 | L18: =VLOOKUP(K16,'Total Result'!$A$3:$N$7,2,FALSE) -> 1
A19: 生命值上限 | B19: =VLOOKUP(B15,'Total Result'!$A$3:$N$7,3,FALSE) -> 160 | C19: =VLOOKUP(B16,'Total Result'!$A$3:$N$7,3,FALSE) -> 240 | D19: 生命值上限 | E19: =VLOOKUP(E15,'Total Result'!$A$3:$N$7,3,FALSE) -> 240 | F19: =VLOOKUP(E16,'Total Result'!$A$3:$N$7,3,FALSE) -> 240 | G19: 生命值上限 | H19: =VLOOKUP(H15,'Total Result'!$A$3:$N$7,3,FALSE) -> 240 | I19: =VLOOKUP(H16,'Total Result'!$A$3:$N$7,3,FALSE) -> 240 | J19: 生命值上限 | K19: =VLOOKUP(K15,'Total Result'!$A$3:$N$7,3,FALSE) -> 160 | L19: =VLOOKUP(K16,'Total Result'!$A$3:$N$7,3,FALSE) -> 240
A20: 攻击力 | B20: =VLOOKUP(B15,'Total Result'!$A$3:$N$7,4,FALSE) -> 30 | C20: =VLOOKUP(B16,'Total Result'!$A$3:$N$7,4,FALSE) -> 20 | D20: 攻击力 | E20: =VLOOKUP(E15,'Total Result'!$A$3:$N$7,4,FALSE) -> 20 | F20: =VLOOKUP(E16,'Total Result'!$A$3:$N$7,4,FALSE) -> 20 | G20: 攻击力 | H20: =VLOOKUP(H15,'Total Result'!$A$3:$N$7,4,FALSE) -> 20 | I20: =VLOOKUP(H16,'Total Result'!$A$3:$N$7,4,FALSE) -> 20 | J20: 攻击力 | K20: =VLOOKUP(K15,'Total Result'!$A$3:$N$7,4,FALSE) -> 30 | L20: =VLOOKUP(K16,'Total Result'!$A$3:$N$7,4,FALSE) -> 20
A21: 护甲 | B21: =VLOOKUP(B15,'Total Result'!$A$3:$N$7,5,FALSE) -> 0 | C21: =VLOOKUP(B16,'Total Result'!$A$3:$N$7,5,FALSE) -> 0 | D21: 护甲 | E21: =VLOOKUP(E15,'Total Result'!$A$3:$N$7,5,FALSE) -> 0 | F21: =VLOOKUP(E16,'Total Result'!$A$3:$N$7,5,FALSE) -> 0 | G21: 护甲 | H21: =VLOOKUP(H15,'Total Result'!$A$3:$N$7,5,FALSE) -> 0 | I21: =VLOOKUP(H16,'Total Result'!$A$3:$N$7,5,FALSE) -> 0 | J21: 护甲 | K21: =VLOOKUP(K15,'Total Result'!$A$3:$N$7,5,FALSE) -> 0 | L21: =VLOOKUP(K16,'Total Result'!$A$3:$N$7,5,FALSE) -> 0
A22: 暴击几率等级 | B22: =VLOOKUP(B15,'Total Result'!$A$3:$N$7,6,FALSE) -> 0 | C22: =VLOOKUP(B16,'Total Result'!$A$3:$N$7,6,FALSE) -> 0 | D22: 暴击几率等级 | E22: =VLOOKUP(E15,'Total Result'!$A$3:$N$7,6,FALSE) -> 0 | F22: =VLOOKUP(E16,'Total Result'!$A$3:$N$7,6,FALSE) -> 0 | G22: 暴击几率等级 | H22: =VLOOKUP(H15,'Total Result'!$A$3:$N$7,6,FALSE) -> 0 | I22: =VLOOKUP(H16,'Total Result'!$A$3:$N$7,6,FALSE) -> 0 | J22: 暴击几率等级 | K22: =VLOOKUP(K15,'Total Result'!$A$3:$N$7,6,FALSE) -> 0 | L22: =VLOOKUP(K16,'Total Result'!$A$3:$N$7,6,FALSE) -> 0
A23: 暴击伤害等级 | B23: =VLOOKUP(B15,'Total Result'!$A$3:$N$7,7,FALSE) -> 0 | C23: =VLOOKUP(B16,'Total Result'!$A$3:$N$7,7,FALSE) -> 0 | D23: 暴击伤害等级 | E23: =VLOOKUP(E15,'Total Result'!$A$3:$N$7,7,FALSE) -> 0 | F23: =VLOOKUP(E16,'Total Result'!$A$3:$N$7,7,FALSE) -> 0 | G23: 暴击伤害等级 | H23: =VLOOKUP(H15,'Total Result'!$A$3:$N$7,7,FALSE) -> 0 | I23: =VLOOKUP(H16,'Total Result'!$A$3:$N$7,7,FALSE) -> 0 | J23: 暴击伤害等级 | K23: =VLOOKUP(K15,'Total Result'!$A$3:$N$7,7,FALSE) -> 0 | L23: =VLOOKUP(K16,'Total Result'!$A$3:$N$7,7,FALSE) -> 0
A24: 偏移几率等级 | B24: =VLOOKUP(B15,'Total Result'!$A$3:$N$7,8,FALSE) -> 0 | C24: =VLOOKUP(B16,'Total Result'!$A$3:$N$7,8,FALSE) -> 0 | D24: 偏移几率等级 | E24: =VLOOKUP(E15,'Total Result'!$A$3:$N$7,8,FALSE) -> 0 | F24: =VLOOKUP(E16,'Total Result'!$A$3:$N$7,8,FALSE) -> 0 | G24: 偏移几率等级 | H24: =VLOOKUP(H15,'Total Result'!$A$3:$N$7,8,FALSE) -> 0 | I24: =VLOOKUP(H16,'Total Result'!$A$3:$N$7,8,FALSE) -> 0 | J24: 偏移几率等级 | K24: =VLOOKUP(K15,'Total Result'!$A$3:$N$7,8,FALSE) -> 0 | L24: =VLOOKUP(K16,'Total Result'!$A$3:$N$7,8,FALSE) -> 0
A25: 偏移减伤等级 | B25: =VLOOKUP(B15,'Total Result'!$A$3:$N$7,9,FALSE) -> 0 | C25: =VLOOKUP(B16,'Total Result'!$A$3:$N$7,9,FALSE) -> 0 | D25: 偏移减伤等级 | E25: =VLOOKUP(E15,'Total Result'!$A$3:$N$7,9,FALSE) -> 0 | F25: =VLOOKUP(E16,'Total Result'!$A$3:$N$7,9,FALSE) -> 0 | G25: 偏移减伤等级 | H25: =VLOOKUP(H15,'Total Result'!$A$3:$N$7,9,FALSE) -> 0 | I25: =VLOOKUP(H16,'Total Result'!$A$3:$N$7,9,FALSE) -> 0 | J25: 偏移减伤等级 | K25: =VLOOKUP(K15,'Total Result'!$A$3:$N$7,9,FALSE) -> 0 | L25: =VLOOKUP(K16,'Total Result'!$A$3:$N$7,9,FALSE) -> 0
A26: 精准等级 | B26: =VLOOKUP(B15,'Total Result'!$A$3:$N$7,10,FALSE) -> 0 | C26: =VLOOKUP(B16,'Total Result'!$A$3:$N$7,10,FALSE) -> 0 | D26: 精准等级 | E26: =VLOOKUP(E15,'Total Result'!$A$3:$N$7,10,FALSE) -> 0 | F26: =VLOOKUP(E16,'Total Result'!$A$3:$N$7,10,FALSE) -> 0 | G26: 精准等级 | H26: =VLOOKUP(H15,'Total Result'!$A$3:$N$7,10,FALSE) -> 0 | I26: =VLOOKUP(H16,'Total Result'!$A$3:$N$7,10,FALSE) -> 0 | J26: 精准等级 | K26: =VLOOKUP(K15,'Total Result'!$A$3:$N$7,10,FALSE) -> 0 | L26: =VLOOKUP(K16,'Total Result'!$A$3:$N$7,10,FALSE) -> 0
A27: 护甲穿透 | B27: =VLOOKUP(B15,'Total Result'!$A$3:$N$7,11,FALSE) -> 0 | C27: =VLOOKUP(B16,'Total Result'!$A$3:$N$7,11,FALSE) -> 0 | D27: 护甲穿透 | E27: =VLOOKUP(E15,'Total Result'!$A$3:$N$7,11,FALSE) -> 0 | F27: =VLOOKUP(E16,'Total Result'!$A$3:$N$7,11,FALSE) -> 0 | G27: 护甲穿透 | H27: =VLOOKUP(H15,'Total Result'!$A$3:$N$7,11,FALSE) -> 0 | I27: =VLOOKUP(H16,'Total Result'!$A$3:$N$7,11,FALSE) -> 0 | J27: 护甲穿透 | K27: =VLOOKUP(K15,'Total Result'!$A$3:$N$7,11,FALSE) -> 0 | L27: =VLOOKUP(K16,'Total Result'!$A$3:$N$7,11,FALSE) -> 0
A28: 韧性等级 | B28: =VLOOKUP(B15,'Total Result'!$A$3:$N$7,12,FALSE) -> 0 | C28: =VLOOKUP(B16,'Total Result'!$A$3:$N$7,12,FALSE) -> 0 | D28: 韧性等级 | E28: =VLOOKUP(E15,'Total Result'!$A$3:$N$7,12,FALSE) -> 0 | F28: =VLOOKUP(E16,'Total Result'!$A$3:$N$7,12,FALSE) -> 0 | G28: 韧性等级 | H28: =VLOOKUP(H15,'Total Result'!$A$3:$N$7,12,FALSE) -> 0 | I28: =VLOOKUP(H16,'Total Result'!$A$3:$N$7,12,FALSE) -> 0 | J28: 韧性等级 | K28: =VLOOKUP(K15,'Total Result'!$A$3:$N$7,12,FALSE) -> 0 | L28: =VLOOKUP(K16,'Total Result'!$A$3:$N$7,12,FALSE) -> 0
A29: 攻击类型 （等待整理） | B29: =VLOOKUP(B15,'Total Result'!$A$3:$N$7,13,FALSE) -> 1 | C29: =VLOOKUP(B16,'Total Result'!$A$3:$N$7,13,FALSE) -> 1 | D29: 攻击类型 （等待整理） | E29: =VLOOKUP(E15,'Total Result'!$A$3:$N$7,13,FALSE) -> 1 | F29: =VLOOKUP(E16,'Total Result'!$A$3:$N$7,13,FALSE) -> 1 | G29: 攻击类型 （等待整理） | H29: =VLOOKUP(H15,'Total Result'!$A$3:$N$7,13,FALSE) -> 1 | I29: =VLOOKUP(H16,'Total Result'!$A$3:$N$7,13,FALSE) -> 1 | J29: 攻击类型 （等待整理） | K29: =VLOOKUP(K15,'Total Result'!$A$3:$N$7,13,FALSE) -> 1 | L29: =VLOOKUP(K16,'Total Result'!$A$3:$N$7,13,FALSE) -> 1
A30: 护甲类型 （等待整理） | B30: =VLOOKUP(B15,'Total Result'!$A$3:$N$7,14,FALSE) -> 1 | C30: =VLOOKUP(B16,'Total Result'!$A$3:$N$7,14,FALSE) -> 1 | D30: 护甲类型 （等待整理） | E30: =VLOOKUP(E15,'Total Result'!$A$3:$N$7,14,FALSE) -> 1 | F30: =VLOOKUP(E16,'Total Result'!$A$3:$N$7,14,FALSE) -> 1 | G30: 护甲类型 （等待整理） | H30: =VLOOKUP(H15,'Total Result'!$A$3:$N$7,14,FALSE) -> 1 | I30: =VLOOKUP(H16,'Total Result'!$A$3:$N$7,14,FALSE) -> 1 | J30: 护甲类型 （等待整理） | K30: =VLOOKUP(K15,'Total Result'!$A$3:$N$7,14,FALSE) -> 1 | L30: =VLOOKUP(K16,'Total Result'!$A$3:$N$7,14,FALSE) -> 1
A32: 护甲减伤率 | B32: =(C21-B27)/(C21-B27+B18*1.5+28.5) -> 0 | D32: 护甲减伤率 | E32: =(F21-E27)/(F21-E27+E18*1.5+28.5) -> 0 | G32: 护甲减伤率 | H32: =(I21-H27)/(I21-H27+H18*1.5+28.5) -> 0 | J32: 护甲减伤率 | K32: =(L21-K27)/(L21-K27+K18*1.5+28.5) -> 0
A33: RPS差 | B33: =VLOOKUP(战斗模拟1!B15,'Total Result'!$A$2:$N$7,13,TRUE)-VLOOKUP(战斗模拟1!B16,'Total Result'!$A$2:$N$7,14,TRUE) -> 0 | D33: RPS差 | E33: =VLOOKUP(战斗模拟1!E15,'Total Result'!$A$2:$N$7,13,TRUE)-VLOOKUP(战斗模拟1!E16,'Total Result'!$A$2:$N$7,14,TRUE) -> 0 | G33: RPS差 | H33: =VLOOKUP(战斗模拟1!H15,'Total Result'!$A$2:$N$7,13,TRUE)-VLOOKUP(战斗模拟1!H16,'Total Result'!$A$2:$N$7,14,TRUE) -> 0 | J33: RPS差 | K33: =VLOOKUP(战斗模拟1!K15,'Total Result'!$A$2:$N$7,13,TRUE)-VLOOKUP(战斗模拟1!K16,'Total Result'!$A$2:$N$7,14,TRUE) -> 0
A34: RPS结果系数 | B34: =IF(MOD(B33,3)=0,100%,IF(MOD(B33,3)=1,90%,110%)) -> 1 | D34: RPS结果系数 | E34: =IF(MOD(E33,3)=0,100%,IF(MOD(E33,3)=1,90%,110%)) -> 1 | G34: RPS结果系数 | H34: =IF(MOD(H33,3)=0,100%,IF(MOD(H33,3)=1,90%,110%)) -> 1 | J34: RPS结果系数 | K34: =IF(MOD(K33,3)=0,100%,IF(MOD(K33,3)=1,90%,110%)) -> 1
A35: 普通击中伤害 | B35: =B20*(1-B32)*B34 -> 30 | D35: 普通击中伤害 | E35: =E20*(1-E32)*E34 -> 20 | G35: 普通击中伤害 | H35: =H20*(1-H32)*H34 -> 20 | J35: 普通击中伤害 | K35: =K20*(1-K32)*K34 -> 30
A36: 偏移几率 | B36: =IF((C24-B26)/(6.7*B18+126.7)+5%>70%,70%,(C24-B26)/(6.7*B18+126.7)+5%) -> 0.05 | D36: 偏移几率 | E36: =IF((F24-E26)/(6.7*E18+126.7)+5%>70%,70%,(F24-E26)/(6.7*E18+126.7)+5%) -> 0.05 | G36: 偏移几率 | H36: =IF((I24-H26)/(6.7*H18+126.7)+5%>70%,70%,(I24-H26)/(6.7*H18+126.7)+5%) -> 0.05 | J36: 偏移几率 | K36: =IF((L24-K26)/(6.7*K18+126.7)+5%>70%,70%,(L24-K26)/(6.7*K18+126.7)+5%) -> 0.05
A37: 是否发生偏移 | B37: =IF(RAND()<B36,1,0) -> 0 | D37: 是否发生偏移 | E37: =IF(RAND()<E36,1,0) -> 0 | G37: 是否发生偏移 | H37: =IF(RAND()<H36,1,0) -> 0 | J37: 是否发生偏移 | K37: =IF(RAND()<K36,1,0) -> 0
A38: 偏移减伤比率 | B38: =IF(C25/(8.3*B18+158.3)+33%>67%,67%,C25/(8.3*B18+158.3)+33%) -> 0.33 | D38: 偏移减伤比率 | E38: =IF(F25/(8.3*E18+158.3)+33%>67%,67%,F25/(8.3*E18+158.3)+33%) -> 0.33 | G38: 偏移减伤比率 | H38: =IF(I25/(8.3*H18+158.3)+33%>67%,67%,I25/(8.3*H18+158.3)+33%) -> 0.33 | J38: 偏移减伤比率 | K38: =IF(L25/(8.3*K18+158.3)+33%>67%,67%,L25/(8.3*K18+158.3)+33%) -> 0.33
A39: 暴击几率 | B39: =IF(B22/(4*C18+76)+5%>70%,70%,B22/(4*C18+76)+5%) -> 0.05 | D39: 暴击几率 | E39: =IF(E22/(4*F18+76)+5%>70%,70%,E22/(4*F18+76)+5%) -> 0.05 | G39: 暴击几率 | H39: =IF(H22/(4*I18+76)+5%>70%,70%,H22/(4*I18+76)+5%) -> 0.05 | J39: 暴击几率 | K39: =IF(K22/(4*L18+76)+5%>70%,70%,K22/(4*L18+76)+5%) -> 0.05
A40: 是否发生暴击 | B40: =IF(RAND()<B39,1,0) -> 0 | D40: 是否发生暴击 | E40: =IF(RAND()<E39,1,0) -> 0 | G40: 是否发生暴击 | H40: =IF(RAND()<H39,1,0) -> 1 | J40: 是否发生暴击 | K40: =IF(RAND()<K39,1,0) -> 0
A41: 暴击伤害率 | B41: =IF((B23-C28)/(5*C18+95)+50%>200%,200%,(B23-C28)/(5*C18+95)+50%) -> 0.5 | D41: 暴击伤害率 | E41: =IF((E23-F28)/(5*F18+95)+50%>200%,200%,(E23-F28)/(5*F18+95)+50%) -> 0.5 | G41: 暴击伤害率 | H41: =IF((H23-I28)/(5*I18+95)+50%>200%,200%,(H23-I28)/(5*I18+95)+50%) -> 0.5 | J41: 暴击伤害率 | K41: =IF((K23-L28)/(5*L18+95)+50%>200%,200%,(K23-L28)/(5*L18+95)+50%) -> 0.5
A42: 5%随机 | B42: =RAND()*0.1+0.95 -> 0.99517326 | D42: 5%随机 | E42: =RAND()*0.1+0.95 -> 0.98033819 | G42: 5%随机 | H42: =RAND()*0.1+0.95 -> 1.0249065 | J42: 5%随机 | K42: =RAND()*0.1+0.95 -> 0.95724962
A43: 本次伤害 | B43: =ROUND(B35*(1+B40*B41)*(1-B37*B38)*B42*B12,0) -> 30 | D43: 本次伤害 | E43: =ROUND(E35*(1+E40*E41)*(1-E37*E38)*E42*E12,0) -> 20 | G43: 本次伤害 | H43: =ROUND(H35*(1+H40*H41)*(1-H37*H38)*H42*H12,0) -> 31 | J43: 本次伤害 | K43: =ROUND(K35*(1+K40*K41)*(1-K37*K38)*K42*K12,0) -> 29
A45: A方所受伤害 | B45: =H43+K43 -> 60 | D45: 是否伤害在A1？ | E45: =E12 -> 1 | G45: B方所受伤害 | H45: =B43+E43 -> 50 | J45: 是否伤害在B1？ | K45: =H12 -> 1
A46: A2输出 | B46: =B43 -> 30 | D46: A1输出 | E46: =E43 -> 20 | G46: B1输出 | H46: =H43 -> 31 | J46: B2输出 | K46: =K43 -> 29
A47: A2剩余血量 | B47: =MAX(B7-(1-E45)*B45,0) -> 160 | D47: A1剩余血量 | E47: =MAX(0,E7-E45*B45) -> 180 | G47: B1剩余血量 | H47: =MAX(0,H7-H45*K45) -> 190 | J47: B2剩余血量 | K47: =MAX(K7-(1-K45)*H45,0) -> 160
...

Sheet 战斗模拟3
A1: 开始时4辆车的血量 | B1: 检测4辆车的状态，若已经死亡则不发射炮弹 | C1: 检测对方前排是否存活 | D1: 检测对方后排是否存活 | E1: 让其战斗30轮 | F1: 记录10轮的剩余血量结果
F2: 战斗结果
B3: =B1208 -> 0 | E3: =E1208 -> 0 | F3: 楚河 | H3: =H1208 -> 0 | K3: =K1208 -> 0
B4: A2 | E4: A1 | F4: 汉界 | H4: B1 | K4: B2
A7: A2初始血量： | B7: ='Total Result'!C3 -> 160 | D7: A1初始血量： | E7: ='Total Result'!C4 -> 240 | G7: B1初始血量 | H7: ='Total Result'!C6 -> 240 | J7: B2初始血量 | K7: ='Total Result'!C7 -> 160
A8: 百分比： | B8: 1 | D8: 百分比 | E8: 1 | G8: 百分比 | H8: 1 | J8: 百分比 | K8: 1
A10: 攻击轮数： | B10: 1
A12: A2是否存活？（上轮A2血量是否大于0？） | B12: =IF(B7>0,1,0) -> 1 | D12: A1是否存活？（上轮A1血量是否大于0？） | E12: =IF(E7>0,1,0) -> 1 | G12: B1是否存活？（上轮B1血量是否大于0？） | H12: =IF(H7>0,1,0) -> 1 | J12: B2是否存活？（上轮B2血量是否大于0？） | K12: =IF(K7>0,1,0) -> 1
A14: A2攻击 | D14: A1攻击 | G14: B1攻击 | J14: B2攻击
A15: 攻击方 | B15: A2 | D15: 攻击方 | E15: A1 | G15: 攻击方 | H15: B1 | J15: 攻击方 | K15: B2
A16: 对象 | B16: =IF($H7>0,"B1","B2") -> B1 | D16: 对象 | E16: =IF($H7>0,"B1","B2") -> B1 | G16: 对象 | H16: =IF($E7>0,"A1","A2") -> A1 | J16: 对象 | K16: =IF(E7>0,"A1","A2") -> A1
A17: 属性 | B17: 攻击方 | C17: 防御方 | D17: 属性 | E17: 攻击方 | F17: 防御方 | G17: 属性 | H17: 攻击方 | I17: 防御方 | J17: 属性 | K17: 攻击方 | L17: 防御方
A18: 级别 | B18: =VLOOKUP(B15,'Total Result'!$A$3:$N$7,2,FALSE) -> 1 | C18: =VLOOKUP(B16,'Total Result'!$A$3:$N$7,2,FALSE) -> 1 | D18: 级别 | E18: =VLOOKUP(E15,'Total Result'!$A$3:$N$7,2,FALSE) -> 1 | F18: =VLOOKUP(E16,'Total Result'!$A$3:$N$7,2,FALSE) -> 1 | G18: 级别 | H18: =VLOOKUP(H15,'Total Result'!$A$3:$N$7,2,FALSE) -> 1 | I18: =VLOOKUP(H16,'Total Result'!$A$3:$N$7,2,FALSE) -> 1 | J18: 级别 | K18: =VLOOKUP(K15,'Total Result'!$A$3:$N$7,2,FALSE) -> 1 | L18: =VLOOKUP(K16,'Total Result'!$A$3:$N$7,2,FALSE) -> 1
A19: 生命值上限 | B19: =VLOOKUP(B15,'Total Result'!$A$3:$N$7,3,FALSE) -> 160 | C19: =VLOOKUP(B16,'Total Result'!$A$3:$N$7,3,FALSE) -> 240 | D19: 生命值上限 | E19: =VLOOKUP(E15,'Total Result'!$A$3:$N$7,3,FALSE) -> 240 | F19: =VLOOKUP(E16,'Total Result'!$A$3:$N$7,3,FALSE) -> 240 | G19: 生命值上限 | H19: =VLOOKUP(H15,'Total Result'!$A$3:$N$7,3,FALSE) -> 240 | I19: =VLOOKUP(H16,'Total Result'!$A$3:$N$7,3,FALSE) -> 240 | J19: 生命值上限 | K19: =VLOOKUP(K15,'Total Result'!$A$3:$N$7,3,FALSE) -> 160 | L19: =VLOOKUP(K16,'Total Result'!$A$3:$N$7,3,FALSE) -> 240
A20: 攻击力 | B20: =VLOOKUP(B15,'Total Result'!$A$3:$N$7,4,FALSE) -> 30 | C20: =VLOOKUP(B16,'Total Result'!$A$3:$N$7,4,FALSE) -> 20 | D20: 攻击力 | E20: =VLOOKUP(E15,'Total Result'!$A$3:$N$7,4,FALSE) -> 20 | F20: =VLOOKUP(E16,'Total Result'!$A$3:$N$7,4,FALSE) -> 20 | G20: 攻击力 | H20: =VLOOKUP(H15,'Total Result'!$A$3:$N$7,4,FALSE) -> 20 | I20: =VLOOKUP(H16,'Total Result'!$A$3:$N$7,4,FALSE) -> 20 | J20: 攻击力 | K20: =VLOOKUP(K15,'Total Result'!$A$3:$N$7,4,FALSE) -> 30 | L20: =VLOOKUP(K16,'Total Result'!$A$3:$N$7,4,FALSE) -> 20
A21: 护甲 | B21: =VLOOKUP(B15,'Total Result'!$A$3:$N$7,5,FALSE) -> 0 | C21: =VLOOKUP(B16,'Total Result'!$A$3:$N$7,5,FALSE) -> 0 | D21: 护甲 | E21: =VLOOKUP(E15,'Total Result'!$A$3:$N$7,5,FALSE) -> 0 | F21: =VLOOKUP(E16,'Total Result'!$A$3:$N$7,5,FALSE) -> 0 | G21: 护甲 | H21: =VLOOKUP(H15,'Total Result'!$A$3:$N$7,5,FALSE) -> 0 | I21: =VLOOKUP(H16,'Total Result'!$A$3:$N$7,5,FALSE) -> 0 | J21: 护甲 | K21: =VLOOKUP(K15,'Total Result'!$A$3:$N$7,5,FALSE) -> 0 | L21: =VLOOKUP(K16,'Total Result'!$A$3:$N$7,5,FALSE) -> 0
A22: 暴击几率等级 | B22: =VLOOKUP(B15,'Total Result'!$A$3:$N$7,6,FALSE) -> 0 | C22: =VLOOKUP(B16,'Total Result'!$A$3:$N$7,6,FALSE) -> 0 | D22: 暴击几率等级 | E22: =VLOOKUP(E15,'Total Result'!$A$3:$N$7,6,FALSE) -> 0 | F22: =VLOOKUP(E16,'Total Result'!$A$3:$N$7,6,FALSE) -> 0 | G22: 暴击几率等级 | H22: =VLOOKUP(H15,'Total Result'!$A$3:$N$7,6,FALSE) -> 0 | I22: =VLOOKUP(H16,'Total Result'!$A$3:$N$7,6,FALSE) -> 0 | J22: 暴击几率等级 | K22: =VLOOKUP(K15,'Total Result'!$A$3:$N$7,6,FALSE) -> 0 | L22: =VLOOKUP(K16,'Total Result'!$A$3:$N$7,6,FALSE) -> 0
A23: 暴击伤害等级 | B23: =VLOOKUP(B15,'Total Result'!$A$3:$N$7,7,FALSE) -> 0 | C23: =VLOOKUP(B16,'Total Result'!$A$3:$N$7,7,FALSE) -> 0 | D23: 暴击伤害等级 | E23: =VLOOKUP(E15,'Total Result'!$A$3:$N$7,7,FALSE) -> 0 | F23: =VLOOKUP(E16,'Total Result'!$A$3:$N$7,7,FALSE) -> 0 | G23: 暴击伤害等级 | H23: =VLOOKUP(H15,'Total Result'!$A$3:$N$7,7,FALSE) -> 0 | I23: =VLOOKUP(H16,'Total Result'!$A$3:$N$7,7,FALSE) -> 0 | J23: 暴击伤害等级 | K23: =VLOOKUP(K15,'Total Result'!$A$3:$N$7,7,FALSE) -> 0 | L23: =VLOOKUP(K16,'Total Result'!$A$3:$N$7,7,FALSE) -> 0
A24: 偏移几率等级 | B24: =VLOOKUP(B15,'Total Result'!$A$3:$N$7,8,FALSE) -> 0 | C24: =VLOOKUP(B16,'Total Result'!$A$3:$N$7,8,FALSE) -> 0 | D24: 偏移几率等级 | E24: =VLOOKUP(E15,'Total Result'!$A$3:$N$7,8,FALSE) -> 0 | F24: =VLOOKUP(E16,'Total Result'!$A$3:$N$7,8,FALSE) -> 0 | G24: 偏移几率等级 | H24: =VLOOKUP(H15,'Total Result'!$A$3:$N$7,8,FALSE) -> 0 | I24: =VLOOKUP(H16,'Total Result'!$A$3:$N$7,8,FALSE) -> 0 | J24: 偏移几率等级 | K24: =VLOOKUP(K15,'Total Result'!$A$3:$N$7,8,FALSE) -> 0 | L24: =VLOOKUP(K16,'Total Result'!$A$3:$N$7,8,FALSE) -> 0
A25: 偏移减伤等级 | B25: =VLOOKUP(B15,'Total Result'!$A$3:$N$7,9,FALSE) -> 0 | C25: =VLOOKUP(B16,'Total Result'!$A$3:$N$7,9,FALSE) -> 0 | D25: 偏移减伤等级 | E25: =VLOOKUP(E15,'Total Result'!$A$3:$N$7,9,FALSE) -> 0 | F25: =VLOOKUP(E16,'Total Result'!$A$3:$N$7,9,FALSE) -> 0 | G25: 偏移减伤等级 | H25: =VLOOKUP(H15,'Total Result'!$A$3:$N$7,9,FALSE) -> 0 | I25: =VLOOKUP(H16,'Total Result'!$A$3:$N$7,9,FALSE) -> 0 | J25: 偏移减伤等级 | K25: =VLOOKUP(K15,'Total Result'!$A$3:$N$7,9,FALSE) -> 0 | L25: =VLOOKUP(K16,'Total Result'!$A$3:$N$7,9,FALSE) -> 0
A26: 精准等级 | B26: =VLOOKUP(B15,'Total Result'!$A$3:$N$7,10,FALSE) -> 0 | C26: =VLOOKUP(B16,'Total Result'!$A$3:$N$7,10,FALSE) -> 0 | D26: 精准等级 | E26: =VLOOKUP(E15,'Total Result'!$A$3:$N$7,10,FALSE) -> 0 | F26: =VLOOKUP(E16,'Total Result'!$A$3:$N$7,10,FALSE) -> 0 | G26: 精准等级 | H26: =VLOOKUP(H15,'Total Result'!$A$3:$N$7,10,FALSE) -> 0 | I26: =VLOOKUP(H16,'Total Result'!$A$3:$N$7,10,FALSE) -> 0 | J26: 精准等级 | K26: =VLOOKUP(K15,'Total Result'!$A$3:$N$7,10,FALSE) -> 0 | L26: =VLOOKUP(K16,'Total Result'!$A$3:$N$7,10,FALSE) -> 0
A27: 护甲穿透 | B27: =VLOOKUP(B15,'Total Result'!$A$3:$N$7,11,FALSE) -> 0 | C27: =VLOOKUP(B16,'Total Result'!$A$3:$N$7,11,FALSE) -> 0 | D27: 护甲穿透 | E27: =VLOOKUP(E15,'Total Result'!$A$3:$N$7,11,FALSE) -> 0 | F27: =VLOOKUP(E16,'Total Result'!$A$3:$N$7,11,FALSE) -> 0 | G27: 护甲穿透 | H27: =VLOOKUP(H15,'Total Result'!$A$3:$N$7,11,FALSE) -> 0 | I27: =VLOOKUP(H16,'Total Result'!$A$3:$N$7,11,FALSE) -> 0 | J27: 护甲穿透 | K27: =VLOOKUP(K15,'Total Result'!$A$3:$N$7,11,FALSE) -> 0 | L27: =VLOOKUP(K16,'Total Result'!$A$3:$N$7,11,FALSE) -> 0
A28: 韧性等级 | B28: =VLOOKUP(B15,'Total Result'!$A$3:$N$7,12,FALSE) -> 0 | C28: =VLOOKUP(B16,'Total Result'!$A$3:$N$7,12,FALSE) -> 0 | D28: 韧性等级 | E28: =VLOOKUP(E15,'Total Result'!$A$3:$N$7,12,FALSE) -> 0 | F28: =VLOOKUP(E16,'Total Result'!$A$3:$N$7,12,FALSE) -> 0 | G28: 韧性等级 | H28: =VLOOKUP(H15,'Total Result'!$A$3:$N$7,12,FALSE) -> 0 | I28: =VLOOKUP(H16,'Total Result'!$A$3:$N$7,12,FALSE) -> 0 | J28: 韧性等级 | K28: =VLOOKUP(K15,'Total Result'!$A$3:$N$7,12,FALSE) -> 0 | L28: =VLOOKUP(K16,'Total Result'!$A$3:$N$7,12,FALSE) -> 0
A29: 攻击类型 （等待整理） | B29: =VLOOKUP(B15,'Total Result'!$A$3:$N$7,13,FALSE) -> 1 | C29: =VLOOKUP(B16,'Total Result'!$A$3:$N$7,13,FALSE) -> 1 | D29: 攻击类型 （等待整理） | E29: =VLOOKUP(E15,'Total Result'!$A$3:$N$7,13,FALSE) -> 1 | F29: =VLOOKUP(E16,'Total Result'!$A$3:$N$7,13,FALSE) -> 1 | G29: 攻击类型 （等待整理） | H29: =VLOOKUP(H15,'Total Result'!$A$3:$N$7,13,FALSE) -> 1 | I29: =VLOOKUP(H16,'Total Result'!$A$3:$N$7,13,FALSE) -> 1 | J29: 攻击类型 （等待整理） | K29: =VLOOKUP(K15,'Total Result'!$A$3:$N$7,13,FALSE) -> 1 | L29: =VLOOKUP(K16,'Total Result'!$A$3:$N$7,13,FALSE) -> 1
A30: 护甲类型 （等待整理） | B30: =VLOOKUP(B15,'Total Result'!$A$3:$N$7,14,FALSE) -> 1 | C30: =VLOOKUP(B16,'Total Result'!$A$3:$N$7,14,FALSE) -> 1 | D30: 护甲类型 （等待整理） | E30: =VLOOKUP(E15,'Total Result'!$A$3:$N$7,14,FALSE) -> 1 | F30: =VLOOKUP(E16,'Total Result'!$A$3:$N$7,14,FALSE) -> 1 | G30: 护甲类型 （等待整理） | H30: =VLOOKUP(H15,'Total Result'!$A$3:$N$7,14,FALSE) -> 1 | I30: =VLOOKUP(H16,'Total Result'!$A$3:$N$7,14,FALSE) -> 1 | J30: 护甲类型 （等待整理） | K30: =VLOOKUP(K15,'Total Result'!$A$3:$N$7,14,FALSE) -> 1 | L30: =VLOOKUP(K16,'Total Result'!$A$3:$N$7,14,FALSE) -> 1
A32: 护甲减伤率 | B32: =(C21-B27)/(C21-B27+B18*1.5+28.5) -> 0 | D32: 护甲减伤率 | E32: =(F21-E27)/(F21-E27+E18*1.5+28.5) -> 0 | G32: 护甲减伤率 | H32: =(I21-H27)/(I21-H27+H18*1.5+28.5) -> 0 | J32: 护甲减伤率 | K32: =(L21-K27)/(L21-K27+K18*1.5+28.5) -> 0
A33: RPS差 | B33: =VLOOKUP(战斗模拟1!B15,'Total Result'!$A$2:$N$7,13,TRUE)-VLOOKUP(战斗模拟1!B16,'Total Result'!$A$2:$N$7,14,TRUE) -> 0 | D33: RPS差 | E33: =VLOOKUP(战斗模拟1!E15,'Total Result'!$A$2:$N$7,13,TRUE)-VLOOKUP(战斗模拟1!E16,'Total Result'!$A$2:$N$7,14,TRUE) -> 0 | G33: RPS差 | H33: =VLOOKUP(战斗模拟1!H15,'Total Result'!$A$2:$N$7,13,TRUE)-VLOOKUP(战斗模拟1!H16,'Total Result'!$A$2:$N$7,14,TRUE) -> 0 | J33: RPS差 | K33: =VLOOKUP(战斗模拟1!K15,'Total Result'!$A$2:$N$7,13,TRUE)-VLOOKUP(战斗模拟1!K16,'Total Result'!$A$2:$N$7,14,TRUE) -> 0
A34: RPS结果系数 | B34: =IF(MOD(B33,3)=0,100%,IF(MOD(B33,3)=1,90%,110%)) -> 1 | D34: RPS结果系数 | E34: =IF(MOD(E33,3)=0,100%,IF(MOD(E33,3)=1,90%,110%)) -> 1 | G34: RPS结果系数 | H34: =IF(MOD(H33,3)=0,100%,IF(MOD(H33,3)=1,90%,110%)) -> 1 | J34: RPS结果系数 | K34: =IF(MOD(K33,3)=0,100%,IF(MOD(K33,3)=1,90%,110%)) -> 1
A35: 普通击中伤害 | B35: =B20*(1-B32)*B34 -> 30 | D35: 普通击中伤害 | E35: =E20*(1-E32)*E34 -> 20 | G35: 普通击中伤害 | H35: =H20*(1-H32)*H34 -> 20 | J35: 普通击中伤害 | K35: =K20*(1-K32)*K34 -> 30
A36: 偏移几率 | B36: =IF((C24-B26)/(6.7*B18+126.7)+5%>70%,70%,(C24-B26)/(6.7*B18+126.7)+5%) -> 0.05 | D36: 偏移几率 | E36: =IF((F24-E26)/(6.7*E18+126.7)+5%>70%,70%,(F24-E26)/(6.7*E18+126.7)+5%) -> 0.05 | G36: 偏移几率 | H36: =IF((I24-H26)/(6.7*H18+126.7)+5%>70%,70%,(I24-H26)/(6.7*H18+126.7)+5%) -> 0.05 | J36: 偏移几率 | K36: =IF((L24-K26)/(6.7*K18+126.7)+5%>70%,70%,(L24-K26)/(6.7*K18+126.7)+5%) -> 0.05
A37: 是否发生偏移 | B37: =IF(RAND()<B36,1,0) -> 0 | D37: 是否发生偏移 | E37: =IF(RAND()<E36,1,0) -> 0 | G37: 是否发生偏移 | H37: =IF(RAND()<H36,1,0) -> 0 | J37: 是否发生偏移 | K37: =IF(RAND()<K36,1,0) -> 0
A38: 偏移减伤比率 | B38: =IF(C25/(8.3*B18+158.3)+33%>67%,67%,C25/(8.3*B18+158.3)+33%) -> 0.33 | D38: 偏移减伤比率 | E38: =IF(F25/(8.3*E18+158.3)+33%>67%,67%,F25/(8.3*E18+158.3)+33%) -> 0.33 | G38: 偏移减伤比率 | H38: =IF(I25/(8.3*H18+158.3)+33%>67%,67%,I25/(8.3*H18+158.3)+33%) -> 0.33 | J38: 偏移减伤比率 | K38: =IF(L25/(8.3*K18+158.3)+33%>67%,67%,L25/(8.3*K18+158.3)+33%) -> 0.33
A39: 暴击几率 | B39: =IF(B22/(4*C18+76)+5%>70%,70%,B22/(4*C18+76)+5%) -> 0.05 | D39: 暴击几率 | E39: =IF(E22/(4*F18+76)+5%>70%,70%,E22/(4*F18+76)+5%) -> 0.05 | G39: 暴击几率 | H39: =IF(H22/(4*I18+76)+5%>70%,70%,H22/(4*I18+76)+5%) -> 0.05 | J39: 暴击几率 | K39: =IF(K22/(4*L18+76)+5%>70%,70%,K22/(4*L18+76)+5%) -> 0.05
A40: 是否发生暴击 | B40: =IF(RAND()<B39,1,0) -> 0 | D40: 是否发生暴击 | E40: =IF(RAND()<E39,1,0) -> 0 | G40: 是否发生暴击 | H40: =IF(RAND()<H39,1,0) -> 0 | J40: 是否发生暴击 | K40: =IF(RAND()<K39,1,0) -> 0
A41: 暴击伤害率 | B41: =IF((B23-C28)/(5*C18+95)+50%>200%,200%,(B23-C28)/(5*C18+95)+50%) -> 0.5 | D41: 暴击伤害率 | E41: =IF((E23-F28)/(5*F18+95)+50%>200%,200%,(E23-F28)/(5*F18+95)+50%) -> 0.5 | G41: 暴击伤害率 | H41: =IF((H23-I28)/(5*I18+95)+50%>200%,200%,(H23-I28)/(5*I18+95)+50%) -> 0.5 | J41: 暴击伤害率 | K41: =IF((K23-L28)/(5*L18+95)+50%>200%,200%,(K23-L28)/(5*L18+95)+50%) -> 0.5
A42: 5%随机 | B42: =RAND()*0.1+0.95 -> 1.010792 | D42: 5%随机 | E42: =RAND()*0.1+0.95 -> 0.97885453 | G42: 5%随机 | H42: =RAND()*0.1+0.95 -> 1.0005157 | J42: 5%随机 | K42: =RAND()*0.1+0.95 -> 1.0066139
A43: 本次伤害 | B43: =ROUND(B35*(1+B40*B41)*(1-B37*B38)*B42*B12,0) -> 30 | D43: 本次伤害 | E43: =ROUND(E35*(1+E40*E41)*(1-E37*E38)*E42*E12,0) -> 20 | G43: 本次伤害 | H43: =ROUND(H35*(1+H40*H41)*(1-H37*H38)*H42*H12,0) -> 20 | J43: 本次伤害 | K43: =ROUND(K35*(1+K40*K41)*(1-K37*K38)*K42*K12,0) -> 30
A45: A方所受伤害 | B45: =H43+K43 -> 50 | D45: 是否伤害在A1？ | E45: =E12 -> 1 | G45: B方所受伤害 | H45: =B43+E43 -> 50 | J45: 是否伤害在B1？ | K45: =H12 -> 1
A46: A2输出 | B46: =B43 -> 30 | D46: A1输出 | E46: =E43 -> 20 | G46: B1输出 | H46: =H43 -> 20 | J46: B2输出 | K46: =K43 -> 30
A47: A2剩余血量 | B47: =MAX(B7-(1-E45)*B45,0) -> 160 | D47: A1剩余血量 | E47: =MAX(0,E7-E45*B45) -> 190 | G47: B1剩余血量 | H47: =MAX(0,H7-H45*K45) -> 190 | J47: B2剩余血量 | K47: =MAX(K7-(1-K45)*H45,0) -> 160
...

Sheet 战斗模拟4
A1: 开始时4辆车的血量 | B1: 检测4辆车的状态，若已经死亡则不发射炮弹 | C1: 检测对方前排是否存活 | D1: 检测对方后排是否存活 | E1: 让其战斗30轮 | F1: 记录10轮的剩余血量结果
F2: 战斗结果
B3: =B1208 -> 0.15 | E3: =E1208 -> 0 | F3: 楚河 | H3: =H1208 -> 0 | K3: =K1208 -> 0
B4: A2 | E4: A1 | F4: 汉界 | H4: B1 | K4: B2
A7: A2初始血量： | B7: ='Total Result'!C3 -> 160 | D7: A1初始血量： | E7: ='Total Result'!C4 -> 240 | G7: B1初始血量 | H7: ='Total Result'!C6 -> 240 | J7: B2初始血量 | K7: ='Total Result'!C7 -> 160
A8: 百分比： | B8: 1 | D8: 百分比 | E8: 1 | G8: 百分比 | H8: 1 | J8: 百分比 | K8: 1
A10: 攻击轮数： | B10: 1
A12: A2是否存活？（上轮A2血量是否大于0？） | B12: =IF(B7>0,1,0) -> 1 | D12: A1是否存活？（上轮A1血量是否大于0？） | E12: =IF(E7>0,1,0) -> 1 | G12: B1是否存活？（上轮B1血量是否大于0？） | H12: =IF(H7>0,1,0) -> 1 | J12: B2是否存活？（上轮B2血量是否大于0？） | K12: =IF(K7>0,1,0) -> 1
A14: A2攻击 | D14: A1攻击 | G14: B1攻击 | J14: B2攻击
A15: 攻击方 | B15: A2 | D15: 攻击方 | E15: A1 | G15: 攻击方 | H15: B1 | J15: 攻击方 | K15: B2
A16: 对象 | B16: =IF($H7>0,"B1","B2") -> B1 | D16: 对象 | E16: =IF($H7>0,"B1","B2") -> B1 | G16: 对象 | H16: =IF($E7>0,"A1","A2") -> A1 | J16: 对象 | K16: =IF(E7>0,"A1","A2") -> A1
A17: 属性 | B17: 攻击方 | C17: 防御方 | D17: 属性 | E17: 攻击方 | F17: 防御方 | G17: 属性 | H17: 攻击方 | I17: 防御方 | J17: 属性 | K17: 攻击方 | L17: 防御方
A18: 级别 | B18: =VLOOKUP(B15,'Total Result'!$A$3:$N$7,2,FALSE) -> 1 | C18: =VLOOKUP(B16,'Total Result'!$A$3:$N$7,2,FALSE) -> 1 | D18: 级别 | E18: =VLOOKUP(E15,'Total Result'!$A$3:$N$7,2,FALSE) -> 1 | F18: =VLOOKUP(E16,'Total Result'!$A$3:$N$7,2,FALSE) -> 1 | G18: 级别 | H18: =VLOOKUP(H15,'Total Result'!$A$3:$N$7,2,FALSE) -> 1 | I18: =VLOOKUP(H16,'Total Result'!$A$3:$N$7,2,FALSE) -> 1 | J18: 级别 | K18: =VLOOKUP(K15,'Total Result'!$A$3:$N$7,2,FALSE) -> 1 | L18: =VLOOKUP(K16,'Total Result'!$A$3:$N$7,2,FALSE) -> 1
A19: 生命值上限 | B19: =VLOOKUP(B15,'Total Result'!$A$3:$N$7,3,FALSE) -> 160 | C19: =VLOOKUP(B16,'Total Result'!$A$3:$N$7,3,FALSE) -> 240 | D19: 生命值上限 | E19: =VLOOKUP(E15,'Total Result'!$A$3:$N$7,3,FALSE) -> 240 | F19: =VLOOKUP(E16,'Total Result'!$A$3:$N$7,3,FALSE) -> 240 | G19: 生命值上限 | H19: =VLOOKUP(H15,'Total Result'!$A$3:$N$7,3,FALSE) -> 240 | I19: =VLOOKUP(H16,'Total Result'!$A$3:$N$7,3,FALSE) -> 240 | J19: 生命值上限 | K19: =VLOOKUP(K15,'Total Result'!$A$3:$N$7,3,FALSE) -> 160 | L19: =VLOOKUP(K16,'Total Result'!$A$3:$N$7,3,FALSE) -> 240
A20: 攻击力 | B20: =VLOOKUP(B15,'Total Result'!$A$3:$N$7,4,FALSE) -> 30 | C20: =VLOOKUP(B16,'Total Result'!$A$3:$N$7,4,FALSE) -> 20 | D20: 攻击力 | E20: =VLOOKUP(E15,'Total Result'!$A$3:$N$7,4,FALSE) -> 20 | F20: =VLOOKUP(E16,'Total Result'!$A$3:$N$7,4,FALSE) -> 20 | G20: 攻击力 | H20: =VLOOKUP(H15,'Total Result'!$A$3:$N$7,4,FALSE) -> 20 | I20: =VLOOKUP(H16,'Total Result'!$A$3:$N$7,4,FALSE) -> 20 | J20: 攻击力 | K20: =VLOOKUP(K15,'Total Result'!$A$3:$N$7,4,FALSE) -> 30 | L20: =VLOOKUP(K16,'Total Result'!$A$3:$N$7,4,FALSE) -> 20
A21: 护甲 | B21: =VLOOKUP(B15,'Total Result'!$A$3:$N$7,5,FALSE) -> 0 | C21: =VLOOKUP(B16,'Total Result'!$A$3:$N$7,5,FALSE) -> 0 | D21: 护甲 | E21: =VLOOKUP(E15,'Total Result'!$A$3:$N$7,5,FALSE) -> 0 | F21: =VLOOKUP(E16,'Total Result'!$A$3:$N$7,5,FALSE) -> 0 | G21: 护甲 | H21: =VLOOKUP(H15,'Total Result'!$A$3:$N$7,5,FALSE) -> 0 | I21: =VLOOKUP(H16,'Total Result'!$A$3:$N$7,5,FALSE) -> 0 | J21: 护甲 | K21: =VLOOKUP(K15,'Total Result'!$A$3:$N$7,5,FALSE) -> 0 | L21: =VLOOKUP(K16,'Total Result'!$A$3:$N$7,5,FALSE) -> 0
A22: 暴击几率等级 | B22: =VLOOKUP(B15,'Total Result'!$A$3:$N$7,6,FALSE) -> 0 | C22: =VLOOKUP(B16,'Total Result'!$A$3:$N$7,6,FALSE) -> 0 | D22: 暴击几率等级 | E22: =VLOOKUP(E15,'Total Result'!$A$3:$N$7,6,FALSE) -> 0 | F22: =VLOOKUP(E16,'Total Result'!$A$3:$N$7,6,FALSE) -> 0 | G22: 暴击几率等级 | H22: =VLOOKUP(H15,'Total Result'!$A$3:$N$7,6,FALSE) -> 0 | I22: =VLOOKUP(H16,'Total Result'!$A$3:$N$7,6,FALSE) -> 0 | J22: 暴击几率等级 | K22: =VLOOKUP(K15,'Total Result'!$A$3:$N$7,6,FALSE) -> 0 | L22: =VLOOKUP(K16,'Total Result'!$A$3:$N$7,6,FALSE) -> 0
A23: 暴击伤害等级 | B23: =VLOOKUP(B15,'Total Result'!$A$3:$N$7,7,FALSE) -> 0 | C23: =VLOOKUP(B16,'Total Result'!$A$3:$N$7,7,FALSE) -> 0 | D23: 暴击伤害等级 | E23: =VLOOKUP(E15,'Total Result'!$A$3:$N$7,7,FALSE) -> 0 | F23: =VLOOKUP(E16,'Total Result'!$A$3:$N$7,7,FALSE) -> 0 | G23: 暴击伤害等级 | H23: =VLOOKUP(H15,'Total Result'!$A$3:$N$7,7,FALSE) -> 0 | I23: =VLOOKUP(H16,'Total Result'!$A$3:$N$7,7,FALSE) -> 0 | J23: 暴击伤害等级 | K23: =VLOOKUP(K15,'Total Result'!$A$3:$N$7,7,FALSE) -> 0 | L23: =VLOOKUP(K16,'Total Result'!$A$3:$N$7,7,FALSE) -> 0
A24: 偏移几率等级 | B24: =VLOOKUP(B15,'Total Result'!$A$3:$N$7,8,FALSE) -> 0 | C24: =VLOOKUP(B16,'Total Result'!$A$3:$N$7,8,FALSE) -> 0 | D24: 偏移几率等级 | E24: =VLOOKUP(E15,'Total Result'!$A$3:$N$7,8,FALSE) -> 0 | F24: =VLOOKUP(E16,'Total Result'!$A$3:$N$7,8,FALSE) -> 0 | G24: 偏移几率等级 | H24: =VLOOKUP(H15,'Total Result'!$A$3:$N$7,8,FALSE) -> 0 | I24: =VLOOKUP(H16,'Total Result'!$A$3:$N$7,8,FALSE) -> 0 | J24: 偏移几率等级 | K24: =VLOOKUP(K15,'Total Result'!$A$3:$N$7,8,FALSE) -> 0 | L24: =VLOOKUP(K16,'Total Result'!$A$3:$N$7,8,FALSE) -> 0
A25: 偏移减伤等级 | B25: =VLOOKUP(B15,'Total Result'!$A$3:$N$7,9,FALSE) -> 0 | C25: =VLOOKUP(B16,'Total Result'!$A$3:$N$7,9,FALSE) -> 0 | D25: 偏移减伤等级 | E25: =VLOOKUP(E15,'Total Result'!$A$3:$N$7,9,FALSE) -> 0 | F25: =VLOOKUP(E16,'Total Result'!$A$3:$N$7,9,FALSE) -> 0 | G25: 偏移减伤等级 | H25: =VLOOKUP(H15,'Total Result'!$A$3:$N$7,9,FALSE) -> 0 | I25: =VLOOKUP(H16,'Total Result'!$A$3:$N$7,9,FALSE) -> 0 | J25: 偏移减伤等级 | K25: =VLOOKUP(K15,'Total Result'!$A$3:$N$7,9,FALSE) -> 0 | L25: =VLOOKUP(K16,'Total Result'!$A$3:$N$7,9,FALSE) -> 0
A26: 精准等级 | B26: =VLOOKUP(B15,'Total Result'!$A$3:$N$7,10,FALSE) -> 0 | C26: =VLOOKUP(B16,'Total Result'!$A$3:$N$7,10,FALSE) -> 0 | D26: 精准等级 | E26: =VLOOKUP(E15,'Total Result'!$A$3:$N$7,10,FALSE) -> 0 | F26: =VLOOKUP(E16,'Total Result'!$A$3:$N$7,10,FALSE) -> 0 | G26: 精准等级 | H26: =VLOOKUP(H15,'Total Result'!$A$3:$N$7,10,FALSE) -> 0 | I26: =VLOOKUP(H16,'Total Result'!$A$3:$N$7,10,FALSE) -> 0 | J26: 精准等级 | K26: =VLOOKUP(K15,'Total Result'!$A$3:$N$7,10,FALSE) -> 0 | L26: =VLOOKUP(K16,'Total Result'!$A$3:$N$7,10,FALSE) -> 0
A27: 护甲穿透 | B27: =VLOOKUP(B15,'Total Result'!$A$3:$N$7,11,FALSE) -> 0 | C27: =VLOOKUP(B16,'Total Result'!$A$3:$N$7,11,FALSE) -> 0 | D27: 护甲穿透 | E27: =VLOOKUP(E15,'Total Result'!$A$3:$N$7,11,FALSE) -> 0 | F27: =VLOOKUP(E16,'Total Result'!$A$3:$N$7,11,FALSE) -> 0 | G27: 护甲穿透 | H27: =VLOOKUP(H15,'Total Result'!$A$3:$N$7,11,FALSE) -> 0 | I27: =VLOOKUP(H16,'Total Result'!$A$3:$N$7,11,FALSE) -> 0 | J27: 护甲穿透 | K27: =VLOOKUP(K15,'Total Result'!$A$3:$N$7,11,FALSE) -> 0 | L27: =VLOOKUP(K16,'Total Result'!$A$3:$N$7,11,FALSE) -> 0
A28: 韧性等级 | B28: =VLOOKUP(B15,'Total Result'!$A$3:$N$7,12,FALSE) -> 0 | C28: =VLOOKUP(B16,'Total Result'!$A$3:$N$7,12,FALSE) -> 0 | D28: 韧性等级 | E28: =VLOOKUP(E15,'Total Result'!$A$3:$N$7,12,FALSE) -> 0 | F28: =VLOOKUP(E16,'Total Result'!$A$3:$N$7,12,FALSE) -> 0 | G28: 韧性等级 | H28: =VLOOKUP(H15,'Total Result'!$A$3:$N$7,12,FALSE) -> 0 | I28: =VLOOKUP(H16,'Total Result'!$A$3:$N$7,12,FALSE) -> 0 | J28: 韧性等级 | K28: =VLOOKUP(K15,'Total Result'!$A$3:$N$7,12,FALSE) -> 0 | L28: =VLOOKUP(K16,'Total Result'!$A$3:$N$7,12,FALSE) -> 0
A29: 攻击类型 （等待整理） | B29: =VLOOKUP(B15,'Total Result'!$A$3:$N$7,13,FALSE) -> 1 | C29: =VLOOKUP(B16,'Total Result'!$A$3:$N$7,13,FALSE) -> 1 | D29: 攻击类型 （等待整理） | E29: =VLOOKUP(E15,'Total Result'!$A$3:$N$7,13,FALSE) -> 1 | F29: =VLOOKUP(E16,'Total Result'!$A$3:$N$7,13,FALSE) -> 1 | G29: 攻击类型 （等待整理） | H29: =VLOOKUP(H15,'Total Result'!$A$3:$N$7,13,FALSE) -> 1 | I29: =VLOOKUP(H16,'Total Result'!$A$3:$N$7,13,FALSE) -> 1 | J29: 攻击类型 （等待整理） | K29: =VLOOKUP(K15,'Total Result'!$A$3:$N$7,13,FALSE) -> 1 | L29: =VLOOKUP(K16,'Total Result'!$A$3:$N$7,13,FALSE) -> 1
A30: 护甲类型 （等待整理） | B30: =VLOOKUP(B15,'Total Result'!$A$3:$N$7,14,FALSE) -> 1 | C30: =VLOOKUP(B16,'Total Result'!$A$3:$N$7,14,FALSE) -> 1 | D30: 护甲类型 （等待整理） | E30: =VLOOKUP(E15,'Total Result'!$A$3:$N$7,14,FALSE) -> 1 | F30: =VLOOKUP(E16,'Total Result'!$A$3:$N$7,14,FALSE) -> 1 | G30: 护甲类型 （等待整理） | H30: =VLOOKUP(H15,'Total Result'!$A$3:$N$7,14,FALSE) -> 1 | I30: =VLOOKUP(H16,'Total Result'!$A$3:$N$7,14,FALSE) -> 1 | J30: 护甲类型 （等待整理） | K30: =VLOOKUP(K15,'Total Result'!$A$3:$N$7,14,FALSE) -> 1 | L30: =VLOOKUP(K16,'Total Result'!$A$3:$N$7,14,FALSE) -> 1
A32: 护甲减伤率 | B32: =(C21-B27)/(C21-B27+B18*1.5+28.5) -> 0 | D32: 护甲减伤率 | E32: =(F21-E27)/(F21-E27+E18*1.5+28.5) -> 0 | G32: 护甲减伤率 | H32: =(I21-H27)/(I21-H27+H18*1.5+28.5) -> 0 | J32: 护甲减伤率 | K32: =(L21-K27)/(L21-K27+K18*1.5+28.5) -> 0
A33: RPS差 | B33: =VLOOKUP(战斗模拟1!B15,'Total Result'!$A$2:$N$7,13,TRUE)-VLOOKUP(战斗模拟1!B16,'Total Result'!$A$2:$N$7,14,TRUE) -> 0 | D33: RPS差 | E33: =VLOOKUP(战斗模拟1!E15,'Total Result'!$A$2:$N$7,13,TRUE)-VLOOKUP(战斗模拟1!E16,'Total Result'!$A$2:$N$7,14,TRUE) -> 0 | G33: RPS差 | H33: =VLOOKUP(战斗模拟1!H15,'Total Result'!$A$2:$N$7,13,TRUE)-VLOOKUP(战斗模拟1!H16,'Total Result'!$A$2:$N$7,14,TRUE) -> 0 | J33: RPS差 | K33: =VLOOKUP(战斗模拟1!K15,'Total Result'!$A$2:$N$7,13,TRUE)-VLOOKUP(战斗模拟1!K16,'Total Result'!$A$2:$N$7,14,TRUE) -> 0
A34: RPS结果系数 | B34: =IF(MOD(B33,3)=0,100%,IF(MOD(B33,3)=1,90%,110%)) -> 1 | D34: RPS结果系数 | E34: =IF(MOD(E33,3)=0,100%,IF(MOD(E33,3)=1,90%,110%)) -> 1 | G34: RPS结果系数 | H34: =IF(MOD(H33,3)=0,100%,IF(MOD(H33,3)=1,90%,110%)) -> 1 | J34: RPS结果系数 | K34: =IF(MOD(K33,3)=0,100%,IF(MOD(K33,3)=1,90%,110%)) -> 1
A35: 普通击中伤害 | B35: =B20*(1-B32)*B34 -> 30 | D35: 普通击中伤害 | E35: =E20*(1-E32)*E34 -> 20 | G35: 普通击中伤害 | H35: =H20*(1-H32)*H34 -> 20 | J35: 普通击中伤害 | K35: =K20*(1-K32)*K34 -> 30
A36: 偏移几率 | B36: =IF((C24-B26)/(6.7*B18+126.7)+5%>70%,70%,(C24-B26)/(6.7*B18+126.7)+5%) -> 0.05 | D36: 偏移几率 | E36: =IF((F24-E26)/(6.7*E18+126.7)+5%>70%,70%,(F24-E26)/(6.7*E18+126.7)+5%) -> 0.05 | G36: 偏移几率 | H36: =IF((I24-H26)/(6.7*H18+126.7)+5%>70%,70%,(I24-H26)/(6.7*H18+126.7)+5%) -> 0.05 | J36: 偏移几率 | K36: =IF((L24-K26)/(6.7*K18+126.7)+5%>70%,70%,(L24-K26)/(6.7*K18+126.7)+5%) -> 0.05
A37: 是否发生偏移 | B37: =IF(RAND()<B36,1,0) -> 0 | D37: 是否发生偏移 | E37: =IF(RAND()<E36,1,0) -> 0 | G37: 是否发生偏移 | H37: =IF(RAND()<H36,1,0) -> 0 | J37: 是否发生偏移 | K37: =IF(RAND()<K36,1,0) -> 0
A38: 偏移减伤比率 | B38: =IF(C25/(8.3*B18+158.3)+33%>67%,67%,C25/(8.3*B18+158.3)+33%) -> 0.33 | D38: 偏移减伤比率 | E38: =IF(F25/(8.3*E18+158.3)+33%>67%,67%,F25/(8.3*E18+158.3)+33%) -> 0.33 | G38: 偏移减伤比率 | H38: =IF(I25/(8.3*H18+158.3)+33%>67%,67%,I25/(8.3*H18+158.3)+33%) -> 0.33 | J38: 偏移减伤比率 | K38: =IF(L25/(8.3*K18+158.3)+33%>67%,67%,L25/(8.3*K18+158.3)+33%) -> 0.33
A39: 暴击几率 | B39: =IF(B22/(4*C18+76)+5%>70%,70%,B22/(4*C18+76)+5%) -> 0.05 | D39: 暴击几率 | E39: =IF(E22/(4*F18+76)+5%>70%,70%,E22/(4*F18+76)+5%) -> 0.05 | G39: 暴击几率 | H39: =IF(H22/(4*I18+76)+5%>70%,70%,H22/(4*I18+76)+5%) -> 0.05 | J39: 暴击几率 | K39: =IF(K22/(4*L18+76)+5%>70%,70%,K22/(4*L18+76)+5%) -> 0.05
A40: 是否发生暴击 | B40: =IF(RAND()<B39,1,0) -> 0 | D40: 是否发生暴击 | E40: =IF(RAND()<E39,1,0) -> 1 | G40: 是否发生暴击 | H40: =IF(RAND()<H39,1,0) -> 0 | J40: 是否发生暴击 | K40: =IF(RAND()<K39,1,0) -> 0
A41: 暴击伤害率 | B41: =IF((B23-C28)/(5*C18+95)+50%>200%,200%,(B23-C28)/(5*C18+95)+50%) -> 0.5 | D41: 暴击伤害率 | E41: =IF((E23-F28)/(5*F18+95)+50%>200%,200%,(E23-F28)/(5*F18+95)+50%) -> 0.5 | G41: 暴击伤害率 | H41: =IF((H23-I28)/(5*I18+95)+50%>200%,200%,(H23-I28)/(5*I18+95)+50%) -> 0.5 | J41: 暴击伤害率 | K41: =IF((K23-L28)/(5*L18+95)+50%>200%,200%,(K23-L28)/(5*L18+95)+50%) -> 0.5
A42: 5%随机 | B42: =RAND()*0.1+0.95 -> 0.97096786 | D42: 5%随机 | E42: =RAND()*0.1+0.95 -> 0.96681021 | G42: 5%随机 | H42: =RAND()*0.1+0.95 -> 0.99293938 | J42: 5%随机 | K42: =RAND()*0.1+0.95 -> 0.99707257
A43: 本次伤害 | B43: =ROUND(B35*(1+B40*B41)*(1-B37*B38)*B42*B12,0) -> 29 | D43: 本次伤害 | E43: =ROUND(E35*(1+E40*E41)*(1-E37*E38)*E42*E12,0) -> 29 | G43: 本次伤害 | H43: =ROUND(H35*(1+H40*H41)*(1-H37*H38)*H42*H12,0) -> 20 | J43: 本次伤害 | K43: =ROUND(K35*(1+K40*K41)*(1-K37*K38)*K42*K12,0) -> 30
A45: A方所受伤害 | B45: =H43+K43 -> 50 | D45: 是否伤害在A1？ | E45: =E12 -> 1 | G45: B方所受伤害 | H45: =B43+E43 -> 58 | J45: 是否伤害在B1？ | K45: =H12 -> 1
A46: A2输出 | B46: =B43 -> 29 | D46: A1输出 | E46: =E43 -> 29 | G46: B1输出 | H46: =H43 -> 20 | J46: B2输出 | K46: =K43 -> 30
A47: A2剩余血量 | B47: =MAX(B7-(1-E45)*B45,0) -> 160 | D47: A1剩余血量 | E47: =MAX(0,E7-E45*B45) -> 190 | G47: B1剩余血量 | H47: =MAX(0,H7-H45*K45) -> 182 | J47: B2剩余血量 | K47: =MAX(K7-(1-K45)*H45,0) -> 160
...

Sheet 战斗模拟5
A1: 开始时4辆车的血量 | B1: 检测4辆车的状态，若已经死亡则不发射炮弹 | C1: 检测对方前排是否存活 | D1: 检测对方后排是否存活 | E1: 让其战斗30轮 | F1: 记录10轮的剩余血量结果
F2: 战斗结果
B3: =B1208 -> 0 | E3: =E1208 -> 0 | F3: 楚河 | H3: =H1208 -> 0 | K3: =K1208 -> 0
B4: A2 | E4: A1 | F4: 汉界 | H4: B1 | K4: B2
A7: A2初始血量： | B7: ='Total Result'!C3 -> 160 | D7: A1初始血量： | E7: ='Total Result'!C4 -> 240 | G7: B1初始血量 | H7: ='Total Result'!C6 -> 240 | J7: B2初始血量 | K7: ='Total Result'!C7 -> 160
A8: 百分比： | B8: 1 | D8: 百分比 | E8: 1 | G8: 百分比 | H8: 1 | J8: 百分比 | K8: 1
A10: 攻击轮数： | B10: 1
A12: A2是否存活？（上轮A2血量是否大于0？） | B12: =IF(B7>0,1,0) -> 1 | D12: A1是否存活？（上轮A1血量是否大于0？） | E12: =IF(E7>0,1,0) -> 1 | G12: B1是否存活？（上轮B1血量是否大于0？） | H12: =IF(H7>0,1,0) -> 1 | J12: B2是否存活？（上轮B2血量是否大于0？） | K12: =IF(K7>0,1,0) -> 1
A14: A2攻击 | D14: A1攻击 | G14: B1攻击 | J14: B2攻击
A15: 攻击方 | B15: A2 | D15: 攻击方 | E15: A1 | G15: 攻击方 | H15: B1 | J15: 攻击方 | K15: B2
A16: 对象 | B16: =IF($H7>0,"B1","B2") -> B1 | D16: 对象 | E16: =IF($H7>0,"B1","B2") -> B1 | G16: 对象 | H16: =IF($E7>0,"A1","A2") -> A1 | J16: 对象 | K16: =IF(E7>0,"A1","A2") -> A1
A17: 属性 | B17: 攻击方 | C17: 防御方 | D17: 属性 | E17: 攻击方 | F17: 防御方 | G17: 属性 | H17: 攻击方 | I17: 防御方 | J17: 属性 | K17: 攻击方 | L17: 防御方
A18: 级别 | B18: =VLOOKUP(B15,'Total Result'!$A$3:$N$7,2,FALSE) -> 1 | C18: =VLOOKUP(B16,'Total Result'!$A$3:$N$7,2,FALSE) -> 1 | D18: 级别 | E18: =VLOOKUP(E15,'Total Result'!$A$3:$N$7,2,FALSE) -> 1 | F18: =VLOOKUP(E16,'Total Result'!$A$3:$N$7,2,FALSE) -> 1 | G18: 级别 | H18: =VLOOKUP(H15,'Total Result'!$A$3:$N$7,2,FALSE) -> 1 | I18: =VLOOKUP(H16,'Total Result'!$A$3:$N$7,2,FALSE) -> 1 | J18: 级别 | K18: =VLOOKUP(K15,'Total Result'!$A$3:$N$7,2,FALSE) -> 1 | L18: =VLOOKUP(K16,'Total Result'!$A$3:$N$7,2,FALSE) -> 1
A19: 生命值上限 | B19: =VLOOKUP(B15,'Total Result'!$A$3:$N$7,3,FALSE) -> 160 | C19: =VLOOKUP(B16,'Total Result'!$A$3:$N$7,3,FALSE) -> 240 | D19: 生命值上限 | E19: =VLOOKUP(E15,'Total Result'!$A$3:$N$7,3,FALSE) -> 240 | F19: =VLOOKUP(E16,'Total Result'!$A$3:$N$7,3,FALSE) -> 240 | G19: 生命值上限 | H19: =VLOOKUP(H15,'Total Result'!$A$3:$N$7,3,FALSE) -> 240 | I19: =VLOOKUP(H16,'Total Result'!$A$3:$N$7,3,FALSE) -> 240 | J19: 生命值上限 | K19: =VLOOKUP(K15,'Total Result'!$A$3:$N$7,3,FALSE) -> 160 | L19: =VLOOKUP(K16,'Total Result'!$A$3:$N$7,3,FALSE) -> 240
A20: 攻击力 | B20: =VLOOKUP(B15,'Total Result'!$A$3:$N$7,4,FALSE) -> 30 | C20: =VLOOKUP(B16,'Total Result'!$A$3:$N$7,4,FALSE) -> 20 | D20: 攻击力 | E20: =VLOOKUP(E15,'Total Result'!$A$3:$N$7,4,FALSE) -> 20 | F20: =VLOOKUP(E16,'Total Result'!$A$3:$N$7,4,FALSE) -> 20 | G20: 攻击力 | H20: =VLOOKUP(H15,'Total Result'!$A$3:$N$7,4,FALSE) -> 20 | I20: =VLOOKUP(H16,'Total Result'!$A$3:$N$7,4,FALSE) -> 20 | J20: 攻击力 | K20: =VLOOKUP(K15,'Total Result'!$A$3:$N$7,4,FALSE) -> 30 | L20: =VLOOKUP(K16,'Total Result'!$A$3:$N$7,4,FALSE) -> 20
