Workbook

Sheet notes
A1: 甲磊的规划 | I1: 车升级的速度？ | K1: 30天 | L1: 延长至两个月
A2: 第1天到3、4级 | I2: double check
A3: 建大使馆 | I3: 升级速度相同
I4: 好车赖车的差别主要在承重上，基础属性有10%差别就可以了
I5: 经验主要通过经验球给，直接加上的部分极少
A6: 前期让玩家去采，应该比较注重让他一定采上来
A8: 90天到20级
A10: 第一天3辆车
A11: 非常前期加research，让玩家解锁buggy1和pickup1 | D11: 因此1级点比较特殊，应该非常弱
A12: 2辆车应该能打得过1级点
A13: 6辆车打2级点
A15: 1、2级
B16: tier2车与1混用 | D16: 打的过3级点
A17: 第3-7天
A19: 第7天开始因为资源压力而pvp
A20: 15天tier3 的车
A21: 14天起进入中期
A23: tier2车
A24: 经验升级速度与tier1相同
A26: 梁梁 | H26: 第一仗有几辆车？ | J26: 2辆？
A27: 加联盟不强制
A28: 10min车升了一级 | H28: 认识承重的时候，第一辆车有几级了？这时候装不上所有tier1的装备有问题吗
A29: 前几天投入2-3个小时 | D29: 通过大本营、研究中心等耗时间
A30: 大使馆2.5天
A31: 第4天造小建筑物断了 | D31: 调主线给的加速道具
A32: tier2研究一辆车 | C32: 1天左右 | D32: 或者需要比较多的油
A33: 10天 | B33: 打4级野点

Sheet 方法
A1: 大区块 | B1: 步骤 | C1: 进度
A2: 1 | B2: 统计玩家行为的种类 | C2: 完成
A3: 1 | B3: 设定玩家的上线时间 | C3: 目前按10~24点算，double check一下
A4: 1 | B4: 做出表格的基本结构 | C4: OK
A5: 1 | B5: 确定玩家行为的基本假设与估计 | C5: 待逐项确定
A6: 2 | B6: 建造队列 | C6: 基本填入，有待结合speedup，以及抠掉前期没有的建筑
A7: 2 | B7: 任务（队列） | C7: 基本OK，再看一下联盟任务的假设
A8: 2 | B8: 科研队列 | C8: 尽快定一个方案
A9: 2 | B9: 造车队列 | C9: 待制作
A10: 2 | B10: march队列 | C10: 待制作
A11: 2 | B11: 修理队列 | C11: 待制作
A12: 2 | B12: 造车队列 | C12: 待制作
A13: 2 | B13: 弹药队列 | C13: 待制作
... A18: 4 | B18: 加入随机机制 | C18: 后期若有可能再制作，优先级低。

Sheet 功能建筑物的权重占比
A1: 名称 | B1: 可造最大个数 | C1: 是否是默认建筑 | D1: 优先级 | E1: 权重 | F1: 总权重
A2: 大本营（HQ） | B2: 1 | C2: Y | D2: 2 | E2: 0.12 | F2: =E2*B2 -> 0.12
A3: 仓库(storage) | B3: 1 | C3: Y | D3: 1 | F3: =E3*B3 -> 0
A4: 城墙(wall) | B4: 1 | C4: Y | D4: 1 | F4: =E4*B4 -> 0
A5: 岗哨(sentry) | B5: 1 | C5: N | D5: 3 | F5: =E5*B5 -> 0
A6: 维修站(repair center) | B6: 3 | C6: N | D6: 2 | F6: =E6*B6 -> 0
A7: 工厂(factory) | B7: 1 | C7: N | D7: 1 | F7: =E7*B7 -> 0
A8: 工坊(workshop) | B8: 1 | C8: N | D8: 2 | F8: =E8*B8 -> 0
A9: 科研中心(research center) | B9: 1 | C9: Y | D9: 2 | F9: =E9*B9 -> 0
A10: 集结旗(rally flag) | B10: 1 | C10: N | D10: 3 | F10: =E10*B10 -> 0
A11: 营地(campsite) | B11: 1 | C11: N | D11: 3 | F11: =E11*B11 -> 0
A12: 车队指挥所（squad center） | B12: 1 | C12: Y | D12: 1 | F12: =E12*B12 -> 0
A13: 弹药库（Ammo depot） | B13: 5 | C13: N | D13: 3 | F13: =E13*B13 -> 0
F14: =SUM(F2:F13) -> 0.12

Sheet 需要确保的时间点
A1: 时间点（s） | B1: 时间描述 | C1: 时间点（天） | D1: 事件 | E1: 参数 | F1: 备注
A2: =C2*24*3600 -> 43200 | B2: =IF(INT(A2/3600/24)=0,"",INT(A2/3600/24)&"D")&IF(INT(MOD(A2,3600*24)/3600)=0,"",INT(MOD(A2,3600*24)/3600)&"H")&IF(INT(MOD(A2,3600)/60)=0,"",INT(MOD(A2,3600)/60)&"M")&IF(MOD(A2,60)=0,"",INT(MOD(A2,60))&"S") -> 12H | C2: 0.5 | D2: 建造车辆 | E2: 1、2
A3: =C3*24*3600 -> 69120 | B3: =IF(INT(A3/3600/24)=0,"",INT(A3/3600/24)&"D")&IF(INT(MOD(A3,3600*24)/3600)=0,"",INT(MOD(A3,3600*24)/3600)&"H")&IF(INT(MOD(A3,3600)/60)=0,"",INT(MOD(A3,3600)/60)&"M")&IF(MOD(A3,60)=0,"",INT(MOD(A3,60))&"S") -> 19H12M0S | C3: 0.8 | D3: 制造装备 | E3: 1
A4: =C4*24*3600 -> 86400 | B4: =IF(INT(A4/3600/24)=0,"",INT(A4/3600/24)&"D")&IF(INT(MOD(A4,3600*24)/3600)=0,"",INT(MOD(A4,3600*24)/3600)&"H")&IF(INT(MOD(A4,3600)/60)=0,"",INT(MOD(A4,3600)/60)&"M")&IF(MOD(A4,60)=0,"",INT(MOD(A4,60))&"S") -> 1D | C4: 1 | D4: 加入联盟 | E4: 1
A5: =C5*24*3600 -> 129600 | B5: =IF(INT(A5/3600/24)=0,"",INT(A5/3600/24)&"D")&IF(INT(MOD(A5,3600*24)/3600)=0,"",INT(MOD(A5,3600*24)/3600)&"H")&IF(INT(MOD(A5,3600)/60)=0,"",INT(MOD(A5,3600)/60)&"M")&IF(MOD(A5,60)=0,"",INT(MOD(A5,60))&"S") -> 1D12H | C5: 1.5 | D5: 修理队列解锁 | E5: 1
A6: =C6*24*3600 -> 172800 | B6: =IF(INT(A6/3600/24)=0,"",INT(A6/3600/24)&"D")&IF(INT(MOD(A6,3600*24)/3600)=0,"",INT(MOD(A6,3600*24)/3600)&"H")&IF(INT(MOD(A6,3600)/60)=0,"",INT(MOD(A6,3600)/60)&"M")&IF(MOD(A6,60)=0,"",INT(MOD(A6,60))&"S") -> 2D | C6: 2 | D6: 建造车辆 | E6: 3、4、5、6
A7: =C7*24*3600 -> 259200 | B7: =IF(INT(A7/3600/24)=0,"",INT(A7/3600/24)&"D")&IF(INT(MOD(A7,3600*24)/3600)=0,"",INT(MOD(A7,3600*24)/3600)&"H")&IF(INT(MOD(A7,3600)/60)=0,"",INT(MOD(A7,3600)/60)&"M")&IF(MOD(A7,60)=0,"",INT(MOD(A7,60))&"S") -> 3D | C7: 3 | D7: 车辆升级 | E7: 1
A8: =C8*24*3600 -> 345600 | B8: =IF(INT(A8/3600/24)=0,"",INT(A8/3600/24)&"D")&IF(INT(MOD(A8,3600*24)/3600)=0,"",INT(MOD(A8,3600*24)/3600)&"H")&IF(INT(MOD(A8,3600)/60)=0,"",INT(MOD(A8,3600)/60)&"M")&IF(MOD(A8,60)=0,"",INT(MOD(A8,60))&"S") -> 4D | C8: 4 | D8: 第一次制造弹药 | E8: 1
A9: =C9*24*3600 -> 604800 | B9: =IF(INT(A9/3600/24)=0,"",INT(A9/3600/24)&"D")&IF(INT(MOD(A9,3600*24)/3600)=0,"",INT(MOD(A9,3600*24)/3600)&"H")&IF(INT(MOD(A9,3600)/60)=0,"",INT(MOD(A9,3600)/60)&"M")&IF(MOD(A9,60)=0,"",INT(MOD(A9,60))&"S") -> 7D | C9: 7 | D9: 解锁车队 | E9: 2
A10: =C10*24*3600 -> 604800 | B10: =IF(INT(A10/3600/24)=0,"",INT(A10/3600/24)&"D")&IF(INT(MOD(A10,3600*24)/3600)=0,"",INT(MOD(A10,3600*24)/3600)&"H")&IF(INT(MOD(A10,3600)/60)=0,"",INT(MOD(A10,3600)/60)&"M")&IF(MOD(A10,60)=0,"",INT(MOD(A10,60))&"S") -> 7D | C10: 7 | D10: 装备升档 | E10: 2
A11: =C11*24*3600 -> 864000 | B11: =IF(INT(A11/3600/24)=0,"",INT(A11/3600/24)&"D")&IF(INT(MOD(A11,3600*24)/3600)=0,"",INT(MOD(A11,3600*24)/3600)&"H")&IF(INT(MOD(A11,3600)/60)=0,"",INT(MOD(A11,3600)/60)&"M")&IF(MOD(A11,60)=0,"",INT(MOD(A11,60))&"S") -> 10D | C11: 10 | D11: 修理队列解锁 | E11: 2
A12: =C12*24*3600 -> 1209600 | B12: =IF(INT(A12/3600/24)=0,"",INT(A12/3600/24)&"D")&IF(INT(MOD(A12,3600*24)/3600)=0,"",INT(MOD(A12,3600*24)/3600)&"H")&IF(INT(MOD(A12,3600)/60)=0,"",INT(MOD(A12,3600)/60)&"M")&IF(MOD(A12,60)=0,"",INT(MOD(A12,60))&"S") -> 14D | C12: 14 | D12: 车辆升级 | E12: 2
A13: =C13*24*3600 -> 1209600 | B13: =IF(INT(A13/3600/24)=0,"",INT(A13/3600/24)&"D")&IF(INT(MOD(A13,3600*24)/3600)=0,"",INT(MOD(A13,3600*24)/3600)&"H")&IF(INT(MOD(A13,3600)/60)=0,"",INT(MOD(A13,3600)/60)&"M")&IF(MOD(A13,60)=0,"",INT(MOD(A13,60))&"S") -> 14D | C13: 14 | D13: 弹药升档 | E13: 2
A14: =C14*24*3600 -> 1814400 | B14: =IF(INT(A14/3600/24)=0,"",INT(A14/3600/24)&"D")&IF(INT(MOD(A14,3600*24)/3600)=0,"",INT(MOD(A14,3600*24)/3600)&"H")&IF(INT(MOD(A14,3600)/60)=0,"",INT(MOD(A14,3600)/60)&"M")&IF(MOD(A14,60)=0,"",INT(MOD(A14,60))&"S") -> 21D | C14: 21 | D14: 装备升档 | E14: 3
A15: =C15*24*3600 -> 2592000 | B15: =IF(INT(A15/3600/24)=0,"",INT(A15/3600/24)&"D")&IF(INT(MOD(A15,3600*24)/3600)=0,"",INT(MOD(A15,3600*24)/3600)&"H")&IF(INT(MOD(A15,3600)/60)=0,"",INT(MOD(A15,3600)/60)&"M")&IF(MOD(A15,60)=0,"",INT(MOD(A15,60))&"S") -> 30D | C15: 30 | D15: 解锁车队 | E15: 3
A16: =C16*24*3600 -> 3456000 | B16: =IF(INT(A16/3600/24)=0,"",INT(A16/3600/24)&"D")&IF(INT(MOD(A16,3600*24)/3600)=0,"",INT(MOD(A16,3600*24)/3600)&"H")&IF(INT(MOD(A16,3600)/60)=0,"",INT(MOD(A16,3600)/60)&"M")&IF(MOD(A16,60)=0,"",INT(MOD(A16,60))&"S") -> 40D | C16: 40 | D16: 修理队列解锁 | E16: 3
A17: =C17*24*3600 -> 3888000 | B17: =IF(INT(A17/3600/24)=0,"",INT(A17/3600/24)&"D")&IF(INT(MOD(A17,3600*24)/3600)=0,"",INT(MOD(A17,3600*24)/3600)&"H")&IF(INT(MOD(A17,3600)/60)=0,"",INT(MOD(A17,3600)/60)&"M")&IF(MOD(A17,60)=0,"",INT(MOD(A17,60))&"S") -> 45D | C17: 45 | D17: 弹药升档 | E17: 3
A18: =C18*24*3600 -> 5184000 | B18: =IF(INT(A18/3600/24)=0,"",INT(A18/3600/24)&"D")&IF(INT(MOD(A18,3600*24)/3600)=0,"",INT(MOD(A18,3600*24)/3600)&"H")&IF(INT(MOD(A18,3600)/60)=0,"",INT(MOD(A18,3600)/60)&"M")&IF(MOD(A18,60)=0,"",INT(MOD(A18,60))&"S") -> 60D | C18: 60 | D18: 装备升档 | E18: 4
... A20: =C20*24*3600 -> 12960000 | B20: =IF(INT(A20/3600/24)=0,"",INT(A20/3600/24)&"D")&IF(INT(MOD(A20,3600*24)/3600)=0,"",INT(MOD(A20,3600*24)/3600)&"H")&IF(INT(MOD(A20,3600)/60)=0,"",INT(MOD(A20,3600)/60)&"M")&IF(MOD(A20,60)=0,"",INT(MOD(A20,60))&"S") -> 150D | C20: 150 | D20: 解锁车队 | E20: 5

Sheet 玩家行为种类
A1: type | B1: 行为 | C1: 备注 | D1: 前置条件 | E1: 后置结果 | F1: 是否可硬货币作用 | G1: 参数1 | H1: 参数2
A2: 总体假设 | B2: 上线 | C2: 每天上午10点
A3: 总体假设 | B3: 下线 | C3: 每天晚12点
A4: 总体假设 | B4: 时间管理 | C4: 上限时间内分秒不损失
A6: 战斗&march | B6: pve | C6: 假设通过精力控制到10次
A7: 战斗&march | B7: pvp | C7: 不统计
A8: 战斗&march | B8: 资源点 | C8: 每日3次，在做联盟任务时回来拉资源
A10: 集结 | B10: 发起战争集结 | C10: 3天1次
A11: 集结 | B11: 参与战争集结 | C11: 1天2次
A13: 支援 | B13: 支援玩家 | C13: 15天起每天1次
A14: 联盟 | B14: 做联盟任务 | C14: 1次6个，1天有10、16、22三次
B15: 领联盟礼包 | C15: 4%付费率可参考，但付费是分多少次进行仍然没有线索
A17: ammo | B17: 制作弹药 | C17: 从使用弹药来推测制作弹药
A18: ammo | B18: 使用弹药 | C18: 假设1/2的战斗使用弹药
A20: 装备 | B20: 制造装备 | C20: 不靠时间卡制造，持续时间算0。表中的进行时间点都按照打到资源计算。讨论一下正常玩家会制造多少个
A21: 装备 | B21: 配置装备 | C21: 是否需要统计？
A22: 装备 | B22: 销毁装备 | C22: 频率低、影响小，不统计
A23: 装备 | B23: 得到材料 | C23: 单独考虑，或者：只统计PVE时间，由pve行为推出
A24: 装备 | B24: 获得更高等级装备 | C24: 从得到材料做二次推算
A25: 装备 | B25: 获得品质更高装备 | C25: 从得到材料做二次推算
A26: 装备方面有另一个选择：不考虑装备的获取，只考虑材料能换取的power
A28: 联盟 | B28: 加入联盟 | C28: 第一次可以预计。讨论一下第二次、第三次加入联盟的时间。 | G28: 1个月-45天
A29: 好友 | B29: 互加好友 | C29: 频率低、影响小，不统计
A30: chat | B30: 聊天、发言 | C30: 频率高、影响小、波动大，不统计
A32: storage | B32: 进保 | C32: 由玩家行为推算，不单算行为
A33: storage | B33: 出保 | C33: 由玩家行为推算，不单算行为
A35: shield | B35: 进盾 | C35: 被打不上盾，因此将开盾放在计划外
A36: shield | B36: 出盾 | C36: 上盾之后x小时去除或玩家攻击去除，不可预计，可以假设被玩家攻击的成功率为一个定值
A38: 道具 | B38: 使用道具 | C38: 是否需要统计？
A39: 道具 | B39: 购买道具 | C39: 是否需要统计？
A41: mail | B41: 收到mail | C41: pve、pvp、scout必然带来收mail行为，这个行为非玩家主动去做，并且可以因此不专设一条
A42: mail | B42: 发出mail | C42: 不统计
A44: scout | B44: 侦查单个玩家 | C44: 攻击玩家前侦查两次（平均算法）
A45: scout | B45: 侦查集结 | C45: 每次被集结则侦查两次
... A48: leaderboard | B48: 查看leaderboard | C48: 影响小，不统计
A50: repair | B50: 修理车辆 | C50: 假设1/2战斗需要修理。修理时间的增长怎么走？ | F50: 待定
A51: repair | B51: 开启修理队列 | C51: 时间可参考修理的建筑物
A53: army car | B53: 制造车辆 | C53: 假设玩家只制造50辆，把时间排出来
A54: army car | B54: 车辆升级 | C54: 个人认为应当给予玩家相当部分的经验球，省去玩家从头练车辆的痛苦
A56: squad | B56: squad up | C56: 暂未想到预计方式
...

Sheet 排序
A1: 项目 | B1: 级别 | C1: 开始时间（s） | D1: 开始时间text | E1: 持续时间 | F1: 结束时间 | G1: 结束时间text | H1: 资源 | I1: power | J1: 车等级
A2: 大本营（HQ） | B2: 1 | C2: 36000 | D2: 10H | E2: 249 | F2: 36249 | G2: 10H4M9S
A3: 油井（oil well） | B3: 1 | C3: 36249 | D3: 10H4M9S | E3: 192 | F3: 36441 | G3: 10H7M21S
A4: 废料厂（junk recycler） | B4: 1 | C4: 36441 | D4: 10H7M21S | E4: 192 | F4: 36633 | G4: 10H10M33S
A5: 随机任务 | B5: 1 | C5: 36600 | D5: 10H10M | E5: 0 | F5: 36600 | G5: 10H10M
A6: 金属厂（metal collector） | B6: 1 | C6: 36633 | D6: 10H10M33S | E6: 192 | F6: 36825 | G6: 10H13M45S
A7: 废料厂（junk recycler） | B7: 1 | C7: 36825 | D7: 10H13M45S | E7: 192 | F7: 37017 | G7: 10H16M57S
A8: 废料厂（junk recycler） | B8: 1 | C8: 37017 | D8: 10H16M57S | E8: 192 | F8: 37209 | G8: 10H20M9S
A9: 废料厂（junk recycler） | B9: 1 | C9: 37209 | D9: 10H20M9S | E9: 192 | F9: 37401 | G9: 10H23M21S
A10: 废料厂（junk recycler） | B10: 1 | C10: 37401 | D10: 10H23M21S | E10: 192 | F10: 37593 | G10: 10H26M33S
A11: 废料厂（junk recycler） | B11: 1 | C11: 37593 | D11: 10H26M33S | E11: 192 | F11: 37785 | G11: 10H29M45S
A12: 金属厂（metal collector） | B12: 1 | C12: 37785 | D12: 10H29M45S | E12: 192 | F12: 37977 | G12: 10H32M57S
A13: 金属厂（metal collector） | B13: 1 | C13: 37977 | D13: 10H32M57S | E13: 192 | F13: 38169 | G13: 10H36M9S
... A7541: 弹药库（Ammo depot） | B7541: 25 | C7541: 43261920 | D7541: 500D17H12M | E7541: 112320 | F7541: 43374240 | G7541: 502D24M

Sheet 汇总（未排序）
A1: 项目 | B1: 级别 | C1: 开始时间（s） | D1: 开始时间text | E1: 持续时间 | F1: 结束时间 | G1: 结束时间text
A2: 大本营（HQ） | B2: 1 | C2: 36000 | D2: 10H | E2: 249 | F2: 36249 | G2: 10H4M9S
A3: 油井（oil well） | B3: 1 | C3: 36249 | D3: 10H4M9S | E3: 192 | F3: 36441 | G3: 10H7M21S
A4: 废料厂（junk recycler） | B4: 1 | C4: 36441 | D4: 10H7M21S | E4: 192 | F4: 36633 | G4: 10H10M33S
A5: 金属厂（metal collector） | B5: 1 | C5: 36633 | D5: 10H10M33S | E5: 192 | F5: 36825 | G5: 10H13M45S
A6: 废料厂（junk recycler） | B6: 1 | C6: 36825 | D6: 10H13M45S | E6: 192 | F6: 37017 | G6: 10H16M57S
A7: 废料厂（junk recycler） | B7: 1 | C7: 37017 | D7: 10H16M57S | E7: 192 | F7: 37209 | G7: 10H20M9S
A8: 废料厂（junk recycler） | B8: 1 | C8: 37209 | D8: 10H20M9S | E8: 192 | F8: 37401 | G8: 10H23M21S
A9: 废料厂（junk recycler） | B9: 1 | C9: 37401 | D9: 10H23M21S | E9: 192 | F9: 37593 | G9: 10H26M33S
A10: 废料厂（junk recycler） | B10: 1 | C10: 37593 | D10: 10H26M33S | E10: 192 | F10: 37785 | G10: 10H29M45S
A11: 金属厂（metal collector） | B11: 1 | C11: 37785 | D11: 10H29M45S | E11: 192 | F11: 37977 | G11: 10H32M57S
A12: 金属厂（metal collector） | B12: 1 | C12: 37977 | D12: 10H32M57S | E12: 192 | F12: 38169 | G12: 10H36M9S
A13: 金属厂（metal collector） | B13: 1 | C13: 38169 | D13: 10H36M9S | E13: 192 | F13: 38361 | G13: 10H39M21S
... A7541: 随机任务 | B7541: 451 | C7541: 38959800 | D7541: 450D22H10M | E7541: 0 | F7541: 38959800 | G7541: 450D22H10M

Sheet 建造队列
A1: 建筑物 | B1: 级别 | C1: 开始时间 | D1: 开始时间text | E1: 持续时间 | F1: 结束时间s | G1: 结束时间text
A2: 大本营（HQ） | B2: =INT((ROW(A2)+29)/31) -> 1 | C2: 36000 | D2: =IF(INT(C2/3600/24)=0,"",INT(C2/3600/24)&"D")&IF(INT(MOD(C2,3600*24)/3600)=0,"",INT(MOD(C2,3600*24)/3600)&"H")&IF(INT(MOD(C2,3600)/60)=0,"",INT(MOD(C2,3600)/60)&"M")&IF(MOD(C2,60)=0,"",INT(MOD(C2,60))&"S") -> 10H | E2: =VLOOKUP(A2,'建造level time'!$A$3:$AB$33,(建造队列!B2+3),FALSE) -> 249 | F2: =C2+E2 -> 36249 | G2: =IF(INT(F2/3600/24)=0,"",INT(F2/3600/24)&"D")&IF(INT(MOD(F2,3600*24)/3600)=0,"",INT(MOD(F2,3600*24)/3600)&"H")&IF(INT(MOD(F2,3600)/60)=0,"",INT(MOD(F2,3600)/60)&"M")&IF(MOD(F2,60)=0,"",INT(MOD(F2,60))&"S") -> 10H4M9S
A3: 油井（oil well） | B3: =INT((ROW(A3)+29)/31) -> 1 | C3: =IF(MOD(F2,86400)<36000,INT(F2/86400)*86400+36000,F2) -> 36249 | D3: =IF(INT(C3/3600/24)=0,"",INT(C3/3600/24)&"D")&IF(INT(MOD(C3,3600*24)/3600)=0,"",INT(MOD(C3,3600*24)/3600)&"H")&IF(INT(MOD(C3,3600)/60)=0,"",INT(MOD(C3,3600)/60)&"M")&IF(MOD(C3,60)=0,"",INT(MOD(C3,60))&"S") -> 10H4M9S | E3: =VLOOKUP(A3,'建造level time'!$A$3:$AB$33,(建造队列!B3+3),FALSE) -> 192 | F3: =C3+E3 -> 36441 | G3: =IF(INT(F3/3600/24)=0,"",INT(F3/3600/24)&"D")&IF(INT(MOD(F3,3600*24)/3600)=0,"",INT(MOD(F3,3600*24)/3600)&"H")&IF(INT(MOD(F3,3600)/60)=0,"",INT(MOD(F3,3600)/60)&"M")&IF(MOD(F3,60)=0,"",INT(MOD(F3,60))&"S") -> 10H7M21S
A4: 废料厂（junk recycler） | B4: =INT((ROW(A4)+29)/31) -> 1 | C4: =IF(MOD(F3,86400)<36000,INT(F3/86400)*86400+36000,F3) -> 36441 | D4: =IF(INT(C4/3600/24)=0,"",INT(C4/3600/24)&"D")&IF(INT(MOD(C4,3600*24)/3600)=0,"",INT(MOD(C4,3600*24)/3600)&"H")&IF(INT(MOD(C4,3600)/60)=0,"",INT(MOD(C4,3600)/60)&"M")&IF(MOD(C4,60)=0,"",INT(MOD(C4,60))&"S") -> 10H7M21S | E4: =VLOOKUP(A4,'建造level time'!$A$3:$AB$33,(建造队列!B4+3),FALSE) -> 192 | F4: =C4+E4 -> 36633 | G4: =IF(INT(F4/3600/24)=0,"",INT(F4/3600/24)&"D")&IF(INT(MOD(F4,3600*24)/3600)=0,"",INT(MOD(F4,3600*24)/3600)&"H")&IF(INT(MOD(F4,3600)/60)=0,"",INT(MOD(F4,3600)/60)&"M")&IF(MOD(F4,60)=0,"",INT(MOD(F4,60))&"S") -> 10H10M33S
A5: 金属厂（metal collector） | B5: =INT((ROW(A5)+29)/31) -> 1 | C5: =IF(MOD(F4,86400)<36000,INT(F4/86400)*86400+36000,F4) -> 36633 | D5: =IF(INT(C5/3600/24)=0,"",INT(C5/3600/24)&"D")&IF(INT(MOD(C5,3600*24)/3600)=0,"",INT(MOD(C5,3600*24)/3600)&"H")&IF(INT(MOD(C5,3600)/60)=0,"",INT(MOD(C5,3600)/60)&"M")&IF(MOD(C5,60)=0,"",INT(MOD(C5,60))&"S") -> 10H10M33S | E5: =VLOOKUP(A5,'建造level time'!$A$3:$AB$33,(建造队列!B5+3),FALSE) -> 192 | F5: =C5+E5 -> 36825 | G5: =IF(INT(F5/3600/24)=0,"",INT(F5/3600/24)&"D")&IF(INT(MOD(F5,3600*24)/3600)=0,"",INT(MOD(F5,3600*24)/3600)&"H")&IF(INT(MOD(F5,3600)/60)=0,"",INT(MOD(F5,3600)/60)&"M")&IF(MOD(F5,60)=0,"",INT(MOD(F5,60))&"S") -> 10H13M45S
A6: 废料厂（junk recycler） | B6: =INT((ROW(A6)+29)/31) -> 1 | C6: =IF(MOD(F5,86400)<36000,INT(F5/86400)*86400+36000,F5) -> 36825 | D6: =IF(INT(C6/3600/24)=0,"",INT(C6/3600/24)&"D")&IF(INT(MOD(C6,3600*24)/3600)=0,"",INT(MOD(C6,3600*24)/3600)&"H")&IF(INT(MOD(C6,3600)/60)=0,"",INT(MOD(C6,3600)/60)&"M")&IF(MOD(C6,60)=0,"",INT(MOD(C6,60))&"S") -> 10H13M45S | E6: =VLOOKUP(A6,'建造level time'!$A$3:$AB$33,(建造队列!B6+3),FALSE) -> 192 | F6: =C6+E6 -> 37017 | G6: =IF(INT(F6/3600/24)=0,"",INT(F6/3600/24)&"D")&IF(INT(MOD(F6,3600*24)/3600)=0,"",INT(MOD(F6,3600*24)/3600)&"H")&IF(INT(MOD(F6,3600)/60)=0,"",INT(MOD(F6,3600)/60)&"M")&IF(MOD(F6,60)=0,"",INT(MOD(F6,60))&"S") -> 10H16M57S
A7: 废料厂（junk recycler） | B7: =INT((ROW(A7)+29)/31) -> 1 | C7: =IF(MOD(F6,86400)<36000,INT(F6/86400)*86400+36000,F6) -> 37017 | D7: =IF(INT(C7/3600/24)=0,"",INT(C7/3600/24)&"D")&IF(INT(MOD(C7,3600*24)/3600)=0,"",INT(MOD(C7,3600*24)/3600)&"H")&IF(INT(MOD(C7,3600)/60)=0,"",INT(MOD(C7,3600)/60)&"M")&IF(MOD(C7,60)=0,"",INT(MOD(C7,60))&"S") -> 10H16M57S | E7: =VLOOKUP(A7,'建造level time'!$A$3:$AB$33,(建造队列!B7+3),FALSE) -> 192 | F7: =C7+E7 -> 37209 | G7: =IF(INT(F7/3600/24)=0,"",INT(F7/3600/24)&"D")&IF(INT(MOD(F7,3600*24)/3600)=0,"",INT(MOD(F7,3600*24)/3600)&"H")&IF(INT(MOD(F7,3600)/60)=0,"",INT(MOD(F7,3600)/60)&"M")&IF(MOD(F7,60)=0,"",INT(MOD(F7,60))&"S") -> 10H20M9S
A8: 废料厂（junk recycler） | B8: =INT((ROW(A8)+29)/31) -> 1 | C8: =IF(MOD(F7,86400)<36000,INT(F7/86400)*86400+36000,F7) -> 37209 | D8: =IF(INT(C8/3600/24)=0,"",INT(C8/3600/24)&"D")&IF(INT(MOD(C8,3600*24)/3600)=0,"",INT(MOD(C8,3600*24)/3600)&"H")&IF(INT(MOD(C8,3600)/60)=0,"",INT(MOD(C8,3600)/60)&"M")&IF(MOD(C8,60)=0,"",INT(MOD(C8,60))&"S") -> 10H20M9S | E8: =VLOOKUP(A8,'建造level time'!$A$3:$AB$33,(建造队列!B8+3),FALSE) -> 192 | F8: =C8+E8 -> 37401 | G8: =IF(INT(F8/3600/24)=0,"",INT(F8/3600/24)&"D")&IF(INT(MOD(F8,3600*24)/3600)=0,"",INT(MOD(F8,3600*24)/3600)&"H")&IF(INT(MOD(F8,3600)/60)=0,"",INT(MOD(F8,3600)/60)&"M")&IF(MOD(F8,60)=0,"",INT(MOD(F8,60))&"S") -> 10H23M21S
A9: 废料厂（junk recycler） | B9: =INT((ROW(A9)+29)/31) -> 1 | C9: =IF(MOD(F8,86400)<36000,INT(F8/86400)*86400+36000,F8) -> 37401 | D9: =IF(INT(C9/3600/24)=0,"",INT(C9/3600/24)&"D")&IF(INT(MOD(C9,3600*24)/3600)=0,"",INT(MOD(C9,3600*24)/3600)&"H")&IF(INT(MOD(C9,3600)/60)=0,"",INT(MOD(C9,3600)/60)&"M")&IF(MOD(C9,60)=0,"",INT(MOD(C9,60))&"S") -> 10H23M21S | E9: =VLOOKUP(A9,'建造level time'!$A$3:$AB$33,(建造队列!B9+3),FALSE) -> 192 | F9: =C9+E9 -> 37593 | G9: =IF(INT(F9/3600/24)=0,"",INT(F9/3600/24)&"D")&IF(INT(MOD(F9,3600*24)/3600)=0,"",INT(MOD(F9,3600*24)/3600)&"H")&IF(INT(MOD(F9,3600)/60)=0,"",INT(MOD(F9,3600)/60)&"M")&IF(MOD(F9,60)=0,"",INT(MOD(F9,60))&"S") -> 10H26M33S
A10: 废料厂（junk recycler） | B10: =INT((ROW(A10)+29)/31) -> 1 | C10: =IF(MOD(F9,86400)<36000,INT(F9/86400)*86400+36000,F9) -> 37593 | D10: =IF(INT(C10/3600/24)=0,"",INT(C10/3600/24)&"D")&IF(INT(MOD(C10,3600*24)/3600)=0,"",INT(MOD(C10,3600*24)/3600)&"H")&IF(INT(MOD(C10,3600)/60)=0,"",INT(MOD(C10,3600)/60)&"M")&IF(MOD(C10,60)=0,"",INT(MOD(C10,60))&"S") -> 10H26M33S | E10: =VLOOKUP(A10,'建造level time'!$A$3:$AB$33,(建造队列!B10+3),FALSE) -> 192 | F10: =C10+E10 -> 37785 | G10: =IF(INT(F10/3600/24)=0,"",INT(F10/3600/24)&"D")&IF(INT(MOD(F10,3600*24)/3600)=0,"",INT(MOD(F10,3600*24)/3600)&"H")&IF(INT(MOD(F10,3600)/60)=0,"",INT(MOD(F10,3600)/60)&"M")&IF(MOD(F10,60)=0,"",INT(MOD(F10,60))&"S") -> 10H29M45S
A11: 金属厂（metal collector） | B11: =INT((ROW(A11)+29)/31) -> 1 | C11: =IF(MOD(F10,86400)<36000,INT(F10/86400)*86400+36000,F10) -> 37785 | D11: =IF(INT(C11/3600/24)=0,"",INT(C11/3600/24)&"D")&IF(INT(MOD(C11,3600*24)/3600)=0,"",INT(MOD(C11,3600*24)/3600)&"H")&IF(INT(MOD(C11,3600)/60)=0,"",INT(MOD(C11,3600)/60)&"M")&IF(MOD(C11,60)=0,"",INT(MOD(C11,60))&"S") -> 10H29M45S | E11: =VLOOKUP(A11,'建造level time'!$A$3:$AB$33,(建造队列!B11+3),FALSE) -> 192 | F11: =C11+E11 -> 37977 | G11: =IF(INT(F11/3600/24)=0,"",INT(F11/3600/24)&"D")&IF(INT(MOD(F11,3600*24)/3600)=0,"",INT(MOD(F11,3600*24)/3600)&"H")&IF(INT(MOD(F11,3600)/60)=0,"",INT(MOD(F11,3600)/60)&"M")&IF(MOD(F11,60)=0,"",INT(MOD(F11,60))&"S") -> 10H32M57S
A12: 金属厂（metal collector） | B12: =INT((ROW(A12)+29)/31) -> 1 | C12: =IF(MOD(F11,86400)<36000,INT(F11/86400)*86400+36000,F11) -> 37977 | D12: =IF(INT(C12/3600/24)=0,"",INT(C12/3600/24)&"D")&IF(INT(MOD(C12,3600*24)/3600)=0,"",INT(MOD(C12,3600*24)/3600)&"H")&IF(INT(MOD(C12,3600)/60)=0,"",INT(MOD(C12,3600)/60)&"M")&IF(MOD(C12,60)=0,"",INT(MOD(C12,60))&"S") -> 10H32M57S | E12: =VLOOKUP(A12,'建造level time'!$A$3:$AB$33,(建造队列!B12+3),FALSE) -> 192 | F12: =C12+E12 -> 38169 | G12: =IF(INT(F12/3600/24)=0,"",INT(F12/3600/24)&"D")&IF(INT(MOD(F12,3600*24)/3600)=0,"",INT(MOD(F12,3600*24)/3600)&"H")&IF(INT(MOD(F12,3600)/60)=0,"",INT(MOD(F12,3600)/60)&"M")&IF(MOD(F12,60)=0,"",INT(MOD(F12,60))&"S") -> 10H36M9S
A13: 金属厂（metal collector） | B13: =INT((ROW(A13)+29)/31) -> 1 | C13: =IF(MOD(F12,86400)<36000,INT(F12/86400)*86400+36000,F12) -> 38169 | D13: =IF(INT(C13/3600/24)=0,"",INT(C13/3600/24)&"D")&IF(INT(MOD(C13,3600*24)/3600)=0,"",INT(MOD(C13,3600*24)/3600)&"H")&IF(INT(MOD(C13,3600)/60)=0,"",INT(MOD(C13,3600)/60)&"M")&IF(MOD(C13,60)=0,"",INT(MOD(C13,60))&"S") -> 10H36M9S | E13: =VLOOKUP(A13,'建造level time'!$A$3:$AB$33,(建造队列!B13+3),FALSE) -> 192 | F13: =C13+E13 -> 38361 | G13: =IF(INT(F13/3600/24)=0,"",INT(F13/3600/24)&"D")&IF(INT(MOD(F13,3600*24)/3600)=0,"",INT(MOD(F13,3600*24)/3600)&"H")&IF(INT(MOD(F13,3600)/60)=0,"",INT(MOD(F13,3600)/60)&"M")&IF(MOD(F13,60)=0,"",INT(MOD(F13,60))&"S") -> 10H39M21S
A14: 金属厂（metal collector） | B14: =INT((ROW(A14)+29)/31) -> 1 | C14: =IF(MOD(F13,86400)<36000,INT(F13/86400)*86400+36000,F13) -> 38361 | D14: =IF(INT(C14/3600/24)=0,"",INT(C14/3600/24)&"D")&IF(INT(MOD(C14,3600*24)/3600)=0,"",INT(MOD(C14,3600*24)/3600)&"H")&IF(INT(MOD(C14,3600)/60)=0,"",INT(MOD(C14,3600)/60)&"M")&IF(MOD(C14,60)=0,"",INT(MOD(C14,60))&"S") -> 10H39M21S | E14: =VLOOKUP(A14,'建造level time'!$A$3:$AB$33,(建造队列!B14+3),FALSE) -> 192 | F14: =C14+E14 -> 38553 | G14: =IF(INT(F14/3600/24)=0,"",INT(F14/3600/24)&"D")&IF(INT(MOD(F14,3600*24)/3600)=0,"",INT(MOD(F14,3600*24)/3600)&"H")&IF(INT(MOD(F14,3600)/60)=0,"",INT(MOD(F14,3600)/60)&"M")&IF(MOD(F14,60)=0,"",INT(MOD(F14,60))&"S") -> 10H42M33S
... A776: 弹药库（Ammo depot） | B776: =INT((ROW(A776)+29)/31) -> 25 | C776: =IF(MOD(F775,86400)<36000,INT(F775/86400)*86400+36000,F775) -> 43261920 | D776: =IF(INT(C776/3600/24)=0,"",INT(C776/3600/24)&"D")&IF(INT(MOD(C776,3600*24)/3600)=0,"",INT(MOD(C776,3600*24)/3600)&"H")&IF(INT(MOD(C776,3600)/60)=0,"",INT(MOD(C776,3600)/60)&"M")&IF(MOD(C776,60)=0,"",INT(MOD(C776,60))&"S") -> 500D17H12M | E776: =VLOOKUP(A776,'建造level time'!$A$3:$AB$33,(建造队列!B776+3),FALSE) -> 112320 | F776: =C776+E776 -> 43374240 | G776: =IF(INT(F776/3600/24)=0,"",INT(F776/3600/24)&"D")&IF(INT(MOD(F776,3600*24)/3600)=0,"",INT(MOD(F776,3600*24)/3600)&"H")&IF(INT(MOD(F776,3600)/60)=0,"",INT(MOD(F776,3600)/60)&"M")&IF(MOD(F776,60)=0,"",INT(MOD(F776,60))&"S") -> 502D24M

Sheet 每日任务、随机任务
A1: 项目 | B1: 级别 | C1: 开始时间 | D1: 开始时间text | E1: 持续时间 | F1: 结束时间s | G1: 结束时间text | L1: 将联盟任务加入
A2: 随机任务 | B2: 1 | C2: 36600 | D2: =IF(INT(C2/3600/24)=0,"",INT(C2/3600/24)&"D")&IF(INT(MOD(C2,3600*24)/3600)=0,"",INT(MOD(C2,3600*24)/3600)&"H")&IF(INT(MOD(C2,3600)/60)=0,"",INT(MOD(C2,3600)/60)&"M")&IF(MOD(C2,60)=0,"",INT(MOD(C2,60))&"S") -> 10H10M | E2: 0 | F2: =C2 -> 36600 | G2: =IF(INT(F2/3600/24)=0,"",INT(F2/3600/24)&"D")&IF(INT(MOD(F2,3600*24)/3600)=0,"",INT(MOD(F2,3600*24)/3600)&"H")&IF(INT(MOD(F2,3600)/60)=0,"",INT(MOD(F2,3600)/60)&"M")&IF(MOD(F2,60)=0,"",INT(MOD(F2,60))&"S") -> 10H10M
A3: 每日任务 | B3: 1 | C3: 43200 | D3: =IF(INT(C3/3600/24)=0,"",INT(C3/3600/24)&"D")&IF(INT(MOD(C3,3600*24)/3600)=0,"",INT(MOD(C3,3600*24)/3600)&"H")&IF(INT(MOD(C3,3600)/60)=0,"",INT(MOD(C3,3600)/60)&"M")&IF(MOD(C3,60)=0,"",INT(MOD(C3,60))&"S") -> 12H | E3: 0 | F3: =C3 -> 43200 | G3: =IF(INT(F3/3600/24)=0,"",INT(F3/3600/24)&"D")&IF(INT(MOD(F3,3600*24)/3600)=0,"",INT(MOD(F3,3600*24)/3600)&"H")&IF(INT(MOD(F3,3600)/60)=0,"",INT(MOD(F3,3600)/60)&"M")&IF(MOD(F3,60)=0,"",INT(MOD(F3,60))&"S") -> 12H
A4: 每日任务 | B4: 1 | C4: =C3+300 -> 43500 | D4: =IF(INT(C4/3600/24)=0,"",INT(C4/3600/24)&"D")&IF(INT(MOD(C4,3600*24)/3600)=0,"",INT(MOD(C4,3600*24)/3600)&"H")&IF(INT(MOD(C4,3600)/60)=0,"",INT(MOD(C4,3600)/60)&"M")&IF(MOD(C4,60)=0,"",INT(MOD(C4,60))&"S") -> 12H5M | E4: 0 | F4: =C4 -> 43500 | G4: =IF(INT(F4/3600/24)=0,"",INT(F4/3600/24)&"D")&IF(INT(MOD(F4,3600*24)/3600)=0,"",INT(MOD(F4,3600*24)/3600)&"H")&IF(INT(MOD(F4,3600)/60)=0,"",INT(MOD(F4,3600)/60)&"M")&IF(MOD(F4,60)=0,"",INT(MOD(F4,60))&"S") -> 12H5M
A5: 每日任务 | B5: 1 | C5: =C4+300 -> 43800 | D5: =IF(INT(C5/3600/24)=0,"",INT(C5/3600/24)&"D")&IF(INT(MOD(C5,3600*24)/3600)=0,"",INT(MOD(C5,3600*24)/3600)&"H")&IF(INT(MOD(C5,3600)/60)=0,"",INT(MOD(C5,3600)/60)&"M")&IF(MOD(C5,60)=0,"",INT(MOD(C5,60))&"S") -> 12H10M | E5: 0 | F5: =C5 -> 43800 | G5: =IF(INT(F5/3600/24)=0,"",INT(F5/3600/24)&"D")&IF(INT(MOD(F5,3600*24)/3600)=0,"",INT(MOD(F5,3600*24)/3600)&"H")&IF(INT(MOD(F5,3600)/60)=0,"",INT(MOD(F5,3600)/60)&"M")&IF(MOD(F5,60)=0,"",INT(MOD(F5,60))&"S") -> 12H10M
A6: 每日任务 | B6: 1 | C6: =C5+300 -> 44100 | D6: =IF(INT(C6/3600/24)=0,"",INT(C6/3600/24)&"D")&IF(INT(MOD(C6,3600*24)/3600)=0,"",INT(MOD(C6,3600*24)/3600)&"H")&IF(INT(MOD(C6,3600)/60)=0,"",INT(MOD(C6,3600)/60)&"M")&IF(MOD(C6,60)=0,"",INT(MOD(C6,60))&"S") -> 12H15M | E6: 0 | F6: =C6 -> 44100 | G6: =IF(INT(F6/3600/24)=0,"",INT(F6/3600/24)&"D")&IF(INT(MOD(F6,3600*24)/3600)=0,"",INT(MOD(F6,3600*24)/3600)&"H")&IF(INT(MOD(F6,3600)/60)=0,"",INT(MOD(F6,3600)/60)&"M")&IF(MOD(F6,60)=0,"",INT(MOD(F6,60))&"S") -> 12H15M
A7: 每日任务 | B7: 1 | C7: =C6+300 -> 44400 | D7: =IF(INT(C7/3600/24)=0,"",INT(C7/3600/24)&"D")&IF(INT(MOD(C7,3600*24)/3600)=0,"",INT(MOD(C7,3600*24)/3600)&"H")&IF(INT(MOD(C7,3600)/60)=0,"",INT(MOD(C7,3600)/60)&"M")&IF(MOD(C7,60)=0,"",INT(MOD(C7,60))&"S") -> 12H20M | E7: 0 | F7: =C7 -> 44400 | G7: =IF(INT(F7/3600/24)=0,"",INT(F7/3600/24)&"D")&IF(INT(MOD(F7,3600*24)/3600)=0,"",INT(MOD(F7,3600*24)/3600)&"H")&IF(INT(MOD(F7,3600)/60)=0,"",INT(MOD(F7,3600)/60)&"M")&IF(MOD(F7,60)=0,"",INT(MOD(F7,60))&"S") -> 12H20M
A8: 每日任务 | B8: 1 | C8: =C7+300 -> 44700 | D8: =IF(INT(C8/3600/24)=0,"",INT(C8/3600/24)&"D")&IF(INT(MOD(C8,3600*24)/3600)=0,"",INT(MOD(C8,3600*24)/3600)&"H")&IF(INT(MOD(C8,3600)/60)=0,"",INT(MOD(C8,3600)/60)&"M")&IF(MOD(C8,60)=0,"",INT(MOD(C8,60))&"S") -> 12H25M | E8: 0 | F8: =C8 -> 44700 | G8: =IF(INT(F8/3600/24)=0,"",INT(F8/3600/24)&"D")&IF(INT(MOD(F8,3600*24)/3600)=0,"",INT(MOD(F8,3600*24)/3600)&"H")&IF(INT(MOD(F8,3600)/60)=0,"",INT(MOD(F8,3600)/60)&"M")&IF(MOD(F8,60)=0,"",INT(MOD(F8,60))&"S") -> 12H25M
A9: 每日任务 | B9: 1 | C9: =C8+300 -> 45000 | D9: =IF(INT(C9/3600/24)=0,"",INT(C9/3600/24)&"D")&IF(INT(MOD(C9,3600*24)/3600)=0,"",INT(MOD(C9,3600*24)/3600)&"H")&IF(INT(MOD(C9,3600)/60)=0,"",INT(MOD(C9,3600)/60)&"M")&IF(MOD(C9,60)=0,"",INT(MOD(C9,60))&"S") -> 12H30M | E9: 0 | F9: =C9 -> 45000 | G9: =IF(INT(F9/3600/24)=0,"",INT(F9/3600/24)&"D")&IF(INT(MOD(F9,3600*24)/3600)=0,"",INT(MOD(F9,3600*24)/3600)&"H")&IF(INT(MOD(F9,3600)/60)=0,"",INT(MOD(F9,3600)/60)&"M")&IF(MOD(F9,60)=0,"",INT(MOD(F9,60))&"S") -> 12H30M
A10: 每日任务 | B10: 1 | C10: =C9+300 -> 45300 | D10: =IF(INT(C10/3600/24)=0,"",INT(C10/3600/24)&"D")&IF(INT(MOD(C10,3600*24)/3600)=0,"",INT(MOD(C10,3600*24)/3600)&"H")&IF(INT(MOD(C10,3600)/60)=0,"",INT(MOD(C10,3600)/60)&"M")&IF(MOD(C10,60)=0,"",INT(MOD(C10,60))&"S") -> 12H35M | E10: 0 | F10: =C10 -> 45300 | G10: =IF(INT(F10/3600/24)=0,"",INT(F10/3600/24)&"D")&IF(INT(MOD(F10,3600*24)/3600)=0,"",INT(MOD(F10,3600*24)/3600)&"H")&IF(INT(MOD(F10,3600)/60)=0,"",INT(MOD(F10,3600)/60)&"M")&IF(MOD(F10,60)=0,"",INT(MOD(F10,60))&"S") -> 12H35M
A11: 每日任务 | B11: 1 | C11: =C10+300 -> 45600 | D11: =IF(INT(C11/3600/24)=0,"",INT(C11/3600/24)&"D")&IF(INT(MOD(C11,3600*24)/3600)=0,"",INT(MOD(C11,3600*24)/3600)&"H")&IF(INT(MOD(C11,3600)/60)=0,"",INT(MOD(C11,3600)/60)&"M")&IF(MOD(C11,60)=0,"",INT(MOD(C11,60))&"S") -> 12H40M | E11: 0 | F11: =C11 -> 45600 | G11: =IF(INT(F11/3600/24)=0,"",INT(F11/3600/24)&"D")&IF(INT(MOD(F11,3600*24)/3600)=0,"",INT(MOD(F11,3600*24)/3600)&"H")&IF(INT(MOD(F11,3600)/60)=0,"",INT(MOD(F11,3600)/60)&"M")&IF(MOD(F11,60)=0,"",INT(MOD(F11,60))&"S") -> 12H40M
A12: 每日任务 | B12: 1 | C12: =C11+300 -> 45900 | D12: =IF(INT(C12/3600/24)=0,"",INT(C12/3600/24)&"D")&IF(INT(MOD(C12,3600*24)/3600)=0,"",INT(MOD(C12,3600*24)/3600)&"H")&IF(INT(MOD(C12,3600)/60)=0,"",INT(MOD(C12,3600)/60)&"M")&IF(MOD(C12,60)=0,"",INT(MOD(C12,60))&"S") -> 12H45M | E12: 0 | F12: =C12 -> 45900 | G12: =IF(INT(F12/3600/24)=0,"",INT(F12/3600/24)&"D")&IF(INT(MOD(F12,3600*24)/3600)=0,"",INT(MOD(F12,3600*24)/3600)&"H")&IF(INT(MOD(F12,3600)/60)=0,"",INT(MOD(F12,3600)/60)&"M")&IF(MOD(F12,60)=0,"",INT(MOD(F12,60))&"S") -> 12H45M
A13: 每日任务 | B13: 1 | C13: =C12+300 -> 46200 | D13: =IF(INT(C13/3600/24)=0,"",INT(C13/3600/24)&"D")&IF(INT(MOD(C13,3600*24)/3600)=0,"",INT(MOD(C13,3600*24)/3600)&"H")&IF(INT(MOD(C13,3600)/60)=0,"",INT(MOD(C13,3600)/60)&"M")&IF(MOD(C13,60)=0,"",INT(MOD(C13,60))&"S") -> 12H50M | E13: 0 | F13: =C13 -> 46200 | G13: =IF(INT(F13/3600/24)=0,"",INT(F13/3600/24)&"D")&IF(INT(MOD(F13,3600*24)/3600)=0,"",INT(MOD(F13,3600*24)/3600)&"H")&IF(INT(MOD(F13,3600)/60)=0,"",INT(MOD(F13,3600)/60)&"M")&IF(MOD(F13,60)=0,"",INT(MOD(F13,60))&"S") -> 12H50M
A14: 每日任务 | B14: 1 | C14: =C13+300 -> 46500 | D14: =IF(INT(C14/3600/24)=0,"",INT(C14/3600/24)&"D")&IF(INT(MOD(C14,3600*24)/3600)=0,"",INT(MOD(C14,3600*24)/3600)&"H")&IF(INT(MOD(C14,3600)/60)=0,"",INT(MOD(C14,3600)/60)&"M")&IF(MOD(C14,60)=0,"",INT(MOD(C14,60))&"S") -> 12H55M | E14: 0 | F14: =C14 -> 46500 | G14: =IF(INT(F14/3600/24)=0,"",INT(F14/3600/24)&"D")&IF(INT(MOD(F14,3600*24)/3600)=0,"",INT(MOD(F14,3600*24)/3600)&"H")&IF(INT(MOD(F14,3600)/60)=0,"",INT(MOD(F14,3600)/60)&"M")&IF(MOD(F14,60)=0,"",INT(MOD(F14,60))&"S") -> 12H55M
A15: 随机任务 | B15: 1 | C15: =C2+21600 -> 58200 | D15: =IF(INT(C15/3600/24)=0,"",INT(C15/3600/24)&"D")&IF(INT(MOD(C15,3600*24)/3600)=0,"",INT(MOD(C15,3600*24)/3600)&"H")&IF(INT(MOD(C15,3600)/60)=0,"",INT(MOD(C15,3600)/60)&"M")&IF(MOD(C15,60)=0,"",INT(MOD(C15,60))&"S") -> 16H10M | E15: 0 | F15: =C15 -> 58200 | G15: =IF(INT(F15/3600/24)=0,"",INT(F15/3600/24)&"D")&IF(INT(MOD(F15,3600*24)/3600)=0,"",INT(MOD(F15,3600*24)/3600)&"H")&IF(INT(MOD(F15,3600)/60)=0,"",INT(MOD(F15,3600)/60)&"M")&IF(MOD(F15,60)=0,"",INT(MOD(F15,60))&"S") -> 16H10M
A16: 随机任务 | B16: 1 | C16: =C15+21600 -> 79800 | D16: =IF(INT(C16/3600/24)=0,"",INT(C16/3600/24)&"D")&IF(INT(MOD(C16,3600*24)/3600)=0,"",INT(MOD(C16,3600*24)/3600)&"H")&IF(INT(MOD(C16,3600)/60)=0,"",INT(MOD(C16,3600)/60)&"M")&IF(MOD(C16,60)=0,"",INT(MOD(C16,60))&"S") -> 22H10M | E16: 0 | F16: =C16 -> 79800 | G16: =IF(INT(F16/3600/24)=0,"",INT(F16/3600/24)&"D")&IF(INT(MOD(F16,3600*24)/3600)=0,"",INT(MOD(F16,3600*24)/3600)&"H")&IF(INT(MOD(F16,3600)/60)=0,"",INT(MOD(F16,3600)/60)&"M")&IF(MOD(F16,60)=0,"",INT(MOD(F16,60))&"S") -> 22H10M
A17: 随机任务 | B17: =B2+1 -> 2 | C17: =C2+86400 -> 123000 | D17: =IF(INT(C17/3600/24)=0,"",INT(C17/3600/24)&"D")&IF(INT(MOD(C17,3600*24)/3600)=0,"",INT(MOD(C17,3600*24)/3600)&"H")&IF(INT(MOD(C17,3600)/60)=0,"",INT(MOD(C17,3600)/60)&"M")&IF(MOD(C17,60)=0,"",INT(MOD(C17,60))&"S") -> 1D10H10M | E17: 0 | F17: =C17 -> 123000 | G17: =IF(INT(F17/3600/24)=0,"",INT(F17/3600/24)&"D")&IF(INT(MOD(F17,3600*24)/3600)=0,"",INT(MOD(F17,3600*24)/3600)&"H")&IF(INT(MOD(F17,3600)/60)=0,"",INT(MOD(F17,3600)/60)&"M")&IF(MOD(F17,60)=0,"",INT(MOD(F17,60))&"S") -> 1D10H10M
A18: 每日任务 | B18: =B3+1 -> 2 | C18: =C3+86400 -> 129600 | D18: =IF(INT(C18/3600/24)=0,"",INT(C18/3600/24)&"D")&IF(INT(MOD(C18,3600*24)/3600)=0,"",INT(MOD(C18,3600*24)/3600)&"H")&IF(INT(MOD(C18,3600)/60)=0,"",INT(MOD(C18,3600)/60)&"M")&IF(MOD(C18,60)=0,"",INT(MOD(C18,60))&"S") -> 1D12H | E18: 0 | F18: =C18 -> 129600 | G18: =IF(INT(F18/3600/24)=0,"",INT(F18/3600/24)&"D")&IF(INT(MOD(F18,3600*24)/3600)=0,"",INT(MOD(F18,3600*24)/3600)&"H")&IF(INT(MOD(F18,3600)/60)=0,"",INT(MOD(F18,3600)/60)&"M")&IF(MOD(F18,60)=0,"",INT(MOD(F18,60))&"S") -> 1D12H
A19: 每日任务 | B19: =B4+1 -> 2 | C19: =C4+86400 -> 129900 | D19: =IF(INT(C19/3600/24)=0,"",INT(C19/3600/24)&"D")&IF(INT(MOD(C19,3600*24)/3600)=0,"",INT(MOD(C19,3600*24)/3600)&"H")&IF(INT(MOD(C19,3600)/60)=0,"",INT(MOD(C19,3600)/60)&"M")&IF(MOD(C19,60)=0,"",INT(MOD(C19,60))&"S") -> 1D12H5M | E19: 0 | F19: =C19 -> 129900 | G19: =IF(INT(F19/3600/24)=0,"",INT(F19/3600/24)&"D")&IF(INT(MOD(F19,3600*24)/3600)=0,"",INT(MOD(F19,3600*24)/3600)&"H")&IF(INT(MOD(F19,3600)/60)=0,"",INT(MOD(F19,3600)/60)&"M")&IF(MOD(F19,60)=0,"",INT(MOD(F19,60))&"S") -> 1D12H5M
A20: 每日任务 | B20: =B5+1 -> 2 | C20: =C5+86400 -> 130200 | D20: =IF(INT(C20/3600/24)=0,"",INT(C20/3600/24)&"D")&IF(INT(MOD(C20,3600*24)/3600)=0,"",INT(MOD(C20,3600*24)/3600)&"H")&IF(INT(MOD(C20,3600)/60)=0,"",INT(MOD(C20,3600)/60)&"M")&IF(MOD(C20,60)=0,"",INT(MOD(C20,60))&"S") -> 1D12H10M | E20: 0 | F20: =C20 -> 130200 | G20: =IF(INT(F20/3600/24)=0,"",INT(F20/3600/24)&"D")&IF(INT(MOD(F20,3600*24)/3600)=0,"",INT(MOD(F20,3600*24)/3600)&"H")&IF(INT(MOD(F20,3600)/60)=0,"",INT(MOD(F20,3600)/60)&"M")&IF(MOD(F20,60)=0,"",INT(MOD(F20,60))&"S") -> 1D12H10M
A21: 每日任务 | B21: =B6+1 -> 2 | C21: =C6+86400 -> 130500 | D21: =IF(INT(C21/3600/24)=0,"",INT(C21/3600/24)&"D")&IF(INT(MOD(C21,3600*24)/3600)=0,"",INT(MOD(C21,3600*24)/3600)&"H")&IF(INT(MOD(C21,3600)/60)=0,"",INT(MOD(C21,3600)/60)&"M")&IF(MOD(C21,60)=0,"",INT(MOD(C21,60))&"S") -> 1D12H15M | E21: 0 | F21: =C21 -> 130500 | G21: =IF(INT(F21/3600/24)=0,"",INT(F21/3600/24)&"D")&IF(INT(MOD(F21,3600*24)/3600)=0,"",INT(MOD(F21,3600*24)/3600)&"H")&IF(INT(MOD(F21,3600)/60)=0,"",INT(MOD(F21,3600)/60)&"M")&IF(MOD(F21,60)=0,"",INT(MOD(F21,60))&"S") -> 1D12H15M
A22: 每日任务 | B22: =B7+1 -> 2 | C22: =C7+86400 -> 130800 | D22: =IF(INT(C22/3600/24)=0,"",INT(C22/3600/24)&"D")&IF(INT(MOD(C22,3600*24)/3600)=0,"",INT(MOD(C22,3600*24)/3600)&"H")&IF(INT(MOD(C22,3600)/60)=0,"",INT(MOD(C22,3600)/60)&"M")&IF(MOD(C22,60)=0,"",INT(MOD(C22,60))&"S") -> 1D12H20M | E22: 0 | F22: =C22 -> 130800 | G22: =IF(INT(F22/3600/24)=0,"",INT(F22/3600/24)&"D")&IF(INT(MOD(F22,3600*24)/3600)=0,"",INT(MOD(F22,3600*24)/3600)&"H")&IF(INT(MOD(F22,3600)/60)=0,"",INT(MOD(F22,3600)/60)&"M")&IF(MOD(F22,60)=0,"",INT(MOD(F22,60))&"S") -> 1D12H20M
A23: 每日任务 | B23: =B8+1 -> 2 | C23: =C8+86400 -> 131100 | D23: =IF(INT(C23/3600/24)=0,"",INT(C23/3600/24)&"D")&IF(INT(MOD(C23,3600*24)/3600)=0,"",INT(MOD(C23,3600*24)/3600)&"H")&IF(INT(MOD(C23,3600)/60)=0,"",INT(MOD(C23,3600)/60)&"M")&IF(MOD(C23,60)=0,"",INT(MOD(C23,60))&"S") -> 1D12H25M | E23: 0 | F23: =C23 -> 131100 | G23: =IF(INT(F23/3600/24)=0,"",INT(F23/3600/24)&"D")&IF(INT(MOD(F23,3600*24)/3600)=0,"",INT(MOD(F23,3600*24)/3600)&"H")&IF(INT(MOD(F23,3600)/60)=0,"",INT(MOD(F23,3600)/60)&"M")&IF(MOD(F23,60)=0,"",INT(MOD(F23,60))&"S") -> 1D12H25M
A24: 每日任务 | B24: =B9+1 -> 2 | C24: =C9+86400 -> 131400 | D24: =IF(INT(C24/3600/24)=0,"",INT(C24/3600/24)&"D")&IF(INT(MOD(C24,3600*24)/3600)=0,"",INT(MOD(C24,3600*24)/3600)&"H")&IF(INT(MOD(C24,3600)/60)=0,"",INT(MOD(C24,3600)/60)&"M")&IF(MOD(C24,60)=0,"",INT(MOD(C24,60))&"S") -> 1D12H30M | E24: 0 | F24: =C24 -> 131400 | G24: =IF(INT(F24/3600/24)=0,"",INT(F24/3600/24)&"D")&IF(INT(MOD(F24,3600*24)/3600)=0,"",INT(MOD(F24,3600*24)/3600)&"H")&IF(INT(MOD(F24,3600)/60)=0,"",INT(MOD(F24,3600)/60)&"M")&IF(MOD(F24,60)=0,"",INT(MOD(F24,60))&"S") -> 1D12H30M
A25: 每日任务 | B25: =B10+1 -> 2 | C25: =C10+86400 -> 131700 | D25: =IF(INT(C25/3600/24)=0,"",INT(C25/3600/24)&"D")&IF(INT(MOD(C25,3600*24)/3600)=0,"",INT(MOD(C25,3600*24)/3600)&"H")&IF(INT(MOD(C25,3600)/60)=0,"",INT(MOD(C25,3600)/60)&"M")&IF(MOD(C25,60)=0,"",INT(MOD(C25,60))&"S") -> 1D12H35M | E25: 0 | F25: =C25 -> 131700 | G25: =IF(INT(F25/3600/24)=0,"",INT(F25/3600/24)&"D")&IF(INT(MOD(F25,3600*24)/3600)=0,"",INT(MOD(F25,3600*24)/3600)&"H")&IF(INT(MOD(F25,3600)/60)=0,"",INT(MOD(F25,3600)/60)&"M")&IF(MOD(F25,60)=0,"",INT(MOD(F25,60))&"S") -> 1D12H35M
A26: 每日任务 | B26: =B11+1 -> 2 | C26: =C11+86400 -> 132000 | D26: =IF(INT(C26/3600/24)=0,"",INT(C26/3600/24)&"D")&IF(INT(MOD(C26,3600*24)/3600)=0,"",INT(MOD(C26,3600*24)/3600)&"H")&IF(INT(MOD(C26,3600)/60)=0,"",INT(MOD(C26,3600)/60)&"M")&IF(MOD(C26,60)=0,"",INT(MOD(C26,60))&"S") -> 1D12H40M | E26: 0 | F26: =C26 -> 132000 | G26: =IF(INT(F26/3600/24)=0,"",INT(F26/3600/24)&"D")&IF(INT(MOD(F26,3600*24)/3600)=0,"",INT(MOD(F26,3600*24)/3600)&"H")&IF(INT(MOD(F26,3600)/60)=0,"",INT(MOD(F26,3600)/60)&"M")&IF(MOD(F26,60)=0,"",INT(MOD(F26,60))&"S") -> 1D12H40M
A27: 每日任务 | B27: =B12+1 -> 2 | C27: =C12+86400 -> 132300 | D27: =IF(INT(C27/3600/24)=0,"",INT(C27/3600/24)&"D")&IF(INT(MOD(C27,3600*24)/3600)=0,"",INT(MOD(C27,3600*24)/3600)&"H")&IF(INT(MOD(C27,3600)/60)=0,"",INT(MOD(C27,3600)/60)&"M")&IF(MOD(C27,60)=0,"",INT(MOD(C27,60))&"S") -> 1D12H45M | E27: 0 | F27: =C27 -> 132300 | G27: =IF(INT(F27/3600/24)=0,"",INT(F27/3600/24)&"D")&IF(INT(MOD(F27,3600*24)/3600)=0,"",INT(MOD(F27,3600*24)/3600)&"H")&IF(INT(MOD(F27,3600)/60)=0,"",INT(MOD(F27,3600)/60)&"M")&IF(MOD(F27,60)=0,"",INT(MOD(F27,60))&"S") -> 1D12H45M
A28: 每日任务 | B28: =B13+1 -> 2 | C28: =C13+86400 -> 132600 | D28: =IF(INT(C28/3600/24)=0,"",INT(C28/3600/24)&"D")&IF(INT(MOD(C28,3600*24)/3600)=0,"",INT(MOD(C28,3600*24)/3600)&"H")&IF(INT(MOD(C28,3600)/60)=0,"",INT(MOD(C28,3600)/60)&"M")&IF(MOD(C28,60)=0,"",INT(MOD(C28,60))&"S") -> 1D12H50M | E28: 0 | F28: =C28 -> 132600 | G28: =IF(INT(F28/3600/24)=0,"",INT(F28/3600/24)&"D")&IF(INT(MOD(F28,3600*24)/3600)=0,"",INT(MOD(F28,3600*24)/3600)&"H")&IF(INT(MOD(F28,3600)/60)=0,"",INT(MOD(F28,3600)/60)&"M")&IF(MOD(F28,60)=0,"",INT(MOD(F28,60))&"S") -> 1D12H50M
... A6766: 随机任务 | B6766: =B6751+1 -> 451 | C6766: =C6751+86400 -> 38959800 | D6766: =IF(INT(C6766/3600/24)=0,"",INT(C6766/3600/24)&"D")&IF(INT(MOD(C6766,3600*24)/3600)=0,"",INT(MOD(C6766,3600*24)/3600)&"H")&IF(INT(MOD(C6766,3600)/60)=0,"",INT(MOD(C6766,3600)/60)&"M")&IF(MOD(C6766,60)=0,"",INT(MOD(C6766,60))&"S") -> 450D22H10M | E6766: 0 | F6766: =C6766 -> 38959800 | G6766: =IF(INT(F6766/3600/24)=0,"",INT(F6766/3600/24)&"D")&IF(INT(MOD(F6766,3600*24)/3600)=0,"",INT(MOD(F6766,3600*24)/3600)&"H")&IF(INT(MOD(F6766,3600)/60)=0,"",INT(MOD(F6766,3600)/60)&"M")&IF(MOD(F6766,60)=0,"",INT(MOD(F6766,60))&"S") -> 450D22H10M

Sheet 科研
A1: 科研有40个左右的项目，每个项目有10级。如有可能，我们将任务的时间规划进一步细化，从而加入这个表格

Sheet 杂项
A1: 行为
A2: 收资源
A3: 每日login
A4: 到达vip等级
A5: 首次加入联盟

Sheet 建造level time
A1: 125 | B1: 400 | D1: 1170 | E1: 1560 | F1: 2340 | G1: 3120 | H1: 4680 | I1: 5850 | J1: 8775 | K1: 12090 | L1: 16770 | M1: 23400 | N1: 32370 | O1: 44850 | P1: 63180 | Q1: 87750 | R1: 121680 | S1: 171990 | T1: 238680 | U1: 310050 | V1: 468000 | W1: 649350 | X1: 900900 | Y1: 1287000 | Z1: 1755000 | AA1: 2527200 | AB1: 3510000
B2: proportion | C2: level time | D2: =D1/$A$1*$B$1 -> 3744 | E2: =E1/$A$1*$B$1 -> 4992 | F2: =F1/$A$1*$B$1 -> 7488 | G2: =G1/$A$1*$B$1 -> 9984 | H2: =H1/$A$1*$B$1 -> 14976 | I2: =I1/$A$1*$B$1 -> 18720 | J2: =J1/$A$1*$B$1 -> 28080 | K2: =K1/$A$1*$B$1 -> 38688 | ... AB2: =AB1/$A$1*$B$1 -> 11232000
A3: 大本营（HQ） | B3: =1/3*[1]功能建筑权重!$E2 -> 0.066666667 | D3: =INT($B3*D$2) -> 249 | E3: =INT($B3*E$2) -> 332 | F3: =INT($B3*F$2) -> 499 | G3: =INT($B3*G$2) -> 665 | H3: =INT($B3*H$2) -> 998 | I3: =INT($B3*I$2) -> 1248 | J3: =INT($B3*J$2) -> 1872 | K3: =INT($B3*K$2) -> 2579 | ... AB3: =INT($B3*AB$2) -> 748800
A4: 油井（oil well） | B4: =2/3/13 -> 0.051282051 | D4: =INT($B4*D$2) -> 192 | E4: =INT($B4*E$2) -> 256 | F4: =INT($B4*F$2) -> 384 | G4: =INT($B4*G$2) -> 512 | H4: =INT($B4*H$2) -> 768 | I4: =INT($B4*I$2) -> 960 | J4: =INT($B4*J$2) -> 1440 | K4: =INT($B4*K$2) -> 1984 | ... AB4: =INT($B4*AB$2) -> 576000
A5: 废料厂（junk recycler） | B5: =2/3/13 -> 0.051282051 | D5: =INT($B5*D$2) -> 192 | E5: =INT($B5*E$2) -> 256 | F5: =INT($B5*F$2) -> 384 | G5: =INT($B5*G$2) -> 512 | H5: =INT($B5*H$2) -> 768 | I5: =INT($B5*I$2) -> 960 | J5: =INT($B5*J$2) -> 1440 | K5: =INT($B5*K$2) -> 1984 | ... AB5: =INT($B5*AB$2) -> 576000
A6: 金属厂（metal collector） | B6: =2/3/13 -> 0.051282051 | D6: =INT($B6*D$2) -> 192 | E6: =INT($B6*E$2) -> 256 | F6: =INT($B6*F$2) -> 384 | G6: =INT($B6*G$2) -> 512 | H6: =INT($B6*H$2) -> 768 | I6: =INT($B6*I$2) -> 960 | J6: =INT($B6*J$2) -> 1440 | K6: =INT($B6*K$2) -> 1984 | ... AB6: =INT($B6*AB$2) -> 576000
A7: 废料厂（junk recycler） | B7: =2/3/13 -> 0.051282051 | D7: =INT($B7*D$2) -> 192 | E7: =INT($B7*E$2) -> 256 | F7: =INT($B7*F$2) -> 384 | G7: =INT($B7*G$2) -> 512 | H7: =INT($B7*H$2) -> 768 | I7: =INT($B7*I$2) -> 960 | J7: =INT($B7*J$2) -> 1440 | K7: =INT($B7*K$2) -> 1984 | ... AB7: =INT($B7*AB$2) -> 576000
A8: 废料厂（junk recycler） | B8: =2/3/13 -> 0.051282051 | D8: =INT($B8*D$2) -> 192 | E8: =INT($B8*E$2) -> 256 | F8: =INT($B8*F$2) -> 384 | G8: =INT($B8*G$2) -> 512 | H8: =INT($B8*H$2) -> 768 | I8: =INT($B8*I$2) -> 960 | J8: =INT($B8*J$2) -> 1440 | K8: =INT($B8*K$2) -> 1984 | ... AB8: =INT($B8*AB$2) -> 576000
A9: 废料厂（junk recycler） | B9: =2/3/13 -> 0.051282051 | D9: =INT($B9*D$2) -> 192 | E9: =INT($B9*E$2) -> 256 | F9: =INT($B9*F$2) -> 384 | G9: =INT($B9*G$2) -> 512 | H9: =INT($B9*H$2) -> 768 | I9: =INT($B9*I$2) -> 960 | J9: =INT($B9*J$2) -> 1440 | K9: =INT($B9*K$2) -> 1984 | ... AB9: =INT($B9*AB$2) -> 576000
A10: 废料厂（junk recycler） | B10: =2/3/13 -> 0.051282051 | D10: =INT($B10*D$2) -> 192 | E10: =INT($B10*E$2) -> 256 | F10: =INT($B10*F$2) -> 384 | G10: =INT($B10*G$2) -> 512 | H10: =INT($B10*H$2) -> 768 | I10: =INT($B10*I$2) -> 960 | J10: =INT($B10*J$2) -> 1440 | K10: =INT($B10*K$2) -> 1984 | ... AB10: =INT($B10*AB$2) -> 576000
A11: 废料厂（junk recycler） | B11: =2/3/13 -> 0.051282051 | D11: =INT($B11*D$2) -> 192 | E11: =INT($B11*E$2) -> 256 | F11: =INT($B11*F$2) -> 384 | G11: =INT($B11*G$2) -> 512 | H11: =INT($B11*H$2) -> 768 | I11: =INT($B11*I$2) -> 960 | J11: =INT($B11*J$2) -> 1440 | K11: =INT($B11*K$2) -> 1984 | ... AB11: =INT($B11*AB$2) -> 576000
A12: 金属厂（metal collector） | B12: =2/3/13 -> 0.051282051 | D12: =INT($B12*D$2) -> 192 | E12: =INT($B12*E$2) -> 256 | F12: =INT($B12*F$2) -> 384 | G12: =INT($B12*G$2) -> 512 | H12: =INT($B12*H$2) -> 768 | I12: =INT($B12*I$2) -> 960 | J12: =INT($B12*J$2) -> 1440 | K12: =INT($B12*K$2) -> 1984 | ... AB12: =INT($B12*AB$2) -> 576000
A13: 金属厂（metal collector） | B13: =2/3/13 -> 0.051282051 | D13: =INT($B13*D$2) -> 192 | E13: =INT($B13*E$2) -> 256 | F13: =INT($B13*F$2) -> 384 | G13: =INT($B13*G$2) -> 512 | H13: =INT($B13*H$2) -> 768 | I13: =INT($B13*I$2) -> 960 | J13: =INT($B13*J$2) -> 1440 | K13: =INT($B13*K$2) -> 1984 | ... AB13: =INT($B13*AB$2) -> 576000
A14: 金属厂（metal collector） | B14: =2/3/13 -> 0.051282051 | D14: =INT($B14*D$2) -> 192 | E14: =INT($B14*E$2) -> 256 | F14: =INT($B14*F$2) -> 384 | G14: =INT($B14*G$2) -> 512 | H14: =INT($B14*H$2) -> 768 | I14: =INT($B14*I$2) -> 960 | J14: =INT($B14*J$2) -> 1440 | K14: =INT($B14*K$2) -> 1984 | ... AB14: =INT($B14*AB$2) -> 576000
A15: 金属厂（metal collector） | B15: =2/3/13 -> 0.051282051 | D15: =INT($B15*D$2) -> 192 | E15: =INT($B15*E$2) -> 256 | F15: =INT($B15*F$2) -> 384 | G15: =INT($B15*G$2) -> 512 | H15: =INT($B15*H$2) -> 768 | I15: =INT($B15*I$2) -> 960 | J15: =INT($B15*J$2) -> 1440 | K15: =INT($B15*K$2) -> 1984 | ... AB15: =INT($B15*AB$2) -> 576000
A16: 金属厂（metal collector） | B16: =2/3/13 -> 0.051282051 | D16: =INT($B16*D$2) -> 192 | E16: =INT($B16*E$2) -> 256 | F16: =INT($B16*F$2) -> 384 | G16: =INT($B16*G$2) -> 512 | H16: =INT($B16*H$2) -> 768 | I16: =INT($B16*I$2) -> 960 | J16: =INT($B16*J$2) -> 1440 | K16: =INT($B16*K$2) -> 1984 | ... AB16: =INT($B16*AB$2) -> 576000
A17: 仓库(storage) | B17: =1/3*[1]功能建筑权重!$E3 -> 0.026666667 | D17: =INT($B17*D$2) -> 99 | E17: =INT($B17*E$2) -> 133 | F17: =INT($B17*F$2) -> 199 | G17: =INT($B17*G$2) -> 266 | H17: =INT($B17*H$2) -> 399 | I17: =INT($B17*I$2) -> 499 | J17: =INT($B17*J$2) -> 748 | K17: =INT($B17*K$2) -> 1031 | ... AB17: =INT($B17*AB$2) -> 299520
A18: 城墙(wall) | B18: =1/3*[1]功能建筑权重!$E4 -> 0.026666667 | D18: =INT($B18*D$2) -> 99 | E18: =INT($B18*E$2) -> 133 | F18: =INT($B18*F$2) -> 199 | G18: =INT($B18*G$2) -> 266 | H18: =INT($B18*H$2) -> 399 | I18: =INT($B18*I$2) -> 499 | J18: =INT($B18*J$2) -> 748 | K18: =INT($B18*K$2) -> 1031 | ... AB18: =INT($B18*AB$2) -> 299520
A19: 科研中心(research center) | B19: =1/3*[1]功能建筑权重!$E9 -> 0.016666667 | D19: =INT($B19*D$2) -> 62 | E19: =INT($B19*E$2) -> 83 | F19: =INT($B19*F$2) -> 124 | G19: =INT($B19*G$2) -> 166 | H19: =INT($B19*H$2) -> 249 | I19: =INT($B19*I$2) -> 312 | J19: =INT($B19*J$2) -> 468 | K19: =INT($B19*K$2) -> 644 | ... AB19: =INT($B19*AB$2) -> 187200
A20: 岗哨(sentry) | B20: =1/3*[1]功能建筑权重!$E5 -> 0.01 | D20: =INT($B20*D$2) -> 37 | E20: =INT($B20*E$2) -> 49 | F20: =INT($B20*F$2) -> 74 | G20: =INT($B20*G$2) -> 99 | H20: =INT($B20*H$2) -> 149 | I20: =INT($B20*I$2) -> 187 | J20: =INT($B20*J$2) -> 280 | K20: =INT($B20*K$2) -> 386 | ... AB20: =INT($B20*AB$2) -> 112320
A21: 维修站(repair center) | B21: =1/3*[1]功能建筑权重!$E6 -> 0.016666667 | D21: =INT($B21*D$2) -> 62 | E21: =INT($B21*E$2) -> 83 | F21: =INT($B21*F$2) -> 124 | G21: =INT($B21*G$2) -> 166 | H21: =INT($B21*H$2) -> 249 | I21: =INT($B21*I$2) -> 312 | J21: =INT($B21*J$2) -> 468 | K21: =INT($B21*K$2) -> 644 | ... AB21: =INT($B21*AB$2) -> 187200
A22: 工厂(factory) | B22: =1/3*[1]功能建筑权重!$E7 -> 0.02 | D22: =INT($B22*D$2) -> 74 | E22: =INT($B22*E$2) -> 99 | F22: =INT($B22*F$2) -> 149 | G22: =INT($B22*G$2) -> 199 | H22: =INT($B22*H$2) -> 299 | I22: =INT($B22*I$2) -> 374 | J22: =INT($B22*J$2) -> 561 | K22: =INT($B22*K$2) -> 773 | ... AB22: =INT($B22*AB$2) -> 224640
A23: 工坊(workshop) | B23: =1/3*[1]功能建筑权重!$E8 -> 0.016666667 | D23: =INT($B23*D$2) -> 62 | E23: =INT($B23*E$2) -> 83 | F23: =INT($B23*F$2) -> 124 | G23: =INT($B23*G$2) -> 166 | H23: =INT($B23*H$2) -> 249 | I23: =INT($B23*I$2) -> 312 | J23: =INT($B23*J$2) -> 468 | K23: =INT($B23*K$2) -> 644 | ... AB23: =INT($B23*AB$2) -> 187200
A24: 车队指挥所（squad center） | B24: =1/3*[1]功能建筑权重!$E12 -> 0.016666667 | D24: =INT($B24*D$2) -> 62 | E24: =INT($B24*E$2) -> 83 | F24: =INT($B24*F$2) -> 124 | G24: =INT($B24*G$2) -> 166 | H24: =INT($B24*H$2) -> 249 | I24: =INT($B24*I$2) -> 312 | J24: =INT($B24*J$2) -> 468 | K24: =INT($B24*K$2) -> 644 | ... AB24: =INT($B24*AB$2) -> 187200
A25: 弹药库（Ammo depot） | B25: =1/3*[1]功能建筑权重!$E$13 -> 0.01 | D25: =INT($B25*D$2) -> 37 | E25: =INT($B25*E$2) -> 49 | F25: =INT($B25*F$2) -> 74 | G25: =INT($B25*G$2) -> 99 | H25: =INT($B25*H$2) -> 149 | I25: =INT($B25*I$2) -> 187 | J25: =INT($B25*J$2) -> 280 | K25: =INT($B25*K$2) -> 386 | ... AB25: =INT($B25*AB$2) -> 112320
A26: 集结旗(rally flag) | B26: =1/3*[1]功能建筑权重!$E10 -> 0.016666667 | D26: =INT($B26*D$2) -> 62 | E26: =INT($B26*E$2) -> 83 | F26: =INT($B26*F$2) -> 124 | G26: =INT($B26*G$2) -> 166 | H26: =INT($B26*H$2) -> 249 | I26: =INT($B26*I$2) -> 312 | J26: =INT($B26*J$2) -> 468 | K26: =INT($B26*K$2) -> 644 | ... AB26: =INT($B26*AB$2) -> 187200
A27: 营地(campsite) | B27: =1/3*[1]功能建筑权重!$E11 -> 0.016666667 | D27: =INT($B27*D$2) -> 62 | E27: =INT($B27*E$2) -> 83 | F27: =INT($B27*F$2) -> 124 | G27: =INT($B27*G$2) -> 166 | H27: =INT($B27*H$2) -> 249 | I27: =INT($B27*I$2) -> 312 | J27: =INT($B27*J$2) -> 468 | K27: =INT($B27*K$2) -> 644 | ... AB27: =INT($B27*AB$2) -> 187200
A28: 维修站(repair center) | B28: =1/3*[1]功能建筑权重!$E6 -> 0.016666667 | D28: =INT($B28*D$2) -> 62 | E28: =INT($B28*E$2) -> 83 | F28: =INT($B28*F$2) -> 124 | G28: =INT($B28*G$2) -> 166 | H28: =INT($B28*H$2) -> 249 | I28: =INT($B28*I$2) -> 312 | J28: =INT($B28*J$2) -> 468 | K28: =INT($B28*K$2) -> 644 | ... AB28: =INT($B28*AB$2) -> 187200
A29: 维修站(repair center) | B29: =1/3*[1]功能建筑权重!$E6 -> 0.016666667 | D29: =INT($B29*D$2) -> 62 | E29: =INT($B29*E$2) -> 83 | F29: =INT($B29*F$2) -> 124 | G29: =INT($B29*G$2) -> 166 | H29: =INT($B29*H$2) -> 249 | I29: =INT($B29*I$2) -> 312 | J29: =INT($B29*J$2) -> 468 | K29: =INT($B29*K$2) -> 644 | ... AB29: =INT($B29*AB$2) -> 187200
A30: 弹药库（Ammo depot） | B30: =1/3*[1]功能建筑权重!$E$13 -> 0.01 | D30: =INT($B30*D$2) -> 37 | E30: =INT($B30*E$2) -> 49 | F30: =INT($B30*F$2) -> 74 | G30: =INT($B30*G$2) -> 99 | H30: =INT($B30*H$2) -> 149 | I30: =INT($B30*I$2) -> 187 | J30: =INT($B30*J$2) -> 280 | K30: =INT($B30*K$2) -> 386 | ... AB30: =INT($B30*AB$2) -> 112320
A31: 弹药库（Ammo depot） | B31: =1/3*[1]功能建筑权重!$E$13 -> 0.01 | D31: =INT($B31*D$2) -> 37 | E31: =INT($B31*E$2) -> 49 | F31: =INT($B31*F$2) -> 74 | G31: =INT($B31*G$2) -> 99 | H31: =INT($B31*H$2) -> 149 | I31: =INT($B31*I$2) -> 187 | J31: =INT($B31*J$2) -> 280 | K31: =INT($B31*K$2) -> 386 | ... AB31: =INT($B31*AB$2) -> 112320
A32: 弹药库（Ammo depot） | B32: =1/3*[1]功能建筑权重!$E$13 -> 0.01 | D32: =INT($B32*D$2) -> 37 | E32: =INT($B32*E$2) -> 49 | F32: =INT($B32*F$2) -> 74 | G32: =INT($B32*G$2) -> 99 | H32: =INT($B32*H$2) -> 149 | I32: =INT($B32*I$2) -> 187 | J32: =INT($B32*J$2) -> 280 | K32: =INT($B32*K$2) -> 386 | ... AB32: =INT($B32*AB$2) -> 112320
A33: 弹药库（Ammo depot） | B33: =1/3*[1]功能建筑权重!$E$13 -> 0.01 | D33: =INT($B33*D$2) -> 37 | E33: =INT($B33*E$2) -> 49 | F33: =INT($B33*F$2) -> 74 | G33: =INT($B33*G$2) -> 99 | H33: =INT($B33*H$2) -> 149 | I33: =INT($B33*I$2) -> 187 | J33: =INT($B33*J$2) -> 280 | K33: =INT($B33*K$2) -> 386 | ... AB33: =INT($B33*AB$2) -> 112320
