Workbook

Sheet 计算基础值，极值问题
A1: 基础生命值 | B1: 162 | D1: 50级品质5达到多少上限值 | E1: 0.5 | G1: 护甲的上限效果 | H1: 1.5
A2: 基础攻击力 | B2: 57 | D2: 裸车在50级品质5占比 | E2: 0.1 | J2: 里面可以看出来用基础值不合适，还是应该给一些裸车基础值
A3: 让玩家有各方面分配的需求，求导得： | H3: 跟裸车在50级的属性占比有关 | I3: 按50级来计算的话 | J3: 比如暴击几率对应暴伤率的当前值，偏移几率对应着偏伤率的当前值。由于当前值还不好确定，先用基础值。后面将方程与f迭代处理
A4: 暴击afh=ecf+bczf+cz偏移afh=ecf+bczf-cz | D4: a | E4: h | F4: c | G4: b | H4: e | I4: z | J4: f | L4: 50级品质5参考值 | M4: 50级裸车属性 | O4: 裸车攻击力或生命值 | P4: 裸车带来的比率 | Q4: 基础比率 | R4: 原本的100% | S4: 比率起点
A5: 比率等级属性 | B5: 对应的基础属性 | C5: 比率跨度 | D5: 基础属性原值 | E5: 基础属性价值 | F5: 比率等级属性价值 | G5: 比率基础值 | H5: 裸车所带几率等级 | I5: 多少比率带来100% | J5: 对应乘数基础值 | O5: afh | P5: ecf | Q5: bczf | R5: cz | U5: 带来100%的属性价值
A6: 护甲 | B6: 生命值 | C6: 1.5 | D6: 4000 | E6: 0.25 | F6: 0.53 | G6: 0 | H6: =M6 -> 161.7 | I6: =L6/$E$1*100% -> 3234 | J6: 1 | L6: 1617 | M6: =L6*$E$2 -> 161.7 | O6: =D6*J6*E6 -> 1000 | P6: =H6*F6*J6 -> 85.701 | Q6: =G6*F6*I6*J6 -> 0 | R6: =F6*I6 -> 1714.02 | S6: =P6+Q6+R6 -> 1799.721 | U6: =I6*F6 -> 1714.02
A7: 暴击几率 | B7: 攻击力 | C7: 0.65 | D7: 1000 | E7: 1 | F7: 1.51 | G7: 0.05 | H7: =M7 -> 56.8 | I7: =L7/$E$1*100% -> 1136 | J7: 0.5 | L7: 568 | M7: =L7*$E$2 -> 56.8 | O7: =D7*J7*E7 -> 500 | P7: =H7*F7*J7 -> 42.884 | Q7: =G7*F7*I7*J7 -> 42.884 | R7: =F7*I7 -> 1715.36 | S7: =P7+Q7+R7 -> 1801.128 | U7: =I7*F7 -> 1715.36
A8: 暴击伤害 | B8: 攻击力 | C8: 1.5 | D8: 1000 | E8: 1 | F8: 0.5 | G8: 0.5 | H8: =M8 -> 171.4 | I8: =L8/$E$1*100% -> 3428 | J8: 0.5 | L8: 1714 | M8: =L8*$E$2 -> 171.4 | O8: =D8*J8*E8 -> 500 | P8: =H8*F8*J8 -> 42.85 | Q8: =G8*F8*I8*J8 -> 428.5 | R8: =F8*I8 -> 1714 | S8: =P8+Q8+R8 -> 2185.35 | U8: =I8*F8 -> 1714
A9: 偏移几率 | B9: 生命值 | C9: 0.7 | D9: 4000 | E9: 0.25 | F9: 1.13 | G9: 0.05 | H9: =M9 -> 75.8 | I9: =L9/$E$1*100% -> 1516 | J9: 0.5 | L9: 758 | M9: =L9*$E$2 -> 75.8 | O9: =D9*J9*E9 -> 500 | P9: =H9*F9*J9 -> 42.827 | Q9: =G9*F9*I9*J9 -> 42.827 | R9: =F9*I9 -> 1713.08 | S9: =P9+Q9-R9 -> -1627.426 | U9: =I9*F9 -> 1713.08
A10: 偏移伤害 | B10: 生命值 | C10: 0.33 | D10: 4000 | E10: 0.25 | F10: 1.13 | G10: 0.5 | H10: =M10 -> 75.8 | I10: =L10/$E$1*100% -> 1516 | J10: 0.5 | L10: 758 | M10: =L10*$E$2 -> 75.8 | O10: =D10*J10*E10 -> 500 | P10: =H10*F10*J10 -> 42.827 | Q10: =G10*F10*I10*J10 -> 428.27 | R10: =F10*I10 -> 1713.08 | S10: =P10+Q10-R10 -> -1241.983 | U10: =I10*F10 -> 1713.08

Sheet 属性种类
A1: 英文名 | B1: 中文名 | C1: 简述 | D1: 提高效果 | E1: 降低效果 | F1: 权重（） | G1: 以1级的假设 | H1: 以1级的实际效果 | I1: 备注
A2: Health Point | B2: 生命值 | C2: 治疗不可突破生命值上限，但护盾可以在这个限制之外发挥作用 | D2: 修理 | E2: 燃烧 | F2: 0.05 | G2: 200 | I2: 以10回合为假设 | K2: 随等级呈线性成长
A3: Attack | B3: 攻击力 | C3: 攻击力不区分物理、魔法 | D3: 增压 | E3: 过热 | F3: 1 | G3: 10 | I3: 基准
A4: Armor | B4: 护甲 | C4: 护甲可按比率降低对方造成的伤害。其伤害减免百分比与级别有关。 | D4: 加固 | E4: 腐蚀 | H4: 50%减伤，100%EHP | I4: 暂定为降低一半伤害
A5: Critical Chance Level | B5: 暴击几率等级 | C5: 影响伤害的几率性结果计算。其比率这算随对方升级而递减。 | D5: 嗜血 | E5: 压抑 | H5: 0.3
A6: Critical Result Level | B6: 暴击伤害等级 | H6: 0.1
A7: Shift Chance Level | B7: 偏移几率等级 | D7: 迅捷 | E7: 迟钝 | H7: 0.3
A8: Shift Result Level | B8: 偏移减伤等级 | H8: 0.1
B9: 精准等级 | C9: 降低自身攻击被偏移的几率。 | D9: 平稳 | E9: 震荡 | H9: 0.2
B10: 护甲穿透 | C10: 攻击敌方单位时忽略一部分护甲。极值情况为按0%护甲减伤计算。 | H10: 护甲/2。护甲穿透可能溢出，属性价值低于护甲。
B11: 韧性 | C11: 自身承受暴击时降低一部分暴击伤害。 | H11: 暴击伤害
A12: Attack Type | B12: 攻击类型 | C12: 分为散弹、穿透、投掷三种攻击类型，与护甲类型有互相克制的二维表关系 | K12: 理论上说战斗属性可以与运载力分开成长 | L12: 如果这么处理，可以在计算物品等级时将运载力做独特处理
A13: Armor Type | B13: 护甲类型 | C13: 轻甲、中甲、重甲三种。与供给类型有互相克制的二维表关系 | K13: 速度有其特殊之处：重要的是，A比B高这件事，高多少完全无所谓。 | L13: 这块可能是用类似运载力的逻辑，也可能用
B16: 回血速度 | C16: 每回合里回血的点数
B17: 吸血等级 | C17: 等级经过折算得到吸血比率
B18: 动力 | C18: 影响单位的大地图行军速度，以及战斗中的出手次序。以动力/负重得到速度。 | D18: 加速 | E18: 减速 | I18: 价值为多少无所谓，因为在回合制的体系下，只是决定谁先出手谁后出手。 比较关键的是：速度这个数值是否还有数值上的提升。 理论上来说，不同级别的同一单位，速度应当保持一致。 | J18: 速度这个属性比较特殊的地方在于：速度是单位穿越大地图时要用到的，并不在战斗过程中作重新的折算。
B19: 运载力 | C19: 影响车辆运送资源的数量 | J19: 运载力也是一个比较特殊的属性。运载力的膨胀速度大体上应当与主城的资源膨胀规模相契合。 因此运载力的alpha次方这个常数可以有一些常数变化
B21: 基于一个和装备方面假定的前提： 各装备的属性比重相同，其上的属性条目也类似。 而属性的复用程度也类似，因此各项属性的占比基本是平均的。 | D21: 基于这个假设，其属性权重值基本决定了我们看到的属性数值大小。
C26: 轻型车生产快，速度快，战斗时打不过重型车。这个打不过主要是防御力差距比较大 | D26: 轻型车打不过重型车这件事，通过哪种方式实现，这要和装备方面商量一下。比如： 轻型车的部位指数明显偏向于车轮、底盘等部位，以此来使得速度极快，战斗比较差。但这种方式下运载力如何处理是个问题。
D31: 比如：权重值不用固定值，而是分装甲类型来定（仅对于防御属性和速度属性）
D34: 比如：轻型车的防御类部件统一用较低的装备等级

Sheet 属性价值参考
A1: 名称 | B1: 效果 | C1: 等级 | D1: 价格
A2: 高级攻击力精华 | B2: +2.25 攻击力 | C2: 3 | D2: 1025 金币
A3: 高级成长攻击力精华 | B3: 每级+0.25 攻击力 (18级+4.5) | C3: 3 | D3: 515 金币
A4: 高级攻击速度精华 | B4: +4.5% 攻击速度 | C4: 3 | D4: 1025 金币
A5: 高级急速精华 | B5: 每级+0.11% 攻击速度 (18级+1.98%) | C5: 3 | D5: 0 金币
A6: 高级暴击伤害精华 | B6: +4.46% 暴击伤害 | C6: 3 | D6: 1025 金币
A7: 高级残暴精华 | B7: 每级+0.11% 暴击伤害 (18级+1.98%) | C7: 3 | D7: 0 金币
A8: 高级暴击几率精华 | B8: +1.86% 暴击几率 | C8: 3 | D8: 1025 金币
A9: 高级野蛮精华 | B9: 每级+0.11% 暴击几率 (18级+1.98%) | C9: 3 | D9: 0 金币
A10: 高级护甲穿透精华 | B10: +2.56护甲穿透 | C10: 3 | D10: 1025 金币
A11: 高级精准精华 | B11: 每级+0.11 护甲穿透 (18级+1.98) | C11: 3 | D11: 0 金币
A12: 高级生命值精华 | B12: +26点生命值 | C12: 3 | D12: 2050 金币
A13: 高级成长生命值精华 | B13: 每级+2.7 生命值 (18级+48.6) | C13: 3 | D13: 2050 金币
A14: 高级护甲精华 | B14: +4.26 护甲 | C14: 3 | D14: 1025 金币
A15: 高级成长护甲精华 | B15: 每级+0.38 护甲 (18级+6.84) | C15: 3 | D15: 1025 金币
A16: 高级魔法抗性精华 | B16: +4 魔法抗性 | C16: 3 | D16: 1025 金币
A17: 高级成长魔法抗性精华 | B17: 每级+0.37 魔法抗性 (18级+6.66) | C17: 3 | D17: 1025 金币
A18: 高级生命回复精华 | B18: +2.7 生命回复/5秒 | C18: 3 | D18: 2050 金币
A19: 高级成长生命回复精华 | B19: 每级+0.28 生命回复/5秒 (18级+5.04) | C19: 3 | D19: 2050 金币
A20: 高级回避精华 | B20: +1.5% 闪避几率 | C20: 3 | D20: 0 金币
A21: 高级闪避精华 | B21: 每级+0.11% 闪避几率 (18级+1.98%) | C21: 3 | D21: 0 金币
A22: 高级冷却缩减精华 | B22: -2.5% 冷却时间 | C22: 3 | D22: 2050 金币
A23: 高级成长冷却缩减精华 | B23: 每级-0.28% 冷却时间 (18级 -5%) | C23: 3 | D23: 1025 金币
A24: 高级法术强度精华 | B24: +4.95 法术强度 | C24: 3 | D24: 1025 金币
A25: 高级成长法术强度精华 | B25: 每级+0.43 法术强度 (18级+7.74) | C25: 3 | D25: 1025 金币
A26: 高级法力值精华 | B26: +37.5 法力值 | C26: 3 | D26: 1025 金币
A27: 高级成长法力值精华 | B27: 每级+4.17 法力值 (18级+75.06) | C27: 3 | D27: 515 金币
A28: 高级法力回复精华 | B28: +1.25 法力回复/5秒 | C28: 3 | D28: 1025 金币
A29: 高级成长法力回复精华 | B29: 每级+0.24 法力回复/5秒 (18级+4.32) | C29: 3 | D29: 1025 金币
A30: 高级法术穿透精华 | B30: +2.01法术穿透 | C30: 3 | D30: 1025 金币
A31: 高级辉煌精华 | B31: 每级+0.11 法术穿透 (18级+1.98) | C31: 3 | D31: 0 金币
A32: 高级移动速度精华 | B32: +1.5% 移动速度 | C32: 3 | D32: 2050 金币
A33: 高级重生精华 | B33: -5% 死亡时间 | C33: 3 | D33: 1025 金币
A34: 高级金币精华 | B34: 每10秒获得1点金钱 | C34: 3 | D34: 515 金币
A35: 高级经验值精华 | B35: +2% 经验获得 | C35: 3 | D35: 2050 金币
A36: 高级能量回复精华 | B36: +1.575 能量回复/5秒 | C36: 3 | D36: 2050 金币
A37: 高级能量值精华 | B37: +5.4 能量 | C37: 3 | D37: 1025 金币
A38: 高级坚毅精华 | B38: 唯一：减少英雄晕眩效果15%的持续时间 | C38: 3 | D38: 0 金币
A39: 高级长寿精华 | B39: 唯一：减少英雄减速和沉默效果15%的持续时间 | C39: 3 | D39: 0 金币
A40: 高级勇猛精华 | B40: 唯一：当你成功击杀或助攻击杀英雄时，你会永久性增加3点生命值，且第一次发生时，外加3点生命值。 | C40: 3 | D40: 0 金币
...

Sheet 装等示例
C1: alpha | D1: =LN(2)/LN(1.5) -> 1.7095113 | F1: 1/alpha | G1: =1/D1 -> 0.5849625
A2: statValue | B2: statValue | M2: sum | N2: itemValue
A3: 153 | B3: 153
A4: =POWER(A3,$D$1) -> 5429.4354 | B4: =POWER(B3,$D$1) -> 5429.4354 | M4: =SUM(A4:L4) -> 10858.871 | N4: =POWER(M4,G1) -> 229.5
A8: Quality | B8: positionFactor | C8: a | D8: b | E8: itemLevel
A9: 1 | B9: 0.33 | C9: 2 | D9: -2 | E9: =C9*$N$4/B9-D9 -> 1392.9091
A10: 2 | B10: 0.33 | C10: 1.8 | D10: -5 | E10: =C10*$N$4/B10-D10 -> 1256.8182
A11: 3 | B11: 0.33 | C11: 1.4 | D11: -8 | E11: =C11*$N$4/B11-D11 -> 981.63636
A12: 4 | B12: 0.33 | C12: 1.2 | D12: -12 | E12: =C12*$N$4/B12-D12 -> 846.54545
A13: 5 | B13: 0.33 | C13: 1 | D13: -17 | E13: =C13*$N$4/B13-D13 -> 712.45455
C15: alpha | D15: =LN(2)/LN(1.5) -> 1.7095113 | F15: 1/alpha | G15: =1/D15 -> 0.5849625
A16: statValue | B16: statValue | C16: statValue | D16: statValue | E16: statValue | F16: statValue | G16: statValue | H16: statValue | I16: statValue | J16: statValue | M16: sum | N16: itemValue
A17: 153 | B17: 153
A18: =POWER(A17,$D$1) -> 5429.4354 | B18: =POWER(B17,$D$1) -> 5429.4354 | M18: =SUM(A18:L18) -> 10858.871 | N18: =POWER(M18,G15) -> 229.5
A22: Quality | B22: positionFactor | C22: a | D22: b | E22: itemLevel
A23: 1 | B23: 2 | C23: 2 | D23: -2 | E23: =C23*$N$4/B23-D23 -> 231.5
A24: 2 | B24: 2 | C24: 1.8 | D24: -5 | E24: =C24*$N$4/B24-D24 -> 211.55
A25: 3 | B25: 2 | C25: 1.4 | D25: -8 | E25: =C25*$N$4/B25-D25 -> 168.65
A26: 4 | B26: 2 | C26: 1.2 | D26: -12 | E26: =C26*$N$4/B26-D26 -> 149.7
A27: 5 | B27: 2 | C27: 1 | D27: -17 | E27: =C27*$N$4/B27-D27 -> 131.75

Sheet 属性价值成长
D1: 2 | E1: 1.8 | F1: 1.4 | G1: 1.2 | H1: 1 | M1: 部位指数
D2: -2 | E2: -5 | F2: -8 | G2: -12 | H2: -17 | M2: 装备部位 | N2: 部位指数
A3: carLevel | B3: baseLoadingCapacity | C3: itemLevel | D3: quality 1 | E3: quality 2 | F3: quality 3 | G3: quality 4 | H3: quality 5 | M3: 引擎 | N3: 2
A4: 1 | B4: 200 | C4: =B4/2.5 -> 80 | D4: =($C4-D$2)/D$1*$N$8 -> 492 | E4: =($C4-E$2)/E$1*$N$8 -> 566.66667 | F4: =($C4-F$2)/F$1*$N$8 -> 754.28571 | G4: =($C4-G$2)/G$1*$N$8 -> 920 | H4: =($C4-H$2)/H$1*$N$8 -> 1164 | M4: 底盘 | N4: 2
A5: 2 | B5: 207 | C5: =B5/2.5 -> 82.8 | D5: =($C5-D$2)/D$1*$N$8 -> 508.8 | E5: =($C5-E$2)/E$1*$N$8 -> 585.33333 | F5: =($C5-F$2)/F$1*$N$8 -> 778.28571 | G5: =($C5-G$2)/G$1*$N$8 -> 948 | H5: =($C5-H$2)/H$1*$N$8 -> 1197.6 | M5: 轮胎 | N5: 2
A6: 3 | B6: 214 | C6: =B6/2.5 -> 85.6 | D6: =($C6-D$2)/D$1*$N$8 -> 525.6 | E6: =($C6-E$2)/E$1*$N$8 -> 604 | F6: =($C6-F$2)/F$1*$N$8 -> 802.28571 | G6: =($C6-G$2)/G$1*$N$8 -> 976 | H6: =($C6-H$2)/H$1*$N$8 -> 1231.2 | M6: 装甲 | N6: 3
A7: 4 | B7: 221 | C7: =B7/2.5 -> 88.4 | D7: =($C7-D$2)/D$1*$N$8 -> 542.4 | E7: =($C7-E$2)/E$1*$N$8 -> 622.66667 | F7: =($C7-F$2)/F$1*$N$8 -> 826.28571 | G7: =($C7-G$2)/G$1*$N$8 -> 1004 | H7: =($C7-H$2)/H$1*$N$8 -> 1264.8 | M7: 火炮 | N7: 3
A8: 5 | B8: 228 | C8: =B8/2.5 -> 91.2 | D8: =($C8-D$2)/D$1*$N$8 -> 559.2 | E8: =($C8-E$2)/E$1*$N$8 -> 641.33333 | F8: =($C8-F$2)/F$1*$N$8 -> 850.28571 | G8: =($C8-G$2)/G$1*$N$8 -> 1032 | H8: =($C8-H$2)/H$1*$N$8 -> 1298.4 | M8: total | N8: 12
A9: 6 | B9: 235 | C9: =B9/2.5 -> 94 | D9: =($C9-D$2)/D$1*$N$8 -> 576 | E9: =($C9-E$2)/E$1*$N$8 -> 660 | F9: =($C9-F$2)/F$1*$N$8 -> 874.28571 | G9: =($C9-G$2)/G$1*$N$8 -> 1060 | H9: =($C9-H$2)/H$1*$N$8 -> 1332
A10: 7 | B10: 242 | C10: =B10/2.5 -> 96.8 | D10: =($C10-D$2)/D$1*$N$8 -> 592.8 | E10: =($C10-E$2)/E$1*$N$8 -> 678.66667 | F10: =($C10-F$2)/F$1*$N$8 -> 898.28571 | G10: =($C10-G$2)/G$1*$N$8 -> 1088 | H10: =($C10-H$2)/H$1*$N$8 -> 1365.6 | J10: alpha | K10: =LN(2)/LN(1.5) -> 1.7095113 | M10: 1/alpha | N10: =1/K10 -> 0.5849625
A11: 8 | B11: 249 | C11: =B11/2.5 -> 99.6 | D11: =($C11-D$2)/D$1*$N$8 -> 609.6 | E11: =($C11-E$2)/E$1*$N$8 -> 697.33333 | F11: =($C11-F$2)/F$1*$N$8 -> 922.28571 | G11: =($C11-G$2)/G$1*$N$8 -> 1116 | H11: =($C11-H$2)/H$1*$N$8 -> 1399.2 | P11: 每个装备上有几条 | Q11: 5
A12: 9 | B12: 256 | C12: =B12/2.5 -> 102.4 | D12: =($C12-D$2)/D$1*$N$8 -> 626.4 | E12: =($C12-E$2)/E$1*$N$8 -> 716 | F12: =($C12-F$2)/F$1*$N$8 -> 946.28571 | G12: =($C12-G$2)/G$1*$N$8 -> 1144 | H12: =($C12-H$2)/H$1*$N$8 -> 1432.8 | J12: itemValue | K12: 3612 | M12: poweralpha | N12: =POWER(K12,K10) -> 1207841.5 | P12: 属性重复次数 | Q12: =Q11/10 -> 0.5
A13: 10 | B13: 263 | C13: =B13/2.5 -> 105.2 | D13: =($C13-D$2)/D$1*$N$8 -> 643.2 | E13: =($C13-E$2)/E$1*$N$8 -> 734.66667 | F13: =($C13-F$2)/F$1*$N$8 -> 970.28571 | G13: =($C13-G$2)/G$1*$N$8 -> 1172 | H13: =($C13-H$2)/H$1*$N$8 -> 1466.4
A14: 11 | B14: 270 | C14: =B14/2.5 -> 108 | D14: =($C14-D$2)/D$1*$N$8 -> 660 | E14: =($C14-E$2)/E$1*$N$8 -> 753.33333 | F14: =($C14-F$2)/F$1*$N$8 -> 994.28571 | G14: =($C14-G$2)/G$1*$N$8 -> 1200 | H14: =($C14-H$2)/H$1*$N$8 -> 1500 | J14: stat1 | K14: stat2 | L14: stat3 | M14: stat4 | N14: stat5
A15: 12 | B15: 279 | C15: =B15/2.5 -> 111.6 | D15: =($C15-D$2)/D$1*$N$8 -> 681.6 | E15: =($C15-E$2)/E$1*$N$8 -> 777.33333 | F15: =($C15-F$2)/F$1*$N$8 -> 1025.1429 | G15: =($C15-G$2)/G$1*$N$8 -> 1236 | H15: =($C15-H$2)/H$1*$N$8 -> 1543.2 | I15: % | J15: 0.2 | K15: 0.2 | L15: 0.2 | M15: 0.2 | N15: 0.2
A16: 13 | B16: 288 | C16: =B16/2.5 -> 115.2 | D16: =($C16-D$2)/D$1*$N$8 -> 703.2 | E16: =($C16-E$2)/E$1*$N$8 -> 801.33333 | F16: =($C16-F$2)/F$1*$N$8 -> 1056 | G16: =($C16-G$2)/G$1*$N$8 -> 1272 | H16: =($C16-H$2)/H$1*$N$8 -> 1586.4 | J16: =$N$12*J15 -> 241568.29 | K16: =$N$12*K15 -> 241568.29 | L16: =$N$12*L15 -> 241568.29 | M16: =$N$12*M15 -> 241568.29 | N16: =$N$12*N15 -> 241568.29
A17: 14 | B17: 298 | C17: =B17/2.5 -> 119.2 | D17: =($C17-D$2)/D$1*$N$8 -> 727.2 | E17: =($C17-E$2)/E$1*$N$8 -> 828 | F17: =($C17-F$2)/F$1*$N$8 -> 1090.2857 | G17: =($C17-G$2)/G$1*$N$8 -> 1312 | H17: =($C17-H$2)/H$1*$N$8 -> 1634.4 | J17: =POWER(J16,$N$10) -> 1408.8881 | K17: =POWER(K16,$N$10) -> 1408.8881 | L17: =POWER(L16,$N$10) -> 1408.8881 | M17: =POWER(M16,$N$10) -> 1408.8881 | N17: =POWER(N16,$N$10) -> 1408.8881
A18: 15 | B18: 307 | C18: =B18/2.5 -> 122.8 | D18: =($C18-D$2)/D$1*$N$8 -> 748.8 | E18: =($C18-E$2)/E$1*$N$8 -> 852 | F18: =($C18-F$2)/F$1*$N$8 -> 1121.1429 | G18: =($C18-G$2)/G$1*$N$8 -> 1348 | H18: =($C18-H$2)/H$1*$N$8 -> 1677.6 | I18: 每条价值 | J18: =J17*$Q$12 -> 704.44405 | K18: =K17*$Q$12 -> 704.44405 | L18: =L17*$Q$12 -> 704.44405 | M18: =M17*$Q$12 -> 704.44405 | N18: =N17*$Q$12 -> 704.44405
A19: 16 | B19: 317 | C19: =B19/2.5 -> 126.8 | D19: =($C19-D$2)/D$1*$N$8 -> 772.8 | E19: =($C19-E$2)/E$1*$N$8 -> 878.66667 | F19: =($C19-F$2)/F$1*$N$8 -> 1155.4286 | G19: =($C19-G$2)/G$1*$N$8 -> 1388 | H19: =($C19-H$2)/H$1*$N$8 -> 1725.6 | L19: 50级品质4 | M19: 30级品质3 | N19: 1级品质1
A20: 17 | B20: 326 | C20: =B20/2.5 -> 130.4 | D20: =($C20-D$2)/D$1*$N$8 -> 794.4 | E20: =($C20-E$2)/E$1*$N$8 -> 902.66667 | F20: =($C20-F$2)/F$1*$N$8 -> 1186.2857 | G20: =($C20-G$2)/G$1*$N$8 -> 1424 | H20: =($C20-H$2)/H$1*$N$8 -> 1768.8 | K20: 单条属性价值 | L20: 704
A21: 18 | B21: 336 | C21: =B21/2.5 -> 134.4 | D21: =($C21-D$2)/D$1*$N$8 -> 818.4 | E21: =($C21-E$2)/E$1*$N$8 -> 929.33333 | F21: =($C21-F$2)/F$1*$N$8 -> 1220.5714 | G21: =($C21-G$2)/G$1*$N$8 -> 1464 | H21: =($C21-H$2)/H$1*$N$8 -> 1816.8 | J21: 属性 | K21: 属性价值系数
A22: 19 | B22: 345 | C22: =B22/2.5 -> 138 | D22: =($C22-D$2)/D$1*$N$8 -> 840 | E22: =($C22-E$2)/E$1*$N$8 -> 953.33333 | F22: =($C22-F$2)/F$1*$N$8 -> 1251.4286 | G22: =($C22-G$2)/G$1*$N$8 -> 1500 | H22: =($C22-H$2)/H$1*$N$8 -> 1860 | J22: 生命值 | K22: 0.25 | L22: =L$20/$K22 -> 2816 | M22: =M$20/$K22 -> 0 | N22: =N$20/$K22 -> 0
A23: 20 | B23: 355 | C23: =B23/2.5 -> 142 | D23: =($C23-D$2)/D$1*$N$8 -> 864 | E23: =($C23-E$2)/E$1*$N$8 -> 980 | F23: =($C23-F$2)/F$1*$N$8 -> 1285.7143 | G23: =($C23-G$2)/G$1*$N$8 -> 1540 | H23: =($C23-H$2)/H$1*$N$8 -> 1908 | J23: 攻击力 | K23: 1 | L23: =L$20/$K23 -> 704 | M23: =M$20/$K23 -> 0 | N23: =N$20/$K23 -> 0
A24: 21 | B24: 364 | C24: =B24/2.5 -> 145.6 | D24: =($C24-D$2)/D$1*$N$8 -> 885.6 | E24: =($C24-E$2)/E$1*$N$8 -> 1004 | F24: =($C24-F$2)/F$1*$N$8 -> 1316.5714 | G24: =($C24-G$2)/G$1*$N$8 -> 1576 | H24: =($C24-H$2)/H$1*$N$8 -> 1951.2 | J24: 护甲 | K24: 0.53 | L24: =L$20/$K24 -> 1328.3019 | M24: =M$20/$K24 -> 0 | N24: =N$20/$K24 -> 0
A25: 22 | B25: 377 | C25: =B25/2.5 -> 150.8 | D25: =($C25-D$2)/D$1*$N$8 -> 916.8 | E25: =($C25-E$2)/E$1*$N$8 -> 1038.6667 | F25: =($C25-F$2)/F$1*$N$8 -> 1361.1429 | G25: =($C25-G$2)/G$1*$N$8 -> 1628 | H25: =($C25-H$2)/H$1*$N$8 -> 2013.6 | J25: 暴击伤害等级 | K25: 0.5 | L25: =L$20/$K25 -> 1408 | M25: =M$20/$K25 -> 0 | N25: =N$20/$K25 -> 0
A26: 23 | B26: 390 | C26: =B26/2.5 -> 156 | D26: =($C26-D$2)/D$1*$N$8 -> 948 | E26: =($C26-E$2)/E$1*$N$8 -> 1073.3333 | F26: =($C26-F$2)/F$1*$N$8 -> 1405.7143 | G26: =($C26-G$2)/G$1*$N$8 -> 1680 | H26: =($C26-H$2)/H$1*$N$8 -> 2076 | J26: 暴击几率等级 | K26: 1.51 | L26: =L$20/$K26 -> 466.22517 | M26: =M$20/$K26 -> 0 | N26: =N$20/$K26 -> 0
A27: 24 | B27: 402 | C27: =B27/2.5 -> 160.8 | D27: =($C27-D$2)/D$1*$N$8 -> 976.8 | E27: =($C27-E$2)/E$1*$N$8 -> 1105.3333 | F27: =($C27-F$2)/F$1*$N$8 -> 1446.8571 | G27: =($C27-G$2)/G$1*$N$8 -> 1728 | H27: =($C27-H$2)/H$1*$N$8 -> 2133.6 | J27: 偏移几率等级 | K27: 1.13 | L27: =L$20/$K27 -> 623.00885 | M27: =M$20/$K27 -> 0 | N27: =N$20/$K27 -> 0
A28: 25 | B28: 415 | C28: =B28/2.5 -> 166 | D28: =($C28-D$2)/D$1*$N$8 -> 1008 | E28: =($C28-E$2)/E$1*$N$8 -> 1140 | F28: =($C28-F$2)/F$1*$N$8 -> 1491.4286 | G28: =($C28-G$2)/G$1*$N$8 -> 1780 | H28: =($C28-H$2)/H$1*$N$8 -> 2196 | J28: 偏移减伤等级 | K28: 1.13 | L28: =L$20/$K28 -> 623.00885 | M28: =M$20/$K28 -> 0 | N28: =N$20/$K28 -> 0
A29: 26 | B29: 428 | C29: =B29/2.5 -> 171.2 | D29: =($C29-D$2)/D$1*$N$8 -> 1039.2 | E29: =($C29-E$2)/E$1*$N$8 -> 1174.6667 | F29: =($C29-F$2)/F$1*$N$8 -> 1536 | G29: =($C29-G$2)/G$1*$N$8 -> 1832 | H29: =($C29-H$2)/H$1*$N$8 -> 2258.4 | J29: 护甲穿透 | K29: 0.88 | L29: =L$20/$K29 -> 800 | M29: =M$20/$K29 -> 0 | N29: =N$20/$K29 -> 0
A30: 27 | B30: 441 | C30: =B30/2.5 -> 176.4 | D30: =($C30-D$2)/D$1*$N$8 -> 1070.4 | E30: =($C30-E$2)/E$1*$N$8 -> 1209.3333 | F30: =($C30-F$2)/F$1*$N$8 -> 1580.5714 | G30: =($C30-G$2)/G$1*$N$8 -> 1884 | H30: =($C30-H$2)/H$1*$N$8 -> 2320.8 | J30: 韧性等级 | K30: 0.84 | L30: =L$20/$K30 -> 838.09524 | M30: =M$20/$K30 -> 0 | N30: =N$20/$K30 -> 0
A31: 28 | B31: 453 | C31: =B31/2.5 -> 181.2 | D31: =($C31-D$2)/D$1*$N$8 -> 1099.2 | E31: =($C31-E$2)/E$1*$N$8 -> 1241.3333 | F31: =($C31-F$2)/F$1*$N$8 -> 1621.7143 | G31: =($C31-G$2)/G$1*$N$8 -> 1932 | H31: =($C31-H$2)/H$1*$N$8 -> 2378.4 | J31: 精准等级 | K31: 1.87 | L31: =L$20/$K31 -> 376.47059 | M31: =M$20/$K31 -> 0 | N31: =N$20/$K31 -> 0
A32: 29 | B32: 466 | C32: =B32/2.5 -> 186.4 | D32: =($C32-D$2)/D$1*$N$8 -> 1130.4 | E32: =($C32-E$2)/E$1*$N$8 -> 1276 | F32: =($C32-F$2)/F$1*$N$8 -> 1666.2857 | G32: =($C32-G$2)/G$1*$N$8 -> 1984 | H32: =($C32-H$2)/H$1*$N$8 -> 2440.8
A33: 30 | B33: 479 | C33: =B33/2.5 -> 191.6 | D33: =($C33-D$2)/D$1*$N$8 -> 1161.6 | E33: =($C33-E$2)/E$1*$N$8 -> 1310.6667 | F33: =($C33-F$2)/F$1*$N$8 -> 1710.8571 | G33: =($C33-G$2)/G$1*$N$8 -> 2036 | H33: =($C33-H$2)/H$1*$N$8 -> 2503.2
A34: 31 | B34: 492 | C34: =B34/2.5 -> 196.8 | D34: =($C34-D$2)/D$1*$N$8 -> 1192.8 | E34: =($C34-E$2)/E$1*$N$8 -> 1345.3333 | F34: =($C34-F$2)/F$1*$N$8 -> 1755.4286 | G34: =($C34-G$2)/G$1*$N$8 -> 2088 | H34: =($C34-H$2)/H$1*$N$8 -> 2565.6
A35: 32 | B35: 509 | C35: =B35/2.5 -> 203.6 | D35: =($C35-D$2)/D$1*$N$8 -> 1233.6 | E35: =($C35-E$2)/E$1*$N$8 -> 1390.6667 | F35: =($C35-F$2)/F$1*$N$8 -> 1813.7143 | G35: =($C35-G$2)/G$1*$N$8 -> 2156 | H35: =($C35-H$2)/H$1*$N$8 -> 2647.2
A36: 33 | B36: 526 | C36: =B36/2.5 -> 210.4 | D36: =($C36-D$2)/D$1*$N$8 -> 1274.4 | E36: =($C36-E$2)/E$1*$N$8 -> 1436 | F36: =($C36-F$2)/F$1*$N$8 -> 1872 | G36: =($C36-G$2)/G$1*$N$8 -> 2224 | H36: =($C36-H$2)/H$1*$N$8 -> 2728.8
A37: 34 | B37: 543 | C37: =B37/2.5 -> 217.2 | D37: =($C37-D$2)/D$1*$N$8 -> 1315.2 | E37: =($C37-E$2)/E$1*$N$8 -> 1481.3333 | F37: =($C37-F$2)/F$1*$N$8 -> 1930.2857 | G37: =($C37-G$2)/G$1*$N$8 -> 2292 | H37: =($C37-H$2)/H$1*$N$8 -> 2810.4
A38: 35 | B38: 560 | C38: =B38/2.5 -> 224 | D38: =($C38-D$2)/D$1*$N$8 -> 1356 | E38: =($C38-E$2)/E$1*$N$8 -> 1526.6667 | F38: =($C38-F$2)/F$1*$N$8 -> 1988.5714 | G38: =($C38-G$2)/G$1*$N$8 -> 2360 | H38: =($C38-H$2)/H$1*$N$8 -> 2892
A39: 36 | B39: 578 | C39: =B39/2.5 -> 231.2 | D39: =($C39-D$2)/D$1*$N$8 -> 1399.2 | E39: =($C39-E$2)/E$1*$N$8 -> 1574.6667 | F39: =($C39-F$2)/F$1*$N$8 -> 2050.2857 | G39: =($C39-G$2)/G$1*$N$8 -> 2432 | H39: =($C39-H$2)/H$1*$N$8 -> 2978.4
A40: 37 | B40: 595 | C40: =B40/2.5 -> 238 | D40: =($C40-D$2)/D$1*$N$8 -> 1440 | E40: =($C40-E$2)/E$1*$N$8 -> 1620 | F40: =($C40-F$2)/F$1*$N$8 -> 2108.5714 | G40: =($C40-G$2)/G$1*$N$8 -> 2500 | H40: =($C40-H$2)/H$1*$N$8 -> 3060
...

Sheet 属性价值成长（以火炮为例）
D1: 2 | E1: 1.8 | F1: 1.4 | G1: 1.2 | H1: 1 | M1: 部位指数
D2: -2 | E2: -5 | F2: -8 | G2: -12 | H2: -17 | M2: 装备部位 | N2: 部位指数 | Q2: 1710
A3: carLevel | B3: baseLoadingCapacity | C3: itemLevel | D3: quality 1 | E3: quality 2 | F3: quality 3 | G3: quality 4 | H3: quality 5 | M3: 引擎 | N3: 2
A4: 1 | B4: 200 | C4: =B4/2.5 -> 80 | D4: =($C4-D$2)/D$1*$N$7 -> 123 | E4: =($C4-E$2)/E$1*$N$7 -> 141.66667 | F4: =($C4-F$2)/F$1*$N$7 -> 188.57143 | G4: =($C4-G$2)/G$1*$N$7 -> 230 | H4: =($C4-H$2)/H$1*$N$7 -> 291 | M4: 底盘 | N4: 2
A5: 2 | B5: 207 | C5: =B5/2.5 -> 82.8 | D5: =($C5-D$2)/D$1*$N$7 -> 127.2 | E5: =($C5-E$2)/E$1*$N$7 -> 146.33333 | F5: =($C5-F$2)/F$1*$N$7 -> 194.57143 | G5: =($C5-G$2)/G$1*$N$7 -> 237 | H5: =($C5-H$2)/H$1*$N$7 -> 299.4 | M5: 轮胎 | N5: 2
A6: 3 | B6: 214 | C6: =B6/2.5 -> 85.6 | D6: =($C6-D$2)/D$1*$N$7 -> 131.4 | E6: =($C6-E$2)/E$1*$N$7 -> 151 | F6: =($C6-F$2)/F$1*$N$7 -> 200.57143 | G6: =($C6-G$2)/G$1*$N$7 -> 244 | H6: =($C6-H$2)/H$1*$N$7 -> 307.8 | M6: 装甲 | N6: 3
A7: 4 | B7: 221 | C7: =B7/2.5 -> 88.4 | D7: =($C7-D$2)/D$1*$N$7 -> 135.6 | E7: =($C7-E$2)/E$1*$N$7 -> 155.66667 | F7: =($C7-F$2)/F$1*$N$7 -> 206.57143 | G7: =($C7-G$2)/G$1*$N$7 -> 251 | H7: =($C7-H$2)/H$1*$N$7 -> 316.2 | M7: 火炮 | N7: 3
A8: 5 | B8: 228 | C8: =B8/2.5 -> 91.2 | D8: =($C8-D$2)/D$1*$N$7 -> 139.8 | E8: =($C8-E$2)/E$1*$N$7 -> 160.33333 | F8: =($C8-F$2)/F$1*$N$7 -> 212.57143 | G8: =($C8-G$2)/G$1*$N$7 -> 258 | H8: =($C8-H$2)/H$1*$N$7 -> 324.6 | M8: total | N8: 12
A9: 6 | B9: 235 | C9: =B9/2.5 -> 94 | D9: =($C9-D$2)/D$1*$N$7 -> 144 | E9: =($C9-E$2)/E$1*$N$7 -> 165 | F9: =($C9-F$2)/F$1*$N$7 -> 218.57143 | G9: =($C9-G$2)/G$1*$N$7 -> 265 | H9: =($C9-H$2)/H$1*$N$7 -> 333
A10: 7 | B10: 242 | C10: =B10/2.5 -> 96.8 | D10: =($C10-D$2)/D$1*$N$7 -> 148.2 | E10: =($C10-E$2)/E$1*$N$7 -> 169.66667 | F10: =($C10-F$2)/F$1*$N$7 -> 224.57143 | G10: =($C10-G$2)/G$1*$N$7 -> 272 | H10: =($C10-H$2)/H$1*$N$7 -> 341.4 | J10: alpha | K10: =LN(2)/LN(1.5) -> 1.7095113 | M10: 1/alpha | N10: =1/K10 -> 0.5849625
A11: 8 | B11: 249 | C11: =B11/2.5 -> 99.6 | D11: =($C11-D$2)/D$1*$N$7 -> 152.4 | E11: =($C11-E$2)/E$1*$N$7 -> 174.33333 | F11: =($C11-F$2)/F$1*$N$7 -> 230.57143 | G11: =($C11-G$2)/G$1*$N$7 -> 279 | H11: =($C11-H$2)/H$1*$N$7 -> 349.8 | P11: 每个装备上有几条 | Q11: 5
A12: 9 | B12: 256 | C12: =B12/2.5 -> 102.4 | D12: =($C12-D$2)/D$1*$N$7 -> 156.6 | E12: =($C12-E$2)/E$1*$N$7 -> 179 | F12: =($C12-F$2)/F$1*$N$7 -> 236.57143 | G12: =($C12-G$2)/G$1*$N$7 -> 286 | H12: =($C12-H$2)/H$1*$N$7 -> 358.2 | J12: itemValue | K12: 1099 | M12: poweralpha | N12: =POWER(K12,K10) -> 157986.47 | P12: 属性重复次数 | Q12: =4*Q11/10 -> 2
A13: 10 | B13: 263 | C13: =B13/2.5 -> 105.2 | D13: =($C13-D$2)/D$1*$N$7 -> 160.8 | E13: =($C13-E$2)/E$1*$N$7 -> 183.66667 | F13: =($C13-F$2)/F$1*$N$7 -> 242.57143 | G13: =($C13-G$2)/G$1*$N$7 -> 293 | H13: =($C13-H$2)/H$1*$N$7 -> 366.6
A14: 11 | B14: 270 | C14: =B14/2.5 -> 108 | D14: =($C14-D$2)/D$1*$N$7 -> 165 | E14: =($C14-E$2)/E$1*$N$7 -> 188.33333 | F14: =($C14-F$2)/F$1*$N$7 -> 248.57143 | G14: =($C14-G$2)/G$1*$N$7 -> 300 | H14: =($C14-H$2)/H$1*$N$7 -> 375 | J14: stat1 | K14: stat2 | L14: stat3 | M14: stat4 | N14: stat5
A15: 12 | B15: 279 | C15: =B15/2.5 -> 111.6 | D15: =($C15-D$2)/D$1*$N$7 -> 170.4 | E15: =($C15-E$2)/E$1*$N$7 -> 194.33333 | F15: =($C15-F$2)/F$1*$N$7 -> 256.28571 | G15: =($C15-G$2)/G$1*$N$7 -> 309 | H15: =($C15-H$2)/H$1*$N$7 -> 385.8 | I15: % | J15: 0.2 | K15: 0.2 | L15: 0.2 | M15: 0.2 | N15: 0.2
A16: 13 | B16: 288 | C16: =B16/2.5 -> 115.2 | D16: =($C16-D$2)/D$1*$N$7 -> 175.8 | E16: =($C16-E$2)/E$1*$N$7 -> 200.33333 | F16: =($C16-F$2)/F$1*$N$7 -> 264 | G16: =($C16-G$2)/G$1*$N$7 -> 318 | H16: =($C16-H$2)/H$1*$N$7 -> 396.6 | J16: =$N$12*J15 -> 31597.294 | K16: =$N$12*K15 -> 31597.294 | L16: =$N$12*L15 -> 31597.294 | M16: =$N$12*M15 -> 31597.294 | N16: =$N$12*N15 -> 31597.294
A17: 14 | B17: 298 | C17: =B17/2.5 -> 119.2 | D17: =($C17-D$2)/D$1*$N$7 -> 181.8 | E17: =($C17-E$2)/E$1*$N$7 -> 207 | F17: =($C17-F$2)/F$1*$N$7 -> 272.57143 | G17: =($C17-G$2)/G$1*$N$7 -> 328 | H17: =($C17-H$2)/H$1*$N$7 -> 408.6 | J17: =POWER(J16,$N$10) -> 428.67332 | K17: =POWER(K16,$N$10) -> 428.67332 | L17: =POWER(L16,$N$10) -> 428.67332 | M17: =POWER(M16,$N$10) -> 428.67332 | N17: =POWER(N16,$N$10) -> 428.67332
A18: 15 | B18: 307 | C18: =B18/2.5 -> 122.8 | D18: =($C18-D$2)/D$1*$N$7 -> 187.2 | E18: =($C18-E$2)/E$1*$N$7 -> 213 | F18: =($C18-F$2)/F$1*$N$7 -> 280.28571 | G18: =($C18-G$2)/G$1*$N$7 -> 337 | H18: =($C18-H$2)/H$1*$N$7 -> 419.4 | I18: 每条价值 | J18: =J17*$Q$12 -> 857.34663 | K18: =K17*$Q$12 -> 857.34663 | L18: =L17*$Q$12 -> 857.34663 | M18: =M17*$Q$12 -> 857.34663 | N18: =N17*$Q$12 -> 857.34663
A19: 16 | B19: 317 | C19: =B19/2.5 -> 126.8 | D19: =($C19-D$2)/D$1*$N$7 -> 193.2 | E19: =($C19-E$2)/E$1*$N$7 -> 219.66667 | F19: =($C19-F$2)/F$1*$N$7 -> 288.85714 | G19: =($C19-G$2)/G$1*$N$7 -> 347 | H19: =($C19-H$2)/H$1*$N$7 -> 431.4 | L19: 50级品质4 | M19: 30级品质3 | N19: 1级品质1 | O19: 50级品质5 | S19: 50级裸车
A20: 17 | B20: 326 | C20: =B20/2.5 -> 130.4 | D20: =($C20-D$2)/D$1*$N$7 -> 198.6 | E20: =($C20-E$2)/E$1*$N$7 -> 225.66667 | F20: =($C20-F$2)/F$1*$N$7 -> 296.57143 | G20: =($C20-G$2)/G$1*$N$7 -> 356 | H20: =($C20-H$2)/H$1*$N$7 -> 442.2 | K20: 单条属性价值 | L20: 704 | M20: 269 | N20: 171 | O20: 857
A21: 18 | B21: 336 | C21: =B21/2.5 -> 134.4 | D21: =($C21-D$2)/D$1*$N$7 -> 204.6 | E21: =($C21-E$2)/E$1*$N$7 -> 232.33333 | F21: =($C21-F$2)/F$1*$N$7 -> 305.14286 | G21: =($C21-G$2)/G$1*$N$7 -> 366 | H21: =($C21-H$2)/H$1*$N$7 -> 454.2 | J21: 属性 | K21: 属性价值系数 | Q21: =25*10/3/K22 -> 333.33333
A22: 19 | B22: 345 | C22: =B22/2.5 -> 138 | D22: =($C22-D$2)/D$1*$N$7 -> 210 | E22: =($C22-E$2)/E$1*$N$7 -> 238.33333 | F22: =($C22-F$2)/F$1*$N$7 -> 312.85714 | G22: =($C22-G$2)/G$1*$N$7 -> 375 | H22: =($C22-H$2)/H$1*$N$7 -> 465 | I22: =25/K22 -> 100 | J22: 生命值 | K22: 0.25 | L22: =L$20/$K22 -> 2816 | M22: =M$20/$K22 -> 1076 | N22: =N$20/$K22 -> 684 | O22: =O$20/$K22 -> 3428 | Q22: =25*10/3/K23 -> 83.333333 | S22: =O22/9 -> 380.88889
A23: 20 | B23: 355 | C23: =B23/2.5 -> 142 | D23: =($C23-D$2)/D$1*$N$7 -> 216 | E23: =($C23-E$2)/E$1*$N$7 -> 245 | F23: =($C23-F$2)/F$1*$N$7 -> 321.42857 | G23: =($C23-G$2)/G$1*$N$7 -> 385 | H23: =($C23-H$2)/H$1*$N$7 -> 477 | I23: =25/K23 -> 25 | J23: 攻击力 | K23: 1 | L23: =L$20/$K23 -> 704 | M23: =M$20/$K23 -> 269 | N23: =N$20/$K23 -> 171 | O23: =O$20/$K23 -> 857 | Q23: =25*10/3/K24 -> 157.2327 | S23: =O23/9 -> 95.222222
A24: 21 | B24: 364 | C24: =B24/2.5 -> 145.6 | D24: =($C24-D$2)/D$1*$N$7 -> 221.4 | E24: =($C24-E$2)/E$1*$N$7 -> 251 | F24: =($C24-F$2)/F$1*$N$7 -> 329.14286 | G24: =($C24-G$2)/G$1*$N$7 -> 394 | H24: =($C24-H$2)/H$1*$N$7 -> 487.8 | I24: =25/K24 -> 47.169811 | J24: 护甲 | K24: 0.53 | L24: =L$20/$K24 -> 1328.3019 | M24: =M$20/$K24 -> 507.54717 | N24: =N$20/$K24 -> 322.64151 | O24: =O$20/$K24 -> 1616.9811 | S24: =O24/9 -> 179.66457
A25: 22 | B25: 377 | C25: =B25/2.5 -> 150.8 | D25: =($C25-D$2)/D$1*$N$7 -> 229.2 | E25: =($C25-E$2)/E$1*$N$7 -> 259.66667 | F25: =($C25-F$2)/F$1*$N$7 -> 340.28571 | G25: =($C25-G$2)/G$1*$N$7 -> 407 | H25: =($C25-H$2)/H$1*$N$7 -> 503.4 | I25: =25/K25 -> 16.556291 | J25: 暴击几率等级 | K25: 1.51 | L25: =L$20/$K25 -> 466.22517 | M25: =M$20/$K25 -> 178.1457 | N25: =N$20/$K25 -> 113.24503 | O25: =O$20/$K25 -> 567.54967 | S25: =O25/9 -> 63.061074
A26: 23 | B26: 390 | C26: =B26/2.5 -> 156 | D26: =($C26-D$2)/D$1*$N$7 -> 237 | E26: =($C26-E$2)/E$1*$N$7 -> 268.33333 | F26: =($C26-F$2)/F$1*$N$7 -> 351.42857 | G26: =($C26-G$2)/G$1*$N$7 -> 420 | H26: =($C26-H$2)/H$1*$N$7 -> 519 | I26: =25/K26 -> 50 | J26: 暴击伤害等级 | K26: 0.5 | L26: =L$20/$K26 -> 1408 | M26: =M$20/$K26 -> 538 | N26: =N$20/$K26 -> 342 | O26: =O$20/$K26 -> 1714 | S26: =O26/9 -> 190.44444
A27: 24 | B27: 402 | C27: =B27/2.5 -> 160.8 | D27: =($C27-D$2)/D$1*$N$7 -> 244.2 | E27: =($C27-E$2)/E$1*$N$7 -> 276.33333 | F27: =($C27-F$2)/F$1*$N$7 -> 361.71429 | G27: =($C27-G$2)/G$1*$N$7 -> 432 | H27: =($C27-H$2)/H$1*$N$7 -> 533.4 | I27: =25/K27 -> 22.123894 | J27: 偏移几率等级 | K27: 1.13 | L27: =L$20/$K27 -> 623.00885 | M27: =M$20/$K27 -> 238.0531 | N27: =N$20/$K27 -> 151.32743 | O27: =O$20/$K27 -> 758.40708 | S27: =O27/9 -> 84.267453
A28: 25 | B28: 415 | C28: =B28/2.5 -> 166 | D28: =($C28-D$2)/D$1*$N$7 -> 252 | E28: =($C28-E$2)/E$1*$N$7 -> 285 | F28: =($C28-F$2)/F$1*$N$7 -> 372.85714 | G28: =($C28-G$2)/G$1*$N$7 -> 445 | H28: =($C28-H$2)/H$1*$N$7 -> 549 | I28: =25/K28 -> 22.123894 | J28: 偏移减伤等级 | K28: 1.13 | L28: =L$20/$K28 -> 623.00885 | M28: =M$20/$K28 -> 238.0531 | N28: =N$20/$K28 -> 151.32743 | O28: =O$20/$K28 -> 758.40708 | S28: =O28/9 -> 84.267453
A29: 26 | B29: 428 | C29: =B29/2.5 -> 171.2 | D29: =($C29-D$2)/D$1*$N$7 -> 259.8 | E29: =($C29-E$2)/E$1*$N$7 -> 293.66667 | F29: =($C29-F$2)/F$1*$N$7 -> 384 | G29: =($C29-G$2)/G$1*$N$7 -> 458 | H29: =($C29-H$2)/H$1*$N$7 -> 564.6 | I29: =25/K29 -> 13.368984 | J29: 精准等级 | K29: 1.87 | L29: =L$20/$K29 -> 376.47059 | M29: =M$20/$K29 -> 143.85027 | N29: =N$20/$K29 -> 91.44385 | O29: =O$20/$K29 -> 458.28877 | S29: =O29/9 -> 50.920974
A30: 27 | B30: 441 | C30: =B30/2.5 -> 176.4 | D30: =($C30-D$2)/D$1*$N$7 -> 267.6 | E30: =($C30-E$2)/E$1*$N$7 -> 302.33333 | F30: =($C30-F$2)/F$1*$N$7 -> 395.14286 | G30: =($C30-G$2)/G$1*$N$7 -> 471 | H30: =($C30-H$2)/H$1*$N$7 -> 580.2 | I30: =25/K30 -> 28.409091 | J30: 护甲穿透 | K30: 0.88 | L30: =L$20/$K30 -> 800 | M30: =M$20/$K30 -> 305.68182 | N30: =N$20/$K30 -> 194.31818 | O30: =O$20/$K30 -> 973.86364 | S30: =O30/9 -> 108.20707
A31: 28 | B31: 453 | C31: =B31/2.5 -> 181.2 | D31: =($C31-D$2)/D$1*$N$7 -> 274.8 | E31: =($C31-E$2)/E$1*$N$7 -> 310.33333 | F31: =($C31-F$2)/F$1*$N$7 -> 405.42857 | G31: =($C31-G$2)/G$1*$N$7 -> 483 | H31: =($C31-H$2)/H$1*$N$7 -> 594.6 | I31: =25/K31 -> 29.761905 | J31: 韧性等级 | K31: 0.84 | L31: =L$20/$K31 -> 838.09524 | M31: =M$20/$K31 -> 320.2381 | N31: =N$20/$K31 -> 203.57143 | O31: =O$20/$K31 -> 1020.2381 | S31: =O31/9 -> 113.35979
A32: 29 | B32: 466 | C32: =B32/2.5 -> 186.4 | D32: =($C32-D$2)/D$1*$N$7 -> 282.6 | E32: =($C32-E$2)/E$1*$N$7 -> 319 | F32: =($C32-F$2)/F$1*$N$7 -> 416.57143 | G32: =($C32-G$2)/G$1*$N$7 -> 496 | H32: =($C32-H$2)/H$1*$N$7 -> 610.2
A33: 30 | B33: 479 | C33: =B33/2.5 -> 191.6 | D33: =($C33-D$2)/D$1*$N$7 -> 290.4 | E33: =($C33-E$2)/E$1*$N$7 -> 327.66667 | F33: =($C33-F$2)/F$1*$N$7 -> 427.71429 | G33: =($C33-G$2)/G$1*$N$7 -> 509 | H33: =($C33-H$2)/H$1*$N$7 -> 625.8
A34: 31 | B34: 492 | C34: =B34/2.5 -> 196.8 | D34: =($C34-D$2)/D$1*$N$7 -> 298.2 | E34: =($C34-E$2)/E$1*$N$7 -> 336.33333 | F34: =($C34-F$2)/F$1*$N$7 -> 438.85714 | G34: =($C34-G$2)/G$1*$N$7 -> 522 | H34: =($C34-H$2)/H$1*$N$7 -> 641.4
A35: 32 | B35: 509 | C35: =B35/2.5 -> 203.6 | D35: =($C35-D$2)/D$1*$N$7 -> 308.4 | E35: =($C35-E$2)/E$1*$N$7 -> 347.66667 | F35: =($C35-F$2)/F$1*$N$7 -> 453.42857 | G35: =($C35-G$2)/G$1*$N$7 -> 539 | H35: =($C35-H$2)/H$1*$N$7 -> 661.8
A36: 33 | B36: 526 | C36: =B36/2.5 -> 210.4 | D36: =($C36-D$2)/D$1*$N$7 -> 318.6 | E36: =($C36-E$2)/E$1*$N$7 -> 359 | F36: =($C36-F$2)/F$1*$N$7 -> 468 | G36: =($C36-G$2)/G$1*$N$7 -> 556 | H36: =($C36-H$2)/H$1*$N$7 -> 682.2 | N36: =L22/N22 -> 4.1169591
A37: 34 | B37: 543 | C37: =B37/2.5 -> 217.2 | D37: =($C37-D$2)/D$1*$N$7 -> 328.8 | E37: =($C37-E$2)/E$1*$N$7 -> 370.33333 | F37: =($C37-F$2)/F$1*$N$7 -> 482.57143 | G37: =($C37-G$2)/G$1*$N$7 -> 573 | H37: =($C37-H$2)/H$1*$N$7 -> 702.6 | N37: 100
A38: 35 | B38: 560 | C38: =B38/2.5 -> 224 | D38: =($C38-D$2)/D$1*$N$7 -> 339 | E38: =($C38-E$2)/E$1*$N$7 -> 381.66667 | F38: =($C38-F$2)/F$1*$N$7 -> 497.14286 | G38: =($C38-G$2)/G$1*$N$7 -> 590 | H38: =($C38-H$2)/H$1*$N$7 -> 723 | N38: =95+50*5 -> 345
A39: 36 | B39: 578 | C39: =B39/2.5 -> 231.2 | D39: =($C39-D$2)/D$1*$N$7 -> 349.8 | E39: =($C39-E$2)/E$1*$N$7 -> 393.66667 | F39: =($C39-F$2)/F$1*$N$7 -> 512.57143 | G39: =($C39-G$2)/G$1*$N$7 -> 608 | H39: =($C39-H$2)/H$1*$N$7 -> 744.6
A40: 37 | B40: 595 | C40: =B40/2.5 -> 238 | D40: =($C40-D$2)/D$1*$N$7 -> 360 | E40: =($C40-E$2)/E$1*$N$7 -> 405 | F40: =($C40-F$2)/F$1*$N$7 -> 527.14286 | G40: =($C40-G$2)/G$1*$N$7 -> 625 | H40: =($C40-H$2)/H$1*$N$7 -> 765
...

Sheet 属性成长（300-120,裸车比率）
A1: 300 | B1: 120 | C1: =A1+B1 -> 420 | D1: =A1/C1 -> 0.71428571 | E1: =C1/F1 -> 4.2 | F1: =5*ROW(C1)+95 -> 100 | G1: =3 -> 3 | H1: =E1/G1 -> 1.4 | I1: 1 | J1: =I1*H1 -> 1.4 | K1: =LN(1.35) -> 0.30010459 | L1: =K1/10 -> 0.030010459 | M1: =EXP(L1) -> 1.0304653 | N1: =计算24级时装备属性位数!J22 -> 77.166607 | O1: =ROUND(N1,0) -> 77
A2: 306 | B2: =C2-A2 -> 126.79543 | C2: =C1*$M$1 -> 432.79543 | D2: =A2/C2 -> 0.70703149 | E2: =C2/F2 -> 4.1218612 | F2: =5*ROW(C2)+95 -> 105 | G2: =3 -> 3 | H2: =E2/G2 -> 1.3739537 | I2: 1 | J2: =I2*H2 -> 1.3739537 | N2: =$N$1/$B$1*B2 -> 81.536443 | O2: =ROUND(N2,0) -> 82
A3: 312 | B3: =C3-A3 -> 133.98068 | C3: =C2*$M$1 -> 445.98068 | D3: =A3/C3 -> 0.69958188 | E3: =C3/F3 -> 4.0543698 | F3: =5*ROW(C3)+95 -> 110 | G3: =3 -> 3 | H3: =E3/G3 -> 1.3514566 | I3: 1 | J3: =I3*H3 -> 1.3514566 | N3: =$N$1/$B$1*B3 -> 86.156953 | O3: =ROUND(N3,0) -> 86
A4: 318 | B4: =C4-A4 -> 141.56762 | C4: =C3*$M$1 -> 459.56762 | D4: =A4/C4 -> 0.69195476 | E4: =C4/F4 -> 3.9962402 | F4: =5*ROW(C4)+95 -> 115 | G4: =3 -> 3 | H4: =E4/G4 -> 1.3320801 | I4: 1 | J4: =I4*H4 -> 1.3320801 | N4: =$N$1/$B$1*B4 -> 91.035773 | O4: =ROUND(N4,0) -> 91
A5: 324 | B5: =C5-A5 -> 149.56849 | C5: =C4*$M$1 -> 473.56849 | D5: =A5/C5 -> 0.68416714 | E5: =C5/F5 -> 3.9464041 | F5: =5*ROW(C5)+95 -> 120 | G5: =3 -> 3 | H5: =E5/G5 -> 1.315468 | I5: 1 | J5: =I5*H5 -> 1.315468 | N5: =$N$1/$B$1*B5 -> 96.180774 | O5: =ROUND(N5,0) -> 96
A6: 330 | B6: =C6-A6 -> 157.9959 | C6: =C5*$M$1 -> 487.9959 | D6: =A6/C6 -> 0.67623519 | E6: =C6/F6 -> 3.9039672 | F6: =5*ROW(C6)+95 -> 125 | G6: =3 -> 3 | H6: =E6/G6 -> 1.3013224 | I6: 1 | J6: =I6*H6 -> 1.3013224 | N6: =$N$1/$B$1*B6 -> 101.60006 | O6: =ROUND(N6,0) -> 102
A7: 336 | B7: =C7-A7 -> 166.86285 | C7: =C6*$M$1 -> 502.86285 | D7: =A7/C7 -> 0.66817424 | E7: =C7/F7 -> 3.8681758 | F7: =5*ROW(C7)+95 -> 130 | G7: =3 -> 3 | H7: =E7/G7 -> 1.2893919 | I7: 1 | J7: =I7*H7 -> 1.2893919 | N7: =$N$1/$B$1*B7 -> 107.302 | O7: =ROUND(N7,0) -> 107
A8: 342 | B8: =C8-A8 -> 176.18272 | C8: =C7*$M$1 -> 518.18272 | D8: =A8/C8 -> 0.65999885 | E8: =C8/F8 -> 3.8383905 | F8: =5*ROW(C8)+95 -> 135 | G8: =3 -> 3 | H8: =E8/G8 -> 1.2794635 | I8: 1 | J8: =I8*H8 -> 1.2794635 | N8: =$N$1/$B$1*B8 -> 113.29519 | O8: =ROUND(N8,0) -> 113
A9: 348 | B9: =C9-A9 -> 185.96932 | C9: =C8*$M$1 -> 533.96932 | D9: =A9/C9 -> 0.65172284 | E9: =C9/F9 -> 3.8140666 | F9: =5*ROW(C9)+95 -> 140 | G9: =3 -> 3 | H9: =E9/G9 -> 1.2713555 | I9: 1 | J9: =I9*H9 -> 1.2713555 | N9: =$N$1/$B$1*B9 -> 119.58851 | O9: =ROUND(N9,0) -> 120
A10: 354 | B10: =C10-A10 -> 196.23686 | C10: =C9*$M$1 -> 550.23686 | D10: =A10/C10 -> 0.6433593 | E10: =C10/F10 -> 3.794737 | F10: =5*ROW(C10)+95 -> 145 | G10: =3 -> 3 | H10: =E10/G10 -> 1.2649123 | I10: 1 | J10: =I10*H10 -> 1.2649123 | N10: =$N$1/$B$1*B10 -> 126.19111 | O10: =ROUND(N10,0) -> 126
A11: 360 | B11: =C11-A11 -> 207 | C11: =C10*$M$1 -> 567 | D11: =A11/C11 -> 0.63492063 | E11: =C11/F11 -> 3.78 | F11: =5*ROW(C11)+95 -> 150 | G11: =3 -> 3 | H11: =E11/G11 -> 1.26 | I11: 1 | J11: =I11*H11 -> 1.26 | N11: =$N$1/$B$1*B11 -> 133.1124 | O11: =ROUND(N11,0) -> 133
A12: 366 | B12: =C12-A12 -> 218.27383 | C12: =C11*$M$1 -> 584.27383 | D12: =A12/C12 -> 0.62641861 | E12: =C12/F12 -> 3.7695086 | F12: =5*ROW(C12)+95 -> 155 | G12: =3 -> 3 | H12: =E12/G12 -> 1.2565029 | I12: 1 | J12: =I12*H12 -> 1.2565029 | N12: =$N$1/$B$1*B12 -> 140.36209 | O12: =ROUND(N12,0) -> 140
A13: 372 | B13: =C13-A13 -> 230.07392 | C13: =C12*$M$1 -> 602.07392 | D13: =A13/C13 -> 0.61786434 | E13: =C13/F13 -> 3.762962 | F13: =5*ROW(C13)+95 -> 160 | G13: =3 -> 3 | H13: =E13/G13 -> 1.2543207 | I13: 1 | J13: =I13*H13 -> 1.2543207 | N13: =$N$1/$B$1*B13 -> 147.95019 | O13: =ROUND(N13,0) -> 148
... A24: 438 | B24: =C24-A24 -> 399.56199 | C24: =C23*$M$1 -> 837.56199 | D24: =A24/C24 -> 0.52294637 | E24: =C24/F24 -> 3.8956371 | F24: =5*ROW(C24)+95 -> 215 | G24: =3 -> 3 | H24: =E24/G24 -> 1.2985457 | I24: 1.33 | J24: =I24*H24 -> 1.7270658 | N24: =$N$1/$B$1*B24 -> 256.94035 | O24: =ROUND(N24,0) -> 257
A25: 444 | B25: =C25-A25 -> 419.07857 | C25: =C24*$M$1 -> 863.07857 | D25: =A25/C25 -> 0.51443752 | E25: =C25/F25 -> 3.9230844 | F25: =5*ROW(C25)+95 -> 220 | G25: 5 | H25: =E25/G25 -> 0.78461688 | I25: 1.33 | J25: =I25*H25 -> 1.0435405 | N25: =$N$1/$B$1*B25 -> 269.49059 | O25: =ROUND(N25,0) -> 269
A26: 450 | B26: =C26-A26 -> 439.37253 | C26: =C25*$M$1 -> 889.37253 | D26: =A26/C26 -> 0.5059747 | E26: =C26/F26 -> 3.9527668 | F26: =5*ROW(C26)+95 -> 225 | G26: 5 | H26: =E26/G26 -> 0.79055336 | I26: 1.33 | J26: =I26*H26 -> 1.051436 | N26: =$N$1/$B$1*B26 -> 282.54073 | O26: =ROUND(N26,0) -> 283
A27: 456 | B27: =C27-A27 -> 460.46754 | C27: =C26*$M$1 -> 916.46754 | D27: =A27/C27 -> 0.49756263 | E27: =C27/F27 -> 3.9846415 | F27: =5*ROW(C27)+95 -> 230 | G27: 5 | H27: =E27/G27 -> 0.7969283 | I27: 1.33 | J27: =I27*H27 -> 1.0599146 | N27: =$N$1/$B$1*B27 -> 296.10598 | O27: =ROUND(N27,0) -> 296
A28: 462 | B28: =C28-A28 -> 482.38801 | C28: =C27*$M$1 -> 944.38801 | D28: =A28/C28 -> 0.4892057 | E28: =C28/F28 -> 4.0186724 | F28: =5*ROW(C28)+95 -> 235 | G28: 5 | H28: =E28/G28 -> 0.80373448 | I28: 1.33 | J28: =I28*H28 -> 1.0689669 | N28: =$N$1/$B$1*B28 -> 310.20205 | O28: =ROUND(N28,0) -> 310
A29: 468 | B29: =C29-A29 -> 505.15909 | C29: =C28*$M$1 -> 973.15909 | D29: =A29/C29 -> 0.48090801 | E29: =C29/F29 -> 4.0548295 | F29: =5*ROW(C29)+95 -> 240 | G29: 5 | H29: =E29/G29 -> 0.81096591 | I29: 1.33 | J29: =I29*H29 -> 1.0785847 | N29: =$N$1/$B$1*B29 -> 324.8451 | O29: =ROUND(N29,0) -> 325
A30: 474 | B30: =C30-A30 -> 528.80668 | C30: =C29*$M$1 -> 1002.8067 | D30: =A30/C30 -> 0.47267336 | E30: =C30/F30 -> 4.0930885 | F30: =5*ROW(C30)+95 -> 245 | G30: 5 | H30: =E30/G30 -> 0.8186177 | I30: 1.33 | J30: =I30*H30 -> 1.0887615 | N30: =$N$1/$B$1*B30 -> 340.05181 | O30: =ROUND(N30,0) -> 340
A31: 480 | B31: =C31-A31 -> 553.3575 | C31: =C30*$M$1 -> 1033.3575 | D31: =A31/C31 -> 0.46450527 | E31: =C31/F31 -> 4.13343 | F31: =5*ROW(C31)+95 -> 250 | G31: 5 | H31: =E31/G31 -> 0.826686 | I31: 1.33 | J31: =I31*H31 -> 1.0994924 | N31: =$N$1/$B$1*B31 -> 355.83934 | O31: =ROUND(N31,0) -> 356
A32: 486 | B32: =C32-A32 -> 578.83906 | C32: =C31*$M$1 -> 1064.8391 | D32: =A32/C32 -> 0.456407 | E32: =C32/F32 -> 4.1758394 | F32: =5*ROW(C32)+95 -> 255 | G32: 5 | H32: =E32/G32 -> 0.83516789 | I32: 1.33 | J32: =I32*H32 -> 1.1107733 | N32: =$N$1/$B$1*B32 -> 372.22538 | O32: =ROUND(N32,0) -> 372
A33: 492 | B33: =C33-A33 -> 605.27971 | C33: =C32*$M$1 -> 1097.2797 | D33: =A33/C33 -> 0.44838157 | E33: =C33/F33 -> 4.2203066 | F33: =5*ROW(C33)+95 -> 260 | G33: 5 | H33: =E33/G33 -> 0.84406132 | I33: 1.33 | J33: =I33*H33 -> 1.1226016 | N33: =$N$1/$B$1*B33 -> 389.22818 | O33: =ROUND(N33,0) -> 389
A34: 498 | B34: =C34-A34 -> 632.70868 | C34: =C33*$M$1 -> 1130.7087 | D34: =A34/C34 -> 0.44043175 | E34: =C34/F34 -> 4.2668252 | F34: =5*ROW(C34)+95 -> 265 | G34: 5 | H34: =E34/G34 -> 0.85336504 | I34: 1.33 | J34: =I34*H34 -> 1.1349755 | N34: =$N$1/$B$1*B34 -> 406.86652 | O34: =ROUND(N34,0) -> 407
A35: 504 | B35: =C35-A35 -> 661.15607 | C35: =C34*$M$1 -> 1165.1561 | D35: =A35/C35 -> 0.43256008 | E35: =C35/F35 -> 4.3153929 | F35: =5*ROW(C35)+95 -> 270 | G35: 5 | H35: =E35/G35 -> 0.86307857 | I35: 1.33 | J35: =I35*H35 -> 1.1478945 | N35: =$N$1/$B$1*B35 -> 425.15976 | O35: =ROUND(N35,0) -> 425
A36: 510 | B36: =C36-A36 -> 690.65292 | C36: =C35*$M$1 -> 1200.6529 | D36: =A36/C36 -> 0.42476888 | E36: =C36/F36 -> 4.3660106 | F36: =5*ROW(C36)+95 -> 275 | G36: 5 | H36: =E36/G36 -> 0.87320212 | I36: 1.33 | J36: =I36*H36 -> 1.1613588 | N36: =$N$1/$B$1*B36 -> 444.12785 | O36: =ROUND(N36,0) -> 444
... A41: 540 | B41: =C41-A41 -> 855.03263 | C41: =C40*$M$1 -> 1395.0326 | D41: =A41/C41 -> 0.38708772 | E41: =C41/F41 -> 4.6501088 | F41: =5*ROW(C41)+95 -> 300 | G41: 7 | H41: =E41/G41 -> 0.66430125 | I41: 1.33 | J41: =I41*H41 -> 0.88352066 | N41: =$N$1/$B$1*B41 -> 549.83305 | O41: =ROUND(N41,0) -> 550
A42: 546 | B42: =C42-A42 -> 891.53273 | C42: =C41*$M$1 -> 1437.5327 | D42: =A42/C42 -> 0.37981744 | E42: =C42/F42 -> 4.7132221 | F42: =5*ROW(C42)+95 -> 305 | G42: 7 | H42: =E42/G42 -> 0.67331744 | J42: =I42*H42 -> 0 | N42: =$N$1/$B$1*B42 -> 573.30463 | O42: =ROUND(N42,0) -> 573
A43: 552 | B43: =C43-A43 -> 929.32761 | C43: =C42*$M$1 -> 1481.3276 | D43: =A43/C43 -> 0.3726387 | E43: =C43/F43 -> 4.7784762 | F43: =5*ROW(C43)+95 -> 310 | G43: 7 | H43: =E43/G43 -> 0.68263945 | J43: =I43*H43 -> 0 | N43: =$N$1/$B$1*B43 -> 597.60882 | O43: =ROUND(N43,0) -> 598
A44: 558 | B44: =C44-A44 -> 968.45672 | C44: =C43*$M$1 -> 1526.4567 | D44: =A44/C44 -> 0.36555245 | E44: =C44/F44 -> 4.8458943 | F44: =5*ROW(C44)+95 -> 315 | G44: 7 | H44: =E44/G44 -> 0.69227062 | J44: =I44*H44 -> 0 | N44: =$N$1/$B$1*B44 -> 622.77099 | O44: =ROUND(N44,0) -> 623
A45: 564 | B45: =C45-A45 -> 1008.9607 | C45: =C44*$M$1 -> 1572.9607 | D45: =A45/C45 -> 0.3585595 | E45: =C45/F45 -> 4.9155022 | F45: =5*ROW(C45)+95 -> 320 | G45: 7 | H45: =E45/G45 -> 0.7022146 | J45: =I45*H45 -> 0 | N45: =$N$1/$B$1*B45 -> 648.81728 | O45: =ROUND(N45,0) -> 649
A46: 570 | B46: =C46-A46 -> 1050.8814 | C46: =C45*$M$1 -> 1620.8814 | D46: =A46/C46 -> 0.35166051 | E46: =C46/F46 -> 4.9873275 | F46: =5*ROW(C46)+95 -> 325 | G46: 7 | H46: =E46/G46 -> 0.71247536 | J46: =I46*H46 -> 0 | N46: =$N$1/$B$1*B46 -> 675.77462 | O46: =ROUND(N46,0) -> 676
A47: 576 | B47: =C47-A47 -> 1094.2621 | C47: =C46*$M$1 -> 1670.2621 | D47: =A47/C47 -> 0.34485606 | E47: =C47/F47 -> 5.0614003 | F47: =5*ROW(C47)+95 -> 330 | G47: 7 | H47: =E47/G47 -> 0.72305718 | J47: =I47*H47 -> 0 | N47: =$N$1/$B$1*B47 -> 703.67077 | O47: =ROUND(N47,0) -> 704
A48: 582 | B48: =C48-A48 -> 1139.1472 | C48: =C47*$M$1 -> 1721.1472 | D48: =A48/C48 -> 0.33814657 | E48: =C48/F48 -> 5.1377527 | F48: =5*ROW(C48)+95 -> 335 | G48: 7 | H48: =E48/G48 -> 0.73396467 | J48: =I48*H48 -> 0 | N48: =$N$1/$B$1*B48 -> 732.53433 | O48: =ROUND(N48,0) -> 733
A49: 588 | B49: =C49-A49 -> 1185.5824 | C49: =C48*$M$1 -> 1773.5824 | D49: =A49/C49 -> 0.33153238 | E49: =C49/F49 -> 5.2164189 | F49: =5*ROW(C49)+95 -> 340 | G49: 7 | H49: =E49/G49 -> 0.7452027 | J49: =I49*H49 -> 0 | N49: =$N$1/$B$1*B49 -> 762.39478 | O49: =ROUND(N49,0) -> 762
A50: 594 | B50: =C50-A50 -> 1233.6152 | C50: =C49*$M$1 -> 1827.6152 | D50: =A50/C50 -> 0.32501372 | E50: =C50/F50 -> 5.2974353 | F50: =5*ROW(C50)+95 -> 345 | G50: 7 | H50: =E50/G50 -> 0.75677647 | J50: =I50*H50 -> 0 | N50: =$N$1/$B$1*B50 -> 793.28248 | O50: =ROUND(N50,0) -> 793
A51: 裸车比例

Sheet 计算24级时装备属性位数
A1: 1级100为基准
A2: 属性 | B2: 1点属性价值等于多少 | C2: 基础值 | D2: 加1点属性价值结果 | F2: 1dps=8ehp | G2: 系统给定值 | H2: 多少点达到这个效果
A3: 生命值 | B3: 4 | C3: 400 | D3: =B3*C5/(1-C8*C9) -> 8.9776681 | G3: 0 | H3: =(C3-G3)/B3 -> 100
A4: 攻击力 | B4: 1 | C4: 100 | D4: =B4*(1+C6*C7)*8 -> 9.32 | G4: 0 | H4: =(C4-G4)/B4 -> 100
A5: 护甲 | B5: 0.02 | C5: 2 | D5: =B5*C3/(1-C8*C9) -> 8.9776681 | G5: 1 | H5: =(C5-G5)/B5 -> 50
A6: 暴击几率等级 | B6: 0.022 | C6: 0.33 | D6: =B6*C7*C4*8 -> 8.8 | G6: 0.05 | H6: =(C6-G6)/B6 -> 12.727273
A7: 暴击伤害等级 | B7: 0.03 | C7: 0.5 | D7: =B7*C6*C4*8 -> 7.92 | G7: 0.5 | H7: =(C7-G7)/B7 -> 0
A8: 偏移几率等级 | B8: 0.025 | C8: 0.33 | D8: =C3*C5*(1/(1-(C8+B8)*C9)-1/(1-C9*C8)) -> 8.3893936 | G8: 0.05 | H8: =(C8-G8)/B8 -> 11.2
A9: 偏移减伤等级 | B9: 0.025 | C9: 0.33 | D9: =C3*C5/(1-(C9+B9)*C8)-C3*C5/(1-C9*C8) -> 8.3893936 | G9: 0.33 | H9: =(C9-G9)/B9 -> 0
A10: 24级 | B10: 此级别每个装备上有几条属性 | C10: 2 | E10: 每个属性被加几遍 | F10: 2 | H10: 用到几条属性 | I10: 5 | K10: 放大系数10000基础上 | M10: 0.509926
A11: 属性 | B11: 1点属性价值等于多少 | C11: 基础值 | D11: 加1点属性价值结果 | F11: 1dps=8ehp | G11: 系统给定值 | H11: 多少点达到这个效果 | J11: 属性价值 | K11: 多少属性带来一点 | M11: 实际数字 | N11: 每个装备上的数字
A12: 生命值 | B12: 4 | C12: =10000*$M$10 -> 5099.26 | D12: =B12*C14/(1-C17*C18) -> 8.9776681 | G12: 0 | H12: =(C12-G12)/B12 -> 1274.815 | J12: 0.25 | K12: =1/B12/J12 -> 1 | M12: =H12/J12 -> 5099.26 | N12: =M12/$F$10 -> 2549.63
A13: 攻击力 | B13: 1 | C13: =2500*$M$10 -> 1274.815 | D13: =B13*(1+C15*C16)*8 -> 9.32 | G13: 0 | H13: =(C13-G13)/B13 -> 1274.815 | J13: 1 | K13: =1/B13/J13 -> 1 | M13: =H13/J13 -> 1274.815 | N13: =M13/$F$10 -> 637.4075 | R13: =0.5239/2054.81*2000 -> 0.50992549
A14: 护甲 | B14: =1/1250/M10 -> 0.0015688551 | C14: 2 | D14: =B14*C12/(1-C17*C18) -> 8.9776681 | G14: 1 | H14: =(C14-G14)/B14 -> 637.4075 | J14: 0.53 | K14: =1/B14/J14 -> 1202.6557 | M14: =H14/J14 -> 1202.6557 | N14: =M14/$F$10 -> 601.32783
A15: 暴击几率等级 | B15: =0.075%/M10 -> 0.0014708016 | C15: 0.33 | D15: =B15*C16*C13*8 -> 7.5 | G15: 0.05 | H15: =(C15-G15)/B15 -> 190.37237 | J15: 1.51 | K15: =1/B15/J15 -> 450.26578 | M15: =H15/J15 -> 126.07442 | N15: =M15/$F$10 -> 63.03721
A16: 暴击伤害等级 | B16: =0.12%/M10 -> 0.0023532826 | C16: 0.5 | D16: =B16*C15*C13*8 -> 7.92 | G16: 0.5 | H16: =(C16-G16)/B16 -> 0 | J16: 0.5 | K16: =1/B16/J16 -> 849.87667 | M16: =H16/J16 -> 0 | N16: =M16/$F$10 -> 0
A17: 偏移几率等级 | B17: =0.108%/M10 -> 0.0021179544 | C17: 0.33 | D17: =C12*C14*(1/(1-(C17+B17)*C18)-1/(1-C18*C17)) -> 8.9837068 | G17: 0.05 | H17: =(C17-G17)/B17 -> 132.20304 | J17: 1.13 | K17: =1/B17/J17 -> 417.83514 | M17: =H17/J17 -> 116.99384 | N17: =M17/$F$10 -> 58.496919
A18: 偏移减伤等级 | B18: =0.1%/M10 -> 0.0019610689 | C18: 0.33 | D18: =C12*C14/(1-(C18+B18)*C17)-C12*C14/(1-C18*C17) -> 8.3177634 | G18: 0.33 | H18: =(C18-G18)/B18 -> 0 | J18: 1.13 | K18: =1/B18/J18 -> 451.26195 | M18: =H18/J18 -> 0 | N18: =M18/$F$10 -> 0
A19: 4 | G19: sum | H19: =SUM(H12:H18) -> 3509.6129 | J19: 这级别裸车占比 | K19: 0.52 | M19: 裸车点数 | N19: =H19*K19 -> 1824.9987 | O19: 2.5 | P19: 实际属性数 | Q19: 438 | R19: 对应的1级属性 | S19: 300 | T19: 减去加成的30%
M20: 生命值 | N20: =$N$19/$O$19*O20 -> 729.99949 | O20: 1 | P20: =N20/J12 -> 2919.9979 | R20: =P20/$Q$19*$S$19 -> 1999.9986 | T20: =R20/1.3 -> 1538.4605
C21: 5 | D21: 1 | E21: 0.05 | F21: 0.95 | M21: 攻击力 | N21: =$N$19/$O$19*O21 -> 729.99949 | O21: 1 | P21: =N21/J13 -> 729.99949 | R21: =P21/$Q$19*$S$19 -> 499.99965 | T21: =R21/1.3 -> 384.61511
B22: 0.02 | C22: =B22/$C$21 -> 0.004 | D22: =$D$21/C22 -> 250 | E22: =$D22*E$21 -> 12.5 | F22: =$D22*F$21 -> 237.5 | J22: =N19*0.4/12*1.4-8 -> 77.166607 | M22: 护甲 | N22: =$N$19/$O$19*O22 -> 364.99974 | O22: 0.5 | P22: =N22/J14 -> 688.67876 | R22: =P22/$Q$19*$S$19 -> 471.69778 | T22: =R22/1.3 -> 362.84445
A23: 25 | B23: 0.022 | C23: =B23/$C$21 -> 0.0044 | D23: =$D$21/C23 -> 227.27273 | E23: =$D23*E$21 -> 11.363636 | F23: =$D23*F$21 -> 215.90909
B24: 0.03 | C24: =B24/$C$21 -> 0.006 | D24: =$D$21/C24 -> 166.66667 | E24: =$D24*E$21 -> 8.3333333 | F24: =$D24*F$21 -> 158.33333
B25: 0.025 | C25: =B25/$C$21 -> 0.005 | D25: =$D$21/C25 -> 200 | E25: =$D25*E$21 -> 10 | F25: =$D25*F$21 -> 190
B26: 0.025 | C26: =B26/$C$21 -> 0.005 | D26: =$D$21/C26 -> 200 | E26: =$D26*E$21 -> 10 | F26: =$D26*F$21 -> 190

Sheet 一步步找点
A1: 属性 | B1: 1点属性价值等于多少 | C1: 基础值 | D1: 加1点属性价值结果 | F1: 1dps=8ehp | G1: 系统给定值 | H1: 多少点达到这个效果
A2: 生命值 | B2: 4 | C2: 400 | D2: =B2*C4/(1-C7*C8) -> 8.9776681 | G2: 0 | H2: =(C2-G2)/B2 -> 100
A3: 攻击力 | B3: 1 | C3: 100 | D3: =B3*(1+C5*C6)*8 -> 8.2 | G3: 0 | H3: =(C3-G3)/B3 -> 100
A4: 护甲 | B4: 0.02 | C4: 2 | D4: =B4*C2/(1-C7*C8) -> 8.9776681 | G4: 1 | H4: =(C4-G4)/B4 -> 50
A5: 暴击几率等级 | B5: 0.022 | C5: 0.05 | D5: =B5*C6*C3*8 -> 8.8 | G5: 0.05 | H5: =(C5-G5)/B5 -> 0
A6: 暴击伤害等级 | B6: 0.03 | C6: 0.5 | D6: =B6*C5*C3*8 -> 1.2 | G6: 0.5 | H6: =(C6-G6)/B6 -> 0
A7: 偏移几率等级 | B7: 0.025 | C7: 0.33 | D7: =C2*C4*(1/(1-(C7+B7)*C8)-1/(1-C8*C7)) -> 8.3893936 | G7: 0.05 | H7: =(C7-G7)/B7 -> 11.2
A8: 偏移减伤等级 | B8: 0.025 | C8: 0.33 | D8: =C2*C4/(1-(C8+B8)*C7)-C2*C4/(1-C8*C7) -> 8.3893936 | G8: 0.33 | H8: =(C8-G8)/B8 -> 0
A9: 精准等级
A10: 护甲穿透
A11: 韧性等级
G15: 5个装备 | O15: 85 | Q15: 15
A16: 初级 | C16: 1000点属性价值 | D16: 变为1001点 | G16: 每个两条 | O16: 85 | Q16: 15
G17: 每个属性一条 | O17: 85 | Q17: 15
K18: 4 | L18: 800 | Q18: 15
B19: 4 | C19: 640 | D19: 6.4 | K19: 1 | L19: 200 | O19: 255 | Q19: 15
B20: 1 | C20: 80 | D20: 1 | K20: 0.02 | L20: 2 | M20: 50 | Q20: 75
B21: 0.01 | C21: 2 | D21: 6.4
C25: =60/59 -> 1.0169492
E26: 当前一点hp带来的收益 | H26: =B2*C4/(1-C7*C8) -> 8.9776681
A27: 两条： | C27: 4 | D27: 800 | E27: 当前一点偏移几率等级带来的收益 | H27: =800/(1-(C7+B7)*C8)-800/(1-C8*C7) -> 8.3893936
A28: 有了暴击几率与偏移几率 | C28: 1 | D28: 200 | E28: 当前一点偏移减伤带来的收益 | H28: =C2*C4/(1-(C8+B8)*C7)-C2*C4/(1-C8*C7) -> 8.3893936
C29: 0.02 | D29: 2 | E29: 50 | F29: 收益：hp/偏移几率 | H29: =H26/H27 -> 1.0701212
A30: 暴击几率 | D30: 0.05 | F30: 收益：hp/偏移减伤 | H30: =H26/H28 -> 1.0701212

Sheet 关于alpha次方
A1: 0.02 | B1: =1.7095 -> 1.7095 | C1: =1/1.7095 -> 0.58496636 | D1: 0.02 | F1: 总点数 | G1: 20 | T1: alpha | U1: =LN(2)/LN(1.5) -> 1.7095113 | W1: 1/alpha | X1: =1/U1 -> 0.5849625
A2: 0.02 | B2: =POWER(A2,$B$1) -> 0.0012462661 | C2: =1-B2 -> 0.99875373 | D2: =POWER(C2,$C$1) -> 0.99927079 | F2: =A2*$A$1+D2*$D$1 -> 0.020385416 | H2: =(一步步找点!$B$7*关于alpha次方!A2*关于alpha次方!$G$1+一步步找点!$C$7)*(一步步找点!$B$8*关于alpha次方!D2*关于alpha次方!$G$1+一步步找点!$C$8) -> 0.28207603 | J2: =(一步步找点!$B$7*关于alpha次方!A2*关于alpha次方!$G$1+一步步找点!$C$7) -> 0.34 | K2: =(一步步找点!$B$8*关于alpha次方!D2*关于alpha次方!$G$1+一步步找点!$C$8) -> 0.82963539
A3: 0.04 | B3: =POWER(A3,$B$1) -> 0.0040758816 | C3: =1-B3 -> 0.99592412 | D3: =POWER(C3,$C$1) -> 0.99761373 | F3: =A3*$A$1+D3*$D$1 -> 0.020752275 | H3: =(一步步找点!$B$7*关于alpha次方!A3*关于alpha次方!$G$1+一步步找点!$C$7)*(一步步找点!$B$8*关于alpha次方!D3*关于alpha次方!$G$1+一步步找点!$C$8) -> 0.2900824 | J3: =(一步步找点!$B$7*关于alpha次方!A3*关于alpha次方!$G$1+一步步找点!$C$7) -> 0.35 | K3: =(一步步找点!$B$8*关于alpha次方!D3*关于alpha次方!$G$1+一步步找点!$C$8) -> 0.82880686 | T3: itemValue | U3: 100 | W3: poweralpha | X3: =POWER(U3,U1) -> 2624.355
A4: 0.06 | B4: =POWER(A4,$B$1) -> 0.0081517258 | C4: =1-B4 -> 0.99184827 | D4: =POWER(C4,$C$1) -> 0.99522342 | F4: =A4*$A$1+D4*$D$1 -> 0.021104468 | H4: =(一步步找点!$B$7*关于alpha次方!A4*关于alpha次方!$G$1+一步步找点!$C$7)*(一步步找点!$B$8*关于alpha次方!D4*关于alpha次方!$G$1+一步步找点!$C$8) -> 0.29794022 | J4: =(一步步找点!$B$7*关于alpha次方!A4*关于alpha次方!$G$1+一步步找点!$C$7) -> 0.36 | K4: =(一步步找点!$B$8*关于alpha次方!D4*关于alpha次方!$G$1+一步步找点!$C$8) -> 0.82761171
A5: 0.08 | B5: =POWER(A5,$B$1) -> 0.013330067 | C5: =1-B5 -> 0.98666993 | D5: =POWER(C5,$C$1) -> 0.99218065 | F5: =A5*$A$1+D5*$D$1 -> 0.021443613 | H5: =(一步步找点!$B$7*关于alpha次方!A5*关于alpha次方!$G$1+一步步找点!$C$7)*(一步步找点!$B$8*关于alpha次方!D5*关于alpha次方!$G$1+一步步找点!$C$8) -> 0.30565342 | J5: =(一步步找点!$B$7*关于alpha次方!A5*关于alpha次方!$G$1+一步步找点!$C$7) -> 0.37 | K5: =(一步步找点!$B$8*关于alpha次方!D5*关于alpha次方!$G$1+一步步找点!$C$8) -> 0.82609033 | T5: stat1 | U5: stat2 | V5: stat3 | W5: stat4 | X5: stat5
A6: 0.1 | B6: =POWER(A6,$B$1) -> 0.019520907 | C6: =1-B6 -> 0.98047909 | D6: =POWER(C6,$C$1) -> 0.98853424 | F6: =A6*$A$1+D6*$D$1 -> 0.021770685 | H6: =(一步步找点!$B$7*关于alpha次方!A6*关于alpha次方!$G$1+一步步找点!$C$7)*(一步步找点!$B$8*关于alpha次方!D6*关于alpha次方!$G$1+一步步找点!$C$8) -> 0.31322151 | J6: =(一步步找点!$B$7*关于alpha次方!A6*关于alpha次方!$G$1+一步步找点!$C$7) -> 0.38 | K6: =(一步步找点!$B$8*关于alpha次方!D6*关于alpha次方!$G$1+一步步找点!$C$8) -> 0.82426712 | T6: 1 | U6: 0 | V6: 0 | W6: 0 | X6: 0
A7: 0.12 | B7: =POWER(A7,$B$1) -> 0.026660012 | C7: =1-B7 -> 0.97333999 | D7: =POWER(C7,$C$1) -> 0.98431741 | F7: =A7*$A$1+D7*$D$1 -> 0.022086348 | H7: =(一步步找点!$B$7*关于alpha次方!A7*关于alpha次方!$G$1+一步步找点!$C$7)*(一步步找点!$B$8*关于alpha次方!D7*关于alpha次方!$G$1+一步步找点!$C$8) -> 0.32064189 | J7: =(一步步找点!$B$7*关于alpha次方!A7*关于alpha次方!$G$1+一步步找点!$C$7) -> 0.39 | K7: =(一步步找点!$B$8*关于alpha次方!D7*关于alpha次方!$G$1+一步步找点!$C$8) -> 0.8221587 | T7: =$X$3*T6 -> 2624.355 | U7: =$X$3*U6 -> 0 | V7: =$X$3*V6 -> 0 | W7: =$X$3*W6 -> 0 | X7: =$X$3*X6 -> 0
A8: 0.14 | B8: =POWER(A8,$B$1) -> 0.034698115 | C8: =1-B8 -> 0.96530189 | D8: =POWER(C8,$C$1) -> 0.97955418 | F8: =A8*$A$1+D8*$D$1 -> 0.022391084 | H8: =(一步步找点!$B$7*关于alpha次方!A8*关于alpha次方!$G$1+一步步找点!$C$7)*(一步步找点!$B$8*关于alpha次方!D8*关于alpha次方!$G$1+一步步找点!$C$8) -> 0.32791084 | J8: =(一步步找点!$B$7*关于alpha次方!A8*关于alpha次方!$G$1+一步步找点!$C$7) -> 0.4 | K8: =(一步步找点!$B$8*关于alpha次方!D8*关于alpha次方!$G$1+一步步找点!$C$8) -> 0.81977709 | T8: =POWER(T7,$X$1) -> 100 | U8: =POWER(U7,$X$1) -> 0 | V8: =POWER(V7,$X$1) -> 0 | W8: =POWER(W7,$X$1) -> 0 | X8: =POWER(X7,$X$1) -> 0 | Z8: 加总 | AA8: =SUM(T8:X8) -> 100
A9: 0.16 | B9: =POWER(A9,$B$1) -> 0.043595645 | C9: =1-B9 -> 0.95640435 | D9: =POWER(C9,$C$1) -> 0.97426243 | F9: =A9*$A$1+D9*$D$1 -> 0.022685249 | H9: =(一步步找点!$B$7*关于alpha次方!A9*关于alpha次方!$G$1+一步步找点!$C$7)*(一步步找点!$B$8*关于alpha次方!D9*关于alpha次方!$G$1+一步步找点!$C$8) -> 0.3350238 | J9: =(一步步找点!$B$7*关于alpha次方!A9*关于alpha次方!$G$1+一步步找点!$C$7) -> 0.41 | K9: =(一步步找点!$B$8*关于alpha次方!D9*关于alpha次方!$G$1+一步步找点!$C$8) -> 0.81713121
A10: 0.18 | B10: =POWER(A10,$B$1) -> 0.05331978 | C10: =1-B10 -> 0.94668022 | D10: =POWER(C10,$C$1) -> 0.96845564 | F10: =A10*$A$1+D10*$D$1 -> 0.022969113 | H10: =(一步步找点!$B$7*关于alpha次方!A10*关于alpha次方!$G$1+一步步找点!$C$7)*(一步步找点!$B$8*关于alpha次方!D10*关于alpha次方!$G$1+一步步找点!$C$8) -> 0.34197568 | J10: =(一步步找点!$B$7*关于alpha次方!A10*关于alpha次方!$G$1+一步步找点!$C$7) -> 0.42 | K10: =(一步步找点!$B$8*关于alpha次方!D10*关于alpha次方!$G$1+一步步找点!$C$8) -> 0.81422782
A11: 0.2 | B11: =POWER(A11,$B$1) -> 0.063842631 | C11: =1-B11 -> 0.93615737 | D11: =POWER(C11,$C$1) -> 0.96214394 | F11: =A11*$A$1+D11*$D$1 -> 0.023242879 | H11: =(一步步找点!$B$7*关于alpha次方!A11*关于alpha次方!$G$1+一步步找点!$C$7)*(一步步找点!$B$8*关于alpha次方!D11*关于alpha次方!$G$1+一步步找点!$C$8) -> 0.34876095 | J11: =(一步步找点!$B$7*关于alpha次方!A11*关于alpha次方!$G$1+一步步找点!$C$7) -> 0.43 | K11: =(一步步找点!$B$8*关于alpha次方!D11*关于alpha次方!$G$1+一步步找点!$C$8) -> 0.81107197 | Z11: 5个均分 | AA11: 195 | AC11: 10
A12: 0.22 | B12: =POWER(A12,$B$1) -> 0.075140066 | C12: =1-B12 -> 0.92485993 | D12: =POWER(C12,$C$1) -> 0.95533476 | F12: =A12*$A$1+D12*$D$1 -> 0.023506695 | H12: =(一步步找点!$B$7*关于alpha次方!A12*关于alpha次方!$G$1+一步步找点!$C$7)*(一步步找点!$B$8*关于alpha次方!D12*关于alpha次方!$G$1+一步步找点!$C$8) -> 0.35537365 | J12: =(一步步找点!$B$7*关于alpha次方!A12*关于alpha次方!$G$1+一步步找点!$C$7) -> 0.44 | K12: =(一步步找点!$B$8*关于alpha次方!D12*关于alpha次方!$G$1+一步步找点!$C$8) -> 0.80766738 | Z12: 4个 | AA12: 178 | AC12: 10
A13: 0.24 | B13: =POWER(A13,$B$1) -> 0.087190891 | C13: =1-B13 -> 0.91280911 | D13: =POWER(C13,$C$1) -> 0.94803334 | F13: =A13*$A$1+D13*$D$1 -> 0.023760667 | H13: =(一步步找点!$B$7*关于alpha次方!A13*关于alpha次方!$G$1+一步步找点!$C$7)*(一步步找点!$B$8*关于alpha次方!D13*关于alpha次方!$G$1+一步步找点!$C$8) -> 0.3618075 | J13: =(一步步找点!$B$7*关于alpha次方!A13*关于alpha次方!$G$1+一步步找点!$C$7) -> 0.45 | K13: =(一步步找点!$B$8*关于alpha次方!D13*关于alpha次方!$G$1+一步步找点!$C$8) -> 0.80401667 | Z13: 3个 | AA13: 157 | AC13: 7
A14: 0.26 | B14: =POWER(A14,$B$1) -> 0.099976272 | C14: =1-B14 -> 0.90002373 | D14: =POWER(C14,$C$1) -> 0.94024299 | F14: =A14*$A$1+D14*$D$1 -> 0.02400486 | H14: =(一步步找点!$B$7*关于alpha次方!A14*关于alpha次方!$G$1+一步步找点!$C$7)*(一步步找点!$B$8*关于alpha次方!D14*关于alpha次方!$G$1+一步步找点!$C$8) -> 0.36805589 | J14: =(一步步找点!$B$7*关于alpha次方!A14*关于alpha次方!$G$1+一步步找点!$C$7) -> 0.46 | K14: =(一步步找点!$B$8*关于alpha次方!D14*关于alpha次方!$G$1+一步步找点!$C$8) -> 0.8001215 | Z14: 2个 | AA14: 133 | AC14: 5
A15: 0.28 | B15: =POWER(A15,$B$1) -> 0.1134793 | C15: =1-B15 -> 0.8865207 | D15: =POWER(C15,$C$1) -> 0.93196533 | F15: =A15*$A$1+D15*$D$1 -> 0.024239307 | H15: =(一步步找点!$B$7*关于alpha次方!A15*关于alpha次方!$G$1+一步步找点!$C$7)*(一步步找点!$B$8*关于alpha次方!D15*关于alpha次方!$G$1+一步步找点!$C$8) -> 0.37411185 | J15: =(一步步找点!$B$7*关于alpha次方!A15*关于alpha次方!$G$1+一步步找点!$C$7) -> 0.47 | K15: =(一步步找点!$B$8*关于alpha次方!D15*关于alpha次方!$G$1+一步步找点!$C$8) -> 0.79598266 | Z15: 1个 | AA15: 100 | AC15: 3
A16: 0.3 | B16: =POWER(A16,$B$1) -> 0.12768468 | C16: =1-B16 -> 0.87231532 | D16: =POWER(C16,$C$1) -> 0.92320042 | F16: =A16*$A$1+D16*$D$1 -> 0.024464008 | H16: =(一步步找点!$B$7*关于alpha次方!A16*关于alpha次方!$G$1+一步步找点!$C$7)*(一步步找点!$B$8*关于alpha次方!D16*关于alpha次方!$G$1+一步步找点!$C$8) -> 0.3799681 | J16: =(一步步找点!$B$7*关于alpha次方!A16*关于alpha次方!$G$1+一步步找点!$C$7) -> 0.48 | K16: =(一步步找点!$B$8*关于alpha次方!D16*关于alpha次方!$G$1+一步步找点!$C$8) -> 0.79160021
A17: 0.32 | B17: =POWER(A17,$B$1) -> 0.14257845 | C17: =1-B17 -> 0.85742155 | D17: =POWER(C17,$C$1) -> 0.91394691 | F17: =A17*$A$1+D17*$D$1 -> 0.024678938 | H17: =(一步步找点!$B$7*关于alpha次方!A17*关于alpha次方!$G$1+一步步找点!$C$7)*(一步步找点!$B$8*关于alpha次方!D17*关于alpha次方!$G$1+一步步找点!$C$8) -> 0.38561699 | J17: =(一步步找点!$B$7*关于alpha次方!A17*关于alpha次方!$G$1+一步步找点!$C$7) -> 0.49 | K17: =(一步步找点!$B$8*关于alpha次方!D17*关于alpha次方!$G$1+一步步找点!$C$8) -> 0.78697345
A18: 0.34 | B18: =POWER(A18,$B$1) -> 0.15814782 | C18: =1-B18 -> 0.84185218 | D18: =POWER(C18,$C$1) -> 0.90420204 | F18: =A18*$A$1+D18*$D$1 -> 0.024884041 | H18: =(一步步找点!$B$7*关于alpha次方!A18*关于alpha次方!$G$1+一步步找点!$C$7)*(一步步找点!$B$8*关于alpha次方!D18*关于alpha次方!$G$1+一步步找点!$C$8) -> 0.39105051 | J18: =(一步步找点!$B$7*关于alpha次方!A18*关于alpha次方!$G$1+一步步找点!$C$7) -> 0.5 | K18: =(一步步找点!$B$8*关于alpha次方!D18*关于alpha次方!$G$1+一步步找点!$C$8) -> 0.78210102
A19: 0.36 | B19: =POWER(A19,$B$1) -> 0.17438098 | C19: =1-B19 -> 0.82561902 | D19: =POWER(C19,$C$1) -> 0.89396171 | F19: =A19*$A$1+D19*$D$1 -> 0.025079234 | H19: =(一步步找点!$B$7*关于alpha次方!A19*关于alpha次方!$G$1+一步步找点!$C$7)*(一步步找点!$B$8*关于alpha次方!D19*关于alpha次方!$G$1+一步步找点!$C$8) -> 0.39626024 | J19: =(一步步找点!$B$7*关于alpha次方!A19*关于alpha次方!$G$1+一步步找点!$C$7) -> 0.51 | K19: =(一步步找点!$B$8*关于alpha次方!D19*关于alpha次方!$G$1+一步步找点!$C$8) -> 0.77698085
A20: 0.38 | B20: =POWER(A20,$B$1) -> 0.19126701 | C20: =1-B20 -> 0.80873299 | D20: =POWER(C20,$C$1) -> 0.88322046 | F20: =A20*$A$1+D20*$D$1 -> 0.025264409 | H20: =(一步步找点!$B$7*关于alpha次方!A20*关于alpha次方!$G$1+一步步找点!$C$7)*(一步步找点!$B$8*关于alpha次方!D20*关于alpha次方!$G$1+一步步找点!$C$8) -> 0.40123732 | J20: =(一步步找点!$B$7*关于alpha次方!A20*关于alpha次方!$G$1+一步步找点!$C$7) -> 0.52 | K20: =(一步步找点!$B$8*关于alpha次方!D20*关于alpha次方!$G$1+一步步找点!$C$8) -> 0.77161023
A21: 0.4 | B21: =POWER(A21,$B$1) -> 0.2087957 | C21: =1-B21 -> 0.7912043 | D21: =POWER(C21,$C$1) -> 0.87197147 | F21: =A21*$A$1+D21*$D$1 -> 0.025439429 | H21: =(一步步找点!$B$7*关于alpha次方!A21*关于alpha次方!$G$1+一步步找点!$C$7)*(一步步找点!$B$8*关于alpha次方!D21*关于alpha次方!$G$1+一步步找点!$C$8) -> 0.40597244 | J21: =(一步步找点!$B$7*关于alpha次方!A21*关于alpha次方!$G$1+一步步找点!$C$7) -> 0.53 | K21: =(一步步找点!$B$8*关于alpha次方!D21*关于alpha次方!$G$1+一步步找点!$C$8) -> 0.76598573
A22: 0.42 | B22: =POWER(A22,$B$1) -> 0.22695756 | C22: =1-B22 -> 0.77304244 | D22: =POWER(C22,$C$1) -> 0.86020648 | F22: =A22*$A$1+D22*$D$1 -> 0.02560413 | H22: =(一步步找点!$B$7*关于alpha次方!A22*关于alpha次方!$G$1+一步步找点!$C$7)*(一步步找点!$B$8*关于alpha次方!D22*关于alpha次方!$G$1+一步步找点!$C$8) -> 0.41045575 | J22: =(一步步找点!$B$7*关于alpha次方!A22*关于alpha次方!$G$1+一步步找点!$C$7) -> 0.54 | K22: =(一步步找点!$B$8*关于alpha次方!D22*关于alpha次方!$G$1+一步步找点!$C$8) -> 0.76010324
A23: 0.44 | B23: =POWER(A23,$B$1) -> 0.24574368 | C23: =1-B23 -> 0.75425632 | D23: =POWER(C23,$C$1) -> 0.84791577 | F23: =A23*$A$1+D23*$D$1 -> 0.025758315 | H23: =(一步步找点!$B$7*关于alpha次方!A23*关于alpha次方!$G$1+一步步找点!$C$7)*(一步步找点!$B$8*关于alpha次方!D23*关于alpha次方!$G$1+一步步找点!$C$8) -> 0.41467684 | J23: =(一步步找点!$B$7*关于alpha次方!A23*关于alpha次方!$G$1+一步步找点!$C$7) -> 0.55 | K23: =(一步步找点!$B$8*关于alpha次方!D23*关于alpha次方!$G$1+一步步找点!$C$8) -> 0.75395788
A24: 0.46 | B24: =POWER(A24,$B$1) -> 0.26514565 | C24: =1-B24 -> 0.73485435 | D24: =POWER(C24,$C$1) -> 0.835088 | F24: =A24*$A$1+D24*$D$1 -> 0.02590176 | H24: =(一步步找点!$B$7*关于alpha次方!A24*关于alpha次方!$G$1+一步步找点!$C$7)*(一步步找点!$B$8*关于alpha次方!D24*关于alpha次方!$G$1+一步步找点!$C$8) -> 0.41862464 | J24: =(一步步找点!$B$7*关于alpha次方!A24*关于alpha次方!$G$1+一步步找点!$C$7) -> 0.56 | K24: =(一步步找点!$B$8*关于alpha次方!D24*关于alpha次方!$G$1+一步步找点!$C$8) -> 0.747544
A25: 0.48 | B25: =POWER(A25,$B$1) -> 0.28515559 | C25: =1-B25 -> 0.71484441 | D25: =POWER(C25,$C$1) -> 0.82171014 | F25: =A25*$A$1+D25*$D$1 -> 0.026034203 | H25: =(一步步找点!$B$7*关于alpha次方!A25*关于alpha次方!$G$1+一步步找点!$C$7)*(一步步找点!$B$8*关于alpha次方!D25*关于alpha次方!$G$1+一步步找点!$C$8) -> 0.42228739 | J25: =(一步步找点!$B$7*关于alpha次方!A25*关于alpha次方!$G$1+一步步找点!$C$7) -> 0.57 | K25: =(一步步找点!$B$8*关于alpha次方!D25*关于alpha次方!$G$1+一步步找点!$C$8) -> 0.74085507
A26: 0.5 | B26: =POWER(A26,$B$1) -> 0.30576602 | C26: =1-B26 -> 0.69423398 | D26: =POWER(C26,$C$1) -> 0.80776729 | F26: =A26*$A$1+D26*$D$1 -> 0.026155346 | H26: =(一步步找点!$B$7*关于alpha次方!A26*关于alpha次方!$G$1+一步步找点!$C$7)*(一步步找点!$B$8*关于alpha次方!D26*关于alpha次方!$G$1+一步步找点!$C$8) -> 0.42565251 | J26: =(一步步找点!$B$7*关于alpha次方!A26*关于alpha次方!$G$1+一步步找点!$C$7) -> 0.58 | K26: =(一步步找点!$B$8*关于alpha次方!D26*关于alpha次方!$G$1+一步步找点!$C$8) -> 0.73388364
A27: 0.52 | B27: =POWER(A27,$B$1) -> 0.32696986 | C27: =1-B27 -> 0.67303014 | D27: =POWER(C27,$C$1) -> 0.7932425 | F27: =A27*$A$1+D27*$D$1 -> 0.02626485 | H27: =(一步步找点!$B$7*关于alpha次方!A27*关于alpha次方!$G$1+一步步找点!$C$7)*(一步步找点!$B$8*关于alpha次方!D27*关于alpha次方!$G$1+一步步找点!$C$8) -> 0.42870654 | J27: =(一步步找点!$B$7*关于alpha次方!A27*关于alpha次方!$G$1+一步步找点!$C$7) -> 0.59 | K27: =(一步步找点!$B$8*关于alpha次方!D27*关于alpha次方!$G$1+一步步找点!$C$8) -> 0.72662125
... A50: 0.98 | B50: =POWER(A50,$B$1) -> 0.96605305 | C50: =1-B50 -> 0.033946949 | D50: =POWER(C50,$C$1) -> 0.13821903 | F50: =A50*$A$1+D50*$D$1 -> 0.022364381 | H50: =(一步步找点!$B$7*关于alpha次方!A50*关于alpha次方!$G$1+一步步找点!$C$7)*(一步步找点!$B$8*关于alpha次方!D50*关于alpha次方!$G$1+一步步找点!$C$8) -> 0.3272698 | J50: =(一步步找点!$B$7*关于alpha次方!A50*关于alpha次方!$G$1+一步步找点!$C$7) -> 0.82 | K50: =(一步步找点!$B$8*关于alpha次方!D50*关于alpha次方!$G$1+一步步找点!$C$8) -> 0.39910952

Sheet 改变属性的效果
A1: 状态 | B1: 释义
A2: 修理 | B2: 持续回复生命值
A3: 燃烧 | B3: 持续降低生命值
A4: 增压 | B4: 提高攻击力
A5: 过热 | B5: 降低攻击力
A6: 加固 | B6: 增加护甲值
A7: 腐蚀 | B7: 降低护甲值
A8: 迅捷 | B8: 提高偏移几率
A9: 迟钝 | B9: 降低偏移几率
A10: 平稳 | B10: 提高精准等级
A11: 震荡 | B11: 降低精准等级
A12: 加速 | B12: 提高速度
A13: 减速 | B13: 降低速度

Sheet 攻防相克系数
A1: 攻防对应 | C1: 防御
C2: 轻甲 | D2: 中甲 | E2: 重甲
A3: 攻击 | B3: 穿透类 | C3: 0.9 | D3: 1.1 | E3: 1
B4: 散射类 | C4: 1.1 | D4: 1 | E4: 0.9
B5: 投射类 | C5: 1 | D5: 0.9 | E5: 1.1
