Workbook

Sheet 付费点收益
B3: Gem的获取
B4: RMB->Gem
B5: RMB | C5: Gem | D5: 汇率 Gem/RMB | E5: 折扣
B6: 30 | C6: 500 | D6: =ROUND(C6/B6,2) -> 16.67 | E6: =$D$6/D6 -> 1
B7: 68 | C7: 1200 | D7: =ROUND(C7/B7,2) -> 17.65 | E7: =$D$6/D7 -> 0.94447592
B8: 128 | C8: 2500 | D8: =ROUND(C8/B8,2) -> 19.53 | E8: =$D$6/D8 -> 0.85355863
B9: 328 | C9: 6500 | D9: =ROUND(C9/B9,2) -> 19.82 | E9: =$D$6/D9 -> 0.84106963
B10: 648 | C10: 14000 | D10: =ROUND(C10/B10,2) -> 21.6 | E10: =$D$6/D10 -> 0.77175926
B12: 分析：
C13: 1、RMB梯度是以2为指数的分布。符合购买习惯。
C14: 2、第一个点刚好为购买3号工人的钱，符合刚入门玩家的心理。第二个点和第三个点比购买4号和5号工人多一些，同时折扣也会更高，诱惑玩家选择更高的档次，购买更多的Gem。
C15: 3、折扣随购买量的增多而增多，但是第四个点折扣变动幅度略小，原因可能是如果玩家选择一次性购买所有农民就会选择第4个点，坑这类玩家，能让玩家付更多的钱。
B17: 免费途径获得Gem
C18: 阶段一：玩家获得第三个工人
C19: 阶段二：剩余过程
B20: 途径 | D20: 阶段一 | E20: 阶段二
B21: 新手教程后获得 | D21: 240 | E21: 0 | G21: 成就统计
B22: 清理原有石头和树木 | D22: 38 | E22: 0 | G22: 成就名 | H22: 储金罐 | I22: 消灭哥布林 | J22: 更大更好 | K22: 清爽整洁 | L22: 释放猛兽 | M22: 抓金手 | N22: 圣水恶作剧 | O22: 战无不胜 | P22: 帝国制造者 | Q22: 拆墙达人 | R22: 攻城拔寨 | S22: 工棚破坏者 | T22: 常胜将军 | U22: 固若金汤 | V22: 患难之交 | W22: 破坏迫击炮 | X22: 盗亦有道
B23: 清理再生树木 | D23: 20 | E23: 2Gem/day | G23: 1星奖励 | H23: 2 | I23: 5 | J23: 5 | K23: 5 | L23: 5 | M23: 5 | N23: 5 | O23: 5 | P23: 5 | Q23: 5 | R23: 5 | S23: 5 | T23: 5 | U23: 5 | V23: 5 | W23: 5 | X23: 5
B24: 成就 | D24: 202 | E24: 1210 | G24: 2星奖励 | H24: 5 | I24: 10 | J24: 10 | K24: 10 | L24: 10 | M24: 10 | N24: 10 | O24: 10 | P24: 10 | Q24: 10 | R24: 10 | S24: 10 | T24: 10 | U24: 50 | V24: 25 | W24: 10 | X24: 10
B25: SUM | D25: =SUM(D21:D24) -> 500 | E25: =SUM(E21:E24) -> 1210 | G25: 3星奖励 | H25: 10 | I25: 20 | J25: 20 | K25: 20 | L25: 20 | M25: 20 | N25: 20 | O25: 450 | P25: 20 | Q25: 20 | R25: 50 | S25: 30 | T25: 20 | U25: 100 | V25: 250 | W25: 20 | X25: 20
B26: 分析： | G26: *红色数字表示在阶段一能获得的成就
C27: 1、购买第三个工人是免费玩家贯穿1-6级最重要的目标，时间周期大概是半个月到一个月。第四个工人要求比较苛刻，较难完成，不太能形成有效的目标
A30: 收费点
B31: 购买建造时间
B32: 核心收费点：购买建筑工人
B33: 工人数 | C33: Gem | D33: 玩半个月(H/Gem) | E33: 玩1个月(H/Gem) | F33: 玩2个月(H/Gem)
B34: 1 | C34: 0 | D34: =IFERROR((15*24)/表1[[#This Row],[Gem]],0) -> 0 | E34: =IFERROR((30*24)/表1[[#This Row],[Gem]],0) -> 0 | F34: =IFERROR((60*24)/表1[[#This Row],[Gem]],0) -> 0
B35: 2 | C35: 250 | D35: =IFERROR((15*24)/表1[[#This Row],[Gem]],0) -> 1.44 | E35: =IFERROR((30*24)/表1[[#This Row],[Gem]],0) -> 2.88 | F35: =IFERROR((60*24)/表1[[#This Row],[Gem]],0) -> 5.76
B36: 3 | C36: 500 | D36: =IFERROR((15*24)/表1[[#This Row],[Gem]],0) -> 0.72 | E36: =IFERROR((30*24)/表1[[#This Row],[Gem]],0) -> 1.44 | F36: =IFERROR((60*24)/表1[[#This Row],[Gem]],0) -> 2.88
B37: 4 | C37: 1000 | D37: =IFERROR((15*24)/表1[[#This Row],[Gem]],0) -> 0.36 | E37: =IFERROR((30*24)/表1[[#This Row],[Gem]],0) -> 0.72 | F37: =IFERROR((60*24)/表1[[#This Row],[Gem]],0) -> 1.44
B38: 5 | C38: 2000 | D38: =IFERROR((15*24)/表1[[#This Row],[Gem]],0) -> 0.18 | E38: =IFERROR((30*24)/表1[[#This Row],[Gem]],0) -> 0.36 | F38: =IFERROR((60*24)/表1[[#This Row],[Gem]],0) -> 0.72
B41: 大本营等级 | C41: 资源类消耗时间 | D41: 防御类消耗时间 | E41: 进攻类消耗时间 | F41: 时间求和 | G41: 2工人 | H41: 3工人 | I41: 4工人 | J41: 5工人
B42: 1 | C42: =数据整合!N17 -> 0.783 | D42: =数据整合!U44 -> 0.53333333 | E42: =数据整合!M71 -> 2.35 | F42: =SUM(C42:E42) -> 3.6663333 | G42: =F42/2 -> 1.8331667 | H42: =F42/3 -> 1.2221111 | I42: =F42/4 -> 0.91658333 | J42: =F42/5 -> 0.73326667
B43: 2 | C43: =数据整合!N18 -> 11.2 | D43: =数据整合!U45 -> 2.25 | E43: =数据整合!M72 -> 11.266667 | F43: =SUM(C43:E43) -> 24.716667 | G43: =F43/2 -> 12.358333 | H43: =F43/3 -> 8.2388889 | I43: =F43/4 -> 6.1791667 | J43: =F43/5 -> 4.9433333
B44: 3 | C44: =数据整合!N19 -> 114.2 | D44: =数据整合!U46 -> 12.75 | E44: =数据整合!M73 -> 27.583333 | F44: =SUM(C44:E44) -> 154.53333 | G44: =F44/2 -> 77.266667 | H44: =F44/3 -> 51.511111 | I44: =F44/4 -> 38.633333 | J44: =F44/5 -> 30.906667
B45: 4 | C45: =数据整合!N20 -> 410.7 | D45: =数据整合!U47 -> 62.5 | E45: =数据整合!M74 -> 85.266667 | F45: =SUM(C45:E45) -> 558.46667 | G45: =F45/2 -> 279.23333 | H45: =F45/3 -> 186.15556 | I45: =F45/4 -> 139.61667 | J45: =F45/5 -> 111.69333
B46: 5 | C46: =数据整合!N21 -> 1434.7 | D46: =数据整合!U48 -> 290.51667 | E46: =数据整合!M75 -> 192.08333 | F46: =SUM(C46:E46) -> 1917.3 | G46: =F46/2 -> 958.65 | H46: =F46/3 -> 639.1 | I46: =F46/4 -> 479.325 | J46: =F46/5 -> 383.46
B47: 6 | C47: =数据整合!N22 -> 570.7 | D47: =数据整合!U49 -> 680 | E47: =数据整合!M76 -> 432 | F47: =SUM(C47:E47) -> 1682.7 | G47: =F47/2 -> 841.35 | H47: =F47/3 -> 560.9 | I47: =F47/4 -> 420.675 | J47: =F47/5 -> 336.54
B48: 7 | C48: =数据整合!N23 -> 1608 | D48: =数据整合!U50 -> 2484.5333 | E48: =数据整合!M77 -> 1412.35 | F48: =SUM(C48:E48) -> 5504.8833 | G48: =F48/2 -> 2752.4417 | H48: =F48/3 -> 1834.9611 | I48: =F48/4 -> 1376.2208 | J48: =F48/5 -> 1100.9767
...

Sheet 战斗数值
B3: 攻防战术博弈
B4: 随着玩家的成长，玩家会获得不同类型的攻防单位，而就前中期（笔者玩到的6级）来说，所有的兵种和防御在设计上环环相扣，战术基本上是被限制住的，变化空间不大
C6: 攻击方 | E6: 攻击方策略 | G6: 防守方 | I6: 防御方策略 | K6: 进攻方配置预估 | M6: 建造时间 min | O6: 建造资源 | Q6: 掠夺资源 | S6: 掠夺效率
G7: 城墙、加农炮、地雷 | I7: 通过城墙保护加农炮，增加加农炮的输出时间;通过分散建筑拖延时间
C8: 野蛮人 | E8: 集中火力突破城墙，优先消灭加农炮；通过单独给野外的建筑配置兵力，减少战斗时间，争取更高胜利收益 | K8: 20野蛮人 | M8: =数据整合!B85*20 -> 6.66
G9: 箭塔 | I9: 同加农炮
C10: 弓箭手 | E10: 不破坏城墙直接攻击内部设施，通过选择落点有限处理攻击型建筑
C11: 哥布林 | E11: 当玩家策略是以获取资源优先时优先使用的兵种，一般会在出巨人之后，通过巨人当肉盾，哥布林进行掠夺，最大化资源获取。对于单层城墙和资源外置型阵型效果较好
E12: 进攻方前期处理迫击炮较为困难，需要对迫击炮的攻击规律有较好把握，通过放置单个诱饵，让迫击炮不攻击大部队，然后大部队近身处理掉迫击炮。 | G12: 迫击炮 | I12: 对付大量野蛮人、弓箭手、哥布林效果明显。所以在前期战术核心围绕如何保护/消灭迫击炮展开。防守方多采用多层城墙，瓮城等布局
C13: 巨人 | E13: 核心肉盾型兵种，优先破坏防御武器，处理好迫击炮以后再放置弓箭手/哥布林，完成剩余破坏任务。
G14: 隐身弹簧 | I14: 放置在关键，可一次最多弹飞3个巨人。可以制造陷阱（例如特别脆弱的墙、开口的墙，城墙内部可投放兵的区域）诱惑进攻者向陷阱内投放巨人。
C15: 从此阶段开始，除了兵种上的博弈之外，还有兵种科技等级和防御武器等级之间的博弈，详细参见下文
C16: 炸弹人 | E16: 针对越来越坚固的城墙进行的针对性的攻击。配合巨人吸引火力，炸弹人能有效的破话防御方的城墙。（炸弹人的操作细节很多，非常考验进攻者的技术水平）炸弹人等级与城墙等级的博弈参见下文 | I16: 防御方可以考虑如何构建瓮城让炸弹人的寻路ai不优先攻击关键城墙。难度较大。
G17: 防空火箭 | I17: 防空火箭拥有所有防御设施中最高的血量，初期可以用于构建瓮城，吸引巨人，拖延时间，给别的攻击武器更多的攻击时间。
C18: 气球兵 | E18: 无视城墙，攻击防御武器，但是由于必须在防御设置头顶攻击，所以较难做好保护。相对难用好的兵种。
C19: 部落城堡 | E19: 根据公会内部的人捐献的兵种来制定使用的战术。 | G19: 部落城堡 | I19: 10个单位的防守，可以有效针对敌人的进攻手段，比如巨人和炸弹人
C20: 雷电法术 | E20: 用于破坏城墙、迫击炮、法师塔等关键防御建筑。同时，对部落城堡的援军有较大杀伤。
E21: 与处理迫击炮同，需要设置诱饵。减少大部队受到伤害。 | G21: 法师塔 | I21: 区域攻击，且没有盲区，处理抱团巨人、大数量部队的有效手段。通过制造内部的通道，聚拢敌人造成片杀伤，是非常有效的策略。
C22: 天使 | E22: 群体加血，配合巨人，有效对付片伤塔。
C23: 后期未玩到，待补充
B25: 兵种等级与防御设施等级博弈
B27: 加农炮 | E27: 野蛮人 | L27: 弓箭手 | S27: 哥布林 | Z27: 巨人 | AG27: 法师
B28: 射速 | C28: 0.8s | D28: 等级 | E28: 1 | F28: 2 | G28: 3 | H28: 4 | I28: 5 | J28: 6 | L28: 1 | M28: 2 | N28: 3 | O28: 4 | P28: 5 | Q28: 6 | S28: 1 | T28: 2 | U28: 3 | V28: 4 | W28: 5 | Z28: 1 | AA28: 2 | AB28: 3 | AC28: 4 | AD28: 5 | AE28: 6 | AG28: 1 | AH28: 2 | AI28: 3 | AJ28: 4 | AK28: 5
B29: 等级 | C29: 攻击力 | D29: 血量 | E29: 45 | F29: 54 | G29: 65 | H29: 78 | I29: 95 | J29: 110 | L29: 20 | M29: 23 | N29: 28 | O29: 33 | P29: 40 | Q29: 44 | S29: 25 | T29: 30 | U29: 36 | V29: 43 | W29: 52 | Z29: 300 | AA29: 360 | AB29: 430 | AC29: 520 | AD29: 670 | AE29: 800 | AG29: 75 | AH29: 90 | AI29: 108 | AJ29: 130 | AK29: 156
B30: 1 | C30: 7 | D30: 攻击次数 | E30: =INT(E$29/$C30)+1 -> 7 | F30: =INT(F$29/$C30)+1 -> 8 | G30: =INT(G$29/$C30)+1 -> 10 | H30: =INT(H$29/$C30)+1 -> 12 | I30: =INT(I$29/$C30)+1 -> 14 | J30: =INT(J$29/$C30)+1 -> 16 | L30: =INT(L$29/$C30)+1 -> 3 | M30: =INT(M$29/$C30)+1 -> 4 | N30: =INT(N$29/$C30)+1 -> 5 | O30: =INT(O$29/$C30)+1 -> 5 | P30: =INT(P$29/$C30)+1 -> 6 | Q30: =INT(Q$29/$C30)+1 -> 7 | S30: =INT(S$29/$C30)+1 -> 4 | T30: =INT(T$29/$C30)+1 -> 5 | U30: =INT(U$29/$C30)+1 -> 6 | V30: =INT(V$29/$C30)+1 -> 7 | W30: =INT(W$29/$C30)+1 -> 8 | Z30: =INT(Z$29/$C30)+1 -> 43 | AA30: =INT(AA$29/$C30)+1 -> 52 | AB30: =INT(AB$29/$C30)+1 -> 62 | AC30: =INT(AC$29/$C30)+1 -> 75 | AD30: =INT(AD$29/$C30)+1 -> 96 | AE30: =INT(AE$29/$C30)+1 -> 115 | AG30: =INT(AG$29/$C30)+1 -> 11 | AH30: =INT(AH$29/$C30)+1 -> 13 | AI30: =INT(AI$29/$C30)+1 -> 16 | AJ30: =INT(AJ$29/$C30)+1 -> 19 | AK30: =INT(AK$29/$C30)+1 -> 23
B31: 2 | C31: 9 | E31: =INT(E$29/$C31)+1 -> 6 | F31: =INT(F$29/$C31)+1 -> 7 | G31: =INT(G$29/$C31)+1 -> 8 | H31: =INT(H$29/$C31)+1 -> 9 | I31: =INT(I$29/$C31)+1 -> 11 | J31: =INT(J$29/$C31)+1 -> 13 | L31: =INT(L$29/$C31)+1 -> 3 | M31: =INT(M$29/$C31)+1 -> 3 | N31: =INT(N$29/$C31)+1 -> 4 | O31: =INT(O$29/$C31)+1 -> 4 | P31: =INT(P$29/$C31)+1 -> 5 | Q31: =INT(Q$29/$C31)+1 -> 5 | S31: =INT(S$29/$C31)+1 -> 3 | T31: =INT(T$29/$C31)+1 -> 4 | U31: =INT(U$29/$C31)+1 -> 5 | V31: =INT(V$29/$C31)+1 -> 5 | W31: =INT(W$29/$C31)+1 -> 6 | Z31: =INT(Z$29/$C31)+1 -> 34 | AA31: =INT(AA$29/$C31)+1 -> 41 | AB31: =INT(AB$29/$C31)+1 -> 48 | AC31: =INT(AC$29/$C31)+1 -> 58 | AD31: =INT(AD$29/$C31)+1 -> 75 | AE31: =INT(AE$29/$C31)+1 -> 89 | AG31: =INT(AG$29/$C31)+1 -> 9 | AH31: =INT(AH$29/$C31)+1 -> 11 | AI31: =INT(AI$29/$C31)+1 -> 13 | AJ31: =INT(AJ$29/$C31)+1 -> 15 | AK31: =INT(AK$29/$C31)+1 -> 18
B32: 3 | C32: 12 | E32: =INT(E$29/$C32)+1 -> 4 | F32: =INT(F$29/$C32)+1 -> 5 | G32: =INT(G$29/$C32)+1 -> 6 | H32: =INT(H$29/$C32)+1 -> 7 | I32: =INT(I$29/$C32)+1 -> 8 | J32: =INT(J$29/$C32)+1 -> 10 | L32: =INT(L$29/$C32)+1 -> 2 | M32: =INT(M$29/$C32)+1 -> 2 | N32: =INT(N$29/$C32)+1 -> 3 | O32: =INT(O$29/$C32)+1 -> 3 | P32: =INT(P$29/$C32)+1 -> 4 | Q32: =INT(Q$29/$C32)+1 -> 4 | S32: =INT(S$29/$C32)+1 -> 3 | T32: =INT(T$29/$C32)+1 -> 3 | U32: =INT(U$29/$C32)+1 -> 4 | V32: =INT(V$29/$C32)+1 -> 4 | W32: =INT(W$29/$C32)+1 -> 5 | Z32: =INT(Z$29/$C32)+1 -> 26 | AA32: =INT(AA$29/$C32)+1 -> 31 | AB32: =INT(AB$29/$C32)+1 -> 36 | AC32: =INT(AC$29/$C32)+1 -> 44 | AD32: =INT(AD$29/$C32)+1 -> 56 | AE32: =INT(AE$29/$C32)+1 -> 67 | AG32: =INT(AG$29/$C32)+1 -> 7 | AH32: =INT(AH$29/$C32)+1 -> 8 | AI32: =INT(AI$29/$C32)+1 -> 10 | AJ32: =INT(AJ$29/$C32)+1 -> 11 | AK32: =INT(AK$29/$C32)+1 -> 14
B33: 4 | C33: 15 | E33: =INT(E$29/$C33)+1 -> 4 | F33: =INT(F$29/$C33)+1 -> 4 | G33: =INT(G$29/$C33)+1 -> 5 | H33: =INT(H$29/$C33)+1 -> 6 | I33: =INT(I$29/$C33)+1 -> 7 | J33: =INT(J$29/$C33)+1 -> 8 | L33: =INT(L$29/$C33)+1 -> 2 | M33: =INT(M$29/$C33)+1 -> 2 | N33: =INT(N$29/$C33)+1 -> 2 | O33: =INT(O$29/$C33)+1 -> 3 | P33: =INT(P$29/$C33)+1 -> 3 | Q33: =INT(Q$29/$C33)+1 -> 3 | S33: =INT(S$29/$C33)+1 -> 2 | T33: =INT(T$29/$C33)+1 -> 3 | U33: =INT(U$29/$C33)+1 -> 3 | V33: =INT(V$29/$C33)+1 -> 3 | W33: =INT(W$29/$C33)+1 -> 4 | Z33: =INT(Z$29/$C33)+1 -> 21 | AA33: =INT(AA$29/$C33)+1 -> 25 | AB33: =INT(AB$29/$C33)+1 -> 29 | AC33: =INT(AC$29/$C33)+1 -> 35 | AD33: =INT(AD$29/$C33)+1 -> 45 | AE33: =INT(AE$29/$C33)+1 -> 54 | AG33: =INT(AG$29/$C33)+1 -> 6 | AH33: =INT(AH$29/$C33)+1 -> 7 | AI33: =INT(AI$29/$C33)+1 -> 8 | AJ33: =INT(AJ$29/$C33)+1 -> 9 | AK33: =INT(AK$29/$C33)+1 -> 11
B34: 5 | C34: 20 | E34: =INT(E$29/$C34)+1 -> 3 | F34: =INT(F$29/$C34)+1 -> 3 | G34: =INT(G$29/$C34)+1 -> 4 | H34: =INT(H$29/$C34)+1 -> 4 | I34: =INT(I$29/$C34)+1 -> 5 | J34: =INT(J$29/$C34)+1 -> 6 | L34: =INT(L$29/$C34)+1 -> 2 | M34: =INT(M$29/$C34)+1 -> 2 | N34: =INT(N$29/$C34)+1 -> 2 | O34: =INT(O$29/$C34)+1 -> 2 | P34: =INT(P$29/$C34)+1 -> 3 | Q34: =INT(Q$29/$C34)+1 -> 3 | S34: =INT(S$29/$C34)+1 -> 2 | T34: =INT(T$29/$C34)+1 -> 2 | U34: =INT(U$29/$C34)+1 -> 2 | V34: =INT(V$29/$C34)+1 -> 3 | W34: =INT(W$29/$C34)+1 -> 3 | Z34: =INT(Z$29/$C34)+1 -> 16 | AA34: =INT(AA$29/$C34)+1 -> 19 | AB34: =INT(AB$29/$C34)+1 -> 22 | AC34: =INT(AC$29/$C34)+1 -> 27 | AD34: =INT(AD$29/$C34)+1 -> 34 | AE34: =INT(AE$29/$C34)+1 -> 41 | AG34: =INT(AG$29/$C34)+1 -> 4 | AH34: =INT(AH$29/$C34)+1 -> 5 | AI34: =INT(AI$29/$C34)+1 -> 6 | AJ34: =INT(AJ$29/$C34)+1 -> 7 | AK34: =INT(AK$29/$C34)+1 -> 8
B35: 6 | C35: 25 | E35: =INT(E$29/$C35)+1 -> 2 | F35: =INT(F$29/$C35)+1 -> 3 | G35: =INT(G$29/$C35)+1 -> 3 | H35: =INT(H$29/$C35)+1 -> 4 | I35: =INT(I$29/$C35)+1 -> 4 | J35: =INT(J$29/$C35)+1 -> 5 | L35: =INT(L$29/$C35)+1 -> 1 | M35: =INT(M$29/$C35)+1 -> 1 | N35: =INT(N$29/$C35)+1 -> 2 | O35: =INT(O$29/$C35)+1 -> 2 | P35: =INT(P$29/$C35)+1 -> 2 | Q35: =INT(Q$29/$C35)+1 -> 2 | S35: =INT(S$29/$C35)+1 -> 2 | T35: =INT(T$29/$C35)+1 -> 2 | U35: =INT(U$29/$C35)+1 -> 2 | V35: =INT(V$29/$C35)+1 -> 2 | W35: =INT(W$29/$C35)+1 -> 3 | Z35: =INT(Z$29/$C35)+1 -> 13 | AA35: =INT(AA$29/$C35)+1 -> 15 | AB35: =INT(AB$29/$C35)+1 -> 18 | AC35: =INT(AC$29/$C35)+1 -> 21 | AD35: =INT(AD$29/$C35)+1 -> 27 | AE35: =INT(AE$29/$C35)+1 -> 33 | AG35: =INT(AG$29/$C35)+1 -> 4 | AH35: =INT(AH$29/$C35)+1 -> 4 | AI35: =INT(AI$29/$C35)+1 -> 5 | AJ35: =INT(AJ$29/$C35)+1 -> 6 | AK35: =INT(AK$29/$C35)+1 -> 7
B36: 7 | C36: 32 | E36: =INT(E$29/$C36)+1 -> 2 | F36: =INT(F$29/$C36)+1 -> 2 | G36: =INT(G$29/$C36)+1 -> 3 | H36: =INT(H$29/$C36)+1 -> 3 | I36: =INT(I$29/$C36)+1 -> 3 | J36: =INT(J$29/$C36)+1 -> 4 | L36: =INT(L$29/$C36)+1 -> 1 | M36: =INT(M$29/$C36)+1 -> 1 | N36: =INT(N$29/$C36)+1 -> 1 | O36: =INT(O$29/$C36)+1 -> 2 | P36: =INT(P$29/$C36)+1 -> 2 | Q36: =INT(Q$29/$C36)+1 -> 2 | S36: =INT(S$29/$C36)+1 -> 1 | T36: =INT(T$29/$C36)+1 -> 1 | U36: =INT(U$29/$C36)+1 -> 2 | V36: =INT(V$29/$C36)+1 -> 2 | W36: =INT(W$29/$C36)+1 -> 2 | Z36: =INT(Z$29/$C36)+1 -> 10 | AA36: =INT(AA$29/$C36)+1 -> 12 | AB36: =INT(AB$29/$C36)+1 -> 14 | AC36: =INT(AC$29/$C36)+1 -> 17 | AD36: =INT(AD$29/$C36)+1 -> 21 | AE36: =INT(AE$29/$C36)+1 -> 26 | AG36: =INT(AG$29/$C36)+1 -> 3 | AH36: =INT(AH$29/$C36)+1 -> 3 | AI36: =INT(AI$29/$C36)+1 -> 4 | AJ36: =INT(AJ$29/$C36)+1 -> 5 | AK36: =INT(AK$29/$C36)+1 -> 5
B37: 8 | C37: 38 | E37: =INT(E$29/$C37)+1 -> 2 | F37: =INT(F$29/$C37)+1 -> 2 | G37: =INT(G$29/$C37)+1 -> 2 | H37: =INT(H$29/$C37)+1 -> 3 | I37: =INT(I$29/$C37)+1 -> 3 | J37: =INT(J$29/$C37)+1 -> 3 | L37: =INT(L$29/$C37)+1 -> 1 | M37: =INT(M$29/$C37)+1 -> 1 | N37: =INT(N$29/$C37)+1 -> 1 | O37: =INT(O$29/$C37)+1 -> 1 | P37: =INT(P$29/$C37)+1 -> 2 | Q37: =INT(Q$29/$C37)+1 -> 2 | S37: =INT(S$29/$C37)+1 -> 1 | T37: =INT(T$29/$C37)+1 -> 1 | U37: =INT(U$29/$C37)+1 -> 1 | V37: =INT(V$29/$C37)+1 -> 2 | W37: =INT(W$29/$C37)+1 -> 2 | Z37: =INT(Z$29/$C37)+1 -> 8 | AA37: =INT(AA$29/$C37)+1 -> 10 | AB37: =INT(AB$29/$C37)+1 -> 12 | AC37: =INT(AC$29/$C37)+1 -> 14 | AD37: =INT(AD$29/$C37)+1 -> 18 | AE37: =INT(AE$29/$C37)+1 -> 22 | AG37: =INT(AG$29/$C37)+1 -> 2 | AH37: =INT(AH$29/$C37)+1 -> 3 | AI37: =INT(AI$29/$C37)+1 -> 3 | AJ37: =INT(AJ$29/$C37)+1 -> 4 | AK37: =INT(AK$29/$C37)+1 -> 5
B38: 9 | C38: 45 | E38: =INT(E$29/$C38)+1 -> 2 | F38: =INT(F$29/$C38)+1 -> 2 | G38: =INT(G$29/$C38)+1 -> 2 | H38: =INT(H$29/$C38)+1 -> 2 | I38: =INT(I$29/$C38)+1 -> 3 | J38: =INT(J$29/$C38)+1 -> 3 | L38: =INT(L$29/$C38)+1 -> 1 | M38: =INT(M$29/$C38)+1 -> 1 | N38: =INT(N$29/$C38)+1 -> 1 | O38: =INT(O$29/$C38)+1 -> 1 | P38: =INT(P$29/$C38)+1 -> 1 | Q38: =INT(Q$29/$C38)+1 -> 1 | S38: =INT(S$29/$C38)+1 -> 1 | T38: =INT(T$29/$C38)+1 -> 1 | U38: =INT(U$29/$C38)+1 -> 1 | V38: =INT(V$29/$C38)+1 -> 1 | W38: =INT(W$29/$C38)+1 -> 2 | Z38: =INT(Z$29/$C38)+1 -> 7 | AA38: =INT(AA$29/$C38)+1 -> 9 | AB38: =INT(AB$29/$C38)+1 -> 10 | AC38: =INT(AC$29/$C38)+1 -> 12 | AD38: =INT(AD$29/$C38)+1 -> 15 | AE38: =INT(AE$29/$C38)+1 -> 18 | AG38: =INT(AG$29/$C38)+1 -> 2 | AH38: =INT(AH$29/$C38)+1 -> 3 | AI38: =INT(AI$29/$C38)+1 -> 3 | AJ38: =INT(AJ$29/$C38)+1 -> 3 | AK38: =INT(AK$29/$C38)+1 -> 4
B39: 10 | C39: 52 | E39: =INT(E$29/$C39)+1 -> 1 | F39: =INT(F$29/$C39)+1 -> 2 | G39: =INT(G$29/$C39)+1 -> 2 | H39: =INT(H$29/$C39)+1 -> 2 | I39: =INT(I$29/$C39)+1 -> 2 | J39: =INT(J$29/$C39)+1 -> 3 | L39: =INT(L$29/$C39)+1 -> 1 | M39: =INT(M$29/$C39)+1 -> 1 | N39: =INT(N$29/$C39)+1 -> 1 | O39: =INT(O$29/$C39)+1 -> 1 | P39: =INT(P$29/$C39)+1 -> 1 | Q39: =INT(Q$29/$C39)+1 -> 1 | S39: =INT(S$29/$C39)+1 -> 1 | T39: =INT(T$29/$C39)+1 -> 1 | U39: =INT(U$29/$C39)+1 -> 1 | V39: =INT(V$29/$C39)+1 -> 1 | W39: =INT(W$29/$C39)+1 -> 2 | Z39: =INT(Z$29/$C39)+1 -> 6 | AA39: =INT(AA$29/$C39)+1 -> 7 | AB39: =INT(AB$29/$C39)+1 -> 9 | AC39: =INT(AC$29/$C39)+1 -> 11 | AD39: =INT(AD$29/$C39)+1 -> 13 | AE39: =INT(AE$29/$C39)+1 -> 16 | AG39: =INT(AG$29/$C39)+1 -> 2 | AH39: =INT(AH$29/$C39)+1 -> 2 | AI39: =INT(AI$29/$C39)+1 -> 3 | AJ39: =INT(AJ$29/$C39)+1 -> 3 | AK39: =INT(AK$29/$C39)+1 -> 4
B40: 11 | C40: 60 | E40: =INT(E$29/$C40)+1 -> 1 | F40: =INT(F$29/$C40)+1 -> 1 | G40: =INT(G$29/$C40)+1 -> 2 | H40: =INT(H$29/$C40)+1 -> 2 | I40: =INT(I$29/$C40)+1 -> 2 | J40: =INT(J$29/$C40)+1 -> 2 | L40: =INT(L$29/$C40)+1 -> 1 | M40: =INT(M$29/$C40)+1 -> 1 | N40: =INT(N$29/$C40)+1 -> 1 | O40: =INT(O$29/$C40)+1 -> 1 | P40: =INT(P$29/$C40)+1 -> 1 | Q40: =INT(Q$29/$C40)+1 -> 1 | S40: =INT(S$29/$C40)+1 -> 1 | T40: =INT(T$29/$C40)+1 -> 1 | U40: =INT(U$29/$C40)+1 -> 1 | V40: =INT(V$29/$C40)+1 -> 1 | W40: =INT(W$29/$C40)+1 -> 1 | Z40: =INT(Z$29/$C40)+1 -> 6 | AA40: =INT(AA$29/$C40)+1 -> 7 | AB40: =INT(AB$29/$C40)+1 -> 8 | AC40: =INT(AC$29/$C40)+1 -> 9 | AD40: =INT(AD$29/$C40)+1 -> 12 | AE40: =INT(AE$29/$C40)+1 -> 14 | AG40: =INT(AG$29/$C40)+1 -> 2 | AH40: =INT(AH$29/$C40)+1 -> 2 | AI40: =INT(AI$29/$C40)+1 -> 2 | AJ40: =INT(AJ$29/$C40)+1 -> 3 | AK40: =INT(AK$29/$C40)+1 -> 3
B41: 12 | C41: 69 | E41: =INT(E$29/$C41)+1 -> 1 | F41: =INT(F$29/$C41)+1 -> 1 | G41: =INT(G$29/$C41)+1 -> 1 | H41: =INT(H$29/$C41)+1 -> 2 | I41: =INT(I$29/$C41)+1 -> 2 | J41: =INT(J$29/$C41)+1 -> 2 | L41: =INT(L$29/$C41)+1 -> 1 | M41: =INT(M$29/$C41)+1 -> 1 | N41: =INT(N$29/$C41)+1 -> 1 | O41: =INT(O$29/$C41)+1 -> 1 | P41: =INT(P$29/$C41)+1 -> 1 | Q41: =INT(Q$29/$C41)+1 -> 1 | S41: =INT(S$29/$C41)+1 -> 1 | T41: =INT(T$29/$C41)+1 -> 1 | U41: =INT(U$29/$C41)+1 -> 1 | V41: =INT(V$29/$C41)+1 -> 1 | W41: =INT(W$29/$C41)+1 -> 1 | Z41: =INT(Z$29/$C41)+1 -> 5 | AA41: =INT(AA$29/$C41)+1 -> 6 | AB41: =INT(AB$29/$C41)+1 -> 7 | AC41: =INT(AC$29/$C41)+1 -> 8 | AD41: =INT(AD$29/$C41)+1 -> 10 | AE41: =INT(AE$29/$C41)+1 -> 12 | AG41: =INT(AG$29/$C41)+1 -> 2 | AH41: =INT(AH$29/$C41)+1 -> 2 | AI41: =INT(AI$29/$C41)+1 -> 2 | AJ41: =INT(AJ$29/$C41)+1 -> 2 | AK41: =INT(AK$29/$C41)+1 -> 3
B43: 弓箭塔 | E43: 野蛮人 | L43: 弓箭手 | S43: 哥布林 | Z43: 巨人 | AG43: 气球兵 | AN43: 法师
B44: 射速 | C44: 1s | D44: 等级 | E44: 1 | F44: 2 | G44: 3 | H44: 4 | I44: 5 | J44: 6 | L44: 1 | M44: 2 | N44: 3 | O44: 4 | P44: 5 | Q44: 6 | S44: 1 | T44: 2 | U44: 3 | V44: 4 | W44: 5 | Z44: 1 | AA44: 2 | AB44: 3 | AC44: 4 | AD44: 5 | AE44: 6 | AG44: 1 | AH44: 2 | AI44: 3 | AJ44: 4 | AK44: 5 | AL44: 6 | AN44: 1 | AO44: 2 | AP44: 3 | AQ44: 4 | AR44: 5
B45: 等级 | C45: 攻击力 | D45: 血量 | E45: 45 | F45: 54 | G45: 65 | H45: 78 | I45: 95 | J45: 110 | L45: 20 | M45: 23 | N45: 28 | O45: 33 | P45: 40 | Q45: 44 | S45: 25 | T45: 30 | U45: 36 | V45: 43 | W45: 52 | Z45: 300 | AA45: 360 | AB45: 430 | AC45: 520 | AD45: 670 | AE45: 800 | AG45: 150 | AH45: 180 | AI45: 216 | AJ45: 280 | AK45: 390 | AL45: 545 | AN45: 75 | AO45: 90 | AP45: 108 | AQ45: 130 | AR45: 156
B46: 1 | C46: 11 | D46: 攻击次数 | E46: =INT(E$45/$C46)+1 -> 5 | F46: =INT(F$45/$C46)+1 -> 5 | G46: =INT(G$45/$C46)+1 -> 6 | H46: =INT(H$45/$C46)+1 -> 8 | I46: =INT(I$45/$C46)+1 -> 9 | J46: =INT(J$45/$C46)+1 -> 11 | L46: =INT(L$45/$C46)+1 -> 2 | M46: =INT(M$45/$C46)+1 -> 3 | N46: =INT(N$45/$C46)+1 -> 3 | O46: =INT(O$45/$C46)+1 -> 4 | P46: =INT(P$45/$C46)+1 -> 4 | Q46: =INT(Q$45/$C46)+1 -> 5 | S46: =INT(S$45/$C46)+1 -> 3 | T46: =INT(T$45/$C46)+1 -> 3 | U46: =INT(U$45/$C46)+1 -> 4 | V46: =INT(V$45/$C46)+1 -> 4 | W46: =INT(W$45/$C46)+1 -> 5 | Z46: =INT(Z$45/$C46)+1 -> 28 | AA46: =INT(AA$45/$C46)+1 -> 33 | AB46: =INT(AB$45/$C46)+1 -> 40 | AC46: =INT(AC$45/$C46)+1 -> 48 | AD46: =INT(AD$45/$C46)+1 -> 61 | AE46: =INT(AE$45/$C46)+1 -> 73 | AG46: =INT(AG$45/$C46)+1 -> 14 | AH46: =INT(AH$45/$C46)+1 -> 17 | AI46: =INT(AI$45/$C46)+1 -> 20 | AJ46: =INT(AJ$45/$C46)+1 -> 26 | AK46: =INT(AK$45/$C46)+1 -> 36 | AL46: =INT(AL$45/$C46)+1 -> 50 | AN46: =INT(AN$45/$C46)+1 -> 7 | AO46: =INT(AO$45/$C46)+1 -> 9 | AP46: =INT(AP$45/$C46)+1 -> 10 | AQ46: =INT(AQ$45/$C46)+1 -> 12 | AR46: =INT(AR$45/$C46)+1 -> 15
...

Sheet 数据整合
A2: 资源类
B3: 大本营等级 | C3: 金矿个数 | D3: 金矿等级 | E3: 圣水个数 | F3: 圣水等级 | G3: 储金罐个数 | H3: 储金罐等级 | I3: 圣水瓶个数 | J3: 圣水瓶等级 | K3: 黑水个数 | L3: 黑水等级 | M3: 黑水瓶个数 | N3: 黑水瓶等级
B4: 1 | C4: 1 | D4: 2 | E4: 1 | F4: 2 | G4: 1 | H4: 1 | I4: 1 | J4: 1 | K4: 0 | L4: 0 | M4: 0 | N4: 0
B5: 2 | C5: 2 | D5: 4 | E5: 2 | F5: 4 | G5: 1 | H5: 3 | I5: 1 | J5: 3 | K5: 0 | L5: 0 | M5: 0 | N5: 0
B6: 3 | C6: 3 | D6: 6 | E6: 3 | F6: 6 | G6: 2 | H6: 6 | I6: 2 | J6: 6 | K6: 0 | L6: 0 | M6: 0 | N6: 0
B7: 4 | C7: 4 | D7: 8 | E7: 4 | F7: 8 | G7: 2 | H7: 8 | I7: 2 | J7: 8 | K7: 0 | L7: 0 | M7: 0 | N7: 0
B8: 5 | C8: 5 | D8: 10 | E8: 5 | F8: 10 | G8: 2 | H8: 9 | I8: 2 | J8: 9 | K8: 0 | L8: 0 | M8: 0 | N8: 0
B9: 6 | C9: 6 | D9: 10 | E9: 6 | F9: 10 | G9: 2 | H9: 10 | I9: 2 | J9: 10 | K9: 0 | L9: 0 | M9: 0 | N9: 0
B10: 7 | C10: 6 | D10: 11 | E10: 6 | F10: 11 | G10: 2 | H10: 11 | I10: 2 | J10: 11 | K10: 0 | L10: 0 | M10: 1 | N10: 2
B11: 8 | C11: 6 | D11: 11 | E11: 6 | F11: 11 | G11: 3 | H11: 11 | I11: 3 | J11: 11 | K11: 1 | L11: 3 | M11: 1 | N11: 4
B12: 9 | C12: 6 | D12: 11 | E12: 6 | F12: 11 | G12: 3 | H12: 11 | I12: 3 | J12: 11 | K12: 2 | L12: 6 | M12: 1 | N12: 6
B13: 10 | C13: 6 | D13: 11 | E13: 6 | F13: 11 | G13: 3 | H13: 11 | I13: 3 | J13: 11 | K13: 3 | L13: 6 | M13: 1 | N13: 6
B15: 时间统计
B16: 大本营等级 | C16: 大本营时间 | D16: 金矿总时间 | E16: 金矿时间 | F16: 圣水时间 | G16: 金矿总时间 | H16: 金矿时间 | I16: 圣水时间 | J16: 黑水总时间 | K16: 黑水时间 | L16: 黑水瓶总时间 | M16: 黑水瓶时间 | N16: 总时间
B17: 1 | C17: 0 | D17: =HLOOKUP(D4,建筑配置!$C$16:$M$18,3,FALSE)*C4 -> 0.1 | E17: =D17 -> 0.1 | F17: =E17 -> 0.1 | G17: =HLOOKUP(H4,建筑配置!$C$35:$M$37,3,FALSE)*G4 -> 0.25 | H17: =G17 -> 0.25 | I17: =H17 -> 0.25 | J17: =IFERROR(K4*HLOOKUP(L4,建筑配置!$C$52:$H$54,3,FALSE),0) -> 0 | K17: =J17 -> 0 | L17: =IFERROR(HLOOKUP(N4,建筑配置!$C$52:$H$54,3,FALSE)*M4,0) -> 0 | M17: =L17 -> 0 | N17: =SUM(C18,E17,F17,H17,I17,K17,M17) -> 0.783
B18: 2 | C18: 0.083 | D18: =HLOOKUP(D5,建筑配置!$C$16:$M$18,3,FALSE)*C5 -> 2.7 | E18: =D18-D17 -> 2.6 | F18: =E18 -> 2.6 | G18: =HLOOKUP(H5,建筑配置!$C$35:$M$37,3,FALSE)*G5 -> 1.75 | H18: =G18-G17 -> 1.5 | I18: =H18 -> 1.5 | J18: =IFERROR(K5*HLOOKUP(L5,建筑配置!$C$52:$H$54,3,FALSE),0) -> 0 | K18: =J18-J17 -> 0 | L18: =IFERROR(HLOOKUP(N5,建筑配置!$C$52:$H$54,3,FALSE)*M5,0) -> 0 | M18: =L18-L17 -> 0 | N18: =SUM(C19,E18,F18,H18,I18,K18,M18) -> 11.2
B19: 3 | C19: 3 | D19: =HLOOKUP(D6,建筑配置!$C$16:$M$18,3,FALSE)*C6 -> 28.05 | E19: =D19-D18 -> 25.35 | F19: =E19 -> 25.35 | G19: =HLOOKUP(H6,建筑配置!$C$35:$M$37,3,FALSE)*G6 -> 21.5 | H19: =G19-G18 -> 19.75 | I19: =H19 -> 19.75 | J19: =IFERROR(K6*HLOOKUP(L6,建筑配置!$C$52:$H$54,3,FALSE),0) -> 0 | K19: =J19-J18 -> 0 | L19: =IFERROR(HLOOKUP(N6,建筑配置!$C$52:$H$54,3,FALSE)*M6,0) -> 0 | M19: =L19-L18 -> 0 | N19: =SUM(C20,E19,F19,H19,I19,K19,M19) -> 114.2
B20: 4 | C20: 24 | D20: =HLOOKUP(D7,建筑配置!$C$16:$M$18,3,FALSE)*C7 -> 181.4 | E20: =D20-D19 -> 153.35 | F20: =E20 -> 153.35 | G20: =HLOOKUP(H7,建筑配置!$C$35:$M$37,3,FALSE)*G7 -> 49.5 | H20: =G20-G19 -> 28 | I20: =H20 -> 28 | J20: =IFERROR(K7*HLOOKUP(L7,建筑配置!$C$52:$H$54,3,FALSE),0) -> 0 | K20: =J20-J19 -> 0 | L20: =IFERROR(HLOOKUP(N7,建筑配置!$C$52:$H$54,3,FALSE)*M7,0) -> 0 | M20: =L20-L19 -> 0 | N20: =SUM(C21,E20,F20,H20,I20,K20,M20) -> 410.7
B21: 5 | C21: 48 | D21: =HLOOKUP(D8,建筑配置!$C$16:$M$18,3,FALSE)*C8 -> 826.75 | E21: =D21-D20 -> 645.35 | F21: =E21 -> 645.35 | G21: =HLOOKUP(H8,建筑配置!$C$35:$M$37,3,FALSE)*G8 -> 73.5 | H21: =G21-G20 -> 24 | I21: =H21 -> 24 | J21: =IFERROR(K8*HLOOKUP(L8,建筑配置!$C$52:$H$54,3,FALSE),0) -> 0 | K21: =J21-J20 -> 0 | L21: =IFERROR(HLOOKUP(N8,建筑配置!$C$52:$H$54,3,FALSE)*M8,0) -> 0 | M21: =L21-L20 -> 0 | N21: =SUM(C22,E21,F21,H21,I21,K21,M21) -> 1434.7
B22: 6 | C22: 96 | D22: =HLOOKUP(D9,建筑配置!$C$16:$M$18,3,FALSE)*C9 -> 992.1 | E22: =D22-D21 -> 165.35 | F22: =E22 -> 165.35 | G22: =HLOOKUP(H9,建筑配置!$C$35:$M$37,3,FALSE)*G9 -> 121.5 | H22: =G22-G21 -> 48 | I22: =H22 -> 48 | J22: =IFERROR(K9*HLOOKUP(L9,建筑配置!$C$52:$H$54,3,FALSE),0) -> 0 | K22: =J22-J21 -> 0 | L22: =IFERROR(HLOOKUP(N9,建筑配置!$C$52:$H$54,3,FALSE)*M9,0) -> 0 | M22: =L22-L21 -> 0 | N22: =SUM(C23,E22,F22,H22,I22,K22,M22) -> 570.7
B23: 7 | C23: 144 | D23: =HLOOKUP(D10,建筑配置!$C$16:$M$18,3,FALSE)*C10 -> 1568.1 | E23: =D23-D22 -> 576 | F23: =E23 -> 576 | G23: =HLOOKUP(H10,建筑配置!$C$35:$M$37,3,FALSE)*G10 -> 217.5 | H23: =G23-G22 -> 96 | I23: =H23 -> 96 | J23: =IFERROR(K10*HLOOKUP(L10,建筑配置!$C$52:$H$54,3,FALSE),0) -> 0 | K23: =J23-J22 -> 0 | L23: =IFERROR(HLOOKUP(N10,建筑配置!$C$52:$H$54,3,FALSE)*M10,0) -> 72 | M23: =L23-L22 -> 72 | N23: =SUM(C24,E23,F23,H23,I23,K23,M23) -> 1608
B24: 8 | C24: 192 | D24: =HLOOKUP(D11,建筑配置!$C$16:$M$18,3,FALSE)*C11 -> 1568.1 | E24: =D24-D23 -> 0 | F24: =E24 -> 0 | G24: =HLOOKUP(H11,建筑配置!$C$35:$M$37,3,FALSE)*G11 -> 326.25 | H24: =G24-G23 -> 108.75 | I24: =H24 -> 108.75 | J24: =IFERROR(K11*HLOOKUP(L11,建筑配置!$C$52:$H$54,3,FALSE),0) -> 144 | K24: =J24-J23 -> 144 | L24: =IFERROR(HLOOKUP(N11,建筑配置!$C$52:$H$54,3,FALSE)*M11,0) -> 240 | M24: =L24-L23 -> 168 | N24: =SUM(C25,E24,F24,H24,I24,K24,M24) -> 769.5
B25: 9 | C25: 240 | D25: =HLOOKUP(D12,建筑配置!$C$16:$M$18,3,FALSE)*C12 -> 1568.1 | E25: =D25-D24 -> 0 | F25: =E25 -> 0 | G25: =HLOOKUP(H12,建筑配置!$C$35:$M$37,3,FALSE)*G12 -> 326.25 | H25: =G25-G24 -> 0 | I25: =H25 -> 0 | J25: =IFERROR(K12*HLOOKUP(L12,建筑配置!$C$52:$H$54,3,FALSE),0) -> 1152 | K25: =J25-J24 -> 1008 | L25: =IFERROR(HLOOKUP(N12,建筑配置!$C$52:$H$54,3,FALSE)*M12,0) -> 576 | M25: =L25-L24 -> 336 | N25: =SUM(C26,E25,F25,H25,I25,K25,M25) -> 1680
B26: 10 | C26: 336 | D26: =HLOOKUP(D13,建筑配置!$C$16:$M$18,3,FALSE)*C13 -> 1568.1 | E26: =D26-D25 -> 0 | F26: =E26 -> 0 | G26: =HLOOKUP(H13,建筑配置!$C$35:$M$37,3,FALSE)*G13 -> 326.25 | H26: =G26-G25 -> 0 | I26: =H26 -> 0 | J26: =IFERROR(K13*HLOOKUP(L13,建筑配置!$C$52:$H$54,3,FALSE),0) -> 1728 | K26: =J26-J25 -> 576 | L26: =IFERROR(HLOOKUP(N13,建筑配置!$C$52:$H$54,3,FALSE)*M13,0) -> 576 | M26: =L26-L25 -> 0 | N26: =SUM(C27,E26,F26,H26,I26,K26,M26) -> 576
A28: 防御类
B30: 大本营等级 | C30: 加农炮 | D30: 加农炮LV | E30: 迫击炮 | F30: 迫击炮LV | G30: 弓箭塔 | H30: 弓箭塔lv | I30: 防空火箭 | J30: 防空火箭lv | K30: 法师塔 | L30: 法师塔LV | M30: 电磁塔 | N30: 电磁塔lv | O30: 城墙 | P30: 城墙LV | Q30: X弩 | R30: X弩lv | S30: 地狱之塔 | T30: 地狱之塔lv
B31: 1 | C31: 2 | D31: 2 | E31: 0 | F31: 0 | G31: 0 | H31: 0 | I31: 0 | J31: 0 | K31: 0 | L31: 0 | M31: 0 | N31: 0 | O31: 0 | P31: 0 | Q31: 0 | R31: 0 | S31: 0 | T31: 0
B32: 2 | C32: 2 | D32: 3 | E32: 0 | F32: 0 | G32: 1 | H32: 2 | I32: 0 | J32: 0 | K32: 0 | L32: 0 | M32: 0 | N32: 0 | O32: 25 | P32: 2 | Q32: 0 | R32: 0 | S32: 0 | T32: 0
B33: 3 | C33: 2 | D33: 4 | E33: 1 | F33: 1 | G33: 1 | H33: 3 | I33: 0 | J33: 0 | K33: 0 | L33: 0 | M33: 0 | N33: 0 | O33: 50 | P33: 3 | Q33: 0 | R33: 0 | S33: 0 | T33: 0
B34: 4 | C34: 2 | D34: 5 | E34: 1 | F34: 2 | G34: 2 | H34: 4 | I34: 1 | J34: 2 | K34: 0 | L34: 0 | M34: 0 | N34: 0 | O34: 75 | P34: 4 | Q34: 0 | R34: 0 | S34: 0 | T34: 0
B35: 5 | C35: 3 | D35: 6 | E35: 1 | F35: 3 | G35: 3 | H35: 6 | I35: 1 | J35: 3 | K35: 1 | L35: 2 | M35: 0 | N35: 0 | O35: 100 | P35: 5 | Q35: 0 | R35: 0 | S35: 0 | T35: 0
B36: 6 | C36: 3 | D36: 7 | E36: 2 | F36: 4 | G36: 3 | H36: 7 | I36: 1 | J36: 4 | K36: 2 | L36: 3 | M36: 0 | N36: 0 | O36: 125 | P36: 6 | Q36: 0 | R36: 0 | S36: 0 | T36: 0
B37: 7 | C37: 5 | D37: 8 | E37: 3 | F37: 5 | G37: 4 | H37: 8 | I37: 2 | J37: 5 | K37: 2 | L37: 4 | M37: 2 | N37: 3 | O37: 175 | P37: 7 | Q37: 0 | R37: 0 | S37: 0 | T37: 0
B38: 8 | C38: 5 | D38: 10 | E38: 3 | F38: 6 | G38: 5 | H38: 10 | I38: 3 | J38: 6 | K38: 3 | L38: 6 | M38: 3 | N38: 6 | O38: 225 | P38: 8 | Q38: 0 | R38: 0 | S38: 0 | T38: 0
B39: 9 | C39: 5 | D39: 11 | E39: 3 | F39: 7 | G39: 6 | H39: 11 | I39: 4 | J39: 7 | K39: 4 | L39: 7 | M39: 4 | N39: 7 | O39: 250 | P39: 10 | Q39: 2 | R39: 3 | S39: 0 | T39: 0
B40: 10 | C40: 6 | D40: 11 | E40: 3 | F40: 7 | G40: 7 | H40: 11 | I40: 4 | J40: 8 | K40: 4 | L40: 7 | M40: 4 | N40: 7 | O40: 250 | P40: 10 | Q40: 2 | R40: 4 | S40: 1 | T40: 2
B42: 时间统计
B43: 大本营等级 | C43: 加农炮 | D43: 加农炮 | E43: 迫击炮 | F43: 迫击炮 | G43: 弓箭塔 | H43: 弓箭塔 | I43: 防空火箭 | J43: 防空火箭 | K43: 法师塔 | L43: 法师塔 | M43: 电磁塔 | N43: 电磁塔 | O43: 城墙 | P43: 城墙 | Q43: X弩 | R43: X弩 | S43: 地狱之塔 | T43: 地狱之塔 | U43: 总时间
B44: 1 | C44: =C31*HLOOKUP(D31,建筑配置!$C$71:$M$73,3,FALSE) -> 0.53333333 | D44: =C44 -> 0.53333333 | E44: =IFERROR(E31*HLOOKUP(F31,建筑配置!$C$80:$I$82,3,FALSE),0) -> 0 | F44: =E44 -> 0 | G44: =IFERROR(G31*HLOOKUP(H31,建筑配置!$C$89:$M$91,3,FALSE),0) -> 0 | H44: =G44 -> 0 | I44: =IFERROR(I31*HLOOKUP(J31,建筑配置!$C$98:$J$100,3,FALSE),0) -> 0 | J44: =I44 -> 0 | K44: =IFERROR(K31*HLOOKUP(L31,建筑配置!$C$107:$I$109,3,FALSE),0) -> 0 | L44: =K44 -> 0 | M44: =IFERROR(M31*HLOOKUP(N31,建筑配置!$C$116:$I$118,3,FALSE),0) -> 0 | N44: =M44 -> 0 | O44: 0 | P44: =O44 -> 0 | Q44: =IFERROR(Q31*HLOOKUP(R31,建筑配置!$C$131:$F$133,3,FALSE),0) -> 0 | R44: =Q44 -> 0 | S44: =IFERROR(S31*HLOOKUP(T31,建筑配置!$C$140:$D$142,3,FALSE),0) -> 0 | T44: =S44 -> 0 | U44: =SUM(D44,F44,H44,J44,L44,N44,P44,R44,T44) -> 0.53333333
B45: 2 | C45: =C32*HLOOKUP(D32,建筑配置!$C$71:$M$73,3,FALSE) -> 2.0333333 | D45: =C45-C44 -> 1.5 | E45: =IFERROR(E32*HLOOKUP(F32,建筑配置!$C$80:$I$82,3,FALSE),0) -> 0 | F45: =E45-E44 -> 0 | G45: =IFERROR(G32*HLOOKUP(H32,建筑配置!$C$89:$M$91,3,FALSE),0) -> 0.75 | H45: =G45-G44 -> 0.75 | I45: =IFERROR(I32*HLOOKUP(J32,建筑配置!$C$98:$J$100,3,FALSE),0) -> 0 | J45: =I45-I44 -> 0 | K45: =IFERROR(K32*HLOOKUP(L32,建筑配置!$C$107:$I$109,3,FALSE),0) -> 0 | L45: =K45-K44 -> 0 | M45: =IFERROR(M32*HLOOKUP(N32,建筑配置!$C$116:$I$118,3,FALSE),0) -> 0 | N45: =M45-M44 -> 0 | O45: 0 | P45: =O45-O44 -> 0 | Q45: =IFERROR(Q32*HLOOKUP(R32,建筑配置!$C$131:$F$133,3,FALSE),0) -> 0 | R45: =Q45-Q44 -> 0 | S45: =IFERROR(S32*HLOOKUP(T32,建筑配置!$C$140:$D$142,3,FALSE),0) -> 0 | T45: =S45-S44 -> 0 | U45: =SUM(D45,F45,H45,J45,L45,N45,P45,R45,T45) -> 2.25
...

Sheet 建筑配置
A1: 大本营
A2: 建筑等级 | C2: 1 | D2: 2 | E2: 3 | F2: 4 | G2: 5 | H2: 6 | I2: 7 | J2: 8 | K2: 9 | L2: 10
A3: 建造时间 | C3: -- | D3: 0.083333333 | E3: 3 | F3: 24 | G3: 48 | H3: 96 | I3: 144 | J3: 192 | K3: 240 | L3: 336
A4: 消耗金币 | C4: -- | D4: 1000 | E4: 4000 | F4: 25000 | G4: 150000 | H4: 750000 | I4: 1200000 | J4: 2000000 | K4: 3000000 | L4: 4000000
A5: 增加经验 | C5: -- | D5: 17 | E5: 103 | F5: 293 | G5: 415 | H5: 587 | I5: 720 | J5: 831 | K5: 929 | L5: 1099
A6: 生命值 | C6: 1500 | D6: 1600 | E6: 1850 | F6: 2100 | G6: 2400 | H6: 2800 | I6: 3200 | J6: 3700 | K6: 4200 | L6: 5000
A8: 部落城堡
A9: 建筑等级 | C9: 1 | D9: 2 | E9: 3 | F9: 4 | G9: 5
A10: 建造时间 | C10: 0 | D10: 0.25 | E10: 1 | F10: 2 | G10: 7
A11: 消耗金币 | C11: 40000 | D11: 100000 | E11: 800000 | F11: 1800000 | G11: 7000000
A12: 增加经验 | C12: 0 | D12: 146 | E12: 293 | F12: 415 | G12: 777
A13: 生命值 | C13: 1000 | D13: 1400 | E13: 2000 | F13: 2600 | G13: 3000
A15: 金矿
A16: 建筑等级 | C16: 1 | D16: 2 | E16: 3 | F16: 4 | G16: 5 | H16: 6 | I16: 7 | J16: 8 | K16: 9 | L16: 10 | M16: 11
A17: 建造时间 | C17: 0.017 | D17: 0.083 | E17: 0.25 | F17: 1 | G17: 2 | H17: 6 | I17: 12 | J17: 24 | K17: 48 | L17: 72 | M17: 96
A18: 建造累计时间 | C18: =SUM($C$17:C17) -> 0.017 | D18: =SUM($C$17:D17) -> 0.1 | E18: =SUM($C$17:E17) -> 0.35 | F18: =SUM($C$17:F17) -> 1.35 | G18: =SUM($C$17:G17) -> 3.35 | H18: =SUM($C$17:H17) -> 9.35 | I18: =SUM($C$17:I17) -> 21.35 | J18: =SUM($C$17:J17) -> 45.35 | ... M18: =SUM($C$17:M17) -> 261.35
A19: 消耗圣水 | C19: 150 | D19: 300 | E19: 700 | F19: 1400 | G19: 3000 | H19: 7000 | I19: 14000 | J19: 28000 | K19: 56000 | L19: 84000 | M19: 168000
A20: 增加经验 | C20: 7 | D20: 17 | E20: 30 | F20: 60 | G20: 120 | H20: 207 | I20: 293 | J20: 415 | K20: 509 | L20: 587 | M20: 657
A21: 生命值 | C21: 400 | D21: 450 | E21: 500 | F21: 550 | G21: 590 | H21: 610 | I21: 630 | J21: 660 | K21: 680 | L21: 710 | M21: 750
A22: 生产速度（每小时） | C22: 200 | D22: 400 | E22: 600 | F22: 800 | G22: 1000 | H22: 1300 | I22: 1600 | J22: 1900 | K22: 2200 | L22: 2500 | M22: 3000
A23: 容量 | C23: 500 | D23: 1000 | E23: 1500 | F23: 2500 | G23: 10000 | H23: 20000 | I23: 30000 | J23: 50000 | K23: 75000 | L23: 100000 | M23: 150000
A25: 圣水收集器
A26: 建筑等级 | C26: 1 | D26: 2 | E26: 3 | F26: 4 | G26: 5 | H26: 6 | I26: 7 | J26: 8 | K26: 9 | L26: 10 | M26: 11
A27: 建造时间 | C27: 0.017 | D27: 0.083 | E27: 0.25 | F27: 1 | G27: 2 | H27: 6 | I27: 12 | J27: 24 | K27: 48 | L27: 72 | M27: 96
A28: 消耗金币 | C28: 150 | D28: 300 | E28: 700 | F28: 1400 | G28: 3000 | H28: 7000 | I28: 14000 | J28: 28000 | K28: 56000 | L28: 84000 | M28: 168000
A29: 增加经验 | C29: 7 | D29: 17 | E29: 30 | F29: 60 | G29: 120 | H29: 207 | I29: 293 | J29: 415 | K29: 509 | L29: 587 | M29: 657
A30: 生命值 | C30: 400 | D30: 450 | E30: 500 | F30: 550 | G30: 590 | H30: 610 | I30: 630 | J30: 660 | K30: 680 | L30: 710 | M30: 750
A31: 生产速度（每小时） | C31: 200 | D31: 400 | E31: 600 | F31: 800 | G31: 1000 | H31: 1300 | I31: 1600 | J31: 1900 | K31: 2200 | L31: 2500 | M31: 3000
A32: 容量 | C32: 500 | D32: 1000 | E32: 1500 | F32: 2500 | G32: 10000 | H32: 20000 | I32: 30000 | J32: 50000 | K32: 75000 | L32: 100000 | M32: 150000
A34: 储金器
A35: 建筑等级 | C35: 1 | D35: 2 | E35: 3 | F35: 4 | G35: 5 | H35: 6 | I35: 7 | J35: 8 | K35: 9 | L35: 10 | M35: 11
A36: 建造时间 | C36: 0.25 | D36: 0.5 | E36: 1 | F36: 2 | G36: 3 | H36: 4 | I36: 6 | J36: 8 | K36: 12 | L36: 24 | M36: 48
A37: 建造累计时间 | C37: =SUM($C$36:C36) -> 0.25 | D37: =SUM($C$36:D36) -> 0.75 | E37: =SUM($C$36:E36) -> 1.75 | F37: =SUM($C$36:F36) -> 3.75 | G37: =SUM($C$36:G36) -> 6.75 | H37: =SUM($C$36:H36) -> 10.75 | I37: =SUM($C$36:I36) -> 16.75 | J37: =SUM($C$36:J36) -> 24.75 | ... M37: =SUM($C$36:M36) -> 108.75
A38: 消耗圣水 | C38: 300 | D38: 750 | E38: 1500 | F38: 3000 | G38: 6000 | H38: 12000 | I38: 25000 | J38: 50000 | K38: 100000 | L38: 250000 | M38: 500000
A39: 增加经验 | C39: 30 | D39: 42 | E39: 60 | F39: 84 | G39: 103 | H39: 120 | I39: 146 | J39: 169 | K39: 207 | L39: 293 | M39: 415
A40: 生命值 | C40: 400 | D40: 600 | E40: 800 | F40: 1000 | G40: 1200 | H40: 1500 | I40: 1650 | J40: 1740 | K40: 1820 | L40: 1920 | M40: 2016
A41: 库存容量 | C41: 1500 | D41: 3000 | E41: 6000 | F41: 12000 | G41: 25000 | H41: 50000 | I41: 100000 | J41: 250000 | K41: 500000 | L41: 1000000 | M41: 2000000
A43: 圣水瓶
A44: 建筑等级 | C44: 1 | D44: 2 | E44: 3 | F44: 4 | G44: 5 | H44: 6 | I44: 7 | J44: 8 | K44: 9 | L44: 10 | M44: 11
A45: 建造时间 | C45: 0.010416667 | D45: 0.020833333 | E45: 0.041666667 | F45: 0.083333333 | G45: 0.125 | H45: 0.16666667 | I45: 0.25 | J45: 0.33333333 | K45: 0.5 | L45: 1 | M45: 2
...

Sheet 等级参数
A1: 建筑数量限制关系
A2: 大本营等级 | B2: 部落城堡 | C2: 金矿 | D2: 圣水收集器 | E2: 储金罐 | F2: 圣水瓶 | G2: 暗黑石油钻井 | H2: 暗黑石油罐 | I2: 工房 | J2: 加农炮 | K2: 迫击炮 | L2: 弓箭塔 | M2: 防空火箭 | N2: 法师塔 | O2: 电磁塔 | P2: 城墙 | Q2: X弩 | R2: 地狱之塔 | S2: 隐身炸弹 | T2: 隐身弹簧 | U2: 巨型炸弹 | V2: 空中炸弹 | W2: 追踪式空中炸弹 | X2: 营地 | Y2: 训练营 | Z2: 黑暗训练营 | AA2: 试验室 | AB2: 法术工厂 | AC2: 野蛮人之王 | AD2: 弓箭女王
A3: 1 | B3: 0 | C3: 1 | D3: 1 | E3: 1 | F3: 1 | G3: 0 | H3: 0 | I3: 5 | J3: 2 | K3: 0 | L3: 0 | M3: 0 | N3: 0 | O3: 0 | P3: 0 | Q3: 0 | R3: 0 | S3: 0 | T3: 0 | U3: 0 | V3: 0 | W3: 0 | X3: 1 | Y3: 1 | Z3: 0 | AA3: 0 | AB3: 0 | AC3: 0 | AD3: 0
A4: 2 | B4: 0 | C4: 2 | D4: 2 | E4: 1 | F4: 1 | G4: 0 | H4: 0 | I4: 5 | J4: 2 | K4: 0 | L4: 1 | M4: 0 | N4: 0 | O4: 0 | P4: 25 | Q4: 0 | R4: 0 | S4: 2 | T4: 0 | U4: 0 | V4: 0 | W4: 0 | X4: 1 | Y4: 2 | Z4: 0 | AA4: 0 | AB4: 0 | AC4: 0 | AD4: 0
A5: 3 | B5: 1 | C5: 3 | D5: 3 | E5: 2 | F5: 2 | G5: 0 | H5: 0 | I5: 5 | J5: 2 | K5: 1 | L5: 1 | M5: 0 | N5: 0 | O5: 0 | P5: 50 | Q5: 0 | R5: 0 | S5: 2 | T5: 0 | U5: 0 | V5: 0 | W5: 0 | X5: 2 | Y5: 2 | Z5: 0 | AA5: 1 | AB5: 0 | AC5: 0 | AD5: 0
A6: 4 | B6: 1 | C6: 4 | D6: 4 | E6: 2 | F6: 2 | G6: 0 | H6: 0 | I6: 5 | J6: 2 | K6: 1 | L6: 2 | M6: 1 | N6: 0 | O6: 0 | P6: 75 | Q6: 0 | R6: 0 | S6: 2 | T6: 2 | U6: 0 | V6: 0 | W6: 0 | X6: 2 | Y6: 3 | Z6: 0 | AA6: 1 | AB6: 0 | AC6: 0 | AD6: 0
A7: 5 | B7: 1 | C7: 5 | D7: 5 | E7: 2 | F7: 2 | G7: 0 | H7: 0 | I7: 5 | J7: 3 | K7: 1 | L7: 3 | M7: 1 | N7: 1 | O7: 0 | P7: 100 | Q7: 0 | R7: 0 | S7: 4 | T7: 2 | U7: 0 | V7: 2 | W7: 0 | X7: 3 | Y7: 3 | Z7: 0 | AA7: 1 | AB7: 1 | AC7: 0 | AD7: 0
A8: 6 | B8: 1 | C8: 6 | D8: 6 | E8: 2 | F8: 2 | G8: 0 | H8: 0 | I8: 5 | J8: 3 | K8: 2 | L8: 3 | M8: 1 | N8: 2 | O8: 0 | P8: 125 | Q8: 0 | R8: 0 | S8: 4 | T8: 4 | U8: 1 | V8: 2 | W8: 0 | X8: 3 | Y8: 3 | Z8: 0 | AA8: 1 | AB8: 1 | AC8: 0 | AD8: 0
A9: 7 | B9: 1 | C9: 6 | D9: 6 | E9: 2 | F9: 2 | G9: 0 | H9: 1 | I9: 5 | J9: 5 | K9: 3 | L9: 4 | M9: 2 | N9: 2 | O9: 2 | P9: 175 | Q9: 0 | R9: 0 | S9: 6 | T9: 4 | U9: 2 | V9: 2 | W9: 1 | X9: 4 | Y9: 4 | Z9: 1 | AA9: 1 | AB9: 1 | AC9: 1 | AD9: 0
A10: 8 | B10: 1 | C10: 6 | D10: 6 | E10: 3 | F10: 3 | G10: 1 | H10: 1 | I10: 5 | J10: 5 | K10: 3 | L10: 5 | M10: 3 | N10: 3 | O10: 3 | P10: 225 | Q10: 0 | R10: 0 | S10: 6 | T10: 6 | U10: 3 | V10: 4 | W10: 2 | X10: 4 | Y10: 4 | Z10: 2 | AA10: 1 | AB10: 1 | AC10: 1 | AD10: 0
A11: 9 | B11: 1 | C11: 6 | D11: 6 | E11: 3 | F11: 3 | G11: 2 | H11: 1 | I11: 5 | J11: 5 | K11: 3 | L11: 6 | M11: 4 | N11: 4 | O11: 4 | P11: 250 | Q11: 2 | R11: 0 | S11: 6 | T11: 6 | U11: 4 | V11: 4 | W11: 3 | X11: 4 | Y11: 4 | Z11: 2 | AA11: 1 | AB11: 1 | AC11: 1 | AD11: 1
A12: 10 | B12: 1 | C12: 6 | D12: 6 | E12: 3 | F12: 3 | G12: 3 | H12: 1 | I12: 5 | J12: 6 | K12: 3 | L12: 7 | M12: 4 | N12: 4 | O12: 4 | P12: 250 | Q12: 2 | R12: 1 | S12: 6 | T12: 6 | U12: 5 | V12: 4 | W12: 3 | X12: 4 | Y12: 4 | Z12: 2 | AA12: 1 | AB12: 1 | AC12: 1 | AD12: 1
A14: 建筑等级限制关系
A15: 大本营等级 | B15: 部落城堡 | C15: 金矿 | D15: 圣水收集器 | E15: 储金罐 | F15: 圣水瓶 | G15: 暗黑石油钻井 | H15: 暗黑石油罐 | I15: 工房 | J15: 加农炮 | K15: 迫击炮 | L15: 弓箭塔 | M15: 防空火箭 | N15: 法师塔 | O15: 电磁塔 | P15: 城墙 | Q15: X弩 | R15: 地狱之塔 | S15: 隐身炸弹 | T15: 隐身弹簧 | U15: 巨型炸弹 | V15: 空中炸弹 | W15: 追踪式空中炸弹 | X15: 营地 | Y15: 训练营 | Z15: 黑暗训练营 | AA15: 试验室 | AB15: 法术工厂 | AC15: 野蛮人之王 | AD15: 弓箭女王
A16: 1 | B16: 0 | C16: 2 | D16: 2 | E16: 1 | F16: 1 | G16: 0 | H16: 0 | I16: 1 | J16: 2 | K16: 0 | L16: 0 | M16: 0 | N16: 0 | O16: 0 | P16: 0 | Q16: 0 | R16: 0 | S16: 0 | T16: 0 | U16: 0 | V16: 0 | W16: 0 | X16: 1 | Y16: 3 | Z16: 0 | AA16: 0 | AB16: 0 | AC16: 0 | AD16: 0
A17: 2 | B17: 0 | C17: 4 | D17: 4 | E17: 3 | F17: 3 | G17: 0 | H17: 0 | I17: 1 | J17: 3 | K17: 0 | L17: 2 | M17: 0 | N17: 0 | O17: 0 | P17: 2 | Q17: 0 | R17: 0 | S17: 1 | T17: 0 | U17: 0 | V17: 0 | W17: 0 | X17: 2 | Y17: 4 | Z17: 0 | AA17: 0 | AB17: 0 | AC17: 0 | AD17: 0
A18: 3 | B18: 1 | C18: 6 | D18: 6 | E18: 6 | F18: 6 | G18: 0 | H18: 0 | I18: 1 | J18: 4 | K18: 1 | L18: 3 | M18: 0 | N18: 0 | O18: 0 | P18: 3 | Q18: 0 | R18: 0 | S18: 1 | T18: 0 | U18: 0 | V18: 0 | W18: 0 | X18: 3 | Y18: 5 | Z18: 0 | AA18: 1 | AB18: 0 | AC18: 0 | AD18: 0
A19: 4 | B19: 2 | C19: 8 | D19: 8 | E19: 8 | F19: 8 | G19: 0 | H19: 0 | I19: 1 | J19: 5 | K19: 2 | L19: 4 | M19: 2 | N19: 0 | O19: 0 | P19: 4 | Q19: 0 | R19: 0 | S19: 1 | T19: 1 | U19: 0 | V19: 0 | W19: 0 | X19: 4 | Y19: 6 | Z19: 0 | AA19: 2 | AB19: 0 | AC19: 0 | AD19: 0
A20: 5 | B20: 2 | C20: 10 | D20: 10 | E20: 9 | F20: 9 | G20: 0 | H20: 0 | I20: 1 | J20: 6 | K20: 3 | L20: 6 | M20: 3 | N20: 2 | O20: 0 | P20: 5 | Q20: 0 | R20: 0 | S20: 1 | T20: 1 | U20: 0 | V20: 1 | W20: 0 | X20: 5 | Y20: 7 | Z20: 0 | AA20: 3 | AB20: 1 | AC20: 0 | AD20: 0
A21: 6 | B21: 3 | C21: 10 | D21: 10 | E21: 10 | F21: 10 | G21: 0 | H21: 0 | I21: 1 | J21: 7 | K21: 4 | L21: 7 | M21: 4 | N21: 3 | O21: 0 | P21: 6 | Q21: 0 | R21: 0 | S21: 1 | T21: 1 | U21: 1 | V21: 1 | W21: 0 | X21: 6 | Y21: 8 | Z21: 0 | AA21: 4 | AB21: 2 | AC21: 0 | AD21: 0
A22: 7 | B22: 3 | C22: 11 | D22: 11 | E22: 11 | F22: 11 | G22: 0 | H22: 2 | I22: 1 | J22: 8 | K22: 5 | L22: 8 | M22: 5 | N22: 4 | O22: 3 | P22: 7 | Q22: 0 | R22: 0 | S22: 1 | T22: 1 | U22: 1 | V22: 1 | W22: 1 | X22: 7 | Y22: 9 | Z22: 2 | AA22: 5 | AB22: 3 | AC22: 5 | AD22: 0
A23: 8 | B23: 4 | C23: 11 | D23: 11 | E23: 11 | F23: 11 | G23: 3 | H23: 4 | I23: 1 | J23: 10 | K23: 6 | L23: 10 | M23: 6 | N23: 6 | O23: 6 | P23: 8 | Q23: 0 | R23: 0 | S23: 1 | T23: 1 | U23: 1 | V23: 1 | W23: 1 | X23: 7 | Y23: 10 | Z23: 4 | AA23: 6 | AB23: 4 | AC23: 10 | AD23: 0
A24: 9 | B24: 5 | C24: 11 | D24: 11 | E24: 11 | F24: 11 | G24: 6 | H24: 6 | I24: 1 | J24: 11 | K24: 7 | L24: 11 | M24: 7 | N24: 7 | O24: 7 | P24: 10 | Q24: 3 | R24: 0 | S24: 1 | T24: 1 | U24: 1 | V24: 1 | W24: 1 | X24: 7 | Y24: 10 | Z24: 4 | AA24: 7 | AB24: 4 | AC24: 30 | AD24: 40
A25: 10 | B25: 5 | C25: 11 | D25: 11 | E25: 11 | F25: 11 | G25: 6 | H25: 6 | I25: 1 | J25: 11 | K25: 7 | L25: 11 | M25: 8 | N25: 7 | O25: 7 | P25: 10 | Q25: 4 | R25: 2 | S25: 1 | T25: 1 | U25: 1 | V25: 1 | W25: 1 | X25: 7 | Y25: 10 | Z25: 4 | AA25: 8 | AB25: 4 | AC25: 40 | AD25: 40
A27: 单建筑升级时间
A28: 大本营 | B28: 部落城堡 | C28: 金矿 | D28: 圣水收集器 | E28: 储金罐 | F28: 圣水瓶 | G28: 暗黑石油钻井 | H28: 暗黑石油罐 | I28: 工房 | J28: 加农炮 | K28: 迫击炮 | L28: 弓箭塔 | M28: 防空火箭 | N28: 法师塔 | O28: 电磁塔 | P28: 城墙 | Q28: X弩 | R28: 地狱之塔 | S28: 隐身炸弹 | T28: 隐身弹簧 | U28: 巨型炸弹 | V28: 空中炸弹 | W28: 追踪式空中炸弹 | X28: 营地 | Y28: 训练营 | Z28: 黑暗训练营 | AA28: 试验室 | AB28: 法术工厂 | AC28: 野蛮人之王 | AD28: 弓箭女王 | AE28: 野蛮人科技 | AF28: 弓箭手科技 | AG28: 哥布林科技 | AH28: 巨人科技 | AI28: 炸弹人科技 | AJ28: 气球兵科技 | AK28: 巫师科技 | AL28: 天使科技 | AM28: 飞龙科技 | AN28: 魔王科技 | AO28: 闪电咒语科技 | AP28: 治疗咒语科技 | AQ28: 狂暴咒语科技 | AR28: 跳跃咒语科技 | AS28: 小飞龙科技 | AT28: 野猪骑士科技 | AU28: 瓦尔基里科技 | AV28: 石头人科技
A29: 0 | B29: 0 | C29: =[1]建筑配置!C17+[1]建筑配置!D17 -> 0.0041666667 | D29: =[1]建筑配置!C26+[1]建筑配置!D26 -> 0.0041666667 | E29: =[1]建筑配置!C35 -> 0.010416667 | F29: =[1]建筑配置!C43 -> 0.010416667 | G29: =IF(G16=0,0,"") -> 0 | H29: =IF(H16=0,0,"") -> 0 | I29: 0 | J29: =[1]建筑配置!C68+[1]建筑配置!D68 -> 0.011111111 | K29: =IF(K16=0,0,"") -> 0 | L29: =IF(L16=0,0,"") -> 0 | M29: =IF(M16=0,0,"") -> 0 | N29: =IF(N16=0,0,"") -> 0 | O29: =IF(O16=0,0,"") -> 0 | P29: =IF(P16=0,0,"") -> 0 | Q29: =IF(Q16=0,0,"") -> 0 | R29: =IF(R16=0,0,"") -> 0 | ... W29: =IF(W16=0,0,"") -> 0 | X29: =[1]建筑配置!C140 -> 0.0034722222 | Y29: =[1]建筑配置!C148+[1]建筑配置!D148+[1]建筑配置!E148 -> 0.094444444 | Z29: =IF(Z16=0,0,"") -> 0 | AA29: =IF(AA16=0,0,"") -> 0 | AB29: =IF(AB16=0,0,"") -> 0 | AC29: =IF(AC16=0,0,"") -> 0 | AD29: =IF(AD16=0,0,"") -> 0 | AE29: =IF(AE16=0,0,"") -> 0 | AF29: =IF(AF16=0,0,"") -> 0 | AG29: =IF(AG16=0,0,"") -> 0 | ... AV29: =IF(AV16=0,0,"") -> 0
A30: =[1]建筑配置!D3 -> 0.0034722222 | B30: 0 | C30: =[1]建筑配置!E17+[1]建筑配置!F17 -> 0.052083333 | D30: =[1]建筑配置!E26+[1]建筑配置!F26 -> 0.052083333 | E30: =[1]建筑配置!D35+[1]建筑配置!E35 -> 0.0625 | F30: =[1]建筑配置!D43+[1]建筑配置!E43 -> 0.0625 | G30: =IF(G17=G16,0,"") -> 0 | H30: =IF(H17=H16,0,"") -> 0 | I30: =IF(I17=I16,0,"") -> 0 | J30: =[1]建筑配置!E68 -> 0.03125 | K30: =IF(K17=K16,0,"") -> 0 | L30: =[1]建筑配置!C84+[1]建筑配置!D84 -> 0.03125 | M30: =IF(M17=M16,0,"") -> 0 | N30: =IF(N17=N16,0,"") -> 0 | O30: =IF(O17=O16,0,"") -> 0 | P30: 0 | Q30: =IF(Q17=Q16,0,"") -> 0 | R30: =IF(R17=R16,0,"") -> 0 | S30: 0 | T30: =IF(T17=T16,0,"") -> 0 | U30: =IF(U17=U16,0,"") -> 0 | V30: =IF(V17=V16,0,"") -> 0 | W30: =IF(W17=W16,0,"") -> 0 | X30: =[1]建筑配置!D140 -> 0.041666667 | Y30: =[1]建筑配置!F148 -> 0.16666667 | Z30: =IF(Z17=Z16,0,"") -> 0 | AA30: =IF(AA17=AA16,0,"") -> 0 | AB30: =IF(AB17=AB16,0,"") -> 0 | AC30: =IF(AC17=AC16,0,"") -> 0 | AD30: =IF(AD17=AD16,0,"") -> 0 | AE30: =IF(AE17=AE16,0,"") -> 0 | AF30: =IF(AF17=AF16,0,"") -> 0 | AG30: =IF(AG17=AG16,0,"") -> 0 | ... AV30: =IF(AV17=AV16,0,"") -> 0
A31: =[1]建筑配置!E3 -> 0.125 | B31: =[1]建筑配置!C10 -> 0 | C31: =[1]建筑配置!G17+[1]建筑配置!H17 -> 0.33333333 | D31: =[1]建筑配置!G26+[1]建筑配置!H26 -> 0.33333333 | E31: =[1]建筑配置!F26+[1]建筑配置!G26+[1]建筑配置!H26 -> 0.375 | F31: =[1]建筑配置!F43+[1]建筑配置!G43+[1]建筑配置!H43 -> 0.375 | G31: =IF(G18=G17,0,"") -> 0 | H31: =IF(H18=H17,0,"") -> 0 | I31: =IF(I18=I17,0,"") -> 0 | J31: =[1]建筑配置!F68 -> 0.083333333 | K31: =[1]建筑配置!C76 -> 0.33333333 | L31: =[1]建筑配置!E84 -> 0.03125 | M31: =IF(M18=M17,0,"") -> 0 | N31: =IF(N18=N17,0,"") -> 0 | O31: =IF(O18=O17,0,"") -> 0 | P31: 0 | Q31: =IF(Q18=Q17,0,"") -> 0 | R31: =IF(R18=R17,0,"") -> 0 | S31: =IF(S18=S17,0,"") -> 0 | T31: =IF(T18=T17,0,"") -> 0 | U31: =IF(U18=U17,0,"") -> 0 | V31: =IF(V18=V17,0,"") -> 0 | W31: =IF(W18=W17,0,"") -> 0 | X31: =[1]建筑配置!E140 -> 0.125 | Y31: =[1]建筑配置!G148 -> 0.41666667 | Z31: =IF(Z18=Z17,0,"") -> 0 | AA31: =[1]建筑配置!C164 -> 0.020833333 | AB31: =IF(AB18=AB17,0,"") -> 0 | AC31: =IF(AC18=AC17,0,"") -> 0 | AD31: =IF(AD18=AD17,0,"") -> 0 | AE31: =[1]建筑配置!C169 -> 0.25 | AF31: =[1]建筑配置!C172 -> 0.5 | AG31: =[1]建筑配置!C175 -> 0.5 | AH31: 0 | AI31: 0 | AJ31: 0 | AK31: 0 | AL31: 0 | AM31: 0 | AN31: 0 | AO31: =[1]建筑配置!C199 -> 1 | AP31: 0 | AQ31: 0 | AR31: 0 | AS31: 0 | AT31: 0 | AU31: 0 | AV31: 0
A32: =[1]建筑配置!F3 -> 1 | B32: =[1]建筑配置!D17 -> 0.0034722222 | C32: =[1]建筑配置!I17+[1]建筑配置!J17 -> 1.5 | D32: =[1]建筑配置!I26+[1]建筑配置!J26 -> 1.5 | E32: =[1]建筑配置!I35+[1]建筑配置!J35 -> 0.58333333 | F32: =[1]建筑配置!I43+[1]建筑配置!J43 -> 0.58333333 | G32: =IF(G19=G18,0,"") -> 0 | H32: =IF(H19=H18,0,"") -> 0 | I32: =IF(I19=I18,0,"") -> 0 | J32: =[1]建筑配置!G68 -> 0.25 | K32: =[1]建筑配置!D76 -> 0.5 | L32: =[1]建筑配置!F84 -> 0.16666667 | M32: =[1]建筑配置!C92+[1]建筑配置!D92 -> 1.2083333 | N32: =IF(N19=N18,0,"") -> 0 | O32: =IF(O19=O18,0,"") -> 0 | P32: 0 | Q32: =IF(Q19=Q18,0,"") -> 0 | R32: =IF(R19=R18,0,"") -> 0 | S32: =IF(S19=S18,0,"") -> 0 | T32: 0 | U32: =IF(U19=U18,0,"") -> 0 | V32: =IF(V19=V18,0,"") -> 0 | W32: =IF(W19=W18,0,"") -> 0 | X32: =[1]建筑配置!F140 -> 0.33333333 | Y32: =[1]建筑配置!H148 -> 0.66666667 | Z32: =IF(Z19=Z18,0,"") -> 0 | AA32: =[1]建筑配置!D164 -> 0.20833333 | AB32: =IF(AB19=AB18,0,"") -> 0 | AC32: =IF(AC19=AC18,0,"") -> 0 | AD32: =IF(AD19=AD18,0,"") -> 0 | AE32: 0 | AF32: 0 | AG32: 0 | AH32: =[1]建筑配置!D178 -> 1 | AI32: =[1]建筑配置!D181 -> 1 | AJ32: =[1]建筑配置!D184 -> 1 | AK32: 0 | AL32: 0 | AM32: 0 | AN32: 0 | AO32: =[1]建筑配置!D199 -> 2 | AP32: =[1]建筑配置!D202 -> 1 | AQ32: 0 | AR32: 0 | AS32: 0 | AT32: 0 | AU32: 0 | AV32: 0
A33: =[1]建筑配置!G3 -> 2 | B33: 0 | C33: =[1]建筑配置!K17+[1]建筑配置!L17 -> 5 | D33: =[1]建筑配置!K26+[1]建筑配置!L26 -> 5 | E33: =[1]建筑配置!K35 -> 0.5 | F33: =[1]建筑配置!K43 -> 0.5 | G33: =IF(G20=G19,0,"") -> 0 | H33: =IF(H20=H19,0,"") -> 0 | I33: =IF(I20=I19,0,"") -> 0 | J33: =[1]建筑配置!H68 -> 0.5 | K33: =[1]建筑配置!E76 -> 1 | L33: =[1]建筑配置!G84+[1]建筑配置!H84 -> 1.5 | M33: =[1]建筑配置!E92 -> 3 | N33: =[1]建筑配置!C100+[1]建筑配置!D100 -> 1.5 | O33: =IF(O20=O19,0,"") -> 0 | P33: 0 | Q33: =IF(Q20=Q19,0,"") -> 0 | R33: =IF(R20=R19,0,"") -> 0 | S33: =IF(S20=S19,0,"") -> 0 | T33: =IF(T20=T19,0,"") -> 0 | U33: =IF(U20=U19,0,"") -> 0 | V33: 0 | W33: =IF(W20=W19,0,"") -> 0 | X33: =[1]建筑配置!G140 -> 1 | Y33: =[1]建筑配置!I148 -> 1 | Z33: =IF(Z20=Z19,0,"") -> 0 | AA33: =[1]建筑配置!E164 -> 0.5 | AB33: =[1]建筑配置!C225 -> 1 | AC33: =IF(AC20=AC19,0,"") -> 0 | AD33: =IF(AD20=AD19,0,"") -> 0 | AE33: =[1]建筑配置!E169 -> 1 | AF33: =[1]建筑配置!E172 -> 2 | AG33: =[1]建筑配置!E175 -> 2 | AH33: 0 | AI33: 0 | AJ33: 0 | AK33: =[1]建筑配置!E187 -> 1 | AL33: 0 | AM33: 0 | AN33: 0 | AO33: =[1]建筑配置!E199 -> 3 | AP33: 0 | AQ33: =[1]建筑配置!E205 -> 2 | AR33: 0 | AS33: 0 | AT33: 0 | AU33: 0 | AV33: 0
A34: =[1]建筑配置!H3 -> 4 | B34: =[1]建筑配置!E10 -> 1 | C34: =[1]建筑配置!M17 -> 4 | D34: =[1]建筑配置!M26 -> 4 | E34: =[1]建筑配置!L35 -> 1 | F34: =[1]建筑配置!L43 -> 1 | G34: =IF(G21=G20,0,"") -> 0 | H34: =IF(H21=H20,0,"") -> 0 | I34: =IF(I21=I20,0,"") -> 0 | J34: =[1]建筑配置!I68 -> 1 | K34: =[1]建筑配置!F76 -> 2 | L34: =[1]建筑配置!I84 -> 3 | M34: =[1]建筑配置!F92 -> 5 | N34: =[1]建筑配置!E100 -> 2 | O34: =IF(O21=O20,0,"") -> 0 | P34: 0 | Q34: =IF(Q21=Q20,0,"") -> 0 | R34: =IF(R21=R20,0,"") -> 0 | S34: =IF(S21=S20,0,"") -> 0 | T34: =IF(T21=T20,0,"") -> 0 | U34: 0 | V34: =IF(V21=V20,0,"") -> 0 | W34: =IF(W21=W20,0,"") -> 0 | X34: =[1]建筑配置!H140 -> 3 | Y34: =[1]建筑配置!J148 -> 2 | Z34: =IF(Z21=Z20,0,"") -> 0 | AA34: =[1]建筑配置!F164 -> 1 | AB34: =[1]建筑配置!D225 -> 2 | AC34: =IF(AC21=AC20,0,"") -> 0 | AD34: =IF(AD21=AD20,0,"") -> 0 | AE34: 0 | AF34: 0 | AG34: 0 | AH34: =[1]建筑配置!F178 -> 2 | AI34: =[1]建筑配置!F181 -> 2 | AJ34: =[1]建筑配置!F184 -> 2 | AK34: =[1]建筑配置!F187 -> 2 | AL34: 0 | AM34: 0 | AN34: 0 | AO34: 0 | AP34: =[1]建筑配置!F202 -> 2 | AQ34: =[1]建筑配置!F205 -> 3 | AR34: 0 | AS34: 0 | AT34: 0 | AU34: 0 | AV34: 0
A35: =[1]建筑配置!I3 -> 6 | B35: 0 | C35: 0 | D35: 0 | E35: =[1]建筑配置!M35 -> 2 | F35: =[1]建筑配置!M43 -> 2 | G35: =IF(G22=G21,0,"") -> 0 | H35: =[1]建筑配置!C60+[1]建筑配置!D60 -> 3 | I35: =IF(I22=I21,0,"") -> 0 | J35: =[1]建筑配置!J68 -> 2 | K35: =[1]建筑配置!G76 -> 4 | L35: =[1]建筑配置!J84 -> 4 | M35: =[1]建筑配置!G92 -> 6 | N35: =[1]建筑配置!F100 -> 4 | O35: =[1]建筑配置!C108+[1]建筑配置!D108+[1]建筑配置!E108 -> 12 | P35: 0 | Q35: =IF(Q22=Q21,0,"") -> 0 | R35: =IF(R22=R21,0,"") -> 0 | S35: =IF(S22=S21,0,"") -> 0 | T35: =IF(T22=T21,0,"") -> 0 | U35: =IF(U22=U21,0,"") -> 0 | V35: =IF(V22=V21,0,"") -> 0 | W35: 0 | X35: =[1]建筑配置!I140 -> 5 | Y35: =[1]建筑配置!K148 -> 4 | Z35: =[1]建筑配置!C156+[1]建筑配置!D156 -> 8 | AA35: =[1]建筑配置!G164 -> 2 | AB35: =[1]建筑配置!E225 -> 4 | AC35: =[1]建筑配置!C233+[1]建筑配置!D233+[1]建筑配置!E233+[1]建筑配置!F233+[1]建筑配置!G233 -> 5 | AD35: =IF(AD22=AD21,0,"") -> 0 | AE35: =[1]建筑配置!G169 -> 3 | AF35: =[1]建筑配置!G172 -> 3 | AG35: =[1]建筑配置!G175 -> 3 | AH35: =[1]建筑配置!G178 -> 3 | AI35: =[1]建筑配置!G181 -> 3 | AJ35: =[1]建筑配置!G184 -> 3 | AK35: =[1]建筑配置!G187 -> 3 | AL35: =[1]建筑配置!G190 -> 3 | AM35: =[1]建筑配置!G193 -> 7 | AN35: 0 | AO35: 0 | AP35: =[1]建筑配置!G202 -> 3 | AQ35: =[1]建筑配置!G205 -> 5 | AR35: 0 | AS35: =[1]建筑配置!G211 -> 5 | AT35: =[1]建筑配置!G214 -> 8 | AU35: 0 | AV35: 0
A36: =[1]建筑配置!J3 -> 8 | B36: =[1]建筑配置!F10 -> 2 | C36: 0 | D36: 0 | E36: =IF(E23=E22,0,"") -> 0 | F36: =IF(F23=F22,0,"") -> 0 | G36: =[1]建筑配置!C51+[1]建筑配置!D51+[1]建筑配置!E51 -> 6 | H36: =[1]建筑配置!E60+[1]建筑配置!F60 -> 7 | I36: =IF(I23=I22,0,"") -> 0 | J36: =[1]建筑配置!K68+[1]建筑配置!L68 -> 7 | K36: =[1]建筑配置!H76 -> 5 | L36: =[1]建筑配置!K84+[1]建筑配置!L84 -> 11 | M36: =[1]建筑配置!H92 -> 8 | N36: =[1]建筑配置!G100+[1]建筑配置!H100 -> 14 | O36: =[1]建筑配置!F108+[1]建筑配置!G108+[1]建筑配置!H108 -> 30 | P36: 0 | Q36: =IF(Q23=Q22,0,"") -> 0 | R36: =IF(R23=R22,0,"") -> 0 | S36: =IF(S23=S22,0,"") -> 0 | T36: =IF(T23=T22,0,"") -> 0 | U36: =IF(U23=U22,0,"") -> 0 | V36: =IF(V23=V22,0,"") -> 0 | W36: =IF(W23=W22,0,"") -> 0 | X36: =IF(X23=X22,0,"") -> 0 | Y36: =[1]建筑配置!L148 -> 6 | Z36: =[1]建筑配置!E156+[1]建筑配置!F156 -> 13 | AA36: =[1]建筑配置!H164 -> 4 | AB36: =[1]建筑配置!F225 -> 5 | AC36: =[1]建筑配置!H233+[1]建筑配置!I233+[1]建筑配置!K233+[1]建筑配置!J233+[1]建筑配置!L233 -> 17.5 | AD36: =IF(AD23=AD22,0,"") -> 0 | AE36: =[1]建筑配置!H169 -> 5 | AF36: =[1]建筑配置!H172 -> 5 | AG36: =[1]建筑配置!H175 -> 5 | AH36: =[1]建筑配置!H178 -> 5 | AI36: =[1]建筑配置!H181 -> 5 | AJ36: =[1]建筑配置!H184 -> 5 | AK36: =[1]建筑配置!H187 -> 5 | AL36: =[1]建筑配置!H190 -> 5 | AM36: =[1]建筑配置!H193 -> 10 | AN36: =[1]建筑配置!H196+[1]建筑配置!I196 -> 22 | AO36: =[1]建筑配置!H199 -> 4 | AP36: =[1]建筑配置!H202 -> 5 | AQ36: =[1]建筑配置!H205 -> 7 | AR36: 0 | AS36: =[1]建筑配置!H211+[1]建筑配置!I211 -> 13 | AT36: =[1]建筑配置!H214+[1]建筑配置!I214 -> 22 | AU36: =[1]建筑配置!H217 -> 10 | AV36: =[1]建筑配置!H220 -> 10
A37: =[1]建筑配置!K3 -> 10 | B37: =[1]建筑配置!G10 -> 7 | C37: 0 | D37: 0 | E37: =IF(E24=E23,0,"") -> 0 | F37: =IF(F24=F23,0,"") -> 0 | G37: =[1]建筑配置!F51+[1]建筑配置!G51+[1]建筑配置!H51 -> 18 | H37: =[1]建筑配置!G60+[1]建筑配置!H60 -> 11 | I37: =IF(I24=I23,0,"") -> 0 | J37: =[1]建筑配置!M68 -> 5 | K37: =[1]建筑配置!I76 -> 7 | L37: =[1]建筑配置!M84 -> 7 | M37: =[1]建筑配置!I92 -> 10 | N37: =[1]建筑配置!I100 -> 10 | O37: =[1]建筑配置!I108 -> 14 | P37: 0 | Q37: =[1]建筑配置!C122+[1]建筑配置!D122+[1]建筑配置!E122 -> 31 | R37: =IF(R24=R23,0,"") -> 0 | S37: =IF(S24=S23,0,"") -> 0 | T37: =IF(T24=T23,0,"") -> 0 | U37: =IF(U24=U23,0,"") -> 0 | V37: =IF(V24=V23,0,"") -> 0 | W37: =IF(W24=W23,0,"") -> 0 | X37: =IF(X24=X23,0,"") -> 0 | Y37: =IF(Y24=Y23,0,"") -> 0 | Z37: =IF(Z24=Z23,0,"") -> 0 | AA37: =[1]建筑配置!J164 -> 5 | AB37: =IF(AB24=AB23,0,"") -> 0 | AC37: =SUM([1]建筑配置!M233:AF233) -> 135 | AD37: =SUM([1]建筑配置!C241:AP241) -> 227.5 | AE37: =[1]建筑配置!J169 -> 10 | AF37: =[1]建筑配置!J172 -> 14 | AG37: 0 | AH37: =[1]建筑配置!J178 -> 10 | AI37: 0 | AJ37: =[1]建筑配置!J184 -> 10 | AK37: 0 | AL37: =[1]建筑配置!J190 -> 7 | AM37: 0 | AN37: 0 | AO37: 0 | AP37: 0 | AQ37: 0 | AR37: =[1]建筑配置!J208 -> 5 | AS37: =[1]建筑配置!J211 -> 10 | AT37: =[1]建筑配置!J214 -> 14 | AU37: =[1]建筑配置!J217+[1]建筑配置!K217 -> 26 | AV37: =[1]建筑配置!J220+[1]建筑配置!K220 -> 26
A38: =[1]建筑配置!L3 -> 14 | B38: 0 | C38: 0 | D38: 0 | E38: =IF(E25=E24,0,"") -> 0 | F38: =IF(F25=F24,0,"") -> 0 | G38: =IF(G25=G24,0,"") -> 0 | H38: =IF(H25=H24,0,"") -> 0 | I38: =IF(I25=I24,0,"") -> 0 | J38: =IF(J25=J24,0,"") -> 0 | K38: =IF(K25=K24,0,"") -> 0 | L38: =IF(L25=L24,0,"") -> 0 | M38: =[1]建筑配置!J92 -> 12 | N38: =IF(N25=N24,0,"") -> 0 | O38: =IF(O25=O24,0,"") -> 0 | P38: =IF(P25=P24,0,"") -> 0 | Q38: =[1]建筑配置!F122 -> 14 | R38: =[1]建筑配置!C130+[1]建筑配置!D130 -> 17 | S38: =IF(S25=S24,0,"") -> 0 | T38: =IF(T25=T24,0,"") -> 0 | U38: =IF(U25=U24,0,"") -> 0 | V38: =IF(V25=V24,0,"") -> 0 | W38: =IF(W25=W24,0,"") -> 0 | X38: =IF(X25=X24,0,"") -> 0 | Y38: =IF(Y25=Y24,0,"") -> 0 | Z38: =IF(Z25=Z24,0,"") -> 0 | AA38: =[1]建筑配置!L164 -> 6 | AB38: =IF(AB25=AB24,0,"") -> 0 | AC38: =SUM([1]建筑配置!AG233:AP233) -> 70 | AD38: =IF(AD25=AD24,0,"") -> 0 | AE38: 0 | AF38: 0 | AG38: 0 | AH38: 0 | AI38: 0 | AJ38: 0 | AK38: 0 | AL38: 0 | AM38: =[1]建筑配置!L193 -> 12 | AN38: 0 | AO38: 0 | AP38: 0 | AQ38: 0 | AR38: 0 | AS38: 0 | AT38: 0 | AU38: 0 | AV38: =[1]建筑配置!L220 -> 14
A40: 升级总时间 | AW40: 建筑时间 | BC40: 科技时间 | BF40: 英雄时间
A41: 大本营 | B41: 部落城堡 | C41: 金矿 | D41: 圣水收集器 | E41: 储金罐 | F41: 圣水瓶 | G41: 暗黑石油钻井 | H41: 暗黑石油罐 | I41: 工房 | J41: 加农炮 | K41: 迫击炮 | L41: 弓箭塔 | M41: 防空火箭 | N41: 法师塔 | O41: 电磁塔 | P41: 城墙 | Q41: X弩 | R41: 地狱之塔 | S41: 隐身炸弹 | T41: 隐身弹簧 | U41: 巨型炸弹 | V41: 空中炸弹 | W41: 追踪式空中炸弹 | X41: 营地 | Y41: 训练营 | Z41: 黑暗训练营 | AA41: 试验室 | AB41: 法术工厂 | AC41: 野蛮人之王 | AD41: 弓箭女王 | AE41: 野蛮人科技 | AF41: 弓箭手科技 | AG41: 哥布林科技 | AH41: 巨人科技 | AI41: 炸弹人科技 | AJ41: 气球兵科技 | AK41: 巫师科技 | AL41: 天使科技 | AM41: 飞龙科技 | AN41: 魔王科技 | AO41: 闪电咒语科技 | AP41: 治疗咒语科技 | AQ41: 狂暴咒语科技 | AR41: 跳跃咒语科技 | AS41: 小飞龙科技 | AT41: 野猪骑士科技 | AU41: 瓦尔基里科技 | AV41: 石头人科技 | AW41: 金币 | AX41: 圣水 | AY41: 建筑时间（2排程） | AZ41: 建筑时间（3排程） | BA41: 建筑时间（4排程） | BB41: 建筑时间（5排程） | BC41: 圣水 | BD41: 黑水 | BE41: 科技时间 | BF41: 黑水
A42: =A29 -> 0 | B42: =B3*B29 -> 0 | C42: =C3*C29 -> 0.0041666667 | D42: =D3*D29 -> 0.0041666667 | E42: =E3*E29 -> 0.010416667 | F42: =F3*F29 -> 0.010416667 | G42: =G3*G29 -> 0 | H42: =H3*H29 -> 0 | I42: =I3*I29 -> 0 | ... AV42: =AV3*AV29 -> 0 | AW42: =SUMPRODUCT(((A$52:AV$52)="金币")*(A42:AV42)) -> 0.036805556 | AX42: =SUMPRODUCT(((A$52:AV$52)="圣水")*(A42:AV42)) -> 0.1125 | AY42: =SUM(AW42:AX42)/2 -> 0.074652778 | AZ42: =SUM(AW42:AX42)/3 -> 0.049768519 | BA42: =SUM(AW42:AX42)/4 -> 0.037326389 | BB42: =SUM(AW42:AX42)/5 -> 0.029861111 | BC42: =SUMPRODUCT(((A$52:AV$52)="圣水科技")*(A42:AV42)) -> 0 | BD42: =SUMPRODUCT(((A$52:AV$52)="黑水科技")*(A42:AV42)) -> 0 | BE42: =BC42+BD42 -> 0 | BF42: =SUMPRODUCT(((A$52:AV$52)="黑水英雄")*(A42:AV42)) -> 0
A43: =A30 -> 0.0034722222 | B43: =B3*B30+(B4-B3)*SUM(B29:B30) -> 0 | C43: =C3*C30+(C4-C3)*SUM(C29:C30) -> 0.10833333 | D43: =D3*D30+(D4-D3)*SUM(D29:D30) -> 0.10833333 | E43: =E3*E30+(E4-E3)*SUM(E29:E30) -> 0.0625 | F43: =F3*F30+(F4-F3)*SUM(F29:F30) -> 0.0625 | G43: =G3*G30+(G4-G3)*SUM(G29:G30) -> 0 | H43: =H3*H30+(H4-H3)*SUM(H29:H30) -> 0 | I43: =I3*I30+(I4-I3)*SUM(I29:I30) -> 0 | ... AD43: =AD3*AD30+(AD4-AD3)*SUM(AD29:AD30) -> 0 | AE43: =AE30 -> 0 | AF43: =AF30 -> 0 | AG43: =AG30 -> 0 | AH43: =AH30 -> 0 | AI43: =AI30 -> 0 | AJ43: =AJ30 -> 0 | AK43: =AK30 -> 0 | AL43: =AL30 -> 0 | ... AV43: =AV30 -> 0 | AW43: =SUMPRODUCT(((A$52:AV$52)="金币")*(A43:AV43)) -> 0.26805556 | AX43: =SUMPRODUCT(((A$52:AV$52)="圣水")*(A43:AV43)) -> 0.64027778 | AY43: =AY42+SUM(AW43:AX43)/2 -> 0.52881944 | AZ43: =AZ42+SUM(AW43:AX43)/3 -> 0.3525463 | BA43: =BA42+SUM(AW43:AX43)/4 -> 0.26440972 | BB43: =BB42+SUM(AW43:AX43)/5 -> 0.21152778 | BC43: =SUMPRODUCT(((A$52:AV$52)="圣水科技")*(A43:AV43)) -> 0 | BD43: =SUMPRODUCT(((A$52:AV$52)="黑水科技")*(A43:AV43)) -> 0 | BE43: =BE42+BD43+BC43 -> 0 | BF43: =SUMPRODUCT(((A$52:AV$52)="黑水英雄")*(A43:AV43))+BF42 -> 0
...
