Workbook

Sheet 角色战力
A1: lv | B1: might | E1: 建筑战力 | F1: 基础值 | G1: 系数 | H1: 等级 | I1: 战力 | J1: 数量 | K1: 建筑总战力 | O1: city | P1: resouce | Q1: waterdragon
A2: 1 | B2: 0 | E2: Home | F2: 10 | G2: 2 | H2: 20 | I2: =F2*(2^(H2/G2-1)) -> 5120 | J2: 6 | K2: =I2*J2 -> 30720 | N2: 地块数量 | O2: 30 | P2: 38 | Q2: 13
A3: 2 | B3: 76 | C3: =B4/B3 -> 1.5263158 | E3: Garrison | F3: 10 | G3: 2 | H3: 20 | I3: =F3*(2^(H3/G3-1)) -> 5120 | J3: 12 | K3: =I3*J3 -> 61440
A4: 3 | B4: 116 | C4: =B5/B4 -> 1.6896552 | E4: Metalsmith | F4: 20 | G4: 2 | H4: 20 | I4: =F4*(2^(H4/G4-1)) -> 10240 | J4: 1 | K4: =I4*J4 -> 10240
A5: 4 | B5: 196 | C5: =B6/B5 -> 1.8163265 | E5: Rookery | F5: 20 | G5: 2 | H5: 20 | I5: =F5*(2^(H5/G5-1)) -> 10240 | J5: 1 | K5: =I5*J5 -> 10240
A6: 5 | B6: 356 | C6: =B7/B6 -> 1.8988764 | E6: Theater | F6: 30 | G6: 2 | H6: 20 | I6: =F6*(2^(H6/G6-1)) -> 15360 | J6: 1 | K6: =I6*J6 -> 15360
A7: 6 | B7: 676 | C7: =B8/B7 -> 1.9467456 | E7: Sentinel | F7: 20 | G7: 2 | H7: 20 | I7: =F7*(2^(H7/G7-1)) -> 10240 | J7: 1 | K7: =I7*J7 -> 10240
A8: 7 | B8: 1316 | C8: =B9/B8 -> 1.9726444 | E8: Factory | F8: 20 | G8: 2 | H8: 20 | I8: =F8*(2^(H8/G8-1)) -> 10240 | J8: 1 | K8: =I8*J8 -> 10240
A9: 8 | B9: 2596 | C9: =B10/B9 -> 1.9861325 | E9: DragonKeep | F9: 50 | G9: 2 | H9: 20 | I9: =F9*(2^(H9/G9-1)) -> 25600 | J9: 1 | K9: =I9*J9 -> 25600
A10: 9 | B10: 5156 | C10: =B11/B10 -> 1.9930178 | E10: Fortress | F10: 50 | G10: 2 | H10: 20 | I10: =F10*(2^(H10/G10-1)) -> 25600 | J10: 1 | K10: =I10*J10 -> 25600
A11: 10 | B11: 10276 | C11: =B12/B11 -> 1.6228104 | E11: OfficerQuarter | F11: 30 | G11: 2 | H11: 20 | I11: =F11*(2^(H11/G11-1)) -> 15360 | J11: 1 | K11: =I11*J11 -> 15360
A12: 11 | B12: 16676 | C12: =B13/B12 -> 1.4797314 | E12: MusterPoint | F12: 30 | G12: 2 | H12: 20 | I12: =F12*(2^(H12/G12-1)) -> 15360 | J12: 1 | K12: =I12*J12 -> 15360
A13: 12 | B13: 24676 | C13: =B14/B13 -> 1.4052521 | E13: ScienceCenter | F13: 30 | G13: 2 | H13: 20 | I13: =F13*(2^(H13/G13-1)) -> 15360 | J13: 1 | K13: =I13*J13 -> 15360
A14: 13 | B14: 34676 | C14: =B15/B14 -> 1.3604799 | E14: StorageVault | F14: 20 | G14: 2 | H14: 20 | I14: =F14*(2^(H14/G14-1)) -> 10240 | J14: 1 | K14: =I14*J14 -> 10240
... A20: 19 | B20: 175355 | C20: =B21/B20 -> 1.2719284 | E20: newbuilding | F20: 10 | G20: 1 | H20: 10 | I20: =F20*(2^(H20/G20-1)) -> 5120 | J20: 4 | K20: =I20*J20 -> 20480
A21: 20 | B21: 223039 | C21: =B22/B21 -> 1.2672358 | E21: waterdragonkeep | F21: 50 | G21: 2 | H21: 20 | I21: =F21*(2^(H21/G21-1)) -> 25600 | J21: total | K21: =SUM(K2:K20) -> 399360
A22: 21 | B22: 282643 | C22: =B23/B22 -> 1.2636046
A23: 22 | B23: 357149 | C23: =B24/B23 -> 1.2607651
A24: 23 | B24: 450281 | C24: =B25/B24 -> 1.2585408 | E24: TrainingCamp | F24: 15 | G24: 2 | H24: 20 | I24: =F24*(2^(H24/G24-1)) -> 7680
A25: 24 | B25: 566697 | C25: =B26/B25 -> 1.2567845 | E25: Silo | F25: 20 | G25: 2 | H25: 20 | I25: =F25*(2^(H25/G25-1)) -> 10240
A26: 25 | B26: 712216 | C26: =B27/B26 -> 1.2553986
A27: 26 | B27: 894115 | C27: =B28/B27 -> 1.2542995
A28: 27 | B28: 1121488 | C28: =B29/B28 -> 1.2534285
A29: 28 | B29: 1405705 | C29: =B30/B29 -> 1.2527358
A30: 29 | B30: 1760977 | C30: =B31/B30 -> 1.2521833
A31: 30 | B31: 2205066 | C31: =B32/B31 -> 1.2517439
A32: 31 | B32: 2760178 | C32: =B33/B32 -> 1.2513928
A33: 32 | B33: 3454067 | C33: =B34/B33 -> 1.2511133
A34: 33 | B34: 4321429 | C34: =B35/B34 -> 1.2508897
A35: 34 | B35: 5405631 | C35: =B36/B35 -> 1.2507113
A36: 35 | B36: 6760884 | C36: =B37/B36 -> 1.2505686
A37: 36 | B37: 8454949 | C37: =B38/B37 -> 1.2504549
... A51: 50 | B51: 192577614 | C51: =B52/B51 -> 0

Sheet 道具列表
A1: item Name | B1: Item Title | C1: Item Icon | D1: Item Type | E1: Category | F1: Rubies | G1: Enabled | H1: Buyable | I1: Usable | J1: Visible
A2: AtlagenHarvestNanosDay | B2: 1 Day Food Nanos | D2: Items::Types::ResourceBoost | E2: production | F2: 7 | G2: Yes | H2: Yes | I2: Yes | J2: Yes
A3: AtlagenHarvestNanosWeek | B3: 1 Week Food Nanos | D3: Items::Types::ResourceBoost | E3: production | F3: 40 | G3: Yes | H3: Yes | I3: Yes | J3: Yes
A4: BeginnerChestOne | B4: Beginner's Chest | D4: Items::Types::Chest | F4: 20 | G4: Yes | H4: No | I4: Yes | J4: No
A5: BeginnerOfferChest | B5: translation missing: en.items.beginnerofferchest.name | D5: Items::Types::Chest | F5: 1000 | G5: Yes | H5: No | I5: No | J5: No
A6: Blast | B6: 2.5 Day Speedup | D6: Items::Types::SpeedUp | E6: speedup | F6: 210 | G6: Yes | H6: Yes | I6: No | J6: Yes
A7: Blink | B7: 1 Minute Speedup | D7: Items::Types::SpeedUp | E7: speedup | F7: 1 | G7: Yes | H7: Yes | I7: No | J7: Yes
A8: Blitz | B8: 4 Day Speedup | D8: Items::Types::SpeedUp | E8: speedup | F8: 275 | G8: Yes | H8: Yes | I8: No | J8: Yes
A9: Bolt | B9: 24-Hour Speedup | D9: Items::Types::SpeedUp | E9: speedup | F9: 95 | G9: Yes | H9: Yes | I9: No | J9: Yes
A10: Bore | B10: 15-Hour Speedup | D10: Items::Types::SpeedUp | E10: speedup | F10: 65 | G10: Yes | H10: Yes | I10: No | J10: Yes
A11: Bounce | B11: 8-Hour Speedup | D11: Items::Types::SpeedUp | E11: speedup | F11: 40 | G11: Yes | H11: Yes | I11: No | J11: Yes
A12: BreatheFire | B12: Fire | D12: Items::Types::DoNothing | E12: dragon_actions | F12: 10 | G12: Yes | H12: Yes | I12: No | J12: Yes
A13: CeaseFireTreaty | B13: Ceasefire Treaty | D13: Items::Types::SafetyBoost | E13: general | F13: 25 | G13: Yes | H13: Yes | I13: Yes | J13: Yes
A14: ChartedWarpDevice | B14: Charted Warp Device | D14: Items::Types::WarpDevice | E14: general | F14: 75 | G14: Yes | H14: Yes | I14: No | J14: Yes
A15: CompletionGrant | B15: Completion Grant | D15: Items::Types::DoNothing | E15: general | F15: 40 | G15: Yes | H15: Yes | I15: No | J15: Yes
A16: CompletionGrantPortfolio | B16: Completion Portfolio | D16: Items::Types::Chest | E16: chest | F16: 155 | G16: Yes | H16: Yes | I16: Yes | J16: Yes
A17: CrimsonBull | B17: Crimson Bull | D17: Items::Types::ResourceBoost | F17: 10 | G17: Yes | H17: No | I17: No | J17: Yes
A18: DarkWarpDevice | B18: Dark Warp Device | D18: Items::Types::WarpDevice | E18: general | F18: 30 | G18: Yes | H18: Yes | I18: Yes | J18: Yes
A19: DoubleTaxDayDeclaration | B19: Double Tax Day Writ | D19: Items::Types::ResourceBoost | E19: production | F19: 10 | G19: Yes | H19: Yes | I19: Yes | J19: Yes
A20: DoubleTaxWeekDeclaration | B20: Double Tax Week Writ | D20: Items::Types::ResourceBoost | E20: production | F20: 40 | G20: Yes | H20: Yes | I20: Yes | J20: Yes
A21: DragonHearts | B21: Dragon Hearts | D21: Items::Types::ResourceBoost | E21: general | F21: 10 | G21: Yes | H21: Yes | I21: Yes | J21: Yes
A22: DragonRoar | B22: Roar | D22: Items::Types::DoNothing | E22: dragon_actions | F22: 10 | G22: Yes | H22: Yes | I22: No | J22: Yes
A23: DragonTransform | B23: Transform | D23: Items::Types::DragonTransform | F23: 10 | G23: Yes | H23: No | I23: No | J23: Yes
A24: DryadForestNanosDay | B24: 1 Day Wood Nanos | D24: Items::Types::ResourceBoost | E24: production | F24: 7 | G24: Yes | H24: Yes | I24: Yes | J24: Yes
A25: DryadForestNanosWeek | B25: 1 Week Wood Nanos | D25: Items::Types::ResourceBoost | E25: production | F25: 40 | G25: Yes | H25: Yes | I25: Yes | J25: Yes
A26: EpeoradMetalsNanosDay | B26: 1 Day Metals Nanos | D26: Items::Types::ResourceBoost | E26: production | F26: 7 | G26: Yes | H26: Yes | I26: Yes | J26: Yes
A27: EpeoradMetalsNanosWeek | B27: 1 Week Metals Nanos | D27: Items::Types::ResourceBoost | E27: production | F27: 40 | G27: Yes | H27: Yes | I27: Yes | J27: Yes
A28: Food250K | B28: 250,000 Food | D28: Items::Types::ResourceBundle | E28: resource | F28: 55 | G28: Yes | H28: Yes | I28: Yes | J28: Yes
A29: Food80K | B29: 80,000 Food | D29: Items::Types::ResourceBundle | E29: resource | F29: 20 | G29: Yes | H29: Yes | I29: Yes | J29: Yes
A30: ForcedMarchDrops | B30: Forced March Drops | D30: Items::Types::SpeedUp | E30: speedup | F30: 7 | G30: Yes | H30: Yes | I30: No | J30: Yes
A31: GeneralRename | B31: Identity Alternator | D31: Items::Types::IdentityAlternator | E31: general | F31: 10 | G31: Yes | H31: Yes | I31: No | J31: Yes
A32: GlowingShields | B32: Glowing Shields | D32: Items::Types::ResourceBoost | E32: general | F32: 10 | G32: Yes | H32: Yes | I32: Yes | J32: Yes
A33: Gold250K | B33: 250,000 Gold | D33: Items::Types::ResourceBundle | E33: resource | F33: 55 | G33: Yes | H33: Yes | I33: Yes | J33: Yes
A34: Gold80K | B34: 80,000 Gold | D34: Items::Types::ResourceBundle | E34: resource | F34: 20 | G34: Yes | H34: Yes | I34: Yes | J34: Yes
A35: GreatDragonArmorChest | B35: Great Dragon Armor Chest | D35: Items::Types::Chest | E35: chest | F35: 219 | G35: Yes | H35: No | I35: Yes | J35: Yes
... A43: NanoCrates | B43: Nano Crates | D43: Items::Types::Chest | E43: chest | F43: 145 | G43: Yes | H43: Yes | I43: Yes | J43: Yes
A44: NewPlayerProtection | B44: translation missing: en.items.newplayerprotection.name | D44: Items::Types::SafetyBoost | F44: 0 | G44: Yes | H44: No | I44: No | J44: No
A45: NomadicRecruitsDay | B45: Dragon's Call | D45: Items::Types::ResourceBoost | F45: 50 | G45: Yes | H45: No | I45: No | J45: Yes
A46: NpcInstanceGreatDragonChest | D46: Items::Types::Chest | F46: 1000 | G46: Yes | H46: No | I46: No | J46: No
A47: Ore250K | B47: 250,000 Metals | D47: Items::Types::ResourceBundle | E47: resource | F47: 55 | G47: Yes | H47: Yes | I47: Yes | J47: Yes
...

Sheet 任务及升级奖励
B1: position | C1: food | D1: wood | E1: stone | F1: ore | G1: gold | I1: level | J1: ore | K1: wood | L1: stone | M1: food | N1: gold
A2: adjust_taxes | B2: 18 | C2: 0 | D2: 0 | E2: 0 | F2: 0 | G2: 1000 | I2: 1 | J2: 0 | K2: 0 | L2: 0 | M2: 0 | N2: 0
A3: aerial_combat_1 | B3: 119 | C3: 0 | D3: 0 | E3: 0 | F3: 0 | G3: 15000 | I3: 2 | J3: 310 | K3: 680 | L3: 320 | M3: 500 | N3: 600
A4: agriculture_research_1 | B4: 7 | C4: 0 | D4: 0 | E4: 0 | F4: 0 | G4: 2000 | I4: 3 | J4: 420 | K4: 1040 | L4: 680 | M4: 700 | N4: 1000
A5: anthropus_conquer | B5: 73 | C5: 5000 | D5: 0 | E5: 0 | F5: 0 | G5: 0 | I5: 4 | J5: 550 | K5: 1580 | L5: 1220 | M5: 1100 | N5: 1600
A6: ballistics_1 | B6: 65 | C6: 0 | D6: 0 | E6: 0 | F6: 0 | G6: 6000 | I6: 5 | J6: 870 | K6: 2300 | L6: 1940 | M6: 1700 | N6: 2400
A7: clairvoyance_1 | B7: 51 | C7: 0 | D7: 0 | E7: 0 | F7: 0 | G7: 7000 | I7: 6 | J7: 1270 | K7: 3200 | L7: 2840 | M7: 2450 | N7: 3400
A8: conquer_forest_1 | B8: 151 | C8: 1000 | D8: 4000 | E8: 1000 | F8: 1000 | G8: 1000 | I8: 7 | J8: 1750 | K8: 4280 | L8: 3920 | M8: 3350 | N8: 4600
A9: conquer_grassland_1 | B9: 152 | C9: 1000 | D9: 4000 | E9: 1000 | F9: 1000 | G9: 1000 | I9: 8 | J9: 2310 | K9: 5540 | L9: 5180 | M9: 4400 | N9: 6000
A10: conquer_high_level_forest_1 | B10: 156 | C10: 3000 | D10: 7000 | E10: 3000 | F10: 3000 | G10: 2500 | I10: 9 | J10: 2950 | K10: 6980 | L10: 6620 | M10: 5600 | N10: 7600
A11: conquer_high_level_forest_2 | B11: 176 | C11: 5000 | D11: 8500 | E11: 5000 | F11: 5000 | G11: 5000 | I11: 10 | J11: 3670 | K11: 8600 | L11: 8240 | M11: 6950 | N11: 9400
A12: conquer_high_level_forest_3 | B12: 188 | C12: 8000 | D12: 15000 | E12: 8000 | F12: 8000 | G12: 8000 | I12: 11 | J12: 4470 | K12: 10400 | L12: 10040 | M12: 8450 | N12: 11400
A13: conquer_high_level_grassland_1 | B13: 157 | C13: 3000 | D13: 7000 | E13: 3000 | F13: 3000 | G13: 2500 | I13: 12 | J13: 5350 | K13: 12380 | L13: 12020 | M13: 10100 | N13: 13600
... A51: garrison_build_5 | B51: 120 | C51: 8000 | D51: 8500 | E51: 8000 | F51: 8000 | G51: 0 | I51: 50 | J51: 0 | K51: 0 | L51: 0 | M51: 0 | N51: 0
A52: garrison_upgrade_1 | B52: 24 | C52: 2000 | D52: 2400 | E52: 3000 | F52: 2000 | G52: 0
A53: garrison_upgrade_1a | B53: 24 | C53: 2000 | D53: 2400 | E53: 3000 | F53: 2000 | G53: 0
A54: garrison_upgrade_2 | B54: 41 | C54: 4000 | D54: 4800 | E54: 6000 | F54: 4000 | G54: 0
A55: garrison_upgrade_3 | B55: 44 | C55: 6000 | D55: 8500 | E55: 8000 | F55: 6000 | G55: 0
A56: garrison_upgrade_4 | B56: 57 | C56: 8000 | D56: 8500 | E56: 10000 | F56: 8000 | G56: 0
A57: garrison_upgrade_5 | B57: 60 | C57: 8000 | D57: 8500 | E57: 10000 | F57: 8000 | G57: 0
A58: garrison_upgrade_6 | B58: 71 | C58: 8000 | D58: 8500 | E58: 10000 | F58: 8000 | G58: 0
A59: garrison_upgrade_7 | B59: 78 | C59: 8000 | D59: 8500 | E59: 10000 | F59: 8000 | G59: 0
A60: garrison_upgrade_8 | B60: 92 | C60: 8000 | D60: 8500 | E60: 10000 | F60: 8000 | G60: 0
A61: garrison_upgrade_9 | B61: 220 | C61: 8000 | D61: 8500 | E61: 10000 | F61: 8000 | G61: 0
A62: gold_production_1 | B62: 140 | C62: 0 | D62: 0 | E62: 0 | F62: 0 | G62: 1000
A63: gold_production_2 | B63: 107 | C63: 0 | D63: 0 | E63: 0 | F63: 0 | G63: 5000
... A234: woodcraft_research_1 | B234: 34 | C234: 0 | D234: 0 | E234: 0 | F234: 0 | G234: 2000

Sheet 金币产出
A1: 初始人口 | B1: 剧场等级 | C1: 幸福感系数 | D1: 对应的最优税率 | E1: home | F1: 增加人口上限 | G1: 数量 | H1: 总上限
A2: 50 | B2: 1 | C2: 1 | D2: =(C2/100+1)/2 -> 0.505 | E2: 1 | F2: 37 | H2: =F2*G2 -> 0 | J2: 税率 | K2: 0.6 | N2: [0, [100 - tax_rate + happiness_per_level[level.to_s] , 100].min].max
B3: 2 | C3: 3 | D3: =(C3/100+1)/2 -> 0.515 | E3: 2 | F3: 100 | H3: =F3*G3 -> 0 | N3: "happiness_per_level" : {"0":0,"1":1,"2":3,"3":4,"4":5,"5":6,"6":7,"7":8,"8":9,"9":10,"10":11,"11":12,"12":14,"13":15,"14":16,"15":18,"16":19,"17":20,"18":22,"19":23,"20":25},
A4: 龙之召唤 | B4: 3 | C4: 4 | D4: =(C4/100+1)/2 -> 0.52 | E4: 3 | F4: 187 | H4: =F4*G4 -> 0 | J4: 剧场等级 | K4: 16
A5: 1 | B5: 4 | C5: 5 | D5: =(C5/100+1)/2 -> 0.525 | E5: 4 | F5: 300 | H5: =F5*G5 -> 0
B6: 5 | C6: 6 | D6: =(C6/100+1)/2 -> 0.53 | E6: 5 | F6: 437 | H6: =F6*G6 -> 0 | J6: 幸福感 | K6: =MAX(0,MIN(1,1+LOOKUP(K4,B:B,C:C)/100-K2)) -> 0.59
B7: 6 | C7: 7 | D7: =(C7/100+1)/2 -> 0.535 | E7: 6 | F7: 600 | H7: =F7*G7 -> 0
B8: 7 | C8: 8 | D8: =(C8/100+1)/2 -> 0.54 | E8: 7 | F8: 787 | H8: =F8*G8 -> 0 | J8: 纳税人口 | K8: =H22*K6 -> 44279.5
B9: 8 | C9: 9 | D9: =(C9/100+1)/2 -> 0.545 | E9: 8 | F9: 1000 | H9: =F9*G9 -> 0
B10: 9 | C10: 10 | D10: =(C10/100+1)/2 -> 0.55 | E10: 9 | F10: 1237 | H10: =F10*G10 -> 0 | J10: 加倍税收道具 | K10: 0
B11: 10 | C11: 11 | D11: =(C11/100+1)/2 -> 0.555 | E11: 10 | F11: 1500 | H11: =F11*G11 -> 0
B12: 11 | C12: 12 | D12: =(C12/100+1)/2 -> 0.56 | E12: 11 | F12: 1787 | H12: =F12*G12 -> 0
B13: 12 | C13: 14 | D13: =(C13/100+1)/2 -> 0.57 | E13: 12 | F13: 2100 | H13: =F13*G13 -> 0 | J13: 金币产量/小时 | K13: =K8*K2*(1+K10) -> 26567.7
B14: 13 | C14: 15 | D14: =(C14/100+1)/2 -> 0.575 | E14: 13 | F14: 2437 | H14: =F14*G14 -> 0
B15: 14 | C15: 16 | D15: =(C15/100+1)/2 -> 0.58 | E15: 14 | F15: 2800 | H15: =F15*G15 -> 0
B16: 15 | C16: 18 | D16: =(C16/100+1)/2 -> 0.59 | E16: 15 | F16: 3187 | H16: =F16*G16 -> 0 | M16: 最优税率: | N16: （幸福感系数+1）/2
B17: 16 | C17: 19 | D17: =(C17/100+1)/2 -> 0.595 | E17: 16 | F17: 3600 | H17: =F17*G17 -> 0
B18: 17 | C18: 20 | D18: =(C18/100+1)/2 -> 0.6 | E18: 17 | F18: 4037 | H18: =F18*G18 -> 0
B19: 18 | C19: 22 | D19: =(C19/100+1)/2 -> 0.61 | E19: 18 | F19: 4500 | H19: =F19*G19 -> 0
B20: 19 | C20: 23 | D20: =(C20/100+1)/2 -> 0.615 | E20: 19 | F20: 4987 | H20: =F20*G20 -> 0
B21: 20 | C21: 25 | D21: =(C21/100+1)/2 -> 0.625 | E21: 20 | F21: 5500 | G21: 10 | H21: =F21*G21 -> 55000
G22: total | H22: =H21+A2+A5*20000 -> 75050

Sheet 资源产出
A1: 资源建筑等级 | B1: 雇佣人口 | C1: 产量每小时 | D1: 上限 | F1: 初始速度/小时 | G1: 100
A2: 1 | B2: 10 | C2: =B2*10 -> 100 | D2: =C2*100 -> 10000
A3: 2 | B3: 30 | C3: =B3*10 -> 300 | D3: =C3*100 -> 30000 | F3: （初始速度+建筑产出速度）*（1+科技加成+野外资源点加成+道具加成）
A4: 3 | B4: 60 | C4: =B4*10 -> 600 | D4: =C4*100 -> 60000
A5: 4 | B5: 100 | C5: =B5*10 -> 1000 | D5: =C5*100 -> 100000 | G5: 建筑数量 | H5: 12
A6: 5 | B6: 150 | C6: =B6*10 -> 1500 | D6: =C6*100 -> 150000 | G6: 建筑等级 | H6: 10
A7: 6 | B7: 210 | C7: =B7*10 -> 2100 | D7: =C7*100 -> 210000 | G7: 科技等级 | H7: 10 | I7: 科技加成 | J7: =0.1*H7 -> 1
A8: 7 | B8: 280 | C8: =B8*10 -> 2800 | D8: =C8*100 -> 280000 | G8: 野外点等级 | H8: 8
A9: 8 | B9: 360 | C9: =B9*10 -> 3600 | D9: =C9*100 -> 360000 | G9: 野外点数量 | H9: 5 | I9: 野外点加成 | J9: =H8*H9*0.05 -> 2
A10: 9 | B10: 450 | C10: =B10*10 -> 4500 | D10: =C10*100 -> 450000 | G10: 道具 | H10: 1 | I10: 道具加成 | J10: =H10*0.25 -> 0.25
A11: 10 | B11: 550 | C11: =B11*10 -> 5500 | D11: =C11*100 -> 550000
G12: 资源产出速度 | H12: =(G1+H5*LOOKUP(H6,A:A,C:C))*(1+J7+J9+J10) -> 11645
E14: 资源达到上限后资源点不再产出
E15: 野外共38个资源点
M16: level | N16: recover | O16: might
A17: water | B17: 雇佣人口 | C17: 产量每小时 | D17: 上限 | F17: 雇佣人口 | G17: laborers_per_level*(level*level+level) | J17: laborers_per_level | K17: 10 | M17: 1 | N17: =P17*12 -> 24 | O17: =INT(10*(2^(M17/2-1))) -> 7 | P17: =M17*M17+M17 -> 2
A18: 1 | B18: =B2*2 -> 20 | C18: =E18*2 -> 4 | D18: =C18*48 -> 192 | E18: =A2^2+A2 -> 2 | F18: 产量每小时 | G18: rate_increase_per_level*(level*level+level) | J18: rate_increase_per_level | K18: 2 | M18: 2 | N18: =P18*12 -> 72 | O18: =INT(10*(2^(M18/2-1))) -> 10 | P18: =M18*M18+M18 -> 6
A19: 2 | B19: =B3*2 -> 60 | C19: =E19*2 -> 12 | D19: =C19*48 -> 576 | E19: =A3^2+A3 -> 6 | F19: 产量上限 | G19: capacity_increase_per_level*(level*level+level) | J19: capacity_increase_per_level | K19: 96 | M19: 3 | N19: =P19*12 -> 144 | O19: =INT(10*(2^(M19/2-1))) -> 14 | P19: =M19*M19+M19 -> 12
A20: 3 | B20: =B4*2 -> 120 | C20: =E20*2 -> 24 | D20: =C20*48 -> 1152 | E20: =A4^2+A4 -> 12 | M20: 4 | N20: =P20*12 -> 240 | O20: =INT(10*(2^(M20/2-1))) -> 20 | P20: =M20*M20+M20 -> 20
A21: 4 | B21: =B5*2 -> 200 | C21: =E21*2 -> 40 | D21: =C21*48 -> 1920 | E21: =A5^2+A5 -> 20 | M21: 5 | N21: =P21*12 -> 360 | O21: =INT(10*(2^(M21/2-1))) -> 28 | P21: =M21*M21+M21 -> 30
A22: 5 | B22: =B6*2 -> 300 | C22: =E22*2 -> 60 | D22: =C22*48 -> 2880 | E22: =A6^2+A6 -> 30 | M22: 6 | N22: =P22*12 -> 504 | O22: =INT(10*(2^(M22/2-1))) -> 40 | P22: =M22*M22+M22 -> 42
A23: 6 | B23: =B7*2 -> 420 | C23: =E23*2 -> 84 | D23: =C23*48 -> 4032 | E23: =A7^2+A7 -> 42 | M23: 7 | N23: =P23*12 -> 672 | O23: =INT(10*(2^(M23/2-1))) -> 56 | P23: =M23*M23+M23 -> 56
A24: 7 | B24: =B8*2 -> 560 | C24: =E24*2 -> 112 | D24: =C24*48 -> 5376 | E24: =A8^2+A8 -> 56 | M24: 8 | N24: =P24*12 -> 864 | O24: =INT(10*(2^(M24/2-1))) -> 80 | P24: =M24*M24+M24 -> 72
A25: 8 | B25: =B9*2 -> 720 | C25: =E25*2 -> 144 | D25: =C25*48 -> 6912 | E25: =A9^2+A9 -> 72 | M25: 9 | N25: =P25*12 -> 1080 | O25: =INT(10*(2^(M25/2-1))) -> 113 | P25: =M25*M25+M25 -> 90
A26: 9 | B26: =B10*2 -> 900 | C26: =E26*2 -> 180 | D26: =C26*48 -> 8640 | E26: =A10^2+A10 -> 90 | M26: 10 | N26: =P26*12 -> 1320 | O26: =INT(10*(2^(M26/2-1))) -> 160 | P26: =M26*M26+M26 -> 110
A27: 10 | B27: =B11*2 -> 1100 | C27: =E27*2 -> 220 | D27: =C27*48 -> 10560 | E27: =A11^2+A11 -> 110 | M27: 11 | N27: =P27*12 -> 1584 | O27: =INT(10*(2^(M27/2-1))) -> 226 | P27: =M27*M27+M27 -> 132
B28: =B18/$E$18 -> 10 | C28: =C18/$E$18 -> 2 | D28: =D18/$E$18 -> 96 | M28: 12 | N28: =P28*12 -> 1872 | O28: =INT(10*(2^(M28/2-1))) -> 320 | P28: =M28*M28+M28 -> 156
M29: 13 | N29: =P29*12 -> 2184 | O29: =INT(10*(2^(M29/2-1))) -> 452 | P29: =M29*M29+M29 -> 182
M30: 14 | N30: =P30*12 -> 2520 | O30: =INT(10*(2^(M30/2-1))) -> 640 | P30: =M30*M30+M30 -> 210
M31: 15 | N31: =P31*12 -> 2880 | O31: =INT(10*(2^(M31/2-1))) -> 905 | P31: =M31*M31+M31 -> 240
M32: 16 | N32: =P32*12 -> 3264 | O32: =INT(10*(2^(M32/2-1))) -> 1280 | P32: =M32*M32+M32 -> 272
M33: 17 | N33: =P33*12 -> 3672 | O33: =INT(10*(2^(M33/2-1))) -> 1810 | P33: =M33*M33+M33 -> 306
M34: 18 | N34: =P34*12 -> 4104 | O34: =INT(10*(2^(M34/2-1))) -> 2560 | P34: =M34*M34+M34 -> 342
M35: 19 | N35: =P35*12 -> 4560 | O35: =INT(10*(2^(M35/2-1))) -> 3620 | P35: =M35*M35+M35 -> 380
M36: 20 | N36: =P36*12 -> 5040 | O36: =INT(10*(2^(M36/2-1))) -> 5120 | P36: =M36*M36+M36 -> 420

Sheet 野蛮营地怪及资源及掉落
A1: Anthropus Troops and Resources by Level | M1: 兵量及资源每5分钟恢复10%
A2: Level | B2: 1 | C2: 2 | D2: 3 | E2: 4 | F2: 5 | G2: 6 | H2: 7 | I2: 8 | J2: 9 | K2: 10 | L2: Equiv
A3: Brats | B3: 500 | C3: 1000 | D3: 2000 | E3: 5000 | F3: 10000 | G3: 15000 | H3: 30000 | I3: 60000 | J3: 120000 | K3: 250000 | L3: porter | M3: =VLOOKUP(L3,兵种!$A$2:$J$13,10,FALSE) -> 1 | N3: =K3*M3 -> 250000
A4: Cannibal | B4: 500 | C4: 1000 | D4: 2000 | E4: 5000 | F4: 10000 | G4: 15000 | H4: 30000 | I4: 60000 | J4: 120000 | K4: 250000 | L4: Conscript | M4: =VLOOKUP(L4,兵种!$A$2:$J$13,10,FALSE) -> 1 | N4: =K4*M4 -> 250000
A5: Stench | C5: 500 | D5: 1000 | E5: 600 | F5: 5000 | G5: 10000 | H5: 15000 | I5: 30000 | J5: 60000 | K5: 120000 | L5: Spy | M5: =VLOOKUP(L5,兵种!$A$2:$J$13,10,FALSE) -> 2 | N5: =K5*M5 -> 240000
A6: She-Devil | C6: 500 | D6: 1000 | E6: 2000 | F6: 5000 | G6: 10000 | H6: 15000 | I6: 30000 | J6: 60000 | K6: 120000 | L6: Halberdsman | M6: =VLOOKUP(L6,兵种!$A$2:$J$13,10,FALSE) -> 2 | N6: =K6*M6 -> 240000
A7: Clubber | D7: 500 | E7: 1000 | F7: 2000 | G7: 5000 | H7: 10000 | I7: 15000 | J7: 30000 | K7: 60000 | L7: Minotaur | M7: =VLOOKUP(L7,兵种!$A$2:$J$13,10,FALSE) -> 3 | N7: =K7*M7 -> 180000
A8: Hurler | E8: 500 | F8: 1000 | G8: 2000 | H8: 5000 | I8: 10000 | J8: 15000 | K8: 30000 | L8: Longbowman | M8: =VLOOKUP(L8,兵种!$A$2:$J$13,10,FALSE) -> 4 | N8: =K8*M8 -> 120000
A9: Shredder | F9: 500 | G9: 1000 | H9: 2000 | I9: 5000 | J9: 10000 | K9: 15000 | L9: SwiftStrikeDragon | M9: =VLOOKUP(L9,兵种!$A$2:$J$13,10,FALSE) -> 5 | N9: =K9*M9 -> 75000
A10: Chieftain | H10: 500 | I10: 1000 | J10: 2000 | K10: 4000 | L10: BattleDragon | M10: =VLOOKUP(L10,兵种!$A$2:$J$13,10,FALSE) -> 7 | N10: =K10*M10 -> 28000
A11: Bloods | J11: 1000 | K11: 2000 | L11: Giant | M11: =VLOOKUP(L11,兵种!$A$2:$J$13,10,FALSE) -> 9 | N11: =K11*M11 -> 18000
A12: Rager | K12: 1000 | L12: FireMirror | M12: =VLOOKUP(L12,兵种!$A$2:$J$13,10,FALSE) -> 10 | N12: =K12*M12 -> 10000
A13: Launchers
A14: Smash
A15: Gnashers
A16: Divers
B17: =SUM(B3:B16) -> 1000 | C17: =SUM(C3:C16) -> 3000 | D17: =SUM(D3:D16) -> 6500 | E17: =SUM(E3:E16) -> 14100 | F17: =SUM(F3:F16) -> 33500 | G17: =SUM(G3:G16) -> 58000 | H17: =SUM(H3:H16) -> 107500 | I17: =SUM(I3:I16) -> 211000 | ... K17: =SUM(K3:K16) -> 852000
B18: 1 | C18: 2 | D18: 3 | E18: 4 | F18: 5 | G18: 6 | H18: 7 | I18: 8 | J18: 9 | K18: 10
A19: Food | B19: 112500 | C19: 225000 | D19: 337500 | E19: 450000 | F19: 562500 | G19: 675000 | H19: 787500 | I19: 900000 | J19: 1012500 | K19: 1125000
A20: 30000 | B20: 30000 | C20: 30000 | D20: 30000 | E20: 30000 | F20: 30000 | G20: 30000 | H20: 35000 | I20: 40000 | J20: 45000 | K20: 50000
A21: Stone | B21: 500 | C21: 1000 | D21: 1500 | E21: 2000 | F21: 2500 | G21: 3000 | H21: 3500 | I21: 4000 | J21: 4500 | K21: 5000
A22: metal | B22: 500 | C22: 1000 | D22: 1500 | E22: 2000 | F22: 2500 | G22: 3000 | H22: 3500 | I22: 4000 | J22: 4500 | K22: 5000
A23: Gold | B23: 2500 | C23: 5000 | D23: 7500 | E23: 10000 | F23: 12500 | G23: 15000 | H23: 17500 | I23: 20000 | J23: 22500 | K23: 25000
A25: 道具产出 | C25: 权重
B26: 几率 | C26: 1 | D26: 2 | E26: 3 | F26: 4
A27: Blink | B27: 0.05 | C27: 4 | D27: 4 | E27: 4 | F27: 4
A28: Hop | B28: 0.05 | C28: 3 | D28: 3 | E28: 3 | F28: 3
A29: Skip | B29: 0.1 | C29: 2 | D29: 2 | E29: 2 | F29: 2
A30: Jump | B30: 0.1 | C30: 1 | D30: 1 | E30: 1 | F30: 1

Sheet 资源点怪及奖励
A1: Level | B1: 1 | C1: 2 | D1: 3 | E1: 4 | F1: 5 | G1: 6 | H1: 7 | I1: 8 | J1: 9 | K1: 10 | L1: Equiv
A2: Cannibals | B2: 50 | C2: 100 | D2: 200 | E2: 500 | F2: 1000 | G2: 2000 | H2: 2000 | I2: 5000 | J2: 10000 | K2: 20000 | L2: Con
A3: Stench | C3: 50 | D3: 100 | E3: 200 | F3: 500 | G3: =G2/2 -> 1000 | H3: =H2/2 -> 1000 | I3: 2000 | J3: 5000 | K3: 10000 | L3: Spy
A4: She-Devil | D4: 50 | E4: 100 | F4: 200 | G4: 500 | H4: 500 | I4: =I3/2 -> 1000 | J4: 2000 | K4: 5000 | L4: Hal
A5: Clubbers | E5: 50 | F5: 100 | G5: 200 | H5: 200 | I5: 500 | J5: =J4/2 -> 1000 | K5: 2000 | L5: Mino | M5: 可占领资源点等级取决于城堡等级
A6: Hurlers | F6: 50 | G6: 100 | H6: 100 | I6: 200 | J6: 500 | K6: =K5/2 -> 1000 | L6: LBM | M6: 每级野外资源点对应资源产出加速5%
A7: Shredders | G7: 50 | H7: 50 | I7: 100 | J7: 200 | K7: 500 | L7: SSD
A8: Chieftains | I8: 50 | J8: 100 | K8: 200 | L8: BD
A9: Bloods | J9: 50 | K9: 100 | L9: Giant
A10: Ragers | K10: 50 | L10: FM
B11: =SUM(B2:B10) -> 50 | C11: =SUM(C2:C10) -> 150 | D11: =SUM(D2:D10) -> 350 | E11: =SUM(E2:E10) -> 850 | F11: =SUM(F2:F10) -> 1850 | G11: =SUM(G2:G10) -> 3850 | H11: =SUM(H2:H10) -> 3850 | I11: =SUM(I2:I10) -> 8850 | ... K11: =SUM(K2:K10) -> 38850
A12: 1 | B12: 2 | C12: 3 | D12: 4 | E12: 5 | F12: 6 | G12: 7 | H12: 8 | I12: 9 | J12: 10
A13: Lake | B13: 1000 | C13: 2000 | D13: 3000 | E13: 4000 | F13: 5000 | G13: 6000 | H13: 7000 | I13: 8000 | J13: 9000 | K13: 10000 | L13: Food
A14: Hill | B14: 1000 | C14: 2000 | D14: 3000 | E14: 4000 | F14: 5000 | G14: 6000 | H14: 7000 | I14: 8000 | J14: 9000 | K14: 10000 | L14: Stone
A15: Mountain | B15: 1000 | C15: 2000 | D15: 3000 | E15: 4000 | F15: 5000 | G15: 6000 | H15: 7000 | I15: 8000 | J15: 9000 | K15: 10000 | L15: metal
A16: Forest | B16: 1000 | C16: 2000 | D16: 3000 | E16: 4000 | F16: 5000 | G16: 6000 | H16: 7000 | I16: 8000 | J16: 9000 | K16: 10000 | L16: Wood
A17: Savanna | B17: 1000 | C17: 2000 | D17: 3000 | E17: 4000 | F17: 5000 | G17: 6000 | H17: 7000 | I17: 8000 | J17: 9000 | K17: 10000 | L17: Food

Sheet 战役兵种及资源
B1: 1 | C1: 2 | D1: 3 | E1: 4 | F1: 5 | G1: 6 | H1: 7 | I1: 8 | J1: 9 | K1: 10
A2: Porter | B2: 5 | D2: 1000
A3: Conscript | C3: 25 | D3: 400
A4: Halberdsman | E4: 500 | H4: 1000
A5: Minotaur | E5: 500
A6: Longbowman | F6: 600 | H6: 1500
A7: SwiftStrikeDragon | G7: 1000
A8: BattleDragon | I8: 500 | J8: 600
A9: Giant | J9: 260
A10: BlackholeOne | K10: 10000000
A14: gold | B14: 1000 | C14: 2000 | D14: 3000 | E14: 4000 | F14: 5000 | G14: 6000 | H14: 7000 | I14: 8000 | J14: 9000 | K14: 20000
A15: food | B15: 1000 | C15: 2000 | D15: 3000 | E15: 4000 | F15: 5000 | G15: 6000 | H15: 7000 | I15: 8000 | J15: 9000 | K15: 20000
A16: wood | B16: 1000 | C16: 2000 | D16: 3000 | E16: 4000 | F16: 5000 | G16: 6000 | H16: 7000 | I16: 8000 | J16: 9000 | K16: 20000
A17: stone | B17: 1000 | C17: 2000 | D17: 3000 | E17: 4000 | F17: 5000 | G17: 6000 | H17: 7000 | I17: 8000 | J17: 9000 | K17: 20000
A18: ore | B18: 1000 | C18: 2000 | D18: 3000 | E18: 4000 | F18: 5000 | G18: 6000 | H18: 7000 | I18: 8000 | J18: 9000 | K18: 20000
A20: 掉落：
B21: replace
B22: PurpleBones | C22: 0.65
B23: DarkWarpDevice | C23: 0.2
B24: Bounce | C24: 0.1
B25: Bore | C25: 0.05
B26: once
B27: Helmet | C27: 0.65
B28: Tail | C28: 0.2
B29: Body | C29: 0.1
B30: Claw | C30: 0.05

Sheet 建筑消耗
A1: building_type | B1: level | C1: time | E1: ore | F1: wood | G1: stone | H1: food | I1: gold | J1: items | K1: time value | L1: total resource | M1: resource value | N1: DI value | O1: total instant upgrade price | P1: modified price
A2: Buildings::DragonKeep | B2: 0 | C2: 0 | D2: =IF(INT(C2/3600/24)=0,"",INT(C2/3600/24)&"D")&IF(INT(MOD(C2,3600*24)/3600)=0,"",INT(MOD(C2,3600*24)/3600)&"H")&IF(INT(MOD(C2,3600)/60)=0,"",INT(MOD(C2,3600)/60)&"M")&INT(MOD(C2,60))&"S" -> 0S | K2: 0 | L2: 0 | M2: 0 | O2: 0
A3: Buildings::DragonKeep | B3: 1 | C3: 5 | D3: =IF(INT(C3/3600/24)=0,"",INT(C3/3600/24)&"D")&IF(INT(MOD(C3,3600*24)/3600)=0,"",INT(MOD(C3,3600*24)/3600)&"H")&IF(INT(MOD(C3,3600)/60)=0,"",INT(MOD(C3,3600)/60)&"M")&INT(MOD(C3,60))&"S" -> 5S | E3: 700 | F3: 2500 | G3: 1200 | H3: 400 | I3: 1500 | K3: 0.083333333 | L3: 6300 | M3: 1.575 | O3: 1.6583333 | P3: 3
A4: Buildings::DragonKeep | B4: 2 | C4: 5 | D4: =IF(INT(C4/3600/24)=0,"",INT(C4/3600/24)&"D")&IF(INT(MOD(C4,3600*24)/3600)=0,"",INT(MOD(C4,3600*24)/3600)&"H")&IF(INT(MOD(C4,3600)/60)=0,"",INT(MOD(C4,3600)/60)&"M")&INT(MOD(C4,60))&"S" -> 5S | E4: 100 | F4: 100 | G4: 100 | H4: 100 | I4: 100 | K4: 0.083333333 | L4: 500 | M4: 0.125 | O4: 0.20833333 | P4: 1
A5: Buildings::DragonKeep | B5: 3 | C5: 190 | D5: =IF(INT(C5/3600/24)=0,"",INT(C5/3600/24)&"D")&IF(INT(MOD(C5,3600*24)/3600)=0,"",INT(MOD(C5,3600*24)/3600)&"H")&IF(INT(MOD(C5,3600)/60)=0,"",INT(MOD(C5,3600)/60)&"M")&INT(MOD(C5,60))&"S" -> 3M10S | E5: 738 | F5: 2638 | G5: 1266 | H5: 422 | I5: 1583 | K5: 3.1666667 | L5: 6647 | M5: 1.66175 | O5: 4.8284167 | P5: 7
A6: Buildings::DragonKeep | B6: 4 | C6: 277 | D6: =IF(INT(C6/3600/24)=0,"",INT(C6/3600/24)&"D")&IF(INT(MOD(C6,3600*24)/3600)=0,"",INT(MOD(C6,3600*24)/3600)&"H")&IF(INT(MOD(C6,3600)/60)=0,"",INT(MOD(C6,3600)/60)&"M")&INT(MOD(C6,60))&"S" -> 4M37S | E6: 1077 | F6: 3847 | G6: 1846 | H6: 615 | I6: 2308 | K6: 4.6166667 | L6: 9693 | M6: 2.42325 | O6: 7.0399167 | P6: 10
A7: Buildings::DragonKeep | B7: 5 | C7: 404 | D7: =IF(INT(C7/3600/24)=0,"",INT(C7/3600/24)&"D")&IF(INT(MOD(C7,3600*24)/3600)=0,"",INT(MOD(C7,3600*24)/3600)&"H")&IF(INT(MOD(C7,3600)/60)=0,"",INT(MOD(C7,3600)/60)&"M")&INT(MOD(C7,60))&"S" -> 6M44S | E7: 1571 | F7: 5611 | G7: 2693 | H7: 897 | I7: 3366 | K7: 4.04 | L7: 14138 | M7: 3.5345 | O7: 7.5745 | P7: 11
A8: Buildings::DragonKeep | B8: 6 | C8: 590 | D8: =IF(INT(C8/3600/24)=0,"",INT(C8/3600/24)&"D")&IF(INT(MOD(C8,3600*24)/3600)=0,"",INT(MOD(C8,3600*24)/3600)&"H")&IF(INT(MOD(C8,3600)/60)=0,"",INT(MOD(C8,3600)/60)&"M")&INT(MOD(C8,60))&"S" -> 9M50S | E8: 1529 | F8: 5462 | G8: 2622 | H8: 874 | I8: 3277 | K8: 5.9 | L8: 13764 | M8: 3.441 | O8: 9.341 | P8: 13
A9: Buildings::DragonKeep | B9: 7 | C9: 860 | D9: =IF(INT(C9/3600/24)=0,"",INT(C9/3600/24)&"D")&IF(INT(MOD(C9,3600*24)/3600)=0,"",INT(MOD(C9,3600*24)/3600)&"H")&IF(INT(MOD(C9,3600)/60)=0,"",INT(MOD(C9,3600)/60)&"M")&INT(MOD(C9,60))&"S" -> 14M20S | E9: 1672 | F9: 5972 | G9: 2866 | H9: 955 | I9: 3583 | K9: 8.6 | L9: 15048 | M9: 3.762 | O9: 12.362 | P9: 17
A10: Buildings::DragonKeep | B10: 8 | C10: 1254 | D10: =IF(INT(C10/3600/24)=0,"",INT(C10/3600/24)&"D")&IF(INT(MOD(C10,3600*24)/3600)=0,"",INT(MOD(C10,3600*24)/3600)&"H")&IF(INT(MOD(C10,3600)/60)=0,"",INT(MOD(C10,3600)/60)&"M")&INT(MOD(C10,60))&"S" -> 20M54S | E10: 2438 | F10: 8708 | G10: 4180 | H10: 1393 | I10: 5225 | J10: =48*60 -> 2880 | K10: 6.9666667 | L10: 21944 | M10: 5.486 | O10: 12.452667 | P10: 18
A11: Buildings::DragonKeep | B11: 9 | C11: 1828 | D11: =IF(INT(C11/3600/24)=0,"",INT(C11/3600/24)&"D")&IF(INT(MOD(C11,3600*24)/3600)=0,"",INT(MOD(C11,3600*24)/3600)&"H")&IF(INT(MOD(C11,3600)/60)=0,"",INT(MOD(C11,3600)/60)&"M")&INT(MOD(C11,60))&"S" -> 30M28S | E11: 3554 | F11: 12694 | G11: 6093 | H11: 2031 | I11: 7616 | K11: 10.155556 | L11: 31988 | M11: 7.997 | O11: 18.152556 | P11: 24
A12: Buildings::DragonKeep | B12: 10 | C12: 2665 | D12: =IF(INT(C12/3600/24)=0,"",INT(C12/3600/24)&"D")&IF(INT(MOD(C12,3600*24)/3600)=0,"",INT(MOD(C12,3600*24)/3600)&"H")&IF(INT(MOD(C12,3600)/60)=0,"",INT(MOD(C12,3600)/60)&"M")&INT(MOD(C12,60))&"S" -> 44M25S | E12: 5181 | F12: 18506 | G12: 8883 | H12: 2961 | I12: 11104 | K12: 14.805556 | L12: 46635 | M12: 11.65875 | O12: 26.464306 | P12: 35
A13: Buildings::DragonKeep | B13: 11 | C13: 3884 | D13: =IF(INT(C13/3600/24)=0,"",INT(C13/3600/24)&"D")&IF(INT(MOD(C13,3600*24)/3600)=0,"",INT(MOD(C13,3600*24)/3600)&"H")&IF(INT(MOD(C13,3600)/60)=0,"",INT(MOD(C13,3600)/60)&"M")&INT(MOD(C13,60))&"S" -> 1H4M44S | E13: 7552 | F13: 26972 | G13: 12946 | H13: 4315 | I13: 16183 | K13: 10.788889 | L13: 67968 | M13: 16.992 | O13: 27.780889 | P13: 37
A14: Buildings::DragonKeep | B14: 12 | C14: 5663 | D14: =IF(INT(C14/3600/24)=0,"",INT(C14/3600/24)&"D")&IF(INT(MOD(C14,3600*24)/3600)=0,"",INT(MOD(C14,3600*24)/3600)&"H")&IF(INT(MOD(C14,3600)/60)=0,"",INT(MOD(C14,3600)/60)&"M")&INT(MOD(C14,60))&"S" -> 1H34M23S | E14: 11011 | F14: 39326 | G14: 18876 | H14: 6292 | I14: 23595 | K14: 15.730556 | L14: 99100 | M14: 24.775 | O14: 40.505556 | P14: 53
A15: Buildings::DragonKeep | B15: 13 | C15: 8255 | D15: =IF(INT(C15/3600/24)=0,"",INT(C15/3600/24)&"D")&IF(INT(MOD(C15,3600*24)/3600)=0,"",INT(MOD(C15,3600*24)/3600)&"H")&IF(INT(MOD(C15,3600)/60)=0,"",INT(MOD(C15,3600)/60)&"M")&INT(MOD(C15,60))&"S" -> 2H17M35S | E15: 16051 | F15: 57326 | G15: 27516 | H15: 9172 | I15: 34395 | K15: 22.930556 | L15: 144460 | M15: 36.115 | O15: 59.045556 | P15: 77
A16: Buildings::DragonKeep | B16: 14 | C16: 12033 | D16: =IF(INT(C16/3600/24)=0,"",INT(C16/3600/24)&"D")&IF(INT(MOD(C16,3600*24)/3600)=0,"",INT(MOD(C16,3600*24)/3600)&"H")&IF(INT(MOD(C16,3600)/60)=0,"",INT(MOD(C16,3600)/60)&"M")&INT(MOD(C16,60))&"S" -> 3H20M33S | E16: 23397 | F16: 83562 | G16: 40110 | H16: 13370 | I16: 50137 | K16: 20.055 | L16: 210576 | M16: 52.644 | O16: 72.699 | P16: 95
A17: Buildings::DragonKeep | B17: 15 | C17: 17540 | D17: =IF(INT(C17/3600/24)=0,"",INT(C17/3600/24)&"D")&IF(INT(MOD(C17,3600*24)/3600)=0,"",INT(MOD(C17,3600*24)/3600)&"H")&IF(INT(MOD(C17,3600)/60)=0,"",INT(MOD(C17,3600)/60)&"M")&INT(MOD(C17,60))&"S" -> 4H52M20S | E17: 34105 | F17: 121805 | G17: 58466 | H17: 19488 | I17: 73083 | K17: 29.233333 | L17: 306947 | M17: 67.52834 | O17: 96.761673 | P17: 126
A18: Buildings::DragonKeep | B18: 16 | C18: 25568 | D18: =IF(INT(C18/3600/24)=0,"",INT(C18/3600/24)&"D")&IF(INT(MOD(C18,3600*24)/3600)=0,"",INT(MOD(C18,3600*24)/3600)&"H")&IF(INT(MOD(C18,3600)/60)=0,"",INT(MOD(C18,3600)/60)&"M")&INT(MOD(C18,60))&"S" -> 7H6M8S | E18: 49715 | F18: 177555 | G18: 85226 | H18: 28408 | I18: 106533 | K18: 42.613333 | L18: 447437 | M18: 98.43614 | O18: 141.04947 | P18: 184
A19: Buildings::DragonKeep | B19: 17 | C19: 37271 | D19: =IF(INT(C19/3600/24)=0,"",INT(C19/3600/24)&"D")&IF(INT(MOD(C19,3600*24)/3600)=0,"",INT(MOD(C19,3600*24)/3600)&"H")&IF(INT(MOD(C19,3600)/60)=0,"",INT(MOD(C19,3600)/60)&"M")&INT(MOD(C19,60))&"S" -> 10H21M11S | E19: 72471 | F19: 258826 | G19: 124236 | H19: 41412 | I19: 155295 | K19: 51.765278 | L19: 652240 | M19: 123.9256 | O19: 175.69088 | P19: 229
A20: Buildings::DragonKeep | B20: 18 | C20: 54329 | D20: =IF(INT(C20/3600/24)=0,"",INT(C20/3600/24)&"D")&IF(INT(MOD(C20,3600*24)/3600)=0,"",INT(MOD(C20,3600*24)/3600)&"H")&IF(INT(MOD(C20,3600)/60)=0,"",INT(MOD(C20,3600)/60)&"M")&INT(MOD(C20,60))&"S" -> 15H5M29S | E20: 105639 | F20: 377284 | G20: 181096 | H20: 60365 | I20: 226370 | K20: 65.396019 | L20: 950754 | M20: 180.64326 | O20: 246.03928 | P20: 320
A21: Buildings::DragonKeep | B21: 19 | C21: 79195 | D21: =IF(INT(C21/3600/24)=0,"",INT(C21/3600/24)&"D")&IF(INT(MOD(C21,3600*24)/3600)=0,"",INT(MOD(C21,3600*24)/3600)&"H")&IF(INT(MOD(C21,3600)/60)=0,"",INT(MOD(C21,3600)/60)&"M")&INT(MOD(C21,60))&"S" -> 21H59M55S | E21: 153990 | F21: 549965 | G21: 263983 | H21: 87994 | I21: 329979 | K21: 95.327315 | L21: 1385911 | M21: 263.32309 | O21: 358.6504 | P21: 467
A22: Buildings::DragonKeep | B22: 20 | C22: 115442 | D22: =IF(INT(C22/3600/24)=0,"",INT(C22/3600/24)&"D")&IF(INT(MOD(C22,3600*24)/3600)=0,"",INT(MOD(C22,3600*24)/3600)&"H")&IF(INT(MOD(C22,3600)/60)=0,"",INT(MOD(C22,3600)/60)&"M")&INT(MOD(C22,60))&"S" -> 1D8H4M2S | E22: 224470 | F22: 801680 | G22: 384806 | H22: 128268 | I22: 481008 | J22: CompletionGrant | K22: 126.93275 | L22: 2020232 | M22: 383.84408 | N22: 40 | O22: 550.77683 | P22: 717
A23: Buildings::Wall | B23: 0 | C23: 0 | D23: =IF(INT(C23/3600/24)=0,"",INT(C23/3600/24)&"D")&IF(INT(MOD(C23,3600*24)/3600)=0,"",INT(MOD(C23,3600*24)/3600)&"H")&IF(INT(MOD(C23,3600)/60)=0,"",INT(MOD(C23,3600)/60)&"M")&INT(MOD(C23,60))&"S" -> 0S | K23: 0 | L23: 0 | M23: 0 | O23: 0 | P23: 0
A24: Buildings::Wall | B24: 1 | C24: 0 | D24: =IF(INT(C24/3600/24)=0,"",INT(C24/3600/24)&"D")&IF(INT(MOD(C24,3600*24)/3600)=0,"",INT(MOD(C24,3600*24)/3600)&"H")&IF(INT(MOD(C24,3600)/60)=0,"",INT(MOD(C24,3600)/60)&"M")&INT(MOD(C24,60))&"S" -> 0S | E24: 0 | F24: 0 | G24: 0 | H24: 0 | I24: 0 | K24: 0 | L24: 0 | M24: 0 | O24: 0 | P24: 0
A25: Buildings::Wall | B25: 2 | C25: 1059 | D25: =IF(INT(C25/3600/24)=0,"",INT(C25/3600/24)&"D")&IF(INT(MOD(C25,3600*24)/3600)=0,"",INT(MOD(C25,3600*24)/3600)&"H")&IF(INT(MOD(C25,3600)/60)=0,"",INT(MOD(C25,3600)/60)&"M")&INT(MOD(C25,60))&"S" -> 17M39S | E25: 266 | F25: 798 | G25: 5324 | H25: 1597 | K25: 5.8833333 | L25: 7985 | M25: 1.99625 | O25: 7.8795833 | P25: 11
A26: Buildings::Wall | B26: 3 | C26: 1507 | D26: =IF(INT(C26/3600/24)=0,"",INT(C26/3600/24)&"D")&IF(INT(MOD(C26,3600*24)/3600)=0,"",INT(MOD(C26,3600*24)/3600)&"H")&IF(INT(MOD(C26,3600)/60)=0,"",INT(MOD(C26,3600)/60)&"M")&INT(MOD(C26,60))&"S" -> 25M7S | E26: 378 | F26: 1136 | G26: 7577 | H26: 2273 | K26: 8.3722222 | L26: 11364 | M26: 2.841 | O26: 11.213222 | P26: 15
A27: Buildings::Wall | B27: 4 | C27: 2144 | D27: =IF(INT(C27/3600/24)=0,"",INT(C27/3600/24)&"D")&IF(INT(MOD(C27,3600*24)/3600)=0,"",INT(MOD(C27,3600*24)/3600)&"H")&IF(INT(MOD(C27,3600)/60)=0,"",INT(MOD(C27,3600)/60)&"M")&INT(MOD(C27,60))&"S" -> 35M44S | E27: 539 | F27: 1617 | G27: 10780 | H27: 3234 | K27: 11.911111 | L27: 16170 | M27: 4.0425 | O27: 15.953611 | P27: 21
A28: Buildings::Wall | B28: 5 | C28: 3052 | D28: =IF(INT(C28/3600/24)=0,"",INT(C28/3600/24)&"D")&IF(INT(MOD(C28,3600*24)/3600)=0,"",INT(MOD(C28,3600*24)/3600)&"H")&IF(INT(MOD(C28,3600)/60)=0,"",INT(MOD(C28,3600)/60)&"M")&INT(MOD(C28,60))&"S" -> 50M52S | E28: 767 | F28: 2301 | G28: 15346 | H28: 4603 | K28: 16.955556 | L28: 23017 | M28: 5.75425 | O28: 22.709806 | P28: 26
A29: Buildings::Wall | B29: 6 | C29: 4343 | D29: =IF(INT(C29/3600/24)=0,"",INT(C29/3600/24)&"D")&IF(INT(MOD(C29,3600*24)/3600)=0,"",INT(MOD(C29,3600*24)/3600)&"H")&IF(INT(MOD(C29,3600)/60)=0,"",INT(MOD(C29,3600)/60)&"M")&INT(MOD(C29,60))&"S" -> 1H12M23S | E29: 1091 | F29: 3275 | G29: 21837 | H29: 6551 | K29: 12.063889 | L29: 32754 | M29: 8.1885 | O29: 20.252389 | P29: 30
A30: Buildings::Wall | B30: 7 | C30: 6181 | D30: =IF(INT(C30/3600/24)=0,"",INT(C30/3600/24)&"D")&IF(INT(MOD(C30,3600*24)/3600)=0,"",INT(MOD(C30,3600*24)/3600)&"H")&IF(INT(MOD(C30,3600)/60)=0,"",INT(MOD(C30,3600)/60)&"M")&INT(MOD(C30,60))&"S" -> 1H43M1S | E30: 1553 | F30: 4661 | G30: 31079 | H30: 9323 | K30: 17.169444 | L30: 46616 | M30: 11.654 | O30: 28.823444 | P30: 38
A31: Buildings::Wall | B31: 8 | C31: 8796 | D31: =IF(INT(C31/3600/24)=0,"",INT(C31/3600/24)&"D")&IF(INT(MOD(C31,3600*24)/3600)=0,"",INT(MOD(C31,3600*24)/3600)&"H")&IF(INT(MOD(C31,3600)/60)=0,"",INT(MOD(C31,3600)/60)&"M")&INT(MOD(C31,60))&"S" -> 2H26M36S | E31: 2211 | F31: 6634 | G31: 44227 | H31: 13268 | K31: 24.433333 | L31: 66340 | M31: 16.585 | O31: 41.018333 | P31: 54
A32: Buildings::Wall | B32: 9 | C32: 12517 | D32: =IF(INT(C32/3600/24)=0,"",INT(C32/3600/24)&"D")&IF(INT(MOD(C32,3600*24)/3600)=0,"",INT(MOD(C32,3600*24)/3600)&"H")&IF(INT(MOD(C32,3600)/60)=0,"",INT(MOD(C32,3600)/60)&"M")&INT(MOD(C32,60))&"S" -> 3H28M37S | E32: 3146 | F32: 9440 | G32: 62937 | H32: 18881 | K32: 20.861667 | L32: 94404 | M32: 23.601 | O32: 44.462667 | P32: 65
A33: Buildings::Wall | B33: 10 | C33: 17812 | D33: =IF(INT(C33/3600/24)=0,"",INT(C33/3600/24)&"D")&IF(INT(MOD(C33,3600*24)/3600)=0,"",INT(MOD(C33,3600*24)/3600)&"H")&IF(INT(MOD(C33,3600)/60)=0,"",INT(MOD(C33,3600)/60)&"M")&INT(MOD(C33,60))&"S" -> 4H56M52S | E33: 4478 | F33: 13434 | G33: 89562 | H33: 26868 | K33: 29.686667 | L33: 134342 | M33: 33.5855 | O33: 63.272167 | P33: 83
A34: Buildings::Wall | B34: 11 | C34: 25348 | D34: =IF(INT(C34/3600/24)=0,"",INT(C34/3600/24)&"D")&IF(INT(MOD(C34,3600*24)/3600)=0,"",INT(MOD(C34,3600*24)/3600)&"H")&IF(INT(MOD(C34,3600)/60)=0,"",INT(MOD(C34,3600)/60)&"M")&INT(MOD(C34,60))&"S" -> 7H2M28S | E34: 6372 | F34: 19118 | G34: 127454 | H34: 38236 | K34: 42.246667 | L34: 191180 | M34: 47.795 | O34: 90.041667 | P34: 118
A35: Buildings::Wall | B35: 12 | C35: 36071 | D35: =IF(INT(C35/3600/24)=0,"",INT(C35/3600/24)&"D")&IF(INT(MOD(C35,3600*24)/3600)=0,"",INT(MOD(C35,3600*24)/3600)&"H")&IF(INT(MOD(C35,3600)/60)=0,"",INT(MOD(C35,3600)/60)&"M")&INT(MOD(C35,60))&"S" -> 10H1M11S | E35: 9068 | F35: 27205 | G35: 181371 | H35: 54411 | K35: 50.098611 | L35: 272055 | M35: 59.8521 | O35: 109.95071 | P35: 143
A36: Buildings::Wall | B36: 13 | C36: 51331 | D36: =IF(INT(C36/3600/24)=0,"",INT(C36/3600/24)&"D")&IF(INT(MOD(C36,3600*24)/3600)=0,"",INT(MOD(C36,3600*24)/3600)&"H")&IF(INT(MOD(C36,3600)/60)=0,"",INT(MOD(C36,3600)/60)&"M")&INT(MOD(C36,60))&"S" -> 14H15M31S | E36: 12905 | F36: 38715 | G36: 258102 | H36: 77430 | K36: 71.293056 | L36: 387152 | M36: 85.17344 | O36: 156.4665 | P36: 204
... A42: Buildings::Wall | B42: 19 | C42: 426282 | D42: =IF(INT(C42/3600/24)=0,"",INT(C42/3600/24)&"D")&IF(INT(MOD(C42,3600*24)/3600)=0,"",INT(MOD(C42,3600*24)/3600)&"H")&IF(INT(MOD(C42,3600)/60)=0,"",INT(MOD(C42,3600)/60)&"M")&INT(MOD(C42,60))&"S" -> 4D22H24M42S | E42: 107171 | F42: 321514 | G42: 2143427 | H42: 643028 | K42: 339.20009 | L42: 3215140 | M42: 610.8766 | O42: 950.07669 | P42: 1236
A43: Buildings::Wall | B43: 20 | C43: 606620 | D43: =IF(INT(C43/3600/24)=0,"",INT(C43/3600/24)&"D")&IF(INT(MOD(C43,3600*24)/3600)=0,"",INT(MOD(C43,3600*24)/3600)&"H")&IF(INT(MOD(C43,3600)/60)=0,"",INT(MOD(C43,3600)/60)&"M")&INT(MOD(C43,60))&"S" -> 7D30M20S | E43: 152510 | F43: 457530 | G43: 3050201 | H43: 915060 | J43: CompletionGrant | K43: 482.69821 | L43: 4575301 | M43: 869.30719 | N43: 40 | O43: 1392.0054 | P43: 1810
A44: Buildings::OfficerQuarter | B44: 0 | C44: 0 | D44: =IF(INT(C44/3600/24)=0,"",INT(C44/3600/24)&"D")&IF(INT(MOD(C44,3600*24)/3600)=0,"",INT(MOD(C44,3600*24)/3600)&"H")&IF(INT(MOD(C44,3600)/60)=0,"",INT(MOD(C44,3600)/60)&"M")&INT(MOD(C44,60))&"S" -> 0S | K44: 0 | L44: 0 | M44: 0 | O44: 0 | P44: 0
A45: Buildings::OfficerQuarter | B45: 1 | C45: 148 | D45: =IF(INT(C45/3600/24)=0,"",INT(C45/3600/24)&"D")&IF(INT(MOD(C45,3600*24)/3600)=0,"",INT(MOD(C45,3600*24)/3600)&"H")&IF(INT(MOD(C45,3600)/60)=0,"",INT(MOD(C45,3600)/60)&"M")&INT(MOD(C45,60))&"S" -> 2M28S | E45: 260 | F45: 930 | G45: 446 | H45: 148 | K45: 2.4666667 | L45: 1784 | M45: 0.446 | O45: 2.9126667 | P45: 4
...

Sheet 科技消耗
A1: research type | B1: lv | C1: instance | D1: time | E1: ore | F1: wood | G1: food | H1: stone | I1: gold | J1: total | O1: item | P1: quantity | Q1: price | R1: 单价 | T1: ScienceCenter | U1: home | V1: wall | W1: Farm | X1: Lumbermill | Y1: Quarry | Z1: mine | AA1: Garrison | AB1: Metalsmith | AC1: Mining | AD1: Woodcraft | AE1: Rookery | AF1: Factory | AG1: Sentinel | AH1: Levitation | AI1: DragonKeep | AJ1: Dragonry
A2: Agriculture | B2: 1 | C2: 5 | D2: 30 | E2: 100 | G2: 500 | I2: 1000 | J2: =SUM(I2:I2) -> 1000 | K2: =IF(J2>$P$14,$R$15,IF(J2>$P$13,$R$14,$R$13))*J2 -> 0.25 | L2: =IF(D2>$P$10,$R$11,IF(D2>$P$9,$R$10,IF(D2>$P$8,$R$9,IF(D2>$P$7,$R$8,IF(D2>$P$6,$R$7,IF(D2>$P$5,$R$6,IF(D2>$P$4,$R$5,IF(D2>$P$3,$R$4,IF(D2>$P$2,$R$3,$R$2))))))))) -> 0.016666667 | M2: =D2*L2 -> 0.5 | N2: =K2+M2 -> 0.75 | O2: 1m | P2: 60 | Q2: 1 | R2: =Q2/P2 -> 0.016666667 | T2: 1 | W2: 1
B3: 2 | C3: 8 | D3: 876 | E3: 200 | G3: 1000 | I3: 2000 | J3: =SUM(I3:I3) -> 2000 | K3: =IF(J3>$P$14,$R$15,IF(J3>$P$13,$R$14,$R$13))*J3 -> 0.5 | L3: =IF(D3>$P$10,$R$11,IF(D3>$P$9,$R$10,IF(D3>$P$8,$R$9,IF(D3>$P$7,$R$8,IF(D3>$P$6,$R$7,IF(D3>$P$5,$R$6,IF(D3>$P$4,$R$5,IF(D3>$P$3,$R$4,IF(D3>$P$2,$R$3,$R$2))))))))) -> 0.0055555556 | M3: =D3*L3 -> 4.8666667 | N3: =K3+M3 -> 5.3666667 | O3: 5m | P3: 300 | Q3: 3 | R3: =Q3/P3 -> 0.01 | T3: 4 | W3: 2
B4: 3 | C4: 14 | D4: 1775 | E4: 400 | G4: 2000 | I4: 4000 | J4: =SUM(I4:I4) -> 4000 | K4: =IF(J4>$P$14,$R$15,IF(J4>$P$13,$R$14,$R$13))*J4 -> 1 | L4: =IF(D4>$P$10,$R$11,IF(D4>$P$9,$R$10,IF(D4>$P$8,$R$9,IF(D4>$P$7,$R$8,IF(D4>$P$6,$R$7,IF(D4>$P$5,$R$6,IF(D4>$P$4,$R$5,IF(D4>$P$3,$R$4,IF(D4>$P$2,$R$3,$R$2))))))))) -> 0.0027777778 | M4: =D4*L4 -> 4.9305556 | N4: =K4+M4 -> 5.9305556 | O4: 15m | P4: =15*60 -> 900 | Q4: 5 | R4: =Q4/P4 -> 0.0055555556 | T4: 6 | W4: 3
B5: 4 | C5: 22 | D5: 3595 | E5: 800 | G5: 4000 | I5: 8000 | J5: =SUM(I5:I5) -> 8000 | K5: =IF(J5>$P$14,$R$15,IF(J5>$P$13,$R$14,$R$13))*J5 -> 2 | L5: =IF(D5>$P$10,$R$11,IF(D5>$P$9,$R$10,IF(D5>$P$8,$R$9,IF(D5>$P$7,$R$8,IF(D5>$P$6,$R$7,IF(D5>$P$5,$R$6,IF(D5>$P$4,$R$5,IF(D5>$P$3,$R$4,IF(D5>$P$2,$R$3,$R$2))))))))) -> 0.0027777778 | M5: =D5*L5 -> 9.9861111 | N5: =K5+M5 -> 11.986111 | O5: 1h | P5: =3600 -> 3600 | Q5: 10 | R5: =Q5/P5 -> 0.0027777778 | T5: 8 | W5: 4
B6: 5 | C6: 34 | D6: 7280 | E6: 1600 | G6: 8000 | I6: 16000 | J6: =SUM(I6:I6) -> 16000 | K6: =IF(J6>$P$14,$R$15,IF(J6>$P$13,$R$14,$R$13))*J6 -> 4 | L6: =IF(D6>$P$10,$R$11,IF(D6>$P$9,$R$10,IF(D6>$P$8,$R$9,IF(D6>$P$7,$R$8,IF(D6>$P$6,$R$7,IF(D6>$P$5,$R$6,IF(D6>$P$4,$R$5,IF(D6>$P$3,$R$4,IF(D6>$P$2,$R$3,$R$2))))))))) -> 0.0016666667 | M6: =D6*L6 -> 12.133333 | N6: =K6+M6 -> 16.133333 | O6: 2.5h | P6: =2.5*3600 -> 9000 | Q6: 15 | R6: =Q6/P6 -> 0.0016666667 | T6: 10 | W6: 5
B7: 6 | C7: 51 | D7: 14743 | E7: 3200 | G7: 16000 | I7: 32000 | J7: =SUM(I7:I7) -> 32000 | K7: =IF(J7>$P$14,$R$15,IF(J7>$P$13,$R$14,$R$13))*J7 -> 8 | L7: =IF(D7>$P$10,$R$11,IF(D7>$P$9,$R$10,IF(D7>$P$8,$R$9,IF(D7>$P$7,$R$8,IF(D7>$P$6,$R$7,IF(D7>$P$5,$R$6,IF(D7>$P$4,$R$5,IF(D7>$P$3,$R$4,IF(D7>$P$2,$R$3,$R$2))))))))) -> 0.0013888889 | M7: =D7*L7 -> 20.476389 | N7: =K7+M7 -> 28.476389 | O7: 8h | P7: =8*3600 -> 28800 | Q7: 40 | R7: =Q7/P7 -> 0.0013888889 | T7: 12 | W7: 6
B8: 7 | C8: 79 | D8: 29856 | E8: 6400 | G8: 32000 | I8: 64000 | J8: =SUM(I8:I8) -> 64000 | K8: =IF(J8>$P$14,$R$15,IF(J8>$P$13,$R$14,$R$13))*J8 -> 16 | L8: =IF(D8>$P$10,$R$11,IF(D8>$P$9,$R$10,IF(D8>$P$8,$R$9,IF(D8>$P$7,$R$8,IF(D8>$P$6,$R$7,IF(D8>$P$5,$R$6,IF(D8>$P$4,$R$5,IF(D8>$P$3,$R$4,IF(D8>$P$2,$R$3,$R$2))))))))) -> 0.0012037037 | M8: =D8*L8 -> 35.937778 | N8: =K8+M8 -> 51.937778 | O8: 15hr | P8: =15*3600 -> 54000 | Q8: 65 | R8: =Q8/P8 -> 0.0012037037 | T8: 14 | W8: 7
B9: 8 | C9: 143 | D9: 60459 | E9: 12800 | G9: 64000 | I9: 128000 | J9: =SUM(I9:I9) -> 128000 | K9: =IF(J9>$P$14,$R$15,IF(J9>$P$13,$R$14,$R$13))*J9 -> 28.16 | L9: =IF(D9>$P$10,$R$11,IF(D9>$P$9,$R$10,IF(D9>$P$8,$R$9,IF(D9>$P$7,$R$8,IF(D9>$P$6,$R$7,IF(D9>$P$5,$R$6,IF(D9>$P$4,$R$5,IF(D9>$P$3,$R$4,IF(D9>$P$2,$R$3,$R$2))))))))) -> 0.001099537 | M9: =D9*L9 -> 66.47691 | N9: =K9+M9 -> 94.63691 | O9: 24h | P9: =24*3600 -> 86400 | Q9: 95 | R9: =Q9/P9 -> 0.001099537 | T9: 16 | W9: 8
B10: 9 | C10: 286 | D10: 122430 | E10: 25600 | G10: 128000 | I10: 256000 | J10: =SUM(I10:I10) -> 256000 | K10: =IF(J10>$P$14,$R$15,IF(J10>$P$13,$R$14,$R$13))*J10 -> 48.64 | L10: =IF(D10>$P$10,$R$11,IF(D10>$P$9,$R$10,IF(D10>$P$8,$R$9,IF(D10>$P$7,$R$8,IF(D10>$P$6,$R$7,IF(D10>$P$5,$R$6,IF(D10>$P$4,$R$5,IF(D10>$P$3,$R$4,IF(D10>$P$2,$R$3,$R$2))))))))) -> 0.00097222222 | M10: =D10*L10 -> 119.02917 | N10: =K10+M10 -> 167.66917 | O10: 2.5d | P10: =2.5*24*3600 -> 216000 | Q10: 210 | R10: =Q10/P10 -> 0.00097222222 | T10: 18 | W10: 9
B11: 10 | C11: 497 | D11: 247920 | E11: 51200 | G11: 256000 | I11: 512000 | J11: =SUM(I11:I11) -> 512000 | K11: =IF(J11>$P$14,$R$15,IF(J11>$P$13,$R$14,$R$13))*J11 -> 97.28 | L11: =IF(D11>$P$10,$R$11,IF(D11>$P$9,$R$10,IF(D11>$P$8,$R$9,IF(D11>$P$7,$R$8,IF(D11>$P$6,$R$7,IF(D11>$P$5,$R$6,IF(D11>$P$4,$R$5,IF(D11>$P$3,$R$4,IF(D11>$P$2,$R$3,$R$2))))))))) -> 0.00079571759 | M11: =D11*L11 -> 197.27431 | N11: =K11+M11 -> 294.55431 | O11: 4d | P11: =4*24*3600 -> 345600 | Q11: 275 | R11: =Q11/P11 -> 0.00079571759 | T11: 20 | W11: 10
B12: total | C12: =SUM(C2:C11) -> 1139 | D12: =SUM(D2:D11) -> 488964 | E12: =SUM(E2:E11) -> 102300 | F12: =SUM(F2:F11) -> 0 | G12: =SUM(G2:G11) -> 511500 | H12: =SUM(H2:H11) -> 0 | I12: =SUM(I2:I11) -> 1023000 | J12: =SUM(I12:I12) -> 1023000 | K12: =IF(J12>$P$14,$R$15,IF(J12>$P$13,$R$14,$R$13))*J12 -> 194.37 | L12: =IF(D12>$P$10,$R$11,IF(D12>$P$9,$R$10,IF(D12>$P$8,$R$9,IF(D12>$P$7,$R$8,IF(D12>$P$6,$R$7,IF(D12>$P$5,$R$6,IF(D12>$P$4,$R$5,IF(D12>$P$3,$R$4,IF(D12>$P$2,$R$3,$R$2))))))))) -> 0.00079571759 | M12: =D12*L12 -> 389.07726 | N12: =K12+M12 -> 583.44726
A13: Woodcraft | B13: 1 | C13: 6 | D13: 491 | E13: 100 | G13: 500 | I13: 1200 | J13: =SUM(I13:I13) -> 1200 | K13: =IF(J13>$P$14,$R$15,IF(J13>$P$13,$R$14,$R$13))*J13 -> 0.3 | L13: =IF(D13>$P$10,$R$11,IF(D13>$P$9,$R$10,IF(D13>$P$8,$R$9,IF(D13>$P$7,$R$8,IF(D13>$P$6,$R$7,IF(D13>$P$5,$R$6,IF(D13>$P$4,$R$5,IF(D13>$P$3,$R$4,IF(D13>$P$2,$R$3,$R$2))))))))) -> 0.0055555556 | M13: =D13*L13 -> 2.7277778 | N13: =K13+M13 -> 3.0277778 | O13: resource | P13: 80000 | Q13: 20 | R13: =Q13/P13 -> 0.00025 | T13: 2 | X13: 1
B14: 2 | C14: 9 | D14: 994 | E14: 200 | G14: 1000 | I14: 2400 | J14: =SUM(I14:I14) -> 2400 | K14: =IF(J14>$P$14,$R$15,IF(J14>$P$13,$R$14,$R$13))*J14 -> 0.6 | L14: =IF(D14>$P$10,$R$11,IF(D14>$P$9,$R$10,IF(D14>$P$8,$R$9,IF(D14>$P$7,$R$8,IF(D14>$P$6,$R$7,IF(D14>$P$5,$R$6,IF(D14>$P$4,$R$5,IF(D14>$P$3,$R$4,IF(D14>$P$2,$R$3,$R$2))))))))) -> 0.0027777778 | M14: =D14*L14 -> 2.7611111 | N14: =K14+M14 -> 3.3611111 | P14: 250000 | Q14: 55 | R14: =Q14/P14 -> 0.00022 | T14: 4 | X14: 2
B15: 3 | C15: 14 | D15: 2013 | E15: 400 | G15: 2000 | I15: 4800 | J15: =SUM(I15:I15) -> 4800 | K15: =IF(J15>$P$14,$R$15,IF(J15>$P$13,$R$14,$R$13))*J15 -> 1.2 | L15: =IF(D15>$P$10,$R$11,IF(D15>$P$9,$R$10,IF(D15>$P$8,$R$9,IF(D15>$P$7,$R$8,IF(D15>$P$6,$R$7,IF(D15>$P$5,$R$6,IF(D15>$P$4,$R$5,IF(D15>$P$3,$R$4,IF(D15>$P$2,$R$3,$R$2))))))))) -> 0.0027777778 | M15: =D15*L15 -> 5.5916667 | N15: =K15+M15 -> 6.7916667 | P15: 500000 | Q15: 95 | R15: =Q15/P15 -> 0.00019 | T15: 6 | X15: 3
B16: 4 | C16: 19 | D16: 4077 | E16: 800 | G16: 4000 | I16: 9600 | J16: =SUM(I16:I16) -> 9600 | K16: =IF(J16>$P$14,$R$15,IF(J16>$P$13,$R$14,$R$13))*J16 -> 2.4 | L16: =IF(D16>$P$10,$R$11,IF(D16>$P$9,$R$10,IF(D16>$P$8,$R$9,IF(D16>$P$7,$R$8,IF(D16>$P$6,$R$7,IF(D16>$P$5,$R$6,IF(D16>$P$4,$R$5,IF(D16>$P$3,$R$4,IF(D16>$P$2,$R$3,$R$2))))))))) -> 0.0016666667 | M16: =D16*L16 -> 6.795 | N16: =K16+M16 -> 9.195 | T16: 8 | X16: 4
B17: 5 | C17: 29 | D17: 8256 | E17: 1600 | G17: 8000 | I17: 19200 | J17: =SUM(I17:I17) -> 19200 | K17: =IF(J17>$P$14,$R$15,IF(J17>$P$13,$R$14,$R$13))*J17 -> 4.8 | L17: =IF(D17>$P$10,$R$11,IF(D17>$P$9,$R$10,IF(D17>$P$8,$R$9,IF(D17>$P$7,$R$8,IF(D17>$P$6,$R$7,IF(D17>$P$5,$R$6,IF(D17>$P$4,$R$5,IF(D17>$P$3,$R$4,IF(D17>$P$2,$R$3,$R$2))))))))) -> 0.0016666667 | M17: =D17*L17 -> 13.76 | N17: =K17+M17 -> 18.56 | T17: 10 | X17: 5
B18: 6 | C18: 56 | D18: 16718 | E18: 3200 | G18: 16000 | I18: 38400 | J18: =SUM(I18:I18) -> 38400 | K18: =IF(J18>$P$14,$R$15,IF(J18>$P$13,$R$14,$R$13))*J18 -> 9.6 | L18: =IF(D18>$P$10,$R$11,IF(D18>$P$9,$R$10,IF(D18>$P$8,$R$9,IF(D18>$P$7,$R$8,IF(D18>$P$6,$R$7,IF(D18>$P$5,$R$6,IF(D18>$P$4,$R$5,IF(D18>$P$3,$R$4,IF(D18>$P$2,$R$3,$R$2))))))))) -> 0.0013888889 | M18: =D18*L18 -> 23.219444 | N18: =K18+M18 -> 32.819444 | T18: 12 | X18: 6
B19: 7 | C19: 96 | D19: 33855 | E19: 6400 | G19: 32000 | I19: 76800 | J19: =SUM(I19:I19) -> 76800 | K19: =IF(J19>$P$14,$R$15,IF(J19>$P$13,$R$14,$R$13))*J19 -> 19.2 | L19: =IF(D19>$P$10,$R$11,IF(D19>$P$9,$R$10,IF(D19>$P$8,$R$9,IF(D19>$P$7,$R$8,IF(D19>$P$6,$R$7,IF(D19>$P$5,$R$6,IF(D19>$P$4,$R$5,IF(D19>$P$3,$R$4,IF(D19>$P$2,$R$3,$R$2))))))))) -> 0.0012037037 | M19: =D19*L19 -> 40.751389 | N19: =K19+M19 -> 59.951389 | T19: 14 | X19: 7
B20: 8 | C20: 167 | D20: 68557 | E20: 12800 | G20: 64000 | I20: 153600 | J20: =SUM(I20:I20) -> 153600 | K20: =IF(J20>$P$14,$R$15,IF(J20>$P$13,$R$14,$R$13))*J20 -> 33.792 | L20: =IF(D20>$P$10,$R$11,IF(D20>$P$9,$R$10,IF(D20>$P$8,$R$9,IF(D20>$P$7,$R$8,IF(D20>$P$6,$R$7,IF(D20>$P$5,$R$6,IF(D20>$P$4,$R$5,IF(D20>$P$3,$R$4,IF(D20>$P$2,$R$3,$R$2))))))))) -> 0.001099537 | M20: =D20*L20 -> 75.380961 | N20: =K20+M20 -> 109.17296 | T20: 16 | X20: 8
B21: 9 | C21: 297 | D21: 138829 | E21: 25600 | G21: 128000 | I21: 307200 | J21: =SUM(I21:I21) -> 307200 | K21: =IF(J21>$P$14,$R$15,IF(J21>$P$13,$R$14,$R$13))*J21 -> 58.368 | L21: =IF(D21>$P$10,$R$11,IF(D21>$P$9,$R$10,IF(D21>$P$8,$R$9,IF(D21>$P$7,$R$8,IF(D21>$P$6,$R$7,IF(D21>$P$5,$R$6,IF(D21>$P$4,$R$5,IF(D21>$P$3,$R$4,IF(D21>$P$2,$R$3,$R$2))))))))) -> 0.00097222222 | M21: =D21*L21 -> 134.97264 | N21: =K21+M21 -> 193.34064 | T21: 18 | X21: 9
B22: 10 | C22: 524 | D22: 281129 | E22: 51200 | G22: 256000 | I22: 614400 | J22: =SUM(I22:I22) -> 614400 | K22: =IF(J22>$P$14,$R$15,IF(J22>$P$13,$R$14,$R$13))*J22 -> 116.736 | L22: =IF(D22>$P$10,$R$11,IF(D22>$P$9,$R$10,IF(D22>$P$8,$R$9,IF(D22>$P$7,$R$8,IF(D22>$P$6,$R$7,IF(D22>$P$5,$R$6,IF(D22>$P$4,$R$5,IF(D22>$P$3,$R$4,IF(D22>$P$2,$R$3,$R$2))))))))) -> 0.00079571759 | M22: =D22*L22 -> 223.69929 | N22: =K22+M22 -> 340.43529 | T22: 20 | X22: 10
B23: total | C23: =SUM(C13:C22) -> 1217 | D23: =SUM(D13:D22) -> 554919 | E23: =SUM(E13:E22) -> 102300 | F23: =SUM(F13:F22) -> 0 | G23: =SUM(G13:G22) -> 511500 | H23: =SUM(H13:H22) -> 0 | I23: =SUM(I13:I22) -> 1227600 | J23: =SUM(I23:I23) -> 1227600 | K23: =IF(J23>$P$14,$R$15,IF(J23>$P$13,$R$14,$R$13))*J23 -> 233.244 | L23: =IF(D23>$P$10,$R$11,IF(D23>$P$9,$R$10,IF(D23>$P$8,$R$9,IF(D23>$P$7,$R$8,IF(D23>$P$6,$R$7,IF(D23>$P$5,$R$6,IF(D23>$P$4,$R$5,IF(D23>$P$3,$R$4,IF(D23>$P$2,$R$3,$R$2))))))))) -> 0.00079571759 | M23: =D23*L23 -> 441.55881 | N23: =K23+M23 -> 674.80281
A24: Masonry | B24: 1 | C24: 6 | D24: 529 | E24: 200 | H24: 500 | I24: 1500 | J24: =SUM(I24:I24) -> 1500 | K24: =IF(J24>$P$14,$R$15,IF(J24>$P$13,$R$14,$R$13))*J24 -> 0.375 | L24: =IF(D24>$P$10,$R$11,IF(D24>$P$9,$R$10,IF(D24>$P$8,$R$9,IF(D24>$P$7,$R$8,IF(D24>$P$6,$R$7,IF(D24>$P$5,$R$6,IF(D24>$P$4,$R$5,IF(D24>$P$3,$R$4,IF(D24>$P$2,$R$3,$R$2))))))))) -> 0.0055555556 | M24: =D24*L24 -> 2.9388889 | N24: =K24+M24 -> 3.3138889 | T24: 2 | Y24: 1
B25: 2 | C25: 8 | D25: 1071 | E25: =E24*2 -> 400 | H25: =H24*2 -> 1000 | I25: =I24*2 -> 3000 | J25: =SUM(I25:I25) -> 3000 | K25: =IF(J25>$P$14,$R$15,IF(J25>$P$13,$R$14,$R$13))*J25 -> 0.75 | L25: =IF(D25>$P$10,$R$11,IF(D25>$P$9,$R$10,IF(D25>$P$8,$R$9,IF(D25>$P$7,$R$8,IF(D25>$P$6,$R$7,IF(D25>$P$5,$R$6,IF(D25>$P$4,$R$5,IF(D25>$P$3,$R$4,IF(D25>$P$2,$R$3,$R$2))))))))) -> 0.0027777778 | M25: =D25*L25 -> 2.975 | N25: =K25+M25 -> 3.725 | T25: 4 | Y25: 2
B26: 3 | C26: 12 | D26: 2169 | E26: =E25*2 -> 800 | H26: =H25*2 -> 2000 | I26: =I25*2 -> 6000 | J26: =SUM(I26:I26) -> 6000 | K26: =IF(J26>$P$14,$R$15,IF(J26>$P$13,$R$14,$R$13))*J26 -> 1.5 | L26: =IF(D26>$P$10,$R$11,IF(D26>$P$9,$R$10,IF(D26>$P$8,$R$9,IF(D26>$P$7,$R$8,IF(D26>$P$6,$R$7,IF(D26>$P$5,$R$6,IF(D26>$P$4,$R$5,IF(D26>$P$3,$R$4,IF(D26>$P$2,$R$3,$R$2))))))))) -> 0.0027777778 | M26: =D26*L26 -> 6.025 | N26: =K26+M26 -> 7.525 | T26: 6 | Y26: 3
B27: 4 | C27: 17 | D27: 4392 | E27: =E26*2 -> 1600 | H27: =H26*2 -> 4000 | I27: =I26*2 -> 12000 | J27: =SUM(I27:I27) -> 12000 | K27: =IF(J27>$P$14,$R$15,IF(J27>$P$13,$R$14,$R$13))*J27 -> 3 | L27: =IF(D27>$P$10,$R$11,IF(D27>$P$9,$R$10,IF(D27>$P$8,$R$9,IF(D27>$P$7,$R$8,IF(D27>$P$6,$R$7,IF(D27>$P$5,$R$6,IF(D27>$P$4,$R$5,IF(D27>$P$3,$R$4,IF(D27>$P$2,$R$3,$R$2))))))))) -> 0.0016666667 | M27: =D27*L27 -> 7.32 | N27: =K27+M27 -> 10.32 | T27: 8 | Y27: 4
B28: 5 | C28: 28 | D28: 8895 | E28: =E27*2 -> 3200 | H28: =H27*2 -> 8000 | I28: =I27*2 -> 24000 | J28: =SUM(I28:I28) -> 24000 | K28: =IF(J28>$P$14,$R$15,IF(J28>$P$13,$R$14,$R$13))*J28 -> 6 | L28: =IF(D28>$P$10,$R$11,IF(D28>$P$9,$R$10,IF(D28>$P$8,$R$9,IF(D28>$P$7,$R$8,IF(D28>$P$6,$R$7,IF(D28>$P$5,$R$6,IF(D28>$P$4,$R$5,IF(D28>$P$3,$R$4,IF(D28>$P$2,$R$3,$R$2))))))))) -> 0.0016666667 | M28: =D28*L28 -> 14.825 | N28: =K28+M28 -> 20.825 | T28: 10 | Y28: 5
B29: 6 | C29: 52 | D29: 18012 | E29: =E28*2 -> 6400 | H29: =H28*2 -> 16000 | I29: =I28*2 -> 48000 | J29: =SUM(I29:I29) -> 48000 | K29: =IF(J29>$P$14,$R$15,IF(J29>$P$13,$R$14,$R$13))*J29 -> 12 | L29: =IF(D29>$P$10,$R$11,IF(D29>$P$9,$R$10,IF(D29>$P$8,$R$9,IF(D29>$P$7,$R$8,IF(D29>$P$6,$R$7,IF(D29>$P$5,$R$6,IF(D29>$P$4,$R$5,IF(D29>$P$3,$R$4,IF(D29>$P$2,$R$3,$R$2))))))))) -> 0.0013888889 | M29: =D29*L29 -> 25.016667 | N29: =K29+M29 -> 37.016667 | T29: 12 | Y29: 6
B30: 7 | C30: 99 | D30: 36475 | E30: =E29*2 -> 12800 | H30: =H29*2 -> 32000 | I30: =I29*2 -> 96000 | J30: =SUM(I30:I30) -> 96000 | K30: =IF(J30>$P$14,$R$15,IF(J30>$P$13,$R$14,$R$13))*J30 -> 21.12 | L30: =IF(D30>$P$10,$R$11,IF(D30>$P$9,$R$10,IF(D30>$P$8,$R$9,IF(D30>$P$7,$R$8,IF(D30>$P$6,$R$7,IF(D30>$P$5,$R$6,IF(D30>$P$4,$R$5,IF(D30>$P$3,$R$4,IF(D30>$P$2,$R$3,$R$2))))))))) -> 0.0012037037 | M30: =D30*L30 -> 43.905093 | N30: =K30+M30 -> 65.025093 | T30: 14 | Y30: 7
B31: 8 | C31: 167 | D31: 73863 | E31: =E30*2 -> 25600 | H31: =H30*2 -> 64000 | I31: =I30*2 -> 192000 | J31: =SUM(I31:I31) -> 192000 | K31: =IF(J31>$P$14,$R$15,IF(J31>$P$13,$R$14,$R$13))*J31 -> 42.24 | L31: =IF(D31>$P$10,$R$11,IF(D31>$P$9,$R$10,IF(D31>$P$8,$R$9,IF(D31>$P$7,$R$8,IF(D31>$P$6,$R$7,IF(D31>$P$5,$R$6,IF(D31>$P$4,$R$5,IF(D31>$P$3,$R$4,IF(D31>$P$2,$R$3,$R$2))))))))) -> 0.001099537 | M31: =D31*L31 -> 81.215104 | N31: =K31+M31 -> 123.4551 | T31: 16 | Y31: 8
B32: 9 | C32: 293 | D32: 149573 | E32: =E31*2 -> 51200 | H32: =H31*2 -> 128000 | I32: =I31*2 -> 384000 | J32: =SUM(I32:I32) -> 384000 | K32: =IF(J32>$P$14,$R$15,IF(J32>$P$13,$R$14,$R$13))*J32 -> 72.96 | L32: =IF(D32>$P$10,$R$11,IF(D32>$P$9,$R$10,IF(D32>$P$8,$R$9,IF(D32>$P$7,$R$8,IF(D32>$P$6,$R$7,IF(D32>$P$5,$R$6,IF(D32>$P$4,$R$5,IF(D32>$P$3,$R$4,IF(D32>$P$2,$R$3,$R$2))))))))) -> 0.00097222222 | M32: =D32*L32 -> 145.41819 | N32: =K32+M32 -> 218.37819 | T32: 18 | Y32: 9
B33: 10 | C33: 610 | D33: 302887 | E33: =E32*2 -> 102400 | H33: =H32*2 -> 256000 | I33: =I32*2 -> 768000 | J33: =SUM(I33:I33) -> 768000 | K33: =IF(J33>$P$14,$R$15,IF(J33>$P$13,$R$14,$R$13))*J33 -> 145.92 | L33: =IF(D33>$P$10,$R$11,IF(D33>$P$9,$R$10,IF(D33>$P$8,$R$9,IF(D33>$P$7,$R$8,IF(D33>$P$6,$R$7,IF(D33>$P$5,$R$6,IF(D33>$P$4,$R$5,IF(D33>$P$3,$R$4,IF(D33>$P$2,$R$3,$R$2))))))))) -> 0.00079571759 | M33: =D33*L33 -> 241.01251 | N33: =K33+M33 -> 386.93251 | T33: 20 | Y33: 10
B34: total | C34: =SUM(C24:C33) -> 1292 | D34: =SUM(D24:D33) -> 597866 | E34: =SUM(E24:E33) -> 204600 | F34: =SUM(F24:F33) -> 0 | G34: =SUM(G24:G33) -> 0 | H34: =SUM(H24:H33) -> 511500 | I34: =SUM(I24:I33) -> 1534500 | J34: =SUM(I34:I34) -> 1534500 | K34: =IF(J34>$P$14,$R$15,IF(J34>$P$13,$R$14,$R$13))*J34 -> 291.555 | L34: =IF(D34>$P$10,$R$11,IF(D34>$P$9,$R$10,IF(D34>$P$8,$R$9,IF(D34>$P$7,$R$8,IF(D34>$P$6,$R$7,IF(D34>$P$5,$R$6,IF(D34>$P$4,$R$5,IF(D34>$P$3,$R$4,IF(D34>$P$2,$R$3,$R$2))))))))) -> 0.00079571759 | M34: =D34*L34 -> 475.73249 | N34: =K34+M34 -> 767.28749
A35: Mining | B35: 1 | C35: 6 | D35: 598 | E35: 800 | I35: 2000 | J35: =SUM(I35:I35) -> 2000 | K35: =IF(J35>$P$14,$R$15,IF(J35>$P$13,$R$14,$R$13))*J35 -> 0.5 | L35: =IF(D35>$P$10,$R$11,IF(D35>$P$9,$R$10,IF(D35>$P$8,$R$9,IF(D35>$P$7,$R$8,IF(D35>$P$6,$R$7,IF(D35>$P$5,$R$6,IF(D35>$P$4,$R$5,IF(D35>$P$3,$R$4,IF(D35>$P$2,$R$3,$R$2))))))))) -> 0.0055555556 | M35: =D35*L35 -> 3.3222222 | N35: =K35+M35 -> 3.8222222 | T35: 2 | Z35: 1
B36: 2 | C36: 9 | D36: 1210 | E36: =E35*2 -> 1600 | I36: =I35*2 -> 4000 | J36: =SUM(I36:I36) -> 4000 | K36: =IF(J36>$P$14,$R$15,IF(J36>$P$13,$R$14,$R$13))*J36 -> 1 | L36: =IF(D36>$P$10,$R$11,IF(D36>$P$9,$R$10,IF(D36>$P$8,$R$9,IF(D36>$P$7,$R$8,IF(D36>$P$6,$R$7,IF(D36>$P$5,$R$6,IF(D36>$P$4,$R$5,IF(D36>$P$3,$R$4,IF(D36>$P$2,$R$3,$R$2))))))))) -> 0.0027777778 | M36: =D36*L36 -> 3.3611111 | N36: =K36+M36 -> 4.3611111 | T36: 4 | Z36: 2
B37: 3 | C37: 13 | D37: 2452 | E37: =E36*2 -> 3200 | I37: =I36*2 -> 8000 | J37: =SUM(I37:I37) -> 8000 | K37: =IF(J37>$P$14,$R$15,IF(J37>$P$13,$R$14,$R$13))*J37 -> 2 | L37: =IF(D37>$P$10,$R$11,IF(D37>$P$9,$R$10,IF(D37>$P$8,$R$9,IF(D37>$P$7,$R$8,IF(D37>$P$6,$R$7,IF(D37>$P$5,$R$6,IF(D37>$P$4,$R$5,IF(D37>$P$3,$R$4,IF(D37>$P$2,$R$3,$R$2))))))))) -> 0.0027777778 | M37: =D37*L37 -> 6.8111111 | N37: =K37+M37 -> 8.8111111 | T37: 6 | Z37: 3
B38: 4 | C38: 23 | D38: 4965 | E38: =E37*2 -> 6400 | I38: =I37*2 -> 16000 | J38: =SUM(I38:I38) -> 16000 | K38: =IF(J38>$P$14,$R$15,IF(J38>$P$13,$R$14,$R$13))*J38 -> 4 | L38: =IF(D38>$P$10,$R$11,IF(D38>$P$9,$R$10,IF(D38>$P$8,$R$9,IF(D38>$P$7,$R$8,IF(D38>$P$6,$R$7,IF(D38>$P$5,$R$6,IF(D38>$P$4,$R$5,IF(D38>$P$3,$R$4,IF(D38>$P$2,$R$3,$R$2))))))))) -> 0.0016666667 | M38: =D38*L38 -> 8.275 | N38: =K38+M38 -> 12.275 | T38: 8 | Z38: 4
B39: 5 | C39: 42 | D39: 10055 | E39: =E38*2 -> 12800 | I39: =I38*2 -> 32000 | J39: =SUM(I39:I39) -> 32000 | K39: =IF(J39>$P$14,$R$15,IF(J39>$P$13,$R$14,$R$13))*J39 -> 8 | L39: =IF(D39>$P$10,$R$11,IF(D39>$P$9,$R$10,IF(D39>$P$8,$R$9,IF(D39>$P$7,$R$8,IF(D39>$P$6,$R$7,IF(D39>$P$5,$R$6,IF(D39>$P$4,$R$5,IF(D39>$P$3,$R$4,IF(D39>$P$2,$R$3,$R$2))))))))) -> 0.0013888889 | M39: =D39*L39 -> 13.965278 | N39: =K39+M39 -> 21.965278 | T39: 10 | Z39: 5
B40: 6 | C40: 59 | D40: 20362 | E40: =E39*2 -> 25600 | I40: =I39*2 -> 64000 | J40: =SUM(I40:I40) -> 64000 | K40: =IF(J40>$P$14,$R$15,IF(J40>$P$13,$R$14,$R$13))*J40 -> 16 | L40: =IF(D40>$P$10,$R$11,IF(D40>$P$9,$R$10,IF(D40>$P$8,$R$9,IF(D40>$P$7,$R$8,IF(D40>$P$6,$R$7,IF(D40>$P$5,$R$6,IF(D40>$P$4,$R$5,IF(D40>$P$3,$R$4,IF(D40>$P$2,$R$3,$R$2))))))))) -> 0.0013888889 | M40: =D40*L40 -> 28.280556 | N40: =K40+M40 -> 44.280556 | T40: 12 | Z40: 6
...

Sheet 将领
A1: 建筑等级 | B1: 刷新出将领数量 | D1: 将领lv | E1: 需要取胜次数 | F1: 攻击加成百分比 | G1: 防御加成百分比 | H1: 花费价钱 | I1: 出现权重 | J1: 几率 | K1: 20级期望出现个数
A2: 1 | B2: 1 | D2: 1 | E2: 0 | F2: 5 | G2: 10 | H2: 1000 | I2: 50 | J2: =I2/$I$22 -> 0.5 | K2: =$B$21*J2 -> 2.5
A3: 2 | B3: 1 | D3: 2 | E3: 3 | F3: 5.5 | G3: 10.5 | H3: 2000 | I3: 20 | J3: =I3/$I$22 -> 0.2 | K3: =$B$21*J3 -> 1
A4: 3 | B4: 1 | D4: 3 | E4: 8 | F4: 6 | G4: 11 | H4: 3000 | I4: 10 | J4: =I4/$I$22 -> 0.1 | K4: =$B$21*J4 -> 0.5
A5: 4 | B5: 1 | D5: 4 | E5: 15 | F5: 6.5 | G5: 11.5 | H5: 4000 | I5: 5 | J5: =I5/$I$22 -> 0.05 | K5: =$B$21*J5 -> 0.25
