Workbook
Name Alliance: 'Reward and Cost'!$DC$4:$DC$7
Name Battle: 'Reward and Cost'!$CZ$4:$CZ$10
Name Casino: 'Reward and Cost'!$CX$4:$CX$5
Name CATEGORY: 'Reward and Cost'!$CS$4:$CS$18
Name Construction: 'Reward and Cost'!$CV$4:$CV$7
Name Construction_BuildingCost_Food: Construction!$J$3
Name Construction_BuildingCost_Ore: Construction!$I$3
Name Construction_BuildingCost_Stone: Construction!$G$3
Name Construction_BuildingCost_Wood: Construction!$H$3
Name Construction_BuildingReward_HeroXP: Construction!$E$2
Name Construction_BuildingReward_Power: Construction!$F$2
Name Construction_Name_and_Level: Construction!$B$2
Name Construction_ProtectedAmountOfEachRssByStorehouse: Construction!$Y$3
Name Construction_QuestReward_Food: Construction!$P$3
Name Construction_QuestReward_HeroXP: Construction!$K$3
Name Construction_QuestReward_Ore: Construction!$O$3
Name Construction_QuestReward_Power: Construction!$L$3
Name Construction_QuestReward_Silver: Construction!$Q$3
Name Construction_QuestReward_Stone: Construction!$M$3
Name Construction_QuestReward_Wood: Construction!$N$3
Name Construction_Time: Construction!$C$2
Name Craft: 'Reward and Cost'!$DA$4:$DA$9
Name Event: 'Reward and Cost'!$DE$4:$DE$6
Name Friend: 'Reward and Cost'!$DD$4:$DD$6
Name Gift: 'Reward and Cost'!$CU$4:$CU$8
Name Level_Up: 'Reward and Cost'!$DB$4:$DB$5
Name Quest: 'Reward and Cost'!$CT$4:$CT$15
Name Research: 'Reward and Cost'!$CW$4:$CW$10
Name Research_Name_and_Level: Research!$C$2
Name Research_QuestReward_Food: Research!$R$3
Name Research_QuestReward_HeroXP: Research!$M$3
Name Research_QuestReward_Ore: Research!$Q$3
Name Research_QuestReward_Power: Research!$N$3
Name Research_QuestReward_Silver: Research!$S$3
Name Research_QuestReward_Stone: Research!$O$3
Name Research_QuestReward_Wood: Research!$P$3
Name Research_Research_Name_and_Level: Research!$C$2
Name Research_ResearchCost_Food: Research!$K$3
Name Research_ResearchCost_Ore: Research!$J$3
Name Research_ResearchCost_Silver: Research!$L$3
Name Research_ResearchCost_Stone: Research!$H$3
Name Research_ResearchCost_Wood: Research!$I$3
Name Research_ResearchReward_HeroXP: Research!$F$3
Name Research_ResearchReward_Power: Research!$G$3
Name Research_Time: Research!$D$2
Name Store: 'Reward and Cost'!$DF$4:$DF$8
Name Training: 'Reward and Cost'!$CY$4:$CY$30
Name Troop_Name: Troop!$B$2
Name Troop_TrainingCost_Food: Troop!$O$3
Name Troop_TrainingCost_Ore: Troop!$N$3
Name Troop_TrainingCost_Silver: Troop!$P$3
Name Troop_TrainingCost_Stone: Troop!$L$3
Name Troop_TrainingCost_Wood: Troop!$M$3
Name Troop_TrainingReward_Power: Troop!$AK$3

Sheet Reward and Cost
D1: 0.019212963
B2: CATEGORY | C2: CLASS | D2: DETAIL | E2: Hero | J2: Power Gained | K2: VIP | N2: Currency - Gold | Q2: Free Time | R2: Help Time | S2: Speed Up Gained or Possessed | AF2: Accumulative Speed Up Time Got | AI2: Accumulative Speed Up Time Used | AJ2: Speed Up Time Left | AK2: Construction Time | AN2: Speed Up Time Used | AO2: Construction Time - Free Time - Help Time - Speed Up Time | AP2: Research Time | AS2: Speed Up Time Used | AT2: Research Time - Help Time - Speed Up Time | AU2: Resources Gained or Consumed | AZ2: Resources Output (1/Hour) | BE2: Upkeep | BF2: City Capacity | BK2: Core Constructions | BM2: Resource Constructions | BX2: Battle Constructions | CC2: Technology Constructions | CD2: Crafting Constructions | CE2: Alliance Constructions | CH2: Hero Constructions | CK2: Gold Construction | CL2: Alliance Currencies | CN2: Casino | CR2: Pull Down Menu | CS2: CATEGORY | CT2: CLASS
E3: Level | F3: Exp Modifier | G3: Original Exp | H3: Exp Actually Gained | I3: Skill Points | K3: Level | L3: Point | M3: Amount of Time | N3: Possessing Gold | O3: Cumulatively Used Gold | P3: Cumulatively Got Gold | S3: 0.00069444444 | T3: 0.0020833333 | U3: 0.0034722222 | V3: 0.0069444444 | W3: 0.010416667 | X3: 0.041666667 | Y3: 0.125 | Z3: 0.33333333 | AA3: 0.625 | AB3: 1 | AC3: 3 | AD3: 25% Time Off | AE3: 50% Time Off | AF3: Got for Free | AG3: Bought | AH3: Sum | AK3: Construction Acceleration | AL3: Original Time | AM3: Actual Time | AP3: Research Acceleration | AQ3: Original Time | AR3: Actual Time | AU3: Stone | AV3: Wood | AW3: Ore | AX3: Food | AY3: Silver | AZ3: Stone | BA3: Wood | BB3: Ore | BC3: Food | BD3: Silver | BE3: Food | BF3: Stone | BG3: Wood | BH3: Ore | BI3: Food | BJ3: Silver | BK3: Stronghold Lv. | BL3: Walls Lv. | BM3: Storehouse Lv. | BN3: Farm Max Lv. | BO3: Farm Num | BP3: Logging Camp Max Lv. | BQ3: Logging Camp Num | BR3: Quarry Max Lv. | BS3: Quarry Num | BT3: Mine Max Lv. | BU3: Mine Num | BV3: Villa Max Lv. | BW3: Villa Num | BX3: Barracks Max Lv. | BY3: Barracks Num | BZ3: Hospital Max Lv. | CA3: Hospital Num | CB3: Watchtower Lv. | CC3: Academy | CD3: Forge | CE3: Marketplace | CF3: Embassy Lv. | CG3: Hall of War Lv. | CH3: Gymnos Lv. | CI3: Prison Lv. | CJ3: Altar Lv. | CK3: Gold Mine | CL3: Loyalty | CM3: Funds | CN3: Chips | CT3: Quest | CU3: Gift | CV3: Construction | CW3: Research | CX3: Casino | CY3: Training | CZ3: Battle | DA3: Craft | DB3: Level_Up | DC3: Alliance | DD3: Friend | DE3: Event | DF3: Store
B4: Initial | D4: Hero Level 1 | E4: 1 | F4: 0 | G4: — | H4: 0 | I4: 1 | J4: 30 | K4: 1 | M4: 0 | N4: 100 | O4: 0 | P4: 100 | Q4: 0.0034722222 | R4: 0.0034722222 | S4: 0 | T4: 0 | U4: 0 | V4: 0 | W4: 0 | X4: 0 | Y4: 0 | Z4: 0 | AA4: 0 | AB4: 0 | AC4: 0 | AD4: 0 | AE4: 0 | AF4: 0 | AG4: 0 | AH4: =AF4+AG4 -> 0 | AI4: 0 | AJ4: =S$3*S4+T$3*T4+U$3*U4+V$3*V4+W$3*W4+X$3*X4+Y$3*Y4+Z$3*Z4+AA$3*AA4+AB$3*AB4+AC$3*AC4 -> 0 | AK4: 0 | AL4: — | AM4: — | AN4: — | AO4: — | AP4: 0 | AQ4: — | AR4: — | AS4: — | AT4: — | AU4: 20000 | AV4: 20000 | AW4: 20000 | AX4: 20000 | AY4: 20000 | AZ4: 0 | BA4: 0 | BB4: 0 | BC4: 0 | BD4: 0 | BE4: 0 | BF4: 0 | BG4: 0 | BH4: 0 | BI4: 0 | BJ4: 0 | BK4: 1 | BL4: 1 | BM4: 1 | BN4: 0 | BO4: 0 | BP4: 0 | BQ4: 0 | BR4: 0 | BS4: 0 | BT4: 0 | BU4: 0 | BV4: 0 | BW4: 0 | BX4: 0 | BY4: 0 | BZ4: 1 | CA4: 1 | CB4: 1 | CC4: 0 | CD4: 0 | CL4: 0 | CN4: — | CS4: Quest | CT4: Initially Completed | CU4: Special | CV4: by Quest | CW4: by Quest | CY4: Swordsmen | CZ4: Field Occupy | DA4: Weapons | DC4: Alliance Gift | DD4: Gold from Friends | DE4: Building Traps | DF4: Buy Speed Ups
B5: Construction | C5: by Quest | D5: Farm 1 | E5: 1 | F5: 0 | G5: =VLOOKUP($D5,Construction!$B:$E,(COLUMN(Construction_BuildingReward_HeroXP)-COLUMN(Construction_Name_and_Level)+1),FALSE) -> 10 | H5: =G5*(1+F5) -> 10 | J5: =VLOOKUP($D5,Construction!$B:$F,(COLUMN(Construction_BuildingReward_Power)-COLUMN(Construction_Name_and_Level)+1),FALSE) -> 5 | Q5: 0.0034722222 | R5: 0.0034722222 | AJ5: =AJ4+(S$3*S5+T$3*T5+U$3*U5+V$3*V5+W$3*W5+X$3*X5+Y$3*Y5+Z$3*Z5+AA$3*AA5+AB$3*AB5+AC$3*AC5) -> 0 | AK5: 0 | AL5: =VLOOKUP($D5,Construction!$B:$C,(COLUMN(Construction_Time)-COLUMN(Construction_Name_and_Level)+1),FALSE) -> 0.00069444444 | AM5: =AL5/(1+AK5) -> 0.00069444444 | AN5: =(S$3*S5+T$3*T5+V$3*V5+W$3*W5+X$3*X5+Y$3*Y5+Z$3*Z5+AA$3*AA5+AB$3*AB5+AC$3*AC5)*(-1) -> 0 | AO5: =IF((AM5-Q5-R5-AN5)>=0,AM5-Q5-R5-AN5,0) -> 0 | AU5: =VLOOKUP($D5,Construction!$B:$J,(COLUMN(Construction_BuildingCost_Stone)-COLUMN(Construction_Name_and_Level)+1),FALSE)*(-1) -> -100 | AV5: =VLOOKUP($D5,Construction!$B:$J,(COLUMN(Construction_BuildingCost_Wood)-COLUMN(Construction_Name_and_Level)+1),FALSE)*(-1) -> -100 | AW5: =VLOOKUP($D5,Construction!$B:$J,(COLUMN(Construction_BuildingCost_Ore)-COLUMN(Construction_Name_and_Level)+1),FALSE)*(-1) -> -100 | AX5: =VLOOKUP($D5,Construction!$B:$J,(COLUMN(Construction_BuildingCost_Food)-COLUMN(Construction_Name_and_Level)+1),FALSE)*(-1) -> 0 | CS5: Gift | CT5: Special | CU5: Online Reward | CV5: at Will | CW5: at Will | CY5: Slingers | CZ5: Scouting | DA5: Helmets | DC5: Alliance Store | DF5: Buy Resources
B6: Quest | C6: Construction Recommended | D6: Farm 1 | E6: 1 | F6: 0 | G6: =VLOOKUP($D6,Construction!$B:$L,(COLUMN(Construction_QuestReward_HeroXP)-COLUMN(Construction_Name_and_Level)+1),FALSE) -> 2525 | H6: =G6*(1+F6) -> 2525 | J6: =VLOOKUP($D6,Construction!$B:$L,(COLUMN(Construction_QuestReward_Power)-COLUMN(Construction_Name_and_Level)+1),FALSE) -> 2 | AJ6: =AJ5+(S$3*S6+T$3*T6+U$3*U6+V$3*V6+W$3*W6+X$3*X6+Y$3*Y6+Z$3*Z6+AA$3*AA6+AB$3*AB6+AC$3*AC6) -> 0 | AU6: =VLOOKUP($D6,Construction!$B:$Q,(COLUMN(Construction_QuestReward_Stone)-COLUMN(Construction_Name_and_Level)+1),FALSE) -> 0 | AV6: =VLOOKUP($D6,Construction!$B:$Q,(COLUMN(Construction_QuestReward_Wood)-COLUMN(Construction_Name_and_Level)+1),FALSE) -> 0 | AW6: =VLOOKUP($D6,Construction!$B:$Q,(COLUMN(Construction_QuestReward_Ore)-COLUMN(Construction_Name_and_Level)+1),FALSE) -> 0 | AX6: =VLOOKUP($D6,Construction!$B:$Q,(COLUMN(Construction_QuestReward_Food)-COLUMN(Construction_Name_and_Level)+1),FALSE) -> 3000 | AY6: =VLOOKUP($D6,Construction!$B:$Q,(COLUMN(Construction_QuestReward_Silver)-COLUMN(Construction_Name_and_Level)+1),FALSE) -> 0 | CS6: Construction | CT6: Daily Quest | CU6: Stronghold upgrade Event | CV6: Deconstruct | CY6: Outriders | CZ6: Attack Players | DA6: Armors | DC6: Resource Help | DF6: Buy Special
B7: Construction | C7: by Quest | D7: Stronghold 2 | E7: 1 | F7: 0 | G7: =VLOOKUP($D7,Construction!$B:$E,(COLUMN(Construction_BuildingReward_HeroXP)-COLUMN(Construction_Name_and_Level)+1),FALSE) -> 5000 | H7: =G7*(1+F7) -> 5000 | J7: =VLOOKUP($D7,Construction!$B:$F,(COLUMN(Construction_BuildingReward_Power)-COLUMN(Construction_Name_and_Level)+1),FALSE) -> 150 | Q7: 0.0034722222 | R7: 0.0041666667 | AJ7: =AJ6+(S$3*S7+T$3*T7+U$3*U7+V$3*V7+W$3*W7+X$3*X7+Y$3*Y7+Z$3*Z7+AA$3*AA7+AB$3*AB7+AC$3*AC7) -> 0 | AK7: 0 | AL7: =VLOOKUP($D7,Construction!$B:$C,(COLUMN(Construction_Time)-COLUMN(Construction_Name_and_Level)+1),FALSE) -> 0.0032407407 | AM7: =AL7/(1+AK7) -> 0.0032407407 | AN7: =(S$3*S7+T$3*T7+V$3*V7+W$3*W7+X$3*X7+Y$3*Y7+Z$3*Z7+AA$3*AA7+AB$3*AB7+AC$3*AC7)*(-1) -> 0 | AO7: =IF((AM7-Q7-R7-AN7)>=0,AM7-Q7-R7-AN7,0) -> 0 | AU7: =VLOOKUP($D7,Construction!$B:$J,(COLUMN(Construction_BuildingCost_Stone)-COLUMN(Construction_Name_and_Level)+1),FALSE)*(-1) -> -1800 | AV7: =VLOOKUP($D7,Construction!$B:$J,(COLUMN(Construction_BuildingCost_Wood)-COLUMN(Construction_Name_and_Level)+1),FALSE)*(-1) -> -1800 | AW7: =VLOOKUP($D7,Construction!$B:$J,(COLUMN(Construction_BuildingCost_Ore)-COLUMN(Construction_Name_and_Level)+1),FALSE)*(-1) -> -720 | AX7: =VLOOKUP($D7,Construction!$B:$J,(COLUMN(Construction_BuildingCost_Food)-COLUMN(Construction_Name_and_Level)+1),FALSE)*(-1) -> -900 | CS7: Research | CT7: Construction Recommended | CU7: Stronghold upgrade Chest | CY7: Battering Ram | CZ7: Attacked by Players | DA7: Accessories | DC7: Alliance Quest | DF7: Buy War Items
B8: Gift | C8: Stronghold upgrade Event | D8: Stronghold 1->2 Event | E8: 1 | AJ8: =AJ7+(S$3*S8+T$3*T8+U$3*U8+V$3*V8+W$3*W8+X$3*X8+Y$3*Y8+Z$3*Z8+AA$3*AA8+AB$3*AB8+AC$3*AC8) -> 0 | AU8: 1900 | AV8: 1900 | AW8: 1900 | AX8: 1500 | AY8: 1600 | CS8: Casino | CT8: Construction at Will | CU8: Hero Level Up | CY8: Hoplites | CZ8: Healing | DA8: Foot Armor | DF8: Buy Treasures
B9: Gift | C9: Special | D9: Beginner's Chest | E9: 1 | V9: 1 | W9: 1 | AF9: =$S$3*$S9+$T$3*$T9+$U$3*$U9+$V$3*$V9+$W$3*$W9+$X$3*$X9+$Y$3*$Y9+$Z$3*$Z9+$AA$3*$AA9+$AB$3*$AB9+$AC$3*$AC9 -> 0.017361111 | AJ9: =AJ8+(S$3*S9+T$3*T9+U$3*U9+V$3*V9+W$3*W9+X$3*X9+Y$3*Y9+Z$3*Z9+AA$3*AA9+AB$3*AB9+AC$3*AC9) -> 0.017361111 | AX9: 5000 | CS9: Training | CT9: Research Recommended | CY9: Skirmish Archers | CZ9: Hero In Jail | DA9: Special Event Gear
B10: Gift | C10: Online Reward | D10: 0.00069444444 | E10: 1 | T10: 1 | AF10: =$S$3*$S10+$T$3*$T10+$U$3*$U10+$V$3*$V10+$W$3*$W10+$X$3*$X10+$Y$3*$Y10+$Z$3*$Z10+$AA$3*$AA10+$AB$3*$AB10+$AC$3*$AC10 -> 0.0020833333 | AJ10: =AJ9+(S$3*S10+T$3*T10+U$3*U10+V$3*V10+W$3*W10+X$3*X10+Y$3*Y10+Z$3*Z10+AA$3*AA10+AB$3*AB10+AC$3*AC10) -> 0.019444444 | CS10: Battle | CT10: Research at Will | CY10: Light Cavalry
B11: Gift | C11: Online Reward | D11: 0.0027777778 | E11: 1 | L11: 100 | AJ11: =AJ10+(S$3*S11+T$3*T11+U$3*U11+V$3*V11+W$3*W11+X$3*X11+Y$3*Y11+Z$3*Z11+AA$3*AA11+AB$3*AB11+AC$3*AC11) -> 0.019444444 | CS11: Craft | CT11: Training Recommended | CY11: Ballista
B12: Casino | E12: 1 | AJ12: =AJ11+(S$3*S12+T$3*T12+U$3*U12+V$3*V12+W$3*W12+X$3*X12+Y$3*Y12+Z$3*Z12+AA$3*AA12+AB$3*AB12+AC$3*AC12) -> 0.019444444 | AY12: 750 | CS12: Friend | CT12: Training at Will | CY12: Armored Pikemen
B13: Gift | C13: Stronghold upgrade Chest | D13: Stronghold 1 Chest | E13: 1 | V13: 1 | W13: 1 | AF13: =$S$3*$S13+$T$3*$T13+$U$3*$U13+$V$3*$V13+$W$3*$W13+$X$3*$X13+$Y$3*$Y13+$Z$3*$Z13+$AA$3*$AA13+$AB$3*$AB13+$AC$3*$AC13 -> 0.017361111 | AJ13: =AJ12+(S$3*S13+T$3*T13+U$3*U13+V$3*V13+W$3*W13+X$3*X13+Y$3*Y13+Z$3*Z13+AA$3*AA13+AB$3*AB13+AC$3*AC13) -> 0.036805556 | AX13: 5000 | CS13: Level_Up | CT13: Increase Production | CY13: Guardians
B14: Gift | C14: Stronghold upgrade Chest | D14: Stronghold 2 Chest | E14: 1 | M14: 0.020833333 | W14: 1 | AF14: =$S$3*$S14+$T$3*$T14+$U$3*$U14+$V$3*$V14+$W$3*$W14+$X$3*$X14+$Y$3*$Y14+$Z$3*$Z14+$AA$3*$AA14+$AB$3*$AB14+$AC$3*$AC14 -> 0.010416667 | AJ14: =AJ13+(S$3*S14+T$3*T14+U$3*U14+V$3*V14+W$3*W14+X$3*X14+Y$3*Y14+Z$3*Z14+AA$3*AA14+AB$3*AB14+AC$3*AC14) -> 0.047222222 | AU14: 1000 | AV14: 1000 | AW14: 1000 | CS14: Alliance | CT14: Hero Upgrade Milestone | CY14: Companion Cavalry
B15: Quest | C15: Construction Recommended | D15: Hospital 1 | E15: 1 | F15: 0 | G15: =VLOOKUP($D15,Construction!$B:$L,(COLUMN(Construction_QuestReward_HeroXP)-COLUMN(Construction_Name_and_Level)+1),FALSE) -> 2525 | H15: =G15*(1+F15) -> 2525 | J15: =VLOOKUP($D15,Construction!$B:$L,(COLUMN(Construction_QuestReward_Power)-COLUMN(Construction_Name_and_Level)+1),FALSE) -> 2 | AJ15: =AJ14+(S$3*S15+T$3*T15+U$3*U15+V$3*V15+W$3*W15+X$3*X15+Y$3*Y15+Z$3*Z15+AA$3*AA15+AB$3*AB15+AC$3*AC15) -> 0.047222222 | AU15: =VLOOKUP($D15,Construction!$B:$Q,(COLUMN(Construction_QuestReward_Stone)-COLUMN(Construction_Name_and_Level)+1),FALSE) -> 5400 | AV15: =VLOOKUP($D15,Construction!$B:$Q,(COLUMN(Construction_QuestReward_Wood)-COLUMN(Construction_Name_and_Level)+1),FALSE) -> 4300 | AW15: =VLOOKUP($D15,Construction!$B:$Q,(COLUMN(Construction_QuestReward_Ore)-COLUMN(Construction_Name_and_Level)+1),FALSE) -> 3300 | AX15: =VLOOKUP($D15,Construction!$B:$Q,(COLUMN(Construction_QuestReward_Food)-COLUMN(Construction_Name_and_Level)+1),FALSE) -> 2700 | AY15: =VLOOKUP($D15,Construction!$B:$Q,(COLUMN(Construction_QuestReward_Silver)-COLUMN(Construction_Name_and_Level)+1),FALSE) -> 50 | CS15: Event | CY15: Siege Tower
B16: Gift | C16: Hero Level Up | D16: Hero 1->2 | E16: 2 | I16: 1 | J16: 57 | AJ16: =AJ15+(S$3*S16+T$3*T16+U$3*U16+V$3*V16+W$3*W16+X$3*X16+Y$3*Y16+Z$3*Z16+AA$3*AA16+AB$3*AB16+AC$3*AC16) -> 0.047222222 | CS16: Store | CY16: Immortals
B17: Level_Up | D17: Hero Level 2 | E17: 2 | F17: 0 | G17: — | H17: 10060 | I17: 2 | J17: 246 | K17: 2 | M17: 0.020833333 | N17: 100 | O17: =SUMIF($B$4:$B16,"<>"&$CS$13,O$4:O16) -> 0 | P17: =SUMIF($B$4:$B16,"<>"&$CS$13,N$4:N16) -> 100 | Q17: 0.0034722222 | R17: 0.0041666667 | S17: 0 | T17: 1 | U17: 0 | V17: 2 | W17: 3 | X17: 0 | Y17: 0 | Z17: 0 | AA17: 0 | AB17: 0 | AC17: 0 | AD17: 0 | AE17: 0 | AF17: =SUMIF($B$4:$B16,"<>"&$CS$13,AF$4:AF16) -> 0.047222222 | AG17: =SUMIF($B$4:$B16,"<>"&$CS$13,AG$4:AG16) -> 0 | AH17: =AF17+AG17 -> 0.047222222 | AI17: =SUMIF($B$4:$B16,"<>"&$CS$13,AI$4:AI16) -> 0 | AJ17: =S$3*S17+T$3*T17+U$3*U17+V$3*V17+W$3*W17+X$3*X17+Y$3*Y17+Z$3*Z17+AA$3*AA17+AB$3*AB17+AC$3*AC17 -> 0.047222222 | AK17: 0 | AL17: — | AM17: — | AN17: — | AO17: — | AP17: 0 | AQ17: — | AR17: — | AS17: — | AT17: — | AU17: 26500 | AV17: 25400 | AW17: 25480 | AX17: 37200 | AY17: 22400 | AZ17: 0 | BA17: 0 | BB17: 0 | BC17: 52 | BD17: 0 | BE17: 0 | BF17: 15000 | BG17: 15000 | BH17: 15000 | BI17: 17500 | BJ17: 15000 | BK17: 2 | BL17: 1 | BM17: 1 | BN17: 1 | BO17: 1 | BP17: 0 | BQ17: 0 | BR17: 0 | BS17: 0 | BT17: 0 | BU17: 0 | BV17: 0 | BW17: 0 | BX17: 0 | BY17: 0 | BZ17: 1 | CA17: 1 | CB17: 1 | CC17: 0 | CD17: 0 | CL17: 0 | CN17: — | CY17: Marksmen
B18: Quest | C18: Initially Completed | D18: Storehouse 1 | E18: 2 | F18: 0 | G18: =VLOOKUP($D18,Construction!$B:$L,(COLUMN(Construction_QuestReward_HeroXP)-COLUMN(Construction_Name_and_Level)+1),FALSE) -> 2525 | H18: =G18*(1+F18) -> 2525 | J18: =VLOOKUP($D18,Construction!$B:$L,(COLUMN(Construction_QuestReward_Power)-COLUMN(Construction_Name_and_Level)+1),FALSE) -> 2 | AJ18: =AJ17+(S$3*S18+T$3*T18+U$3*U18+V$3*V18+W$3*W18+X$3*X18+Y$3*Y18+Z$3*Z18+AA$3*AA18+AB$3*AB18+AC$3*AC18) -> 0.047222222 | AU18: =VLOOKUP($D18,Construction!$B:$Q,(COLUMN(Construction_QuestReward_Stone)-COLUMN(Construction_Name_and_Level)+1),FALSE) -> 4000 | AV18: =VLOOKUP($D18,Construction!$B:$Q,(COLUMN(Construction_QuestReward_Wood)-COLUMN(Construction_Name_and_Level)+1),FALSE) -> 4000 | AW18: =VLOOKUP($D18,Construction!$B:$Q,(COLUMN(Construction_QuestReward_Ore)-COLUMN(Construction_Name_and_Level)+1),FALSE) -> 3000 | AX18: =VLOOKUP($D18,Construction!$B:$Q,(COLUMN(Construction_QuestReward_Food)-COLUMN(Construction_Name_and_Level)+1),FALSE) -> 2100 | AY18: =VLOOKUP($D18,Construction!$B:$Q,(COLUMN(Construction_QuestReward_Silver)-COLUMN(Construction_Name_and_Level)+1),FALSE) -> 100 | CY18: War Elephant
B19: Quest | C19: Initially Completed | D19: Watchtower 1 | E19: 2 | F19: 0 | G19: =VLOOKUP($D19,Construction!$B:$L,(COLUMN(Construction_QuestReward_HeroXP)-COLUMN(Construction_Name_and_Level)+1),FALSE) -> 2525 | H19: =G19*(1+F19) -> 2525 | J19: =VLOOKUP($D19,Construction!$B:$L,(COLUMN(Construction_QuestReward_Power)-COLUMN(Construction_Name_and_Level)+1),FALSE) -> 2 | AJ19: =AJ18+(S$3*S19+T$3*T19+U$3*U19+V$3*V19+W$3*W19+X$3*X19+Y$3*Y19+Z$3*Z19+AA$3*AA19+AB$3*AB19+AC$3*AC19) -> 0.047222222 | AU19: =VLOOKUP($D19,Construction!$B:$Q,(COLUMN(Construction_QuestReward_Stone)-COLUMN(Construction_Name_and_Level)+1),FALSE) -> 2500 | AV19: =VLOOKUP($D19,Construction!$B:$Q,(COLUMN(Construction_QuestReward_Wood)-COLUMN(Construction_Name_and_Level)+1),FALSE) -> 2100 | AW19: =VLOOKUP($D19,Construction!$B:$Q,(COLUMN(Construction_QuestReward_Ore)-COLUMN(Construction_Name_and_Level)+1),FALSE) -> 500 | AX19: =VLOOKUP($D19,Construction!$B:$Q,(COLUMN(Construction_QuestReward_Food)-COLUMN(Construction_Name_and_Level)+1),FALSE) -> 1100 | AY19: =VLOOKUP($D19,Construction!$B:$Q,(COLUMN(Construction_QuestReward_Silver)-COLUMN(Construction_Name_and_Level)+1),FALSE) -> 50 | CY19: Onager
B20: Quest | C20: Construction Recommended | D20: Stronghold 2 | E20: 2 | F20: 0 | G20: =VLOOKUP($D20,Construction!$B:$L,(COLUMN(Construction_QuestReward_HeroXP)-COLUMN(Construction_Name_and_Level)+1),FALSE) -> 2575 | H20: =G20*(1+F20) -> 2575 | J20: =VLOOKUP($D20,Construction!$B:$L,(COLUMN(Construction_QuestReward_Power)-COLUMN(Construction_Name_and_Level)+1),FALSE) -> 30 | W20: 1 | AF20: =$S$3*$S20+$T$3*$T20+$U$3*$U20+$V$3*$V20+$W$3*$W20+$X$3*$X20+$Y$3*$Y20+$Z$3*$Z20+$AA$3*$AA20+$AB$3*$AB20+$AC$3*$AC20 -> 0.010416667 | AJ20: =AJ19+(S$3*S20+T$3*T20+U$3*U20+V$3*V20+W$3*W20+X$3*X20+Y$3*Y20+Z$3*Z20+AA$3*AA20+AB$3*AB20+AC$3*AC20) -> 0.057638889 | AU20: =VLOOKUP($D20,Construction!$B:$Q,(COLUMN(Construction_QuestReward_Stone)-COLUMN(Construction_Name_and_Level)+1),FALSE) -> 4600 | AV20: =VLOOKUP($D20,Construction!$B:$Q,(COLUMN(Construction_QuestReward_Wood)-COLUMN(Construction_Name_and_Level)+1),FALSE) -> 4600 | AW20: =VLOOKUP($D20,Construction!$B:$Q,(COLUMN(Construction_QuestReward_Ore)-COLUMN(Construction_Name_and_Level)+1),FALSE) -> 1800 | AX20: =VLOOKUP($D20,Construction!$B:$Q,(COLUMN(Construction_QuestReward_Food)-COLUMN(Construction_Name_and_Level)+1),FALSE) -> 2300 | AY20: =VLOOKUP($D20,Construction!$B:$Q,(COLUMN(Construction_QuestReward_Silver)-COLUMN(Construction_Name_and_Level)+1),FALSE) -> 400 | CY20: War Bricks
B21: Construction | C21: by Quest | D21: Logging Camp 1 | E21: 2 | F21: 0 | G21: =VLOOKUP($D21,Construction!$B:$E,(COLUMN(Construction_BuildingReward_HeroXP)-COLUMN(Construction_Name_and_Level)+1),FALSE) -> 10 | H21: =G21*(1+F21) -> 10 | J21: =VLOOKUP($D21,Construction!$B:$F,(COLUMN(Construction_BuildingReward_Power)-COLUMN(Construction_Name_and_Level)+1),FALSE) -> 5 | Q21: 0.0034722222 | R21: 0.0041666667 | AJ21: =AJ20+(S$3*S21+T$3*T21+U$3*U21+V$3*V21+W$3*W21+X$3*X21+Y$3*Y21+Z$3*Z21+AA$3*AA21+AB$3*AB21+AC$3*AC21) -> 0.057638889 | AK21: 0 | AL21: =VLOOKUP($D21,Construction!$B:$C,(COLUMN(Construction_Time)-COLUMN(Construction_Name_and_Level)+1),FALSE) -> 0.00069444444 | AM21: =AL21/(1+AK21) -> 0.00069444444 | AN21: =(S$3*S21+T$3*T21+V$3*V21+W$3*W21+X$3*X21+Y$3*Y21+Z$3*Z21+AA$3*AA21+AB$3*AB21+AC$3*AC21)*(-1) -> 0 | AO21: =IF((AM21-Q21-R21-AN21)>=0,AM21-Q21-R21-AN21,0) -> 0 | AU21: =VLOOKUP($D21,Construction!$B:$J,(COLUMN(Construction_BuildingCost_Stone)-COLUMN(Construction_Name_and_Level)+1),FALSE)*(-1) -> -100 | AV21: =VLOOKUP($D21,Construction!$B:$J,(COLUMN(Construction_BuildingCost_Wood)-COLUMN(Construction_Name_and_Level)+1),FALSE)*(-1) -> 0 | AW21: =VLOOKUP($D21,Construction!$B:$J,(COLUMN(Construction_BuildingCost_Ore)-COLUMN(Construction_Name_and_Level)+1),FALSE)*(-1) -> -100 | AX21: =VLOOKUP($D21,Construction!$B:$J,(COLUMN(Construction_BuildingCost_Food)-COLUMN(Construction_Name_and_Level)+1),FALSE)*(-1) -> -100 | CY21: Archer Tower
B22: Quest | C22: Construction Recommended | D22: Logging Camp 1 | E22: 2 | F22: 0 | G22: =VLOOKUP($D22,Construction!$B:$L,(COLUMN(Construction_QuestReward_HeroXP)-COLUMN(Construction_Name_and_Level)+1),FALSE) -> 2525 | H22: =G22*(1+F22) -> 2525 | J22: =VLOOKUP($D22,Construction!$B:$L,(COLUMN(Construction_QuestReward_Power)-COLUMN(Construction_Name_and_Level)+1),FALSE) -> 2 | AJ22: =AJ21+(S$3*S22+T$3*T22+U$3*U22+V$3*V22+W$3*W22+X$3*X22+Y$3*Y22+Z$3*Z22+AA$3*AA22+AB$3*AB22+AC$3*AC22) -> 0.057638889 | AU22: =VLOOKUP($D22,Construction!$B:$Q,(COLUMN(Construction_QuestReward_Stone)-COLUMN(Construction_Name_and_Level)+1),FALSE) -> 0 | AV22: =VLOOKUP($D22,Construction!$B:$Q,(COLUMN(Construction_QuestReward_Wood)-COLUMN(Construction_Name_and_Level)+1),FALSE) -> 3000 | AW22: =VLOOKUP($D22,Construction!$B:$Q,(COLUMN(Construction_QuestReward_Ore)-COLUMN(Construction_Name_and_Level)+1),FALSE) -> 0 | AX22: =VLOOKUP($D22,Construction!$B:$Q,(COLUMN(Construction_QuestReward_Food)-COLUMN(Construction_Name_and_Level)+1),FALSE) -> 0 | AY22: =VLOOKUP($D22,Construction!$B:$Q,(COLUMN(Construction_QuestReward_Silver)-COLUMN(Construction_Name_and_Level)+1),FALSE) -> 0 | CY22: Spikes
B23: Construction | C23: by Quest | D23: Academy 1 | E23: 2 | F23: 0 | G23: =VLOOKUP($D23,Construction!$B:$E,(COLUMN(Construction_BuildingReward_HeroXP)-COLUMN(Construction_Name_and_Level)+1),FALSE) -> 10 | H23: =G23*(1+F23) -> 10 | J23: =VLOOKUP($D23,Construction!$B:$F,(COLUMN(Construction_BuildingReward_Power)-COLUMN(Construction_Name_and_Level)+1),FALSE) -> 35 | Q23: 0.0034722222 | R23: 0.0041666667 | AJ23: =AJ22+(S$3*S23+T$3*T23+U$3*U23+V$3*V23+W$3*W23+X$3*X23+Y$3*Y23+Z$3*Z23+AA$3*AA23+AB$3*AB23+AC$3*AC23) -> 0.057638889 | AK23: 0 | AL23: =VLOOKUP($D23,Construction!$B:$C,(COLUMN(Construction_Time)-COLUMN(Construction_Name_and_Level)+1),FALSE) -> 0.0011574074 | AM23: =AL23/(1+AK23) -> 0.0011574074 | AN23: =(S$3*S23+T$3*T23+V$3*V23+W$3*W23+X$3*X23+Y$3*Y23+Z$3*Z23+AA$3*AA23+AB$3*AB23+AC$3*AC23)*(-1) -> 0 | AO23: =IF((AM23-Q23-R23-AN23)>=0,AM23-Q23-R23-AN23,0) -> 0 | AP23: 0.01 | AU23: =VLOOKUP($D23,Construction!$B:$J,(COLUMN(Construction_BuildingCost_Stone)-COLUMN(Construction_Name_and_Level)+1),FALSE)*(-1) -> -500 | AV23: =VLOOKUP($D23,Construction!$B:$J,(COLUMN(Construction_BuildingCost_Wood)-COLUMN(Construction_Name_and_Level)+1),FALSE)*(-1) -> -500 | AW23: =VLOOKUP($D23,Construction!$B:$J,(COLUMN(Construction_BuildingCost_Ore)-COLUMN(Construction_Name_and_Level)+1),FALSE)*(-1) -> -200 | AX23: =VLOOKUP($D23,Construction!$B:$J,(COLUMN(Construction_BuildingCost_Food)-COLUMN(Construction_Name_and_Level)+1),FALSE)*(-1) -> -300 | CY23: Boiling Tar
B24: Quest | C24: Construction Recommended | D24: Academy 1 | E24: 2 | F24: 0 | G24: =VLOOKUP($D24,Construction!$B:$L,(COLUMN(Construction_QuestReward_HeroXP)-COLUMN(Construction_Name_and_Level)+1),FALSE) -> 2525 | H24: =G24*(1+F24) -> 2525 | J24: =VLOOKUP($D24,Construction!$B:$L,(COLUMN(Construction_QuestReward_Power)-COLUMN(Construction_Name_and_Level)+1),FALSE) -> 5 | AJ24: =AJ23+(S$3*S24+T$3*T24+U$3*U24+V$3*V24+W$3*W24+X$3*X24+Y$3*Y24+Z$3*Z24+AA$3*AA24+AB$3*AB24+AC$3*AC24) -> 0.057638889 | AU24: =VLOOKUP($D24,Construction!$B:$Q,(COLUMN(Construction_QuestReward_Stone)-COLUMN(Construction_Name_and_Level)+1),FALSE) -> 2500 | AV24: =VLOOKUP($D24,Construction!$B:$Q,(COLUMN(Construction_QuestReward_Wood)-COLUMN(Construction_Name_and_Level)+1),FALSE) -> 2500 | AW24: =VLOOKUP($D24,Construction!$B:$Q,(COLUMN(Construction_QuestReward_Ore)-COLUMN(Construction_Name_and_Level)+1),FALSE) -> 1100 | AX24: =VLOOKUP($D24,Construction!$B:$Q,(COLUMN(Construction_QuestReward_Food)-COLUMN(Construction_Name_and_Level)+1),FALSE) -> 1500 | AY24: =VLOOKUP($D24,Construction!$B:$Q,(COLUMN(Construction_QuestReward_Silver)-COLUMN(Construction_Name_and_Level)+1),FALSE) -> 100
B25: Research | C25: by Quest | D25: Scouting 1 | E25: 2 | F25: 0 | G25: =VLOOKUP($D25,Research!$C:$F,(COLUMN(Research_ResearchReward_HeroXP)-COLUMN(Research_Name_and_Level)+1),FALSE) -> 48000 | H25: =G25*(1+F25) -> 48000 | J25: 31 | AJ25: =AJ24+(S$3*S25+T$3*T25+U$3*U25+V$3*V25+W$3*W25+X$3*X25+Y$3*Y25+Z$3*Z25+AA$3*AA25+AB$3*AB25+AC$3*AC25) -> 0.057638889 | AU25: =VLOOKUP($D25,Research!$C:$L,(COLUMN(Research_ResearchCost_Stone)-COLUMN(Research_Name_and_Level)+1),FALSE)*(-1) -> 0 | AV25: =VLOOKUP($D25,Research!$C:$L,(COLUMN(Research_ResearchCost_Wood)-COLUMN(Research_Name_and_Level)+1),FALSE)*(-1) -> 0 | AW25: =VLOOKUP($D25,Research!$C:$L,(COLUMN(Research_ResearchCost_Ore)-COLUMN(Research_Name_and_Level)+1),FALSE)*(-1) -> 0 | AX25: =VLOOKUP($D25,Research!$C:$L,(COLUMN(Research_ResearchCost_Food)-COLUMN(Research_Name_and_Level)+1),FALSE)*(-1) -> 0 | AY25: =VLOOKUP($D25,Research!$C:$L,(COLUMN(Research_ResearchCost_Silver)-COLUMN(Research_Name_and_Level)+1),FALSE)*(-1) -> -225
B26: Gift | C26: Hero Level Up | D26: Hero 2->3 | E26: 3 | I26: 1 | J26: 29 | AJ26: =AJ25+(S$3*S26+T$3*T26+U$3*U26+V$3*V26+W$3*W26+X$3*X26+Y$3*Y26+Z$3*Z26+AA$3*AA26+AB$3*AB26+AC$3*AC26) -> 0.057638889
B27: Level_Up | D27: Hero Level 3 | E27: 3 | F27: 0 | G27: — | H27: 60000 | I27: 3 | J27: 338 | K27: 2 | M27: 0.020833333 | N27: 100 | O27: =SUMIF($B$4:$B26,"<>"&$CS$13,O$4:O26) -> 0 | P27: =SUMIF($B$4:$B26,"<>"&$CS$13,N$4:N26) -> 100 | Q27: 0.0034722222 | R27: 0.0041666667 | S27: 0 | T27: 1 | U27: 0 | V27: 2 | W27: 4 | X27: 0 | Y27: 0 | Z27: 0 | AA27: 0 | AB27: 0 | AC27: 0 | AD27: 0 | AE27: 0 | AF27: =SUMIF($B$4:$B26,"<>"&$CS$13,AF$4:AF26) -> 0.057638889 | AG27: =SUMIF($B$4:$B26,"<>"&$CS$13,AG$4:AG26) -> 0 | AH27: =AF27+AG27 -> 0.057638889 | AI27: =SUMIF($B$4:$B26,"<>"&$CS$13,AI$4:AI26) -> 0 | AJ27: =S$3*S27+T$3*T27+U$3*U27+V$3*V27+W$3*W27+X$3*X27+Y$3*Y27+Z$3*Z27+AA$3*AA27+AB$3*AB27+AC$3*AC27 -> 0.057638889 | AK27: 0 | AL27: — | AM27: — | AN27: — | AO27: — | AP27: 0.01 | AQ27: — | AR27: — | AS27: — | AT27: — | AU27: 39500 | AV27: 41100 | AW27: 31580 | AX27: 43800 | AY27: 23820 | AZ27: 0 | BA27: 42 | BB27: 0 | BC27: 52 | BD27: 0 | BE27: 0 | BF27: 15000 | BG27: 17000 | BH27: 15000 | BI27: 17500 | BJ27: 15000 | BK27: 2 | BL27: 1 | BM27: 1 | BN27: 1 | BO27: 1 | BP27: 1 | BQ27: 1 | BR27: 0 | BS27: 0 | BT27: 0 | BU27: 0 | BV27: 0 | BW27: 0 | BX27: 0 | BY27: 0 | BZ27: 1 | CA27: 1 | CB27: 1 | CC27: 1 | CD27: 0 | CL27: 0 | CN27: —
B28: Gift | C28: Hero Level Up | D28: Hero 3->4 | E28: 4 | I28: 1 | J28: 29 | AJ28: =AJ27+(S$3*S28+T$3*T28+U$3*U28+V$3*V28+W$3*W28+X$3*X28+Y$3*Y28+Z$3*Z28+AA$3*AA28+AB$3*AB28+AC$3*AC28) -> 0.057638889
B29: Level_Up | D29: Hero Level 4 | E29: 4 | F29: 0 | G29: — | H29: 70755 | I29: 4 | J29: 396 | K29: 2 | M29: 0.020833333 | N29: 100 | O29: =SUMIF($B$4:$B28,"<>"&$CS$13,O$4:O28) -> 0 | P29: =SUMIF($B$4:$B28,"<>"&$CS$13,N$4:N28) -> 100 | Q29: 0.0034722222 | R29: 0.0041666667 | S29: 0 | T29: 1 | U29: 0 | V29: 2 | W29: 4 | X29: 0 | Y29: 0 | Z29: 0 | AA29: 0 | AB29: 0 | AC29: 0 | AD29: 0 | AE29: 0 | AF29: =SUMIF($B$4:$B28,"<>"&$CS$13,AF$4:AF28) -> 0.057638889 | AG29: =SUMIF($B$4:$B28,"<>"&$CS$13,AG$4:AG28) -> 0 | AH29: =AF29+AG29 -> 0.057638889 | AI29: =SUMIF($B$4:$B28,"<>"&$CS$13,AI$4:AI28) -> 0 | AJ29: =S$3*S29+T$3*T29+U$3*U29+V$3*V29+W$3*W29+X$3*X29+Y$3*Y29+Z$3*Z29+AA$3*AA29+AB$3*AB29+AC$3*AC29 -> 0.057638889 | AK29: 0 | AL29: — | AM29: — | AN29: — | AO29: — | AP29: 0.01 | AQ29: — | AR29: — | AS29: — | AT29: — | AU29: 39500 | AV29: 41100 | AW29: 31580 | AX29: 43800 | AY29: 23820 | AZ29: 0 | BA29: 42 | BB29: 0 | BC29: 52 | BD29: 0 | BE29: 0 | BF29: 15000 | BG29: 17000 | BH29: 15000 | BI29: 17500 | BJ29: 15000 | BK29: 2 | BL29: 1 | BM29: 1 | BN29: 1 | BO29: 1 | BP29: 1 | BQ29: 1 | BR29: 0 | BS29: 0 | BT29: 0 | BU29: 0 | BV29: 0 | BW29: 0 | BX29: 0 | BY29: 0 | BZ29: 1 | CA29: 1 | CB29: 1 | CC29: 1 | CD29: 0 | CL29: 0 | CN29: —
B30: Quest | C30: Research Recommended | D30: Scouting 1 | E30: 4 | F30: 0 | G30: =VLOOKUP($D30,Research!$C:$M,(COLUMN(Research_QuestReward_HeroXP)-COLUMN(Research_Name_and_Level)+1),FALSE) -> 1000 | H30: =G30*(1+F30) -> 1000 | J30: =VLOOKUP($D30,Research!$C:$N,(COLUMN(Research_QuestReward_Power)-COLUMN(Research_Name_and_Level)+1),FALSE) -> 75 | AJ30: =AJ29+(S$3*S30+T$3*T30+U$3*U30+V$3*V30+W$3*W30+X$3*X30+Y$3*Y30+Z$3*Z30+AA$3*AA30+AB$3*AB30+AC$3*AC30) -> 0.057638889 | AU30: =VLOOKUP($D30,Research!$C:$S,(COLUMN(Research_QuestReward_Stone)-COLUMN(Research_Name_and_Level)+1),FALSE) -> 0 | AV30: =VLOOKUP($D30,Research!$C:$S,(COLUMN(Research_QuestReward_Wood)-COLUMN(Research_Name_and_Level)+1),FALSE) -> 0 | AW30: =VLOOKUP($D30,Research!$C:$S,(COLUMN(Research_QuestReward_Ore)-COLUMN(Research_Name_and_Level)+1),FALSE) -> 0 | AX30: =VLOOKUP($D30,Research!$C:$S,(COLUMN(Research_QuestReward_Food)-COLUMN(Research_Name_and_Level)+1),FALSE) -> 0 | AY30: =VLOOKUP($D30,Research!$C:$S,(COLUMN(Research_QuestReward_Silver)-COLUMN(Research_Name_and_Level)+1),FALSE) -> 387
B31: Construction | C31: at Will | D31: Barracks 1 | E31: 4 | F31: 0 | G31: =VLOOKUP($D31,Construction!$B:$E,(COLUMN(Construction_BuildingReward_HeroXP)-COLUMN(Construction_Name_and_Level)+1),FALSE) -> 10 | H31: =G31*(1+F31) -> 10 | J31: =VLOOKUP($D31,Construction!$B:$F,(COLUMN(Construction_BuildingReward_Power)-COLUMN(Construction_Name_and_Level)+1),FALSE) -> 20 | Q31: 0.0034722222 | R31: 0.0041666667 | AJ31: =AJ30+(S$3*S31+T$3*T31+U$3*U31+V$3*V31+W$3*W31+X$3*X31+Y$3*Y31+Z$3*Z31+AA$3*AA31+AB$3*AB31+AC$3*AC31) -> 0.057638889 | AK31: 0 | AL31: =VLOOKUP($D31,Construction!$B:$C,(COLUMN(Construction_Time)-COLUMN(Construction_Name_and_Level)+1),FALSE) -> 0.0010416667 | AM31: =AL31/(1+AK31) -> 0.0010416667 | AN31: =(S$3*S31+T$3*T31+V$3*V31+W$3*W31+X$3*X31+Y$3*Y31+Z$3*Z31+AA$3*AA31+AB$3*AB31+AC$3*AC31)*(-1) -> 0 | AO31: =IF((AM31-Q31-R31-AN31)>=0,AM31-Q31-R31-AN31,0) -> 0 | AU31: =VLOOKUP($D31,Construction!$B:$J,(COLUMN(Construction_BuildingCost_Stone)-COLUMN(Construction_Name_and_Level)+1),FALSE)*(-1) -> -500 | AV31: =VLOOKUP($D31,Construction!$B:$J,(COLUMN(Construction_BuildingCost_Wood)-COLUMN(Construction_Name_and_Level)+1),FALSE)*(-1) -> -400 | AW31: =VLOOKUP($D31,Construction!$B:$J,(COLUMN(Construction_BuildingCost_Ore)-COLUMN(Construction_Name_and_Level)+1),FALSE)*(-1) -> -300 | AX31: =VLOOKUP($D31,Construction!$B:$J,(COLUMN(Construction_BuildingCost_Food)-COLUMN(Construction_Name_and_Level)+1),FALSE)*(-1) -> -250
B32: Training | C32: Swordsmen | D32: 20 | E32: 4 | J32: =VLOOKUP($C32,Troop!$B:$AK,(COLUMN(Troop_TrainingReward_Power)-COLUMN(Troop_Name)+1),FALSE)*$D32 -> 40 | AJ32: =AJ31+(S$3*S32+T$3*T32+U$3*U32+V$3*V32+W$3*W32+X$3*X32+Y$3*Y32+Z$3*Z32+AA$3*AA32+AB$3*AB32+AC$3*AC32) -> 0.057638889 | AU32: =VLOOKUP($C32,Troop!$B:$P,(COLUMN(Troop_TrainingCost_Stone)-COLUMN(Troop_Name)+1),FALSE)*$D32*(-1) -> 0 | AV32: =VLOOKUP($C32,Troop!$B:$P,(COLUMN(Troop_TrainingCost_Wood)-COLUMN(Troop_Name)+1),FALSE)*$D32*(-1) -> -1000 | AW32: =VLOOKUP($C32,Troop!$B:$P,(COLUMN(Troop_TrainingCost_Ore)-COLUMN(Troop_Name)+1),FALSE)*$D32*(-1) -> -760 | AX32: =VLOOKUP($C32,Troop!$B:$P,(COLUMN(Troop_TrainingCost_Food)-COLUMN(Troop_Name)+1),FALSE)*$D32*(-1) -> -1000 | AY32: =VLOOKUP($C32,Troop!$B:$P,(COLUMN(Troop_TrainingCost_Silver)-COLUMN(Troop_Name)+1),FALSE)*$D32*(-1) -> 0
B33: Quest | C33: Construction Recommended | D33: Barracks 1 | E33: 4 | F33: 0 | G33: =VLOOKUP($D33,Construction!$B:$L,(COLUMN(Construction_QuestReward_HeroXP)-COLUMN(Construction_Name_and_Level)+1),FALSE) -> 2525 | H33: =G33*(1+F33) -> 2525 | J33: =VLOOKUP($D33,Construction!$B:$L,(COLUMN(Construction_QuestReward_Power)-COLUMN(Construction_Name_and_Level)+1),FALSE) -> 2 | AJ33: =AJ32+(S$3*S33+T$3*T33+U$3*U33+V$3*V33+W$3*W33+X$3*X33+Y$3*Y33+Z$3*Z33+AA$3*AA33+AB$3*AB33+AC$3*AC33) -> 0.057638889 | AU33: =VLOOKUP($D33,Construction!$B:$Q,(COLUMN(Construction_QuestReward_Stone)-COLUMN(Construction_Name_and_Level)+1),FALSE) -> 5000 | AV33: =VLOOKUP($D33,Construction!$B:$Q,(COLUMN(Construction_QuestReward_Wood)-COLUMN(Construction_Name_and_Level)+1),FALSE) -> 4000 | AW33: =VLOOKUP($D33,Construction!$B:$Q,(COLUMN(Construction_QuestReward_Ore)-COLUMN(Construction_Name_and_Level)+1),FALSE) -> 3000 | AX33: =VLOOKUP($D33,Construction!$B:$Q,(COLUMN(Construction_QuestReward_Food)-COLUMN(Construction_Name_and_Level)+1),FALSE) -> 2500 | AY33: =VLOOKUP($D33,Construction!$B:$Q,(COLUMN(Construction_QuestReward_Silver)-COLUMN(Construction_Name_and_Level)+1),FALSE) -> 100
B34: Quest | C34: Training Recommended | D34: Swordsmen 20 | E34: 4 | F34: 0 | G34: 2500 | H34: =G34*(1+F34) -> 2500 | J34: 25 | AJ34: =AJ33+(S$3*S34+T$3*T34+U$3*U34+V$3*V34+W$3*W34+X$3*X34+Y$3*Y34+Z$3*Z34+AA$3*AA34+AB$3*AB34+AC$3*AC34) -> 0.057638889 | AU34: 0 | AV34: 2100 | AW34: 1500 | AX34: 2100 | AY34: 0
B35: Quest | C35: Special | D35: Participate an Event | E35: 4 | F35: 0 | G35: 10000 | H35: =G35*(1+F35) -> 10000 | J35: 25 | M35: 0.041666667 | AJ35: =AJ34+(S$3*S35+T$3*T35+U$3*U35+V$3*V35+W$3*W35+X$3*X35+Y$3*Y35+Z$3*Z35+AA$3*AA35+AB$3*AB35+AC$3*AC35) -> 0.057638889
B36: Quest | C36: Special | D36: Join an Alliance | E36: 4 | N36: 100 | AJ36: =AJ35+(S$3*S36+T$3*T36+U$3*U36+V$3*V36+W$3*W36+X$3*X36+Y$3*Y36+Z$3*Z36+AA$3*AA36+AB$3*AB36+AC$3*AC36) -> 0.057638889
B37: Construction | C37: at Will | D37: Storehouse 2 | E37: 4 | F37: 0 | G37: =VLOOKUP($D37,Construction!$B:$E,(COLUMN(Construction_BuildingReward_HeroXP)-COLUMN(Construction_Name_and_Level)+1),FALSE) -> 25 | H37: =G37*(1+F37) -> 25 | J37: =VLOOKUP($D37,Construction!$B:$F,(COLUMN(Construction_BuildingReward_Power)-COLUMN(Construction_Name_and_Level)+1),FALSE) -> 20 | Q37: 0.0034722222 | R37: 0.0041666667 | AJ37: =AJ36+(S$3*S37+T$3*T37+U$3*U37+V$3*V37+W$3*W37+X$3*X37+Y$3*Y37+Z$3*Z37+AA$3*AA37+AB$3*AB37+AC$3*AC37) -> 0.057638889 | AK37: 0 | AL37: =VLOOKUP($D37,Construction!$B:$C,(COLUMN(Construction_Time)-COLUMN(Construction_Name_and_Level)+1),FALSE) -> 0.0013888889 | AM37: =AL37/(1+AK37) -> 0.0013888889 | AN37: =(S$3*S37+T$3*T37+V$3*V37+W$3*W37+X$3*X37+Y$3*Y37+Z$3*Z37+AA$3*AA37+AB$3*AB37+AC$3*AC37)*(-1) -> 0 | AO37: =IF((AM37-Q37-R37-AN37)>=0,AM37-Q37-R37-AN37,0) -> 0 | AU37: =VLOOKUP($D37,Construction!$B:$J,(COLUMN(Construction_BuildingCost_Stone)-COLUMN(Construction_Name_and_Level)+1),FALSE)*(-1) -> -680 | AV37: =VLOOKUP($D37,Construction!$B:$J,(COLUMN(Construction_BuildingCost_Wood)-COLUMN(Construction_Name_and_Level)+1),FALSE)*(-1) -> -680 | AW37: =VLOOKUP($D37,Construction!$B:$J,(COLUMN(Construction_BuildingCost_Ore)-COLUMN(Construction_Name_and_Level)+1),FALSE)*(-1) -> -510 | AX37: =VLOOKUP($D37,Construction!$B:$J,(COLUMN(Construction_BuildingCost_Food)-COLUMN(Construction_Name_and_Level)+1),FALSE)*(-1) -> -340
B38: Construction | C38: at Will | D38: Walls 2 | E38: 4 | F38: 0 | G38: =VLOOKUP($D38,Construction!$B:$E,(COLUMN(Construction_BuildingReward_HeroXP)-COLUMN(Construction_Name_and_Level)+1),FALSE) -> 5000 | H38: =G38*(1+F38) -> 5000 | J38: =VLOOKUP($D38,Construction!$B:$F,(COLUMN(Construction_BuildingReward_Power)-COLUMN(Construction_Name_and_Level)+1),FALSE) -> 90 | Q38: 0.0034722222 | R38: 0.0041666667 | AJ38: =AJ37+(S$3*S38+T$3*T38+U$3*U38+V$3*V38+W$3*W38+X$3*X38+Y$3*Y38+Z$3*Z38+AA$3*AA38+AB$3*AB38+AC$3*AC38) -> 0.057638889 | AK38: 0 | AL38: =VLOOKUP($D38,Construction!$B:$C,(COLUMN(Construction_Time)-COLUMN(Construction_Name_and_Level)+1),FALSE) -> 0.0024305556 | AM38: =AL38/(1+AK38) -> 0.0024305556 | AN38: =(S$3*S38+T$3*T38+V$3*V38+W$3*W38+X$3*X38+Y$3*Y38+Z$3*Z38+AA$3*AA38+AB$3*AB38+AC$3*AC38)*(-1) -> 0 | AO38: =IF((AM38-Q38-R38-AN38)>=0,AM38-Q38-R38-AN38,0) -> 0 | AU38: =VLOOKUP($D38,Construction!$B:$J,(COLUMN(Construction_BuildingCost_Stone)-COLUMN(Construction_Name_and_Level)+1),FALSE)*(-1) -> -1800 | AV38: =VLOOKUP($D38,Construction!$B:$J,(COLUMN(Construction_BuildingCost_Wood)-COLUMN(Construction_Name_and_Level)+1),FALSE)*(-1) -> -1440 | AW38: =VLOOKUP($D38,Construction!$B:$J,(COLUMN(Construction_BuildingCost_Ore)-COLUMN(Construction_Name_and_Level)+1),FALSE)*(-1) -> -540 | AX38: =VLOOKUP($D38,Construction!$B:$J,(COLUMN(Construction_BuildingCost_Food)-COLUMN(Construction_Name_and_Level)+1),FALSE)*(-1) -> -900
B39: Construction | C39: at Will | D39: Stronghold 3 | E39: 4 | F39: 0 | G39: =VLOOKUP($D39,Construction!$B:$E,(COLUMN(Construction_BuildingReward_HeroXP)-COLUMN(Construction_Name_and_Level)+1),FALSE) -> 10000 | H39: =G39*(1+F39) -> 10000 | J39: =VLOOKUP($D39,Construction!$B:$F,(COLUMN(Construction_BuildingReward_Power)-COLUMN(Construction_Name_and_Level)+1),FALSE) -> 150 | Q39: 0.0034722222 | R39: 0.0048611111 | T39: -1 | AI39: =(-1)*($S$3*$S39+$T$3*$T39+$U$3*$U39+$V$3*$V39+$W$3*$W39+$X$3*$X39+$Y$3*$Y39+$Z$3*$Z39+$AA$3*$AA39+$AB$3*$AB39+$AC$3*$AC39) -> 0.0020833333 | AJ39: =AJ38+(S$3*S39+T$3*T39+U$3*U39+V$3*V39+W$3*W39+X$3*X39+Y$3*Y39+Z$3*Z39+AA$3*AA39+AB$3*AB39+AC$3*AC39) -> 0.055555556 | AK39: 0 | AL39: =VLOOKUP($D39,Construction!$B:$C,(COLUMN(Construction_Time)-COLUMN(Construction_Name_and_Level)+1),FALSE) -> 0.013888889 | AM39: =AL39/(1+AK39) -> 0.013888889 | AN39: =(S$3*S39+T$3*T39+V$3*V39+W$3*W39+X$3*X39+Y$3*Y39+Z$3*Z39+AA$3*AA39+AB$3*AB39+AC$3*AC39)*(-1) -> 0.0020833333 | AO39: =IF((AM39-Q39-R39-AN39)>=0,AM39-Q39-R39-AN39,0) -> 0.0034722222 | AU39: =VLOOKUP($D39,Construction!$B:$J,(COLUMN(Construction_BuildingCost_Stone)-COLUMN(Construction_Name_and_Level)+1),FALSE)*(-1) -> -3240 | AV39: =VLOOKUP($D39,Construction!$B:$J,(COLUMN(Construction_BuildingCost_Wood)-COLUMN(Construction_Name_and_Level)+1),FALSE)*(-1) -> -3240 | AW39: =VLOOKUP($D39,Construction!$B:$J,(COLUMN(Construction_BuildingCost_Ore)-COLUMN(Construction_Name_and_Level)+1),FALSE)*(-1) -> -1296 | AX39: =VLOOKUP($D39,Construction!$B:$J,(COLUMN(Construction_BuildingCost_Food)-COLUMN(Construction_Name_and_Level)+1),FALSE)*(-1) -> -1620
B40: Gift | C40: Stronghold upgrade Event | D40: Stronghold 2->3 Event | E40: 4 | W40: 2 | AF40: =$S$3*$S40+$T$3*$T40+$U$3*$U40+$V$3*$V40+$W$3*$W40+$X$3*$X40+$Y$3*$Y40+$Z$3*$Z40+$AA$3*$AA40+$AB$3*$AB40+$AC$3*$AC40 -> 0.020833333 | AJ40: =AJ39+(S$3*S40+T$3*T40+U$3*U40+V$3*V40+W$3*W40+X$3*X40+Y$3*Y40+Z$3*Z40+AA$3*AA40+AB$3*AB40+AC$3*AC40) -> 0.076388889 | AU40: 2800 | AV40: 3600 | AW40: 3600 | AX40: 4200 | AY40: 2800
...

Sheet Construction Sequence
B2: CATEGORY | C2: CLASS | D2: DETAIL | E2: Hero | J2: Power Gained | K2: VIP | N2: Currency | O2: Free Time | P2: Help Time | Q2: Speed Up Gained or Possessed | AD2: Total Amount of Speed Up Time | AE2: Construction Time | AH2: Speed Up Time Used | AI2: Construction Time - Free Time - Help Time - Speed Up Time | AJ2: Saved Time | AK2: Resources Gained or Consumed
E3: Level | F3: Exp Modifier | G3: Original Exp | H3: Exp Actually Gained | I3: Skill Points | K3: Level | L3: Point | M3: Amount of Time | N3: Gold | Q3: 0.00069444444 | R3: 0.0020833333 | S3: 0.0034722222 | T3: 0.0069444444 | U3: 0.010416667 | V3: 0.041666667 | W3: 0.125 | X3: 0.33333333 | Y3: 0.625 | Z3: 1 | AA3: 3 | AB3: 25% Time Off | AC3: 50% Time Off | AE3: Construction Acceleration | AF3: Original Time | AG3: Actual Time | AK3: Stone | AL3: Wood | AM3: Ore | AN3: Food | AO3: Silver
B4: Construction | C4: by Quest | D4: Farm 1 | E4: 1 | F4: 0 | G4: =VLOOKUP($D4,Construction!$B:$E,(COLUMN(Construction_BuildingReward_HeroXP)-COLUMN(Construction_Name_and_Level)+1),FALSE) -> 10 | H4: =G4*(1+F4) -> 10 | J4: =VLOOKUP($D4,Construction!$B:$F,(COLUMN(Construction_BuildingReward_Power)-COLUMN(Construction_Name_and_Level)+1),FALSE) -> 5 | O4: 0.0034722222 | P4: 0.0034722222 | AD4: =#REF!+(Q$3*Q4+R$3*R4+S$3*S4+T$3*T4+U$3*U4+V$3*V4+W$3*W4+X$3*X4+Y$3*Y4+Z$3*Z4+AA$3*AA4) -> #REF! | AE4: 0 | AF4: =VLOOKUP($D4,Construction!$B:$C,(COLUMN(Construction_Time)-COLUMN(Construction_Name_and_Level)+1),FALSE) -> 0.00069444444 | AG4: =AF4/(1+AE4) -> 0.00069444444 | AH4: =(Q$3*Q4+R$3*R4+T$3*T4+U$3*U4+V$3*V4+W$3*W4+X$3*X4+Y$3*Y4+Z$3*Z4+AA$3*AA4)*(-1) -> 0 | AI4: =IF((AG4-O4-P4-AH4)>=0,AG4-O4-P4-AH4,0) -> 0 | AJ4: =AF4-AI4 -> 0.00069444444 | AK4: =VLOOKUP($D4,Construction!$B:$J,(COLUMN(Construction_BuildingCost_Stone)-COLUMN(Construction_Name_and_Level)+1),FALSE)*(-1) -> -100 | AL4: =VLOOKUP($D4,Construction!$B:$J,(COLUMN(Construction_BuildingCost_Wood)-COLUMN(Construction_Name_and_Level)+1),FALSE)*(-1) -> -100 | AM4: =VLOOKUP($D4,Construction!$B:$J,(COLUMN(Construction_BuildingCost_Ore)-COLUMN(Construction_Name_and_Level)+1),FALSE)*(-1) -> -100 | AN4: =VLOOKUP($D4,Construction!$B:$J,(COLUMN(Construction_BuildingCost_Food)-COLUMN(Construction_Name_and_Level)+1),FALSE)*(-1) -> 0
B5: Construction | C5: by Quest | D5: Stronghold 2 | E5: 1 | F5: 0 | G5: =VLOOKUP($D5,Construction!$B:$E,(COLUMN(Construction_BuildingReward_HeroXP)-COLUMN(Construction_Name_and_Level)+1),FALSE) -> 5000 | H5: =G5*(1+F5) -> 5000 | J5: =VLOOKUP($D5,Construction!$B:$F,(COLUMN(Construction_BuildingReward_Power)-COLUMN(Construction_Name_and_Level)+1),FALSE) -> 150 | O5: 0.0034722222 | P5: 0.0041666667 | AD5: =AD4+(Q$3*Q5+R$3*R5+S$3*S5+T$3*T5+U$3*U5+V$3*V5+W$3*W5+X$3*X5+Y$3*Y5+Z$3*Z5+AA$3*AA5) -> #REF! | AE5: 0 | AF5: =VLOOKUP($D5,Construction!$B:$C,(COLUMN(Construction_Time)-COLUMN(Construction_Name_and_Level)+1),FALSE) -> 0.0032407407 | AG5: =AF5/(1+AE5) -> 0.0032407407 | AH5: =(Q$3*Q5+R$3*R5+T$3*T5+U$3*U5+V$3*V5+W$3*W5+X$3*X5+Y$3*Y5+Z$3*Z5+AA$3*AA5)*(-1) -> 0 | AI5: =IF((AG5-O5-P5-AH5)>=0,AG5-O5-P5-AH5,0) -> 0 | AJ5: =AF5-AI5 -> 0.0032407407 | AK5: =VLOOKUP($D5,Construction!$B:$J,(COLUMN(Construction_BuildingCost_Stone)-COLUMN(Construction_Name_and_Level)+1),FALSE)*(-1) -> -1800 | AL5: =VLOOKUP($D5,Construction!$B:$J,(COLUMN(Construction_BuildingCost_Wood)-COLUMN(Construction_Name_and_Level)+1),FALSE)*(-1) -> -1800 | AM5: =VLOOKUP($D5,Construction!$B:$J,(COLUMN(Construction_BuildingCost_Ore)-COLUMN(Construction_Name_and_Level)+1),FALSE)*(-1) -> -720 | AN5: =VLOOKUP($D5,Construction!$B:$J,(COLUMN(Construction_BuildingCost_Food)-COLUMN(Construction_Name_and_Level)+1),FALSE)*(-1) -> -900
B6: Construction | C6: by Quest | D6: Logging Camp 1 | E6: 2 | F6: 0 | G6: =VLOOKUP($D6,Construction!$B:$E,(COLUMN(Construction_BuildingReward_HeroXP)-COLUMN(Construction_Name_and_Level)+1),FALSE) -> 10 | H6: =G6*(1+F6) -> 10 | J6: =VLOOKUP($D6,Construction!$B:$F,(COLUMN(Construction_BuildingReward_Power)-COLUMN(Construction_Name_and_Level)+1),FALSE) -> 5 | O6: 0.0034722222 | P6: 0.0041666667 | AD6: =AD5+(Q$3*Q6+R$3*R6+S$3*S6+T$3*T6+U$3*U6+V$3*V6+W$3*W6+X$3*X6+Y$3*Y6+Z$3*Z6+AA$3*AA6) -> #REF! | AE6: 0 | AF6: =VLOOKUP($D6,Construction!$B:$C,(COLUMN(Construction_Time)-COLUMN(Construction_Name_and_Level)+1),FALSE) -> 0.00069444444 | AG6: =AF6/(1+AE6) -> 0.00069444444 | AH6: =(Q$3*Q6+R$3*R6+T$3*T6+U$3*U6+V$3*V6+W$3*W6+X$3*X6+Y$3*Y6+Z$3*Z6+AA$3*AA6)*(-1) -> 0 | AI6: =IF((AG6-O6-P6-AH6)>=0,AG6-O6-P6-AH6,0) -> 0 | AJ6: =AF6-AI6 -> 0.00069444444 | AK6: =VLOOKUP($D6,Construction!$B:$J,(COLUMN(Construction_BuildingCost_Stone)-COLUMN(Construction_Name_and_Level)+1),FALSE)*(-1) -> -100 | AL6: =VLOOKUP($D6,Construction!$B:$J,(COLUMN(Construction_BuildingCost_Wood)-COLUMN(Construction_Name_and_Level)+1),FALSE)*(-1) -> 0 | AM6: =VLOOKUP($D6,Construction!$B:$J,(COLUMN(Construction_BuildingCost_Ore)-COLUMN(Construction_Name_and_Level)+1),FALSE)*(-1) -> -100 | AN6: =VLOOKUP($D6,Construction!$B:$J,(COLUMN(Construction_BuildingCost_Food)-COLUMN(Construction_Name_and_Level)+1),FALSE)*(-1) -> -100
B7: Construction | C7: by Quest | D7: Academy 1 | E7: 2 | F7: 0 | G7: =VLOOKUP($D7,Construction!$B:$E,(COLUMN(Construction_BuildingReward_HeroXP)-COLUMN(Construction_Name_and_Level)+1),FALSE) -> 10 | H7: =G7*(1+F7) -> 10 | J7: =VLOOKUP($D7,Construction!$B:$F,(COLUMN(Construction_BuildingReward_Power)-COLUMN(Construction_Name_and_Level)+1),FALSE) -> 35 | O7: 0.0034722222 | P7: 0.0041666667 | AD7: =AD6+(Q$3*Q7+R$3*R7+S$3*S7+T$3*T7+U$3*U7+V$3*V7+W$3*W7+X$3*X7+Y$3*Y7+Z$3*Z7+AA$3*AA7) -> #REF! | AE7: 0 | AF7: =VLOOKUP($D7,Construction!$B:$C,(COLUMN(Construction_Time)-COLUMN(Construction_Name_and_Level)+1),FALSE) -> 0.0011574074 | AG7: =AF7/(1+AE7) -> 0.0011574074 | AH7: =(Q$3*Q7+R$3*R7+T$3*T7+U$3*U7+V$3*V7+W$3*W7+X$3*X7+Y$3*Y7+Z$3*Z7+AA$3*AA7)*(-1) -> 0 | AI7: =IF((AG7-O7-P7-AH7)>=0,AG7-O7-P7-AH7,0) -> 0 | AJ7: =AF7-AI7 -> 0.0011574074 | AK7: =VLOOKUP($D7,Construction!$B:$J,(COLUMN(Construction_BuildingCost_Stone)-COLUMN(Construction_Name_and_Level)+1),FALSE)*(-1) -> -500 | AL7: =VLOOKUP($D7,Construction!$B:$J,(COLUMN(Construction_BuildingCost_Wood)-COLUMN(Construction_Name_and_Level)+1),FALSE)*(-1) -> -500 | AM7: =VLOOKUP($D7,Construction!$B:$J,(COLUMN(Construction_BuildingCost_Ore)-COLUMN(Construction_Name_and_Level)+1),FALSE)*(-1) -> -200 | AN7: =VLOOKUP($D7,Construction!$B:$J,(COLUMN(Construction_BuildingCost_Food)-COLUMN(Construction_Name_and_Level)+1),FALSE)*(-1) -> -300
B8: Construction | C8: at Will | D8: Barracks 1 | E8: 4 | F8: 0 | G8: =VLOOKUP($D8,Construction!$B:$E,(COLUMN(Construction_BuildingReward_HeroXP)-COLUMN(Construction_Name_and_Level)+1),FALSE) -> 10 | H8: =G8*(1+F8) -> 10 | J8: =VLOOKUP($D8,Construction!$B:$F,(COLUMN(Construction_BuildingReward_Power)-COLUMN(Construction_Name_and_Level)+1),FALSE) -> 20 | O8: 0.0034722222 | P8: 0.0041666667 | AD8: =AD7+(Q$3*Q8+R$3*R8+S$3*S8+T$3*T8+U$3*U8+V$3*V8+W$3*W8+X$3*X8+Y$3*Y8+Z$3*Z8+AA$3*AA8) -> #REF! | AE8: 0 | AF8: =VLOOKUP($D8,Construction!$B:$C,(COLUMN(Construction_Time)-COLUMN(Construction_Name_and_Level)+1),FALSE) -> 0.0010416667 | AG8: =AF8/(1+AE8) -> 0.0010416667 | AH8: =(Q$3*Q8+R$3*R8+T$3*T8+U$3*U8+V$3*V8+W$3*W8+X$3*X8+Y$3*Y8+Z$3*Z8+AA$3*AA8)*(-1) -> 0 | AI8: =IF((AG8-O8-P8-AH8)>=0,AG8-O8-P8-AH8,0) -> 0 | AJ8: =AF8-AI8 -> 0.0010416667 | AK8: =VLOOKUP($D8,Construction!$B:$J,(COLUMN(Construction_BuildingCost_Stone)-COLUMN(Construction_Name_and_Level)+1),FALSE)*(-1) -> -500 | AL8: =VLOOKUP($D8,Construction!$B:$J,(COLUMN(Construction_BuildingCost_Wood)-COLUMN(Construction_Name_and_Level)+1),FALSE)*(-1) -> -400 | AM8: =VLOOKUP($D8,Construction!$B:$J,(COLUMN(Construction_BuildingCost_Ore)-COLUMN(Construction_Name_and_Level)+1),FALSE)*(-1) -> -300 | AN8: =VLOOKUP($D8,Construction!$B:$J,(COLUMN(Construction_BuildingCost_Food)-COLUMN(Construction_Name_and_Level)+1),FALSE)*(-1) -> -250
B9: Construction | C9: at Will | D9: Storehouse 2 | E9: 4 | F9: 0 | G9: =VLOOKUP($D9,Construction!$B:$E,(COLUMN(Construction_BuildingReward_HeroXP)-COLUMN(Construction_Name_and_Level)+1),FALSE) -> 25 | H9: =G9*(1+F9) -> 25 | J9: =VLOOKUP($D9,Construction!$B:$F,(COLUMN(Construction_BuildingReward_Power)-COLUMN(Construction_Name_and_Level)+1),FALSE) -> 20 | O9: 0.0034722222 | P9: 0.0041666667 | AD9: =AD8+(Q$3*Q9+R$3*R9+S$3*S9+T$3*T9+U$3*U9+V$3*V9+W$3*W9+X$3*X9+Y$3*Y9+Z$3*Z9+AA$3*AA9) -> #REF! | AE9: 0 | AF9: =VLOOKUP($D9,Construction!$B:$C,(COLUMN(Construction_Time)-COLUMN(Construction_Name_and_Level)+1),FALSE) -> 0.0013888889 | AG9: =AF9/(1+AE9) -> 0.0013888889 | AH9: =(Q$3*Q9+R$3*R9+T$3*T9+U$3*U9+V$3*V9+W$3*W9+X$3*X9+Y$3*Y9+Z$3*Z9+AA$3*AA9)*(-1) -> 0 | AI9: =IF((AG9-O9-P9-AH9)>=0,AG9-O9-P9-AH9,0) -> 0 | AJ9: =AF9-AI9 -> 0.0013888889 | AK9: =VLOOKUP($D9,Construction!$B:$J,(COLUMN(Construction_BuildingCost_Stone)-COLUMN(Construction_Name_and_Level)+1),FALSE)*(-1) -> -680 | AL9: =VLOOKUP($D9,Construction!$B:$J,(COLUMN(Construction_BuildingCost_Wood)-COLUMN(Construction_Name_and_Level)+1),FALSE)*(-1) -> -680 | AM9: =VLOOKUP($D9,Construction!$B:$J,(COLUMN(Construction_BuildingCost_Ore)-COLUMN(Construction_Name_and_Level)+1),FALSE)*(-1) -> -510 | AN9: =VLOOKUP($D9,Construction!$B:$J,(COLUMN(Construction_BuildingCost_Food)-COLUMN(Construction_Name_and_Level)+1),FALSE)*(-1) -> -340
B10: Construction | C10: at Will | D10: Walls 2 | E10: 4 | F10: 0 | G10: =VLOOKUP($D10,Construction!$B:$E,(COLUMN(Construction_BuildingReward_HeroXP)-COLUMN(Construction_Name_and_Level)+1),FALSE) -> 5000 | H10: =G10*(1+F10) -> 5000 | J10: =VLOOKUP($D10,Construction!$B:$F,(COLUMN(Construction_BuildingReward_Power)-COLUMN(Construction_Name_and_Level)+1),FALSE) -> 90 | O10: 0.0034722222 | P10: 0.0041666667 | AD10: =AD9+(Q$3*Q10+R$3*R10+S$3*S10+T$3*T10+U$3*U10+V$3*V10+W$3*W10+X$3*X10+Y$3*Y10+Z$3*Z10+AA$3*AA10) -> #REF! | AE10: 0 | AF10: =VLOOKUP($D10,Construction!$B:$C,(COLUMN(Construction_Time)-COLUMN(Construction_Name_and_Level)+1),FALSE) -> 0.0024305556 | AG10: =AF10/(1+AE10) -> 0.0024305556 | AH10: =(Q$3*Q10+R$3*R10+T$3*T10+U$3*U10+V$3*V10+W$3*W10+X$3*X10+Y$3*Y10+Z$3*Z10+AA$3*AA10)*(-1) -> 0 | AI10: =IF((AG10-O10-P10-AH10)>=0,AG10-O10-P10-AH10,0) -> 0 | AJ10: =AF10-AI10 -> 0.0024305556 | AK10: =VLOOKUP($D10,Construction!$B:$J,(COLUMN(Construction_BuildingCost_Stone)-COLUMN(Construction_Name_and_Level)+1),FALSE)*(-1) -> -1800 | AL10: =VLOOKUP($D10,Construction!$B:$J,(COLUMN(Construction_BuildingCost_Wood)-COLUMN(Construction_Name_and_Level)+1),FALSE)*(-1) -> -1440 | AM10: =VLOOKUP($D10,Construction!$B:$J,(COLUMN(Construction_BuildingCost_Ore)-COLUMN(Construction_Name_and_Level)+1),FALSE)*(-1) -> -540 | AN10: =VLOOKUP($D10,Construction!$B:$J,(COLUMN(Construction_BuildingCost_Food)-COLUMN(Construction_Name_and_Level)+1),FALSE)*(-1) -> -900
B11: Construction | C11: at Will | D11: Stronghold 3 | E11: 4 | F11: 0 | G11: =VLOOKUP($D11,Construction!$B:$E,(COLUMN(Construction_BuildingReward_HeroXP)-COLUMN(Construction_Name_and_Level)+1),FALSE) -> 10000 | H11: =G11*(1+F11) -> 10000 | J11: =VLOOKUP($D11,Construction!$B:$F,(COLUMN(Construction_BuildingReward_Power)-COLUMN(Construction_Name_and_Level)+1),FALSE) -> 150 | O11: 0.0034722222 | P11: 0.0048611111 | R11: -1 | AD11: =AD10+(Q$3*Q11+R$3*R11+S$3*S11+T$3*T11+U$3*U11+V$3*V11+W$3*W11+X$3*X11+Y$3*Y11+Z$3*Z11+AA$3*AA11) -> #REF! | AE11: 0 | AF11: =VLOOKUP($D11,Construction!$B:$C,(COLUMN(Construction_Time)-COLUMN(Construction_Name_and_Level)+1),FALSE) -> 0.013888889 | AG11: =AF11/(1+AE11) -> 0.013888889 | AH11: =(Q$3*Q11+R$3*R11+T$3*T11+U$3*U11+V$3*V11+W$3*W11+X$3*X11+Y$3*Y11+Z$3*Z11+AA$3*AA11)*(-1) -> 0.0020833333 | AI11: =IF((AG11-O11-P11-AH11)>=0,AG11-O11-P11-AH11,0) -> 0.0034722222 | AJ11: =AF11-AI11 -> 0.010416667 | AK11: =VLOOKUP($D11,Construction!$B:$J,(COLUMN(Construction_BuildingCost_Stone)-COLUMN(Construction_Name_and_Level)+1),FALSE)*(-1) -> -3240 | AL11: =VLOOKUP($D11,Construction!$B:$J,(COLUMN(Construction_BuildingCost_Wood)-COLUMN(Construction_Name_and_Level)+1),FALSE)*(-1) -> -3240 | AM11: =VLOOKUP($D11,Construction!$B:$J,(COLUMN(Construction_BuildingCost_Ore)-COLUMN(Construction_Name_and_Level)+1),FALSE)*(-1) -> -1296 | AN11: =VLOOKUP($D11,Construction!$B:$J,(COLUMN(Construction_BuildingCost_Food)-COLUMN(Construction_Name_and_Level)+1),FALSE)*(-1) -> -1620
B12: Construction | C12: at Will | D12: Storehouse 3 | E12: 5 | F12: 0 | G12: =VLOOKUP($D12,Construction!$B:$E,(COLUMN(Construction_BuildingReward_HeroXP)-COLUMN(Construction_Name_and_Level)+1),FALSE) -> 50 | H12: =G12*(1+F12) -> 50 | J12: =VLOOKUP($D12,Construction!$B:$F,(COLUMN(Construction_BuildingReward_Power)-COLUMN(Construction_Name_and_Level)+1),FALSE) -> 30 | O12: 0.0034722222 | P12: 0.0048611111 | AD12: =AD11+(Q$3*Q12+R$3*R12+S$3*S12+T$3*T12+U$3*U12+V$3*V12+W$3*W12+X$3*X12+Y$3*Y12+Z$3*Z12+AA$3*AA12) -> #REF! | AE12: 0 | AF12: =VLOOKUP($D12,Construction!$B:$C,(COLUMN(Construction_Time)-COLUMN(Construction_Name_and_Level)+1),FALSE) -> 0.0027777778 | AG12: =AF12/(1+AE12) -> 0.0027777778 | AH12: =(Q$3*Q12+R$3*R12+T$3*T12+U$3*U12+V$3*V12+W$3*W12+X$3*X12+Y$3*Y12+Z$3*Z12+AA$3*AA12)*(-1) -> 0 | AI12: =IF((AG12-O12-P12-AH12)>=0,AG12-O12-P12-AH12,0) -> 0 | AJ12: =AF12-AI12 -> 0.0027777778 | AK12: =VLOOKUP($D12,Construction!$B:$J,(COLUMN(Construction_BuildingCost_Stone)-COLUMN(Construction_Name_and_Level)+1),FALSE)*(-1) -> -1156 | AL12: =VLOOKUP($D12,Construction!$B:$J,(COLUMN(Construction_BuildingCost_Wood)-COLUMN(Construction_Name_and_Level)+1),FALSE)*(-1) -> -1156 | AM12: =VLOOKUP($D12,Construction!$B:$J,(COLUMN(Construction_BuildingCost_Ore)-COLUMN(Construction_Name_and_Level)+1),FALSE)*(-1) -> -867 | AN12: =VLOOKUP($D12,Construction!$B:$J,(COLUMN(Construction_BuildingCost_Food)-COLUMN(Construction_Name_and_Level)+1),FALSE)*(-1) -> -578
B13: Construction | C13: at Will | D13: Stronghold 4 | E13: 5 | F13: 0 | G13: =VLOOKUP($D13,Construction!$B:$E,(COLUMN(Construction_BuildingReward_HeroXP)-COLUMN(Construction_Name_and_Level)+1),FALSE) -> 10000 | H13: =G13*(1+F13) -> 10000 | J13: =VLOOKUP($D13,Construction!$B:$F,(COLUMN(Construction_BuildingReward_Power)-COLUMN(Construction_Name_and_Level)+1),FALSE) -> 250 | O13: 0.0034722222 | P13: 0.0055555556 | T13: -2 | U13: -1 | AD13: =AD12+(Q$3*Q13+R$3*R13+S$3*S13+T$3*T13+U$3*U13+V$3*V13+W$3*W13+X$3*X13+Y$3*Y13+Z$3*Z13+AA$3*AA13) -> #REF! | AE13: 0 | AF13: =VLOOKUP($D13,Construction!$B:$C,(COLUMN(Construction_Time)-COLUMN(Construction_Name_and_Level)+1),FALSE) -> 0.027777778 | AG13: =AF13/(1+AE13) -> 0.027777778 | AH13: =(Q$3*Q13+R$3*R13+T$3*T13+U$3*U13+V$3*V13+W$3*W13+X$3*X13+Y$3*Y13+Z$3*Z13+AA$3*AA13)*(-1) -> 0.024305556 | AI13: =IF((AG13-O13-P13-AH13)>=0,AG13-O13-P13-AH13,0) -> 0 | AJ13: =AF13-AI13 -> 0.027777778 | AK13: =VLOOKUP($D13,Construction!$B:$J,(COLUMN(Construction_BuildingCost_Stone)-COLUMN(Construction_Name_and_Level)+1),FALSE)*(-1) -> -5832 | AL13: =VLOOKUP($D13,Construction!$B:$J,(COLUMN(Construction_BuildingCost_Wood)-COLUMN(Construction_Name_and_Level)+1),FALSE)*(-1) -> -5832 | AM13: =VLOOKUP($D13,Construction!$B:$J,(COLUMN(Construction_BuildingCost_Ore)-COLUMN(Construction_Name_and_Level)+1),FALSE)*(-1) -> -2333 | AN13: =VLOOKUP($D13,Construction!$B:$J,(COLUMN(Construction_BuildingCost_Food)-COLUMN(Construction_Name_and_Level)+1),FALSE)*(-1) -> -2916
B14: Construction | C14: at Will | D14: Storehouse 4 | E14: 5 | F14: 0 | G14: =VLOOKUP($D14,Construction!$B:$E,(COLUMN(Construction_BuildingReward_HeroXP)-COLUMN(Construction_Name_and_Level)+1),FALSE) -> 200 | H14: =G14*(1+F14) -> 200 | J14: =VLOOKUP($D14,Construction!$B:$F,(COLUMN(Construction_BuildingReward_Power)-COLUMN(Construction_Name_and_Level)+1),FALSE) -> 50 | O14: 0.0034722222 | P14: 0.0055555556 | AD14: =AD13+(Q$3*Q14+R$3*R14+S$3*S14+T$3*T14+U$3*U14+V$3*V14+W$3*W14+X$3*X14+Y$3*Y14+Z$3*Z14+AA$3*AA14) -> #REF! | AE14: 0 | AF14: =VLOOKUP($D14,Construction!$B:$C,(COLUMN(Construction_Time)-COLUMN(Construction_Name_and_Level)+1),FALSE) -> 0.0055555556 | AG14: =AF14/(1+AE14) -> 0.0055555556 | AH14: =(Q$3*Q14+R$3*R14+T$3*T14+U$3*U14+V$3*V14+W$3*W14+X$3*X14+Y$3*Y14+Z$3*Z14+AA$3*AA14)*(-1) -> 0 | AI14: =IF((AG14-O14-P14-AH14)>=0,AG14-O14-P14-AH14,0) -> 0 | AJ14: =AF14-AI14 -> 0.0055555556 | AK14: =VLOOKUP($D14,Construction!$B:$J,(COLUMN(Construction_BuildingCost_Stone)-COLUMN(Construction_Name_and_Level)+1),FALSE)*(-1) -> -1966 | AL14: =VLOOKUP($D14,Construction!$B:$J,(COLUMN(Construction_BuildingCost_Wood)-COLUMN(Construction_Name_and_Level)+1),FALSE)*(-1) -> -1966 | AM14: =VLOOKUP($D14,Construction!$B:$J,(COLUMN(Construction_BuildingCost_Ore)-COLUMN(Construction_Name_and_Level)+1),FALSE)*(-1) -> -1474 | AN14: =VLOOKUP($D14,Construction!$B:$J,(COLUMN(Construction_BuildingCost_Food)-COLUMN(Construction_Name_and_Level)+1),FALSE)*(-1) -> -983
B15: Construction | C15: at Will | D15: Walls 3 | E15: 5 | F15: 0 | G15: =VLOOKUP($D15,Construction!$B:$E,(COLUMN(Construction_BuildingReward_HeroXP)-COLUMN(Construction_Name_and_Level)+1),FALSE) -> 5000 | H15: =G15*(1+F15) -> 5000 | J15: =VLOOKUP($D15,Construction!$B:$F,(COLUMN(Construction_BuildingReward_Power)-COLUMN(Construction_Name_and_Level)+1),FALSE) -> 100 | O15: 0.0034722222 | P15: 0.0055555556 | AD15: =AD14+(Q$3*Q15+R$3*R15+S$3*S15+T$3*T15+U$3*U15+V$3*V15+W$3*W15+X$3*X15+Y$3*Y15+Z$3*Z15+AA$3*AA15) -> #REF! | AE15: 0 | AF15: =VLOOKUP($D15,Construction!$B:$C,(COLUMN(Construction_Time)-COLUMN(Construction_Name_and_Level)+1),FALSE) -> 0.0048611111 | AG15: =AF15/(1+AE15) -> 0.0048611111 | AH15: =(Q$3*Q15+R$3*R15+T$3*T15+U$3*U15+V$3*V15+W$3*W15+X$3*X15+Y$3*Y15+Z$3*Z15+AA$3*AA15)*(-1) -> 0 | AI15: =IF((AG15-O15-P15-AH15)>=0,AG15-O15-P15-AH15,0) -> 0 | AJ15: =AF15-AI15 -> 0.0048611111 | AK15: =VLOOKUP($D15,Construction!$B:$J,(COLUMN(Construction_BuildingCost_Stone)-COLUMN(Construction_Name_and_Level)+1),FALSE)*(-1) -> -3240 | AL15: =VLOOKUP($D15,Construction!$B:$J,(COLUMN(Construction_BuildingCost_Wood)-COLUMN(Construction_Name_and_Level)+1),FALSE)*(-1) -> -2592 | AM15: =VLOOKUP($D15,Construction!$B:$J,(COLUMN(Construction_BuildingCost_Ore)-COLUMN(Construction_Name_and_Level)+1),FALSE)*(-1) -> -972 | AN15: =VLOOKUP($D15,Construction!$B:$J,(COLUMN(Construction_BuildingCost_Food)-COLUMN(Construction_Name_and_Level)+1),FALSE)*(-1) -> -1620
B16: Construction | C16: by Quest | D16: Quarry 1 | E16: 7 | F16: 0 | G16: =VLOOKUP($D16,Construction!$B:$E,(COLUMN(Construction_BuildingReward_HeroXP)-COLUMN(Construction_Name_and_Level)+1),FALSE) -> 10 | H16: =G16*(1+F16) -> 10 | J16: =VLOOKUP($D16,Construction!$B:$F,(COLUMN(Construction_BuildingReward_Power)-COLUMN(Construction_Name_and_Level)+1),FALSE) -> 5 | O16: 0.0034722222 | P16: 0.0055555556 | AD16: =AD15+(Q$3*Q16+R$3*R16+S$3*S16+T$3*T16+U$3*U16+V$3*V16+W$3*W16+X$3*X16+Y$3*Y16+Z$3*Z16+AA$3*AA16) -> #REF! | AE16: 0.01 | AF16: =VLOOKUP($D16,Construction!$B:$C,(COLUMN(Construction_Time)-COLUMN(Construction_Name_and_Level)+1),FALSE) -> 0.00069444444 | AG16: =AF16/(1+AE16) -> 0.00068756876 | AH16: =(Q$3*Q16+R$3*R16+T$3*T16+U$3*U16+V$3*V16+W$3*W16+X$3*X16+Y$3*Y16+Z$3*Z16+AA$3*AA16)*(-1) -> 0 | AI16: =IF((AG16-O16-P16-AH16)>=0,AG16-O16-P16-AH16,0) -> 0 | AJ16: =AF16-AI16 -> 0.00069444444 | AK16: =VLOOKUP($D16,Construction!$B:$J,(COLUMN(Construction_BuildingCost_Stone)-COLUMN(Construction_Name_and_Level)+1),FALSE)*(-1) -> 0 | AL16: =VLOOKUP($D16,Construction!$B:$J,(COLUMN(Construction_BuildingCost_Wood)-COLUMN(Construction_Name_and_Level)+1),FALSE)*(-1) -> -100 | AM16: =VLOOKUP($D16,Construction!$B:$J,(COLUMN(Construction_BuildingCost_Ore)-COLUMN(Construction_Name_and_Level)+1),FALSE)*(-1) -> -100 | AN16: =VLOOKUP($D16,Construction!$B:$J,(COLUMN(Construction_BuildingCost_Food)-COLUMN(Construction_Name_and_Level)+1),FALSE)*(-1) -> -100
