Workbook
Name activechart1: army!$M$198:$M$202
Name buffvalue: hero!$I$19:$P$36
Name goldvalue: research!$DC$3:$DJ$16
Name n: hero!$I$19:$Q$36
Name resourcevalue: building!$V$6:$AC$21
Name selectchart: CHOOSE(army!$I$221,resourcevalue,timevalue,buffvalue,goldvalue,threecompare)
Name threecompare: hero!$AC$17:$AJ$34
Name timevalue: hero!$R$19:$Y$36

Sheet brief
M1: Troop Benefit | N1: Troop Benefit | O1: Troop Benefit | P1: Troop Benefit | Q1: Troop Benefit | R1: Troop Benefit | S1: Troop Benefit | T1: Troop Benefit | U1: Building Benefit | V1: Training Benefit | W1: Training Benefit | X1: Training Benefit | Y1: Knight Benefit | Z1: March Benefit | AA1: March Benefit | AB1: March Benefit | AC1: March Benefit | AD1: March Benefit | AE1: March Benefit | AF1: March Benefit | AG1: March Benefit | AH1: March Benefit | AI1: March Benefit | AJ1: March Benefit | AK1: Population Benefit | AL1: Population Benefit | AM1: Population Benefit | AN1: Population Benefit | AO1: Resource Benefit | AP1: Resource Benefit | AQ1: Resource Benefit | AR1: Resource Benefit | AS1: Resource Benefit | AT1: Resource Benefit | AU1: Resource Benefit | AV1: Resource Benefit | AW1: Resource Benefit | AX1: Resource Benefit | AY1: Resource Benefit | AZ1: Resource Benefit | BA1: Resource Benefit
A2: Building / Research | C2: Type | D2: Level ID | E2: Prestige Level | F2: Building Level | G2: Comment | H2: UI Changes | I2: Prestige Bonus | J2: Might | K2: Previous strings | L2: New strings | M2: Trap, Caltrops, Crossbow slots | N2: Boiling Oil, Spiked Barrier, Trebuchet slots | O2: Greek Fire, Sulfur, Hellfire Thrower slots | P2: % buff to attack | Q2: % buff to health | R2: % buff to load | S2: % buff to health to troops reinforcing you | T2: % debuff attacking player attack | U2: % increase in construction speed | V2: Training Time Speed Increase (Infantry) | W2: Training Time Speed Increase (Horse) | X2: Training Time Speed Increase (Artillery) | Y2: Knights unlocked | Z2: % debuff attacking player march speed | AA2: Scout Time Speed Increase | AB2: Attack March Time Speed Increase (Infantry) | AC2: Attack March Time Speed Increase (Horse) | AD2: Attack March Time Speed Increase (Artillery) | AE2: Support March Time Speed Increase (Infantry) | AF2: Support March Time Speed Increase (Horse) | AG2: Support March Time Speed Increase (Artillery) | AH2: Scout March Time Speed Increase | AI2: # of marches | AJ2: # of troops per march | AK2: Workers | AL2: Population Cap | AM2: Population | AN2: Labor Population | AO2: Gold Protection | AP2: Food Protection | AQ2: Wood Protection | AR2: Stone Protection | AS2: Ore Protection | AT2: Food Production | AU2: Wood Production | AV2: Stone Production | AW2: Ore Production | AX2: Food Capacity | AY2: Wood Capacity | AZ2: Stone Capacity | BA2: Ore Capacity
A3: Alchemy Lab | B3: =VLOOKUP(A3,'name convert'!$A$1:$B$39,2,FALSE) -> Academy | C3: Building | D3: 1 | E3: 1 | F3: 1 | J3: 0 | K3: Level 1 research | L3: Level 1 research
A4: Alchemy Lab | B4: =VLOOKUP(A4,'name convert'!$A$1:$B$39,2,FALSE) -> Academy | C4: Building | D4: 2 | E4: 1 | F4: 2 | J4: 0 | K4: Level 2 research | L4: Level 2 research
A5: Alchemy Lab | B5: =VLOOKUP(A5,'name convert'!$A$1:$B$39,2,FALSE) -> Academy | C5: Building | D5: 3 | E5: 1 | F5: 3 | J5: 0 | K5: Level 3 research | L5: Level 3 research
A6: Alchemy Lab | B6: =VLOOKUP(A6,'name convert'!$A$1:$B$39,2,FALSE) -> Academy | C6: Building | D6: 4 | E6: 1 | F6: 4 | J6: 0 | K6: Level 4 research | L6: Level 4 research
A7: Alchemy Lab | B7: =VLOOKUP(A7,'name convert'!$A$1:$B$39,2,FALSE) -> Academy | C7: Building | D7: 5 | E7: 1 | F7: 5 | J7: 0 | K7: Level 5 research | L7: Level 5 research
A8: Alchemy Lab | B8: =VLOOKUP(A8,'name convert'!$A$1:$B$39,2,FALSE) -> Academy | C8: Building | D8: 6 | E8: 1 | F8: 6 | J8: 0 | K8: Level 6 research | L8: Level 6 research
A9: Alchemy Lab | B9: =VLOOKUP(A9,'name convert'!$A$1:$B$39,2,FALSE) -> Academy | C9: Building | D9: 7 | E9: 1 | F9: 7 | J9: 0 | K9: Level 7 research | L9: Level 7 research
A10: Alchemy Lab | B10: =VLOOKUP(A10,'name convert'!$A$1:$B$39,2,FALSE) -> Academy | C10: Building | D10: 8 | E10: 1 | F10: 8 | J10: 0 | K10: Level 8 research | L10: Level 8 research
A11: Alchemy Lab | B11: =VLOOKUP(A11,'name convert'!$A$1:$B$39,2,FALSE) -> Academy | C11: Building | D11: 9 | E11: 1 | F11: 9 | J11: 0 | K11: Level 9 research | L11: Level 9 research
A12: Alchemy Lab | B12: =VLOOKUP(A12,'name convert'!$A$1:$B$39,2,FALSE) -> Academy | C12: Building | D12: 10 | E12: 1 | F12: 10 | J12: 0 | K12: Level 10 research | L12: Level 10 research
A13: Alchemy Lab | B13: =VLOOKUP(A13,'name convert'!$A$1:$B$39,2,FALSE) -> Academy | C13: Building | D13: 11 | E13: 2 | F13: 1 | J13: 0 | L13: Level 11 research
A14: Alchemy Lab | B14: =VLOOKUP(A14,'name convert'!$A$1:$B$39,2,FALSE) -> Academy | C14: Building | D14: 12 | E14: 2 | F14: 2 | J14: 0 | L14: Level 12 research
A15: Alchemy Lab | B15: =VLOOKUP(A15,'name convert'!$A$1:$B$39,2,FALSE) -> Academy | C15: Building | D15: 13 | E15: 2 | F15: 3 | J15: 0 | L15: Level 13 research
A16: Alchemy Lab | B16: =VLOOKUP(A16,'name convert'!$A$1:$B$39,2,FALSE) -> Academy | C16: Building | D16: 14 | E16: 2 | F16: 4 | J16: 0 | L16: Level 14 research
A17: Alchemy Lab | B17: =VLOOKUP(A17,'name convert'!$A$1:$B$39,2,FALSE) -> Academy | C17: Building | D17: 15 | E17: 2 | F17: 5 | J17: 0 | L17: Level 15 research
A18: Alchemy Lab | B18: =VLOOKUP(A18,'name convert'!$A$1:$B$39,2,FALSE) -> Academy | C18: Building | D18: 16 | E18: 2 | F18: 6 | J18: 0 | L18: Level 16 research
A19: Alchemy Lab | B19: =VLOOKUP(A19,'name convert'!$A$1:$B$39,2,FALSE) -> Academy | C19: Building | D19: 17 | E19: 2 | F19: 7 | J19: 0 | L19: Level 17 research
A20: Alchemy Lab | B20: =VLOOKUP(A20,'name convert'!$A$1:$B$39,2,FALSE) -> Academy | C20: Building | D20: 18 | E20: 2 | F20: 8 | J20: 0 | L20: Level 18 research
A21: Alchemy Lab | B21: =VLOOKUP(A21,'name convert'!$A$1:$B$39,2,FALSE) -> Academy | C21: Building | D21: 19 | E21: 2 | F21: 9 | J21: 0 | L21: Level 19 research
A22: Alchemy Lab | B22: =VLOOKUP(A22,'name convert'!$A$1:$B$39,2,FALSE) -> Academy | C22: Building | D22: 20 | E22: 2 | F22: 10 | J22: 0 | L22: Level 20 research
A23: Alchemy Lab | B23: =VLOOKUP(A23,'name convert'!$A$1:$B$39,2,FALSE) -> Academy | C23: Building | D23: 21 | E23: 2 | F23: 11 | J23: 0 | L23: Level 21 research
A24: Barracks | B24: =VLOOKUP(A24,'name convert'!$A$1:$B$39,2,FALSE) -> Barracks | C24: Building | D24: 1 | E24: 1 | F24: 1 | G24: Need speed benefit | J24: 0 | K24: Train Supply Troops; train light cavalry; training speed increase | L24: Train Supply Troops; train light cavalry; training speed increase | V24: NEED | W24: NEED | X24: NEED
A25: Barracks | B25: =VLOOKUP(A25,'name convert'!$A$1:$B$39,2,FALSE) -> Barracks | C25: Building | D25: 2 | E25: 1 | F25: 2 | G25: Need speed benefit | J25: 0 | K25: Train Militiamen; training speed decrease | L25: Train Militiamen; training speed increase | V25: NEED | W25: NEED | X25: NEED
A26: Barracks | B26: =VLOOKUP(A26,'name convert'!$A$1:$B$39,2,FALSE) -> Barracks | C26: Building | D26: 3 | E26: 1 | F26: 3 | G26: Need speed benefit | J26: 0 | K26: Train Archers; training speed decrease | L26: Train Archers; training speed increase | V26: NEED | W26: NEED | X26: NEED
A27: Barracks | B27: =VLOOKUP(A27,'name convert'!$A$1:$B$39,2,FALSE) -> Barracks | C27: Building | D27: 4 | E27: 1 | F27: 4 | G27: Need speed benefit | J27: 0 | K27: Train Supply Cart; train Calavry; training speed decrease | L27: Train Supply Cart; train Calavry; training speed increase | V27: NEED | W27: NEED | X27: NEED
A28: Barracks | B28: =VLOOKUP(A28,'name convert'!$A$1:$B$39,2,FALSE) -> Barracks | C28: Building | D28: 5 | E28: 1 | F28: 5 | G28: Need speed benefit | J28: 0 | K28: Train Swordsmen; training speed decrease | L28: Train Swordsmen; training speed increase | V28: NEED | W28: NEED | X28: NEED
A29: Barracks | B29: =VLOOKUP(A29,'name convert'!$A$1:$B$39,2,FALSE) -> Barracks | C29: Building | D29: 6 | E29: 1 | F29: 6 | G29: Need speed benefit | J29: 0 | K29: Train Ballistae; training speed decrease | L29: Train Ballistae; training speed increase | V29: NEED | W29: NEED | X29: NEED
A30: Barracks | B30: =VLOOKUP(A30,'name convert'!$A$1:$B$39,2,FALSE) -> Barracks | C30: Building | D30: 7 | E30: 1 | F30: 7 | G30: Need speed benefit | J30: 0 | K30: Train Supply Wagon; training speed decrease | L30: Train Supply Wagon; training speed increase | V30: NEED | W30: NEED | X30: NEED
A31: Barracks | B31: =VLOOKUP(A31,'name convert'!$A$1:$B$39,2,FALSE) -> Barracks | C31: Building | D31: 8 | E31: 1 | F31: 8 | G31: Need speed benefit | J31: 0 | K31: Train Heavy Cavalry; training speed decrease | L31: Train Heavy Cavalry; training speed increase | V31: NEED | W31: NEED | X31: NEED
A32: Barracks | B32: =VLOOKUP(A32,'name convert'!$A$1:$B$39,2,FALSE) -> Barracks | C32: Building | D32: 9 | E32: 1 | F32: 9 | G32: Need speed benefit | J32: 0 | K32: Train Battering Rams; training speed decrease | L32: Train Battering Rams; training speed increase | V32: NEED | W32: NEED | X32: NEED
A33: Barracks | B33: =VLOOKUP(A33,'name convert'!$A$1:$B$39,2,FALSE) -> Barracks | C33: Building | D33: 10 | E33: 1 | F33: 10 | G33: Need speed benefit | J33: 0 | K33: Train Catapults; training speed decrease | L33: Train Catapults; training speed increase | V33: NEED | W33: NEED | X33: NEED
A34: Barracks | B34: =VLOOKUP(A34,'name convert'!$A$1:$B$39,2,FALSE) -> Barracks | C34: Building | D34: 11 | E34: 2 | F34: 1 | I34: NEED | J34: 0 | L34: Training speed increase | V34: =V24+(V24*$I34) -> #VALUE! | W34: =W24+(W24*$I34) -> #VALUE! | X34: =X24+(X24*$I34) -> #VALUE!
A35: Barracks | B35: =VLOOKUP(A35,'name convert'!$A$1:$B$39,2,FALSE) -> Barracks | C35: Building | D35: 12 | E35: 2 | F35: 2 | I35: NEED | J35: 0 | L35: Training speed increase | V35: =V25+(V25*$I35) -> #VALUE! | W35: =W25+(W25*$I35) -> #VALUE! | X35: =X25+(X25*$I35) -> #VALUE!
A36: Barracks | B36: =VLOOKUP(A36,'name convert'!$A$1:$B$39,2,FALSE) -> Barracks | C36: Building | D36: 13 | E36: 2 | F36: 3 | I36: NEED | J36: 0 | L36: Training speed increase | V36: =V26+(V26*$I36) -> #VALUE! | W36: =W26+(W26*$I36) -> #VALUE! | X36: =X26+(X26*$I36) -> #VALUE!
A37: Barracks | B37: =VLOOKUP(A37,'name convert'!$A$1:$B$39,2,FALSE) -> Barracks | C37: Building | D37: 14 | E37: 2 | F37: 4 | I37: NEED | J37: 0 | L37: Training speed increase | V37: =V27+(V27*$I37) -> #VALUE! | W37: =W27+(W27*$I37) -> #VALUE! | X37: =X27+(X27*$I37) -> #VALUE!
A38: Barracks | B38: =VLOOKUP(A38,'name convert'!$A$1:$B$39,2,FALSE) -> Barracks | C38: Building | D38: 15 | E38: 2 | F38: 5 | I38: NEED | J38: 0 | L38: Training speed increase | V38: =V28+(V28*$I38) -> #VALUE! | W38: =W28+(W28*$I38) -> #VALUE! | X38: =X28+(X28*$I38) -> #VALUE!
A39: Barracks | B39: =VLOOKUP(A39,'name convert'!$A$1:$B$39,2,FALSE) -> Barracks | C39: Building | D39: 16 | E39: 2 | F39: 6 | I39: NEED | J39: 0 | L39: Training speed increase | V39: =V29+(V29*$I39) -> #VALUE! | W39: =W29+(W29*$I39) -> #VALUE! | X39: =X29+(X29*$I39) -> #VALUE!
A40: Barracks | B40: =VLOOKUP(A40,'name convert'!$A$1:$B$39,2,FALSE) -> Barracks | C40: Building | D40: 17 | E40: 2 | F40: 7 | I40: NEED | J40: 0 | L40: Training speed increase | V40: =V30+(V30*$I40) -> #VALUE! | W40: =W30+(W30*$I40) -> #VALUE! | X40: =X30+(X30*$I40) -> #VALUE!
...

Sheet Current
S1: Level Requirements | T1: Gate Requirement | U1: Time Requirements | X1: Resource Requirements | AB1: Building Requirements | AU1: Research Requirements
A2: Building / Research | B2: Type | C2: Level | D2: Might | E2: Bonus | F2: Training Time Decrease | G2: Workers | H2: Population Cap | I2: Population | J2: Labor Population | K2: Food Production | L2: Wood Production | M2: Stone Production | N2: Ore Production | O2: Food Capacity | P2: Wood Capacity | Q2: Stone Capacity | R2: Ore Capacity | S2: Player Level | T2: Item | U2: Build Time (sec) | V2: Build Time (min) | W2: Gold | X2: Food | Y2: Wood | Z2: Stone | AA2: Ore | AB2: Castle | AC2: Alchemy Lab | AD2: Cottage | AE2: Barracks | AF2: Knight's Hall | AG2: Storehouse | AH2: Rally Point | AI2: Embassy | AJ2: Blacksmith | AK2: Workshop | AL2: Watch Tower | AM2: Stable | AN2: Relief Station | AO2: Round Tower | AP2: Wall | AQ2: Farm | AR2: Sawmill | AS2: Quarry | AT2: Mine | AU2: Fertilizer | AV2: Logging | AW2: Stoneworking | AX2: Smelting | AY2: Geometry | AZ2: Eagle Eyes | BA2: Poisoned Edge | BB2: Metal Alloys | BC2: Featherweight Powder | BD2: Magical Mapping | BE2: Alloy Horseshoes | BF2: Fletching | BG2: Shrinking Powder | BH2: Healing Potions | BI2: Giant's Stength
A3: Castle | B3: Building | C3: 1 | D3: 0 | E3: Control 1 wild; 13 resource plots | S3: 0 | U3: 900 | V3: =U3/60 -> 15 | W3: 0 | X3: 200 | Y3: 3000 | Z3: 2500 | AA3: 100 | AP3: 0
A4: Castle | B4: Building | C4: =C3+1 -> 2 | D4: 0 | E4: Control 2 wilds; 16 resource plots | S4: 0 | U4: =U3*2 -> 1800 | V4: =U4/60 -> 30 | W4: 0 | X4: =X3*2 -> 400 | Y4: =Y3*2 -> 6000 | Z4: =Z3*2 -> 5000 | AA4: =AA3*2 -> 200 | AB4: 1 | AP4: 0
A5: Castle | B5: Building | C5: =C4+1 -> 3 | D5: 0 | E5: Control 3 wilds; 19 resource plots | S5: 0 | U5: =U4*2 -> 3600 | V5: =U5/60 -> 60 | W5: 0 | X5: =X4*2 -> 800 | Y5: =Y4*2 -> 12000 | Z5: =Z4*2 -> 10000 | AA5: =AA4*2 -> 400 | AB5: =AB4+1 -> 2 | AP5: 1
A6: Castle | B6: Building | C6: =C5+1 -> 4 | D6: 0 | E6: Control 4 wilds; 22 resource plots | S6: 0 | U6: =U5*2 -> 7200 | V6: =U6/60 -> 120 | W6: 0 | X6: =X5*2 -> 1600 | Y6: =Y5*2 -> 24000 | Z6: =Z5*2 -> 20000 | AA6: =AA5*2 -> 800 | AB6: =AB5+1 -> 3 | AP6: =AP5+1 -> 2
A7: Castle | B7: Building | C7: =C6+1 -> 5 | D7: 0 | E7: Control 5 wilds; 25 resource plots | S7: 0 | U7: =U6*2 -> 14400 | V7: =U7/60 -> 240 | W7: 0 | X7: =X6*2 -> 3200 | Y7: =Y6*2 -> 48000 | Z7: =Z6*2 -> 40000 | AA7: =AA6*2 -> 1600 | AB7: =AB6+1 -> 4 | AP7: =AP6+1 -> 3
A8: Castle | B8: Building | C8: =C7+1 -> 6 | D8: 0 | E8: Control 6 wilds; 28 resource plots | S8: 0 | U8: =U7*2 -> 28800 | V8: =U8/60 -> 480 | W8: 0 | X8: =X7*2 -> 6400 | Y8: =Y7*2 -> 96000 | Z8: =Z7*2 -> 80000 | AA8: =AA7*2 -> 3200 | AB8: =AB7+1 -> 5 | AP8: =AP7+1 -> 4
A9: Castle | B9: Building | C9: =C8+1 -> 7 | D9: 0 | E9: Control 7 wilds; 31 resource plots | S9: 0 | U9: =U8*2 -> 57600 | V9: =U9/60 -> 960 | W9: 0 | X9: =X8*2 -> 12800 | Y9: =Y8*2 -> 192000 | Z9: =Z8*2 -> 160000 | AA9: =AA8*2 -> 6400 | AB9: =AB8+1 -> 6 | AP9: =AP8+1 -> 5
A10: Castle | B10: Building | C10: =C9+1 -> 8 | D10: 0 | E10: Control 8 wilds; 34 resource plots | S10: 0 | U10: =U9*2 -> 115200 | V10: =U10/60 -> 1920 | W10: 0 | X10: =X9*2 -> 25600 | Y10: =Y9*2 -> 384000 | Z10: =Z9*2 -> 320000 | AA10: =AA9*2 -> 12800 | AB10: =AB9+1 -> 7 | AP10: =AP9+1 -> 6
A11: Castle | B11: Building | C11: =C10+1 -> 9 | D11: 0 | E11: Control 9 wilds; 37 resource plots | S11: 0 | U11: =U10*2 -> 230400 | V11: =U11/60 -> 3840 | W11: 0 | X11: =X10*2 -> 51200 | Y11: =Y10*2 -> 768000 | Z11: =Z10*2 -> 640000 | AA11: =AA10*2 -> 25600 | AB11: =AB10+1 -> 8 | AP11: =AP10+1 -> 7
A12: Castle | B12: Building | C12: =C11+1 -> 10 | D12: 0 | E12: Control 10 wilds; 40 resource plots | S12: 0 | T12: Divine Inspiration | U12: =U11*2 -> 460800 | V12: =U12/60 -> 7680 | W12: 0 | X12: =X11*2 -> 102400 | Y12: =Y11*2 -> 1536000 | Z12: =Z11*2 -> 1280000 | AA12: =AA11*2 -> 51200 | AB12: =AB11+1 -> 9 | AP12: =AP11+1 -> 8
A13: Castle | B13: Building | C13: =C12+1 -> 11 | V13: =U13/60 -> 0 | W13: 0
A14: Castle | B14: Building | C14: =C13+1 -> 12 | V14: =U14/60 -> 0 | W14: 0
A15: Castle | B15: Building | C15: =C14+1 -> 13 | V15: =U15/60 -> 0 | W15: 0
A16: Castle | B16: Building | C16: =C15+1 -> 14 | V16: =U16/60 -> 0 | W16: 0
A17: Castle | B17: Building | C17: =C16+1 -> 15 | V17: =U17/60 -> 0 | W17: 0
A18: Castle | B18: Building | C18: =C17+1 -> 16 | V18: =U18/60 -> 0 | W18: 0
A19: Castle | B19: Building | C19: =C18+1 -> 17 | V19: =U19/60 -> 0 | W19: 0
A20: Castle | B20: Building | C20: =C19+1 -> 18 | V20: =U20/60 -> 0 | W20: 0
A21: Castle | B21: Building | C21: =C20+1 -> 19 | V21: =U21/60 -> 0 | W21: 0
A22: Castle | B22: Building | C22: =C21+1 -> 20 | T22: Divine Blah | V22: =U22/60 -> 0 | W22: 0
A23: Alchemy Lab | B23: Building | C23: 1 | D23: 0 | S23: 2 | U23: 15 | V23: =U23/60 -> 0.25 | W23: 0 | X23: 120 | Y23: 2500 | Z23: 1500 | AA23: 200
A24: Alchemy Lab | B24: Building | C24: =C23+1 -> 2 | D24: 0 | S24: 2 | U24: 960 | V24: =U24/60 -> 16 | W24: 0 | X24: =X23*2 -> 240 | Y24: =Y23*2 -> 5000 | Z24: =Z23*2 -> 3000 | AA24: =AA23*2 -> 400 | AC24: 1
A25: Alchemy Lab | B25: Building | C25: =C24+1 -> 3 | D25: 0 | S25: 2 | U25: =U24*2 -> 1920 | V25: =U25/60 -> 32 | W25: 0 | X25: =X24*2 -> 480 | Y25: =Y24*2 -> 10000 | Z25: =Z24*2 -> 6000 | AA25: =AA24*2 -> 800 | AC25: =AC24+1 -> 2
A26: Alchemy Lab | B26: Building | C26: =C25+1 -> 4 | D26: 0 | S26: 2 | U26: =U25*2 -> 3840 | V26: =U26/60 -> 64 | W26: 0 | X26: =X25*2 -> 960 | Y26: =Y25*2 -> 20000 | Z26: =Z25*2 -> 12000 | AA26: =AA25*2 -> 1600 | AC26: =AC25+1 -> 3
A27: Alchemy Lab | B27: Building | C27: =C26+1 -> 5 | D27: 0 | S27: 2 | U27: =U26*2 -> 7680 | V27: =U27/60 -> 128 | W27: 0 | X27: =X26*2 -> 1920 | Y27: =Y26*2 -> 40000 | Z27: =Z26*2 -> 24000 | AA27: =AA26*2 -> 3200 | AC27: =AC26+1 -> 4
A28: Alchemy Lab | B28: Building | C28: =C27+1 -> 6 | D28: 0 | S28: 2 | U28: =U27*2 -> 15360 | V28: =U28/60 -> 256 | W28: 0 | X28: =X27*2 -> 3840 | Y28: =Y27*2 -> 80000 | Z28: =Z27*2 -> 48000 | AA28: =AA27*2 -> 6400 | AC28: =AC27+1 -> 5
A29: Alchemy Lab | B29: Building | C29: =C28+1 -> 7 | D29: 0 | S29: 2 | U29: =U28*2 -> 30720 | V29: =U29/60 -> 512 | W29: 0 | X29: =X28*2 -> 7680 | Y29: =Y28*2 -> 160000 | Z29: =Z28*2 -> 96000 | AA29: =AA28*2 -> 12800 | AC29: =AC28+1 -> 6
A30: Alchemy Lab | B30: Building | C30: =C29+1 -> 8 | D30: 0 | S30: 2 | U30: =U29*2 -> 61440 | V30: =U30/60 -> 1024 | W30: 0 | X30: =X29*2 -> 15360 | Y30: =Y29*2 -> 320000 | Z30: =Z29*2 -> 192000 | AA30: =AA29*2 -> 25600 | AC30: =AC29+1 -> 7
A31: Alchemy Lab | B31: Building | C31: =C30+1 -> 9 | D31: 0 | S31: 2 | U31: =U30*2 -> 122880 | V31: =U31/60 -> 2048 | W31: 0 | X31: =X30*2 -> 30720 | Y31: =Y30*2 -> 640000 | Z31: =Z30*2 -> 384000 | AA31: =AA30*2 -> 51200 | AC31: =AC30+1 -> 8
A32: Alchemy Lab | B32: Building | C32: =C31+1 -> 10 | D32: 0 | S32: 2 | T32: Divine Inspiration | U32: =U31*2 -> 245760 | V32: =U32/60 -> 4096 | W32: 0 | X32: =X31*2 -> 61440 | Y32: =Y31*2 -> 1280000 | Z32: =Z31*2 -> 768000 | AA32: =AA31*2 -> 102400 | AC32: =AC31+1 -> 9
A33: Alchemy Lab | B33: Building | C33: =C32+1 -> 11 | V33: =U33/60 -> 0 | W33: 0
A34: Alchemy Lab | B34: Building | C34: =C33+1 -> 12 | V34: =U34/60 -> 0 | W34: 0
A35: Alchemy Lab | B35: Building | C35: =C34+1 -> 13 | V35: =U35/60 -> 0 | W35: 0
A36: Alchemy Lab | B36: Building | C36: =C35+1 -> 14 | V36: =U36/60 -> 0 | W36: 0
A37: Alchemy Lab | B37: Building | C37: =C36+1 -> 15 | V37: =U37/60 -> 0 | W37: 0
A38: Alchemy Lab | B38: Building | C38: =C37+1 -> 16 | V38: =U38/60 -> 0 | W38: 0
A39: Alchemy Lab | B39: Building | C39: =C38+1 -> 17 | V39: =U39/60 -> 0 | W39: 0
A40: Alchemy Lab | B40: Building | C40: =C39+1 -> 18 | V40: =U40/60 -> 0 | W40: 0
...

Sheet requirements
E1: 3 | G1: Level Requirements | H1: Gate Requirement | I1: Time Requirements | J1: Time Requirements | K1: Resource Requirements | L1: Resource Requirements | M1: Resource Requirements | N1: Resource Requirements | O1: Resource Requirements | P1: Building Requirements | Q1: Building Requirements | R1: Building Requirements | S1: Building Requirements | T1: Building Requirements | U1: Building Requirements | V1: Building Requirements | W1: Building Requirements | X1: Building Requirements | Y1: Building Requirements | Z1: Building Requirements | AA1: Building Requirements | AB1: Building Requirements | AC1: Building Requirements | AD1: Building Requirements | AE1: Building Requirements | AF1: Building Requirements | AG1: Building Requirements | AH1: Building Requirements | AI1: Research Requirements | AJ1: Research Requirements | AK1: Research Requirements | AL1: Research Requirements | AM1: Research Requirements | AN1: Research Requirements | AO1: Research Requirements | AP1: Research Requirements | AQ1: Research Requirements | AR1: Research Requirements | AS1: Research Requirements | AT1: Research Requirements | AU1: Research Requirements | AV1: Research Requirements | AW1: Research Requirements
A2: Building / Research | B2: Building / Research | C2: Type | D2: Level ID | E2: Prestige Level | F2: Building Level | G2: Player Level | H2: Item | I2: Build Time (sec) | J2: Build Time (min) | K2: Gold | L2: Food | M2: Wood | N2: Stone | O2: Ore | P2: Castle | Q2: Alchemy Lab | R2: Cottage | S2: Barracks | T2: Knight's Hall | U2: Storehouse | V2: Rally Point | W2: Embassy | X2: Blacksmith | Y2: Workshop | Z2: Watch Tower | AA2: Stable | AB2: Relief Station | AC2: Round Tower | AD2: Wall | AE2: Farm | AF2: Sawmill | AG2: Quarry | AH2: Mine | AI2: Fertilizer | AJ2: Logging | AK2: Stoneworking | AL2: Smelting | AM2: Geometry | AN2: Eagle Eyes | AO2: Poisoned Edge | AP2: Metal Alloys | AQ2: Featherweight Powder | AR2: Magical Mapping | AS2: Alloy Horseshoes | AT2: Fletching | AU2: Shrinking Powder | AV2: Healing Potions | AW2: Giant's Stength
A3: Building / Research | B3: Building / Research | C3: Type | D3: Level ID | E3: Prestige Level | F3: Building Level | G3: Player Level | H3: Item | I3: Build Time (sec) | J3: Build Time (min) | K3: Gold | L3: Food | M3: Wood | N3: Stone | O3: Ore | P3: =VLOOKUP(P2,'name convert'!$A$1:$B$39,2,FALSE) -> keep | Q3: =VLOOKUP(Q2,'name convert'!$A$1:$B$39,2,FALSE) -> Academy | R3: =VLOOKUP(R2,'name convert'!$A$1:$B$39,2,FALSE) -> home | S3: =VLOOKUP(S2,'name convert'!$A$1:$B$39,2,FALSE) -> Barracks | T3: =VLOOKUP(T2,'name convert'!$A$1:$B$39,2,FALSE) -> Great hall | U3: =VLOOKUP(U2,'name convert'!$A$1:$B$39,2,FALSE) -> vault | V3: =VLOOKUP(V2,'name convert'!$A$1:$B$39,2,FALSE) -> Muster Field | W3: =VLOOKUP(W2,'name convert'!$A$1:$B$39,2,FALSE) -> Embassy | ... AW3: =VLOOKUP(AW2,'name convert'!$A$1:$B$39,2,FALSE) -> Engineering
A4: Alchemy Lab | B4: =VLOOKUP(A4,'name convert'!$A$1:$B$50,2,FALSE) -> Academy | C4: Building | D4: 1 | E4: 1 | F4: 1 | G4: 2 | I4: 15 | J4: =I4/60 -> 0.25 | K4: 0 | L4: 120 | M4: 2500 | N4: 1500 | O4: 200
A5: Alchemy Lab | B5: =VLOOKUP(A5,'name convert'!$A$1:$B$50,2,FALSE) -> Academy | C5: Building | D5: 2 | E5: 1 | F5: 2 | G5: 2 | I5: 960 | J5: =I5/60 -> 16 | K5: 0 | L5: =L4*2 -> 240 | M5: =M4*2 -> 5000 | N5: =N4*2 -> 3000 | O5: =O4*2 -> 400 | Q5: 1
A6: Alchemy Lab | B6: =VLOOKUP(A6,'name convert'!$A$1:$B$50,2,FALSE) -> Academy | C6: Building | D6: 3 | E6: 1 | F6: 3 | G6: 2 | I6: =I5*2 -> 1920 | J6: =I6/60 -> 32 | K6: 0 | L6: =L5*2 -> 480 | M6: =M5*2 -> 10000 | N6: =N5*2 -> 6000 | O6: =O5*2 -> 800 | Q6: =Q5+1 -> 2
A7: Alchemy Lab | B7: =VLOOKUP(A7,'name convert'!$A$1:$B$50,2,FALSE) -> Academy | C7: Building | D7: 4 | E7: 1 | F7: 4 | G7: 2 | I7: =I6*2 -> 3840 | J7: =I7/60 -> 64 | K7: 0 | L7: =L6*2 -> 960 | M7: =M6*2 -> 20000 | N7: =N6*2 -> 12000 | O7: =O6*2 -> 1600 | Q7: =Q6+1 -> 3
A8: Alchemy Lab | B8: =VLOOKUP(A8,'name convert'!$A$1:$B$50,2,FALSE) -> Academy | C8: Building | D8: 5 | E8: 1 | F8: 5 | G8: 2 | I8: =I7*2 -> 7680 | J8: =I8/60 -> 128 | K8: 0 | L8: =L7*2 -> 1920 | M8: =M7*2 -> 40000 | N8: =N7*2 -> 24000 | O8: =O7*2 -> 3200 | Q8: =Q7+1 -> 4
A9: Alchemy Lab | B9: =VLOOKUP(A9,'name convert'!$A$1:$B$50,2,FALSE) -> Academy | C9: Building | D9: 6 | E9: 1 | F9: 6 | G9: 2 | I9: =I8*2 -> 15360 | J9: =I9/60 -> 256 | K9: 0 | L9: =L8*2 -> 3840 | M9: =M8*2 -> 80000 | N9: =N8*2 -> 48000 | O9: =O8*2 -> 6400 | Q9: =Q8+1 -> 5
A10: Alchemy Lab | B10: =VLOOKUP(A10,'name convert'!$A$1:$B$50,2,FALSE) -> Academy | C10: Building | D10: 7 | E10: 1 | F10: 7 | G10: 2 | I10: =I9*2 -> 30720 | J10: =I10/60 -> 512 | K10: 0 | L10: =L9*2 -> 7680 | M10: =M9*2 -> 160000 | N10: =N9*2 -> 96000 | O10: =O9*2 -> 12800 | Q10: =Q9+1 -> 6
A11: Alchemy Lab | B11: =VLOOKUP(A11,'name convert'!$A$1:$B$50,2,FALSE) -> Academy | C11: Building | D11: 8 | E11: 1 | F11: 8 | G11: 2 | I11: =I10*2 -> 61440 | J11: =I11/60 -> 1024 | K11: 0 | L11: =L10*2 -> 15360 | M11: =M10*2 -> 320000 | N11: =N10*2 -> 192000 | O11: =O10*2 -> 25600 | Q11: =Q10+1 -> 7
A12: Alchemy Lab | B12: =VLOOKUP(A12,'name convert'!$A$1:$B$50,2,FALSE) -> Academy | C12: Building | D12: 9 | E12: 1 | F12: 9 | G12: 2 | I12: =I11*2 -> 122880 | J12: =I12/60 -> 2048 | K12: 0 | L12: =L11*2 -> 30720 | M12: =M11*2 -> 640000 | N12: =N11*2 -> 384000 | O12: =O11*2 -> 51200 | Q12: =Q11+1 -> 8
A13: Alchemy Lab | B13: =VLOOKUP(A13,'name convert'!$A$1:$B$50,2,FALSE) -> Academy | C13: Building | D13: 10 | E13: 1 | F13: 10 | G13: 2 | H13: Divine Inspiration | I13: =I12*2 -> 245760 | J13: =I13/60 -> 4096 | K13: 0 | L13: =L12*2 -> 61440 | M13: =M12*2 -> 1280000 | N13: =N12*2 -> 768000 | O13: =O12*2 -> 102400 | Q13: =Q12+1 -> 9
A14: Alchemy Lab | B14: =VLOOKUP(A14,'name convert'!$A$1:$B$50,2,FALSE) -> Academy | C14: Building | D14: 11 | E14: 2 | F14: 1 | G14: 2 | I14: 0 | J14: =I14/60 -> 0 | K14: 0 | L14: 0 | M14: 0 | N14: 0 | O14: 0 | P14: 11 | Q14: =Q13+1 -> 10
A15: Alchemy Lab | B15: =VLOOKUP(A15,'name convert'!$A$1:$B$50,2,FALSE) -> Academy | C15: Building | D15: 12 | E15: 2 | F15: 2 | G15: 2 | I15: =(I5)*3 -> 2880 | J15: =I15/60 -> 48 | K15: 0 | L15: =L5 -> 240 | M15: =M5 -> 5000 | N15: =N5 -> 3000 | O15: =O5 -> 400 | P15: =P14+1 -> 12 | Q15: =Q14+1 -> 11
A16: Alchemy Lab | B16: =VLOOKUP(A16,'name convert'!$A$1:$B$50,2,FALSE) -> Academy | C16: Building | D16: 13 | E16: 2 | F16: 3 | G16: 2 | I16: =(I6)*3 -> 5760 | J16: =I16/60 -> 96 | K16: 0 | L16: =L6 -> 480 | M16: =M6 -> 10000 | N16: =N6 -> 6000 | O16: =O6 -> 800 | P16: =P15+1 -> 13 | Q16: =Q15+1 -> 12
A17: Alchemy Lab | B17: =VLOOKUP(A17,'name convert'!$A$1:$B$50,2,FALSE) -> Academy | C17: Building | D17: 14 | E17: 2 | F17: 4 | G17: 2 | I17: =(I7)*3 -> 11520 | J17: =I17/60 -> 192 | K17: 0 | L17: =L7 -> 960 | M17: =M7 -> 20000 | N17: =N7 -> 12000 | O17: =O7 -> 1600 | P17: =P16+1 -> 14 | Q17: =Q16+1 -> 13
A18: Alchemy Lab | B18: =VLOOKUP(A18,'name convert'!$A$1:$B$50,2,FALSE) -> Academy | C18: Building | D18: 15 | E18: 2 | F18: 5 | G18: 2 | I18: =(I8)*3 -> 23040 | J18: =I18/60 -> 384 | K18: 0 | L18: =L8 -> 1920 | M18: =M8 -> 40000 | N18: =N8 -> 24000 | O18: =O8 -> 3200 | P18: =P17+1 -> 15 | Q18: =Q17+1 -> 14
A19: Alchemy Lab | B19: =VLOOKUP(A19,'name convert'!$A$1:$B$50,2,FALSE) -> Academy | C19: Building | D19: 16 | E19: 2 | F19: 6 | G19: 2 | I19: =(I9)*3 -> 46080 | J19: =I19/60 -> 768 | K19: 0 | L19: =L9 -> 3840 | M19: =M9 -> 80000 | N19: =N9 -> 48000 | O19: =O9 -> 6400 | P19: =P18+1 -> 16 | Q19: =Q18+1 -> 15
A20: Alchemy Lab | B20: =VLOOKUP(A20,'name convert'!$A$1:$B$50,2,FALSE) -> Academy | C20: Building | D20: 17 | E20: 2 | F20: 7 | G20: 2 | I20: =(I10)*3 -> 92160 | J20: =I20/60 -> 1536 | K20: 0 | L20: =L10 -> 7680 | M20: =M10 -> 160000 | N20: =N10 -> 96000 | O20: =O10 -> 12800 | P20: =P19+1 -> 17 | Q20: =Q19+1 -> 16
A21: Alchemy Lab | B21: =VLOOKUP(A21,'name convert'!$A$1:$B$50,2,FALSE) -> Academy | C21: Building | D21: 18 | E21: 2 | F21: 8 | G21: 2 | I21: =(I11)*3 -> 184320 | J21: =I21/60 -> 3072 | K21: 0 | L21: =L11 -> 15360 | M21: =M11 -> 320000 | N21: =N11 -> 192000 | O21: =O11 -> 25600 | P21: =P20+1 -> 18 | Q21: =Q20+1 -> 17
A22: Alchemy Lab | B22: =VLOOKUP(A22,'name convert'!$A$1:$B$50,2,FALSE) -> Academy | C22: Building | D22: 19 | E22: 2 | F22: 9 | G22: 2 | I22: =(I12)*3 -> 368640 | J22: =I22/60 -> 6144 | K22: 0 | L22: =L12 -> 30720 | M22: =M12 -> 640000 | N22: =N12 -> 384000 | O22: =O12 -> 51200 | P22: =P21+1 -> 19 | Q22: =Q21+1 -> 18
A23: Alchemy Lab | B23: =VLOOKUP(A23,'name convert'!$A$1:$B$50,2,FALSE) -> Academy | C23: Building | D23: 20 | E23: 2 | F23: 10 | G23: 2 | I23: =(I13)*3 -> 737280 | J23: =I23/60 -> 12288 | K23: 0 | L23: =L13 -> 61440 | M23: =M13 -> 1280000 | N23: =N13 -> 768000 | O23: =O13 -> 102400 | P23: =P22+1 -> 20 | Q23: =Q22+1 -> 19
A24: Alchemy Lab | B24: =VLOOKUP(A24,'name convert'!$A$1:$B$50,2,FALSE) -> Academy | C24: Building | D24: 21 | E24: 2 | F24: 11 | G24: 2 | H24: Divine Blah | I24: 737280 | J24: 4096 | K24: 0 | L24: 61440 | M24: 1280000 | N24: 768000 | O24: 102400 | P24: =P23+1 -> 21 | Q24: =Q23+1 -> 20
A25: Barracks | B25: =VLOOKUP(A25,'name convert'!$A$1:$B$50,2,FALSE) -> Barracks | C25: Building | D25: 1 | E25: 1 | F25: 1 | G25: 2 | I25: 300 | J25: =I25/60 -> 5 | K25: 0 | L25: 250 | M25: 1200 | N25: 1500 | O25: 500
A26: Barracks | B26: =VLOOKUP(A26,'name convert'!$A$1:$B$50,2,FALSE) -> Barracks | C26: Building | D26: 2 | E26: 1 | F26: 2 | G26: 2 | I26: =I25*2 -> 600 | J26: =I26/60 -> 10 | K26: 0 | L26: =L25*2 -> 500 | M26: =M25*2 -> 2400 | N26: =N25*2 -> 3000 | O26: =O25*2 -> 1000 | S26: 1
A27: Barracks | B27: =VLOOKUP(A27,'name convert'!$A$1:$B$50,2,FALSE) -> Barracks | C27: Building | D27: 3 | E27: 1 | F27: 3 | G27: 2 | I27: =I26*2 -> 1200 | J27: =I27/60 -> 20 | K27: 0 | L27: =L26*2 -> 1000 | M27: =M26*2 -> 4800 | N27: =N26*2 -> 6000 | O27: =O26*2 -> 2000 | S27: =S26+1 -> 2
A28: Barracks | B28: =VLOOKUP(A28,'name convert'!$A$1:$B$50,2,FALSE) -> Barracks | C28: Building | D28: 4 | E28: 1 | F28: 4 | G28: 2 | I28: =I27*2 -> 2400 | J28: =I28/60 -> 40 | K28: 0 | L28: =L27*2 -> 2000 | M28: =M27*2 -> 9600 | N28: =N27*2 -> 12000 | O28: =O27*2 -> 4000 | S28: =S27+1 -> 3
A29: Barracks | B29: =VLOOKUP(A29,'name convert'!$A$1:$B$50,2,FALSE) -> Barracks | C29: Building | D29: 5 | E29: 1 | F29: 5 | G29: 2 | I29: =I28*2 -> 4800 | J29: =I29/60 -> 80 | K29: 0 | L29: =L28*2 -> 4000 | M29: =M28*2 -> 19200 | N29: =N28*2 -> 24000 | O29: =O28*2 -> 8000 | S29: =S28+1 -> 4
A30: Barracks | B30: =VLOOKUP(A30,'name convert'!$A$1:$B$50,2,FALSE) -> Barracks | C30: Building | D30: 6 | E30: 1 | F30: 6 | G30: 2 | I30: =I29*2 -> 9600 | J30: =I30/60 -> 160 | K30: 0 | L30: =L29*2 -> 8000 | M30: =M29*2 -> 38400 | N30: =N29*2 -> 48000 | O30: =O29*2 -> 16000 | S30: =S29+1 -> 5
A31: Barracks | B31: =VLOOKUP(A31,'name convert'!$A$1:$B$50,2,FALSE) -> Barracks | C31: Building | D31: 7 | E31: 1 | F31: 7 | G31: 2 | I31: =I30*2 -> 19200 | J31: =I31/60 -> 320 | K31: 0 | L31: =L30*2 -> 16000 | M31: =M30*2 -> 76800 | N31: =N30*2 -> 96000 | O31: =O30*2 -> 32000 | S31: =S30+1 -> 6
A32: Barracks | B32: =VLOOKUP(A32,'name convert'!$A$1:$B$50,2,FALSE) -> Barracks | C32: Building | D32: 8 | E32: 1 | F32: 8 | G32: 2 | I32: =I31*2 -> 38400 | J32: =I32/60 -> 640 | K32: 0 | L32: =L31*2 -> 32000 | M32: =M31*2 -> 153600 | N32: =N31*2 -> 192000 | O32: =O31*2 -> 64000 | S32: =S31+1 -> 7
A33: Barracks | B33: =VLOOKUP(A33,'name convert'!$A$1:$B$50,2,FALSE) -> Barracks | C33: Building | D33: 9 | E33: 1 | F33: 9 | G33: 2 | I33: =I32*2 -> 76800 | J33: =I33/60 -> 1280 | K33: 0 | L33: =L32*2 -> 64000 | M33: =M32*2 -> 307200 | N33: =N32*2 -> 384000 | O33: =O32*2 -> 128000 | S33: =S32+1 -> 8
A34: Barracks | B34: =VLOOKUP(A34,'name convert'!$A$1:$B$50,2,FALSE) -> Barracks | C34: Building | D34: 10 | E34: 1 | F34: 10 | G34: 2 | H34: Divine Inspiration | I34: =I33*2 -> 153600 | J34: =I34/60 -> 2560 | K34: 0 | L34: =L33*2 -> 128000 | M34: =M33*2 -> 614400 | N34: =N33*2 -> 768000 | O34: =O33*2 -> 256000 | S34: =S33+1 -> 9
A35: Barracks | B35: =VLOOKUP(A35,'name convert'!$A$1:$B$50,2,FALSE) -> Barracks | C35: Building | D35: 11 | E35: 2 | F35: 1 | G35: 15 | I35: 0 | J35: =I35/60 -> 0 | K35: 0 | L35: 0 | M35: 0 | N35: 0 | O35: 0 | P35: 11 | S35: =S34+1 -> 10
A36: Barracks | B36: =VLOOKUP(A36,'name convert'!$A$1:$B$50,2,FALSE) -> Barracks | C36: Building | D36: 12 | E36: 2 | F36: 2 | G36: 15 | I36: 1800 | J36: =I36/60 -> 30 | K36: 0 | L36: =L26 -> 500 | M36: =M26 -> 2400 | N36: =N26 -> 3000 | O36: =O26 -> 1000 | P36: =P35+1 -> 12 | S36: =S35+1 -> 11
A37: Barracks | B37: =VLOOKUP(A37,'name convert'!$A$1:$B$50,2,FALSE) -> Barracks | C37: Building | D37: 13 | E37: 2 | F37: 3 | G37: 15 | I37: 3600 | J37: =I37/60 -> 60 | K37: 0 | L37: =L27 -> 1000 | M37: =M27 -> 4800 | N37: =N27 -> 6000 | O37: =O27 -> 2000 | P37: =P36+1 -> 13 | S37: =S36+1 -> 12
A38: Barracks | B38: =VLOOKUP(A38,'name convert'!$A$1:$B$50,2,FALSE) -> Barracks | C38: Building | D38: 14 | E38: 2 | F38: 4 | G38: 15 | I38: 7200 | J38: =I38/60 -> 120 | K38: 0 | L38: =L28 -> 2000 | M38: =M28 -> 9600 | N38: =N28 -> 12000 | O38: =O28 -> 4000 | P38: =P37+1 -> 14 | S38: =S37+1 -> 13
A39: Barracks | B39: =VLOOKUP(A39,'name convert'!$A$1:$B$50,2,FALSE) -> Barracks | C39: Building | D39: 15 | E39: 2 | F39: 5 | G39: 15 | I39: 14400 | J39: =I39/60 -> 240 | K39: 0 | L39: =L29 -> 4000 | M39: =M29 -> 19200 | N39: =N29 -> 24000 | O39: =O29 -> 8000 | P39: =P38+1 -> 15 | S39: =S38+1 -> 14
A40: Barracks | B40: =VLOOKUP(A40,'name convert'!$A$1:$B$50,2,FALSE) -> Barracks | C40: Building | D40: 16 | E40: 2 | F40: 6 | G40: 15 | I40: 28800 | J40: =I40/60 -> 480 | K40: 0 | L40: =L30 -> 8000 | M40: =M30 -> 38400 | N40: =N30 -> 48000 | O40: =O30 -> 16000 | P40: =P39+1 -> 16 | S40: =S39+1 -> 15
...

Sheet building_require
C1: buildings name | D1: building required | E1: research required | F1: now | G1: prestige
A2: 2 | B2: doing | C2: castle | D2: wall | F2: Control wild; unlock resource plots | G2: Control more wild;unlock resource plots
A3: 2 | B3: done | C3: cottage | D3: castle | F3: Increase population rate; increase population cap | G3: Increase population rate; increase population cap
A4: 2 | C4: wall | D4: quarry | F4: Build defensive troops； increases # of defense slots | G4: increases # of defense slots,queue
C5: workshop | F5: combine stone | G5: combine high level stones
A6: 1 | B6: done | C6: storehouse | F6: Protects resources from PvP attacks | G6: Protects resources from PvP attacks,Gold
A7: 1 | B7: doing | C7: barracks | F7: unlock Train troops; training speed decrease | G7: unlock T4 T5 T6 Train troops; training speed decrease
C8: relief station | D8: stable | E8: alloy horseshoes | F8: Raises speed for support marches | G8: Raises speed for support marches
A9: 确定功能 | C9: embassy | F9: Can join/create alliance; the number of reinforcing army | G9: alliance help need gems,view alliacen members
A10: 确定功能 | C10: RoundTower
A11: 工作量大 | C11: alchemy lab | F11: Level # research
A12: 星级将军 | C12: knights hall | F12: Unlocks knights
A13: 2 | C13: quarry
A14: 2 | C14: sawmill
A15: 2 | C15: farm
A16: 2 | C16: mine
A17: 确定功能 | C17: watchtower
A18: 1 | C18: rallly point | F18: Increases number of marches and troop cap per march | G18: troop cap per march
C19: stable | D19: farm | F19: train mounted troops faster
C20: blacksmith | D20: mine

Sheet name convert
A1: Castle | B1: keep
A2: Alchemy Lab | B2: Academy
A3: Barracks | B3: Barracks
A4: Knight's Hall | B4: Great hall
A5: Satellite Station | B5: Satellite Station
A6: Cottage | B6: home
A7: Embassy | B7: Embassy
A8: Trading Post | B8: Trading Post
A9: Rally Point | B9: Muster Field
A10: Relief Station | B10: Traven
A11: Stable | B11: Stables
A12: Perimeter | B12: Perimeter
... A40: Logistics Center | B40: Tavern

Sheet hobbits requirement
AY1: levelneeded | CJ1: army money cost
A2: ` | B2: Type | C2: Level ID | D2: Prestige Level | E2: Building Level | F2: Player Level | G2: Item | H2: Build Time (sec) | I2: Build Time (min) | J2: experience gained | K2: Gold | L2: Food | M2: Wood | N2: Stone | O2: Ore | P2: peopleused | Q2: keep | R2: Academy | S2: home | T2: Barracks | U2: Great hall | V2: vault | W2: Muster Field | X2: Embassy | Y2: Forge | Z2: Armory | AA2: Watch tower | AB2: Stables | AC2: Tavern | AD2: Sage's Tower | AE2: City wall | AF2: Farm | AG2: Arboretum | AH2: Quarry | AI2: MINE/ore vein | AJ2: Fertilizer | AK2: Arbors | AL2: Masonry | AM2: Smelting | AN2: Siege Weapons | AO2: Far Seeing | AP2: Honed Blades | AQ2: Metal Alloys | AR2: Saddlebags | AS2: Catorgraphy | AT2: Horseshoes | AU2: Fletching | AV2: StrongBox | AW2: Vigor | AX2: Engineering | AY2: keep | AZ2: Academy | BA2: home | BB2: Barracks | BC2: Great hall | BD2: vault | BE2: Muster Field | BF2: Embassy | BG2: Forge | BH2: Armory | BI2: Watch tower | BJ2: Stables | BK2: tavern | BL2: Sage's Tower | BM2: City wall | BN2: Farm | BO2: Arboretum | BP2: Quarry | BQ2: MINE/ore vein | BR2: Fertilizer | BS2: Arbors | BT2: Masonry | BU2: Smelting | BV2: Siege Weapons | BW2: Far Seeing | BX2: Honed Blades | BY2: Metal Alloys | BZ2: Saddlebags | CA2: Catorgraphy | CB2: Horseshoes | CC2: Fletching | CD2: StrongBox | CE2: Vigor | CF2: Engineering | CG2: totalrequired | CH2: maxrequiredlevel | CI2: gold(total l) | CJ2: Fertilizer | CK2: Arbors | CL2: Masonry | CM2: Smelting | CN2: Siege Weapons | CO2: Far Seeing | CP2: Honed Blades | CQ2: Metal Alloys | CR2: Saddlebags | CS2: Catorgraphy | CT2: Horseshoes | CU2: Fletching | CV2: StrongBox | CW2: Vigor | CX2: Engineering | CY2: total cost
A3: keep | B3: Building | C3: 1 | D3: 1 | E3: 1 | F3: 0 | H3: 900 | I3: 15 | J3: =ROUNDUP(H3/30,0) -> 30 | K3: 0 | L3: 200 | M3: 3000 | N3: 2500 | O3: 100 | AE3: 0 | AY3: =SUMIFS($F$3:$F$341,$A$3:$A$341,Q$2,$C$3:$C$341,Q3) -> 0 | AZ3: =SUMIFS($F$3:$F$341,$A$3:$A$341,R$2,$C$3:$C$341,R3) -> 0 | BA3: =SUMIFS($F$3:$F$341,$A$3:$A$341,S$2,$C$3:$C$341,S3) -> 0 | BB3: =SUMIFS($F$3:$F$341,$A$3:$A$341,T$2,$C$3:$C$341,T3) -> 0 | BC3: =SUMIFS($F$3:$F$341,$A$3:$A$341,U$2,$C$3:$C$341,U3) -> 0 | BD3: =SUMIFS($F$3:$F$341,$A$3:$A$341,V$2,$C$3:$C$341,V3) -> 0 | BE3: =SUMIFS($F$3:$F$341,$A$3:$A$341,W$2,$C$3:$C$341,W3) -> 0 | BF3: =SUMIFS($F$3:$F$341,$A$3:$A$341,X$2,$C$3:$C$341,X3) -> 0 | ... CF3: =SUMIFS($F$3:$F$341,$A$3:$A$341,AX$2,$C$3:$C$341,AX3) -> 0 | CG3: =MAX(AY3:CF3) -> 0 | CH3: =MAX(F3,CG3) -> 0
A4: keep | B4: Building | C4: 2 | D4: 1 | E4: 2 | F4: 0 | H4: 1800 | I4: 30 | J4: =ROUNDUP(H4/30,0) -> 60 | K4: 0 | L4: 400 | M4: 6000 | N4: 5000 | O4: 200 | Q4: 1 | AE4: 0 | AY4: =SUMIFS($F$3:$F$341,$A$3:$A$341,Q$2,$C$3:$C$341,Q4) -> 0 | AZ4: =SUMIFS($F$3:$F$341,$A$3:$A$341,R$2,$C$3:$C$341,R4) -> 0 | BA4: =SUMIFS($F$3:$F$341,$A$3:$A$341,S$2,$C$3:$C$341,S4) -> 0 | BB4: =SUMIFS($F$3:$F$341,$A$3:$A$341,T$2,$C$3:$C$341,T4) -> 0 | BC4: =SUMIFS($F$3:$F$341,$A$3:$A$341,U$2,$C$3:$C$341,U4) -> 0 | BD4: =SUMIFS($F$3:$F$341,$A$3:$A$341,V$2,$C$3:$C$341,V4) -> 0 | BE4: =SUMIFS($F$3:$F$341,$A$3:$A$341,W$2,$C$3:$C$341,W4) -> 0 | BF4: =SUMIFS($F$3:$F$341,$A$3:$A$341,X$2,$C$3:$C$341,X4) -> 0 | ... CF4: =SUMIFS($F$3:$F$341,$A$3:$A$341,AX$2,$C$3:$C$341,AX4) -> 0 | CG4: =MAX(AY4:CF4) -> 0 | CH4: =MAX(F4,CG4) -> 0
A5: home | B5: Building | C5: 1 | D5: 1 | E5: 1 | F5: 0 | H5: 5 | I5: 0.083333333 | J5: =ROUNDUP(H5/30,0) -> 1 | K5: 0 | L5: 100 | M5: 500 | N5: 100 | O5: 50 | AY5: =SUMIFS($CH$3:$CH$341,$A$3:$A$341,Q$2,$C$3:$C$341,Q5) -> 0 | AZ5: =SUMIFS($CH$3:$CH$341,$A$3:$A$341,R$2,$C$3:$C$341,R5) -> 0 | BA5: =SUMIFS($CH$3:$CH$341,$A$3:$A$341,S$2,$C$3:$C$341,S5) -> 0 | BB5: =SUMIFS($CH$3:$CH$341,$A$3:$A$341,T$2,$C$3:$C$341,T5) -> 0 | BC5: =SUMIFS($CH$3:$CH$341,$A$3:$A$341,U$2,$C$3:$C$341,U5) -> 0 | BD5: =SUMIFS($CH$3:$CH$341,$A$3:$A$341,V$2,$C$3:$C$341,V5) -> 0 | BE5: =SUMIFS($CH$3:$CH$341,$A$3:$A$341,W$2,$C$3:$C$341,W5) -> 0 | BF5: =SUMIFS($CH$3:$CH$341,$A$3:$A$341,X$2,$C$3:$C$341,X5) -> 0 | ... CF5: =SUMIFS($CH$3:$CH$341,$A$3:$A$341,AX$2,$C$3:$C$341,AX5) -> 0 | CG5: =MAX(AY5:CF5) -> 0 | CH5: =MAX(F5,CG5) -> 0
A6: home | B6: Building | C6: 2 | D6: 1 | E6: 2 | F6: 0 | H6: 30 | I6: 0.5 | J6: =ROUNDUP(H6/30,0) -> 1 | K6: 0 | L6: 200 | M6: 1000 | N6: 200 | O6: 100 | Q6: 1 | S6: 1 | AY6: =SUMIFS($CH$3:$CH$341,$A$3:$A$341,Q$2,$C$3:$C$341,Q6) -> 0 | AZ6: =SUMIFS($CH$3:$CH$341,$A$3:$A$341,R$2,$C$3:$C$341,R6) -> 0 | BA6: =SUMIFS($CH$3:$CH$341,$A$3:$A$341,S$2,$C$3:$C$341,S6) -> 0 | BB6: =SUMIFS($CH$3:$CH$341,$A$3:$A$341,T$2,$C$3:$C$341,T6) -> 0 | BC6: =SUMIFS($CH$3:$CH$341,$A$3:$A$341,U$2,$C$3:$C$341,U6) -> 0 | BD6: =SUMIFS($CH$3:$CH$341,$A$3:$A$341,V$2,$C$3:$C$341,V6) -> 0 | BE6: =SUMIFS($CH$3:$CH$341,$A$3:$A$341,W$2,$C$3:$C$341,W6) -> 0 | BF6: =SUMIFS($CH$3:$CH$341,$A$3:$A$341,X$2,$C$3:$C$341,X6) -> 0 | ... CF6: =SUMIFS($CH$3:$CH$341,$A$3:$A$341,AX$2,$C$3:$C$341,AX6) -> 0 | CG6: =MAX(AY6:CF6) -> 0 | CH6: =MAX(F6,CG6) -> 0
A7: home | B7: Building | C7: 3 | D7: 1 | E7: 3 | F7: 0 | H7: 120 | I7: 2 | J7: =ROUNDUP(H7/30,0) -> 4 | K7: 0 | L7: 400 | M7: 2000 | N7: 400 | O7: 200 | Q7: 2 | S7: 2 | AY7: =SUMIFS($CH$3:$CH$341,$A$3:$A$341,Q$2,$C$3:$C$341,Q7) -> 0 | AZ7: =SUMIFS($CH$3:$CH$341,$A$3:$A$341,R$2,$C$3:$C$341,R7) -> 0 | BA7: =SUMIFS($CH$3:$CH$341,$A$3:$A$341,S$2,$C$3:$C$341,S7) -> 0 | BB7: =SUMIFS($CH$3:$CH$341,$A$3:$A$341,T$2,$C$3:$C$341,T7) -> 0 | BC7: =SUMIFS($CH$3:$CH$341,$A$3:$A$341,U$2,$C$3:$C$341,U7) -> 0 | BD7: =SUMIFS($CH$3:$CH$341,$A$3:$A$341,V$2,$C$3:$C$341,V7) -> 0 | BE7: =SUMIFS($CH$3:$CH$341,$A$3:$A$341,W$2,$C$3:$C$341,W7) -> 0 | BF7: =SUMIFS($CH$3:$CH$341,$A$3:$A$341,X$2,$C$3:$C$341,X7) -> 0 | ... CF7: =SUMIFS($CH$3:$CH$341,$A$3:$A$341,AX$2,$C$3:$C$341,AX7) -> 0 | CG7: =MAX(AY7:CF7) -> 0 | CH7: =MAX(F7,CG7) -> 0
A8: Farm | B8: Building | C8: 1 | D8: 1 | E8: 1 | F8: 0 | H8: 5 | I8: 0.083333333 | J8: =ROUNDUP(H8/30,0) -> 1 | K8: 0 | L8: 50 | M8: 300 | N8: 200 | O8: 150 | P8: 10 | AY8: =SUMIFS($CH$3:$CH$341,$A$3:$A$341,Q$2,$C$3:$C$341,Q8) -> 0 | AZ8: =SUMIFS($CH$3:$CH$341,$A$3:$A$341,R$2,$C$3:$C$341,R8) -> 0 | BA8: =SUMIFS($CH$3:$CH$341,$A$3:$A$341,S$2,$C$3:$C$341,S8) -> 0 | BB8: =SUMIFS($CH$3:$CH$341,$A$3:$A$341,T$2,$C$3:$C$341,T8) -> 0 | BC8: =SUMIFS($CH$3:$CH$341,$A$3:$A$341,U$2,$C$3:$C$341,U8) -> 0 | BD8: =SUMIFS($CH$3:$CH$341,$A$3:$A$341,V$2,$C$3:$C$341,V8) -> 0 | BE8: =SUMIFS($CH$3:$CH$341,$A$3:$A$341,W$2,$C$3:$C$341,W8) -> 0 | BF8: =SUMIFS($CH$3:$CH$341,$A$3:$A$341,X$2,$C$3:$C$341,X8) -> 0 | ... CF8: =SUMIFS($CH$3:$CH$341,$A$3:$A$341,AX$2,$C$3:$C$341,AX8) -> 0 | CG8: =MAX(AY8:CF8) -> 0 | CH8: =MAX(F8,CG8) -> 0
A9: Farm | B9: Building | C9: 2 | D9: 1 | E9: 2 | F9: 0 | H9: 30 | I9: 0.5 | J9: =ROUNDUP(H9/30,0) -> 1 | K9: 0 | L9: 100 | M9: 600 | N9: 400 | O9: 300 | P9: 30 | AF9: 1 | AY9: =SUMIFS($CH$3:$CH$341,$A$3:$A$341,Q$2,$C$3:$C$341,Q9) -> 0 | AZ9: =SUMIFS($CH$3:$CH$341,$A$3:$A$341,R$2,$C$3:$C$341,R9) -> 0 | BA9: =SUMIFS($CH$3:$CH$341,$A$3:$A$341,S$2,$C$3:$C$341,S9) -> 0 | BB9: =SUMIFS($CH$3:$CH$341,$A$3:$A$341,T$2,$C$3:$C$341,T9) -> 0 | BC9: =SUMIFS($CH$3:$CH$341,$A$3:$A$341,U$2,$C$3:$C$341,U9) -> 0 | BD9: =SUMIFS($CH$3:$CH$341,$A$3:$A$341,V$2,$C$3:$C$341,V9) -> 0 | BE9: =SUMIFS($CH$3:$CH$341,$A$3:$A$341,W$2,$C$3:$C$341,W9) -> 0 | BF9: =SUMIFS($CH$3:$CH$341,$A$3:$A$341,X$2,$C$3:$C$341,X9) -> 0 | ... CF9: =SUMIFS($CH$3:$CH$341,$A$3:$A$341,AX$2,$C$3:$C$341,AX9) -> 0 | CG9: =MAX(AY9:CF9) -> 0 | CH9: =MAX(F9,CG9) -> 0
A10: Farm | B10: Building | C10: 3 | D10: 1 | E10: 3 | F10: 0 | H10: 120 | I10: 2 | J10: =ROUNDUP(H10/30,0) -> 4 | K10: 0 | L10: 200 | M10: 1200 | N10: 800 | O10: 600 | P10: 60 | AF10: 2 | AY10: =SUMIFS($CH$3:$CH$341,$A$3:$A$341,Q$2,$C$3:$C$341,Q10) -> 0 | AZ10: =SUMIFS($CH$3:$CH$341,$A$3:$A$341,R$2,$C$3:$C$341,R10) -> 0 | BA10: =SUMIFS($CH$3:$CH$341,$A$3:$A$341,S$2,$C$3:$C$341,S10) -> 0 | BB10: =SUMIFS($CH$3:$CH$341,$A$3:$A$341,T$2,$C$3:$C$341,T10) -> 0 | BC10: =SUMIFS($CH$3:$CH$341,$A$3:$A$341,U$2,$C$3:$C$341,U10) -> 0 | BD10: =SUMIFS($CH$3:$CH$341,$A$3:$A$341,V$2,$C$3:$C$341,V10) -> 0 | BE10: =SUMIFS($CH$3:$CH$341,$A$3:$A$341,W$2,$C$3:$C$341,W10) -> 0 | BF10: =SUMIFS($CH$3:$CH$341,$A$3:$A$341,X$2,$C$3:$C$341,X10) -> 0 | ... CF10: =SUMIFS($CH$3:$CH$341,$A$3:$A$341,AX$2,$C$3:$C$341,AX10) -> 0 | CG10: =MAX(AY10:CF10) -> 0 | CH10: =MAX(F10,CG10) -> 0
A11: Farm | B11: Building | C11: 4 | D11: 1 | E11: 4 | F11: 0 | H11: 240 | I11: 4 | J11: =ROUNDUP(H11/30,0) -> 8 | K11: 0 | L11: 400 | M11: 2400 | N11: 1600 | O11: 1200 | P11: 100 | AF11: 3 | AY11: =SUMIFS($CH$3:$CH$341,$A$3:$A$341,Q$2,$C$3:$C$341,Q11) -> 0 | AZ11: =SUMIFS($CH$3:$CH$341,$A$3:$A$341,R$2,$C$3:$C$341,R11) -> 0 | BA11: =SUMIFS($CH$3:$CH$341,$A$3:$A$341,S$2,$C$3:$C$341,S11) -> 0 | BB11: =SUMIFS($CH$3:$CH$341,$A$3:$A$341,T$2,$C$3:$C$341,T11) -> 0 | BC11: =SUMIFS($CH$3:$CH$341,$A$3:$A$341,U$2,$C$3:$C$341,U11) -> 0 | BD11: =SUMIFS($CH$3:$CH$341,$A$3:$A$341,V$2,$C$3:$C$341,V11) -> 0 | BE11: =SUMIFS($CH$3:$CH$341,$A$3:$A$341,W$2,$C$3:$C$341,W11) -> 0 | BF11: =SUMIFS($CH$3:$CH$341,$A$3:$A$341,X$2,$C$3:$C$341,X11) -> 0 | ... CF11: =SUMIFS($CH$3:$CH$341,$A$3:$A$341,AX$2,$C$3:$C$341,AX11) -> 0 | CG11: =MAX(AY11:CF11) -> 0 | CH11: =MAX(F11,CG11) -> 0
A12: Farm | B12: Building | C12: 5 | D12: 1 | E12: 5 | F12: 0 | H12: 480 | I12: 8 | J12: =ROUNDUP(H12/30,0) -> 16 | K12: 0 | L12: 800 | M12: 4800 | N12: 3200 | O12: 2400 | P12: 150 | AF12: 4 | AY12: =SUMIFS($CH$3:$CH$341,$A$3:$A$341,Q$2,$C$3:$C$341,Q12) -> 0 | AZ12: =SUMIFS($CH$3:$CH$341,$A$3:$A$341,R$2,$C$3:$C$341,R12) -> 0 | BA12: =SUMIFS($CH$3:$CH$341,$A$3:$A$341,S$2,$C$3:$C$341,S12) -> 0 | BB12: =SUMIFS($CH$3:$CH$341,$A$3:$A$341,T$2,$C$3:$C$341,T12) -> 0 | BC12: =SUMIFS($CH$3:$CH$341,$A$3:$A$341,U$2,$C$3:$C$341,U12) -> 0 | BD12: =SUMIFS($CH$3:$CH$341,$A$3:$A$341,V$2,$C$3:$C$341,V12) -> 0 | BE12: =SUMIFS($CH$3:$CH$341,$A$3:$A$341,W$2,$C$3:$C$341,W12) -> 0 | BF12: =SUMIFS($CH$3:$CH$341,$A$3:$A$341,X$2,$C$3:$C$341,X12) -> 0 | ... CF12: =SUMIFS($CH$3:$CH$341,$A$3:$A$341,AX$2,$C$3:$C$341,AX12) -> 0 | CG12: =MAX(AY12:CF12) -> 0 | CH12: =MAX(F12,CG12) -> 0
A13: Farm | B13: Building | C13: 6 | D13: 1 | E13: 6 | F13: 0 | H13: 960 | I13: 16 | J13: =ROUNDUP(H13/30,0) -> 32 | K13: 0 | L13: 1600 | M13: 9600 | N13: 6400 | O13: 4800 | P13: 210 | AF13: 5 | AY13: =SUMIFS($CH$3:$CH$341,$A$3:$A$341,Q$2,$C$3:$C$341,Q13) -> 0 | AZ13: =SUMIFS($CH$3:$CH$341,$A$3:$A$341,R$2,$C$3:$C$341,R13) -> 0 | BA13: =SUMIFS($CH$3:$CH$341,$A$3:$A$341,S$2,$C$3:$C$341,S13) -> 0 | BB13: =SUMIFS($CH$3:$CH$341,$A$3:$A$341,T$2,$C$3:$C$341,T13) -> 0 | BC13: =SUMIFS($CH$3:$CH$341,$A$3:$A$341,U$2,$C$3:$C$341,U13) -> 0 | BD13: =SUMIFS($CH$3:$CH$341,$A$3:$A$341,V$2,$C$3:$C$341,V13) -> 0 | BE13: =SUMIFS($CH$3:$CH$341,$A$3:$A$341,W$2,$C$3:$C$341,W13) -> 0 | BF13: =SUMIFS($CH$3:$CH$341,$A$3:$A$341,X$2,$C$3:$C$341,X13) -> 0 | ... CF13: =SUMIFS($CH$3:$CH$341,$A$3:$A$341,AX$2,$C$3:$C$341,AX13) -> 0 | CG13: =MAX(AY13:CF13) -> 0 | CH13: =MAX(F13,CG13) -> 0
A14: Farm | B14: Building | C14: 7 | D14: 1 | E14: 7 | F14: 0 | H14: 1920 | I14: 32 | J14: =ROUNDUP(H14/30,0) -> 64 | K14: 0 | L14: 3200 | M14: 19200 | N14: 12800 | O14: 9600 | P14: 280 | AF14: 6 | AY14: =SUMIFS($CH$3:$CH$341,$A$3:$A$341,Q$2,$C$3:$C$341,Q14) -> 0 | AZ14: =SUMIFS($CH$3:$CH$341,$A$3:$A$341,R$2,$C$3:$C$341,R14) -> 0 | BA14: =SUMIFS($CH$3:$CH$341,$A$3:$A$341,S$2,$C$3:$C$341,S14) -> 0 | BB14: =SUMIFS($CH$3:$CH$341,$A$3:$A$341,T$2,$C$3:$C$341,T14) -> 0 | BC14: =SUMIFS($CH$3:$CH$341,$A$3:$A$341,U$2,$C$3:$C$341,U14) -> 0 | BD14: =SUMIFS($CH$3:$CH$341,$A$3:$A$341,V$2,$C$3:$C$341,V14) -> 0 | BE14: =SUMIFS($CH$3:$CH$341,$A$3:$A$341,W$2,$C$3:$C$341,W14) -> 0 | BF14: =SUMIFS($CH$3:$CH$341,$A$3:$A$341,X$2,$C$3:$C$341,X14) -> 0 | ... CF14: =SUMIFS($CH$3:$CH$341,$A$3:$A$341,AX$2,$C$3:$C$341,AX14) -> 0 | CG14: =MAX(AY14:CF14) -> 0 | CH14: =MAX(F14,CG14) -> 0
A15: Farm | B15: Building | C15: 8 | D15: 1 | E15: 8 | F15: 0 | H15: 3840 | I15: 64 | J15: =ROUNDUP(H15/30,0) -> 128 | K15: 0 | L15: 6400 | M15: 38400 | N15: 25600 | O15: 19200 | P15: 360 | AF15: 7 | AY15: =SUMIFS($CH$3:$CH$341,$A$3:$A$341,Q$2,$C$3:$C$341,Q15) -> 0 | AZ15: =SUMIFS($CH$3:$CH$341,$A$3:$A$341,R$2,$C$3:$C$341,R15) -> 0 | BA15: =SUMIFS($CH$3:$CH$341,$A$3:$A$341,S$2,$C$3:$C$341,S15) -> 0 | BB15: =SUMIFS($CH$3:$CH$341,$A$3:$A$341,T$2,$C$3:$C$341,T15) -> 0 | BC15: =SUMIFS($CH$3:$CH$341,$A$3:$A$341,U$2,$C$3:$C$341,U15) -> 0 | BD15: =SUMIFS($CH$3:$CH$341,$A$3:$A$341,V$2,$C$3:$C$341,V15) -> 0 | BE15: =SUMIFS($CH$3:$CH$341,$A$3:$A$341,W$2,$C$3:$C$341,W15) -> 0 | BF15: =SUMIFS($CH$3:$CH$341,$A$3:$A$341,X$2,$C$3:$C$341,X15) -> 0 | ... CF15: =SUMIFS($CH$3:$CH$341,$A$3:$A$341,AX$2,$C$3:$C$341,AX15) -> 0 | CG15: =MAX(AY15:CF15) -> 0 | CH15: =MAX(F15,CG15) -> 0
A16: Farm | B16: Building | C16: 9 | D16: 1 | E16: 9 | F16: 0 | H16: 7680 | I16: 128 | J16: =ROUNDUP(H16/30,0) -> 256 | K16: 0 | L16: 12800 | M16: 76800 | N16: 51200 | O16: 38400 | AF16: 8 | AY16: =SUMIFS($CH$3:$CH$341,$A$3:$A$341,Q$2,$C$3:$C$341,Q16) -> 0 | AZ16: =SUMIFS($CH$3:$CH$341,$A$3:$A$341,R$2,$C$3:$C$341,R16) -> 0 | BA16: =SUMIFS($CH$3:$CH$341,$A$3:$A$341,S$2,$C$3:$C$341,S16) -> 0 | BB16: =SUMIFS($CH$3:$CH$341,$A$3:$A$341,T$2,$C$3:$C$341,T16) -> 0 | BC16: =SUMIFS($CH$3:$CH$341,$A$3:$A$341,U$2,$C$3:$C$341,U16) -> 0 | BD16: =SUMIFS($CH$3:$CH$341,$A$3:$A$341,V$2,$C$3:$C$341,V16) -> 0 | BE16: =SUMIFS($CH$3:$CH$341,$A$3:$A$341,W$2,$C$3:$C$341,W16) -> 0 | BF16: =SUMIFS($CH$3:$CH$341,$A$3:$A$341,X$2,$C$3:$C$341,X16) -> 0 | ... CF16: =SUMIFS($CH$3:$CH$341,$A$3:$A$341,AX$2,$C$3:$C$341,AX16) -> 0 | CG16: =MAX(AY16:CF16) -> 0 | CH16: =MAX(F16,CG16) -> 0
A17: Farm | B17: Building | C17: 10 | D17: 1 | E17: 10 | F17: 0 | G17: Divine Inspiration | H17: 15360 | I17: 256 | J17: =ROUNDUP(H17/30,0) -> 512 | K17: 0 | L17: 25600 | M17: 153600 | N17: 102400 | O17: 76800 | P17: 550 | AF17: 9 | AY17: =SUMIFS($CH$3:$CH$341,$A$3:$A$341,Q$2,$C$3:$C$341,Q17) -> 0 | AZ17: =SUMIFS($CH$3:$CH$341,$A$3:$A$341,R$2,$C$3:$C$341,R17) -> 0 | BA17: =SUMIFS($CH$3:$CH$341,$A$3:$A$341,S$2,$C$3:$C$341,S17) -> 0 | BB17: =SUMIFS($CH$3:$CH$341,$A$3:$A$341,T$2,$C$3:$C$341,T17) -> 0 | BC17: =SUMIFS($CH$3:$CH$341,$A$3:$A$341,U$2,$C$3:$C$341,U17) -> 0 | BD17: =SUMIFS($CH$3:$CH$341,$A$3:$A$341,V$2,$C$3:$C$341,V17) -> 0 | BE17: =SUMIFS($CH$3:$CH$341,$A$3:$A$341,W$2,$C$3:$C$341,W17) -> 0 | BF17: =SUMIFS($CH$3:$CH$341,$A$3:$A$341,X$2,$C$3:$C$341,X17) -> 0 | ... CF17: =SUMIFS($CH$3:$CH$341,$A$3:$A$341,AX$2,$C$3:$C$341,AX17) -> 0 | CG17: =MAX(AY17:CF17) -> 0 | CH17: =MAX(F17,CG17) -> 0
A18: MINE/ore vein | B18: Building | C18: 1 | D18: 1 | E18: 1 | F18: 0 | H18: 5 | I18: 0.083333333 | J18: =ROUNDUP(H18/30,0) -> 1 | K18: 0 | L18: 210 | M18: 600 | N18: 500 | O18: 200 | P18: 25 | AY18: =SUMIFS($CH$3:$CH$341,$A$3:$A$341,Q$2,$C$3:$C$341,Q18) -> 0 | AZ18: =SUMIFS($CH$3:$CH$341,$A$3:$A$341,R$2,$C$3:$C$341,R18) -> 0 | BA18: =SUMIFS($CH$3:$CH$341,$A$3:$A$341,S$2,$C$3:$C$341,S18) -> 0 | BB18: =SUMIFS($CH$3:$CH$341,$A$3:$A$341,T$2,$C$3:$C$341,T18) -> 0 | BC18: =SUMIFS($CH$3:$CH$341,$A$3:$A$341,U$2,$C$3:$C$341,U18) -> 0 | BD18: =SUMIFS($CH$3:$CH$341,$A$3:$A$341,V$2,$C$3:$C$341,V18) -> 0 | BE18: =SUMIFS($CH$3:$CH$341,$A$3:$A$341,W$2,$C$3:$C$341,W18) -> 0 | BF18: =SUMIFS($CH$3:$CH$341,$A$3:$A$341,X$2,$C$3:$C$341,X18) -> 0 | ... CF18: =SUMIFS($CH$3:$CH$341,$A$3:$A$341,AX$2,$C$3:$C$341,AX18) -> 0 | CG18: =MAX(AY18:CF18) -> 0 | CH18: =MAX(F18,CG18) -> 0
A19: MINE/ore vein | B19: Building | C19: 2 | D19: 1 | E19: 2 | F19: 0 | H19: 90 | I19: 1.5 | J19: =ROUNDUP(H19/30,0) -> 3 | K19: 0 | L19: 420 | M19: 1200 | N19: 1000 | O19: 400 | P19: 75 | AI19: 1 | AY19: =SUMIFS($CH$3:$CH$341,$A$3:$A$341,Q$2,$C$3:$C$341,Q19) -> 0 | AZ19: =SUMIFS($CH$3:$CH$341,$A$3:$A$341,R$2,$C$3:$C$341,R19) -> 0 | BA19: =SUMIFS($CH$3:$CH$341,$A$3:$A$341,S$2,$C$3:$C$341,S19) -> 0 | BB19: =SUMIFS($CH$3:$CH$341,$A$3:$A$341,T$2,$C$3:$C$341,T19) -> 0 | BC19: =SUMIFS($CH$3:$CH$341,$A$3:$A$341,U$2,$C$3:$C$341,U19) -> 0 | BD19: =SUMIFS($CH$3:$CH$341,$A$3:$A$341,V$2,$C$3:$C$341,V19) -> 0 | BE19: =SUMIFS($CH$3:$CH$341,$A$3:$A$341,W$2,$C$3:$C$341,W19) -> 0 | BF19: =SUMIFS($CH$3:$CH$341,$A$3:$A$341,X$2,$C$3:$C$341,X19) -> 0 | ... CF19: =SUMIFS($CH$3:$CH$341,$A$3:$A$341,AX$2,$C$3:$C$341,AX19) -> 0 | CG19: =MAX(AY19:CF19) -> 0 | CH19: =MAX(F19,CG19) -> 0
A20: MINE/ore vein | B20: Building | C20: 3 | D20: 1 | E20: 3 | F20: 0 | H20: 360 | I20: 6 | J20: =ROUNDUP(H20/30,0) -> 12 | K20: 0 | L20: 840 | M20: 2400 | N20: 2000 | O20: 800 | P20: 150 | AI20: 2 | AY20: =SUMIFS($CH$3:$CH$341,$A$3:$A$341,Q$2,$C$3:$C$341,Q20) -> 0 | AZ20: =SUMIFS($CH$3:$CH$341,$A$3:$A$341,R$2,$C$3:$C$341,R20) -> 0 | BA20: =SUMIFS($CH$3:$CH$341,$A$3:$A$341,S$2,$C$3:$C$341,S20) -> 0 | BB20: =SUMIFS($CH$3:$CH$341,$A$3:$A$341,T$2,$C$3:$C$341,T20) -> 0 | BC20: =SUMIFS($CH$3:$CH$341,$A$3:$A$341,U$2,$C$3:$C$341,U20) -> 0 | BD20: =SUMIFS($CH$3:$CH$341,$A$3:$A$341,V$2,$C$3:$C$341,V20) -> 0 | BE20: =SUMIFS($CH$3:$CH$341,$A$3:$A$341,W$2,$C$3:$C$341,W20) -> 0 | BF20: =SUMIFS($CH$3:$CH$341,$A$3:$A$341,X$2,$C$3:$C$341,X20) -> 0 | ... CF20: =SUMIFS($CH$3:$CH$341,$A$3:$A$341,AX$2,$C$3:$C$341,AX20) -> 0 | CG20: =MAX(AY20:CF20) -> 0 | CH20: =MAX(F20,CG20) -> 0
A21: MINE/ore vein | B21: Building | C21: 4 | D21: 1 | E21: 4 | F21: 0 | H21: 720 | I21: 12 | J21: =ROUNDUP(H21/30,0) -> 24 | K21: 0 | L21: 1680 | M21: 4800 | N21: 4000 | O21: 1600 | P21: 250 | AI21: 3 | AY21: =SUMIFS($CH$3:$CH$341,$A$3:$A$341,Q$2,$C$3:$C$341,Q21) -> 0 | AZ21: =SUMIFS($CH$3:$CH$341,$A$3:$A$341,R$2,$C$3:$C$341,R21) -> 0 | BA21: =SUMIFS($CH$3:$CH$341,$A$3:$A$341,S$2,$C$3:$C$341,S21) -> 0 | BB21: =SUMIFS($CH$3:$CH$341,$A$3:$A$341,T$2,$C$3:$C$341,T21) -> 0 | BC21: =SUMIFS($CH$3:$CH$341,$A$3:$A$341,U$2,$C$3:$C$341,U21) -> 0 | BD21: =SUMIFS($CH$3:$CH$341,$A$3:$A$341,V$2,$C$3:$C$341,V21) -> 0 | BE21: =SUMIFS($CH$3:$CH$341,$A$3:$A$341,W$2,$C$3:$C$341,W21) -> 0 | BF21: =SUMIFS($CH$3:$CH$341,$A$3:$A$341,X$2,$C$3:$C$341,X21) -> 0 | ... CF21: =SUMIFS($CH$3:$CH$341,$A$3:$A$341,AX$2,$C$3:$C$341,AX21) -> 0 | CG21: =MAX(AY21:CF21) -> 0 | CH21: =MAX(F21,CG21) -> 0
A22: MINE/ore vein | B22: Building | C22: 5 | D22: 1 | E22: 5 | F22: 0 | H22: 1440 | I22: 24 | J22: =ROUNDUP(H22/30,0) -> 48 | K22: 0 | L22: 3360 | M22: 9600 | N22: 8000 | O22: 3200 | P22: 375 | AI22: 4 | AY22: =SUMIFS($CH$3:$CH$341,$A$3:$A$341,Q$2,$C$3:$C$341,Q22) -> 0 | AZ22: =SUMIFS($CH$3:$CH$341,$A$3:$A$341,R$2,$C$3:$C$341,R22) -> 0 | BA22: =SUMIFS($CH$3:$CH$341,$A$3:$A$341,S$2,$C$3:$C$341,S22) -> 0 | BB22: =SUMIFS($CH$3:$CH$341,$A$3:$A$341,T$2,$C$3:$C$341,T22) -> 0 | BC22: =SUMIFS($CH$3:$CH$341,$A$3:$A$341,U$2,$C$3:$C$341,U22) -> 0 | BD22: =SUMIFS($CH$3:$CH$341,$A$3:$A$341,V$2,$C$3:$C$341,V22) -> 0 | BE22: =SUMIFS($CH$3:$CH$341,$A$3:$A$341,W$2,$C$3:$C$341,W22) -> 0 | BF22: =SUMIFS($CH$3:$CH$341,$A$3:$A$341,X$2,$C$3:$C$341,X22) -> 0 | ... CF22: =SUMIFS($CH$3:$CH$341,$A$3:$A$341,AX$2,$C$3:$C$341,AX22) -> 0 | CG22: =MAX(AY22:CF22) -> 0 | CH22: =MAX(F22,CG22) -> 0
A23: MINE/ore vein | B23: Building | C23: 6 | D23: 1 | E23: 6 | F23: 0 | H23: 2880 | I23: 48 | J23: =ROUNDUP(H23/30,0) -> 96 | K23: 0 | L23: 6720 | M23: 19200 | N23: 16000 | O23: 6400 | P23: 525 | AI23: 5 | AY23: =SUMIFS($CH$3:$CH$341,$A$3:$A$341,Q$2,$C$3:$C$341,Q23) -> 0 | AZ23: =SUMIFS($CH$3:$CH$341,$A$3:$A$341,R$2,$C$3:$C$341,R23) -> 0 | BA23: =SUMIFS($CH$3:$CH$341,$A$3:$A$341,S$2,$C$3:$C$341,S23) -> 0 | BB23: =SUMIFS($CH$3:$CH$341,$A$3:$A$341,T$2,$C$3:$C$341,T23) -> 0 | BC23: =SUMIFS($CH$3:$CH$341,$A$3:$A$341,U$2,$C$3:$C$341,U23) -> 0 | BD23: =SUMIFS($CH$3:$CH$341,$A$3:$A$341,V$2,$C$3:$C$341,V23) -> 0 | BE23: =SUMIFS($CH$3:$CH$341,$A$3:$A$341,W$2,$C$3:$C$341,W23) -> 0 | BF23: =SUMIFS($CH$3:$CH$341,$A$3:$A$341,X$2,$C$3:$C$341,X23) -> 0 | ... CF23: =SUMIFS($CH$3:$CH$341,$A$3:$A$341,AX$2,$C$3:$C$341,AX23) -> 0 | CG23: =MAX(AY23:CF23) -> 0 | CH23: =MAX(F23,CG23) -> 0
A24: MINE/ore vein | B24: Building | C24: 7 | D24: 1 | E24: 7 | F24: 0 | H24: 5760 | I24: 96 | J24: =ROUNDUP(H24/30,0) -> 192 | K24: 0 | L24: 13440 | M24: 38400 | N24: 32000 | O24: 12800 | P24: 700 | AI24: 6 | AY24: =SUMIFS($CH$3:$CH$341,$A$3:$A$341,Q$2,$C$3:$C$341,Q24) -> 0 | AZ24: =SUMIFS($CH$3:$CH$341,$A$3:$A$341,R$2,$C$3:$C$341,R24) -> 0 | BA24: =SUMIFS($CH$3:$CH$341,$A$3:$A$341,S$2,$C$3:$C$341,S24) -> 0 | BB24: =SUMIFS($CH$3:$CH$341,$A$3:$A$341,T$2,$C$3:$C$341,T24) -> 0 | BC24: =SUMIFS($CH$3:$CH$341,$A$3:$A$341,U$2,$C$3:$C$341,U24) -> 0 | BD24: =SUMIFS($CH$3:$CH$341,$A$3:$A$341,V$2,$C$3:$C$341,V24) -> 0 | BE24: =SUMIFS($CH$3:$CH$341,$A$3:$A$341,W$2,$C$3:$C$341,W24) -> 0 | BF24: =SUMIFS($CH$3:$CH$341,$A$3:$A$341,X$2,$C$3:$C$341,X24) -> 0 | ... CF24: =SUMIFS($CH$3:$CH$341,$A$3:$A$341,AX$2,$C$3:$C$341,AX24) -> 0 | CG24: =MAX(AY24:CF24) -> 0 | CH24: =MAX(F24,CG24) -> 0
A25: MINE/ore vein | B25: Building | C25: 8 | D25: 1 | E25: 8 | F25: 0 | H25: 11520 | I25: 192 | J25: =ROUNDUP(H25/30,0) -> 384 | K25: 0 | L25: 26880 | M25: 76800 | N25: 64000 | O25: 25600 | P25: 900 | AI25: 7 | AY25: =SUMIFS($CH$3:$CH$341,$A$3:$A$341,Q$2,$C$3:$C$341,Q25) -> 0 | AZ25: =SUMIFS($CH$3:$CH$341,$A$3:$A$341,R$2,$C$3:$C$341,R25) -> 0 | BA25: =SUMIFS($CH$3:$CH$341,$A$3:$A$341,S$2,$C$3:$C$341,S25) -> 0 | BB25: =SUMIFS($CH$3:$CH$341,$A$3:$A$341,T$2,$C$3:$C$341,T25) -> 0 | BC25: =SUMIFS($CH$3:$CH$341,$A$3:$A$341,U$2,$C$3:$C$341,U25) -> 0 | BD25: =SUMIFS($CH$3:$CH$341,$A$3:$A$341,V$2,$C$3:$C$341,V25) -> 0 | BE25: =SUMIFS($CH$3:$CH$341,$A$3:$A$341,W$2,$C$3:$C$341,W25) -> 0 | BF25: =SUMIFS($CH$3:$CH$341,$A$3:$A$341,X$2,$C$3:$C$341,X25) -> 0 | ... CF25: =SUMIFS($CH$3:$CH$341,$A$3:$A$341,AX$2,$C$3:$C$341,AX25) -> 0 | CG25: =MAX(AY25:CF25) -> 0 | CH25: =MAX(F25,CG25) -> 0
A26: MINE/ore vein | B26: Building | C26: 9 | D26: 1 | E26: 9 | F26: 0 | H26: 23040 | I26: 384 | J26: =ROUNDUP(H26/30,0) -> 768 | K26: 0 | L26: 53760 | M26: 153600 | N26: 128000 | O26: 51200 | P26: 1125 | AI26: 8 | AY26: =SUMIFS($CH$3:$CH$341,$A$3:$A$341,Q$2,$C$3:$C$341,Q26) -> 0 | AZ26: =SUMIFS($CH$3:$CH$341,$A$3:$A$341,R$2,$C$3:$C$341,R26) -> 0 | BA26: =SUMIFS($CH$3:$CH$341,$A$3:$A$341,S$2,$C$3:$C$341,#REF!) -> 0 | BB26: =SUMIFS($CH$3:$CH$341,$A$3:$A$341,T$2,$C$3:$C$341,T26) -> 0 | BC26: =SUMIFS($CH$3:$CH$341,$A$3:$A$341,U$2,$C$3:$C$341,U26) -> 0 | BD26: =SUMIFS($CH$3:$CH$341,$A$3:$A$341,V$2,$C$3:$C$341,V26) -> 0 | BE26: =SUMIFS($CH$3:$CH$341,$A$3:$A$341,W$2,$C$3:$C$341,W26) -> 0 | BF26: =SUMIFS($CH$3:$CH$341,$A$3:$A$341,X$2,$C$3:$C$341,X26) -> 0 | BG26: =SUMIFS($CH$3:$CH$341,$A$3:$A$341,Y$2,$C$3:$C$341,Y26) -> 0 | BH26: =SUMIFS($CH$3:$CH$341,$A$3:$A$341,Z$2,$C$3:$C$341,Z26) -> 0 | BI26: =SUMIFS($CH$3:$CH$341,$A$3:$A$341,AA$2,$C$3:$C$341,AA26) -> 0 | ... CF26: =SUMIFS($CH$3:$CH$341,$A$3:$A$341,AX$2,$C$3:$C$341,AX26) -> 0 | CG26: =MAX(AY26:CF26) -> 0 | CH26: =MAX(F26,CG26) -> 0
A27: MINE/ore vein | B27: Building | C27: 10 | D27: 1 | E27: 10 | F27: 0 | G27: Divine Inspiration | H27: 46080 | I27: 768 | J27: =ROUNDUP(H27/30,0) -> 1536 | K27: 0 | L27: 107520 | M27: 307200 | N27: 256000 | O27: 102400 | P27: 1375 | AI27: 9 | AY27: =SUMIFS($CH$3:$CH$341,$A$3:$A$341,Q$2,$C$3:$C$341,Q27) -> 0 | AZ27: =SUMIFS($CH$3:$CH$341,$A$3:$A$341,R$2,$C$3:$C$341,R27) -> 0 | BA27: =SUMIFS($CH$3:$CH$341,$A$3:$A$341,S$2,$C$3:$C$341,S27) -> 0 | BB27: =SUMIFS($CH$3:$CH$341,$A$3:$A$341,T$2,$C$3:$C$341,T27) -> 0 | BC27: =SUMIFS($CH$3:$CH$341,$A$3:$A$341,U$2,$C$3:$C$341,U27) -> 0 | BD27: =SUMIFS($CH$3:$CH$341,$A$3:$A$341,V$2,$C$3:$C$341,V27) -> 0 | BE27: =SUMIFS($CH$3:$CH$341,$A$3:$A$341,W$2,$C$3:$C$341,W27) -> 0 | BF27: =SUMIFS($CH$3:$CH$341,$A$3:$A$341,X$2,$C$3:$C$341,X27) -> 0 | ... CF27: =SUMIFS($CH$3:$CH$341,$A$3:$A$341,AX$2,$C$3:$C$341,AX27) -> 0 | CG27: =MAX(AY27:CF27) -> 0 | CH27: =MAX(F27,CG27) -> 0
A28: Quarry | B28: Building | C28: 1 | D28: 1 | E28: 1 | F28: 0 | H28: 5 | I28: 0.083333333 | J28: =ROUNDUP(H28/30,0) -> 1 | K28: 0 | L28: 180 | M28: 500 | N28: 150 | O28: 400 | P28: 20 | AY28: =SUMIFS($CH$3:$CH$341,$A$3:$A$341,Q$2,$C$3:$C$341,Q28) -> 0 | AZ28: =SUMIFS($CH$3:$CH$341,$A$3:$A$341,R$2,$C$3:$C$341,R28) -> 0 | BA28: =SUMIFS($CH$3:$CH$341,$A$3:$A$341,S$2,$C$3:$C$341,S28) -> 0 | BB28: =SUMIFS($CH$3:$CH$341,$A$3:$A$341,T$2,$C$3:$C$341,T28) -> 0 | BC28: =SUMIFS($CH$3:$CH$341,$A$3:$A$341,U$2,$C$3:$C$341,U28) -> 0 | BD28: =SUMIFS($CH$3:$CH$341,$A$3:$A$341,V$2,$C$3:$C$341,V28) -> 0 | BE28: =SUMIFS($CH$3:$CH$341,$A$3:$A$341,W$2,$C$3:$C$341,W28) -> 0 | BF28: =SUMIFS($CH$3:$CH$341,$A$3:$A$341,X$2,$C$3:$C$341,X28) -> 0 | ... CF28: =SUMIFS($CH$3:$CH$341,$A$3:$A$341,AX$2,$C$3:$C$341,AX28) -> 0 | CG28: =MAX(AY28:CF28) -> 0 | CH28: =MAX(F28,CG28) -> 0
A29: Quarry | B29: Building | C29: 2 | D29: 1 | E29: 2 | F29: 0 | H29: 45 | I29: 0.75 | J29: =ROUNDUP(H29/30,0) -> 2 | K29: 0 | L29: 360 | M29: 1000 | N29: 300 | O29: 800 | P29: 60 | AH29: 1 | AY29: =SUMIFS($CH$3:$CH$341,$A$3:$A$341,Q$2,$C$3:$C$341,Q29) -> 0 | AZ29: =SUMIFS($CH$3:$CH$341,$A$3:$A$341,R$2,$C$3:$C$341,R29) -> 0 | BA29: =SUMIFS($CH$3:$CH$341,$A$3:$A$341,S$2,$C$3:$C$341,S29) -> 0 | BB29: =SUMIFS($CH$3:$CH$341,$A$3:$A$341,T$2,$C$3:$C$341,T29) -> 0 | BC29: =SUMIFS($CH$3:$CH$341,$A$3:$A$341,U$2,$C$3:$C$341,U29) -> 0 | BD29: =SUMIFS($CH$3:$CH$341,$A$3:$A$341,V$2,$C$3:$C$341,V29) -> 0 | BE29: =SUMIFS($CH$3:$CH$341,$A$3:$A$341,W$2,$C$3:$C$341,W29) -> 0 | BF29: =SUMIFS($CH$3:$CH$341,$A$3:$A$341,X$2,$C$3:$C$341,X29) -> 0 | ... CF29: =SUMIFS($CH$3:$CH$341,$A$3:$A$341,AX$2,$C$3:$C$341,AX29) -> 0 | CG29: =MAX(AY29:CF29) -> 0 | CH29: =MAX(F29,CG29) -> 0
